Workbook

Sheet Entries April 2026
B1: ENTRIES FOR DAILY CONS. MONITOR | O1: =B1 -> ENTRIES FOR DAILY CONS. MONITOR
O2: Service 227.3 cubic meters (2273 Hls)Filtered 189.3 cubic meters(1893 Hls)
D3: FUEL | J3: ELECT. | L3: CO2 | O3: WATER | AG3: CO2 Scrubber (m3) | AH3: Supply to Washdown Area (m3) | AI3: Supply to RUs (m3) | AJ3: Steam Mass Flow Meter | AL3: CO2 TANKS' READING
B4: Boilers tot. | C4: Boiler 1 | D4: Gen. meter | E4: Tank level | F4: Boiler 1 | G4: Boiler 2 | H4: Gen | I4: Meter1 | J4: Meter 2 | K4: Gen Meter | L4: Consumption (FILTRATION) (kg) | M4: Consumption (Totalizer Flowmeter) | N4: Consumption (Filler) (kg) | O4: Nawasa Meter (m3) | P4: Annandale Supply (m3) | Q4: Service Supply to Plant (m3) | R4: Cellars/Filtration (m3) | S4: Brewhouse Meter (m3) | T4: Cellars/Process Areas (m3) | U4: Pasteuriser (m3) | V4: Water Plant-Nawasa Annadale (m3) | W4: Water Plant-Well # 1 (m3) | X4: CIP Process | Y4: Bottle Washer | Z4: Boiler | AA4: Permeate #1 | AB4: Permeate #2 | AC4: Bottle Filler (m3) | AD4: RO # 1 Totaliser (m3) | AE4: RO # 2 Totaliser (m3) | AF4: Recovered Water (m3) | AL4: Tank "C" | AM4: Tank "A" | AN4: Tank "B" | AO4: Mobile Tanker
A5: DATE | B5: (liters) | C5: (liters) | D5: (Imp. gals) | E5: (inches) | F5: Hrs | G5: Hrs | H5: Hrs. | I5: (Kwhr) | J5: (Kwhr) | K5: (Kwhr) | M5: (kg) | X5: (m3) | Y5: (m3) | Z5: (m3) | AL5: inH2O | AM5: (Kg.) | AN5: (Kg.) | AO5: (pounds)
A6: 1 | B6: 8119100 | E6: 64 | F6: 8658.6 | G6: 68225 | I6: 825474 | K6: 468000 | L6: 19274.65 | M6: 377633.25 | N6: 58084.65 | O6: 227533 | P6: 61994 | Q6: 959930 | S6: 78247 | U6: 22559 | V6: 1341402 | X6: 43639 | Y6: 59389 | Z6: 13039 | AA6: 97122 | AC6: 4267 | AD6: 262820 | AJ6: 7360518.3
A7: 2 | B7: 8121800 | E7: 64 | F7: 8675.8 | G7: 68225 | I7: 831401 | K7: 468000 | L7: 19386.46 | M7: 379260.63 | N7: 58202.47 | O7: 227740 | P7: 62150 | Q7: 960141 | S7: 78343 | U7: 22561 | V7: 1341566 | X7: 43707 | Y7: 59449 | Z7: 13052 | AA7: 97122 | AC7: 4280 | AD7: 262846 | AJ7: 7361047.4
A8: 3 | B8: 8124250 | E8: 64 | F8: 8693.4 | G8: 68225 | I8: 837233 | K8: 468000 | L8: 19624.64 | M8: 381077.13 | N8: 58342.52 | O8: 227864 | P8: 62318 | Q8: 960307 | S8: 78419 | U8: 22563 | V8: 1341743 | X8: 43730 | Y8: 59506 | Z8: 13056 | AA8: 97122 | AC8: 4301 | AD8: 262846 | AJ8: 7361047.4
A9: 4 | B9: 8124400 | E9: 64 | F9: 8695.1 | G9: 68225 | I9: 839927 | K9: 468000 | L9: 19624.64 | M9: 381077.13 | N9: 58342.52 | O9: 227864 | P9: 62318 | Q9: 960320 | S9: 78419 | U9: 22563 | V9: 1341743 | X9: 43730 | Y9: 59506 | Z9: 13073 | AA9: 97122 | AC9: 4301 | AD9: 262846 | AJ9: 7361047.4
A10: 5 | B10: 8124760 | E10: 64 | F10: 8697.6 | G10: 68225 | I10: 842898 | K10: 468000 | L10: 19624.64 | M10: 381077.13 | N10: 58342.52 | O10: 227891 | P10: 62438 | Q10: 960378 | S10: 78419 | U10: 22563 | V10: 1341869 | X10: 43730 | Y10: 59540 | Z10: 13075 | AA10: 97122 | AC10: 4301 | AD10: 262846 | AJ10: 7361047.4
A11: 6 | B11: 8124760 | E11: 64 | F11: 8697.6 | G11: 68225 | I11: 845809 | K11: 468000 | L11: 19624.64 | M11: 381077.13 | N11: 58342.52 | O11: 227891 | P11: 62438 | Q11: 960386 | S11: 78419 | U11: 22563 | V11: 1341869 | X11: 43730 | Y11: 59540 | Z11: 13075 | AA11: 97122 | AC11: 4301 | AD11: 262846 | AJ11: 7361047.4
A12: 7 | B12: 8125540 | E12: 64 | F12: 8702.2 | G12: 68225 | I12: 848408 | K12: 468000 | L12: 19624.64 | M12: 381077.13 | N12: 58342.52 | O12: 227891 | P12: 62438 | Q12: 960392 | S12: 78419 | U12: 22563 | V12: 1341869 | X12: 43730 | Y12: 59540 | Z12: 13079 | AA12: 97122 | AC12: 4301 | AD12: 262846 | AJ12: 7361047.4
A13: 8 | B13: 8128770 | E13: 64 | F13: 8723.1 | G13: 68225 | I13: 853622 | K13: 468000 | L13: 19652.22 | M13: 381750.11 | N13: 58478.74 | O13: 227925 | P13: 62622 | Q13: 960544 | S13: 78559 | U13: 22566 | V13: 1342062 | X13: 43772 | Y13: 59578 | Z13: 13094 | AA13: 97122 | AC13: 4318 | AD13: 262846 | AJ13: 7361475
A14: 9 | B14: 8131570 | E14: 64 | F14: 8742 | G14: 68225 | I14: 859472 | K14: 468000 | L14: 19811.83 | M14: 384862.26 | N14: 58796.08 | O14: 228097 | P14: 62769 | Q14: 960807 | S14: 78612 | U14: 22567 | V14: 1342217 | X14: 43820 | Y14: 59698 | Z14: 13109 | AA14: 97122 | AC14: 4350 | AD14: 262857 | AJ14: 7361475
A15: 10 | B15: 8135360 | E15: 64 | F15: 8762.4 | G15: 68225 | I15: 866373 | K15: 468000 | L15: 20086.56 | M15: 388373.94 | N15: 59204.72 | O15: 228334 | P15: 62907 | Q15: 961065 | S15: 78779 | U15: 22568 | V15: 1342361 | X15: 43851 | Y15: 59834 | Z15: 13126 | AA15: 97122 | AC15: 4383 | AD15: 262878 | AJ15: 7361475
A16: 11 | B16: 8137760 | E16: 64 | F16: 8779.8 | G16: 68225 | I16: 873219 | K16: 468000 | L16: 20422.05 | M16: 391468.13 | N16: 59491.2 | O16: 228545 | P16: 63073 | Q16: 961269 | S16: 78891 | U16: 22568 | V16: 1342535 | X16: 43881 | Y16: 59913 | Z16: 13142 | AA16: 97122 | AC16: 4408 | AD16: 262902 | AJ16: 7361475
A17: 12 | B17: 8137760 | E17: 64 | F17: 8779.8 | G17: 68225 | I17: 876202 | K17: 468000 | L17: 20422.05 | M17: 391468.13 | N17: 59491.2 | O17: 228576 | P17: 63105 | Q17: 961320 | S17: 78891 | U17: 22568 | V17: 1342569 | X17: 43881 | Y17: 59939 | Z17: 13143 | AA17: 97122 | AC17: 4408 | AD17: 262902 | AJ17: 7361475
... A36: 1 | B36: 8185550 | E36: 64 | F36: 9079.9 | G36: 68225 | I36: 978969 | K36: 468000 | L36: 23965.65 | M36: 423063.03 | N36: 63182.72 | O36: 231941 | P36: 65287 | Q36: 964847 | S36: 80995 | U36: 22587 | V36: 1344858 | X36: 44524 | Y36: 61386 | Z36: 13446 | AA36: 97122 | AC36: 4803 | AD36: 263138 | AJ36: 7362269.3

Sheet Utility Analysis April 2026
J2: GRENADA BREWERIES LIMITED
J3: UTILITY ANALYSIS
A5: MONTH: | I5: 39295
A7: DATE | D7: ELECTRICITY GRENLEC | E7: Solar System CARIB | F7: % (Solar/Total Usage) | G7: CARIB GENSET | H7: ELECTRICITY TOTAL | I7: WATER | J7: FUEL | K7: CO2 | L7: PRODUCTION - HL | Q7: UTILITY RATIOS
B8: METER 1 | C8: METER 2 | Q8: Elect | R8: Water | S8: Fuel | T8: CO2
G9: USAGE (kwh) | H9: USAGE (kwh) | I9: USAGE (Hl) | J9: USAGE (l) | K9: USAGE (Kg.) | L9: BREWED | M9: BOTTLED | N9: KEGS | O9: OTHER | P9: TOTAL | Q9: KWH/Hl | R9: Hl/hl | S9: Litres/hl | T9: kg./Hl
A10: 1 | B10: =IF('Entries April 2026'!I7<'Entries April 2026'!I6,"0",(IF('Entries April 2026'!I7>='Entries April 2026'!I6,'Entries April 2026'!I7-'Entries April 2026'!I6,(999999-'Entries April 2026'!I6)+'Entries April 2026'!I7+1))) -> 5927 | C10: =IF('Entries April 2026'!J7<='Entries April 2026'!J6,"0",IF('Entries April 2026'!J7>='Entries April 2026'!J6,'Entries April 2026'!J7-'Entries April 2026'!J6,(999999-'Entries April 2026'!J6)+'Entries April 2026'!J7+1)) -> 0 | D10: =B10+C10 -> 5927 | E10: 1739.4 | F10: =IF((E10+D10)=0,"0",E10/(D10+E10)) -> 0.22688615 | G10: =IF('Entries April 2026'!K7<'Entries April 2026'!K6,"0",IF('Entries April 2026'!K7>='Entries April 2026'!K6,'Entries April 2026'!K7-'Entries April 2026'!K6,(999999-'Entries April 2026'!K6)+'Entries April 2026'!K7+1)) -> 0 | H10: =D10+G10+E10 -> 7666.4 | I10: ='Water '!Z7*10 -> 3630 | J10: =IF('Entries April 2026'!B7-'Entries April 2026'!B6<1,"0",'Entries April 2026'!B7-'Entries April 2026'!B6) -> 2700 | K10: ='CO2'!E7 -> 1200 | L10: =+'PROD.FIG. '!F5 -> 0 | M10: =+'PROD.FIG. '!C5 -> 0 | N10: =+'PROD.FIG. '!D5 -> 0 | O10: =+'PROD.FIG. '!E5 -> 0 | P10: {=TRANSPOSE('Daily KPIs'!B9:AE9)} -> 209.55 | Q10: =IF(P10=0,0,H10/P10) -> 36.585063 | R10: =IF(Q10=0,0,I10/P10) -> 17.322835 | S10: =IF(R10=0,0,J10/P10) -> 12.884753 | T10: =IF(S10=0,0,K10/P10) -> 5.7265569
A11: 2 | B11: =IF('Entries April 2026'!I8<'Entries April 2026'!I7,"0",(IF('Entries April 2026'!I8>='Entries April 2026'!I7,'Entries April 2026'!I8-'Entries April 2026'!I7,(999999-'Entries April 2026'!I7)+'Entries April 2026'!I8+1))) -> 5832 | C11: =IF('Entries April 2026'!J8<='Entries April 2026'!J7,"0",IF('Entries April 2026'!J8>='Entries April 2026'!J7,'Entries April 2026'!J8-'Entries April 2026'!J7,(999999-'Entries April 2026'!J7)+'Entries April 2026'!J8+1)) -> 0 | D11: =B11+C11 -> 5832 | E11: 1604.4 | F11: =IF((E11+D11)=0,"0",E11/(D11+E11)) -> 0.21574956 | G11: =IF('Entries April 2026'!K8<'Entries April 2026'!K7,"0",IF('Entries April 2026'!K8>='Entries April 2026'!K7,'Entries April 2026'!K8-'Entries April 2026'!K7,(999999-'Entries April 2026'!K7)+'Entries April 2026'!K8+1)) -> 0 | H11: =D11+G11+E11 -> 7436.4 | I11: ='Water '!Z8*10 -> 2920 | J11: =IF('Entries April 2026'!B8-'Entries April 2026'!B7<1,"0",'Entries April 2026'!B8-'Entries April 2026'!B7) -> 2450 | K11: ='CO2'!E8 -> 1400 | L11: =+'PROD.FIG. '!F6 -> 0 | M11: =+'PROD.FIG. '!C6 -> 0 | N11: =+'PROD.FIG. '!D6 -> 0 | O11: =+'PROD.FIG. '!E6 -> 0 | P11: 189.288 | Q11: =IF(P11=0,0,H11/P11) -> 39.286167 | R11: =IF(Q11=0,0,I11/P11) -> 15.426229 | S11: =IF(R11=0,0,J11/P11) -> 12.94324 | T11: =IF(S11=0,0,K11/P11) -> 7.3961371
A12: 3 | B12: =IF('Entries April 2026'!I9<'Entries April 2026'!I8,"0",(IF('Entries April 2026'!I9>='Entries April 2026'!I8,'Entries April 2026'!I9-'Entries April 2026'!I8,(999999-'Entries April 2026'!I8)+'Entries April 2026'!I9+1))) -> 2694 | C12: =IF('Entries April 2026'!J9<='Entries April 2026'!J8,"0",IF('Entries April 2026'!J9>='Entries April 2026'!J8,'Entries April 2026'!J9-'Entries April 2026'!J8,(999999-'Entries April 2026'!J8)+'Entries April 2026'!J9+1)) -> 0 | D12: =B12+C12 -> 2694 | E12: 1730.6 | F12: =IF((E12+D12)=0,"0",E12/(D12+E12)) -> 0.3911314 | G12: =IF('Entries April 2026'!K9<'Entries April 2026'!K8,"0",IF('Entries April 2026'!K9>='Entries April 2026'!K8,'Entries April 2026'!K9-'Entries April 2026'!K8,(999999-'Entries April 2026'!K8)+'Entries April 2026'!K9+1)) -> 0 | H12: =D12+G12+E12 -> 4424.6 | I12: ='Water '!Z9*10 -> 0 | J12: =IF('Entries April 2026'!B9-'Entries April 2026'!B8<1,"0",'Entries April 2026'!B9-'Entries April 2026'!B8) -> 150 | K12: ='CO2'!E9 -> 0 | L12: =+'PROD.FIG. '!F7 -> 0 | M12: =+'PROD.FIG. '!C7 -> 0 | N12: =+'PROD.FIG. '!D7 -> 0 | O12: =+'PROD.FIG. '!E7 -> 0 | P12: 0 | Q12: =IF(P12=0,0,H12/P12) -> 0 | R12: =IF(Q12=0,0,I12/P12) -> 0 | S12: =IF(R12=0,0,J12/P12) -> 0 | T12: =IF(S12=0,0,K12/P12) -> 0
A13: 4 | B13: =IF('Entries April 2026'!I10<'Entries April 2026'!I9,"0",(IF('Entries April 2026'!I10>='Entries April 2026'!I9,'Entries April 2026'!I10-'Entries April 2026'!I9,(999999-'Entries April 2026'!I9)+'Entries April 2026'!I10+1))) -> 2971 | C13: =IF('Entries April 2026'!J10<='Entries April 2026'!J9,"0",IF('Entries April 2026'!J10>='Entries April 2026'!J9,'Entries April 2026'!J10-'Entries April 2026'!J9,(999999-'Entries April 2026'!J9)+'Entries April 2026'!J10+1)) -> 0 | D13: =B13+C13 -> 2971 | E13: 1214.2 | F13: =IF((E13+D13)=0,"0",E13/(D13+E13)) -> 0.29011756 | G13: =IF('Entries April 2026'!K10<'Entries April 2026'!K9,"0",IF('Entries April 2026'!K10>='Entries April 2026'!K9,'Entries April 2026'!K10-'Entries April 2026'!K9,(999999-'Entries April 2026'!K9)+'Entries April 2026'!K10+1)) -> 0 | H13: =D13+G13+E13 -> 4185.2 | I13: ='Water '!Z10*10 -> 1470 | J13: =IF('Entries April 2026'!B10-'Entries April 2026'!B9<1,"0",'Entries April 2026'!B10-'Entries April 2026'!B9) -> 360 | K13: ='CO2'!E10 -> 0 | L13: =+'PROD.FIG. '!F8 -> 0 | M13: =+'PROD.FIG. '!C8 -> 0 | N13: =+'PROD.FIG. '!D8 -> 0 | O13: =+'PROD.FIG. '!E8 -> 0 | P13: 0 | Q13: =IF(P13=0,0,H13/P13) -> 0 | R13: =IF(Q13=0,0,I13/P13) -> 0 | S13: =IF(R13=0,0,J13/P13) -> 0 | T13: =IF(S13=0,0,K13/P13) -> 0
A14: 5 | B14: =IF('Entries April 2026'!I11<'Entries April 2026'!I10,"0",(IF('Entries April 2026'!I11>='Entries April 2026'!I10,'Entries April 2026'!I11-'Entries April 2026'!I10,(999999-'Entries April 2026'!I10)+'Entries April 2026'!I11+1))) -> 2911 | C14: =IF('Entries April 2026'!J11<='Entries April 2026'!J10,"0",IF('Entries April 2026'!J11>='Entries April 2026'!J10,'Entries April 2026'!J11-'Entries April 2026'!J10,(999999-'Entries April 2026'!J10)+'Entries April 2026'!J11+1)) -> 0 | D14: =B14+C14 -> 2911 | E14: 1085.9 | F14: =IF((E14+D14)=0,"0",E14/(D14+E14)) -> 0.27168556 | G14: =IF('Entries April 2026'!K11<'Entries April 2026'!K10,"0",IF('Entries April 2026'!K11>='Entries April 2026'!K10,'Entries April 2026'!K11-'Entries April 2026'!K10,(999999-'Entries April 2026'!K10)+'Entries April 2026'!K11+1)) -> 0 | H14: =D14+G14+E14 -> 3996.9 | I14: ='Water '!Z11*10 -> 0 | J14: =IF('Entries April 2026'!B11-'Entries April 2026'!B10<1,"0",'Entries April 2026'!B11-'Entries April 2026'!B10) -> 0 | K14: ='CO2'!E11 -> 0 | L14: =+'PROD.FIG. '!F9 -> 0 | M14: =+'PROD.FIG. '!C9 -> 0 | N14: =+'PROD.FIG. '!D9 -> 0 | O14: =+'PROD.FIG. '!E9 -> 0 | P14: 0 | Q14: =IF(P14=0,0,H14/P14) -> 0 | R14: =IF(Q14=0,0,I14/P14) -> 0 | S14: =IF(R14=0,0,J14/P14) -> 0 | T14: =IF(S14=0,0,K14/P14) -> 0
A15: 6 | B15: =IF('Entries April 2026'!I12<'Entries April 2026'!I11,"0",(IF('Entries April 2026'!I12>='Entries April 2026'!I11,'Entries April 2026'!I12-'Entries April 2026'!I11,(999999-'Entries April 2026'!I11)+'Entries April 2026'!I12+1))) -> 2599 | C15: =IF('Entries April 2026'!J12<='Entries April 2026'!J11,"0",IF('Entries April 2026'!J12>='Entries April 2026'!J11,'Entries April 2026'!J12-'Entries April 2026'!J11,(999999-'Entries April 2026'!J11)+'Entries April 2026'!J12+1)) -> 0 | D15: =B15+C15 -> 2599 | E15: 1238.7 | F15: =IF((E15+D15)=0,"0",E15/(D15+E15)) -> 0.32277145 | G15: =IF('Entries April 2026'!K12<'Entries April 2026'!K11,"0",IF('Entries April 2026'!K12>='Entries April 2026'!K11,'Entries April 2026'!K12-'Entries April 2026'!K11,(999999-'Entries April 2026'!K11)+'Entries April 2026'!K12+1)) -> 0 | H15: =D15+G15+E15 -> 3837.7 | I15: ='Water '!Z12*10 -> 0 | J15: =IF('Entries April 2026'!B12-'Entries April 2026'!B11<1,"0",'Entries April 2026'!B12-'Entries April 2026'!B11) -> 780 | K15: ='CO2'!E12 -> 600 | L15: =+'PROD.FIG. '!F10 -> 0 | M15: =+'PROD.FIG. '!C10 -> 0 | N15: =+'PROD.FIG. '!D10 -> 0 | O15: =+'PROD.FIG. '!E10 -> 0 | P15: 0 | Q15: =IF(P15=0,0,H15/P15) -> 0 | R15: =IF(Q15=0,0,I15/P15) -> 0 | S15: =IF(R15=0,0,J15/P15) -> 0 | T15: =IF(S15=0,0,K15/P15) -> 0
A16: 7 | B16: =IF('Entries April 2026'!I13<'Entries April 2026'!I12,"0",(IF('Entries April 2026'!I13>='Entries April 2026'!I12,'Entries April 2026'!I13-'Entries April 2026'!I12,(999999-'Entries April 2026'!I12)+'Entries April 2026'!I13+1))) -> 5214 | C16: =IF('Entries April 2026'!J13<='Entries April 2026'!J12,"0",IF('Entries April 2026'!J13>='Entries April 2026'!J12,'Entries April 2026'!J13-'Entries April 2026'!J12,(999999-'Entries April 2026'!J12)+'Entries April 2026'!J13+1)) -> 0 | D16: =B16+C16 -> 5214 | E16: 1488 | F16: =IF((E16+D16)=0,"0",E16/(D16+E16)) -> 0.22202328 | G16: =IF('Entries April 2026'!K13<'Entries April 2026'!K12,"0",IF('Entries April 2026'!K13>='Entries April 2026'!K12,'Entries April 2026'!K13-'Entries April 2026'!K12,(999999-'Entries April 2026'!K12)+'Entries April 2026'!K13+1)) -> 0 | H16: =D16+G16+E16 -> 6702 | I16: ='Water '!Z13*10 -> 2180 | J16: =IF('Entries April 2026'!B13-'Entries April 2026'!B12<1,"0",'Entries April 2026'!B13-'Entries April 2026'!B12) -> 3230 | K16: ='CO2'!E13 -> 700 | L16: =+'PROD.FIG. '!F11 -> 0 | M16: =+'PROD.FIG. '!C11 -> 0 | N16: =+'PROD.FIG. '!D11 -> 0 | O16: =+'PROD.FIG. '!E11 -> 0 | P16: 71.148 | Q16: =IF(P16=0,0,H16/P16) -> 94.19801 | R16: =IF(Q16=0,0,I16/P16) -> 30.640355 | S16: =IF(R16=0,0,J16/P16) -> 45.398325 | T16: =IF(S16=0,0,K16/P16) -> 9.8386462
A17: 8 | B17: =IF('Entries April 2026'!I14<'Entries April 2026'!I13,"0",(IF('Entries April 2026'!I14>='Entries April 2026'!I13,'Entries April 2026'!I14-'Entries April 2026'!I13,(999999-'Entries April 2026'!I13)+'Entries April 2026'!I14+1))) -> 5850 | C17: =IF('Entries April 2026'!J14<='Entries April 2026'!J13,"0",IF('Entries April 2026'!J14>='Entries April 2026'!J13,'Entries April 2026'!J14-'Entries April 2026'!J13,(999999-'Entries April 2026'!J13)+'Entries April 2026'!J14+1)) -> 0 | D17: =B17+C17 -> 5850 | E17: 1547.2 | F17: =IF((E17+D17)=0,"0",E17/(D17+E17)) -> 0.20916022 | G17: =IF('Entries April 2026'!K14<'Entries April 2026'!K13,"0",IF('Entries April 2026'!K14>='Entries April 2026'!K13,'Entries April 2026'!K14-'Entries April 2026'!K13,(999999-'Entries April 2026'!K13)+'Entries April 2026'!K14+1)) -> 0 | H17: =D17+G17+E17 -> 7397.2 | I17: ='Water '!Z14*10 -> 3190 | J17: =IF('Entries April 2026'!B14-'Entries April 2026'!B13<1,"0",'Entries April 2026'!B14-'Entries April 2026'!B13) -> 2800 | K17: ='CO2'!E14 -> 3700 | L17: =+'PROD.FIG. '!F12 -> 0 | M17: =+'PROD.FIG. '!C12 -> 0 | N17: =+'PROD.FIG. '!D12 -> 0 | O17: =+'PROD.FIG. '!E12 -> 0 | P17: 602.778 | Q17: =IF(P17=0,0,H17/P17) -> 12.271848 | R17: =IF(Q17=0,0,I17/P17) -> 5.2921639 | S17: =IF(R17=0,0,J17/P17) -> 4.6451596 | T17: =IF(S17=0,0,K17/P17) -> 6.1382466
A18: 9 | B18: =IF('Entries April 2026'!I15<'Entries April 2026'!I14,"0",(IF('Entries April 2026'!I15>='Entries April 2026'!I14,'Entries April 2026'!I15-'Entries April 2026'!I14,(999999-'Entries April 2026'!I14)+'Entries April 2026'!I15+1))) -> 6901 | C18: =IF('Entries April 2026'!J15<='Entries April 2026'!J14,"0",IF('Entries April 2026'!J15>='Entries April 2026'!J14,'Entries April 2026'!J15-'Entries April 2026'!J14,(999999-'Entries April 2026'!J14)+'Entries April 2026'!J15+1)) -> 0 | D18: =B18+C18 -> 6901 | E18: 1598.2 | F18: =IF((E18+D18)=0,"0",E18/(D18+E18)) -> 0.18804123 | G18: =IF('Entries April 2026'!K15<'Entries April 2026'!K14,"0",IF('Entries April 2026'!K15>='Entries April 2026'!K14,'Entries April 2026'!K15-'Entries April 2026'!K14,(999999-'Entries April 2026'!K14)+'Entries April 2026'!K15+1)) -> 0 | H18: =D18+G18+E18 -> 8499.2 | I18: ='Water '!Z15*10 -> 3750 | J18: =IF('Entries April 2026'!B15-'Entries April 2026'!B14<1,"0",'Entries April 2026'!B15-'Entries April 2026'!B14) -> 3790 | K18: ='CO2'!E15 -> 4000 | L18: =+'PROD.FIG. '!F13 -> 0 | M18: =+'PROD.FIG. '!C13 -> 0 | N18: =+'PROD.FIG. '!D13 -> 0 | O18: =+'PROD.FIG. '!E13 -> 0 | P18: 651.42 | Q18: =IF(P18=0,0,H18/P18) -> 13.047189 | R18: =IF(Q18=0,0,I18/P18) -> 5.7566547 | S18: =IF(R18=0,0,J18/P18) -> 5.818059 | T18: =IF(S18=0,0,K18/P18) -> 6.1404317
A19: 10 | B19: =IF('Entries April 2026'!I16<'Entries April 2026'!I15,"0",(IF('Entries April 2026'!I16>='Entries April 2026'!I15,'Entries April 2026'!I16-'Entries April 2026'!I15,(999999-'Entries April 2026'!I15)+'Entries April 2026'!I16+1))) -> 6846 | C19: =IF('Entries April 2026'!J16<='Entries April 2026'!J15,"0",IF('Entries April 2026'!J16>='Entries April 2026'!J15,'Entries April 2026'!J16-'Entries April 2026'!J15,(999999-'Entries April 2026'!J15)+'Entries April 2026'!J16+1)) -> 0 | D19: =B19+C19 -> 6846 | E19: 1712.9 | F19: =IF((E19+D19)=0,"0",E19/(D19+E19)) -> 0.20013086 | G19: =IF('Entries April 2026'!K16<'Entries April 2026'!K15,"0",IF('Entries April 2026'!K16>='Entries April 2026'!K15,'Entries April 2026'!K16-'Entries April 2026'!K15,(999999-'Entries April 2026'!K15)+'Entries April 2026'!K16+1)) -> 0 | H19: =D19+G19+E19 -> 8558.9 | I19: ='Water '!Z16*10 -> 3770 | J19: =IF('Entries April 2026'!B16-'Entries April 2026'!B15<1,"0",'Entries April 2026'!B16-'Entries April 2026'!B15) -> 2400 | K19: ='CO2'!E16 -> 0 | L19: =+'PROD.FIG. '!F14 -> 0 | M19: =+'PROD.FIG. '!C14 -> 0 | N19: =+'PROD.FIG. '!D14 -> 0 | O19: =+'PROD.FIG. '!E14 -> 0 | P19: 427.482 | Q19: =IF(P19=0,0,H19/P19) -> 20.021662 | R19: =IF(Q19=0,0,I19/P19) -> 8.8190848 | S19: =IF(R19=0,0,J19/P19) -> 5.6142715 | T19: =IF(S19=0,0,K19/P19) -> 0
A20: 11 | B20: =IF('Entries April 2026'!I17<'Entries April 2026'!I16,"0",(IF('Entries April 2026'!I17>='Entries April 2026'!I16,'Entries April 2026'!I17-'Entries April 2026'!I16,(999999-'Entries April 2026'!I16)+'Entries April 2026'!I17+1))) -> 2983 | C20: =IF('Entries April 2026'!J17<='Entries April 2026'!J16,"0",IF('Entries April 2026'!J17>='Entries April 2026'!J16,'Entries April 2026'!J17-'Entries April 2026'!J16,(999999-'Entries April 2026'!J16)+'Entries April 2026'!J17+1)) -> 0 | D20: =B20+C20 -> 2983 | E20: 1617.5 | F20: =IF((E20+D20)=0,"0",E20/(D20+E20)) -> 0.35159222 | G20: =IF('Entries April 2026'!K17<'Entries April 2026'!K16,"0",IF('Entries April 2026'!K17>='Entries April 2026'!K16,'Entries April 2026'!K17-'Entries April 2026'!K16,(999999-'Entries April 2026'!K16)+'Entries April 2026'!K17+1)) -> 0 | H20: =D20+G20+E20 -> 4600.5 | I20: ='Water '!Z17*10 -> 630 | J20: =IF('Entries April 2026'!B17-'Entries April 2026'!B16<1,"0",'Entries April 2026'!B17-'Entries April 2026'!B16) -> 0 | K20: ='CO2'!E17 -> 0 | L20: =+'PROD.FIG. '!F15 -> 0 | M20: =+'PROD.FIG. '!C15 -> 0 | N20: =+'PROD.FIG. '!D15 -> 0 | O20: =+'PROD.FIG. '!E15 -> 0 | P20: 0 | Q20: =IF(P20=0,0,H20/P20) -> 0 | R20: =IF(Q20=0,0,I20/P20) -> 0 | S20: =IF(R20=0,0,J20/P20) -> 0 | T20: =IF(S20=0,0,K20/P20) -> 0
A21: 12 | B21: =IF('Entries April 2026'!I18<'Entries April 2026'!I17,"0",(IF('Entries April 2026'!I18>='Entries April 2026'!I17,'Entries April 2026'!I18-'Entries April 2026'!I17,(999999-'Entries April 2026'!I17)+'Entries April 2026'!I18+1))) -> 1952 | C21: =IF('Entries April 2026'!J18<='Entries April 2026'!J17,"0",IF('Entries April 2026'!J18>='Entries April 2026'!J17,'Entries April 2026'!J18-'Entries April 2026'!J17,(999999-'Entries April 2026'!J17)+'Entries April 2026'!J18+1)) -> 0 | D21: =B21+C21 -> 1952 | E21: 1489.4 | F21: =IF((E21+D21)=0,"0",E21/(D21+E21)) -> 0.43278898 | G21: =IF('Entries April 2026'!K18<'Entries April 2026'!K17,"0",IF('Entries April 2026'!K18>='Entries April 2026'!K17,'Entries April 2026'!K18-'Entries April 2026'!K17,(999999-'Entries April 2026'!K17)+'Entries April 2026'!K18+1)) -> 0 | H21: =D21+G21+E21 -> 3441.4 | I21: ='Water '!Z18*10 -> 20 | J21: =IF('Entries April 2026'!B18-'Entries April 2026'!B17<1,"0",'Entries April 2026'!B18-'Entries April 2026'!B17) -> 700 | K21: ='CO2'!E18 -> 0 | L21: =+'PROD.FIG. '!F16 -> 0 | M21: =+'PROD.FIG. '!C16 -> 0 | N21: =+'PROD.FIG. '!D16 -> 0 | O21: =+'PROD.FIG. '!E16 -> 0 | P21: 0 | Q21: =IF(P21=0,0,H21/P21) -> 0 | R21: =IF(Q21=0,0,I21/P21) -> 0 | S21: =IF(R21=0,0,J21/P21) -> 0 | T21: =IF(S21=0,0,K21/P21) -> 0
A22: 13 | B22: =IF('Entries April 2026'!I19<'Entries April 2026'!I18,"0",(IF('Entries April 2026'!I19>='Entries April 2026'!I18,'Entries April 2026'!I19-'Entries April 2026'!I18,(999999-'Entries April 2026'!I18)+'Entries April 2026'!I19+1))) -> 6237 | C22: =IF('Entries April 2026'!J19<='Entries April 2026'!J18,"0",IF('Entries April 2026'!J19>='Entries April 2026'!J18,'Entries April 2026'!J19-'Entries April 2026'!J18,(999999-'Entries April 2026'!J18)+'Entries April 2026'!J19+1)) -> 0 | D22: =B22+C22 -> 6237 | E22: 1655.2 | F22: =IF((E22+D22)=0,"0",E22/(D22+E22)) -> 0.20972606 | G22: =IF('Entries April 2026'!K19<'Entries April 2026'!K18,"0",IF('Entries April 2026'!K19>='Entries April 2026'!K18,'Entries April 2026'!K19-'Entries April 2026'!K18,(999999-'Entries April 2026'!K18)+'Entries April 2026'!K19+1)) -> 0 | H22: =D22+G22+E22 -> 7892.2 | I22: ='Water '!Z19*10 -> 3900 | J22: =IF('Entries April 2026'!B19-'Entries April 2026'!B18<1,"0",'Entries April 2026'!B19-'Entries April 2026'!B18) -> 3520 | K22: ='CO2'!E19 -> 2600 | L22: =+'PROD.FIG. '!F17 -> 0 | M22: =+'PROD.FIG. '!C17 -> 0 | N22: =+'PROD.FIG. '!D17 -> 0 | O22: =+'PROD.FIG. '!E17 -> 0 | P22: 418.044 | Q22: =IF(P22=0,0,H22/P22) -> 18.878874 | R22: =IF(Q22=0,0,I22/P22) -> 9.3291615 | S22: =IF(R22=0,0,J22/P22) -> 8.4201663 | T22: =IF(S22=0,0,K22/P22) -> 6.219441
... A39: 30 | B39: =IF('Entries April 2026'!I36<'Entries April 2026'!I35,"0",(IF('Entries April 2026'!I36>='Entries April 2026'!I35,'Entries April 2026'!I36-'Entries April 2026'!I35,(999999-'Entries April 2026'!I35)+'Entries April 2026'!I36+1))) -> 6457 | C39: =IF('Entries April 2026'!J36<='Entries April 2026'!J35,"0",IF('Entries April 2026'!J36>='Entries April 2026'!J35,'Entries April 2026'!J36-'Entries April 2026'!J35,(999999-'Entries April 2026'!J35)+'Entries April 2026'!J36+1)) -> 0 | D39: =B39+C39 -> 6457 | E39: 1713.9 | F39: =IF((E39+D39)=0,"0",E39/(D39+E39)) -> 0.20975658 | G39: =IF('Entries April 2026'!K36<'Entries April 2026'!K35,"0",IF('Entries April 2026'!K36>='Entries April 2026'!K35,'Entries April 2026'!K36-'Entries April 2026'!K35,(999999-'Entries April 2026'!K35)+'Entries April 2026'!K36+1)) -> 0 | H39: =D39+G39+E39 -> 8170.9 | I39: ='Water '!Z36*10 -> 4310 | J39: =IF('Entries April 2026'!B36-'Entries April 2026'!B35<1,"0",'Entries April 2026'!B36-'Entries April 2026'!B35) -> 3130 | K39: ='CO2'!E36 -> 2000 | L39: =+'PROD.FIG. '!F34 -> 0 | M39: =+'PROD.FIG. '!C34 -> 0 | N39: =+'PROD.FIG. '!D34 -> 0 | O39: =+'PROD.FIG. '!E34 -> 0 | P39: 407.748 | Q39: =IF(P39=0,0,H39/P39) -> 20.039093 | R39: =IF(Q39=0,0,I39/P39) -> 10.570254 | S39: =IF(R39=0,0,J39/P39) -> 7.6763099 | T39: =IF(S39=0,0,K39/P39) -> 4.9049903
B40: =IF('Entries April 2026'!I37<'Entries April 2026'!I36,"0",(IF('Entries April 2026'!I37>='Entries April 2026'!I36,'Entries April 2026'!I37-'Entries April 2026'!I36,(999999-'Entries April 2026'!I36)+'Entries April 2026'!I37+1))) -> 0 | C40: =IF('Entries April 2026'!J37<='Entries April 2026'!J36,"0",IF('Entries April 2026'!J37>='Entries April 2026'!J36,'Entries April 2026'!J37-'Entries April 2026'!J36,(999999-'Entries April 2026'!J36)+'Entries April 2026'!J37+1)) -> 0 | D40: =B40+C40 -> 0 | F40: =IF((E40+D40)=0,"0",E40/(D40+E40)) -> 0 | G40: =IF('Entries April 2026'!K37<'Entries April 2026'!K36,"0",IF('Entries April 2026'!K37>='Entries April 2026'!K36,'Entries April 2026'!K37-'Entries April 2026'!K36,(999999-'Entries April 2026'!K36)+'Entries April 2026'!K37+1)) -> 0 | H40: =D40+G40+E40 -> 0 | I40: ='Water '!Z37*10 -> 0 | J40: =IF('Entries April 2026'!B37-'Entries April 2026'!B36<1,"0",'Entries April 2026'!B37-'Entries April 2026'!B36) -> 0 | K40: ='CO2'!E37 -> 0 | Q40: =IF(P40=0,0,H40/P40) -> 0 | R40: =IF(Q40=0,0,I40/P40) -> 0 | S40: =IF(R40=0,0,J40/P40) -> 0 | T40: =IF(S40=0,0,K40/P40) -> 0
Q41: MTD
D42: Kwhr | G42: Kwhr | H42: Kwhr | I42: Hl | J42: L | K42: kg. | L42: hl | M42: hl | N42: hl | O42: hl | P42: hl | Q42: Elect | R42: Water | S42: Fuel | T42: CO2
A43: Total | D43: =SUM(D10:D40) -> 153495 | E43: =SUM(E10:E40) -> 42857.2 | F43: =IF((E43+D43)=0,"0",E43/(D43+E43)) -> 0.21826697 | G43: =SUM(G10:G40) -> 0 | H43: =SUM(H10:H40) -> 196352.2 | I43: =SUM(I10:I40) -> 77010 | J43: =SUM(J10:J40) -> 66450 | K43: =SUM(K10:K40) -> 43100 | L43: =SUM(L10:L40) -> 0 | M43: =SUM(M10:M40) -> 0 | N43: =SUM(N10:N40) -> 0 | ... P43: =SUM(P10:P40) -> 7992.864 | Q43: KWH/Hl | R43: Hl/hl | S43: Litres/hl | T43: kg./Hl
D44: TOTAL | E44: =D43+E43 -> 196352.2 | Q44: =IF(P43=0,0,H43/P43) -> 24.565938 | R44: =IF(Q44=0,0,I43/P43) -> 9.6348443 | S44: =IF(R44=0,0,J43/P43) -> 8.3136658 | T44: =IF(S44=0,0,K43/P43) -> 5.3923099

Sheet Steam Mass Flow 
A3: DATE | B3: Steam Mass Flow Reading
A5: 1 | B5: =IF('Entries April 2026'!AJ7-'Entries April 2026'!AJ6<1,"0",'Entries April 2026'!AJ7-'Entries April 2026'!AJ6) -> 529.108
A6: 2 | B6: =IF('Entries April 2026'!AJ8-'Entries April 2026'!AJ7<1,"0",'Entries April 2026'!AJ8-'Entries April 2026'!AJ7) -> 0
A7: 3 | B7: =IF('Entries April 2026'!AJ9-'Entries April 2026'!AJ8<1,"0",'Entries April 2026'!AJ9-'Entries April 2026'!AJ8) -> 0
A8: 4 | B8: =IF('Entries April 2026'!AJ10-'Entries April 2026'!AJ9<1,"0",'Entries April 2026'!AJ10-'Entries April 2026'!AJ9) -> 0
A9: 5 | B9: =IF('Entries April 2026'!AJ11-'Entries April 2026'!AJ10<1,"0",'Entries April 2026'!AJ11-'Entries April 2026'!AJ10) -> 0
A10: 6 | B10: =IF('Entries April 2026'!AJ12-'Entries April 2026'!AJ11<1,"0",'Entries April 2026'!AJ12-'Entries April 2026'!AJ11) -> 0
A11: 7 | B11: =IF('Entries April 2026'!AJ13-'Entries April 2026'!AJ12<1,"0",'Entries April 2026'!AJ13-'Entries April 2026'!AJ12) -> 427.666
A12: 8 | B12: =IF('Entries April 2026'!AJ14-'Entries April 2026'!AJ13<1,"0",'Entries April 2026'!AJ14-'Entries April 2026'!AJ13) -> 0
A13: 9 | B13: =IF('Entries April 2026'!AJ15-'Entries April 2026'!AJ14<1,"0",'Entries April 2026'!AJ15-'Entries April 2026'!AJ14) -> 0
A14: 10 | B14: =IF('Entries April 2026'!AJ16-'Entries April 2026'!AJ15<1,"0",'Entries April 2026'!AJ16-'Entries April 2026'!AJ15) -> 0
A15: 11 | B15: =IF('Entries April 2026'!AJ17-'Entries April 2026'!AJ16<1,"0",'Entries April 2026'!AJ17-'Entries April 2026'!AJ16) -> 0
A16: 12 | B16: =IF('Entries April 2026'!AJ18-'Entries April 2026'!AJ17<1,"0",'Entries April 2026'!AJ18-'Entries April 2026'!AJ17) -> 0
... A34: 30 | B34: =IF('Entries April 2026'!AJ36-'Entries April 2026'!AJ35<1,"0",'Entries April 2026'!AJ36-'Entries April 2026'!AJ35) -> 0
B36: =SUM(B5:B35) -> 1751.085

Sheet Fuel 
A1: DAILY FUEL CONSUMPTION FOR APRIL 2026
A4: DATE | B4: Boiler 1 | C4: Boiler 1 | D4: Boiler 2 | E4: Boiler 2 | F4: Gen. | G4: Gen | H4: Boiler 1 sp. | I4: Boiler 2 sp. | J4: Gen. sp | K4: Daily cons. | L4: Total Prod.(HL) | M4: Fuel(Litres/HL)
B5: Cons ( l ) | C5: Hrs | D5: Cons ( l ) | E5: Hrs | F5: Cons ( l ) | G5: Hrs | H5: cons (l/hr) | I5: cons (l/hr) | J5: Cons.(l/hr) | K5: (litres)
A7: 1 | B7: =IF('Entries April 2026'!B7-'Entries April 2026'!B6<1,"0",'Entries April 2026'!B7-'Entries April 2026'!B6) -> 2700 | C7: =IF('Entries April 2026'!F7-'Entries April 2026'!F6<1,"0",'Entries April 2026'!F7-'Entries April 2026'!F6) -> 17.2 | D7: =IF('Entries April 2026'!C6=0,0,+'Entries April 2026'!C6-'Entries April 2026'!#REF!) -> 0 | E7: =IF('Entries April 2026'!G7-'Entries April 2026'!G6<1,"0",'Entries April 2026'!G7-'Entries April 2026'!G6) -> 0 | H7: =IF(C7+E7=0,"0", B7/(C7+E7)) -> 156.97674 | I7: =IF(E7=0,"0", D7/E7) -> 0 | J7: =IF(G7=0,"0", F7/G7) -> 0 | K7: =B7+D7+F7 -> 2700 | L7: {=IF(TRANSPOSE('Daily KPIs'!B9:AE9)=0,"0",TRANSPOSE('Daily KPIs'!B9:AE9))} -> 209.55 | M7: =IF(L7=0,"0",(K7/L7)) -> 12.884753
A8: 2 | B8: =IF('Entries April 2026'!B8-'Entries April 2026'!B7<1,"0",'Entries April 2026'!B8-'Entries April 2026'!B7) -> 2450 | C8: =IF('Entries April 2026'!F8-'Entries April 2026'!F7<1,"0",'Entries April 2026'!F8-'Entries April 2026'!F7) -> 17.6 | D8: =IF('Entries April 2026'!C7=0,0,+'Entries April 2026'!C7-'Entries April 2026'!C6) -> 0 | E8: =IF('Entries April 2026'!G8-'Entries April 2026'!G7<1,"0",'Entries April 2026'!G8-'Entries April 2026'!G7) -> 0 | H8: =IF(C8+E8=0,"0", B8/(C8+E8)) -> 139.20455 | I8: =IF(E8=0,"0", D8/E8) -> 0 | J8: =IF(G8=0,"0", F8/G8) -> 0 | K8: =B8+D8+F8 -> 2450 | L8: 189.288 | M8: =IF(L8=0,"0",(K8/L8)) -> 12.94324
A9: 3 | B9: =IF('Entries April 2026'!B9-'Entries April 2026'!B8<1,"0",'Entries April 2026'!B9-'Entries April 2026'!B8) -> 150 | C9: =IF('Entries April 2026'!F9-'Entries April 2026'!F8<1,"0",'Entries April 2026'!F9-'Entries April 2026'!F8) -> 1.7 | D9: =IF('Entries April 2026'!C8=0,0,+'Entries April 2026'!C8-'Entries April 2026'!C7) -> 0 | E9: =IF('Entries April 2026'!G9-'Entries April 2026'!G8<1,"0",'Entries April 2026'!G9-'Entries April 2026'!G8) -> 0 | H9: =IF(C9+E9=0,"0", B9/(C9+E9)) -> 88.235294 | I9: =IF(E9=0,"0", D9/E9) -> 0 | J9: =IF(G9=0,"0", F9/G9) -> 0 | K9: =B9+D9+F9 -> 150 | L9: 0 | M9: =IF(L9=0,"0",(K9/L9)) -> 0
A10: 4 | B10: =IF('Entries April 2026'!B10-'Entries April 2026'!B9<1,"0",'Entries April 2026'!B10-'Entries April 2026'!B9) -> 360 | C10: =IF('Entries April 2026'!F10-'Entries April 2026'!F9<1,"0",'Entries April 2026'!F10-'Entries April 2026'!F9) -> 2.5 | D10: =IF('Entries April 2026'!C11=0,0,+'Entries April 2026'!C11-'Entries April 2026'!C8) -> 0 | E10: =IF('Entries April 2026'!G10-'Entries April 2026'!G9<1,"0",'Entries April 2026'!G10-'Entries April 2026'!G9) -> 0 | H10: =IF(C10+E10=0,"0", B10/(C10+E10)) -> 144 | I10: =IF(E10=0,"0", D10/E10) -> 0 | J10: =IF(G10=0,"0", F10/G10) -> 0 | K10: =B10+D10+F10 -> 360 | L10: 0 | M10: =IF(L10=0,"0",(K10/L10)) -> 0
A11: 5 | B11: =IF('Entries April 2026'!B11-'Entries April 2026'!B10<1,"0",'Entries April 2026'!B11-'Entries April 2026'!B10) -> 0 | C11: =IF('Entries April 2026'!F11-'Entries April 2026'!F10<1,"0",'Entries April 2026'!F11-'Entries April 2026'!F10) -> 0 | D11: =IF('Entries April 2026'!C10=0,0,+'Entries April 2026'!C10-'Entries April 2026'!C11) -> 0 | E11: =IF('Entries April 2026'!G11-'Entries April 2026'!G10<1,"0",'Entries April 2026'!G11-'Entries April 2026'!G10) -> 0 | H11: =IF(C11+E11=0,"0", B11/(C11+E11)) -> 0 | I11: =IF(E11=0,"0", D11/E11) -> 0 | J11: =IF(G11=0,"0", F11/G11) -> 0 | K11: =B11+D11+F11 -> 0 | L11: 0 | M11: =IF(L11=0,"0",(K11/L11)) -> 0
A12: 6 | B12: =IF('Entries April 2026'!B12-'Entries April 2026'!B11<1,"0",'Entries April 2026'!B12-'Entries April 2026'!B11) -> 780 | C12: =IF('Entries April 2026'!F12-'Entries April 2026'!F11<1,"0",'Entries April 2026'!F12-'Entries April 2026'!F11) -> 4.6 | D12: =IF('Entries April 2026'!C12=0,0,+'Entries April 2026'!C12-'Entries April 2026'!C10) -> 0 | E12: =IF('Entries April 2026'!G12-'Entries April 2026'!G11<1,"0",'Entries April 2026'!G12-'Entries April 2026'!G11) -> 0 | H12: =IF(C12+E12=0,"0", B12/(C12+E12)) -> 169.56522 | I12: =IF(E12=0,"0", D12/E12) -> 0 | J12: =IF(G12=0,"0", F12/G12) -> 0 | K12: =B12+D12+F12 -> 780 | L12: 0 | M12: =IF(L12=0,"0",(K12/L12)) -> 0
A13: 7 | B13: =IF('Entries April 2026'!B13-'Entries April 2026'!B12<1,"0",'Entries April 2026'!B13-'Entries April 2026'!B12) -> 3230 | C13: =IF('Entries April 2026'!F13-'Entries April 2026'!F12<1,"0",'Entries April 2026'!F13-'Entries April 2026'!F12) -> 20.9 | D13: =IF('Entries April 2026'!C13=0,0,+'Entries April 2026'!C13-'Entries April 2026'!C11) -> 0 | E13: =IF('Entries April 2026'!G13-'Entries April 2026'!G12<1,"0",'Entries April 2026'!G13-'Entries April 2026'!G12) -> 0 | H13: =IF(C13+E13=0,"0", B13/(C13+E13)) -> 154.54545 | I13: =IF(E13=0,"0", D13/E13) -> 0 | J13: =IF(G13=0,"0", F13/G13) -> 0 | K13: =B13+D13+F13 -> 3230 | L13: 71.148 | M13: =IF(L13=0,"0",(K13/L13)) -> 45.398325
A14: 8 | B14: =IF('Entries April 2026'!B14-'Entries April 2026'!B13<1,"0",'Entries April 2026'!B14-'Entries April 2026'!B13) -> 2800 | C14: =IF('Entries April 2026'!F14-'Entries April 2026'!F13<1,"0",'Entries April 2026'!F14-'Entries April 2026'!F13) -> 18.9 | D14: =IF('Entries April 2026'!C13=0,0,+'Entries April 2026'!C13-'Entries April 2026'!#REF!) -> 0 | E14: =IF('Entries April 2026'!G14-'Entries April 2026'!G13<1,"0",'Entries April 2026'!G14-'Entries April 2026'!G13) -> 0 | H14: =IF(C14+E14=0,"0", B14/(C14+E14)) -> 148.14815 | I14: =IF(E14=0,"0", D14/E14) -> 0 | J14: =IF(G14=0,"0", F14/G14) -> 0 | K14: =B14+D14+F14 -> 2800 | L14: 602.778 | M14: =IF(L14=0,"0",(K14/L14)) -> 4.6451596
A15: 9 | B15: =IF('Entries April 2026'!B15-'Entries April 2026'!B14<1,"0",'Entries April 2026'!B15-'Entries April 2026'!B14) -> 3790 | C15: =IF('Entries April 2026'!F15-'Entries April 2026'!F14<1,"0",'Entries April 2026'!F15-'Entries April 2026'!F14) -> 20.4 | D15: =IF('Entries April 2026'!C14=0,0,+'Entries April 2026'!C14-'Entries April 2026'!C13) -> 0 | E15: =IF('Entries April 2026'!G15-'Entries April 2026'!G14<1,"0",'Entries April 2026'!G15-'Entries April 2026'!G14) -> 0 | H15: =IF(C15+E15=0,"0", B15/(C15+E15)) -> 185.78431 | I15: =IF(E15=0,"0", D15/E15) -> 0 | J15: =IF(G15=0,"0", F15/G15) -> 0 | K15: =B15+D15+F15 -> 3790 | L15: 651.42 | M15: =IF(L15=0,"0",(K15/L15)) -> 5.818059
A16: 10 | B16: =IF('Entries April 2026'!B16-'Entries April 2026'!B15<1,"0",'Entries April 2026'!B16-'Entries April 2026'!B15) -> 2400 | C16: =IF('Entries April 2026'!F16-'Entries April 2026'!F15<1,"0",'Entries April 2026'!F16-'Entries April 2026'!F15) -> 17.4 | D16: =IF('Entries April 2026'!C15=0,0,+'Entries April 2026'!C15-'Entries April 2026'!C14) -> 0 | E16: =IF('Entries April 2026'!G16-'Entries April 2026'!G15<1,"0",'Entries April 2026'!G16-'Entries April 2026'!G15) -> 0 | H16: =IF(C16+E16=0,"0", B16/(C16+E16)) -> 137.93103 | I16: =IF(E16=0,"0", D16/E16) -> 0 | J16: =IF(G16=0,"0", F16/G16) -> 0 | K16: =B16+D16+F16 -> 2400 | L16: 427.482 | M16: =IF(L16=0,"0",(K16/L16)) -> 5.6142715
A17: 11 | B17: =IF('Entries April 2026'!B17-'Entries April 2026'!B16<1,"0",'Entries April 2026'!B17-'Entries April 2026'!B16) -> 0 | C17: =IF('Entries April 2026'!F17-'Entries April 2026'!F16<1,"0",'Entries April 2026'!F17-'Entries April 2026'!F16) -> 0 | D17: =IF('Entries April 2026'!C16=0,0,+'Entries April 2026'!C16-'Entries April 2026'!C15) -> 0 | E17: =IF('Entries April 2026'!G17-'Entries April 2026'!G16<1,"0",'Entries April 2026'!G17-'Entries April 2026'!G16) -> 0 | H17: =IF(C17+E17=0,"0", B17/(C17+E17)) -> 0 | I17: =IF(E17=0,"0", D17/E17) -> 0 | J17: =IF(G17=0,"0", F17/G17) -> 0 | K17: =B17+D17+F17 -> 0 | L17: 0 | M17: =IF(L17=0,"0",(K17/L17)) -> 0
A18: 12 | B18: =IF('Entries April 2026'!B18-'Entries April 2026'!B17<1,"0",'Entries April 2026'!B18-'Entries April 2026'!B17) -> 700 | C18: =IF('Entries April 2026'!F18-'Entries April 2026'!F17<1,"0",'Entries April 2026'!F18-'Entries April 2026'!F17) -> 4 | D18: =IF('Entries April 2026'!C17=0,0,+'Entries April 2026'!C17-'Entries April 2026'!C16) -> 0 | E18: =IF('Entries April 2026'!G18-'Entries April 2026'!G17<1,"0",'Entries April 2026'!G18-'Entries April 2026'!G17) -> 0 | H18: =IF(C18+E18=0,"0", B18/(C18+E18)) -> 175 | I18: =IF(E18=0,"0", D18/E18) -> 0 | J18: =IF(G18=0,"0", F18/G18) -> 0 | K18: =B18+D18+F18 -> 700 | L18: 0 | M18: =IF(L18=0,"0",(K18/L18)) -> 0
A19: 13 | B19: =IF('Entries April 2026'!B19-'Entries April 2026'!B18<1,"0",'Entries April 2026'!B19-'Entries April 2026'!B18) -> 3520 | C19: =IF('Entries April 2026'!F19-'Entries April 2026'!F18<1,"0",'Entries April 2026'!F19-'Entries April 2026'!F18) -> 21 | D19: =IF('Entries April 2026'!C18=0,0,+'Entries April 2026'!C18-'Entries April 2026'!C17) -> 0 | E19: =IF('Entries April 2026'!G19-'Entries April 2026'!G18<1,"0",'Entries April 2026'!G19-'Entries April 2026'!G18) -> 0 | H19: =IF(C19+E19=0,"0", B19/(C19+E19)) -> 167.61905 | I19: =IF(E19=0,"0", D19/E19) -> 0 | J19: =IF(G19=0,"0", F19/G19) -> 0 | K19: =B19+D19+F19 -> 3520 | L19: 418.044 | M19: =IF(L19=0,"0",(K19/L19)) -> 8.4201663
A20: 14 | B20: =IF('Entries April 2026'!B20-'Entries April 2026'!B19<1,"0",'Entries April 2026'!B20-'Entries April 2026'!B19) -> 3090 | C20: =IF('Entries April 2026'!F20-'Entries April 2026'!F19<1,"0",'Entries April 2026'!F20-'Entries April 2026'!F19) -> 19.5 | D20: =IF('Entries April 2026'!C19=0,0,+'Entries April 2026'!C19-'Entries April 2026'!C18) -> 0 | E20: =IF('Entries April 2026'!G20-'Entries April 2026'!G19<1,"0",'Entries April 2026'!G20-'Entries April 2026'!G19) -> 0 | H20: =IF(C20+E20=0,"0", B20/(C20+E20)) -> 158.46154 | I20: =IF(E20=0,"0", D20/E20) -> 0 | J20: =IF(G20=0,"0", F20/G20) -> 0 | K20: =B20+D20+F20 -> 3090 | L20: 398.178 | M20: =IF(L20=0,"0",(K20/L20)) -> 7.7603484
A21: 15 | B21: =IF('Entries April 2026'!B21-'Entries April 2026'!B20<1,"0",'Entries April 2026'!B21-'Entries April 2026'!B20) -> 3370 | C21: =IF('Entries April 2026'!F21-'Entries April 2026'!F20<1,"0",'Entries April 2026'!F21-'Entries April 2026'!F20) -> 19.9 | D21: =IF('Entries April 2026'!C20=0,0,+'Entries April 2026'!C20-'Entries April 2026'!C19) -> 0 | E21: =IF('Entries April 2026'!G21-'Entries April 2026'!G20<1,"0",'Entries April 2026'!G21-'Entries April 2026'!G20) -> 0 | H21: =IF(C21+E21=0,"0", B21/(C21+E21)) -> 169.34673 | I21: =IF(E21=0,"0", D21/E21) -> 0 | J21: =IF(G21=0,"0", F21/G21) -> 0 | K21: =B21+D21+F21 -> 3370 | L21: 489.786 | M21: =IF(L21=0,"0",(K21/L21)) -> 6.880556
A22: 16 | B22: =IF('Entries April 2026'!B22-'Entries April 2026'!B21<1,"0",'Entries April 2026'!B22-'Entries April 2026'!B21) -> 3340 | C22: =IF('Entries April 2026'!F22-'Entries April 2026'!F21<1,"0",'Entries April 2026'!F22-'Entries April 2026'!F21) -> 20.5 | D22: =IF('Entries April 2026'!C21=0,0,+'Entries April 2026'!C21-'Entries April 2026'!C20) -> 0 | E22: =IF('Entries April 2026'!G22-'Entries April 2026'!G21<1,"0",'Entries April 2026'!G22-'Entries April 2026'!G21) -> 0 | H22: =IF(C22+E22=0,"0", B22/(C22+E22)) -> 162.92683 | I22: =IF(E22=0,"0", D22/E22) -> 0 | J22: =IF(G22=0,"0", F22/G22) -> 0 | K22: =B22+D22+F22 -> 3340 | L22: 622.512 | M22: =IF(L22=0,"0",(K22/L22)) -> 5.3653584
A23: 17 | B23: =IF('Entries April 2026'!B23-'Entries April 2026'!B22<1,"0",'Entries April 2026'!B23-'Entries April 2026'!B22) -> 2190 | C23: =IF('Entries April 2026'!F23-'Entries April 2026'!F22<1,"0",'Entries April 2026'!F23-'Entries April 2026'!F22) -> 14.5 | D23: =IF('Entries April 2026'!C22=0,0,+'Entries April 2026'!C22-'Entries April 2026'!C21) -> 0 | E23: =IF('Entries April 2026'!G23-'Entries April 2026'!G22<1,"0",'Entries April 2026'!G23-'Entries April 2026'!G22) -> 0 | H23: =IF(C23+E23=0,"0", B23/(C23+E23)) -> 151.03448 | I23: =IF(E23=0,"0", D23/E23) -> 0 | J23: =IF(G23=0,"0", F23/G23) -> 0 | K23: =B23+D23+F23 -> 2190 | L23: 330.594 | M23: =IF(L23=0,"0",(K23/L23)) -> 6.6244396
A24: 18 | B24: =IF('Entries April 2026'!B24-'Entries April 2026'!B23<1,"0",'Entries April 2026'!B24-'Entries April 2026'!B23) -> 0 | C24: =IF('Entries April 2026'!F24-'Entries April 2026'!F23<1,"0",'Entries April 2026'!F24-'Entries April 2026'!F23) -> 0 | D24: =IF('Entries April 2026'!C23=0,0,+'Entries April 2026'!C23-'Entries April 2026'!C22) -> 0 | E24: =IF('Entries April 2026'!G24-'Entries April 2026'!G23<1,"0",'Entries April 2026'!G24-'Entries April 2026'!G23) -> 0 | H24: =IF(C24+E24=0,"0", B24/(C24+E24)) -> 0 | I24: =IF(E24=0,"0", D24/E24) -> 0 | J24: =IF(G24=0,"0", F24/G24) -> 0 | K24: =B24+D24+F24 -> 0 | L24: 0 | M24: =IF(L24=0,"0",(K24/L24)) -> 0
A25: 19 | B25: =IF('Entries April 2026'!B25-'Entries April 2026'!B24<1,"0",'Entries April 2026'!B25-'Entries April 2026'!B24) -> 1180 | C25: =IF('Entries April 2026'!F25-'Entries April 2026'!F24<1,"0",'Entries April 2026'!F25-'Entries April 2026'!F24) -> 7.1 | D25: =IF('Entries April 2026'!C24=0,0,+'Entries April 2026'!C24-'Entries April 2026'!C23) -> 0 | E25: =IF('Entries April 2026'!G25-'Entries April 2026'!G24<1,"0",'Entries April 2026'!G25-'Entries April 2026'!G24) -> 0 | H25: =IF(C25+E25=0,"0", B25/(C25+E25)) -> 166.19718 | I25: =IF(E25=0,"0", D25/E25) -> 0 | J25: =IF(G25=0,"0", F25/G25) -> 0 | K25: =B25+D25+F25 -> 1180 | L25: 0 | M25: =IF(L25=0,"0",(K25/L25)) -> 0
A26: 20 | B26: =IF('Entries April 2026'!B26-'Entries April 2026'!B25<1,"0",'Entries April 2026'!B26-'Entries April 2026'!B25) -> 3070 | C26: =IF('Entries April 2026'!F26-'Entries April 2026'!F25<1,"0",'Entries April 2026'!F26-'Entries April 2026'!F25) -> 19.6 | D26: =IF('Entries April 2026'!C25=0,0,+'Entries April 2026'!C25-'Entries April 2026'!C24) -> 0 | E26: =IF('Entries April 2026'!G26-'Entries April 2026'!G25<1,"0",'Entries April 2026'!G26-'Entries April 2026'!G25) -> 0 | H26: =IF(C26+E26=0,"0", B26/(C26+E26)) -> 156.63265 | I26: =IF(E26=0,"0", D26/E26) -> 0 | J26: =IF(G26=0,"0", F26/G26) -> 0 | K26: =B26+D26+F26 -> 3070 | L26: 256.41 | M26: =IF(L26=0,"0",(K26/L26)) -> 11.973012
A27: 21 | B27: =IF('Entries April 2026'!B27-'Entries April 2026'!B26<1,"0",'Entries April 2026'!B27-'Entries April 2026'!B26) -> 3580 | C27: =IF('Entries April 2026'!F27-'Entries April 2026'!F26<1,"0",'Entries April 2026'!F27-'Entries April 2026'!F26) -> 20.8 | D27: =IF('Entries April 2026'!C26=0,0,+'Entries April 2026'!C26-'Entries April 2026'!C25) -> 0 | E27: =IF('Entries April 2026'!G27-'Entries April 2026'!G26<1,"0",'Entries April 2026'!G27-'Entries April 2026'!G26) -> 0 | H27: =IF(C27+E27=0,"0", B27/(C27+E27)) -> 172.11538 | I27: =IF(E27=0,"0", D27/E27) -> 0 | J27: =IF(G27=0,"0", F27/G27) -> 0 | K27: =B27+D27+F27 -> 3580 | L27: 521.466 | M27: =IF(L27=0,"0",(K27/L27)) -> 6.8652606
A28: 22 | B28: =IF('Entries April 2026'!B28-'Entries April 2026'!B27<1,"0",'Entries April 2026'!B28-'Entries April 2026'!B27) -> 3550 | C28: =IF('Entries April 2026'!F28-'Entries April 2026'!F27<1,"0",'Entries April 2026'!F28-'Entries April 2026'!F27) -> 21.5 | D28: =IF('Entries April 2026'!C27=0,0,+'Entries April 2026'!C27-'Entries April 2026'!C26) -> 0 | E28: =IF('Entries April 2026'!G28-'Entries April 2026'!G27<1,"0",'Entries April 2026'!G28-'Entries April 2026'!G27) -> 0 | H28: =IF(C28+E28=0,"0", B28/(C28+E28)) -> 165.11628 | I28: =IF(E28=0,"0", D28/E28) -> 0 | J28: =IF(G28=0,"0", F28/G28) -> 0 | K28: =B28+D28+F28 -> 3550 | L28: 517.308 | M28: =IF(L28=0,"0",(K28/L28)) -> 6.8624494
A29: 23 | B29: =IF('Entries April 2026'!B29-'Entries April 2026'!B28<1,"0",'Entries April 2026'!B29-'Entries April 2026'!B28) -> 2580 | C29: =IF('Entries April 2026'!F29-'Entries April 2026'!F28<1,"0",'Entries April 2026'!F29-'Entries April 2026'!F28) -> 17.1 | D29: =IF('Entries April 2026'!C28=0,0,+'Entries April 2026'!C28-'Entries April 2026'!C27) -> 0 | E29: =IF('Entries April 2026'!G29-'Entries April 2026'!G28<1,"0",'Entries April 2026'!G29-'Entries April 2026'!G28) -> 0 | H29: =IF(C29+E29=0,"0", B29/(C29+E29)) -> 150.87719 | I29: =IF(E29=0,"0", D29/E29) -> 0 | J29: =IF(G29=0,"0", F29/G29) -> 0 | K29: =B29+D29+F29 -> 2580 | L29: 241.692 | M29: =IF(L29=0,"0",(K29/L29)) -> 10.674743
A30: 24 | B30: =IF('Entries April 2026'!B30-'Entries April 2026'!B29<1,"0",'Entries April 2026'!B30-'Entries April 2026'!B29) -> 2520 | C30: =IF('Entries April 2026'!F30-'Entries April 2026'!F29<1,"0",'Entries April 2026'!F30-'Entries April 2026'!F29) -> 15.8 | D30: =IF('Entries April 2026'!C29=0,0,+'Entries April 2026'!C29-'Entries April 2026'!C28) -> 0 | E30: =IF('Entries April 2026'!G30-'Entries April 2026'!G29<1,"0",'Entries April 2026'!G30-'Entries April 2026'!G29) -> 0 | H30: =IF(C30+E30=0,"0", B30/(C30+E30)) -> 159.49367 | I30: =IF(E30=0,"0", D30/E30) -> 0 | J30: =IF(G30=0,"0", F30/G30) -> 0 | K30: =B30+D30+F30 -> 2520 | L30: 224.334 | M30: =IF(L30=0,"0",(K30/L30)) -> 11.23325
A31: 25 | B31: =IF('Entries April 2026'!B31-'Entries April 2026'!B30<1,"0",'Entries April 2026'!B31-'Entries April 2026'!B30) -> 1290 | C31: =IF('Entries April 2026'!F31-'Entries April 2026'!F30<1,"0",'Entries April 2026'!F31-'Entries April 2026'!F30) -> 10.5 | D31: =IF('Entries April 2026'!C30=0,0,+'Entries April 2026'!C30-'Entries April 2026'!C29) -> 0 | E31: =IF('Entries April 2026'!G31-'Entries April 2026'!G30<1,"0",'Entries April 2026'!G31-'Entries April 2026'!G30) -> 0 | H31: =IF(C31+E31=0,"0", B31/(C31+E31)) -> 122.85714 | I31: =IF(E31=0,"0", D31/E31) -> 0 | J31: =IF(G31=0,"0", F31/G31) -> 0 | K31: =B31+D31+F31 -> 1290 | L31: 0 | M31: =IF(L31=0,"0",(K31/L31)) -> 0
A32: 26 | B32: =IF('Entries April 2026'!B32-'Entries April 2026'!B31<1,"0",'Entries April 2026'!B32-'Entries April 2026'!B31) -> 1200 | C32: =IF('Entries April 2026'!F32-'Entries April 2026'!F31<1,"0",'Entries April 2026'!F32-'Entries April 2026'!F31) -> 8.3 | D32: =IF('Entries April 2026'!C31=0,0,+'Entries April 2026'!C31-'Entries April 2026'!C30) -> 0 | E32: =IF('Entries April 2026'!G32-'Entries April 2026'!G31<1,"0",'Entries April 2026'!G32-'Entries April 2026'!G31) -> 0 | H32: =IF(C32+E32=0,"0", B32/(C32+E32)) -> 144.57831 | I32: =IF(E32=0,"0", D32/E32) -> 0 | J32: =IF(G32=0,"0", F32/G32) -> 0 | K32: =B32+D32+F32 -> 1200 | L32: 0 | M32: =IF(L32=0,"0",(K32/L32)) -> 0
A33: 27 | B33: =IF('Entries April 2026'!B33-'Entries April 2026'!B32<1,"0",'Entries April 2026'!B33-'Entries April 2026'!B32) -> 3290 | C33: =IF('Entries April 2026'!F33-'Entries April 2026'!F32<1,"0",'Entries April 2026'!F33-'Entries April 2026'!F32) -> 20.7 | D33: =IF('Entries April 2026'!C32=0,0,+'Entries April 2026'!C32-'Entries April 2026'!C31) -> 0 | E33: =IF('Entries April 2026'!G33-'Entries April 2026'!G32<1,"0",'Entries April 2026'!G33-'Entries April 2026'!G32) -> 0 | H33: =IF(C33+E33=0,"0", B33/(C33+E33)) -> 158.9372 | I33: =IF(E33=0,"0", D33/E33) -> 0 | J33: =IF(G33=0,"0", F33/G33) -> 0 | K33: =B33+D33+F33 -> 3290 | L33: 390.456 | M33: =IF(L33=0,"0",(K33/L33)) -> 8.4260454
A34: 28 | B34: =IF('Entries April 2026'!B34-'Entries April 2026'!B33<1,"0",'Entries April 2026'!B34-'Entries April 2026'!B33) -> 3050 | C34: =IF('Entries April 2026'!F34-'Entries April 2026'!F33<1,"0",'Entries April 2026'!F34-'Entries April 2026'!F33) -> 19.3 | D34: =IF('Entries April 2026'!C33=0,0,+'Entries April 2026'!C33-'Entries April 2026'!C32) -> 0 | E34: =IF('Entries April 2026'!G34-'Entries April 2026'!G33<1,"0",'Entries April 2026'!G34-'Entries April 2026'!G33) -> 0 | H34: =IF(C34+E34=0,"0", B34/(C34+E34)) -> 158.03109 | I34: =IF(E34=0,"0", D34/E34) -> 0 | J34: =IF(G34=0,"0", F34/G34) -> 0 | K34: =B34+D34+F34 -> 3050 | L34: 452.496 | M34: =IF(L34=0,"0",(K34/L34)) -> 6.7403911
A35: 29 | B35: =IF('Entries April 2026'!B35-'Entries April 2026'!B34<1,"0",'Entries April 2026'!B35-'Entries April 2026'!B34) -> 3140 | C35: =IF('Entries April 2026'!F35-'Entries April 2026'!F34<1,"0",'Entries April 2026'!F35-'Entries April 2026'!F34) -> 20.7 | E35: =IF('Entries April 2026'!G35-'Entries April 2026'!G34<1,"0",'Entries April 2026'!G35-'Entries April 2026'!G34) -> 0 | H35: =IF(C35+E35=0,"0", B35/(C35+E35)) -> 151.69082 | I35: =IF(E35=0,"0", D35/E35) -> 0 | J35: =IF(G35=0,"0", F35/G35) -> 0 | K35: =B35+D35+F35 -> 3140 | L35: 570.174 | M35: =IF(L35=0,"0",(K35/L35)) -> 5.5070908
A36: 30 | B36: =IF('Entries April 2026'!B36-'Entries April 2026'!B35<1,"0",'Entries April 2026'!B36-'Entries April 2026'!B35) -> 3130 | C36: =IF('Entries April 2026'!F36-'Entries April 2026'!F35<1,"0",'Entries April 2026'!F36-'Entries April 2026'!F35) -> 19.3 | E36: =IF('Entries April 2026'!G36-'Entries April 2026'!G35<1,"0",'Entries April 2026'!G36-'Entries April 2026'!G35) -> 0 | H36: =IF(C36+E36=0,"0", B36/(C36+E36)) -> 162.17617 | I36: =IF(E36=0,"0", D36/E36) -> 0 | J36: =IF(G36=0,"0", F36/G36) -> 0 | K36: =B36+D36+F36 -> 3130 | L36: 407.748 | M36: =IF(L36=0,"0",(K36/L36)) -> 7.6763099
B37: =IF('Entries April 2026'!B37-'Entries April 2026'!B36<1,"0",'Entries April 2026'!B37-'Entries April 2026'!B36) -> 0 | C37: =IF('Entries April 2026'!F37-'Entries April 2026'!F36<1,"0",'Entries April 2026'!F37-'Entries April 2026'!F36) -> 0 | E37: =IF('Entries April 2026'!G37-'Entries April 2026'!G36<1,"0",'Entries April 2026'!G37-'Entries April 2026'!G36) -> 0 | H37: =IF(C37+E37=0,"0", B37/(C37+E37)) -> 0 | I37: =IF(E37=0,"0", D37/E37) -> 0 | J37: =IF(G37=0,"0", F37/G37) -> 0 | K37: =B37+D37+F37 -> 0
B38: =SUM(B7:B36) -> 66450 | C38: =SUM(C7:C36) -> 421.3 | M38: =IF(L38=0,"0",(K38/L38)) -> 0 | N38: 7.2 | O38: =M38/N38*100 -> 0
A39: AVE. | B39: =AVERAGE(B7:B37) -> 2461.1111 | C39: =AVERAGE(C7:C37) -> 15.603704 | H39: cons (l/hr)

Sheet Water 
B4: DATE | C4: Well Supply (m3) | D4: Nawasa Supply (m3) | E4: Annanale Supply (m3) | F4: RO Water Plant Nawasa (m3) | G4: Service Water Received (m3) | H4: Service Water Supply to Plant (m3) | I4: CO2 Scrubber (m3) | J4: Brewhouse / Old Pepsi Area (m3) | K4: Filtration/Cellars (m3) | L4: Cellars/Process Area (m3) | M4: Pasteuriser (m3) | R4: Permeate Produced (m3) | S4: Plant Cons. USAGE (Hl.) | U4: Bottle Filler (m3) | X4: Rus (m3) | Y4: Washdown Area (m3) | Z4: TOTAL SUPPLY (M3) | AA4: Total Prod.(HL) | AB4: Water KPI (Hl/Hl)
N5: CIP Process (m3) | O5: Bottles Washer (m3) | P5: Bottles Filler (m3) | Q5: Boiler Supply (m3) | T5: ∑ Service Water to Processes | V5: Water into RO #1 (m3) | W5: Water into RO #2 (m3)
B6: -
B7: 1 | C7: =IF('Entries April 2026'!W7-'Entries April 2026'!W6<1,"0",'Entries April 2026'!W7-'Entries April 2026'!W6) -> 0 | D7: =IF('Entries April 2026'!O7-'Entries April 2026'!O6<1,"0",'Entries April 2026'!O7-'Entries April 2026'!O6) -> 207 | E7: =IF('Entries April 2026'!P7-'Entries April 2026'!P6<1,"0",'Entries April 2026'!P7-'Entries April 2026'!P6) -> 156 | F7: =IF('Entries April 2026'!V7-'Entries April 2026'!V6<1,"0",'Entries April 2026'!V7-'Entries April 2026'!V6) -> 164 | G7: =(D7+E7)-F7 -> 199 | H7: =IF('Entries April 2026'!Q7-'Entries April 2026'!Q6<1,0,'Entries April 2026'!Q7-'Entries April 2026'!Q6) -> 211 | I7: =IF('Entries April 2026'!AG7-'Entries April 2026'!AG6<1,0,'Entries April 2026'!AG7-'Entries April 2026'!AG6) -> 0 | J7: =IF('Entries April 2026'!S7-'Entries April 2026'!S6<1,"0",'Entries April 2026'!S7-'Entries April 2026'!S6) -> 96 | K7: =IF('Entries April 2026'!R7-'Entries April 2026'!R6<1,"0",'Entries April 2026'!R7-'Entries April 2026'!R6) -> 0 | L7: =IF('Entries April 2026'!T7-'Entries April 2026'!T6<1,"0",'Entries April 2026'!T7-'Entries April 2026'!T6) -> 0 | M7: =IF('Entries April 2026'!U7-'Entries April 2026'!U6<1,"0",'Entries April 2026'!U7-'Entries April 2026'!U6) -> 2 | N7: =IF('Entries April 2026'!X7-'Entries April 2026'!X6<1,"0",'Entries April 2026'!X7-'Entries April 2026'!X6) -> 68 | O7: =IF('Entries April 2026'!Y7-'Entries April 2026'!Y6<1,"0",'Entries April 2026'!Y7-'Entries April 2026'!Y6) -> 60 | P7: =IF('Entries April 2026'!AC7-'Entries April 2026'!AC6<1,"0",'Entries April 2026'!AC7-'Entries April 2026'!AC6) -> 13 | Q7: =IF('Entries April 2026'!Z7-'Entries April 2026'!Z6<1,"0",'Entries April 2026'!Z7-'Entries April 2026'!Z6) -> 13 | R7: =IF(('Entries April 2026'!AA7-'Entries April 2026'!AA6)+('Entries April 2026'!AB7-'Entries April 2026'!AB6)<1,"0",('Entries April 2026'!AA7-'Entries April 2026'!AA6)+('Entries April 2026'!AB7-'Entries April 2026'!AB6)) -> 0 | S7: =(R7+G7)*10 -> 1990 | T7: =O7+N7+M7+L7 -> 130 | U7: =IF('Entries April 2026'!AC7-'Entries April 2026'!AC6<1,"0",'Entries April 2026'!AC7-'Entries April 2026'!AC6) -> 13 | V7: =IF('Entries April 2026'!AD7-'Entries April 2026'!AD6<1,"0",'Entries April 2026'!AD7-'Entries April 2026'!AD6) -> 26 | W7: =IF('Entries April 2026'!AE7-'Entries April 2026'!AE6<1,"0",'Entries April 2026'!AE7-'Entries April 2026'!AE6) -> 0 | X7: =IF('Entries April 2026'!AI7-'Entries April 2026'!AI6<1,"0",'Entries April 2026'!AI7-'Entries April 2026'!AI6) -> 0 | Y7: =IF('Entries April 2026'!AH7-'Entries April 2026'!AH6<1,"0",'Entries April 2026'!AH7-'Entries April 2026'!AH6) -> 0 | Z7: =C7+D7+E7 -> 363 | AA7: {=IF(TRANSPOSE('Daily KPIs'!B9:AE9)=0,"0",TRANSPOSE('Daily KPIs'!B9:AE9))} -> 209.55 | AB7: =IF(AA7=0,"0",(Z7*10/AA7)) -> 17.322835
B8: 2 | C8: =IF('Entries April 2026'!W8-'Entries April 2026'!W7<1,"0",'Entries April 2026'!W8-'Entries April 2026'!W7) -> 0 | D8: =IF('Entries April 2026'!O8-'Entries April 2026'!O7<1,"0",'Entries April 2026'!O8-'Entries April 2026'!O7) -> 124 | E8: =IF('Entries April 2026'!P8-'Entries April 2026'!P7<1,"0",'Entries April 2026'!P8-'Entries April 2026'!P7) -> 168 | F8: =IF('Entries April 2026'!V8-'Entries April 2026'!V7<1,"0",'Entries April 2026'!V8-'Entries April 2026'!V7) -> 177 | G8: =(D8+E8)-F8 -> 115 | H8: =IF('Entries April 2026'!Q8-'Entries April 2026'!Q7<1,0,'Entries April 2026'!Q8-'Entries April 2026'!Q7) -> 166 | I8: =IF('Entries April 2026'!AG8-'Entries April 2026'!AG7<1,0,'Entries April 2026'!AG8-'Entries April 2026'!AG7) -> 0 | J8: =IF('Entries April 2026'!S8-'Entries April 2026'!S7<1,"0",'Entries April 2026'!S8-'Entries April 2026'!S7) -> 76 | K8: =IF('Entries April 2026'!R8-'Entries April 2026'!R7<1,"0",'Entries April 2026'!R8-'Entries April 2026'!R7) -> 0 | L8: =IF('Entries April 2026'!T8-'Entries April 2026'!T7<1,"0",'Entries April 2026'!T8-'Entries April 2026'!T7) -> 0 | M8: =IF('Entries April 2026'!U8-'Entries April 2026'!U7<1,"0",'Entries April 2026'!U8-'Entries April 2026'!U7) -> 2 | N8: =IF('Entries April 2026'!X8-'Entries April 2026'!X7<1,"0",'Entries April 2026'!X8-'Entries April 2026'!X7) -> 23 | O8: =IF('Entries April 2026'!Y8-'Entries April 2026'!Y7<1,"0",'Entries April 2026'!Y8-'Entries April 2026'!Y7) -> 57 | P8: =IF('Entries April 2026'!AC8-'Entries April 2026'!AC7<1,"0",'Entries April 2026'!AC8-'Entries April 2026'!AC7) -> 21 | Q8: =IF('Entries April 2026'!Z8-'Entries April 2026'!Z7<1,"0",'Entries April 2026'!Z8-'Entries April 2026'!Z7) -> 4 | R8: =IF(('Entries April 2026'!AA8-'Entries April 2026'!AA7)+('Entries April 2026'!AB8-'Entries April 2026'!AB7)<1,"0",('Entries April 2026'!AA8-'Entries April 2026'!AA7)+('Entries April 2026'!AB8-'Entries April 2026'!AB7)) -> 0 | S8: =(R8+G8)*10 -> 1150 | T8: =O8+N8+M8+L8 -> 82 | U8: =IF('Entries April 2026'!AC8-'Entries April 2026'!AC7<1,"0",'Entries April 2026'!AC8-'Entries April 2026'!AC7) -> 21 | V8: =IF('Entries April 2026'!AD8-'Entries April 2026'!AD7<1,"0",'Entries April 2026'!AD8-'Entries April 2026'!AD7) -> 0 | W8: =IF('Entries April 2026'!AE8-'Entries April 2026'!AE7<1,"0",'Entries April 2026'!AE8-'Entries April 2026'!AE7) -> 0 | X8: =IF('Entries April 2026'!AI8-'Entries April 2026'!AI7<1,"0",'Entries April 2026'!AI8-'Entries April 2026'!AI7) -> 0 | Y8: =IF('Entries April 2026'!AH8-'Entries April 2026'!AH7<1,"0",'Entries April 2026'!AH8-'Entries April 2026'!AH7) -> 0 | Z8: =C8+D8+E8 -> 292 | AA8: 189.288 | AB8: =IF(AA8=0,"0",(Z8*10/AA8)) -> 15.426229
B9: 3 | C9: =IF('Entries April 2026'!W9-'Entries April 2026'!W8<1,"0",'Entries April 2026'!W9-'Entries April 2026'!W8) -> 0 | D9: =IF('Entries April 2026'!O9-'Entries April 2026'!O8<1,"0",'Entries April 2026'!O9-'Entries April 2026'!O8) -> 0 | E9: =IF('Entries April 2026'!P9-'Entries April 2026'!P8<1,"0",'Entries April 2026'!P9-'Entries April 2026'!P8) -> 0 | F9: =IF('Entries April 2026'!V9-'Entries April 2026'!V8<1,"0",'Entries April 2026'!V9-'Entries April 2026'!V8) -> 0 | G9: =(D9+E9)-F9 -> 0 | H9: =IF('Entries April 2026'!Q9-'Entries April 2026'!Q8<1,0,'Entries April 2026'!Q9-'Entries April 2026'!Q8) -> 13 | I9: =IF('Entries April 2026'!AG9-'Entries April 2026'!AG8<1,0,'Entries April 2026'!AG9-'Entries April 2026'!AG8) -> 0 | J9: =IF('Entries April 2026'!S9-'Entries April 2026'!S8<1,"0",'Entries April 2026'!S9-'Entries April 2026'!S8) -> 0 | K9: =IF('Entries April 2026'!R9-'Entries April 2026'!R8<1,"0",'Entries April 2026'!R9-'Entries April 2026'!R8) -> 0 | L9: =IF('Entries April 2026'!T9-'Entries April 2026'!T8<1,"0",'Entries April 2026'!T9-'Entries April 2026'!T8) -> 0 | M9: =IF('Entries April 2026'!U9-'Entries April 2026'!U8<1,"0",'Entries April 2026'!U9-'Entries April 2026'!U8) -> 0 | N9: =IF('Entries April 2026'!X9-'Entries April 2026'!X8<1,"0",'Entries April 2026'!X9-'Entries April 2026'!X8) -> 0 | O9: =IF('Entries April 2026'!Y9-'Entries April 2026'!Y8<1,"0",'Entries April 2026'!Y9-'Entries April 2026'!Y8) -> 0 | P9: =IF('Entries April 2026'!AC9-'Entries April 2026'!AC8<1,"0",'Entries April 2026'!AC9-'Entries April 2026'!AC8) -> 0 | Q9: =IF('Entries April 2026'!Z9-'Entries April 2026'!Z8<1,"0",'Entries April 2026'!Z9-'Entries April 2026'!Z8) -> 17 | R9: =IF(('Entries April 2026'!AA9-'Entries April 2026'!AA8)+('Entries April 2026'!AB9-'Entries April 2026'!AB8)<1,"0",('Entries April 2026'!AA9-'Entries April 2026'!AA8)+('Entries April 2026'!AB9-'Entries April 2026'!AB8)) -> 0 | S9: =(R9+G9)*10 -> 0 | T9: =O9+N9+M9+L9 -> 0 | U9: =IF('Entries April 2026'!AC9-'Entries April 2026'!AC8<1,"0",'Entries April 2026'!AC9-'Entries April 2026'!AC8) -> 0 | V9: =IF('Entries April 2026'!AD9-'Entries April 2026'!AD8<1,"0",'Entries April 2026'!AD9-'Entries April 2026'!AD8) -> 0 | W9: =IF('Entries April 2026'!AE9-'Entries April 2026'!AE8<1,"0",'Entries April 2026'!AE9-'Entries April 2026'!AE8) -> 0 | X9: =IF('Entries April 2026'!AI9-'Entries April 2026'!AI8<1,"0",'Entries April 2026'!AI9-'Entries April 2026'!AI8) -> 0 | Y9: =IF('Entries April 2026'!AH9-'Entries April 2026'!AH8<1,"0",'Entries April 2026'!AH9-'Entries April 2026'!AH8) -> 0 | Z9: =C9+D9+E9 -> 0 | AA9: 0 | AB9: =IF(AA9=0,"0",(Z9*10/AA9)) -> 0
