Workbook
Name ProductList: [1]November15!$R$3:$R$9
Name ProductList: [2]November15!$R$3:$R$9

Sheet Dec 18th
T1: P.G. | V1: Hot Time | X1: Process Time | Z1: Cooling Time
B2: Brewing Department Daily Process Loss Report | T2: Lower | U2: Upper | V2: Lower | W2: Upper | X2: Lower | Y2: Upper | Z2: Lower | AA2: Upper
S3: CARIB | T3: 11.6 | U3: 12 | V3: 0 | W3: 0.11805556 | X3: 0.17361111 | Y3: 0.21180556 | Z3: 0 | AA3: 60 | AC3: HR- PISNER
B4: Date: | C4: 45278 | J4: LOT WORT COLOUR: 3.4 | M4: Filter Sheets (Target 20 days) | S4: STAG | T4: 11.6 | U4: 12 | V4: 0 | W4: 0.11805556 | X4: 0.17361111 | Y4: 0.21180556 | Z4: 0 | AA4: 60
M5: Double | N5: Single | S5: GUINNESS | T5: 17 | U5: 17.5 | V5: 0 | W5: 0.10763889 | X5: 0.19444444 | Y5: 0.23263889 | Z5: 0 | AA5: 60
J6: MALT LOT: Lot 8 | L6: Sheet Day | S6: MACKESON | T6: 13.3 | U6: 13.5 | V6: 0 | W6: 0.12905093 | X6: 0.22222222 | Y6: 0.25347222 | Z6: 0
S7: STARMALT | T7: 17.1 | U7: 17.5 | V7: 0 | W7: 0.13605324 | X7: 0.20833333 | Y7: 0.24305556 | Z7: 0 | AA7: 60
B8: Brand | C8: Brew no. | D8: Kett. Hls | E8: Wort | F8: Cool Time(Mins) | G8: Cast. P.G. (Lab Result) | H8: Cast P.G. (Cellar Operator)-gravity | I8: Extr. Rec (79.1%) | J8: Theor. Extr. (77.5%) | K8: Boil Off /Vol. (4-6%) | L8: Boil Time | M8: Total Hot | N8: Brewing | P8: Comments | Q8: Actual Pilsen Malt | S8: Hurricane Reef | T8: 16.6 | U8: 17 | V8: 0 | W8: 0.12905093 | X8: 0.22222222 | Y8: 0.25347222 | Z8: 0
E9: Meter (Hls) | F9: Target(< 60Mins) | M9: Time | S9: VITAMALT | T9: 14.4 | U9: 14.6 | V9: 0 | W9: 0.13905093 | X9: 0.19097222 | Y9: 0.22569444 | Z9: 0 | AA9: 75
S10: =B10 -> 0 | T10: =VLOOKUP($B10,$S$3:$Y$9,2,FALSE) -> #N/A | U10: =VLOOKUP($B10,$S$3:$Y$9,3,FALSE) -> #N/A | V10: =VLOOKUP($B10,$S$3:$Y$9,4,FALSE) -> #N/A | W10: =VLOOKUP($B10,$S$3:$Y$9,5,FALSE) -> #N/A | X10: =VLOOKUP($B10,$S$3:$Y$9,6,FALSE) -> #N/A | Y10: =VLOOKUP($B10,$S$3:$Y$9,7,FALSE) -> #N/A | Z10: =VLOOKUP($B10,$S$3:$AA$9,8,FALSE) -> #N/A | AA10: =VLOOKUP($B10,$S$3:$AA$9,9,FALSE) -> #N/A
S11: =B11 -> 0 | T11: =VLOOKUP($B11,$S$3:$Y$9,2,FALSE) -> #N/A | U11: =VLOOKUP($B11,$S$3:$Y$9,3,FALSE) -> #N/A | V11: =VLOOKUP($B11,$S$3:$Y$9,4,FALSE) -> #N/A | W11: =VLOOKUP($B11,$S$3:$Y$9,5,FALSE) -> #N/A | X11: =VLOOKUP($B11,$S$3:$Y$9,6,FALSE) -> #N/A | Y11: =VLOOKUP($B11,$S$3:$Y$9,7,FALSE) -> #N/A | Z11: =VLOOKUP($B11,$S$3:$AA$9,8,FALSE) -> #N/A | AA11: =VLOOKUP($B11,$S$3:$AA$9,9,FALSE) -> #N/A
S12: =B12 -> 0 | T12: =VLOOKUP($B12,$S$3:$Y$9,2,FALSE) -> #N/A | U12: =VLOOKUP($B12,$S$3:$Y$9,3,FALSE) -> #N/A | V12: =VLOOKUP($B12,$S$3:$Y$9,4,FALSE) -> #N/A | W12: =VLOOKUP($B12,$S$3:$Y$9,5,FALSE) -> #N/A | X12: =VLOOKUP($B12,$S$3:$Y$9,6,FALSE) -> #N/A | Y12: =VLOOKUP($B12,$S$3:$Y$9,7,FALSE) -> #N/A | Z12: =VLOOKUP($B12,$S$3:$AA$9,8,FALSE) -> #N/A | AA12: =VLOOKUP($B12,$S$3:$AA$9,9,FALSE) -> #N/A
S13: =B13 -> 0 | T13: =VLOOKUP($B13,$S$3:$Y$9,2,FALSE) -> #N/A | U13: =VLOOKUP($B13,$S$3:$Y$9,3,FALSE) -> #N/A | V13: =VLOOKUP($B13,$S$3:$Y$9,4,FALSE) -> #N/A | W13: =VLOOKUP($B13,$S$3:$Y$9,5,FALSE) -> #N/A | X13: =VLOOKUP($B13,$S$3:$Y$9,6,FALSE) -> #N/A | Y13: =VLOOKUP($B13,$S$3:$Y$9,7,FALSE) -> #N/A | Z13: =VLOOKUP($B13,$S$3:$AA$9,8,FALSE) -> #N/A | AA13: =VLOOKUP($B13,$S$3:$AA$9,9,FALSE) -> #N/A
S14: =B14 -> 0 | T14: =VLOOKUP($B14,$S$3:$Y$9,2,FALSE) -> #N/A | U14: =VLOOKUP($B14,$S$3:$Y$9,3,FALSE) -> #N/A | V14: =VLOOKUP($B14,$S$3:$Y$9,4,FALSE) -> #N/A | W14: =VLOOKUP($B14,$S$3:$Y$9,5,FALSE) -> #N/A | X14: =VLOOKUP($B14,$S$3:$Y$9,6,FALSE) -> #N/A | Y14: =VLOOKUP($B14,$S$3:$Y$9,7,FALSE) -> #N/A | Z14: =VLOOKUP($B14,$S$3:$AA$9,8,FALSE) -> #N/A | AA14: =VLOOKUP($B14,$S$3:$AA$9,9,FALSE) -> #N/A
S15: =B15 -> 0 | T15: =VLOOKUP($B15,$S$3:$Y$9,2,FALSE) -> #N/A | U15: =VLOOKUP($B15,$S$3:$Y$9,3,FALSE) -> #N/A | V15: =VLOOKUP($B15,$S$3:$Y$9,4,FALSE) -> #N/A | W15: =VLOOKUP($B15,$S$3:$Y$9,5,FALSE) -> #N/A | X15: =VLOOKUP($B15,$S$3:$Y$9,6,FALSE) -> #N/A | Y15: =VLOOKUP($B15,$S$3:$Y$9,7,FALSE) -> #N/A | Z15: =VLOOKUP($B15,$S$3:$AA$9,8,FALSE) -> #N/A | AA15: =VLOOKUP($B15,$S$3:$AA$9,9,FALSE) -> #N/A
S16: =B16 -> 0 | T16: =VLOOKUP($B16,$S$3:$Y$9,2,FALSE) -> #N/A | U16: =VLOOKUP($B16,$S$3:$Y$9,3,FALSE) -> #N/A | V16: =VLOOKUP($B16,$S$3:$Y$9,4,FALSE) -> #N/A | W16: =VLOOKUP($B16,$S$3:$Y$9,5,FALSE) -> #N/A | X16: =VLOOKUP($B16,$S$3:$Y$9,6,FALSE) -> #N/A | Y16: =VLOOKUP($B16,$S$3:$Y$9,7,FALSE) -> #N/A | Z16: =VLOOKUP($B16,$S$3:$AA$9,8,FALSE) -> #N/A | AA16: =VLOOKUP($B16,$S$3:$AA$9,9,FALSE) -> #N/A
S17: =B17 -> 0 | T17: =VLOOKUP($B17,$S$3:$Y$9,2,FALSE) -> #N/A | U17: =VLOOKUP($B17,$S$3:$Y$9,3,FALSE) -> #N/A | V17: =VLOOKUP($B17,$S$3:$Y$9,4,FALSE) -> #N/A | W17: =VLOOKUP($B17,$S$3:$Y$9,5,FALSE) -> #N/A | X17: =VLOOKUP($B17,$S$3:$Y$9,6,FALSE) -> #N/A | Y17: =VLOOKUP($B17,$S$3:$Y$9,7,FALSE) -> #N/A | Z17: =VLOOKUP($B17,$S$3:$AA$9,8,FALSE) -> #N/A | AA17: =VLOOKUP($B17,$S$3:$AA$9,9,FALSE) -> #N/A
S18: =B18 -> 0 | T18: =VLOOKUP($B18,$S$3:$Y$9,2,FALSE) -> #N/A | U18: =VLOOKUP($B18,$S$3:$Y$9,3,FALSE) -> #N/A | V18: =VLOOKUP($B18,$S$3:$Y$9,4,FALSE) -> #N/A | W18: =VLOOKUP($B18,$S$3:$Y$9,5,FALSE) -> #N/A | X18: =VLOOKUP($B18,$S$3:$Y$9,6,FALSE) -> #N/A | Y18: =VLOOKUP($B18,$S$3:$Y$9,7,FALSE) -> #N/A | Z18: =VLOOKUP($B18,$S$3:$AA$9,8,FALSE) -> #N/A | AA18: =VLOOKUP($B18,$S$3:$AA$9,9,FALSE) -> #N/A
S19: =B19 -> 0 | T19: =VLOOKUP($B19,$S$3:$Y$9,2,FALSE) -> #N/A | U19: =VLOOKUP($B19,$S$3:$Y$9,3,FALSE) -> #N/A | V19: =VLOOKUP($B19,$S$3:$Y$9,4,FALSE) -> #N/A | W19: =VLOOKUP($B19,$S$3:$Y$9,5,FALSE) -> #N/A | X19: =VLOOKUP($B19,$S$3:$Y$9,6,FALSE) -> #N/A | Y19: =VLOOKUP($B19,$S$3:$Y$9,7,FALSE) -> #N/A | Z19: =VLOOKUP($B19,$S$3:$AA$9,8,FALSE) -> #N/A | AA19: =VLOOKUP($B19,$S$3:$AA$9,9,FALSE) -> #N/A
S20: =B20 -> 0 | T20: =VLOOKUP($B20,$S$3:$Y$9,2,FALSE) -> #N/A | U20: =VLOOKUP($B20,$S$3:$Y$9,3,FALSE) -> #N/A | V20: =VLOOKUP($B20,$S$3:$Y$9,4,FALSE) -> #N/A | W20: =VLOOKUP($B20,$S$3:$Y$9,5,FALSE) -> #N/A | X20: =VLOOKUP($B20,$S$3:$Y$9,6,FALSE) -> #N/A | Y20: =VLOOKUP($B20,$S$3:$Y$9,7,FALSE) -> #N/A | Z20: =VLOOKUP($B20,$S$3:$AA$9,8,FALSE) -> #N/A | AA20: =VLOOKUP($B20,$S$3:$AA$9,9,FALSE) -> #N/A
S21: =B21 -> 0 | T21: =VLOOKUP($B21,$S$3:$Y$9,2,FALSE) -> #N/A | U21: =VLOOKUP($B21,$S$3:$Y$9,3,FALSE) -> #N/A | V21: =VLOOKUP($B21,$S$3:$Y$9,4,FALSE) -> #N/A | W21: =VLOOKUP($B21,$S$3:$Y$9,5,FALSE) -> #N/A | X21: =VLOOKUP($B21,$S$3:$Y$9,6,FALSE) -> #N/A | Y21: =VLOOKUP($B21,$S$3:$Y$9,7,FALSE) -> #N/A | Z21: =VLOOKUP($B21,$S$3:$AA$9,8,FALSE) -> #N/A | AA21: =VLOOKUP($B21,$S$3:$AA$9,9,FALSE) -> #N/A
... S47: =B47 -> 0 | T47: =VLOOKUP($B47,$S$3:$Y$9,2,FALSE) -> #N/A | U47: =VLOOKUP($B47,$S$3:$Y$9,3,FALSE) -> #N/A | V47: =VLOOKUP($B47,$S$3:$Y$9,4,FALSE) -> #N/A | W47: =VLOOKUP($B47,$S$3:$Y$9,5,FALSE) -> #N/A | X47: =VLOOKUP($B47,$S$3:$Y$9,6,FALSE) -> #N/A | Y47: =VLOOKUP($B47,$S$3:$Y$9,7,FALSE) -> #N/A | Z47: =VLOOKUP($B47,$S$3:$AA$9,8,FALSE) -> #N/A | AA47: =VLOOKUP($B47,$S$3:$AA$9,9,FALSE) -> #N/A
I48: EXTRACT RECOVERY
B49: BRAND | D49: BBT P.G./ O.G | I49: Brand | J49: Actual | K49: MTD No. of Brews | L49: MTD | M49: YTD | N49: Target
B50: STAG | C50: 11.8 | D50: 11.73 | I50: CARIB | K50: =COUNTA([3]Brewhouse!$A$1596:$A$1619) -> 24 | L50: =AVERAGE([3]Brewhouse!$AU$1529,[3]Brewhouse!$AU$1531:$AU$1594,[3]Brewhouse!$AU$1596:$AU$1619) -> 98.205761 | M50: =AVERAGE([3]Brewhouse!$AU$849:$AU$924,[3]Brewhouse!$AU$926:$AU$971,[3]Brewhouse!$AU$973:$AU$1066,[3]Brewhouse!$AU$1068:$AU$1111,[3]Brewhouse!$AU$1113:$AU$1132,[3]Brewhouse!$AU$1134:$AU$1167,[3]Brewhouse!$AU$1169:$AU$1230,[3]Brewhouse!$AU$1232:$AU$1299,[3]Brewhouse!$AU$1301:$AU$1363,[3]Brewhouse!$AU$1365:$AU$1444,[3]Brewhouse!$AU$1446:$AU$1527,[3]Brewhouse!$AU$1529,[3]Brewhouse!$AU$1531:$AU$1594,[3]Brewhouse!$AU$1596:$AU$1619) -> 98.381806 | N50: 98
C51: 11.9 | I51: STAG | K51: =COUNTA([4]Brewhouse!$A$976:$A$1007) -> 32 | L51: =AVERAGE([4]Brewhouse!$AS$976:$AS$979,[4]Brewhouse!$AS$981:$AS$1007) -> 98.538567 | M51: =AVERAGE([4]Brewhouse!$AS$577:$AS$618,[4]Brewhouse!$AS$620:$AS$651,[4]Brewhouse!$AS$653:$AS$696,[4]Brewhouse!$AS$698:$AS$708,[4]Brewhouse!$AS$710:$AS$733,[4]Brewhouse!$AS$735:$AS$777,[4]Brewhouse!$AS$779:$AS$822,[4]Brewhouse!$AS$824:$AS$863,[4]Brewhouse!$AS$865:$AS$974,[4]Brewhouse!$AS$976:$AS$979,[4]Brewhouse!$AS$981:$AS$1007) -> 98.489671 | N51: 98
I52: GUINNESS | K52: =COUNTA([5]Brewhouse!$A$282:$A$289) -> 8 | L52: =AVERAGE([5]Brewhouse!$AU$269:$AU$279,[5]Brewhouse!$AU$282:$AU$289) -> 96.186177 | M52: =AVERAGE([5]Brewhouse!$AU$161:$AU$176,[5]Brewhouse!$AU$178:$AU$195,[5]Brewhouse!$AU$197:$AU$208,[5]Brewhouse!$AU$210:$AU$221,[5]Brewhouse!$AU$223:$AU$232,[5]Brewhouse!$AU$234:$AU$279,[5]Brewhouse!$AU$282:$AU$289) -> 96.64916 | N52: 98
I53: VITAMALT | K53: =COUNTA([6]Brewhouse!$A$158:$A$163) -> 6 | L53: =AVERAGE([6]Brewhouse!$AU$158:$AU$163) -> 94.60305 | M53: =AVERAGE([6]Brewhouse!$AU$91:$AU$101,[6]Brewhouse!$AU$103:$AU$112,[6]Brewhouse!$AU$114:$AU$123,[6]Brewhouse!$AU$125:$AU$134,[6]Brewhouse!$AU$136:$AU$145,[6]Brewhouse!$AU$147:$AU$156,[6]Brewhouse!$AU$158:$AU$163) -> 96.240014 | N53: 98
I54: MAXIMALT | N54: 98
I55: MACKESON | M55: =AVERAGE([7]Brewhouse!$AT$74:$AT$79) -> 93.959836 | N55: 98
I56: STARMALT | K56: =COUNTA([8]Brewhouse!$A$249:$A$254) -> 6 | L56: =AVERAGE([8]Brewhouse!$AY$249:$AY$254) -> 99.681996 | M56: =AVERAGE([8]Brewhouse!$AY$138:$AY$143,[8]Brewhouse!$AY$145:$AY$153,[8]Brewhouse!$AY$155,[8]Brewhouse!$AY$156:$AY$174,[8]Brewhouse!$AY$176:$AY$185,[8]Brewhouse!$AY$187:$AY$198,[8]Brewhouse!$AY$200:$AY$247,[8]Brewhouse!$AY$249:$AY$254) -> 98.774703 | N56: 98
I57: HR- P | M57: =AVERAGE([9]Brewhouse!$AW$13:$AW$14,[9]Brewhouse!$AW$16:$AW$17) -> 92.042628 | N57: 98
I58: Hurricane Reef | M58: =AVERAGE([9]Brewhouse!$AW$13:$AW$14) -> 88.376943 | N58: 98
K59: =SUM(K50:K58) -> 76 | L59: =((L50*K50)+(L51*K51)+(L52*K52)+(L53*K53)+(L54*K54)+(K57*L57)+(L55*K55)+(L56*K56)+(L58*K58))/(K59) -> 97.965422 | M59: =AVERAGE('[10]Closing- January 2023'!$L$42,'[11]Feb. 28th'!$L$42,'[12]March 31st'!$L$75,'[13]Apri 28th'!$L$51,L59) -> 98.06926 | N59: 98
J62: Daily Brewing Plan
J63: Brand | K63: Brews Achieved | L63: Average Brews per day
J64: CARIB | L64: MTD | M64: YTD | N64: TARGET
J65: STAG | K65: 5 | L65: =AVERAGE(#REF!,#REF!,K74,#REF!,#REF!,#REF!,#REF!,#REF!,#REF!,#REF!,#REF!) -> #REF! | M65: =AVERAGE(6,6,'[12]March 31st'!$L$80,'[14]June 30th '!$L$71,6,L65,'[15]July 31st'!$L$108,'[16]Aug 30th'!$L$124,7,[17]Oct.31st!$L$51) -> #REF! | N65: 9
J66: GUINN
J67: VITAMALT
...

Sheet Apr. 1st
T1: P.G. | V1: Hot Time | X1: Process Time | Z1: Cooling Time
B2: Brewing Department Daily Process Loss Report | T2: Lower | U2: Upper | V2: Lower | W2: Upper | X2: Lower | Y2: Upper | Z2: Lower | AA2: Upper
S3: CARIB | T3: 11.6 | U3: 12 | V3: 0 | W3: 0.11805556 | X3: 0.22569444 | Y3: 0.26388889 | Z3: 0 | AA3: 60 | AC3: HR- PISNER
B4: Date: | C4: 45749 | J4: LOT WORT COLOUR: 3.3 | M4: Filter Sheets (Target 20 days) | S4: STAG | T4: 11.6 | U4: 12 | V4: 0 | W4: 0.11805556 | X4: 0.22569444 | Y4: 0.26388889 | Z4: 0 | AA4: 60
M5: Double | N5: Single | S5: GUINNESS | T5: 17 | U5: 17.5 | V5: 0 | W5: 0.10763889 | X5: 0.24652778 | Y5: 0.28472222 | Z5: 0 | AA5: 60
J6: MALT LOT: Lot 33 | L6: Sheet Day | M6: 12 | N6: 10 | S6: MACKESON | T6: 13.3 | U6: 13.5 | V6: 0 | W6: 0.12905093 | X6: 0.27430556 | Y6: 0.30208333 | Z6: 0
S7: STARMALT | T7: 17.1 | U7: 17.5 | V7: 0 | W7: 0.13605324 | X7: 0.27430556 | Y7: 0.30902778 | Z7: 0 | AA7: 60
B8: Brand | C8: Brew no. | D8: Kett. Hls | E8: Wort | F8: Cool Time(Mins) | G8: Cast. P.G. (Lab Result) | H8: Cast P.G. (Cellar Operator)-gravity | I8: Extr. Rec (80.9%) | J8: Theor. Extr. (77.5%) | K8: Boil Off /Vol. (4-6%) | L8: Boil Time | M8: Total Hot | N8: Brewing | O8: Operator | P8: Comments | Q8: Actual Pilsen Malt | S8: Hurricane Reef | T8: 16.6 | U8: 17 | V8: 0 | W8: 0.12905093 | X8: 0.27430556 | Y8: 0.30208333 | Z8: 0
E9: Meter (Hls) | F9: Target(< 60Mins) | M9: Time | S9: VITAMALT | T9: 14.4 | U9: 14.6 | V9: 0 | W9: 0.13905093 | X9: 0.26041667 | Y9: 0.29513889 | Z9: 0 | AA9: 75
S10: =B10 -> 0 | T10: =VLOOKUP($B10,$S$3:$Y$9,2,FALSE) -> #N/A | U10: =VLOOKUP($B10,$S$3:$Y$9,3,FALSE) -> #N/A | V10: =VLOOKUP($B10,$S$3:$Y$9,4,FALSE) -> #N/A | W10: =VLOOKUP($B10,$S$3:$Y$9,5,FALSE) -> #N/A | X10: =VLOOKUP($B10,$S$3:$Y$9,6,FALSE) -> #N/A | Y10: =VLOOKUP($B10,$S$3:$Y$9,7,FALSE) -> #N/A | Z10: =VLOOKUP($B10,$S$3:$AA$9,8,FALSE) -> #N/A | AA10: =VLOOKUP($B10,$S$3:$AA$9,9,FALSE) -> #N/A
S11: =B11 -> 0 | T11: =VLOOKUP($B11,$S$3:$Y$9,2,FALSE) -> #N/A | U11: =VLOOKUP($B11,$S$3:$Y$9,3,FALSE) -> #N/A | V11: =VLOOKUP($B11,$S$3:$Y$9,4,FALSE) -> #N/A | W11: =VLOOKUP($B11,$S$3:$Y$9,5,FALSE) -> #N/A | X11: =VLOOKUP($B11,$S$3:$Y$9,6,FALSE) -> #N/A | Y11: =VLOOKUP($B11,$S$3:$Y$9,7,FALSE) -> #N/A | Z11: =VLOOKUP($B11,$S$3:$AA$9,8,FALSE) -> #N/A | AA11: =VLOOKUP($B11,$S$3:$AA$9,9,FALSE) -> #N/A
S12: =B12 -> 0 | T12: =VLOOKUP($B12,$S$3:$Y$9,2,FALSE) -> #N/A | U12: =VLOOKUP($B12,$S$3:$Y$9,3,FALSE) -> #N/A | V12: =VLOOKUP($B12,$S$3:$Y$9,4,FALSE) -> #N/A | W12: =VLOOKUP($B12,$S$3:$Y$9,5,FALSE) -> #N/A | X12: =VLOOKUP($B12,$S$3:$Y$9,6,FALSE) -> #N/A | Y12: =VLOOKUP($B12,$S$3:$Y$9,7,FALSE) -> #N/A | Z12: =VLOOKUP($B12,$S$3:$AA$9,8,FALSE) -> #N/A | AA12: =VLOOKUP($B12,$S$3:$AA$9,9,FALSE) -> #N/A
S13: =B13 -> 0 | T13: =VLOOKUP($B13,$S$3:$Y$9,2,FALSE) -> #N/A | U13: =VLOOKUP($B13,$S$3:$Y$9,3,FALSE) -> #N/A | V13: =VLOOKUP($B13,$S$3:$Y$9,4,FALSE) -> #N/A | W13: =VLOOKUP($B13,$S$3:$Y$9,5,FALSE) -> #N/A | X13: =VLOOKUP($B13,$S$3:$Y$9,6,FALSE) -> #N/A | Y13: =VLOOKUP($B13,$S$3:$Y$9,7,FALSE) -> #N/A | Z13: =VLOOKUP($B13,$S$3:$AA$9,8,FALSE) -> #N/A | AA13: =VLOOKUP($B13,$S$3:$AA$9,9,FALSE) -> #N/A
S14: =B14 -> 0 | T14: =VLOOKUP($B14,$S$3:$Y$9,2,FALSE) -> #N/A | U14: =VLOOKUP($B14,$S$3:$Y$9,3,FALSE) -> #N/A | V14: =VLOOKUP($B14,$S$3:$Y$9,4,FALSE) -> #N/A | W14: =VLOOKUP($B14,$S$3:$Y$9,5,FALSE) -> #N/A | X14: =VLOOKUP($B14,$S$3:$Y$9,6,FALSE) -> #N/A | Y14: =VLOOKUP($B14,$S$3:$Y$9,7,FALSE) -> #N/A | Z14: =VLOOKUP($B14,$S$3:$AA$9,8,FALSE) -> #N/A | AA14: =VLOOKUP($B14,$S$3:$AA$9,9,FALSE) -> #N/A
B15: GUINNESS | C15: =[22]Brewhouse!$A37 -> GU031 | D15: =[22]Brewhouse!$AF37 -> 58.6 | E15: =[22]Brewhouse!$AI37 -> 53.6 | F15: =[22]Brewhouse!$V37 -> 63 | G15: =[22]Brewhouse!$AG37 -> 17 | H15: 17.1 | I15: =[22]Brewhouse!$AU37 -> 96.214668 | J15: =[22]Brewhouse!$AV37 -> 97.322929 | K15: =[22]Brewhouse!$R37 -> 2.9015544 | L15: =[22]Brewhouse!$O37 -> 60 | M15: =[22]Brewhouse!$U37-[22]Brewhouse!$T37 -> 0.12361111 | N15: =[22]Brewhouse!$Z37 -> 0.29861111 | O15: =[22]Brewhouse!$AW37 -> R. Regis | S15: =B15 -> GUINNESS | T15: =VLOOKUP($B15,$S$3:$Y$9,2,FALSE) -> 17 | U15: =VLOOKUP($B15,$S$3:$Y$9,3,FALSE) -> 17.5 | V15: =VLOOKUP($B15,$S$3:$Y$9,4,FALSE) -> 0 | W15: =VLOOKUP($B15,$S$3:$Y$9,5,FALSE) -> 0.10763889 | X15: =VLOOKUP($B15,$S$3:$Y$9,6,FALSE) -> 0.24652778 | Y15: =VLOOKUP($B15,$S$3:$Y$9,7,FALSE) -> 0.28472222 | Z15: =VLOOKUP($B15,$S$3:$AA$9,8,FALSE) -> 0 | AA15: =VLOOKUP($B15,$S$3:$AA$9,9,FALSE) -> 60
S16: =B16 -> 0 | T16: =VLOOKUP($B16,$S$3:$Y$9,2,FALSE) -> #N/A | U16: =VLOOKUP($B16,$S$3:$Y$9,3,FALSE) -> #N/A | V16: =VLOOKUP($B16,$S$3:$Y$9,4,FALSE) -> #N/A | W16: =VLOOKUP($B16,$S$3:$Y$9,5,FALSE) -> #N/A | X16: =VLOOKUP($B16,$S$3:$Y$9,6,FALSE) -> #N/A | Y16: =VLOOKUP($B16,$S$3:$Y$9,7,FALSE) -> #N/A | Z16: =VLOOKUP($B16,$S$3:$AA$9,8,FALSE) -> #N/A | AA16: =VLOOKUP($B16,$S$3:$AA$9,9,FALSE) -> #N/A
S17: =B17 -> 0 | T17: =VLOOKUP($B17,$S$3:$Y$9,2,FALSE) -> #N/A | U17: =VLOOKUP($B17,$S$3:$Y$9,3,FALSE) -> #N/A | V17: =VLOOKUP($B17,$S$3:$Y$9,4,FALSE) -> #N/A | W17: =VLOOKUP($B17,$S$3:$Y$9,5,FALSE) -> #N/A | X17: =VLOOKUP($B17,$S$3:$Y$9,6,FALSE) -> #N/A | Y17: =VLOOKUP($B17,$S$3:$Y$9,7,FALSE) -> #N/A | Z17: =VLOOKUP($B17,$S$3:$AA$9,8,FALSE) -> #N/A | AA17: =VLOOKUP($B17,$S$3:$AA$9,9,FALSE) -> #N/A
S18: =B18 -> 0 | T18: =VLOOKUP($B18,$S$3:$Y$9,2,FALSE) -> #N/A | U18: =VLOOKUP($B18,$S$3:$Y$9,3,FALSE) -> #N/A | V18: =VLOOKUP($B18,$S$3:$Y$9,4,FALSE) -> #N/A | W18: =VLOOKUP($B18,$S$3:$Y$9,5,FALSE) -> #N/A | X18: =VLOOKUP($B18,$S$3:$Y$9,6,FALSE) -> #N/A | Y18: =VLOOKUP($B18,$S$3:$Y$9,7,FALSE) -> #N/A | Z18: =VLOOKUP($B18,$S$3:$AA$9,8,FALSE) -> #N/A | AA18: =VLOOKUP($B18,$S$3:$AA$9,9,FALSE) -> #N/A
S19: =B19 -> 0 | T19: =VLOOKUP($B19,$S$3:$Y$9,2,FALSE) -> #N/A | U19: =VLOOKUP($B19,$S$3:$Y$9,3,FALSE) -> #N/A | V19: =VLOOKUP($B19,$S$3:$Y$9,4,FALSE) -> #N/A | W19: =VLOOKUP($B19,$S$3:$Y$9,5,FALSE) -> #N/A | X19: =VLOOKUP($B19,$S$3:$Y$9,6,FALSE) -> #N/A | Y19: =VLOOKUP($B19,$S$3:$Y$9,7,FALSE) -> #N/A | Z19: =VLOOKUP($B19,$S$3:$AA$9,8,FALSE) -> #N/A | AA19: =VLOOKUP($B19,$S$3:$AA$9,9,FALSE) -> #N/A
S20: =B20 -> 0 | T20: =VLOOKUP($B20,$S$3:$Y$9,2,FALSE) -> #N/A | U20: =VLOOKUP($B20,$S$3:$Y$9,3,FALSE) -> #N/A | V20: =VLOOKUP($B20,$S$3:$Y$9,4,FALSE) -> #N/A | W20: =VLOOKUP($B20,$S$3:$Y$9,5,FALSE) -> #N/A | X20: =VLOOKUP($B20,$S$3:$Y$9,6,FALSE) -> #N/A | Y20: =VLOOKUP($B20,$S$3:$Y$9,7,FALSE) -> #N/A | Z20: =VLOOKUP($B20,$S$3:$AA$9,8,FALSE) -> #N/A | AA20: =VLOOKUP($B20,$S$3:$AA$9,9,FALSE) -> #N/A
S21: =B21 -> 0 | T21: =VLOOKUP($B21,$S$3:$Y$9,2,FALSE) -> #N/A | U21: =VLOOKUP($B21,$S$3:$Y$9,3,FALSE) -> #N/A | V21: =VLOOKUP($B21,$S$3:$Y$9,4,FALSE) -> #N/A | W21: =VLOOKUP($B21,$S$3:$Y$9,5,FALSE) -> #N/A | X21: =VLOOKUP($B21,$S$3:$Y$9,6,FALSE) -> #N/A | Y21: =VLOOKUP($B21,$S$3:$Y$9,7,FALSE) -> #N/A | Z21: =VLOOKUP($B21,$S$3:$AA$9,8,FALSE) -> #N/A | AA21: =VLOOKUP($B21,$S$3:$AA$9,9,FALSE) -> #N/A
S22: =B22 -> 0 | T22: =VLOOKUP($B22,$S$3:$Y$9,2,FALSE) -> #N/A | U22: =VLOOKUP($B22,$S$3:$Y$9,3,FALSE) -> #N/A | V22: =VLOOKUP($B22,$S$3:$Y$9,4,FALSE) -> #N/A | W22: =VLOOKUP($B22,$S$3:$Y$9,5,FALSE) -> #N/A | X22: =VLOOKUP($B22,$S$3:$Y$9,6,FALSE) -> #N/A | Y22: =VLOOKUP($B22,$S$3:$Y$9,7,FALSE) -> #N/A | Z22: =VLOOKUP($B22,$S$3:$AA$9,8,FALSE) -> #N/A | AA22: =VLOOKUP($B22,$S$3:$AA$9,9,FALSE) -> #N/A
I23: EXTRACT RECOVERY | S23: =B23 -> 0 | T23: =VLOOKUP($B23,$S$3:$Y$9,2,FALSE) -> #N/A | U23: =VLOOKUP($B23,$S$3:$Y$9,3,FALSE) -> #N/A | V23: =VLOOKUP($B23,$S$3:$Y$9,4,FALSE) -> #N/A | W23: =VLOOKUP($B23,$S$3:$Y$9,5,FALSE) -> #N/A | X23: =VLOOKUP($B23,$S$3:$Y$9,6,FALSE) -> #N/A | Y23: =VLOOKUP($B23,$S$3:$Y$9,7,FALSE) -> #N/A | Z23: =VLOOKUP($B23,$S$3:$AA$9,8,FALSE) -> #N/A | AA23: =VLOOKUP($B23,$S$3:$AA$9,9,FALSE) -> #N/A
B24: BRAND | D24: BBT P.G./ O.G | I24: Brand | J24: Actual | K24: MTD No. of Brews | L24: MTD | M24: YTD | N24: Target | S24: =B24 -> BRAND | T24: =VLOOKUP($B24,$S$3:$Y$9,2,FALSE) -> #N/A | U24: =VLOOKUP($B24,$S$3:$Y$9,3,FALSE) -> #N/A | V24: =VLOOKUP($B24,$S$3:$Y$9,4,FALSE) -> #N/A | W24: =VLOOKUP($B24,$S$3:$Y$9,5,FALSE) -> #N/A | X24: =VLOOKUP($B24,$S$3:$Y$9,6,FALSE) -> #N/A | Y24: =VLOOKUP($B24,$S$3:$Y$9,7,FALSE) -> #N/A | Z24: =VLOOKUP($B24,$S$3:$AA$9,8,FALSE) -> #N/A | AA24: =VLOOKUP($B24,$S$3:$AA$9,9,FALSE) -> #N/A
B25: =I25 -> CARIB | C25: =[23]Process!D291 -> 11.83 | D25: 11.67 | I25: CARIB | M25: =AVERAGE([23]Brewhouse!$AU$102:$AU$171,[23]Brewhouse!$AU$173:$AU$253,[23]Brewhouse!$AU$255:$AU$339) -> 96.788244 | N25: 98
C26: =[23]Process!D292 -> 11.8 | I26: STAG | M26: =AVERAGE([24]Brewhouse!$AS$15:$AS$64,[24]Brewhouse!$AS$66:$AS$103,[24]Brewhouse!$AS$105:$AS$140) -> 96.70556 | N26: 98
C27: =[23]Process!D293 -> 11.8 | D27: 11.78 | I27: GUINNESS | J27: =AVERAGE(I15) -> 96.214668 | K27: =COUNTA([22]Brewhouse!$A$37) -> 1 | L27: =AVERAGE([22]Brewhouse!$AU$37) -> 96.214668 | M27: =AVERAGE([22]Brewhouse!$AU$4:$AU$7,[22]Brewhouse!$AU$9:$AU$22,[22]Brewhouse!$AU$24:$AU$35,[22]Brewhouse!$AU$37) -> 96.767265 | N27: 98
C28: =[23]Process!D294 -> 12 | I28: VITAMALT | M28: =AVERAGE([25]Brewhouse!$AV$5:$AV$14,[25]Brewhouse!$AV$16:$AV$19,[25]Brewhouse!$AV$21:$AV$24) -> 98.616017 | N28: 98
I29: MAXIMALT | N29: 98
I30: MACKESON | M30: =AVERAGE([26]Brewhouse!$AT$4:$AT$11) -> 94.812617 | N30: 98
I31: STARMALT | M31: =AVERAGE([27]Brewhouse!$AY$6:$AY$13,[27]Brewhouse!$AY$15:$AY$20,[27]Brewhouse!$AY$22:$AY$29) -> 95.660462 | N31: 98
I32: HR- Pils | M32: =AVERAGE([28]Brewhouse!$AU$5:$AU$8) -> 91.006888 | N32: 98
I33: HR- IPA | N33: 98
I34: HR- APA | N34: 98
K35: =SUM(K25:K34) -> 1 | L35: =((L25*K25)+(L26*K26)+(L27*K27)+(L28*K28)+(L29*K29)+(K32*L32)+(L30*K30)+(L31*K31)+(L34*K34))/(K35) -> 96.214668 | M35: =AVERAGE('[29]Jan 31st'!$L$65,'[30]Feb 28th'!$L$35,L35) -> 95.885881 | N35: 98
B37: =I26 -> STAG | C37: =[24]Process!D121 -> 11.8 | D37: 11.71 | J37: Daily Brewing Plan
C38: =[24]Process!D122 -> 11.7 | J38: Brand | K38: Brews Achieved | L38: Average Brews per day
C39: =[24]Process!D123 -> 11.9 | D39: 11.79 | J39: CARIB | L39: MTD | M39: YTD | N39: TARGET
C40: =[24]Process!D124 -> 11.7 | J40: STAG | L40: =K49 -> 1 | M40: =AVERAGE('[29]Jan 29th '!$M$70,'[30]Feb 28th'!$L$40,'[31]Mar. 31st'!$L$40,L40) -> 5.2038342 | N40: 9.2
C41: =[24]Process!D125 -> 11.85 | D41: 11.65 | J41: GUINN | K41: 1
...

Sheet Apr. 3rd
T1: P.G. | V1: Hot Time | X1: Process Time | Z1: Cooling Time
B2: Brewing Department Daily Process Loss Report | T2: Lower | U2: Upper | V2: Lower | W2: Upper | X2: Lower | Y2: Upper | Z2: Lower | AA2: Upper
S3: CARIB | T3: 11.6 | U3: 12 | V3: 0 | W3: 0.11805556 | X3: 0.22569444 | Y3: 0.26388889 | Z3: 0 | AA3: 60 | AC3: HR- PISNER
B4: Date: | C4: 45751 | J4: LOT WORT COLOUR: 3.3 | M4: Filter Sheets (Target 20 days) | S4: STAG | T4: 11.6 | U4: 12 | V4: 0 | W4: 0.11805556 | X4: 0.22569444 | Y4: 0.26388889 | Z4: 0 | AA4: 60
M5: Double | N5: Single | S5: GUINNESS | T5: 17 | U5: 17.5 | V5: 0 | W5: 0.10763889 | X5: 0.24652778 | Y5: 0.28472222 | Z5: 0 | AA5: 60
J6: MALT LOT: Lot 29/ 33 | L6: Sheet Day | M6: 12 | N6: 10 | S6: MACKESON | T6: 13.3 | U6: 13.5 | V6: 0 | W6: 0.12905093 | X6: 0.27430556 | Y6: 0.30208333 | Z6: 0
S7: STARMALT | T7: 17.1 | U7: 17.5 | V7: 0 | W7: 0.13605324 | X7: 0.27430556 | Y7: 0.30902778 | Z7: 0 | AA7: 60
B8: Brand | C8: Brew no. | D8: Kett. Hls | E8: Wort | F8: Cool Time(Mins) | G8: Cast. P.G. (Lab Result) | H8: Cast P.G. (Cellar Operator)-gravity | I8: Extr. Rec (80.9%) | J8: Theor. Extr. (77.5%) | K8: Boil Off /Vol. (4-6%) | L8: Boil Time | M8: Total Hot | N8: Brewing | O8: Operator | P8: Comments | Q8: Actual Pilsen Malt | S8: Hurricane Reef | T8: 16.6 | U8: 17 | V8: 0 | W8: 0.12905093 | X8: 0.27430556 | Y8: 0.30208333 | Z8: 0
E9: Meter (Hls) | F9: Target(< 60Mins) | M9: Time | S9: VITAMALT | T9: 14.4 | U9: 14.6 | V9: 0 | W9: 0.13905093 | X9: 0.26041667 | Y9: 0.29513889 | Z9: 0 | AA9: 75
B10: STAG | C10: =[24]Brewhouse!$A142 -> ST125 | D10: =[24]Brewhouse!$AD142 -> 52.3 | E10: =[24]Brewhouse!$AG142 -> 48.3 | F10: =[24]Brewhouse!$V142 -> 55 | G10: =[24]Brewhouse!$AE142 -> 12.1 | H10: 12.1 | I10: =[24]Brewhouse!$AS142 -> 97.215215 | J10: =[24]Brewhouse!$AT142 -> 98.325317 | K10: =[24]Brewhouse!$Q142 -> 8.8724584 | L10: =[24]Brewhouse!$P142 -> 61 | M10: =[24]Brewhouse!$U142-[24]Brewhouse!$T142 -> 0.11319444 | N10: =[24]Brewhouse!$AW142 -> 0.26944444 | O10: =[24]Brewhouse!$AV142 -> K. Benjamin | S10: =B10 -> STAG | T10: =VLOOKUP($B10,$S$3:$Y$9,2,FALSE) -> 11.6 | U10: =VLOOKUP($B10,$S$3:$Y$9,3,FALSE) -> 12 | V10: =VLOOKUP($B10,$S$3:$Y$9,4,FALSE) -> 0 | W10: =VLOOKUP($B10,$S$3:$Y$9,5,FALSE) -> 0.11805556 | X10: =VLOOKUP($B10,$S$3:$Y$9,6,FALSE) -> 0.22569444 | Y10: =VLOOKUP($B10,$S$3:$Y$9,7,FALSE) -> 0.26388889 | Z10: =VLOOKUP($B10,$S$3:$AA$9,8,FALSE) -> 0 | AA10: =VLOOKUP($B10,$S$3:$AA$9,9,FALSE) -> 60
B11: STAG | C11: =[24]Brewhouse!$A143 -> ST126 | D11: =[24]Brewhouse!$AD143 -> 52.3 | E11: =[24]Brewhouse!$AG143 -> 51 | F11: =[24]Brewhouse!$V143 -> 57 | G11: =[24]Brewhouse!$AE143 -> 11.8 | H11: 11.8 | I11: =[24]Brewhouse!$AS143 -> 100.22636 | J11: =[24]Brewhouse!$AT143 -> 101.3701 | K11: =[24]Brewhouse!$Q143 -> 6.4102564 | L11: =[24]Brewhouse!$P143 -> 78 | M11: =[24]Brewhouse!$U143-[24]Brewhouse!$T143 -> 0.11041667 | N11: =[24]Brewhouse!$AW143 -> 0.24652778 | O11: =[24]Brewhouse!$AV143 -> K. Benjamin | S11: =B11 -> STAG | T11: =VLOOKUP($B11,$S$3:$Y$9,2,FALSE) -> 11.6 | U11: =VLOOKUP($B11,$S$3:$Y$9,3,FALSE) -> 12 | V11: =VLOOKUP($B11,$S$3:$Y$9,4,FALSE) -> 0 | W11: =VLOOKUP($B11,$S$3:$Y$9,5,FALSE) -> 0.11805556 | X11: =VLOOKUP($B11,$S$3:$Y$9,6,FALSE) -> 0.22569444 | Y11: =VLOOKUP($B11,$S$3:$Y$9,7,FALSE) -> 0.26388889 | Z11: =VLOOKUP($B11,$S$3:$AA$9,8,FALSE) -> 0 | AA11: =VLOOKUP($B11,$S$3:$AA$9,9,FALSE) -> 60
S12: =B12 -> 0 | T12: =VLOOKUP($B12,$S$3:$Y$9,2,FALSE) -> #N/A | U12: =VLOOKUP($B12,$S$3:$Y$9,3,FALSE) -> #N/A | V12: =VLOOKUP($B12,$S$3:$Y$9,4,FALSE) -> #N/A | W12: =VLOOKUP($B12,$S$3:$Y$9,5,FALSE) -> #N/A | X12: =VLOOKUP($B12,$S$3:$Y$9,6,FALSE) -> #N/A | Y12: =VLOOKUP($B12,$S$3:$Y$9,7,FALSE) -> #N/A | Z12: =VLOOKUP($B12,$S$3:$AA$9,8,FALSE) -> #N/A | AA12: =VLOOKUP($B12,$S$3:$AA$9,9,FALSE) -> #N/A
S13: =B13 -> 0 | T13: =VLOOKUP($B13,$S$3:$Y$9,2,FALSE) -> #N/A | U13: =VLOOKUP($B13,$S$3:$Y$9,3,FALSE) -> #N/A | V13: =VLOOKUP($B13,$S$3:$Y$9,4,FALSE) -> #N/A | W13: =VLOOKUP($B13,$S$3:$Y$9,5,FALSE) -> #N/A | X13: =VLOOKUP($B13,$S$3:$Y$9,6,FALSE) -> #N/A | Y13: =VLOOKUP($B13,$S$3:$Y$9,7,FALSE) -> #N/A | Z13: =VLOOKUP($B13,$S$3:$AA$9,8,FALSE) -> #N/A | AA13: =VLOOKUP($B13,$S$3:$AA$9,9,FALSE) -> #N/A
S14: =B14 -> 0 | T14: =VLOOKUP($B14,$S$3:$Y$9,2,FALSE) -> #N/A | U14: =VLOOKUP($B14,$S$3:$Y$9,3,FALSE) -> #N/A | V14: =VLOOKUP($B14,$S$3:$Y$9,4,FALSE) -> #N/A | W14: =VLOOKUP($B14,$S$3:$Y$9,5,FALSE) -> #N/A | X14: =VLOOKUP($B14,$S$3:$Y$9,6,FALSE) -> #N/A | Y14: =VLOOKUP($B14,$S$3:$Y$9,7,FALSE) -> #N/A | Z14: =VLOOKUP($B14,$S$3:$AA$9,8,FALSE) -> #N/A | AA14: =VLOOKUP($B14,$S$3:$AA$9,9,FALSE) -> #N/A
S15: =B15 -> 0 | T15: =VLOOKUP($B15,$S$3:$Y$9,2,FALSE) -> #N/A | U15: =VLOOKUP($B15,$S$3:$Y$9,3,FALSE) -> #N/A | V15: =VLOOKUP($B15,$S$3:$Y$9,4,FALSE) -> #N/A | W15: =VLOOKUP($B15,$S$3:$Y$9,5,FALSE) -> #N/A | X15: =VLOOKUP($B15,$S$3:$Y$9,6,FALSE) -> #N/A | Y15: =VLOOKUP($B15,$S$3:$Y$9,7,FALSE) -> #N/A | Z15: =VLOOKUP($B15,$S$3:$AA$9,8,FALSE) -> #N/A | AA15: =VLOOKUP($B15,$S$3:$AA$9,9,FALSE) -> #N/A
S16: =B16 -> 0 | T16: =VLOOKUP($B16,$S$3:$Y$9,2,FALSE) -> #N/A | U16: =VLOOKUP($B16,$S$3:$Y$9,3,FALSE) -> #N/A | V16: =VLOOKUP($B16,$S$3:$Y$9,4,FALSE) -> #N/A | W16: =VLOOKUP($B16,$S$3:$Y$9,5,FALSE) -> #N/A | X16: =VLOOKUP($B16,$S$3:$Y$9,6,FALSE) -> #N/A | Y16: =VLOOKUP($B16,$S$3:$Y$9,7,FALSE) -> #N/A | Z16: =VLOOKUP($B16,$S$3:$AA$9,8,FALSE) -> #N/A | AA16: =VLOOKUP($B16,$S$3:$AA$9,9,FALSE) -> #N/A
S17: =B17 -> 0 | T17: =VLOOKUP($B17,$S$3:$Y$9,2,FALSE) -> #N/A | U17: =VLOOKUP($B17,$S$3:$Y$9,3,FALSE) -> #N/A | V17: =VLOOKUP($B17,$S$3:$Y$9,4,FALSE) -> #N/A | W17: =VLOOKUP($B17,$S$3:$Y$9,5,FALSE) -> #N/A | X17: =VLOOKUP($B17,$S$3:$Y$9,6,FALSE) -> #N/A | Y17: =VLOOKUP($B17,$S$3:$Y$9,7,FALSE) -> #N/A | Z17: =VLOOKUP($B17,$S$3:$AA$9,8,FALSE) -> #N/A | AA17: =VLOOKUP($B17,$S$3:$AA$9,9,FALSE) -> #N/A
S18: =B18 -> 0 | T18: =VLOOKUP($B18,$S$3:$Y$9,2,FALSE) -> #N/A | U18: =VLOOKUP($B18,$S$3:$Y$9,3,FALSE) -> #N/A | V18: =VLOOKUP($B18,$S$3:$Y$9,4,FALSE) -> #N/A | W18: =VLOOKUP($B18,$S$3:$Y$9,5,FALSE) -> #N/A | X18: =VLOOKUP($B18,$S$3:$Y$9,6,FALSE) -> #N/A | Y18: =VLOOKUP($B18,$S$3:$Y$9,7,FALSE) -> #N/A | Z18: =VLOOKUP($B18,$S$3:$AA$9,8,FALSE) -> #N/A | AA18: =VLOOKUP($B18,$S$3:$AA$9,9,FALSE) -> #N/A
S19: =B19 -> 0 | T19: =VLOOKUP($B19,$S$3:$Y$9,2,FALSE) -> #N/A | U19: =VLOOKUP($B19,$S$3:$Y$9,3,FALSE) -> #N/A | V19: =VLOOKUP($B19,$S$3:$Y$9,4,FALSE) -> #N/A | W19: =VLOOKUP($B19,$S$3:$Y$9,5,FALSE) -> #N/A | X19: =VLOOKUP($B19,$S$3:$Y$9,6,FALSE) -> #N/A | Y19: =VLOOKUP($B19,$S$3:$Y$9,7,FALSE) -> #N/A | Z19: =VLOOKUP($B19,$S$3:$AA$9,8,FALSE) -> #N/A | AA19: =VLOOKUP($B19,$S$3:$AA$9,9,FALSE) -> #N/A
S20: =B20 -> 0 | T20: =VLOOKUP($B20,$S$3:$Y$9,2,FALSE) -> #N/A | U20: =VLOOKUP($B20,$S$3:$Y$9,3,FALSE) -> #N/A | V20: =VLOOKUP($B20,$S$3:$Y$9,4,FALSE) -> #N/A | W20: =VLOOKUP($B20,$S$3:$Y$9,5,FALSE) -> #N/A | X20: =VLOOKUP($B20,$S$3:$Y$9,6,FALSE) -> #N/A | Y20: =VLOOKUP($B20,$S$3:$Y$9,7,FALSE) -> #N/A | Z20: =VLOOKUP($B20,$S$3:$AA$9,8,FALSE) -> #N/A | AA20: =VLOOKUP($B20,$S$3:$AA$9,9,FALSE) -> #N/A
S21: =B21 -> 0 | T21: =VLOOKUP($B21,$S$3:$Y$9,2,FALSE) -> #N/A | U21: =VLOOKUP($B21,$S$3:$Y$9,3,FALSE) -> #N/A | V21: =VLOOKUP($B21,$S$3:$Y$9,4,FALSE) -> #N/A | W21: =VLOOKUP($B21,$S$3:$Y$9,5,FALSE) -> #N/A | X21: =VLOOKUP($B21,$S$3:$Y$9,6,FALSE) -> #N/A | Y21: =VLOOKUP($B21,$S$3:$Y$9,7,FALSE) -> #N/A | Z21: =VLOOKUP($B21,$S$3:$AA$9,8,FALSE) -> #N/A | AA21: =VLOOKUP($B21,$S$3:$AA$9,9,FALSE) -> #N/A
S22: =B22 -> 0 | T22: =VLOOKUP($B22,$S$3:$Y$9,2,FALSE) -> #N/A | U22: =VLOOKUP($B22,$S$3:$Y$9,3,FALSE) -> #N/A | V22: =VLOOKUP($B22,$S$3:$Y$9,4,FALSE) -> #N/A | W22: =VLOOKUP($B22,$S$3:$Y$9,5,FALSE) -> #N/A | X22: =VLOOKUP($B22,$S$3:$Y$9,6,FALSE) -> #N/A | Y22: =VLOOKUP($B22,$S$3:$Y$9,7,FALSE) -> #N/A | Z22: =VLOOKUP($B22,$S$3:$AA$9,8,FALSE) -> #N/A | AA22: =VLOOKUP($B22,$S$3:$AA$9,9,FALSE) -> #N/A
I23: EXTRACT RECOVERY | S23: =B23 -> 0 | T23: =VLOOKUP($B23,$S$3:$Y$9,2,FALSE) -> #N/A | U23: =VLOOKUP($B23,$S$3:$Y$9,3,FALSE) -> #N/A | V23: =VLOOKUP($B23,$S$3:$Y$9,4,FALSE) -> #N/A | W23: =VLOOKUP($B23,$S$3:$Y$9,5,FALSE) -> #N/A | X23: =VLOOKUP($B23,$S$3:$Y$9,6,FALSE) -> #N/A | Y23: =VLOOKUP($B23,$S$3:$Y$9,7,FALSE) -> #N/A | Z23: =VLOOKUP($B23,$S$3:$AA$9,8,FALSE) -> #N/A | AA23: =VLOOKUP($B23,$S$3:$AA$9,9,FALSE) -> #N/A
B24: BRAND | D24: BBT P.G./ O.G | I24: Brand | J24: Actual | K24: MTD No. of Brews | L24: MTD | M24: YTD | N24: Target | S24: =B24 -> BRAND | T24: =VLOOKUP($B24,$S$3:$Y$9,2,FALSE) -> #N/A | U24: =VLOOKUP($B24,$S$3:$Y$9,3,FALSE) -> #N/A | V24: =VLOOKUP($B24,$S$3:$Y$9,4,FALSE) -> #N/A | W24: =VLOOKUP($B24,$S$3:$Y$9,5,FALSE) -> #N/A | X24: =VLOOKUP($B24,$S$3:$Y$9,6,FALSE) -> #N/A | Y24: =VLOOKUP($B24,$S$3:$Y$9,7,FALSE) -> #N/A | Z24: =VLOOKUP($B24,$S$3:$AA$9,8,FALSE) -> #N/A | AA24: =VLOOKUP($B24,$S$3:$AA$9,9,FALSE) -> #N/A
B25: CARIBE | I25: CARIB | M25: =AVERAGE([23]Brewhouse!$AU$102:$AU$171,[23]Brewhouse!$AU$173:$AU$253,[23]Brewhouse!$AU$255:$AU$339) -> 96.788244 | N25: 98
I26: STAG | J26: =AVERAGE(I10:I11) -> 98.720787 | K26: =COUNTA([24]Brewhouse!$A$142:$A$143) -> 2 | L26: =AVERAGE([24]Brewhouse!$AS$142:$AS$143) -> 98.720787 | M26: =AVERAGE([24]Brewhouse!$AS$15:$AS$64,[24]Brewhouse!$AS$66:$AS$103,[24]Brewhouse!$AS$105:$AS$140,[24]Brewhouse!$AS$142:$AS$143) -> 96.737548 | N26: 98
I27: GUINNESS | K27: =COUNTA([22]Brewhouse!$A$37) -> 1 | L27: =AVERAGE([22]Brewhouse!$AU$37) -> 96.214668 | M27: =AVERAGE([22]Brewhouse!$AU$4:$AU$7,[22]Brewhouse!$AU$9:$AU$22,[22]Brewhouse!$AU$24:$AU$35,[22]Brewhouse!$AU$37) -> 96.767265 | N27: 98
I28: VITAMALT | M28: =AVERAGE([25]Brewhouse!$AV$5:$AV$14,[25]Brewhouse!$AV$16:$AV$19,[25]Brewhouse!$AV$21:$AV$24) -> 98.616017 | N28: 98
I29: MAXIMALT | N29: 98
I30: MACKESON | M30: =AVERAGE([26]Brewhouse!$AT$4:$AT$11) -> 94.812617 | N30: 98
I31: STARMALT | M31: =AVERAGE([27]Brewhouse!$AY$6:$AY$13,[27]Brewhouse!$AY$15:$AY$20,[27]Brewhouse!$AY$22:$AY$29) -> 95.660462 | N31: 98
I32: HR- Pils | M32: =AVERAGE([28]Brewhouse!$AU$5:$AU$8) -> 91.006888 | N32: 98
I33: HR- IPA | N33: 98
I34: HR- APA | N34: 98
K35: =SUM(K25:K34) -> 3 | L35: =((L25*K25)+(L26*K26)+(L27*K27)+(L28*K28)+(L29*K29)+(K32*L32)+(L30*K30)+(L31*K31)+(L34*K34))/(K35) -> 97.885414 | M35: =AVERAGE('[29]Jan 31st'!$L$65,'[30]Feb 28th'!$L$35,L35) -> 96.442797 | N35: 98
J37: Daily Brewing Plan
J38: Brand | K38: Brews Achieved | L38: Average Brews per day
J39: CARIB | L39: MTD | M39: YTD | N39: TARGET
J40: STAG | K40: 2 | L40: =AVERAGE('Apr. 1st'!K49,'Apr. 3rd'!K49) -> 1.5 | M40: =AVERAGE('[29]Jan 29th '!$M$70,'[30]Feb 28th'!$L$40,'[31]Mar. 31st'!$L$40,L40) -> 5.3288342 | N40: 9.2
J41: GUINN
...

Sheet Apr. 4th
T1: P.G. | V1: Hot Time | X1: Process Time | Z1: Cooling Time
B2: Brewing Department Daily Process Loss Report | T2: Lower | U2: Upper | V2: Lower | W2: Upper | X2: Lower | Y2: Upper | Z2: Lower | AA2: Upper
S3: CARIB | T3: 11.6 | U3: 12 | V3: 0 | W3: 0.11805556 | X3: 0.22569444 | Y3: 0.26388889 | Z3: 0 | AA3: 60 | AC3: HR- PISNER
B4: Date: | C4: 45754 | J4: LOT WORT COLOUR: 3.3 | M4: Filter Sheets (Target 20 days) | S4: STAG | T4: 11.6 | U4: 12 | V4: 0 | W4: 0.11805556 | X4: 0.22569444 | Y4: 0.26388889 | Z4: 0 | AA4: 60
M5: Double | N5: Single | S5: GUINNESS | T5: 17 | U5: 17.5 | V5: 0 | W5: 0.10763889 | X5: 0.24652778 | Y5: 0.28472222 | Z5: 0 | AA5: 60
J6: MALT LOT: Lot 29/ 33 | L6: Sheet Day | M6: 12 | N6: 10 | S6: MACKESON | T6: 13.3 | U6: 13.5 | V6: 0 | W6: 0.12905093 | X6: 0.27430556 | Y6: 0.30208333 | Z6: 0
S7: STARMALT | T7: 17.1 | U7: 17.5 | V7: 0 | W7: 0.13605324 | X7: 0.27430556 | Y7: 0.30902778 | Z7: 0 | AA7: 60
B8: Brand | C8: Brew no. | D8: Kett. Hls | E8: Wort | F8: Cool Time(Mins) | G8: Cast. P.G. (Lab Result) | H8: Cast P.G. (Cellar Operator)-gravity | I8: Extr. Rec (80.9%) | J8: Theor. Extr. (77.5%) | K8: Boil Off /Vol. (4-6%) | L8: Boil Time | M8: Total Hot | N8: Brewing | O8: Operator | P8: Cellars Vol. Extr | Q8: Actual Pilsen Malt | S8: Hurricane Reef | T8: 16.6 | U8: 17 | V8: 0 | W8: 0.12905093 | X8: 0.27430556 | Y8: 0.30208333 | Z8: 0
E9: Meter (Hls) | F9: Target(< 60Mins) | M9: Time | S9: VITAMALT | T9: 14.4 | U9: 14.6 | V9: 0 | W9: 0.13905093 | X9: 0.26041667 | Y9: 0.29513889 | Z9: 0 | AA9: 75
S10: =B10 -> 0 | T10: =VLOOKUP($B10,$S$3:$Y$9,2,FALSE) -> #N/A | U10: =VLOOKUP($B10,$S$3:$Y$9,3,FALSE) -> #N/A | V10: =VLOOKUP($B10,$S$3:$Y$9,4,FALSE) -> #N/A | W10: =VLOOKUP($B10,$S$3:$Y$9,5,FALSE) -> #N/A | X10: =VLOOKUP($B10,$S$3:$Y$9,6,FALSE) -> #N/A | Y10: =VLOOKUP($B10,$S$3:$Y$9,7,FALSE) -> #N/A | Z10: =VLOOKUP($B10,$S$3:$AA$9,8,FALSE) -> #N/A | AA10: =VLOOKUP($B10,$S$3:$AA$9,9,FALSE) -> #N/A
S11: =B11 -> 0 | T11: =VLOOKUP($B11,$S$3:$Y$9,2,FALSE) -> #N/A | U11: =VLOOKUP($B11,$S$3:$Y$9,3,FALSE) -> #N/A | V11: =VLOOKUP($B11,$S$3:$Y$9,4,FALSE) -> #N/A | W11: =VLOOKUP($B11,$S$3:$Y$9,5,FALSE) -> #N/A | X11: =VLOOKUP($B11,$S$3:$Y$9,6,FALSE) -> #N/A | Y11: =VLOOKUP($B11,$S$3:$Y$9,7,FALSE) -> #N/A | Z11: =VLOOKUP($B11,$S$3:$AA$9,8,FALSE) -> #N/A | AA11: =VLOOKUP($B11,$S$3:$AA$9,9,FALSE) -> #N/A
B12: STAG | C12: =[24]Brewhouse!$A144 -> ST127 | D12: =[24]Brewhouse!$AD144 -> 53.3 | E12: =[24]Brewhouse!$AG144 -> 49.8 | F12: =[24]Brewhouse!$V144 -> 79 | G12: =[24]Brewhouse!$AE144 -> 12 | H12: 12 | I12: =[24]Brewhouse!$AS144 -> 99.612903 | J12: =[24]Brewhouse!$AT144 -> 100.74964 | K12: =[24]Brewhouse!$Q144 -> 4.2750929 | L12: =[24]Brewhouse!$P144 -> 58 | M12: =[24]Brewhouse!$U144-[24]Brewhouse!$T144 -> 0.12152778 | N12: =[24]Brewhouse!$AW144 -> 0.26180556 | O12: =[24]Brewhouse!$AV144 -> R.Sookram | P12: 96.269229 | S12: =B12 -> STAG | T12: =VLOOKUP($B12,$S$3:$Y$9,2,FALSE) -> 11.6 | U12: =VLOOKUP($B12,$S$3:$Y$9,3,FALSE) -> 12 | V12: =VLOOKUP($B12,$S$3:$Y$9,4,FALSE) -> 0 | W12: =VLOOKUP($B12,$S$3:$Y$9,5,FALSE) -> 0.11805556 | X12: =VLOOKUP($B12,$S$3:$Y$9,6,FALSE) -> 0.22569444 | Y12: =VLOOKUP($B12,$S$3:$Y$9,7,FALSE) -> 0.26388889 | Z12: =VLOOKUP($B12,$S$3:$AA$9,8,FALSE) -> 0 | AA12: =VLOOKUP($B12,$S$3:$AA$9,9,FALSE) -> 60
B13: STAG | C13: =[24]Brewhouse!$A145 -> ST128 | D13: =[24]Brewhouse!$AD145 -> 53.9 | E13: =[24]Brewhouse!$AG145 -> 50.5 | F13: =[24]Brewhouse!$V145 -> 62 | G13: =[24]Brewhouse!$AE145 -> 11.8 | H13: 11.8 | I13: =[24]Brewhouse!$AS145 -> 98.872381 | J13: =[24]Brewhouse!$AT145 -> 100.00177 | K13: =[24]Brewhouse!$Q145 -> 5.1756007 | L13: =[24]Brewhouse!$P145 -> 57 | M13: =[24]Brewhouse!$U145-[24]Brewhouse!$T145 -> 0.11180556 | N13: =[24]Brewhouse!$AW145 -> 0.25138889 | O13: =[24]Brewhouse!$AV145 -> K. Benjamin | P13: 92.56199 | S13: =B13 -> STAG | T13: =VLOOKUP($B13,$S$3:$Y$9,2,FALSE) -> 11.6 | U13: =VLOOKUP($B13,$S$3:$Y$9,3,FALSE) -> 12 | V13: =VLOOKUP($B13,$S$3:$Y$9,4,FALSE) -> 0 | W13: =VLOOKUP($B13,$S$3:$Y$9,5,FALSE) -> 0.11805556 | X13: =VLOOKUP($B13,$S$3:$Y$9,6,FALSE) -> 0.22569444 | Y13: =VLOOKUP($B13,$S$3:$Y$9,7,FALSE) -> 0.26388889 | Z13: =VLOOKUP($B13,$S$3:$AA$9,8,FALSE) -> 0 | AA13: =VLOOKUP($B13,$S$3:$AA$9,9,FALSE) -> 60
B14: STAG | C14: =[24]Brewhouse!$A146 -> ST129 | D14: =[24]Brewhouse!$AD146 -> 53.7 | E14: =[24]Brewhouse!$AG146 -> 50.4 | F14: =[24]Brewhouse!$V146 -> 60 | G14: =[24]Brewhouse!$AE146 -> 11.7 | H14: 11.8 | I14: =[24]Brewhouse!$AS146 -> 98.164308 | J14: =[24]Brewhouse!$AT146 -> 99.284517 | K14: =[24]Brewhouse!$Q146 -> 4.6296296 | L14: =[24]Brewhouse!$P146 -> 60 | M14: =[24]Brewhouse!$U146-[24]Brewhouse!$T146 -> 0.11527778 | N14: =[24]Brewhouse!$AW146 -> 0.25625 | O14: =[24]Brewhouse!$AV146 -> K. Benjamin | P14: 98.612773 | S14: =B14 -> STAG | T14: =VLOOKUP($B14,$S$3:$Y$9,2,FALSE) -> 11.6 | U14: =VLOOKUP($B14,$S$3:$Y$9,3,FALSE) -> 12 | V14: =VLOOKUP($B14,$S$3:$Y$9,4,FALSE) -> 0 | W14: =VLOOKUP($B14,$S$3:$Y$9,5,FALSE) -> 0.11805556 | X14: =VLOOKUP($B14,$S$3:$Y$9,6,FALSE) -> 0.22569444 | Y14: =VLOOKUP($B14,$S$3:$Y$9,7,FALSE) -> 0.26388889 | Z14: =VLOOKUP($B14,$S$3:$AA$9,8,FALSE) -> 0 | AA14: =VLOOKUP($B14,$S$3:$AA$9,9,FALSE) -> 60
B15: STAG | C15: =[24]Brewhouse!$A147 -> ST130 | D15: =[24]Brewhouse!$AD147 -> 52.5 | E15: =[24]Brewhouse!$AG147 -> 49.3 | F15: =[24]Brewhouse!$V147 -> 59 | G15: =[24]Brewhouse!$AE147 -> 11.8 | H15: 11.8 | I15: =[24]Brewhouse!$AS147 -> 96.76433 | J15: =[24]Brewhouse!$AT147 -> 97.868924 | K15: =[24]Brewhouse!$Q147 -> 4.4444444 | L15: =[24]Brewhouse!$P147 -> 61 | M15: =[24]Brewhouse!$U147-[24]Brewhouse!$T147 -> 0.11875 | N15: =[24]Brewhouse!$AW147 -> 0.24722222 | O15: =[24]Brewhouse!$AV147 -> K. Benjamin | P15: 97.403979 | S15: =B15 -> STAG | T15: =VLOOKUP($B15,$S$3:$Y$9,2,FALSE) -> 11.6 | U15: =VLOOKUP($B15,$S$3:$Y$9,3,FALSE) -> 12 | V15: =VLOOKUP($B15,$S$3:$Y$9,4,FALSE) -> 0 | W15: =VLOOKUP($B15,$S$3:$Y$9,5,FALSE) -> 0.11805556 | X15: =VLOOKUP($B15,$S$3:$Y$9,6,FALSE) -> 0.22569444 | Y15: =VLOOKUP($B15,$S$3:$Y$9,7,FALSE) -> 0.26388889 | Z15: =VLOOKUP($B15,$S$3:$AA$9,8,FALSE) -> 0 | AA15: =VLOOKUP($B15,$S$3:$AA$9,9,FALSE) -> 60
B16: STAG | C16: =[24]Brewhouse!$A148 -> ST131 | D16: =[24]Brewhouse!$AD148 -> 53.4 | E16: =[24]Brewhouse!$AG148 -> 50.1 | F16: =[24]Brewhouse!$V148 -> 63 | G16: =[24]Brewhouse!$AE148 -> 11.8 | H16: 11.9 | I16: =[24]Brewhouse!$AS148 -> 98.581082 | J16: =[24]Brewhouse!$AT148 -> 99.70568 | K16: =[24]Brewhouse!$Q148 -> 4.4036697 | L16: =[24]Brewhouse!$P148 -> 60 | M16: =[24]Brewhouse!$U148-[24]Brewhouse!$T148 -> 0.10902778 | N16: =[24]Brewhouse!$AW148 -> 0.25902778 | O16: =[24]Brewhouse!$AV148 -> R.Sookram | P16: 96.995685 | S16: =B16 -> STAG | T16: =VLOOKUP($B16,$S$3:$Y$9,2,FALSE) -> 11.6 | U16: =VLOOKUP($B16,$S$3:$Y$9,3,FALSE) -> 12 | V16: =VLOOKUP($B16,$S$3:$Y$9,4,FALSE) -> 0 | W16: =VLOOKUP($B16,$S$3:$Y$9,5,FALSE) -> 0.11805556 | X16: =VLOOKUP($B16,$S$3:$Y$9,6,FALSE) -> 0.22569444 | Y16: =VLOOKUP($B16,$S$3:$Y$9,7,FALSE) -> 0.26388889 | Z16: =VLOOKUP($B16,$S$3:$AA$9,8,FALSE) -> 0 | AA16: =VLOOKUP($B16,$S$3:$AA$9,9,FALSE) -> 60
B17: STAG | C17: =[24]Brewhouse!$A149 -> ST132 | D17: =[24]Brewhouse!$AD149 -> 53.4 | E17: =[24]Brewhouse!$AG149 -> 50.2 | F17: =[24]Brewhouse!$V149 -> 61 | G17: =[24]Brewhouse!$AE149 -> 11.8 | H17: 11.8 | I17: =[24]Brewhouse!$AS149 -> 98.65418 | J17: =[24]Brewhouse!$AT149 -> 99.77998 | K17: =[24]Brewhouse!$Q149 -> 4.9270073 | L17: =[24]Brewhouse!$P149 -> 57 | M17: =[24]Brewhouse!$U149-[24]Brewhouse!$T149 -> 0.10763889 | N17: =[24]Brewhouse!$AW149 -> 0.26666667 | O17: =[24]Brewhouse!$AV149 -> R.Sookram | P17: 95.370767 | S17: =B17 -> STAG | T17: =VLOOKUP($B17,$S$3:$Y$9,2,FALSE) -> 11.6 | U17: =VLOOKUP($B17,$S$3:$Y$9,3,FALSE) -> 12 | V17: =VLOOKUP($B17,$S$3:$Y$9,4,FALSE) -> 0 | W17: =VLOOKUP($B17,$S$3:$Y$9,5,FALSE) -> 0.11805556 | X17: =VLOOKUP($B17,$S$3:$Y$9,6,FALSE) -> 0.22569444 | Y17: =VLOOKUP($B17,$S$3:$Y$9,7,FALSE) -> 0.26388889 | Z17: =VLOOKUP($B17,$S$3:$AA$9,8,FALSE) -> 0 | AA17: =VLOOKUP($B17,$S$3:$AA$9,9,FALSE) -> 60
P18: 96.39695 | S18: =B18 -> 0 | T18: =VLOOKUP($B18,$S$3:$Y$9,2,FALSE) -> #N/A | U18: =VLOOKUP($B18,$S$3:$Y$9,3,FALSE) -> #N/A | V18: =VLOOKUP($B18,$S$3:$Y$9,4,FALSE) -> #N/A | W18: =VLOOKUP($B18,$S$3:$Y$9,5,FALSE) -> #N/A | X18: =VLOOKUP($B18,$S$3:$Y$9,6,FALSE) -> #N/A | Y18: =VLOOKUP($B18,$S$3:$Y$9,7,FALSE) -> #N/A | Z18: =VLOOKUP($B18,$S$3:$AA$9,8,FALSE) -> #N/A | AA18: =VLOOKUP($B18,$S$3:$AA$9,9,FALSE) -> #N/A
P19: 97.671569 | S19: =B19 -> 0 | T19: =VLOOKUP($B19,$S$3:$Y$9,2,FALSE) -> #N/A | U19: =VLOOKUP($B19,$S$3:$Y$9,3,FALSE) -> #N/A | V19: =VLOOKUP($B19,$S$3:$Y$9,4,FALSE) -> #N/A | W19: =VLOOKUP($B19,$S$3:$Y$9,5,FALSE) -> #N/A | X19: =VLOOKUP($B19,$S$3:$Y$9,6,FALSE) -> #N/A | Y19: =VLOOKUP($B19,$S$3:$Y$9,7,FALSE) -> #N/A | Z19: =VLOOKUP($B19,$S$3:$AA$9,8,FALSE) -> #N/A | AA19: =VLOOKUP($B19,$S$3:$AA$9,9,FALSE) -> #N/A
S20: =B20 -> 0 | T20: =VLOOKUP($B20,$S$3:$Y$9,2,FALSE) -> #N/A | U20: =VLOOKUP($B20,$S$3:$Y$9,3,FALSE) -> #N/A | V20: =VLOOKUP($B20,$S$3:$Y$9,4,FALSE) -> #N/A | W20: =VLOOKUP($B20,$S$3:$Y$9,5,FALSE) -> #N/A | X20: =VLOOKUP($B20,$S$3:$Y$9,6,FALSE) -> #N/A | Y20: =VLOOKUP($B20,$S$3:$Y$9,7,FALSE) -> #N/A | Z20: =VLOOKUP($B20,$S$3:$AA$9,8,FALSE) -> #N/A | AA20: =VLOOKUP($B20,$S$3:$AA$9,9,FALSE) -> #N/A
S21: =B21 -> 0 | T21: =VLOOKUP($B21,$S$3:$Y$9,2,FALSE) -> #N/A | U21: =VLOOKUP($B21,$S$3:$Y$9,3,FALSE) -> #N/A | V21: =VLOOKUP($B21,$S$3:$Y$9,4,FALSE) -> #N/A | W21: =VLOOKUP($B21,$S$3:$Y$9,5,FALSE) -> #N/A | X21: =VLOOKUP($B21,$S$3:$Y$9,6,FALSE) -> #N/A | Y21: =VLOOKUP($B21,$S$3:$Y$9,7,FALSE) -> #N/A | Z21: =VLOOKUP($B21,$S$3:$AA$9,8,FALSE) -> #N/A | AA21: =VLOOKUP($B21,$S$3:$AA$9,9,FALSE) -> #N/A
S22: =B22 -> 0 | T22: =VLOOKUP($B22,$S$3:$Y$9,2,FALSE) -> #N/A | U22: =VLOOKUP($B22,$S$3:$Y$9,3,FALSE) -> #N/A | V22: =VLOOKUP($B22,$S$3:$Y$9,4,FALSE) -> #N/A | W22: =VLOOKUP($B22,$S$3:$Y$9,5,FALSE) -> #N/A | X22: =VLOOKUP($B22,$S$3:$Y$9,6,FALSE) -> #N/A | Y22: =VLOOKUP($B22,$S$3:$Y$9,7,FALSE) -> #N/A | Z22: =VLOOKUP($B22,$S$3:$AA$9,8,FALSE) -> #N/A | AA22: =VLOOKUP($B22,$S$3:$AA$9,9,FALSE) -> #N/A
I23: EXTRACT RECOVERY | S23: =B23 -> 0 | T23: =VLOOKUP($B23,$S$3:$Y$9,2,FALSE) -> #N/A | U23: =VLOOKUP($B23,$S$3:$Y$9,3,FALSE) -> #N/A | V23: =VLOOKUP($B23,$S$3:$Y$9,4,FALSE) -> #N/A | W23: =VLOOKUP($B23,$S$3:$Y$9,5,FALSE) -> #N/A | X23: =VLOOKUP($B23,$S$3:$Y$9,6,FALSE) -> #N/A | Y23: =VLOOKUP($B23,$S$3:$Y$9,7,FALSE) -> #N/A | Z23: =VLOOKUP($B23,$S$3:$AA$9,8,FALSE) -> #N/A | AA23: =VLOOKUP($B23,$S$3:$AA$9,9,FALSE) -> #N/A
B24: BRAND | D24: BBT P.G./ O.G | I24: Brand | J24: Actual | K24: MTD No. of Brews | L24: MTD | M24: YTD | N24: Target | S24: =B24 -> BRAND | T24: =VLOOKUP($B24,$S$3:$Y$9,2,FALSE) -> #N/A | U24: =VLOOKUP($B24,$S$3:$Y$9,3,FALSE) -> #N/A | V24: =VLOOKUP($B24,$S$3:$Y$9,4,FALSE) -> #N/A | W24: =VLOOKUP($B24,$S$3:$Y$9,5,FALSE) -> #N/A | X24: =VLOOKUP($B24,$S$3:$Y$9,6,FALSE) -> #N/A | Y24: =VLOOKUP($B24,$S$3:$Y$9,7,FALSE) -> #N/A | Z24: =VLOOKUP($B24,$S$3:$AA$9,8,FALSE) -> #N/A | AA24: =VLOOKUP($B24,$S$3:$AA$9,9,FALSE) -> #N/A
B25: =I25 -> CARIB | C25: =[23]Process!D296 -> 11.7 | D25: 11.77 | I25: CARIB | M25: =AVERAGE([23]Brewhouse!$AU$102:$AU$171,[23]Brewhouse!$AU$173:$AU$253,[23]Brewhouse!$AU$255:$AU$339) -> 96.788244 | N25: 98
C26: =[23]Process!D297 -> 12 | I26: STAG | J26: =AVERAGE(I12:I17) -> 98.441531 | K26: =COUNTA([24]Brewhouse!$A$142:$A$149) -> 8 | L26: =AVERAGE([24]Brewhouse!$AS$142:$AS$149) -> 98.511345 | M26: =AVERAGE([24]Brewhouse!$AS$15:$AS$64,[24]Brewhouse!$AS$66:$AS$103,[24]Brewhouse!$AS$105:$AS$140,[24]Brewhouse!$AS$142:$AS$149) -> 96.815001 | N26: 98
C27: =[23]Process!D304 -> 11.76 | D27: 11.8 | I27: GUINNESS | K27: =COUNTA([22]Brewhouse!$A$37) -> 1 | L27: =AVERAGE([22]Brewhouse!$AU$37) -> 96.214668 | M27: =AVERAGE([22]Brewhouse!$AU$4:$AU$7,[22]Brewhouse!$AU$9:$AU$22,[22]Brewhouse!$AU$24:$AU$35,[22]Brewhouse!$AU$37) -> 96.767265 | N27: 98
C28: =[23]Process!D305 -> 11.72 | I28: VITAMALT | M28: =AVERAGE([25]Brewhouse!$AV$5:$AV$14,[25]Brewhouse!$AV$16:$AV$19,[25]Brewhouse!$AV$21:$AV$24) -> 98.616017 | N28: 98
C29: =[23]Process!D306 -> 11.78 | D29: 11.84 | I29: MAXIMALT | N29: 98
C30: =[23]Process!D307 -> 11.76 | I30: MACKESON | M30: =AVERAGE([26]Brewhouse!$AT$4:$AT$11) -> 94.812617 | N30: 98
I31: STARMALT | M31: =AVERAGE([27]Brewhouse!$AY$6:$AY$13,[27]Brewhouse!$AY$15:$AY$20,[27]Brewhouse!$AY$22:$AY$29) -> 95.660462 | N31: 98
I32: HR- Pils | M32: =AVERAGE([28]Brewhouse!$AU$5:$AU$8) -> 91.006888 | N32: 98
I33: HR- IPA | N33: 98
I34: HR- APA | N34: 98
K35: =SUM(K25:K34) -> 9 | L35: =((L25*K25)+(L26*K26)+(L27*K27)+(L28*K28)+(L29*K29)+(K32*L32)+(L30*K30)+(L31*K31)+(L34*K34))/(K35) -> 98.256158 | M35: =AVERAGE('[29]Jan 31st'!$L$65,'[30]Feb 28th'!$L$35,L35) -> 96.566378 | N35: 98
B37: =I25 -> CARIB | C37: =[23]Process!D308 -> 11.7 | D37: 12.02 | J37: Daily Brewing Plan
C38: =[23]Process!D309 -> 11.95 | J38: Brand | K38: Brews Achieved | L38: Average Brews per day
C39: =[23]Process!D310 -> 11.93 | D39: 12.05 | J39: CARIB | L39: MTD | M39: YTD | N39: TARGET
C40: =[23]Process!D311 -> 11.8 | J40: STAG | K40: 6 | L40: =AVERAGE('Apr. 1st'!K49,'Apr. 4th'!K49,'Apr. 3rd'!K49) -> 3 | M40: =AVERAGE('[29]Jan 29th '!$M$70,'[30]Feb 28th'!$L$40,'[31]Mar. 31st'!$L$40,L40) -> 5.7038342 | N40: 9.2
J41: GUINN
...

Sheet Apr. 7th 
T1: P.G. | V1: Hot Time | X1: Process Time | Z1: Cooling Time
B2: Brewing Department Daily Process Loss Report | T2: Lower | U2: Upper | V2: Lower | W2: Upper | X2: Lower | Y2: Upper | Z2: Lower | AA2: Upper
S3: CARIB | T3: 11.6 | U3: 12 | V3: 0 | W3: 0.11805556 | X3: 0.22569444 | Y3: 0.26388889 | Z3: 0 | AA3: 60 | AC3: HR- PISNER
B4: Date: | C4: 45755 | J4: LOT WORT COLOUR: 3.3 | M4: Filter Sheets (Target 20 days) | S4: STAG | T4: 11.6 | U4: 12 | V4: 0 | W4: 0.11805556 | X4: 0.22569444 | Y4: 0.26388889 | Z4: 0 | AA4: 60
M5: Double | N5: Single | S5: GUINNESS | T5: 17 | U5: 17.5 | V5: 0 | W5: 0.10763889 | X5: 0.24652778 | Y5: 0.28472222 | Z5: 0 | AA5: 60
J6: MALT LOT: Lot 29/ 33 | L6: Sheet Day | M6: 12 | N6: 10 | S6: MACKESON | T6: 13.3 | U6: 13.5 | V6: 0 | W6: 0.12905093 | X6: 0.27430556 | Y6: 0.30208333 | Z6: 0
S7: STARMALT | T7: 17.1 | U7: 17.5 | V7: 0 | W7: 0.13605324 | X7: 0.27430556 | Y7: 0.30902778 | Z7: 0 | AA7: 60
B8: Brand | C8: Brew no. | D8: Kett. Hls | E8: Wort | F8: Cool Time(Mins) | G8: Cast. P.G. (Lab Result) | H8: Cast P.G. (Cellar Operator)-gravity | I8: Extr. Rec (80.9%) | J8: Theor. Extr. (77.5%) | K8: Boil Off /Vol. (4-6%) | L8: Boil Time | M8: Total Hot | N8: Brewing | O8: Operator | P8: Cellars Vol. Extr | Q8: Actual Pilsen Malt | S8: Hurricane Reef | T8: 16.6 | U8: 17 | V8: 0 | W8: 0.12905093 | X8: 0.27430556 | Y8: 0.30208333 | Z8: 0
E9: Meter (Hls) | F9: Target(< 60Mins) | M9: Time | S9: VITAMALT | T9: 14.4 | U9: 14.6 | V9: 0 | W9: 0.13905093 | X9: 0.26041667 | Y9: 0.29513889 | Z9: 0 | AA9: 75
B10: CARIB | C10: =[23]Brewhouse!$A341 -> CA237 | D10: =[23]Brewhouse!$AF341 -> 52.5 | E10: =[23]Brewhouse!$AI341 -> 48.4 | F10: =[23]Brewhouse!$V341 -> 56 | G10: =[23]Brewhouse!$AG341 -> 12 | H10: 11.8 | I10: =[23]Brewhouse!$AU341 -> 95.054952 | J10: =[23]Brewhouse!$AV341 -> 96.311757 | K10: =[23]Brewhouse!$Q341 -> 8.6764706 | L10: =[23]Brewhouse!$P341 -> 64 | M10: =[23]Brewhouse!$U341-[23]Brewhouse!$T341 -> 0.11458333 | N10: =[23]Brewhouse!$Z341 -> 0.25902778 | O10: =[23]Brewhouse!$AX341 -> K.Benjamin | S10: =B10 -> CARIB | T10: =VLOOKUP($B10,$S$3:$Y$9,2,FALSE) -> 11.6 | U10: =VLOOKUP($B10,$S$3:$Y$9,3,FALSE) -> 12 | V10: =VLOOKUP($B10,$S$3:$Y$9,4,FALSE) -> 0 | W10: =VLOOKUP($B10,$S$3:$Y$9,5,FALSE) -> 0.11805556 | X10: =VLOOKUP($B10,$S$3:$Y$9,6,FALSE) -> 0.22569444 | Y10: =VLOOKUP($B10,$S$3:$Y$9,7,FALSE) -> 0.26388889 | Z10: =VLOOKUP($B10,$S$3:$AA$9,8,FALSE) -> 0 | AA10: =VLOOKUP($B10,$S$3:$AA$9,9,FALSE) -> 60
B11: CARIB | C11: =[23]Brewhouse!$A342 -> CA238 | D11: =[23]Brewhouse!$AF342 -> 53.8 | E11: =[23]Brewhouse!$AI342 -> 50 | F11: =[23]Brewhouse!$V342 -> 57 | G11: =[23]Brewhouse!$AG342 -> 12 | H11: 11.7 | I11: =[23]Brewhouse!$AU342 -> 98.197264 | J11: =[23]Brewhouse!$AV342 -> 99.495617 | K11: =[23]Brewhouse!$Q342 -> 7.4909091 | L11: =[23]Brewhouse!$P342 -> 57 | M11: =[23]Brewhouse!$U342-[23]Brewhouse!$T342 -> 0.10486111 | N11: =[23]Brewhouse!$Z342 -> 0.26111111 | O11: =[23]Brewhouse!$AX342 -> K.Benjamin | S11: =B11 -> CARIB | T11: =VLOOKUP($B11,$S$3:$Y$9,2,FALSE) -> 11.6 | U11: =VLOOKUP($B11,$S$3:$Y$9,3,FALSE) -> 12 | V11: =VLOOKUP($B11,$S$3:$Y$9,4,FALSE) -> 0 | W11: =VLOOKUP($B11,$S$3:$Y$9,5,FALSE) -> 0.11805556 | X11: =VLOOKUP($B11,$S$3:$Y$9,6,FALSE) -> 0.22569444 | Y11: =VLOOKUP($B11,$S$3:$Y$9,7,FALSE) -> 0.26388889 | Z11: =VLOOKUP($B11,$S$3:$AA$9,8,FALSE) -> 0 | AA11: =VLOOKUP($B11,$S$3:$AA$9,9,FALSE) -> 60
B12: CARIB | C12: =[23]Brewhouse!$A343 -> CA239 | D12: =[23]Brewhouse!$AF343 -> 54.3 | E12: =[23]Brewhouse!$AI343 -> 50.7 | F12: =[23]Brewhouse!$V343 -> 61 | G12: =[23]Brewhouse!$AG343 -> 11.7 | H12: 11.7 | I12: =[23]Brewhouse!$AU343 -> 97.890696 | J12: =[23]Brewhouse!$AV343 -> 99.240154 | K12: =[23]Brewhouse!$Q343 -> 7.477314 | L12: =[23]Brewhouse!$P343 -> 60 | M12: =[23]Brewhouse!$U343-[23]Brewhouse!$T343 -> 0.11319444 | N12: =[23]Brewhouse!$Z343 -> 0.24513889 | O12: =[23]Brewhouse!$AX343 -> R. Regis | S12: =B12 -> CARIB | T12: =VLOOKUP($B12,$S$3:$Y$9,2,FALSE) -> 11.6 | U12: =VLOOKUP($B12,$S$3:$Y$9,3,FALSE) -> 12 | V12: =VLOOKUP($B12,$S$3:$Y$9,4,FALSE) -> 0 | W12: =VLOOKUP($B12,$S$3:$Y$9,5,FALSE) -> 0.11805556 | X12: =VLOOKUP($B12,$S$3:$Y$9,6,FALSE) -> 0.22569444 | Y12: =VLOOKUP($B12,$S$3:$Y$9,7,FALSE) -> 0.26388889 | Z12: =VLOOKUP($B12,$S$3:$AA$9,8,FALSE) -> 0 | AA12: =VLOOKUP($B12,$S$3:$AA$9,9,FALSE) -> 60
B13: CARIB | C13: =[23]Brewhouse!$A344 -> CA240 | D13: =[23]Brewhouse!$AF344 -> 53.9 | E13: =[23]Brewhouse!$AI344 -> 50.3 | F13: =[23]Brewhouse!$V344 -> 60 | G13: =[23]Brewhouse!$AG344 -> 11.8 | H13: 11.8 | I13: =[23]Brewhouse!$AU344 -> 97.267564 | J13: =[23]Brewhouse!$AV344 -> 98.608871 | K13: =[23]Brewhouse!$Q344 -> 7.2563177 | L13: =[23]Brewhouse!$P344 -> 60 | M13: =[23]Brewhouse!$U344-[23]Brewhouse!$T344 -> 0.12013889 | N13: =[23]Brewhouse!$Z344 -> 0.25763889 | O13: =[23]Brewhouse!$AX344 -> R. Regis | S13: =B13 -> CARIB | T13: =VLOOKUP($B13,$S$3:$Y$9,2,FALSE) -> 11.6 | U13: =VLOOKUP($B13,$S$3:$Y$9,3,FALSE) -> 12 | V13: =VLOOKUP($B13,$S$3:$Y$9,4,FALSE) -> 0 | W13: =VLOOKUP($B13,$S$3:$Y$9,5,FALSE) -> 0.11805556 | X13: =VLOOKUP($B13,$S$3:$Y$9,6,FALSE) -> 0.22569444 | Y13: =VLOOKUP($B13,$S$3:$Y$9,7,FALSE) -> 0.26388889 | Z13: =VLOOKUP($B13,$S$3:$AA$9,8,FALSE) -> 0 | AA13: =VLOOKUP($B13,$S$3:$AA$9,9,FALSE) -> 60
B14: CARIB | C14: =[23]Brewhouse!$A345 -> CA241 | D14: =[23]Brewhouse!$AF345 -> 55.4 | E14: =[23]Brewhouse!$AI345 -> 51.8 | F14: =[23]Brewhouse!$V345 -> 60 | G14: =[23]Brewhouse!$AG345 -> 11.8 | H14: 11.8 | I14: =[23]Brewhouse!$AU345 -> 100.78902 | J14: =[23]Brewhouse!$AV345 -> 102.17851 | K14: =[23]Brewhouse!$Q345 -> 6.4991023 | L14: =[23]Brewhouse!$P345 -> 58 | M14: =[23]Brewhouse!$U345-[23]Brewhouse!$T345 -> 0.10833333 | N14: =[23]Brewhouse!$Z345 -> 0.25277778 | O14: =[23]Brewhouse!$AX345 -> R.Sookram | S14: =B14 -> CARIB | T14: =VLOOKUP($B14,$S$3:$Y$9,2,FALSE) -> 11.6 | U14: =VLOOKUP($B14,$S$3:$Y$9,3,FALSE) -> 12 | V14: =VLOOKUP($B14,$S$3:$Y$9,4,FALSE) -> 0 | W14: =VLOOKUP($B14,$S$3:$Y$9,5,FALSE) -> 0.11805556 | X14: =VLOOKUP($B14,$S$3:$Y$9,6,FALSE) -> 0.22569444 | Y14: =VLOOKUP($B14,$S$3:$Y$9,7,FALSE) -> 0.26388889 | Z14: =VLOOKUP($B14,$S$3:$AA$9,8,FALSE) -> 0 | AA14: =VLOOKUP($B14,$S$3:$AA$9,9,FALSE) -> 60
B15: CARIB | C15: =[23]Brewhouse!$A346 -> CA242 | D15: =[23]Brewhouse!$AF346 -> 53.2 | E15: =[23]Brewhouse!$AI346 -> 49.9 | F15: =[23]Brewhouse!$V346 -> 62 | G15: =[23]Brewhouse!$AG346 -> 11.8 | I15: =[23]Brewhouse!$AU346 -> 97.09213 | J15: =[23]Brewhouse!$AV346 -> 98.430652 | K15: =[23]Brewhouse!$Q346 -> 6.118068 | L15: =[23]Brewhouse!$P346 -> 57 | M15: =[23]Brewhouse!$U346-[23]Brewhouse!$T346 -> 0.10625 | N15: =[23]Brewhouse!$Z346 -> 0.24652778 | O15: =[23]Brewhouse!$AX346 -> R.Sookram | S15: =B15 -> CARIB | T15: =VLOOKUP($B15,$S$3:$Y$9,2,FALSE) -> 11.6 | U15: =VLOOKUP($B15,$S$3:$Y$9,3,FALSE) -> 12 | V15: =VLOOKUP($B15,$S$3:$Y$9,4,FALSE) -> 0 | W15: =VLOOKUP($B15,$S$3:$Y$9,5,FALSE) -> 0.11805556 | X15: =VLOOKUP($B15,$S$3:$Y$9,6,FALSE) -> 0.22569444 | Y15: =VLOOKUP($B15,$S$3:$Y$9,7,FALSE) -> 0.26388889 | Z15: =VLOOKUP($B15,$S$3:$AA$9,8,FALSE) -> 0 | AA15: =VLOOKUP($B15,$S$3:$AA$9,9,FALSE) -> 60
B16: CARIB | C16: =[23]Brewhouse!$A347 -> CA243 | D16: =[23]Brewhouse!$AF347 -> 55.7 | E16: =[23]Brewhouse!$AI347 -> 52.2 | F16: =[23]Brewhouse!$V347 -> 63 | G16: Missing Brew data.. Dump? Placed in tank? | K16: =[23]Brewhouse!$Q347 -> 5.4121864 | L16: =[23]Brewhouse!$P347 -> 62 | M16: =[23]Brewhouse!$U347-[23]Brewhouse!$T347 -> 0.11527778 | N16: =[23]Brewhouse!$Z347 -> 0.25347222 | O16: =[23]Brewhouse!$AX347 -> R.Sookram | S16: =B16 -> CARIB | T16: =VLOOKUP($B16,$S$3:$Y$9,2,FALSE) -> 11.6 | U16: =VLOOKUP($B16,$S$3:$Y$9,3,FALSE) -> 12 | V16: =VLOOKUP($B16,$S$3:$Y$9,4,FALSE) -> 0 | W16: =VLOOKUP($B16,$S$3:$Y$9,5,FALSE) -> 0.11805556 | X16: =VLOOKUP($B16,$S$3:$Y$9,6,FALSE) -> 0.22569444 | Y16: =VLOOKUP($B16,$S$3:$Y$9,7,FALSE) -> 0.26388889 | Z16: =VLOOKUP($B16,$S$3:$AA$9,8,FALSE) -> 0 | AA16: =VLOOKUP($B16,$S$3:$AA$9,9,FALSE) -> 60
B17: CARIB | C17: =[23]Brewhouse!$A348 -> CA244 | D17: =[23]Brewhouse!$AF348 -> 52.1 | E17: =[23]Brewhouse!$AI348 -> 49.9 | F17: =[23]Brewhouse!$V348 -> 63 | G17: =[23]Brewhouse!$AG348 -> 11.7 | H17: 11.9 | I17: =[23]Brewhouse!$AU348 -> 96.34607 | J17: =[23]Brewhouse!$AV348 -> 97.674234 | K17: =[23]Brewhouse!$Q348 -> 7.2563177 | L17: =[23]Brewhouse!$P348 -> 59 | M17: =[23]Brewhouse!$U348-[23]Brewhouse!$T348 -> 0.11944444 | N17: =[23]Brewhouse!$Z348 -> 0.25625 | O17: =[23]Brewhouse!$AX348 -> K.Benjamin | S17: =B17 -> CARIB | T17: =VLOOKUP($B17,$S$3:$Y$9,2,FALSE) -> 11.6 | U17: =VLOOKUP($B17,$S$3:$Y$9,3,FALSE) -> 12 | V17: =VLOOKUP($B17,$S$3:$Y$9,4,FALSE) -> 0 | W17: =VLOOKUP($B17,$S$3:$Y$9,5,FALSE) -> 0.11805556 | X17: =VLOOKUP($B17,$S$3:$Y$9,6,FALSE) -> 0.22569444 | Y17: =VLOOKUP($B17,$S$3:$Y$9,7,FALSE) -> 0.26388889 | Z17: =VLOOKUP($B17,$S$3:$AA$9,8,FALSE) -> 0 | AA17: =VLOOKUP($B17,$S$3:$AA$9,9,FALSE) -> 60
S18: =B18 -> 0 | T18: =VLOOKUP($B18,$S$3:$Y$9,2,FALSE) -> #N/A | U18: =VLOOKUP($B18,$S$3:$Y$9,3,FALSE) -> #N/A | V18: =VLOOKUP($B18,$S$3:$Y$9,4,FALSE) -> #N/A | W18: =VLOOKUP($B18,$S$3:$Y$9,5,FALSE) -> #N/A | X18: =VLOOKUP($B18,$S$3:$Y$9,6,FALSE) -> #N/A | Y18: =VLOOKUP($B18,$S$3:$Y$9,7,FALSE) -> #N/A | Z18: =VLOOKUP($B18,$S$3:$AA$9,8,FALSE) -> #N/A | AA18: =VLOOKUP($B18,$S$3:$AA$9,9,FALSE) -> #N/A
B19: STARMALT | C19: =[27]Brewhouse!$A31 -> SM023 | D19: =[27]Brewhouse!$AH31 -> 52.2 | E19: =[27]Brewhouse!$AM31 -> 50.8 | F19: =[27]Brewhouse!$Z31 -> 64 | G19: =[27]Brewhouse!$AK31 -> 17.5 | I19: =[27]Brewhouse!$AY31 -> 97.699495 | J19: =[27]Brewhouse!$AZ31 -> 98.349954 | K19: =[27]Brewhouse!$U31 -> 3.0268199 | L19: =[27]Brewhouse!$T31 -> 60 | M19: =[27]Brewhouse!$Y31-[27]Brewhouse!$X31 -> 0.12986111 | N19: =[27]Brewhouse!$AD31 -> 0.28611111 | O19: =[27]Brewhouse!$BC31 -> K. Benjamin | S19: =B19 -> STARMALT | T19: =VLOOKUP($B19,$S$3:$Y$9,2,FALSE) -> 17.1 | U19: =VLOOKUP($B19,$S$3:$Y$9,3,FALSE) -> 17.5 | V19: =VLOOKUP($B19,$S$3:$Y$9,4,FALSE) -> 0 | W19: =VLOOKUP($B19,$S$3:$Y$9,5,FALSE) -> 0.13605324 | X19: =VLOOKUP($B19,$S$3:$Y$9,6,FALSE) -> 0.27430556 | Y19: =VLOOKUP($B19,$S$3:$Y$9,7,FALSE) -> 0.30902778 | Z19: =VLOOKUP($B19,$S$3:$AA$9,8,FALSE) -> 0 | AA19: =VLOOKUP($B19,$S$3:$AA$9,9,FALSE) -> 60
S20: =B20 -> 0 | T20: =VLOOKUP($B20,$S$3:$Y$9,2,FALSE) -> #N/A | U20: =VLOOKUP($B20,$S$3:$Y$9,3,FALSE) -> #N/A | V20: =VLOOKUP($B20,$S$3:$Y$9,4,FALSE) -> #N/A | W20: =VLOOKUP($B20,$S$3:$Y$9,5,FALSE) -> #N/A | X20: =VLOOKUP($B20,$S$3:$Y$9,6,FALSE) -> #N/A | Y20: =VLOOKUP($B20,$S$3:$Y$9,7,FALSE) -> #N/A | Z20: =VLOOKUP($B20,$S$3:$AA$9,8,FALSE) -> #N/A | AA20: =VLOOKUP($B20,$S$3:$AA$9,9,FALSE) -> #N/A
S21: =B21 -> 0 | T21: =VLOOKUP($B21,$S$3:$Y$9,2,FALSE) -> #N/A | U21: =VLOOKUP($B21,$S$3:$Y$9,3,FALSE) -> #N/A | V21: =VLOOKUP($B21,$S$3:$Y$9,4,FALSE) -> #N/A | W21: =VLOOKUP($B21,$S$3:$Y$9,5,FALSE) -> #N/A | X21: =VLOOKUP($B21,$S$3:$Y$9,6,FALSE) -> #N/A | Y21: =VLOOKUP($B21,$S$3:$Y$9,7,FALSE) -> #N/A | Z21: =VLOOKUP($B21,$S$3:$AA$9,8,FALSE) -> #N/A | AA21: =VLOOKUP($B21,$S$3:$AA$9,9,FALSE) -> #N/A
S22: =B22 -> 0 | T22: =VLOOKUP($B22,$S$3:$Y$9,2,FALSE) -> #N/A | U22: =VLOOKUP($B22,$S$3:$Y$9,3,FALSE) -> #N/A | V22: =VLOOKUP($B22,$S$3:$Y$9,4,FALSE) -> #N/A | W22: =VLOOKUP($B22,$S$3:$Y$9,5,FALSE) -> #N/A | X22: =VLOOKUP($B22,$S$3:$Y$9,6,FALSE) -> #N/A | Y22: =VLOOKUP($B22,$S$3:$Y$9,7,FALSE) -> #N/A | Z22: =VLOOKUP($B22,$S$3:$AA$9,8,FALSE) -> #N/A | AA22: =VLOOKUP($B22,$S$3:$AA$9,9,FALSE) -> #N/A
S23: =B23 -> 0 | T23: =VLOOKUP($B23,$S$3:$Y$9,2,FALSE) -> #N/A | U23: =VLOOKUP($B23,$S$3:$Y$9,3,FALSE) -> #N/A | V23: =VLOOKUP($B23,$S$3:$Y$9,4,FALSE) -> #N/A | W23: =VLOOKUP($B23,$S$3:$Y$9,5,FALSE) -> #N/A | X23: =VLOOKUP($B23,$S$3:$Y$9,6,FALSE) -> #N/A | Y23: =VLOOKUP($B23,$S$3:$Y$9,7,FALSE) -> #N/A | Z23: =VLOOKUP($B23,$S$3:$AA$9,8,FALSE) -> #N/A | AA23: =VLOOKUP($B23,$S$3:$AA$9,9,FALSE) -> #N/A
I24: EXTRACT RECOVERY | S24: =B24 -> 0 | T24: =VLOOKUP($B24,$S$3:$Y$9,2,FALSE) -> #N/A | U24: =VLOOKUP($B24,$S$3:$Y$9,3,FALSE) -> #N/A | V24: =VLOOKUP($B24,$S$3:$Y$9,4,FALSE) -> #N/A | W24: =VLOOKUP($B24,$S$3:$Y$9,5,FALSE) -> #N/A | X24: =VLOOKUP($B24,$S$3:$Y$9,6,FALSE) -> #N/A | Y24: =VLOOKUP($B24,$S$3:$Y$9,7,FALSE) -> #N/A | Z24: =VLOOKUP($B24,$S$3:$AA$9,8,FALSE) -> #N/A | AA24: =VLOOKUP($B24,$S$3:$AA$9,9,FALSE) -> #N/A
B25: BRAND | D25: BBT P.G./ O.G | I25: Brand | J25: Actual | K25: MTD No. of Brews | L25: MTD | M25: YTD | N25: Target | S25: =B25 -> BRAND | T25: =VLOOKUP($B25,$S$3:$Y$9,2,FALSE) -> #N/A | U25: =VLOOKUP($B25,$S$3:$Y$9,3,FALSE) -> #N/A | V25: =VLOOKUP($B25,$S$3:$Y$9,4,FALSE) -> #N/A | W25: =VLOOKUP($B25,$S$3:$Y$9,5,FALSE) -> #N/A | X25: =VLOOKUP($B25,$S$3:$Y$9,6,FALSE) -> #N/A | Y25: =VLOOKUP($B25,$S$3:$Y$9,7,FALSE) -> #N/A | Z25: =VLOOKUP($B25,$S$3:$AA$9,8,FALSE) -> #N/A | AA25: =VLOOKUP($B25,$S$3:$AA$9,9,FALSE) -> #N/A
B26: =I26 -> CARIB | C26: {=[23]Process!$D$296:$D$301} -> 11.7 | D26: 11.9 | I26: CARIB | J26: =AVERAGE(I10:I15,I17) -> 97.519671 | K26: =COUNTA([23]Brewhouse!$A$341:$A$348) -> 8 | L26: =AVERAGE([23]Brewhouse!$AU$341:$AU$346,[23]Brewhouse!$AU$348) -> 97.519671 | M26: =AVERAGE([23]Brewhouse!$AU$102:$AU$171,[23]Brewhouse!$AU$173:$AU$253,[23]Brewhouse!$AU$255:$AU$339,[23]Brewhouse!$AU$341:$AU$346,[23]Brewhouse!$AU$348) -> 96.809313 | N26: 98
C27: 12 | I27: STAG | K27: =COUNTA([24]Brewhouse!$A$142:$A$149) -> 8 | L27: =AVERAGE([24]Brewhouse!$AS$142:$AS$149) -> 98.511345 | M27: =AVERAGE([24]Brewhouse!$AS$15:$AS$64,[24]Brewhouse!$AS$66:$AS$103,[24]Brewhouse!$AS$105:$AS$140,[24]Brewhouse!$AS$142:$AS$149) -> 96.815001 | N27: 98
C28: 12.4 | D28: 11.85 | I28: GUINNESS | K28: =COUNTA([22]Brewhouse!$A$37) -> 1 | L28: =AVERAGE([22]Brewhouse!$AU$37) -> 96.214668 | M28: =AVERAGE([22]Brewhouse!$AU$4:$AU$7,[22]Brewhouse!$AU$9:$AU$22,[22]Brewhouse!$AU$24:$AU$35,[22]Brewhouse!$AU$37) -> 96.767265 | N28: 98
C29: 11.88 | I29: VITAMALT | M29: =AVERAGE([25]Brewhouse!$AV$5:$AV$14,[25]Brewhouse!$AV$16:$AV$19,[25]Brewhouse!$AV$21:$AV$24) -> 98.616017 | N29: 98
C30: 11.9 | D30: 12.19 | I30: MAXIMALT | N30: 98
C31: 11.91 | I31: MACKESON | M31: =AVERAGE([26]Brewhouse!$AT$4:$AT$11) -> 94.812617 | N31: 98
C32: =[23]Process!$D$295 -> 11.64 | D32: 12 | I32: STARMALT | J32: =I19 -> 97.699495 | K32: =COUNTA([27]Brewhouse!$A$31) -> 1 | L32: =AVERAGE([27]Brewhouse!$AY$31) -> 97.699495 | M32: =AVERAGE([27]Brewhouse!$AY$6:$AY$13,[27]Brewhouse!$AY$15:$AY$20,[27]Brewhouse!$AY$22:$AY$29,[27]Brewhouse!$AY$31) -> 95.749116 | N32: 98
C33: =[23]Process!$D$286 -> 11.8 | I33: HR- Pils | M33: =AVERAGE([28]Brewhouse!$AU$5:$AU$8) -> 91.006888 | N33: 98
I34: HR- IPA | N34: 98
I35: HR- APA | N35: 98
K36: =SUM(K26:K35) -> 18 | L36: =((L26*K26)+(L27*K27)+(L28*K28)+(L29*K29)+(L30*K30)+(K33*L33)+(L31*K31)+(L32*K32)+(L35*K35))/(K36) -> 97.897905 | M36: =AVERAGE('[29]Jan 31st'!$L$65,'[30]Feb 28th'!$L$35,'[31]Mar. 31st'!$L$35,L36) -> 97.01578 | N36: 98
B38: =I26 -> CARIB | C38: {=[23]Process!$D$316:$D$319} -> 11.99 | D38: 11.7 | J38: Daily Brewing Plan
C39: 11.91 | J39: Brand | K39: Brews Achieved | L39: Average Brews per day
C40: 11.95 | D40: 11.97 | J40: CARIB | K40: 8 | L40: MTD | M40: YTD | N40: TARGET
C41: 12 | J41: STAG | L41: =AVERAGE('Apr. 1st'!K49,'Apr. 7th '!K50,'Apr. 3rd'!K49,'Apr. 4th'!K49) -> 4.5 | M41: =AVERAGE('[29]Jan 29th '!$M$70,'[30]Feb 28th'!$L$40,'[31]Mar. 31st'!$L$40,L41) -> 6.0788342 | N41: 9.2
...

Sheet Apr. 8th  
T1: P.G. | V1: Hot Time | X1: Process Time | Z1: Cooling Time
B2: Brewing Department Daily Process Loss Report | T2: Lower | U2: Upper | V2: Lower | W2: Upper | X2: Lower | Y2: Upper | Z2: Lower | AA2: Upper
S3: CARIB | T3: 11.6 | U3: 12 | V3: 0 | W3: 0.11805556 | X3: 0.22569444 | Y3: 0.26388889 | Z3: 0 | AA3: 60 | AC3: HR- PISNER
