Workbook
Name ProductList: [1]November15!$R$3:$R$9
Name ProductList: [2]November15!$R$3:$R$9

Sheet Dec 18th
T1: P.G. | V1: Hot Time | X1: Process Time | Z1: Cooling Time
B2: Brewing Department Daily Process Loss Report | T2: Lower | U2: Upper | V2: Lower | W2: Upper | X2: Lower | Y2: Upper | Z2: Lower | AA2: Upper
S3: CARIB | T3: 11.6 | U3: 12 | V3: 0 | W3: 0.11805556 | X3: 0.17361111 | Y3: 0.21180556 | Z3: 0 | AA3: 60 | AC3: HR- PISNER
B4: Date: | C4: 45278 | J4: LOT WORT COLOUR: 3.4 | M4: Filter Sheets (Target 20 days) | S4: STAG | T4: 11.6 | U4: 12 | V4: 0 | W4: 0.11805556 | X4: 0.17361111 | Y4: 0.21180556 | Z4: 0 | AA4: 60
M5: Double | N5: Single | S5: GUINNESS | T5: 17 | U5: 17.5 | V5: 0 | W5: 0.10763889 | X5: 0.19444444 | Y5: 0.23263889 | Z5: 0 | AA5: 60
J6: MALT LOT: Lot 8 | L6: Sheet Day | S6: MACKESON | T6: 13.3 | U6: 13.5 | V6: 0 | W6: 0.12905093 | X6: 0.22222222 | Y6: 0.25347222 | Z6: 0
S7: STARMALT | T7: 17.1 | U7: 17.5 | V7: 0 | W7: 0.13605324 | X7: 0.20833333 | Y7: 0.24305556 | Z7: 0 | AA7: 60
B8: Brand | C8: Brew no. | D8: Kett. Hls | E8: Wort | F8: Cool Time(Mins) | G8: Cast. P.G. (Lab Result) | H8: Cast P.G. (Cellar Operator)-gravity | I8: Extr. Rec (79.1%) | J8: Theor. Extr. (77.5%) | K8: Boil Off /Vol. (4-6%) | L8: Boil Time | M8: Total Hot | N8: Brewing | P8: Comments | Q8: Actual Pilsen Malt | S8: Hurricane Reef | T8: 16.6 | U8: 17 | V8: 0 | W8: 0.12905093 | X8: 0.22222222 | Y8: 0.25347222 | Z8: 0
E9: Meter (Hls) | F9: Target(< 60Mins) | M9: Time | S9: VITAMALT | T9: 14.4 | U9: 14.6 | V9: 0 | W9: 0.13905093 | X9: 0.19097222 | Y9: 0.22569444 | Z9: 0 | AA9: 75
S10: =B10 -> 0 | T10: =VLOOKUP($B10,$S$3:$Y$9,2,FALSE) -> #N/A | U10: =VLOOKUP($B10,$S$3:$Y$9,3,FALSE) -> #N/A | V10: =VLOOKUP($B10,$S$3:$Y$9,4,FALSE) -> #N/A | W10: =VLOOKUP($B10,$S$3:$Y$9,5,FALSE) -> #N/A | X10: =VLOOKUP($B10,$S$3:$Y$9,6,FALSE) -> #N/A | Y10: =VLOOKUP($B10,$S$3:$Y$9,7,FALSE) -> #N/A | Z10: =VLOOKUP($B10,$S$3:$AA$9,8,FALSE) -> #N/A | AA10: =VLOOKUP($B10,$S$3:$AA$9,9,FALSE) -> #N/A
S11: =B11 -> 0 | T11: =VLOOKUP($B11,$S$3:$Y$9,2,FALSE) -> #N/A | U11: =VLOOKUP($B11,$S$3:$Y$9,3,FALSE) -> #N/A | V11: =VLOOKUP($B11,$S$3:$Y$9,4,FALSE) -> #N/A | W11: =VLOOKUP($B11,$S$3:$Y$9,5,FALSE) -> #N/A | X11: =VLOOKUP($B11,$S$3:$Y$9,6,FALSE) -> #N/A | Y11: =VLOOKUP($B11,$S$3:$Y$9,7,FALSE) -> #N/A | Z11: =VLOOKUP($B11,$S$3:$AA$9,8,FALSE) -> #N/A | AA11: =VLOOKUP($B11,$S$3:$AA$9,9,FALSE) -> #N/A
S12: =B12 -> 0 | T12: =VLOOKUP($B12,$S$3:$Y$9,2,FALSE) -> #N/A | U12: =VLOOKUP($B12,$S$3:$Y$9,3,FALSE) -> #N/A | V12: =VLOOKUP($B12,$S$3:$Y$9,4,FALSE) -> #N/A | W12: =VLOOKUP($B12,$S$3:$Y$9,5,FALSE) -> #N/A | X12: =VLOOKUP($B12,$S$3:$Y$9,6,FALSE) -> #N/A | Y12: =VLOOKUP($B12,$S$3:$Y$9,7,FALSE) -> #N/A | Z12: =VLOOKUP($B12,$S$3:$AA$9,8,FALSE) -> #N/A | AA12: =VLOOKUP($B12,$S$3:$AA$9,9,FALSE) -> #N/A
S13: =B13 -> 0 | T13: =VLOOKUP($B13,$S$3:$Y$9,2,FALSE) -> #N/A | U13: =VLOOKUP($B13,$S$3:$Y$9,3,FALSE) -> #N/A | V13: =VLOOKUP($B13,$S$3:$Y$9,4,FALSE) -> #N/A | W13: =VLOOKUP($B13,$S$3:$Y$9,5,FALSE) -> #N/A | X13: =VLOOKUP($B13,$S$3:$Y$9,6,FALSE) -> #N/A | Y13: =VLOOKUP($B13,$S$3:$Y$9,7,FALSE) -> #N/A | Z13: =VLOOKUP($B13,$S$3:$AA$9,8,FALSE) -> #N/A | AA13: =VLOOKUP($B13,$S$3:$AA$9,9,FALSE) -> #N/A
S14: =B14 -> 0 | T14: =VLOOKUP($B14,$S$3:$Y$9,2,FALSE) -> #N/A | U14: =VLOOKUP($B14,$S$3:$Y$9,3,FALSE) -> #N/A | V14: =VLOOKUP($B14,$S$3:$Y$9,4,FALSE) -> #N/A | W14: =VLOOKUP($B14,$S$3:$Y$9,5,FALSE) -> #N/A | X14: =VLOOKUP($B14,$S$3:$Y$9,6,FALSE) -> #N/A | Y14: =VLOOKUP($B14,$S$3:$Y$9,7,FALSE) -> #N/A | Z14: =VLOOKUP($B14,$S$3:$AA$9,8,FALSE) -> #N/A | AA14: =VLOOKUP($B14,$S$3:$AA$9,9,FALSE) -> #N/A
S15: =B15 -> 0 | T15: =VLOOKUP($B15,$S$3:$Y$9,2,FALSE) -> #N/A | U15: =VLOOKUP($B15,$S$3:$Y$9,3,FALSE) -> #N/A | V15: =VLOOKUP($B15,$S$3:$Y$9,4,FALSE) -> #N/A | W15: =VLOOKUP($B15,$S$3:$Y$9,5,FALSE) -> #N/A | X15: =VLOOKUP($B15,$S$3:$Y$9,6,FALSE) -> #N/A | Y15: =VLOOKUP($B15,$S$3:$Y$9,7,FALSE) -> #N/A | Z15: =VLOOKUP($B15,$S$3:$AA$9,8,FALSE) -> #N/A | AA15: =VLOOKUP($B15,$S$3:$AA$9,9,FALSE) -> #N/A
S16: =B16 -> 0 | T16: =VLOOKUP($B16,$S$3:$Y$9,2,FALSE) -> #N/A | U16: =VLOOKUP($B16,$S$3:$Y$9,3,FALSE) -> #N/A | V16: =VLOOKUP($B16,$S$3:$Y$9,4,FALSE) -> #N/A | W16: =VLOOKUP($B16,$S$3:$Y$9,5,FALSE) -> #N/A | X16: =VLOOKUP($B16,$S$3:$Y$9,6,FALSE) -> #N/A | Y16: =VLOOKUP($B16,$S$3:$Y$9,7,FALSE) -> #N/A | Z16: =VLOOKUP($B16,$S$3:$AA$9,8,FALSE) -> #N/A | AA16: =VLOOKUP($B16,$S$3:$AA$9,9,FALSE) -> #N/A
S17: =B17 -> 0 | T17: =VLOOKUP($B17,$S$3:$Y$9,2,FALSE) -> #N/A | U17: =VLOOKUP($B17,$S$3:$Y$9,3,FALSE) -> #N/A | V17: =VLOOKUP($B17,$S$3:$Y$9,4,FALSE) -> #N/A | W17: =VLOOKUP($B17,$S$3:$Y$9,5,FALSE) -> #N/A | X17: =VLOOKUP($B17,$S$3:$Y$9,6,FALSE) -> #N/A | Y17: =VLOOKUP($B17,$S$3:$Y$9,7,FALSE) -> #N/A | Z17: =VLOOKUP($B17,$S$3:$AA$9,8,FALSE) -> #N/A | AA17: =VLOOKUP($B17,$S$3:$AA$9,9,FALSE) -> #N/A
S18: =B18 -> 0 | T18: =VLOOKUP($B18,$S$3:$Y$9,2,FALSE) -> #N/A | U18: =VLOOKUP($B18,$S$3:$Y$9,3,FALSE) -> #N/A | V18: =VLOOKUP($B18,$S$3:$Y$9,4,FALSE) -> #N/A | W18: =VLOOKUP($B18,$S$3:$Y$9,5,FALSE) -> #N/A | X18: =VLOOKUP($B18,$S$3:$Y$9,6,FALSE) -> #N/A | Y18: =VLOOKUP($B18,$S$3:$Y$9,7,FALSE) -> #N/A | Z18: =VLOOKUP($B18,$S$3:$AA$9,8,FALSE) -> #N/A | AA18: =VLOOKUP($B18,$S$3:$AA$9,9,FALSE) -> #N/A
S19: =B19 -> 0 | T19: =VLOOKUP($B19,$S$3:$Y$9,2,FALSE) -> #N/A | U19: =VLOOKUP($B19,$S$3:$Y$9,3,FALSE) -> #N/A | V19: =VLOOKUP($B19,$S$3:$Y$9,4,FALSE) -> #N/A | W19: =VLOOKUP($B19,$S$3:$Y$9,5,FALSE) -> #N/A | X19: =VLOOKUP($B19,$S$3:$Y$9,6,FALSE) -> #N/A | Y19: =VLOOKUP($B19,$S$3:$Y$9,7,FALSE) -> #N/A | Z19: =VLOOKUP($B19,$S$3:$AA$9,8,FALSE) -> #N/A | AA19: =VLOOKUP($B19,$S$3:$AA$9,9,FALSE) -> #N/A
S20: =B20 -> 0 | T20: =VLOOKUP($B20,$S$3:$Y$9,2,FALSE) -> #N/A | U20: =VLOOKUP($B20,$S$3:$Y$9,3,FALSE) -> #N/A | V20: =VLOOKUP($B20,$S$3:$Y$9,4,FALSE) -> #N/A | W20: =VLOOKUP($B20,$S$3:$Y$9,5,FALSE) -> #N/A | X20: =VLOOKUP($B20,$S$3:$Y$9,6,FALSE) -> #N/A | Y20: =VLOOKUP($B20,$S$3:$Y$9,7,FALSE) -> #N/A | Z20: =VLOOKUP($B20,$S$3:$AA$9,8,FALSE) -> #N/A | AA20: =VLOOKUP($B20,$S$3:$AA$9,9,FALSE) -> #N/A
S21: =B21 -> 0 | T21: =VLOOKUP($B21,$S$3:$Y$9,2,FALSE) -> #N/A | U21: =VLOOKUP($B21,$S$3:$Y$9,3,FALSE) -> #N/A | V21: =VLOOKUP($B21,$S$3:$Y$9,4,FALSE) -> #N/A | W21: =VLOOKUP($B21,$S$3:$Y$9,5,FALSE) -> #N/A | X21: =VLOOKUP($B21,$S$3:$Y$9,6,FALSE) -> #N/A | Y21: =VLOOKUP($B21,$S$3:$Y$9,7,FALSE) -> #N/A | Z21: =VLOOKUP($B21,$S$3:$AA$9,8,FALSE) -> #N/A | AA21: =VLOOKUP($B21,$S$3:$AA$9,9,FALSE) -> #N/A
... S47: =B47 -> 0 | T47: =VLOOKUP($B47,$S$3:$Y$9,2,FALSE) -> #N/A | U47: =VLOOKUP($B47,$S$3:$Y$9,3,FALSE) -> #N/A | V47: =VLOOKUP($B47,$S$3:$Y$9,4,FALSE) -> #N/A | W47: =VLOOKUP($B47,$S$3:$Y$9,5,FALSE) -> #N/A | X47: =VLOOKUP($B47,$S$3:$Y$9,6,FALSE) -> #N/A | Y47: =VLOOKUP($B47,$S$3:$Y$9,7,FALSE) -> #N/A | Z47: =VLOOKUP($B47,$S$3:$AA$9,8,FALSE) -> #N/A | AA47: =VLOOKUP($B47,$S$3:$AA$9,9,FALSE) -> #N/A
I48: EXTRACT RECOVERY
B49: BRAND | D49: BBT P.G./ O.G | I49: Brand | J49: Actual | K49: MTD No. of Brews | L49: MTD | M49: YTD | N49: Target
B50: STAG | C50: 11.8 | D50: 11.73 | I50: CARIB | K50: =COUNTA([3]Brewhouse!$A$1596:$A$1619) -> 24 | L50: =AVERAGE([3]Brewhouse!$AU$1529,[3]Brewhouse!$AU$1531:$AU$1594,[3]Brewhouse!$AU$1596:$AU$1619) -> 98.205761 | M50: =AVERAGE([3]Brewhouse!$AU$849:$AU$924,[3]Brewhouse!$AU$926:$AU$971,[3]Brewhouse!$AU$973:$AU$1066,[3]Brewhouse!$AU$1068:$AU$1111,[3]Brewhouse!$AU$1113:$AU$1132,[3]Brewhouse!$AU$1134:$AU$1167,[3]Brewhouse!$AU$1169:$AU$1230,[3]Brewhouse!$AU$1232:$AU$1299,[3]Brewhouse!$AU$1301:$AU$1363,[3]Brewhouse!$AU$1365:$AU$1444,[3]Brewhouse!$AU$1446:$AU$1527,[3]Brewhouse!$AU$1529,[3]Brewhouse!$AU$1531:$AU$1594,[3]Brewhouse!$AU$1596:$AU$1619) -> 98.381806 | N50: 98
C51: 11.9 | I51: STAG | K51: =COUNTA([4]Brewhouse!$A$976:$A$1007) -> 32 | L51: =AVERAGE([4]Brewhouse!$AS$976:$AS$979,[4]Brewhouse!$AS$981:$AS$1007) -> 98.538567 | M51: =AVERAGE([4]Brewhouse!$AS$577:$AS$618,[4]Brewhouse!$AS$620:$AS$651,[4]Brewhouse!$AS$653:$AS$696,[4]Brewhouse!$AS$698:$AS$708,[4]Brewhouse!$AS$710:$AS$733,[4]Brewhouse!$AS$735:$AS$777,[4]Brewhouse!$AS$779:$AS$822,[4]Brewhouse!$AS$824:$AS$863,[4]Brewhouse!$AS$865:$AS$974,[4]Brewhouse!$AS$976:$AS$979,[4]Brewhouse!$AS$981:$AS$1007) -> 98.489671 | N51: 98
I52: GUINNESS | K52: =COUNTA([5]Brewhouse!$A$282:$A$289) -> 8 | L52: =AVERAGE([5]Brewhouse!$AU$269:$AU$279,[5]Brewhouse!$AU$282:$AU$289) -> 96.186177 | M52: =AVERAGE([5]Brewhouse!$AU$161:$AU$176,[5]Brewhouse!$AU$178:$AU$195,[5]Brewhouse!$AU$197:$AU$208,[5]Brewhouse!$AU$210:$AU$221,[5]Brewhouse!$AU$223:$AU$232,[5]Brewhouse!$AU$234:$AU$279,[5]Brewhouse!$AU$282:$AU$289) -> 96.64916 | N52: 98
I53: VITAMALT | K53: =COUNTA([6]Brewhouse!$A$158:$A$163) -> 6 | L53: =AVERAGE([6]Brewhouse!$AU$158:$AU$163) -> 94.60305 | M53: =AVERAGE([6]Brewhouse!$AU$91:$AU$101,[6]Brewhouse!$AU$103:$AU$112,[6]Brewhouse!$AU$114:$AU$123,[6]Brewhouse!$AU$125:$AU$134,[6]Brewhouse!$AU$136:$AU$145,[6]Brewhouse!$AU$147:$AU$156,[6]Brewhouse!$AU$158:$AU$163) -> 96.240014 | N53: 98
I54: MAXIMALT | N54: 98
I55: MACKESON | M55: =AVERAGE([7]Brewhouse!$AT$74:$AT$79) -> 93.959836 | N55: 98
I56: STARMALT | K56: =COUNTA([8]Brewhouse!$A$249:$A$254) -> 6 | L56: =AVERAGE([8]Brewhouse!$AY$249:$AY$254) -> 99.681996 | M56: =AVERAGE([8]Brewhouse!$AY$138:$AY$143,[8]Brewhouse!$AY$145:$AY$153,[8]Brewhouse!$AY$155,[8]Brewhouse!$AY$156:$AY$174,[8]Brewhouse!$AY$176:$AY$185,[8]Brewhouse!$AY$187:$AY$198,[8]Brewhouse!$AY$200:$AY$247,[8]Brewhouse!$AY$249:$AY$254) -> 98.774703 | N56: 98
I57: HR- P | M57: =AVERAGE([9]Brewhouse!$AW$13:$AW$14,[9]Brewhouse!$AW$16:$AW$17) -> 92.042628 | N57: 98
I58: Hurricane Reef | M58: =AVERAGE([9]Brewhouse!$AW$13:$AW$14) -> 88.376943 | N58: 98
K59: =SUM(K50:K58) -> 76 | L59: =((L50*K50)+(L51*K51)+(L52*K52)+(L53*K53)+(L54*K54)+(K57*L57)+(L55*K55)+(L56*K56)+(L58*K58))/(K59) -> 97.965422 | M59: =AVERAGE('[10]Closing- January 2023'!$L$42,'[11]Feb. 28th'!$L$42,'[12]March 31st'!$L$75,'[13]Apri 28th'!$L$51,L59) -> 98.06926 | N59: 98
J62: Daily Brewing Plan
J63: Brand | K63: Brews Achieved | L63: Average Brews per day
J64: CARIB | L64: MTD | M64: YTD | N64: TARGET
J65: STAG | K65: 5 | L65: =AVERAGE(#REF!,#REF!,K74,#REF!,#REF!,#REF!,#REF!,#REF!,#REF!,#REF!,#REF!) -> #REF! | M65: =AVERAGE(6,6,'[12]March 31st'!$L$80,'[14]June 30th '!$L$71,6,L65,'[15]July 31st'!$L$108,'[16]Aug 30th'!$L$124,7,[17]Oct.31st!$L$51) -> #REF! | N65: 9
J66: GUINN
J67: VITAMALT
...

Sheet Aug 4th 
S1: P.G. | U1: Hot Time | W1: Process Time | Y1: Cooling Time
B2: Brewing Department Daily Process Loss Report | S2: Lower | T2: Upper | U2: Lower | V2: Upper | W2: Lower | X2: Upper | Y2: Lower | Z2: Upper
R3: CARIB | S3: 11.6 | T3: 12 | U3: 0 | V3: 0.11805556 | W3: 0.22569444 | X3: 0.26388889 | Y3: 0 | Z3: 60 | AB3: HR- PISNER
B4: Date: | C4: 45874 | J4: LOT WORT COLOUR: 3.0/3.3 | M4: Filter Sheets (Target 20 days) | R4: STAG | S4: 11.6 | T4: 12 | U4: 0 | V4: 0.11805556 | W4: 0.22569444 | X4: 0.26388889 | Y4: 0 | Z4: 60
M5: Double | N5: Single | R5: GUINNESS | S5: 17 | T5: 17.5 | U5: 0 | V5: 0.10763889 | W5: 0.24652778 | X5: 0.28472222 | Y5: 0 | Z5: 60
J6: MALT LOT: Lot #41 /42 | L6: Sheet Day | M6: 10 | N6: 10 | R6: MACKESON | S6: 13.3 | T6: 13.5 | U6: 0 | V6: 0.12905093 | W6: 0.27430556 | X6: 0.30208333 | Y6: 0
R7: STARMALT | S7: 17.1 | T7: 17.5 | U7: 0 | V7: 0.13605324 | W7: 0.27430556 | X7: 0.30902778 | Y7: 0 | Z7: 85
B8: Brand | C8: Brew no. | D8: Kett. Hls | E8: Wort | F8: Cool Time(Mins) | G8: Cast. P.G. (Lab Result) | H8: Cast P.G. (Cellar Operator)-gravity | I8: Extr. Rec (77.9%) | J8: Theor. Extr. (77.5%) | K8: Boil Off /Vol. (4-6%) | L8: Boil Time | M8: Total Hot | N8: Brewing | O8: Operator | R8: Hurricane Reef | S8: 16.6 | T8: 17 | U8: 0 | V8: 0.12905093 | W8: 0.27430556 | X8: 0.30208333 | Y8: 0
E9: Meter (Hls) | F9: Target(< 60Mins) | M9: Time | R9: VITAMALT | S9: 14.4 | T9: 14.6 | U9: 0 | V9: 0.13905093 | W9: 0.26041667 | X9: 0.29513889 | Y9: 0 | Z9: 75
B10: STAG | C10: =[22]Brewhouse!$A324 -> ST303 | D10: =[22]Brewhouse!$AD324 -> 49.9 | E10: =[22]Brewhouse!$AG324 -> 48.9 | F10: =[22]Brewhouse!$V324 -> 63 | G10: =[22]Brewhouse!$AE324 -> 12.1 | H10: 12.1 | I10: =[22]Brewhouse!$AS324 -> 99.121856 | J10: =[22]Brewhouse!$AT324 -> 100.04506 | K10: =[22]Brewhouse!$Q324 -> 11.152416 | L10: =[22]Brewhouse!$P324 -> 60 | M10: =[22]Brewhouse!$U324-[22]Brewhouse!$T324 -> 0.11041667 | N10: =[22]Brewhouse!$AW324 -> 0.24166667 | O10: =[22]Brewhouse!$AV324 -> R.Sookram | R10: =B10 -> STAG | S10: =VLOOKUP($B10,$R$3:$X$9,2,FALSE) -> 11.6 | T10: =VLOOKUP($B10,$R$3:$X$9,3,FALSE) -> 12 | U10: =VLOOKUP($B10,$R$3:$X$9,4,FALSE) -> 0 | V10: =VLOOKUP($B10,$R$3:$X$9,5,FALSE) -> 0.11805556 | W10: =VLOOKUP($B10,$R$3:$X$9,6,FALSE) -> 0.22569444 | X10: =VLOOKUP($B10,$R$3:$X$9,7,FALSE) -> 0.26388889 | Y10: =VLOOKUP($B10,$R$3:$Z$9,8,FALSE) -> 0 | Z10: =VLOOKUP($B10,$R$3:$Z$9,9,FALSE) -> 60
B11: STAG | C11: =[22]Brewhouse!$A325 -> ST304 | D11: =[22]Brewhouse!$AD325 -> 50.5 | E11: =[22]Brewhouse!$AG325 -> 48.9 | F11: =[22]Brewhouse!$V325 -> 60 | G11: =[22]Brewhouse!$AE325 -> 11.8 | H11: 11.8 | I11: =[22]Brewhouse!$AS325 -> 95.100831 | J11: =[22]Brewhouse!$AT325 -> 96.473457 | K11: =[22]Brewhouse!$Q325 -> 3.5573123 | L11: =[22]Brewhouse!$P325 -> 59 | M11: =[22]Brewhouse!$U325-[22]Brewhouse!$T325 -> 0.10902778 | N11: =[22]Brewhouse!$AW325 -> 0.24236111 | O11: =[22]Brewhouse!$AV325 -> R.Sookram | R11: =B11 -> STAG | S11: =VLOOKUP($B11,$R$3:$X$9,2,FALSE) -> 11.6 | T11: =VLOOKUP($B11,$R$3:$X$9,3,FALSE) -> 12 | U11: =VLOOKUP($B11,$R$3:$X$9,4,FALSE) -> 0 | V11: =VLOOKUP($B11,$R$3:$X$9,5,FALSE) -> 0.11805556 | W11: =VLOOKUP($B11,$R$3:$X$9,6,FALSE) -> 0.22569444 | X11: =VLOOKUP($B11,$R$3:$X$9,7,FALSE) -> 0.26388889 | Y11: =VLOOKUP($B11,$R$3:$Z$9,8,FALSE) -> 0 | Z11: =VLOOKUP($B11,$R$3:$Z$9,9,FALSE) -> 60
B12: STAG | C12: =[22]Brewhouse!$A326 -> ST305 | D12: =[22]Brewhouse!$AD326 -> 50.8 | E12: =[22]Brewhouse!$AG326 -> 50.4 | F12: =[22]Brewhouse!$V326 -> 55 | G12: =[22]Brewhouse!$AE326 -> 12 | H12: 11.9 | I12: =[22]Brewhouse!$AS326 -> 99.76552 | J12: =[22]Brewhouse!$AT326 -> 101.20547 | K12: =[22]Brewhouse!$Q326 -> 11.296296 | L12: =[22]Brewhouse!$P326 -> 57 | M12: =[22]Brewhouse!$U326-[22]Brewhouse!$T326 -> 0.10972222 | N12: =[22]Brewhouse!$AW326 -> 0.24375 | O12: =[22]Brewhouse!$AV326 -> R.Sookram | R12: =B12 -> STAG | S12: =VLOOKUP($B12,$R$3:$X$9,2,FALSE) -> 11.6 | T12: =VLOOKUP($B12,$R$3:$X$9,3,FALSE) -> 12 | U12: =VLOOKUP($B12,$R$3:$X$9,4,FALSE) -> 0 | V12: =VLOOKUP($B12,$R$3:$X$9,5,FALSE) -> 0.11805556 | W12: =VLOOKUP($B12,$R$3:$X$9,6,FALSE) -> 0.22569444 | X12: =VLOOKUP($B12,$R$3:$X$9,7,FALSE) -> 0.26388889 | Y12: =VLOOKUP($B12,$R$3:$Z$9,8,FALSE) -> 0 | Z12: =VLOOKUP($B12,$R$3:$Z$9,9,FALSE) -> 60
B13: STAG | C13: =[22]Brewhouse!$A327 -> ST306 | D13: =[22]Brewhouse!$AD327 -> 50.6 | E13: =[22]Brewhouse!$AG327 -> 50.1 | F13: =[22]Brewhouse!$V327 -> 58 | G13: =[22]Brewhouse!$AE327 -> 11.9 | H13: 11.8 | I13: =[22]Brewhouse!$AS327 -> 98.303136 | J13: =[22]Brewhouse!$AT327 -> 99.721982 | K13: =[22]Brewhouse!$Q327 -> 11.743119 | L13: =[22]Brewhouse!$P327 -> 59 | M13: =[22]Brewhouse!$U327-[22]Brewhouse!$T327 -> 0.10972222 | N13: =[22]Brewhouse!$AW327 -> 0.25 | O13: =[22]Brewhouse!$AV327 -> K. Benjamin | R13: =B13 -> STAG | S13: =VLOOKUP($B13,$R$3:$X$9,2,FALSE) -> 11.6 | T13: =VLOOKUP($B13,$R$3:$X$9,3,FALSE) -> 12 | U13: =VLOOKUP($B13,$R$3:$X$9,4,FALSE) -> 0 | V13: =VLOOKUP($B13,$R$3:$X$9,5,FALSE) -> 0.11805556 | W13: =VLOOKUP($B13,$R$3:$X$9,6,FALSE) -> 0.22569444 | X13: =VLOOKUP($B13,$R$3:$X$9,7,FALSE) -> 0.26388889 | Y13: =VLOOKUP($B13,$R$3:$Z$9,8,FALSE) -> 0 | Z13: =VLOOKUP($B13,$R$3:$Z$9,9,FALSE) -> 60
B14: STAG | C14: =[22]Brewhouse!$A328 -> ST307 | D14: =[22]Brewhouse!$AD328 -> 50.8 | E14: =[22]Brewhouse!$AG328 -> 50.6 | F14: =[22]Brewhouse!$V328 -> 59 | G14: =[22]Brewhouse!$AE328 -> 11.9 | H14: 11.8 | I14: =[22]Brewhouse!$AS328 -> 99.780557 | J14: =[22]Brewhouse!$AT328 -> 101.21887 | K14: =[22]Brewhouse!$Q328 -> 9.6474954 | L14: =[22]Brewhouse!$P328 -> 61 | M14: =[22]Brewhouse!$U328-[22]Brewhouse!$T328 -> 0.11527778 | N14: =[22]Brewhouse!$AW328 -> 0.25138889 | O14: =[22]Brewhouse!$AV328 -> K. Benjamin | R14: =B14 -> STAG | S14: =VLOOKUP($B14,$R$3:$X$9,2,FALSE) -> 11.6 | T14: =VLOOKUP($B14,$R$3:$X$9,3,FALSE) -> 12 | U14: =VLOOKUP($B14,$R$3:$X$9,4,FALSE) -> 0 | V14: =VLOOKUP($B14,$R$3:$X$9,5,FALSE) -> 0.11805556 | W14: =VLOOKUP($B14,$R$3:$X$9,6,FALSE) -> 0.22569444 | X14: =VLOOKUP($B14,$R$3:$X$9,7,FALSE) -> 0.26388889 | Y14: =VLOOKUP($B14,$R$3:$Z$9,8,FALSE) -> 0 | Z14: =VLOOKUP($B14,$R$3:$Z$9,9,FALSE) -> 60
B15: STAG | C15: =[22]Brewhouse!$A329 -> ST308 | D15: =[22]Brewhouse!$AD329 -> 52.5 | E15: =[22]Brewhouse!$AG329 -> 51.4 | F15: =[22]Brewhouse!$V329 -> 64 | G15: =[22]Brewhouse!$AE329 -> 12 | I15: =[22]Brewhouse!$AS329 -> 102.38161 | J15: =[22]Brewhouse!$AT329 -> 103.85693 | K15: =[22]Brewhouse!$Q329 -> 9.9815157 | L15: =[22]Brewhouse!$P329 -> 59 | M15: =[22]Brewhouse!$U329-[22]Brewhouse!$T329 -> 0.11319444 | N15: =[22]Brewhouse!$AW329 -> 0.24652778 | O15: =[22]Brewhouse!$AV329 -> K. Benjamin | R15: =B15 -> STAG | S15: =VLOOKUP($B15,$R$3:$X$9,2,FALSE) -> 11.6 | T15: =VLOOKUP($B15,$R$3:$X$9,3,FALSE) -> 12 | U15: =VLOOKUP($B15,$R$3:$X$9,4,FALSE) -> 0 | V15: =VLOOKUP($B15,$R$3:$X$9,5,FALSE) -> 0.11805556 | W15: =VLOOKUP($B15,$R$3:$X$9,6,FALSE) -> 0.22569444 | X15: =VLOOKUP($B15,$R$3:$X$9,7,FALSE) -> 0.26388889 | Y15: =VLOOKUP($B15,$R$3:$Z$9,8,FALSE) -> 0 | Z15: =VLOOKUP($B15,$R$3:$Z$9,9,FALSE) -> 60
B16: STAG | C16: =[22]Brewhouse!$A330 -> ST309 | D16: =[22]Brewhouse!$AD330 -> 51 | E16: =[22]Brewhouse!$AG330 -> 50.1 | F16: =[22]Brewhouse!$V330 -> 64 | G16: =[22]Brewhouse!$AE330 -> 11.7 | H16: 11.7 | I16: =[22]Brewhouse!$AS330 -> 97.414067 | J16: =[22]Brewhouse!$AT330 -> 98.816893 | K16: =[22]Brewhouse!$Q330 -> 9.7785978 | L16: =[22]Brewhouse!$P330 -> 60 | M16: =[22]Brewhouse!$U330-[22]Brewhouse!$T330 -> 0.11458333 | N16: =[22]Brewhouse!$AW330 -> 0.24583333 | O16: =[22]Brewhouse!$AV330 -> R. Regis | R16: =B16 -> STAG | S16: =VLOOKUP($B16,$R$3:$X$9,2,FALSE) -> 11.6 | T16: =VLOOKUP($B16,$R$3:$X$9,3,FALSE) -> 12 | U16: =VLOOKUP($B16,$R$3:$X$9,4,FALSE) -> 0 | V16: =VLOOKUP($B16,$R$3:$X$9,5,FALSE) -> 0.11805556 | W16: =VLOOKUP($B16,$R$3:$X$9,6,FALSE) -> 0.22569444 | X16: =VLOOKUP($B16,$R$3:$X$9,7,FALSE) -> 0.26388889 | Y16: =VLOOKUP($B16,$R$3:$Z$9,8,FALSE) -> 0 | Z16: =VLOOKUP($B16,$R$3:$Z$9,9,FALSE) -> 60
B17: STAG | C17: =[22]Brewhouse!$A331 -> ST310 | D17: =[22]Brewhouse!$AD331 -> 50.2 | E17: =[22]Brewhouse!$AG331 -> 49.3 | F17: =[22]Brewhouse!$V331 -> 60 | G17: =[22]Brewhouse!$AE331 -> 11.7 | H17: 11.7 | I17: =[22]Brewhouse!$AS331 -> 95.738446 | J17: =[22]Brewhouse!$AT331 -> 97.117593 | K17: =[22]Brewhouse!$Q331 -> 8.5343228 | L17: =[22]Brewhouse!$P331 -> 60 | M17: =[22]Brewhouse!$U331-[22]Brewhouse!$T331 -> 0.11111111 | N17: =[22]Brewhouse!$AW331 -> 0.23958333 | O17: =[22]Brewhouse!$AV331 -> R. Regis | R17: =B17 -> STAG | S17: =VLOOKUP($B17,$R$3:$X$9,2,FALSE) -> 11.6 | T17: =VLOOKUP($B17,$R$3:$X$9,3,FALSE) -> 12 | U17: =VLOOKUP($B17,$R$3:$X$9,4,FALSE) -> 0 | V17: =VLOOKUP($B17,$R$3:$X$9,5,FALSE) -> 0.11805556 | W17: =VLOOKUP($B17,$R$3:$X$9,6,FALSE) -> 0.22569444 | X17: =VLOOKUP($B17,$R$3:$X$9,7,FALSE) -> 0.26388889 | Y17: =VLOOKUP($B17,$R$3:$Z$9,8,FALSE) -> 0 | Z17: =VLOOKUP($B17,$R$3:$Z$9,9,FALSE) -> 60
R18: =B18 -> 0 | S18: =VLOOKUP($B18,$R$3:$X$9,2,FALSE) -> #N/A | T18: =VLOOKUP($B18,$R$3:$X$9,3,FALSE) -> #N/A | U18: =VLOOKUP($B18,$R$3:$X$9,4,FALSE) -> #N/A | V18: =VLOOKUP($B18,$R$3:$X$9,5,FALSE) -> #N/A | W18: =VLOOKUP($B18,$R$3:$X$9,6,FALSE) -> #N/A | X18: =VLOOKUP($B18,$R$3:$X$9,7,FALSE) -> #N/A | Y18: =VLOOKUP($B18,$R$3:$Z$9,8,FALSE) -> #N/A | Z18: =VLOOKUP($B18,$R$3:$Z$9,9,FALSE) -> #N/A
R19: =B19 -> 0 | S19: =VLOOKUP($B19,$R$3:$X$9,2,FALSE) -> #N/A | T19: =VLOOKUP($B19,$R$3:$X$9,3,FALSE) -> #N/A | U19: =VLOOKUP($B19,$R$3:$X$9,4,FALSE) -> #N/A | V19: =VLOOKUP($B19,$R$3:$X$9,5,FALSE) -> #N/A | W19: =VLOOKUP($B19,$R$3:$X$9,6,FALSE) -> #N/A | X19: =VLOOKUP($B19,$R$3:$X$9,7,FALSE) -> #N/A | Y19: =VLOOKUP($B19,$R$3:$Z$9,8,FALSE) -> #N/A | Z19: =VLOOKUP($B19,$R$3:$Z$9,9,FALSE) -> #N/A
R20: =B20 -> 0 | S20: =VLOOKUP($B20,$R$3:$X$9,2,FALSE) -> #N/A | T20: =VLOOKUP($B20,$R$3:$X$9,3,FALSE) -> #N/A | U20: =VLOOKUP($B20,$R$3:$X$9,4,FALSE) -> #N/A | V20: =VLOOKUP($B20,$R$3:$X$9,5,FALSE) -> #N/A | W20: =VLOOKUP($B20,$R$3:$X$9,6,FALSE) -> #N/A | X20: =VLOOKUP($B20,$R$3:$X$9,7,FALSE) -> #N/A | Y20: =VLOOKUP($B20,$R$3:$Z$9,8,FALSE) -> #N/A | Z20: =VLOOKUP($B20,$R$3:$Z$9,9,FALSE) -> #N/A
R21: =B21 -> 0 | S21: =VLOOKUP($B21,$R$3:$X$9,2,FALSE) -> #N/A | T21: =VLOOKUP($B21,$R$3:$X$9,3,FALSE) -> #N/A | U21: =VLOOKUP($B21,$R$3:$X$9,4,FALSE) -> #N/A | V21: =VLOOKUP($B21,$R$3:$X$9,5,FALSE) -> #N/A | W21: =VLOOKUP($B21,$R$3:$X$9,6,FALSE) -> #N/A | X21: =VLOOKUP($B21,$R$3:$X$9,7,FALSE) -> #N/A | Y21: =VLOOKUP($B21,$R$3:$Z$9,8,FALSE) -> #N/A | Z21: =VLOOKUP($B21,$R$3:$Z$9,9,FALSE) -> #N/A
R22: =B22 -> 0 | S22: =VLOOKUP($B22,$R$3:$X$9,2,FALSE) -> #N/A | T22: =VLOOKUP($B22,$R$3:$X$9,3,FALSE) -> #N/A | U22: =VLOOKUP($B22,$R$3:$X$9,4,FALSE) -> #N/A | V22: =VLOOKUP($B22,$R$3:$X$9,5,FALSE) -> #N/A | W22: =VLOOKUP($B22,$R$3:$X$9,6,FALSE) -> #N/A | X22: =VLOOKUP($B22,$R$3:$X$9,7,FALSE) -> #N/A | Y22: =VLOOKUP($B22,$R$3:$Z$9,8,FALSE) -> #N/A | Z22: =VLOOKUP($B22,$R$3:$Z$9,9,FALSE) -> #N/A
R23: =B23 -> 0 | S23: =VLOOKUP($B23,$R$3:$X$9,2,FALSE) -> #N/A | T23: =VLOOKUP($B23,$R$3:$X$9,3,FALSE) -> #N/A | U23: =VLOOKUP($B23,$R$3:$X$9,4,FALSE) -> #N/A | V23: =VLOOKUP($B23,$R$3:$X$9,5,FALSE) -> #N/A | W23: =VLOOKUP($B23,$R$3:$X$9,6,FALSE) -> #N/A | X23: =VLOOKUP($B23,$R$3:$X$9,7,FALSE) -> #N/A | Y23: =VLOOKUP($B23,$R$3:$Z$9,8,FALSE) -> #N/A | Z23: =VLOOKUP($B23,$R$3:$Z$9,9,FALSE) -> #N/A
R24: =B24 -> 0 | S24: =VLOOKUP($B24,$R$3:$X$9,2,FALSE) -> #N/A | T24: =VLOOKUP($B24,$R$3:$X$9,3,FALSE) -> #N/A | U24: =VLOOKUP($B24,$R$3:$X$9,4,FALSE) -> #N/A | V24: =VLOOKUP($B24,$R$3:$X$9,5,FALSE) -> #N/A | W24: =VLOOKUP($B24,$R$3:$X$9,6,FALSE) -> #N/A | X24: =VLOOKUP($B24,$R$3:$X$9,7,FALSE) -> #N/A | Y24: =VLOOKUP($B24,$R$3:$Z$9,8,FALSE) -> #N/A | Z24: =VLOOKUP($B24,$R$3:$Z$9,9,FALSE) -> #N/A
R25: =B25 -> 0 | S25: =VLOOKUP($B25,$R$3:$X$9,2,FALSE) -> #N/A | T25: =VLOOKUP($B25,$R$3:$X$9,3,FALSE) -> #N/A | U25: =VLOOKUP($B25,$R$3:$X$9,4,FALSE) -> #N/A | V25: =VLOOKUP($B25,$R$3:$X$9,5,FALSE) -> #N/A | W25: =VLOOKUP($B25,$R$3:$X$9,6,FALSE) -> #N/A | X25: =VLOOKUP($B25,$R$3:$X$9,7,FALSE) -> #N/A | Y25: =VLOOKUP($B25,$R$3:$Z$9,8,FALSE) -> #N/A | Z25: =VLOOKUP($B25,$R$3:$Z$9,9,FALSE) -> #N/A
R26: =B26 -> 0 | S26: =VLOOKUP($B26,$R$3:$X$9,2,FALSE) -> #N/A | T26: =VLOOKUP($B26,$R$3:$X$9,3,FALSE) -> #N/A | U26: =VLOOKUP($B26,$R$3:$X$9,4,FALSE) -> #N/A | V26: =VLOOKUP($B26,$R$3:$X$9,5,FALSE) -> #N/A | W26: =VLOOKUP($B26,$R$3:$X$9,6,FALSE) -> #N/A | X26: =VLOOKUP($B26,$R$3:$X$9,7,FALSE) -> #N/A | Y26: =VLOOKUP($B26,$R$3:$Z$9,8,FALSE) -> #N/A | Z26: =VLOOKUP($B26,$R$3:$Z$9,9,FALSE) -> #N/A
R27: =B27 -> 0 | S27: =VLOOKUP($B27,$R$3:$X$9,2,FALSE) -> #N/A | T27: =VLOOKUP($B27,$R$3:$X$9,3,FALSE) -> #N/A | U27: =VLOOKUP($B27,$R$3:$X$9,4,FALSE) -> #N/A | V27: =VLOOKUP($B27,$R$3:$X$9,5,FALSE) -> #N/A | W27: =VLOOKUP($B27,$R$3:$X$9,6,FALSE) -> #N/A | X27: =VLOOKUP($B27,$R$3:$X$9,7,FALSE) -> #N/A | Y27: =VLOOKUP($B27,$R$3:$Z$9,8,FALSE) -> #N/A | Z27: =VLOOKUP($B27,$R$3:$Z$9,9,FALSE) -> #N/A
R28: =B28 -> 0 | S28: =VLOOKUP($B28,$R$3:$X$9,2,FALSE) -> #N/A | T28: =VLOOKUP($B28,$R$3:$X$9,3,FALSE) -> #N/A | U28: =VLOOKUP($B28,$R$3:$X$9,4,FALSE) -> #N/A | V28: =VLOOKUP($B28,$R$3:$X$9,5,FALSE) -> #N/A | W28: =VLOOKUP($B28,$R$3:$X$9,6,FALSE) -> #N/A | X28: =VLOOKUP($B28,$R$3:$X$9,7,FALSE) -> #N/A | Y28: =VLOOKUP($B28,$R$3:$Z$9,8,FALSE) -> #N/A | Z28: =VLOOKUP($B28,$R$3:$Z$9,9,FALSE) -> #N/A
R29: =B29 -> 0 | S29: =VLOOKUP($B29,$R$3:$X$9,2,FALSE) -> #N/A | T29: =VLOOKUP($B29,$R$3:$X$9,3,FALSE) -> #N/A | U29: =VLOOKUP($B29,$R$3:$X$9,4,FALSE) -> #N/A | V29: =VLOOKUP($B29,$R$3:$X$9,5,FALSE) -> #N/A | W29: =VLOOKUP($B29,$R$3:$X$9,6,FALSE) -> #N/A | X29: =VLOOKUP($B29,$R$3:$X$9,7,FALSE) -> #N/A | Y29: =VLOOKUP($B29,$R$3:$Z$9,8,FALSE) -> #N/A | Z29: =VLOOKUP($B29,$R$3:$Z$9,9,FALSE) -> #N/A
... R32: =B32 -> 0 | S32: =VLOOKUP($B32,$R$3:$X$9,2,FALSE) -> #N/A | T32: =VLOOKUP($B32,$R$3:$X$9,3,FALSE) -> #N/A | U32: =VLOOKUP($B32,$R$3:$X$9,4,FALSE) -> #N/A | V32: =VLOOKUP($B32,$R$3:$X$9,5,FALSE) -> #N/A | W32: =VLOOKUP($B32,$R$3:$X$9,6,FALSE) -> #N/A | X32: =VLOOKUP($B32,$R$3:$X$9,7,FALSE) -> #N/A | Y32: =VLOOKUP($B32,$R$3:$Z$9,8,FALSE) -> #N/A | Z32: =VLOOKUP($B32,$R$3:$Z$9,9,FALSE) -> #N/A
B33: BRAND | D33: BBT P.G./ O.G | I33: Brand | J33: Actual | K33: MTD No. of Brews | L33: MTD | M33: YTD | N33: Target | R33: =B33 -> BRAND | S33: =VLOOKUP($B33,$R$3:$X$9,2,FALSE) -> #N/A | T33: =VLOOKUP($B33,$R$3:$X$9,3,FALSE) -> #N/A | U33: =VLOOKUP($B33,$R$3:$X$9,4,FALSE) -> #N/A | V33: =VLOOKUP($B33,$R$3:$X$9,5,FALSE) -> #N/A | W33: =VLOOKUP($B33,$R$3:$X$9,6,FALSE) -> #N/A | X33: =VLOOKUP($B33,$R$3:$X$9,7,FALSE) -> #N/A | Y33: =VLOOKUP($B33,$R$3:$Z$9,8,FALSE) -> #N/A | Z33: =VLOOKUP($B33,$R$3:$Z$9,9,FALSE) -> #N/A
B34: =I40 -> STARMALT | C34: {=[23]Process!$D$63:$D$64} -> 16.8 | D34: 17.07 | I34: CARIB | M34: =AVERAGE([24]Brewhouse!$AU$102:$AU$171,[24]Brewhouse!$AU$173:$AU$253,[24]Brewhouse!$AU$255:$AU$339,[24]Brewhouse!$AU$341:$AU$346,[24]Brewhouse!$AU$348,[24]Brewhouse!$AU$349:$AU$406,[24]Brewhouse!$AU$408:$AU$491,[24]Brewhouse!$AU$493:$AU$578,[24]Brewhouse!$AU$580:$AU$652) -> 97.878594 | N34: 98
C35: 17.4 | I35: STAG | J35: =AVERAGE(I10:I17) -> 98.450752 | K35: =COUNTA([22]Brewhouse!$A$324:$A$331) -> 8 | L35: =AVERAGE([22]Brewhouse!$AS$324:$AS$331) -> 98.450752 | M35: =AVERAGE([22]Brewhouse!$AS$15:$AS$64,[22]Brewhouse!$AS$66:$AS$103,[22]Brewhouse!$AS$105:$AS$140,[22]Brewhouse!$AS$142:$AS$193,[22]Brewhouse!$AS$195:$AS$240,[22]Brewhouse!$AS$242:$AS$273,[22]Brewhouse!$AS$275:$AS$322,[22]Brewhouse!$AS$324:$AS$331) -> 98.076073 | N35: 98
I36: GUINNESS | M36: =AVERAGE([25]Brewhouse!$AU$4:$AU$7,[25]Brewhouse!$AU$9:$AU$22,[25]Brewhouse!$AU$24:$AU$35,[25]Brewhouse!$AU$37:$AU$45,[25]Brewhouse!$AU$47:$AU$62,[25]Brewhouse!$AU$64:$AU$79) -> 97.01892 | N36: 98
I37: VITAMALT | M37: =AVERAGE([26]Brewhouse!$AV$5:$AV$14,[26]Brewhouse!$AV$16:$AV$19,[26]Brewhouse!$AV$21:$AV$24,[26]Brewhouse!$AV$26:$AV$33,[26]Brewhouse!$AV$35:$AV$46,[26]Brewhouse!$AV$48:$AV$53,[26]Brewhouse!$AV$55:$AV$62) -> 98.773361 | N37: 98
I38: MAXIMALT | N38: 98
I39: MACKESON | M39: =AVERAGE([27]Brewhouse!$AT$4:$AT$11,[27]Brewhouse!$AT$13:$AT$16,[27]Brewhouse!$AT$18:$AT$21,[27]Brewhouse!$AT$26) -> 94.588058 | N39: 98
I40: STARMALT | M40: =AVERAGE([23]Brewhouse!$AY$6:$AY$13,[23]Brewhouse!$AY$15:$AY$20,[23]Brewhouse!$AY$22:$AY$29,[23]Brewhouse!$AY$31:$AY$34,[23]Brewhouse!$AY$36:$AY$43,[23]Brewhouse!$AY$45:$AY$50, [23]Brewhouse!$AY$56:$AY$73) -> 97.363751 | N40: 98
I41: HR- Pils | M41: =AVERAGE([28]Brewhouse!$AU$5:$AU$8,[28]Brewhouse!$AU$10:$AU$13) -> 94.247667 | N41: 98
I42: HR- IPA | M42: =AVERAGE([29]Brewhouse!$AW$26:$AW$27) -> 95.310681 | N42: 98
...

Sheet Aug 5th 
S1: P.G. | U1: Hot Time | W1: Process Time | Y1: Cooling Time
B2: Brewing Department Daily Process Loss Report | S2: Lower | T2: Upper | U2: Lower | V2: Upper | W2: Lower | X2: Upper | Y2: Lower | Z2: Upper
R3: CARIB | S3: 11.6 | T3: 12 | U3: 0 | V3: 0.11805556 | W3: 0.22569444 | X3: 0.26388889 | Y3: 0 | Z3: 60 | AB3: HR- PISNER
B4: Date: | C4: 45875 | J4: LOT WORT COLOUR: 3.3 | M4: Filter Sheets (Target 20 days) | R4: STAG | S4: 11.6 | T4: 12 | U4: 0 | V4: 0.11805556 | W4: 0.22569444 | X4: 0.26388889 | Y4: 0 | Z4: 60
M5: Double | N5: Single | R5: GUINNESS | S5: 17 | T5: 17.5 | U5: 0 | V5: 0.10763889 | W5: 0.24652778 | X5: 0.28472222 | Y5: 0 | Z5: 60
J6: MALT LOT: Lot #42 | L6: Sheet Day | M6: 10 | N6: 10 | R6: MACKESON | S6: 13.3 | T6: 13.5 | U6: 0 | V6: 0.12905093 | W6: 0.27430556 | X6: 0.30208333 | Y6: 0
R7: STARMALT | S7: 17.1 | T7: 17.5 | U7: 0 | V7: 0.13605324 | W7: 0.27430556 | X7: 0.30902778 | Y7: 0 | Z7: 85
B8: Brand | C8: Brew no. | D8: Kett. Hls | E8: Wort | F8: Cool Time(Mins) | G8: Cast. P.G. (Lab Result) | H8: Cast P.G. (Cellar Operator)-gravity | I8: Extr. Rec (77.9%) | J8: Theor. Extr. (77.5%) | K8: Boil Off /Vol. (4-6%) | L8: Boil Time | M8: Total Hot | N8: Brewing | O8: Operator | R8: Hurricane Reef | S8: 16.6 | T8: 17 | U8: 0 | V8: 0.12905093 | W8: 0.27430556 | X8: 0.30208333 | Y8: 0
E9: Meter (Hls) | F9: Target(< 60Mins) | M9: Time | R9: VITAMALT | S9: 14.2 | T9: 14.6 | U9: 0 | V9: 0.13905093 | W9: 0.26041667 | X9: 0.29513889 | Y9: 0 | Z9: 75
B10: VITAMALT | C10: =[26]Brewhouse!A64 -> VM053 | D10: =[26]Brewhouse!AE64 -> 48.9 | E10: =[26]Brewhouse!AJ64 -> 47.6 | F10: =[26]Brewhouse!X64 -> 87 | G10: =[26]Brewhouse!AH64 -> 14.5 | H10: 14.5 | I10: =[26]Brewhouse!AV64 -> 98.008773 | J10: =[26]Brewhouse!AW64 -> 98.362301 | K10: =[26]Brewhouse!S64 -> 6.6666667 | L10: =[26]Brewhouse!R64 -> 59 | M10: =[26]Brewhouse!$W64-[26]Brewhouse!$V64 -> 0.15069444 | N10: =[26]Brewhouse!AB64 -> 0.28194444 | O10: =[26]Brewhouse!$AZ64 -> R.Sookram | R10: =B10 -> VITAMALT | S10: =VLOOKUP($B10,$R$3:$X$9,2,FALSE) -> 14.2 | T10: =VLOOKUP($B10,$R$3:$X$9,3,FALSE) -> 14.6 | U10: =VLOOKUP($B10,$R$3:$X$9,4,FALSE) -> 0 | V10: =VLOOKUP($B10,$R$3:$X$9,5,FALSE) -> 0.13905093 | W10: =VLOOKUP($B10,$R$3:$X$9,6,FALSE) -> 0.26041667 | X10: =VLOOKUP($B10,$R$3:$X$9,7,FALSE) -> 0.29513889 | Y10: =VLOOKUP($B10,$R$3:$Z$9,8,FALSE) -> 0 | Z10: =VLOOKUP($B10,$R$3:$Z$9,9,FALSE) -> 75
B11: VITAMALT | C11: =[26]Brewhouse!A65 -> VM054 | D11: =[26]Brewhouse!AE65 -> 50.1 | E11: =[26]Brewhouse!AJ65 -> 47.9 | F11: =[26]Brewhouse!X65 -> 83 | G11: =[26]Brewhouse!AH65 -> 14.2 | H11: 14.3 | I11: =[26]Brewhouse!AV65 -> 97.056248 | J11: =[26]Brewhouse!AW65 -> 97.397423 | K11: =[26]Brewhouse!S65 -> 8.502994 | L11: =[26]Brewhouse!R65 -> 57 | M11: =[26]Brewhouse!$W65-[26]Brewhouse!$V65 -> 0.13611111 | N11: =[26]Brewhouse!AB65 -> 0.26597222 | O11: =[26]Brewhouse!$AZ65 -> R.Sookram | R11: =B11 -> VITAMALT | S11: =VLOOKUP($B11,$R$3:$X$9,2,FALSE) -> 14.2 | T11: =VLOOKUP($B11,$R$3:$X$9,3,FALSE) -> 14.6 | U11: =VLOOKUP($B11,$R$3:$X$9,4,FALSE) -> 0 | V11: =VLOOKUP($B11,$R$3:$X$9,5,FALSE) -> 0.13905093 | W11: =VLOOKUP($B11,$R$3:$X$9,6,FALSE) -> 0.26041667 | X11: =VLOOKUP($B11,$R$3:$X$9,7,FALSE) -> 0.29513889 | Y11: =VLOOKUP($B11,$R$3:$Z$9,8,FALSE) -> 0 | Z11: =VLOOKUP($B11,$R$3:$Z$9,9,FALSE) -> 75
B12: VITAMALT | C12: =[26]Brewhouse!A66 -> VM055 | D12: =[26]Brewhouse!AE66 -> 46.7 | E12: =[26]Brewhouse!AJ66 -> 48.1 | F12: =[26]Brewhouse!X66 -> 75 | G12: =[26]Brewhouse!AH66 -> 14.5 | H12: 14.4 | I12: =[26]Brewhouse!AV66 -> 99.038277 | J12: =[26]Brewhouse!AW66 -> 99.395519 | K12: =[26]Brewhouse!S66 -> 0.77087794 | L12: =[26]Brewhouse!R66 -> 57 | M12: =[26]Brewhouse!$W66-[26]Brewhouse!$V66 -> 0.13055556 | N12: =[26]Brewhouse!AB66 -> 0.26319444 | O12: =[26]Brewhouse!$AZ66 -> R.Sookram | R12: =B12 -> VITAMALT | S12: =VLOOKUP($B12,$R$3:$X$9,2,FALSE) -> 14.2 | T12: =VLOOKUP($B12,$R$3:$X$9,3,FALSE) -> 14.6 | U12: =VLOOKUP($B12,$R$3:$X$9,4,FALSE) -> 0 | V12: =VLOOKUP($B12,$R$3:$X$9,5,FALSE) -> 0.13905093 | W12: =VLOOKUP($B12,$R$3:$X$9,6,FALSE) -> 0.26041667 | X12: =VLOOKUP($B12,$R$3:$X$9,7,FALSE) -> 0.29513889 | Y12: =VLOOKUP($B12,$R$3:$Z$9,8,FALSE) -> 0 | Z12: =VLOOKUP($B12,$R$3:$Z$9,9,FALSE) -> 75
B13: VITAMALT | C13: =[26]Brewhouse!A67 -> VM056 | D13: =[26]Brewhouse!AE67 -> 51.8 | E13: =[26]Brewhouse!AJ67 -> 48.2 | F13: =[26]Brewhouse!X67 -> 78 | G13: =[26]Brewhouse!AH67 -> 14.3 | H13: 14.3 | I13: =[26]Brewhouse!AV67 -> 97.755191 | J13: =[26]Brewhouse!AW67 -> 98.107805 | K13: =[26]Brewhouse!S67 -> 7.8378378 | L13: =[26]Brewhouse!R67 -> 58 | M13: =[26]Brewhouse!$W67-[26]Brewhouse!$V67 -> 0.13125 | N13: =[26]Brewhouse!AB67 -> 0.27013889 | O13: =[26]Brewhouse!$AZ67 -> K. Benjamin | R13: =B13 -> VITAMALT | S13: =VLOOKUP($B13,$R$3:$X$9,2,FALSE) -> 14.2 | T13: =VLOOKUP($B13,$R$3:$X$9,3,FALSE) -> 14.6 | U13: =VLOOKUP($B13,$R$3:$X$9,4,FALSE) -> 0 | V13: =VLOOKUP($B13,$R$3:$X$9,5,FALSE) -> 0.13905093 | W13: =VLOOKUP($B13,$R$3:$X$9,6,FALSE) -> 0.26041667 | X13: =VLOOKUP($B13,$R$3:$X$9,7,FALSE) -> 0.29513889 | Y13: =VLOOKUP($B13,$R$3:$Z$9,8,FALSE) -> 0 | Z13: =VLOOKUP($B13,$R$3:$Z$9,9,FALSE) -> 75
R14: =B14 -> 0 | S14: =VLOOKUP($B14,$R$3:$X$9,2,FALSE) -> #N/A | T14: =VLOOKUP($B14,$R$3:$X$9,3,FALSE) -> #N/A | U14: =VLOOKUP($B14,$R$3:$X$9,4,FALSE) -> #N/A | V14: =VLOOKUP($B14,$R$3:$X$9,5,FALSE) -> #N/A | W14: =VLOOKUP($B14,$R$3:$X$9,6,FALSE) -> #N/A | X14: =VLOOKUP($B14,$R$3:$X$9,7,FALSE) -> #N/A | Y14: =VLOOKUP($B14,$R$3:$Z$9,8,FALSE) -> #N/A | Z14: =VLOOKUP($B14,$R$3:$Z$9,9,FALSE) -> #N/A
R15: =B15 -> 0 | S15: =VLOOKUP($B15,$R$3:$X$9,2,FALSE) -> #N/A | T15: =VLOOKUP($B15,$R$3:$X$9,3,FALSE) -> #N/A | U15: =VLOOKUP($B15,$R$3:$X$9,4,FALSE) -> #N/A | V15: =VLOOKUP($B15,$R$3:$X$9,5,FALSE) -> #N/A | W15: =VLOOKUP($B15,$R$3:$X$9,6,FALSE) -> #N/A | X15: =VLOOKUP($B15,$R$3:$X$9,7,FALSE) -> #N/A | Y15: =VLOOKUP($B15,$R$3:$Z$9,8,FALSE) -> #N/A | Z15: =VLOOKUP($B15,$R$3:$Z$9,9,FALSE) -> #N/A
B16: CARIB | C16: =[24]Brewhouse!$A655 -> CA547 | D16: =[24]Brewhouse!$AF655 -> 52.3 | E16: =[24]Brewhouse!$AI655 -> 49.7 | F16: =[24]Brewhouse!$V655 -> 60 | G16: =[24]Brewhouse!AG655 -> 11.9 | H16: 11.7 | I16: =[24]Brewhouse!$AU655 -> 96.304712 | J16: =[24]Brewhouse!$AV655 -> 97.912271 | K16: =[24]Brewhouse!$Q655 -> 9.3090909 | L16: =[24]Brewhouse!$P655 -> 64 | M16: =[24]Brewhouse!$U655-[24]Brewhouse!$T655 -> 0.11666667 | N16: =[24]Brewhouse!$Z655 -> 0.24513889 | O16: =[24]Brewhouse!$AX655 -> K.Benjamin | R16: =B16 -> CARIB | S16: =VLOOKUP($B16,$R$3:$X$9,2,FALSE) -> 11.6 | T16: =VLOOKUP($B16,$R$3:$X$9,3,FALSE) -> 12 | U16: =VLOOKUP($B16,$R$3:$X$9,4,FALSE) -> 0 | V16: =VLOOKUP($B16,$R$3:$X$9,5,FALSE) -> 0.11805556 | W16: =VLOOKUP($B16,$R$3:$X$9,6,FALSE) -> 0.22569444 | X16: =VLOOKUP($B16,$R$3:$X$9,7,FALSE) -> 0.26388889 | Y16: =VLOOKUP($B16,$R$3:$Z$9,8,FALSE) -> 0 | Z16: =VLOOKUP($B16,$R$3:$Z$9,9,FALSE) -> 60
B17: CARIB | C17: =[24]Brewhouse!$A656 -> CA548 | D17: =[24]Brewhouse!$AF656 -> 53 | E17: =[24]Brewhouse!$AI656 -> 52.2 | F17: =[24]Brewhouse!$V656 -> 61 | G17: =[24]Brewhouse!AG656 -> 11.7 | H17: 11.8 | I17: =[24]Brewhouse!$AU656 -> 99.118181 | J17: =[24]Brewhouse!$AV656 -> 100.77306 | K17: =[24]Brewhouse!$Q656 -> 8.2032668 | L17: =[24]Brewhouse!$P656 -> 60 | M17: =[24]Brewhouse!$U656-[24]Brewhouse!$T656 -> 0.11388889 | N17: =[24]Brewhouse!$Z656 -> 0.23541667 | O17: =[24]Brewhouse!$AX656 -> K.Benjamin | R17: =B17 -> CARIB | S17: =VLOOKUP($B17,$R$3:$X$9,2,FALSE) -> 11.6 | T17: =VLOOKUP($B17,$R$3:$X$9,3,FALSE) -> 12 | U17: =VLOOKUP($B17,$R$3:$X$9,4,FALSE) -> 0 | V17: =VLOOKUP($B17,$R$3:$X$9,5,FALSE) -> 0.11805556 | W17: =VLOOKUP($B17,$R$3:$X$9,6,FALSE) -> 0.22569444 | X17: =VLOOKUP($B17,$R$3:$X$9,7,FALSE) -> 0.26388889 | Y17: =VLOOKUP($B17,$R$3:$Z$9,8,FALSE) -> 0 | Z17: =VLOOKUP($B17,$R$3:$Z$9,9,FALSE) -> 60
B18: CARIB | C18: =[24]Brewhouse!$A657 -> CA549 | D18: =[24]Brewhouse!$AF657 -> 52.4 | E18: =[24]Brewhouse!$AI657 -> 50.5 | F18: =[24]Brewhouse!$V657 -> 55 | G18: =[24]Brewhouse!AG657 -> 11.9 | H18: 11.9 | I18: =[24]Brewhouse!$AU657 -> 97.61512 | J18: =[24]Brewhouse!$AV657 -> 99.244906 | K18: =[24]Brewhouse!$Q657 -> 8.2647585 | L18: =[24]Brewhouse!$P657 -> 60 | M18: =[24]Brewhouse!$U657-[24]Brewhouse!$T657 -> 0.10555556 | N18: =[24]Brewhouse!$Z657 -> 0.25069444 | O18: =[24]Brewhouse!$AX657 -> R. Regis | P18: AG Trial | R18: =B18 -> CARIB | S18: =VLOOKUP($B18,$R$3:$X$9,2,FALSE) -> 11.6 | T18: =VLOOKUP($B18,$R$3:$X$9,3,FALSE) -> 12 | U18: =VLOOKUP($B18,$R$3:$X$9,4,FALSE) -> 0 | V18: =VLOOKUP($B18,$R$3:$X$9,5,FALSE) -> 0.11805556 | W18: =VLOOKUP($B18,$R$3:$X$9,6,FALSE) -> 0.22569444 | X18: =VLOOKUP($B18,$R$3:$X$9,7,FALSE) -> 0.26388889 | Y18: =VLOOKUP($B18,$R$3:$Z$9,8,FALSE) -> 0 | Z18: =VLOOKUP($B18,$R$3:$Z$9,9,FALSE) -> 60
R19: =B19 -> 0 | S19: =VLOOKUP($B19,$R$3:$X$9,2,FALSE) -> #N/A | T19: =VLOOKUP($B19,$R$3:$X$9,3,FALSE) -> #N/A | U19: =VLOOKUP($B19,$R$3:$X$9,4,FALSE) -> #N/A | V19: =VLOOKUP($B19,$R$3:$X$9,5,FALSE) -> #N/A | W19: =VLOOKUP($B19,$R$3:$X$9,6,FALSE) -> #N/A | X19: =VLOOKUP($B19,$R$3:$X$9,7,FALSE) -> #N/A | Y19: =VLOOKUP($B19,$R$3:$Z$9,8,FALSE) -> #N/A | Z19: =VLOOKUP($B19,$R$3:$Z$9,9,FALSE) -> #N/A
R20: =B20 -> 0 | S20: =VLOOKUP($B20,$R$3:$X$9,2,FALSE) -> #N/A | T20: =VLOOKUP($B20,$R$3:$X$9,3,FALSE) -> #N/A | U20: =VLOOKUP($B20,$R$3:$X$9,4,FALSE) -> #N/A | V20: =VLOOKUP($B20,$R$3:$X$9,5,FALSE) -> #N/A | W20: =VLOOKUP($B20,$R$3:$X$9,6,FALSE) -> #N/A | X20: =VLOOKUP($B20,$R$3:$X$9,7,FALSE) -> #N/A | Y20: =VLOOKUP($B20,$R$3:$Z$9,8,FALSE) -> #N/A | Z20: =VLOOKUP($B20,$R$3:$Z$9,9,FALSE) -> #N/A
R21: =B21 -> 0 | S21: =VLOOKUP($B21,$R$3:$X$9,2,FALSE) -> #N/A | T21: =VLOOKUP($B21,$R$3:$X$9,3,FALSE) -> #N/A | U21: =VLOOKUP($B21,$R$3:$X$9,4,FALSE) -> #N/A | V21: =VLOOKUP($B21,$R$3:$X$9,5,FALSE) -> #N/A | W21: =VLOOKUP($B21,$R$3:$X$9,6,FALSE) -> #N/A | X21: =VLOOKUP($B21,$R$3:$X$9,7,FALSE) -> #N/A | Y21: =VLOOKUP($B21,$R$3:$Z$9,8,FALSE) -> #N/A | Z21: =VLOOKUP($B21,$R$3:$Z$9,9,FALSE) -> #N/A
R22: =B22 -> 0 | S22: =VLOOKUP($B22,$R$3:$X$9,2,FALSE) -> #N/A | T22: =VLOOKUP($B22,$R$3:$X$9,3,FALSE) -> #N/A | U22: =VLOOKUP($B22,$R$3:$X$9,4,FALSE) -> #N/A | V22: =VLOOKUP($B22,$R$3:$X$9,5,FALSE) -> #N/A | W22: =VLOOKUP($B22,$R$3:$X$9,6,FALSE) -> #N/A | X22: =VLOOKUP($B22,$R$3:$X$9,7,FALSE) -> #N/A | Y22: =VLOOKUP($B22,$R$3:$Z$9,8,FALSE) -> #N/A | Z22: =VLOOKUP($B22,$R$3:$Z$9,9,FALSE) -> #N/A
R23: =B23 -> 0 | S23: =VLOOKUP($B23,$R$3:$X$9,2,FALSE) -> #N/A | T23: =VLOOKUP($B23,$R$3:$X$9,3,FALSE) -> #N/A | U23: =VLOOKUP($B23,$R$3:$X$9,4,FALSE) -> #N/A | V23: =VLOOKUP($B23,$R$3:$X$9,5,FALSE) -> #N/A | W23: =VLOOKUP($B23,$R$3:$X$9,6,FALSE) -> #N/A | X23: =VLOOKUP($B23,$R$3:$X$9,7,FALSE) -> #N/A | Y23: =VLOOKUP($B23,$R$3:$Z$9,8,FALSE) -> #N/A | Z23: =VLOOKUP($B23,$R$3:$Z$9,9,FALSE) -> #N/A
R24: =B24 -> 0 | S24: =VLOOKUP($B24,$R$3:$X$9,2,FALSE) -> #N/A | T24: =VLOOKUP($B24,$R$3:$X$9,3,FALSE) -> #N/A | U24: =VLOOKUP($B24,$R$3:$X$9,4,FALSE) -> #N/A | V24: =VLOOKUP($B24,$R$3:$X$9,5,FALSE) -> #N/A | W24: =VLOOKUP($B24,$R$3:$X$9,6,FALSE) -> #N/A | X24: =VLOOKUP($B24,$R$3:$X$9,7,FALSE) -> #N/A | Y24: =VLOOKUP($B24,$R$3:$Z$9,8,FALSE) -> #N/A | Z24: =VLOOKUP($B24,$R$3:$Z$9,9,FALSE) -> #N/A
R25: =B25 -> 0 | S25: =VLOOKUP($B25,$R$3:$X$9,2,FALSE) -> #N/A | T25: =VLOOKUP($B25,$R$3:$X$9,3,FALSE) -> #N/A | U25: =VLOOKUP($B25,$R$3:$X$9,4,FALSE) -> #N/A | V25: =VLOOKUP($B25,$R$3:$X$9,5,FALSE) -> #N/A | W25: =VLOOKUP($B25,$R$3:$X$9,6,FALSE) -> #N/A | X25: =VLOOKUP($B25,$R$3:$X$9,7,FALSE) -> #N/A | Y25: =VLOOKUP($B25,$R$3:$Z$9,8,FALSE) -> #N/A | Z25: =VLOOKUP($B25,$R$3:$Z$9,9,FALSE) -> #N/A
R26: =B26 -> 0 | S26: =VLOOKUP($B26,$R$3:$X$9,2,FALSE) -> #N/A | T26: =VLOOKUP($B26,$R$3:$X$9,3,FALSE) -> #N/A | U26: =VLOOKUP($B26,$R$3:$X$9,4,FALSE) -> #N/A | V26: =VLOOKUP($B26,$R$3:$X$9,5,FALSE) -> #N/A | W26: =VLOOKUP($B26,$R$3:$X$9,6,FALSE) -> #N/A | X26: =VLOOKUP($B26,$R$3:$X$9,7,FALSE) -> #N/A | Y26: =VLOOKUP($B26,$R$3:$Z$9,8,FALSE) -> #N/A | Z26: =VLOOKUP($B26,$R$3:$Z$9,9,FALSE) -> #N/A
R27: =B27 -> 0 | S27: =VLOOKUP($B27,$R$3:$X$9,2,FALSE) -> #N/A | T27: =VLOOKUP($B27,$R$3:$X$9,3,FALSE) -> #N/A | U27: =VLOOKUP($B27,$R$3:$X$9,4,FALSE) -> #N/A | V27: =VLOOKUP($B27,$R$3:$X$9,5,FALSE) -> #N/A | W27: =VLOOKUP($B27,$R$3:$X$9,6,FALSE) -> #N/A | X27: =VLOOKUP($B27,$R$3:$X$9,7,FALSE) -> #N/A | Y27: =VLOOKUP($B27,$R$3:$Z$9,8,FALSE) -> #N/A | Z27: =VLOOKUP($B27,$R$3:$Z$9,9,FALSE) -> #N/A
R28: =B28 -> 0 | S28: =VLOOKUP($B28,$R$3:$X$9,2,FALSE) -> #N/A | T28: =VLOOKUP($B28,$R$3:$X$9,3,FALSE) -> #N/A | U28: =VLOOKUP($B28,$R$3:$X$9,4,FALSE) -> #N/A | V28: =VLOOKUP($B28,$R$3:$X$9,5,FALSE) -> #N/A | W28: =VLOOKUP($B28,$R$3:$X$9,6,FALSE) -> #N/A | X28: =VLOOKUP($B28,$R$3:$X$9,7,FALSE) -> #N/A | Y28: =VLOOKUP($B28,$R$3:$Z$9,8,FALSE) -> #N/A | Z28: =VLOOKUP($B28,$R$3:$Z$9,9,FALSE) -> #N/A
R29: =B29 -> 0 | S29: =VLOOKUP($B29,$R$3:$X$9,2,FALSE) -> #N/A | T29: =VLOOKUP($B29,$R$3:$X$9,3,FALSE) -> #N/A | U29: =VLOOKUP($B29,$R$3:$X$9,4,FALSE) -> #N/A | V29: =VLOOKUP($B29,$R$3:$X$9,5,FALSE) -> #N/A | W29: =VLOOKUP($B29,$R$3:$X$9,6,FALSE) -> #N/A | X29: =VLOOKUP($B29,$R$3:$X$9,7,FALSE) -> #N/A | Y29: =VLOOKUP($B29,$R$3:$Z$9,8,FALSE) -> #N/A | Z29: =VLOOKUP($B29,$R$3:$Z$9,9,FALSE) -> #N/A
R30: =B30 -> 0 | S30: =VLOOKUP($B30,$R$3:$X$9,2,FALSE) -> #N/A | T30: =VLOOKUP($B30,$R$3:$X$9,3,FALSE) -> #N/A | U30: =VLOOKUP($B30,$R$3:$X$9,4,FALSE) -> #N/A | V30: =VLOOKUP($B30,$R$3:$X$9,5,FALSE) -> #N/A | W30: =VLOOKUP($B30,$R$3:$X$9,6,FALSE) -> #N/A | X30: =VLOOKUP($B30,$R$3:$X$9,7,FALSE) -> #N/A | Y30: =VLOOKUP($B30,$R$3:$Z$9,8,FALSE) -> #N/A | Z30: =VLOOKUP($B30,$R$3:$Z$9,9,FALSE) -> #N/A
... R32: =B32 -> 0 | S32: =VLOOKUP($B32,$R$3:$X$9,2,FALSE) -> #N/A | T32: =VLOOKUP($B32,$R$3:$X$9,3,FALSE) -> #N/A | U32: =VLOOKUP($B32,$R$3:$X$9,4,FALSE) -> #N/A | V32: =VLOOKUP($B32,$R$3:$X$9,5,FALSE) -> #N/A | W32: =VLOOKUP($B32,$R$3:$X$9,6,FALSE) -> #N/A | X32: =VLOOKUP($B32,$R$3:$X$9,7,FALSE) -> #N/A | Y32: =VLOOKUP($B32,$R$3:$Z$9,8,FALSE) -> #N/A | Z32: =VLOOKUP($B32,$R$3:$Z$9,9,FALSE) -> #N/A
B33: BRAND | D33: BBT P.G./ O.G | I33: Brand | J33: Actual | K33: MTD No. of Brews | L33: MTD | M33: YTD | N33: Target | R33: =B33 -> BRAND | S33: =VLOOKUP($B33,$R$3:$X$9,2,FALSE) -> #N/A | T33: =VLOOKUP($B33,$R$3:$X$9,3,FALSE) -> #N/A | U33: =VLOOKUP($B33,$R$3:$X$9,4,FALSE) -> #N/A | V33: =VLOOKUP($B33,$R$3:$X$9,5,FALSE) -> #N/A | W33: =VLOOKUP($B33,$R$3:$X$9,6,FALSE) -> #N/A | X33: =VLOOKUP($B33,$R$3:$X$9,7,FALSE) -> #N/A | Y33: =VLOOKUP($B33,$R$3:$Z$9,8,FALSE) -> #N/A | Z33: =VLOOKUP($B33,$R$3:$Z$9,9,FALSE) -> #N/A
B34: =I34 -> CARIB | C34: =[24]Process!D612 -> 12.2 | D34: 11.8 | I34: CARIB | J34: =AVERAGE(I16:I18) -> 97.679338 | K34: =COUNTA([24]Brewhouse!$A$655:$A$657) -> 3 | L34: =AVERAGE([24]Brewhouse!$AU$655:$AU$657) -> 97.679338 | M34: =AVERAGE([24]Brewhouse!$AU$102:$AU$171,[24]Brewhouse!$AU$173:$AU$253,[24]Brewhouse!$AU$255:$AU$339,[24]Brewhouse!$AU$341:$AU$346,[24]Brewhouse!$AU$348,[24]Brewhouse!$AU$349:$AU$406,[24]Brewhouse!$AU$408:$AU$491,[24]Brewhouse!$AU$493:$AU$578,[24]Brewhouse!$AU$580:$AU$652,[24]Brewhouse!$AU$655:$AU$657) -> 97.877501 | N34: 98
C35: =[24]Process!D613 -> 12 | I35: STAG | K35: =COUNTA([22]Brewhouse!$A$324:$A$331) -> 8 | L35: =AVERAGE([22]Brewhouse!$AS$324:$AS$331) -> 98.450752 | M35: =AVERAGE([22]Brewhouse!$AS$15:$AS$64,[22]Brewhouse!$AS$66:$AS$103,[22]Brewhouse!$AS$105:$AS$140,[22]Brewhouse!$AS$142:$AS$193,[22]Brewhouse!$AS$195:$AS$240,[22]Brewhouse!$AS$242:$AS$273,[22]Brewhouse!$AS$275:$AS$322,[22]Brewhouse!$AS$324:$AS$331) -> 98.076073 | N35: 98
C36: =[24]Process!D614 -> 12 | D36: 11.9 | I36: GUINNESS | M36: =AVERAGE([25]Brewhouse!$AU$4:$AU$7,[25]Brewhouse!$AU$9:$AU$22,[25]Brewhouse!$AU$24:$AU$35,[25]Brewhouse!$AU$37:$AU$45,[25]Brewhouse!$AU$47:$AU$62,[25]Brewhouse!$AU$64:$AU$79) -> 97.01892 | N36: 98
C37: =[24]Process!D615 -> 11.8 | I37: VITAMALT | J37: =AVERAGE(I10:I13) -> 97.964622 | K37: =COUNTA([26]Brewhouse!$A$64:$A$67) -> 4 | L37: =AVERAGE([26]Brewhouse!$AV$64:$AV$67) -> 97.964622 | M37: =AVERAGE([26]Brewhouse!$AV$5:$AV$14,[26]Brewhouse!$AV$16:$AV$19,[26]Brewhouse!$AV$21:$AV$24,[26]Brewhouse!$AV$26:$AV$33,[26]Brewhouse!$AV$35:$AV$46,[26]Brewhouse!$AV$48:$AV$53,[26]Brewhouse!$AV$55:$AV$62,[26]Brewhouse!$AV$64:$AV$67) -> 98.715594 | N37: 98
C38: =[24]Process!D616 -> 12 | D38: 11.92 | I38: MAXIMALT | N38: 98
C39: =[24]Process!D617 -> 11.8 | I39: MACKESON | M39: =AVERAGE([27]Brewhouse!$AT$4:$AT$11,[27]Brewhouse!$AT$13:$AT$16,[27]Brewhouse!$AT$18:$AT$21,[27]Brewhouse!$AT$26) -> 94.588058 | N39: 98
C40: =[24]Process!D618 -> 12 | D40: 11.82 | I40: STARMALT | M40: =AVERAGE([23]Brewhouse!$AY$6:$AY$13,[23]Brewhouse!$AY$15:$AY$20,[23]Brewhouse!$AY$22:$AY$29,[23]Brewhouse!$AY$31:$AY$34,[23]Brewhouse!$AY$36:$AY$43,[23]Brewhouse!$AY$45:$AY$50, [23]Brewhouse!$AY$56:$AY$73) -> 97.363751 | N40: 98
C41: =[24]Process!D619 -> 11.7 | I41: HR- Pils | M41: =AVERAGE([28]Brewhouse!$AU$5:$AU$8,[28]Brewhouse!$AU$10:$AU$13) -> 94.247667 | N41: 98
...

Sheet Aug 6th 
S1: P.G. | U1: Hot Time | W1: Process Time | Y1: Cooling Time
B2: Brewing Department Daily Process Loss Report | S2: Lower | T2: Upper | U2: Lower | V2: Upper | W2: Lower | X2: Upper | Y2: Lower | Z2: Upper
R3: CARIB | S3: 11.6 | T3: 12 | U3: 0 | V3: 0.11805556 | W3: 0.22569444 | X3: 0.26388889 | Y3: 0 | Z3: 60 | AB3: HR- PISNER
B4: Date: | C4: 45875 | J4: LOT WORT COLOUR: 3.3 | M4: Filter Sheets (Target 20 days) | R4: STAG | S4: 11.6 | T4: 12 | U4: 0 | V4: 0.11805556 | W4: 0.22569444 | X4: 0.26388889 | Y4: 0 | Z4: 60
M5: Double | N5: Single | R5: GUINNESS | S5: 17 | T5: 17.5 | U5: 0 | V5: 0.10763889 | W5: 0.24652778 | X5: 0.28472222 | Y5: 0 | Z5: 60
J6: MALT LOT: Lot #42 | L6: Sheet Day | M6: 10 | N6: 10 | R6: MACKESON | S6: 13.3 | T6: 13.5 | U6: 0 | V6: 0.12905093 | W6: 0.27430556 | X6: 0.30208333 | Y6: 0
R7: STARMALT | S7: 17.1 | T7: 17.5 | U7: 0 | V7: 0.13605324 | W7: 0.27430556 | X7: 0.30902778 | Y7: 0 | Z7: 85
B8: Brand | C8: Brew no. | D8: Kett. Hls | E8: Wort | F8: Cool Time(Mins) | G8: Cast. P.G. (Lab Result) | H8: Cast P.G. (Cellar Operator)-gravity | I8: Extr. Rec (77.9%) | J8: Theor. Extr. (77.5%) | K8: Boil Off /Vol. (4-6%) | L8: Boil Time | M8: Total Hot | N8: Brewing | O8: Operator | R8: Hurricane Reef | S8: 16.6 | T8: 17 | U8: 0 | V8: 0.12905093 | W8: 0.27430556 | X8: 0.30208333 | Y8: 0
E9: Meter (Hls) | F9: Target(< 60Mins) | M9: Time | R9: VITAMALT | S9: 14.4 | T9: 14.6 | U9: 0 | V9: 0.13905093 | W9: 0.26041667 | X9: 0.29513889 | Y9: 0 | Z9: 75
R10: =B10 -> 0 | S10: =VLOOKUP($B10,$R$3:$X$9,2,FALSE) -> #N/A | T10: =VLOOKUP($B10,$R$3:$X$9,3,FALSE) -> #N/A | U10: =VLOOKUP($B10,$R$3:$X$9,4,FALSE) -> #N/A | V10: =VLOOKUP($B10,$R$3:$X$9,5,FALSE) -> #N/A | W10: =VLOOKUP($B10,$R$3:$X$9,6,FALSE) -> #N/A | X10: =VLOOKUP($B10,$R$3:$X$9,7,FALSE) -> #N/A | Y10: =VLOOKUP($B10,$R$3:$Z$9,8,FALSE) -> #N/A | Z10: =VLOOKUP($B10,$R$3:$Z$9,9,FALSE) -> #N/A
R11: =B11 -> 0 | S11: =VLOOKUP($B11,$R$3:$X$9,2,FALSE) -> #N/A | T11: =VLOOKUP($B11,$R$3:$X$9,3,FALSE) -> #N/A | U11: =VLOOKUP($B11,$R$3:$X$9,4,FALSE) -> #N/A | V11: =VLOOKUP($B11,$R$3:$X$9,5,FALSE) -> #N/A | W11: =VLOOKUP($B11,$R$3:$X$9,6,FALSE) -> #N/A | X11: =VLOOKUP($B11,$R$3:$X$9,7,FALSE) -> #N/A | Y11: =VLOOKUP($B11,$R$3:$Z$9,8,FALSE) -> #N/A | Z11: =VLOOKUP($B11,$R$3:$Z$9,9,FALSE) -> #N/A
R12: =B12 -> 0 | S12: =VLOOKUP($B12,$R$3:$X$9,2,FALSE) -> #N/A | T12: =VLOOKUP($B12,$R$3:$X$9,3,FALSE) -> #N/A | U12: =VLOOKUP($B12,$R$3:$X$9,4,FALSE) -> #N/A | V12: =VLOOKUP($B12,$R$3:$X$9,5,FALSE) -> #N/A | W12: =VLOOKUP($B12,$R$3:$X$9,6,FALSE) -> #N/A | X12: =VLOOKUP($B12,$R$3:$X$9,7,FALSE) -> #N/A | Y12: =VLOOKUP($B12,$R$3:$Z$9,8,FALSE) -> #N/A | Z12: =VLOOKUP($B12,$R$3:$Z$9,9,FALSE) -> #N/A
R13: =B13 -> 0 | S13: =VLOOKUP($B13,$R$3:$X$9,2,FALSE) -> #N/A | T13: =VLOOKUP($B13,$R$3:$X$9,3,FALSE) -> #N/A | U13: =VLOOKUP($B13,$R$3:$X$9,4,FALSE) -> #N/A | V13: =VLOOKUP($B13,$R$3:$X$9,5,FALSE) -> #N/A | W13: =VLOOKUP($B13,$R$3:$X$9,6,FALSE) -> #N/A | X13: =VLOOKUP($B13,$R$3:$X$9,7,FALSE) -> #N/A | Y13: =VLOOKUP($B13,$R$3:$Z$9,8,FALSE) -> #N/A | Z13: =VLOOKUP($B13,$R$3:$Z$9,9,FALSE) -> #N/A
R14: =B14 -> 0 | S14: =VLOOKUP($B14,$R$3:$X$9,2,FALSE) -> #N/A | T14: =VLOOKUP($B14,$R$3:$X$9,3,FALSE) -> #N/A | U14: =VLOOKUP($B14,$R$3:$X$9,4,FALSE) -> #N/A | V14: =VLOOKUP($B14,$R$3:$X$9,5,FALSE) -> #N/A | W14: =VLOOKUP($B14,$R$3:$X$9,6,FALSE) -> #N/A | X14: =VLOOKUP($B14,$R$3:$X$9,7,FALSE) -> #N/A | Y14: =VLOOKUP($B14,$R$3:$Z$9,8,FALSE) -> #N/A | Z14: =VLOOKUP($B14,$R$3:$Z$9,9,FALSE) -> #N/A
R15: =B15 -> 0 | S15: =VLOOKUP($B15,$R$3:$X$9,2,FALSE) -> #N/A | T15: =VLOOKUP($B15,$R$3:$X$9,3,FALSE) -> #N/A | U15: =VLOOKUP($B15,$R$3:$X$9,4,FALSE) -> #N/A | V15: =VLOOKUP($B15,$R$3:$X$9,5,FALSE) -> #N/A | W15: =VLOOKUP($B15,$R$3:$X$9,6,FALSE) -> #N/A | X15: =VLOOKUP($B15,$R$3:$X$9,7,FALSE) -> #N/A | Y15: =VLOOKUP($B15,$R$3:$Z$9,8,FALSE) -> #N/A | Z15: =VLOOKUP($B15,$R$3:$Z$9,9,FALSE) -> #N/A
R16: =B16 -> 0 | S16: =VLOOKUP($B16,$R$3:$X$9,2,FALSE) -> #N/A | T16: =VLOOKUP($B16,$R$3:$X$9,3,FALSE) -> #N/A | U16: =VLOOKUP($B16,$R$3:$X$9,4,FALSE) -> #N/A | V16: =VLOOKUP($B16,$R$3:$X$9,5,FALSE) -> #N/A | W16: =VLOOKUP($B16,$R$3:$X$9,6,FALSE) -> #N/A | X16: =VLOOKUP($B16,$R$3:$X$9,7,FALSE) -> #N/A | Y16: =VLOOKUP($B16,$R$3:$Z$9,8,FALSE) -> #N/A | Z16: =VLOOKUP($B16,$R$3:$Z$9,9,FALSE) -> #N/A
R17: =B17 -> 0 | S17: =VLOOKUP($B17,$R$3:$X$9,2,FALSE) -> #N/A | T17: =VLOOKUP($B17,$R$3:$X$9,3,FALSE) -> #N/A | U17: =VLOOKUP($B17,$R$3:$X$9,4,FALSE) -> #N/A | V17: =VLOOKUP($B17,$R$3:$X$9,5,FALSE) -> #N/A | W17: =VLOOKUP($B17,$R$3:$X$9,6,FALSE) -> #N/A | X17: =VLOOKUP($B17,$R$3:$X$9,7,FALSE) -> #N/A | Y17: =VLOOKUP($B17,$R$3:$Z$9,8,FALSE) -> #N/A | Z17: =VLOOKUP($B17,$R$3:$Z$9,9,FALSE) -> #N/A
R18: =B18 -> 0 | S18: =VLOOKUP($B18,$R$3:$X$9,2,FALSE) -> #N/A | T18: =VLOOKUP($B18,$R$3:$X$9,3,FALSE) -> #N/A | U18: =VLOOKUP($B18,$R$3:$X$9,4,FALSE) -> #N/A | V18: =VLOOKUP($B18,$R$3:$X$9,5,FALSE) -> #N/A | W18: =VLOOKUP($B18,$R$3:$X$9,6,FALSE) -> #N/A | X18: =VLOOKUP($B18,$R$3:$X$9,7,FALSE) -> #N/A | Y18: =VLOOKUP($B18,$R$3:$Z$9,8,FALSE) -> #N/A | Z18: =VLOOKUP($B18,$R$3:$Z$9,9,FALSE) -> #N/A
B19: CARIB | C19: =[24]Brewhouse!$A658 -> CA550 | D19: =[24]Brewhouse!$AF658 -> 53.7 | E19: =[24]Brewhouse!$AI658 -> 52.8 | F19: =[24]Brewhouse!$V658 -> 65 | G19: =[24]Brewhouse!AG658 -> 11.9 | H19: 11.8 | I19: =[24]Brewhouse!$AU658 -> 103.15419 | J19: =[24]Brewhouse!$AV658 -> 104.94947 | K19: =[24]Brewhouse!$Q658 -> 7.7697842 | L19: =[24]Brewhouse!$P658 -> 60 | M19: =[24]Brewhouse!$U658-[24]Brewhouse!$T658 -> 0.11319444 | N19: =[24]Brewhouse!$Z658 -> 0.25 | O19: =[24]Brewhouse!$AX658 -> R. Regis | R19: =B19 -> CARIB | S19: =VLOOKUP($B19,$R$3:$X$9,2,FALSE) -> 11.6 | T19: =VLOOKUP($B19,$R$3:$X$9,3,FALSE) -> 12 | U19: =VLOOKUP($B19,$R$3:$X$9,4,FALSE) -> 0 | V19: =VLOOKUP($B19,$R$3:$X$9,5,FALSE) -> 0.11805556 | W19: =VLOOKUP($B19,$R$3:$X$9,6,FALSE) -> 0.22569444 | X19: =VLOOKUP($B19,$R$3:$X$9,7,FALSE) -> 0.26388889 | Y19: =VLOOKUP($B19,$R$3:$Z$9,8,FALSE) -> 0 | Z19: =VLOOKUP($B19,$R$3:$Z$9,9,FALSE) -> 60
B20: CARIB | C20: =[24]Brewhouse!$A659 -> CA551 | D20: =[24]Brewhouse!$AF659 -> 52.1 | E20: =[24]Brewhouse!$AI659 -> 50.3 | F20: =[24]Brewhouse!$V659 -> 57 | G20: =[24]Brewhouse!AG659 -> 12 | H20: 12 | I20: =[24]Brewhouse!$AU659 -> 98.649638 | J20: =[24]Brewhouse!$AV659 -> 100.36689 | K20: =[24]Brewhouse!$Q659 -> 8.4135472 | L20: =[24]Brewhouse!$P659 -> 60 | M20: =[24]Brewhouse!$U659-[24]Brewhouse!$T659 -> 0.10625 | N20: =[24]Brewhouse!$Z659 -> 0.25 | O20: =[24]Brewhouse!$AX659 -> R. Regis | R20: =B20 -> CARIB | S20: =VLOOKUP($B20,$R$3:$X$9,2,FALSE) -> 11.6 | T20: =VLOOKUP($B20,$R$3:$X$9,3,FALSE) -> 12 | U20: =VLOOKUP($B20,$R$3:$X$9,4,FALSE) -> 0 | V20: =VLOOKUP($B20,$R$3:$X$9,5,FALSE) -> 0.11805556 | W20: =VLOOKUP($B20,$R$3:$X$9,6,FALSE) -> 0.22569444 | X20: =VLOOKUP($B20,$R$3:$X$9,7,FALSE) -> 0.26388889 | Y20: =VLOOKUP($B20,$R$3:$Z$9,8,FALSE) -> 0 | Z20: =VLOOKUP($B20,$R$3:$Z$9,9,FALSE) -> 60
B21: CARIB | C21: =[24]Brewhouse!$A660 -> CA552 | D21: =[24]Brewhouse!$AF660 -> 52.4 | E21: =[24]Brewhouse!$AI660 -> 50.9 | F21: =[24]Brewhouse!$V660 -> 62 | G21: =[24]Brewhouse!AG660 -> 11.8 | H21: 11.8 | I21: =[24]Brewhouse!$AU660 -> 97.957125 | J21: =[24]Brewhouse!$AV660 -> 99.662413 | K21: =[24]Brewhouse!$Q660 -> 4.1187384 | L21: =[24]Brewhouse!$P660 -> 57 | M21: =[24]Brewhouse!$U660-[24]Brewhouse!$T660 -> 0.10208333 | N21: =[24]Brewhouse!$Z660 -> 0.25277778 | O21: =[24]Brewhouse!$AX660 -> R. Sookram | R21: =B21 -> CARIB | S21: =VLOOKUP($B21,$R$3:$X$9,2,FALSE) -> 11.6 | T21: =VLOOKUP($B21,$R$3:$X$9,3,FALSE) -> 12 | U21: =VLOOKUP($B21,$R$3:$X$9,4,FALSE) -> 0 | V21: =VLOOKUP($B21,$R$3:$X$9,5,FALSE) -> 0.11805556 | W21: =VLOOKUP($B21,$R$3:$X$9,6,FALSE) -> 0.22569444 | X21: =VLOOKUP($B21,$R$3:$X$9,7,FALSE) -> 0.26388889 | Y21: =VLOOKUP($B21,$R$3:$Z$9,8,FALSE) -> 0 | Z21: =VLOOKUP($B21,$R$3:$Z$9,9,FALSE) -> 60
B22: CARIB | C22: =[24]Brewhouse!$A661 -> CA553 | D22: =[24]Brewhouse!$AF661 -> 52.5 | E22: =[24]Brewhouse!$AI661 -> 50.4 | F22: =[24]Brewhouse!$V661 -> 70 | G22: =[24]Brewhouse!AG661 -> 11.7 | H22: 11.7 | I22: =[24]Brewhouse!$AU661 -> 96.012097 | J22: =[24]Brewhouse!$AV661 -> 97.683616 | K22: =[24]Brewhouse!$Q661 -> 6.7513612 | L22: =[24]Brewhouse!$P661 -> 59 | M22: =[24]Brewhouse!$U661-[24]Brewhouse!$T661 -> 0.11180556 | N22: =[24]Brewhouse!$Z661 -> 0.27152778 | O22: =[24]Brewhouse!$AX661 -> R. Sookram | R22: =B22 -> CARIB | S22: =VLOOKUP($B22,$R$3:$X$9,2,FALSE) -> 11.6 | T22: =VLOOKUP($B22,$R$3:$X$9,3,FALSE) -> 12 | U22: =VLOOKUP($B22,$R$3:$X$9,4,FALSE) -> 0 | V22: =VLOOKUP($B22,$R$3:$X$9,5,FALSE) -> 0.11805556 | W22: =VLOOKUP($B22,$R$3:$X$9,6,FALSE) -> 0.22569444 | X22: =VLOOKUP($B22,$R$3:$X$9,7,FALSE) -> 0.26388889 | Y22: =VLOOKUP($B22,$R$3:$Z$9,8,FALSE) -> 0 | Z22: =VLOOKUP($B22,$R$3:$Z$9,9,FALSE) -> 60
B23: CARIB | C23: =[24]Brewhouse!$A662 -> CA554 | D23: =[24]Brewhouse!$AF662 -> 53.1 | E23: =[24]Brewhouse!$AI662 -> 51.3 | F23: =[24]Brewhouse!$V662 -> 61 | G23: =[24]Brewhouse!AG662 -> 11.8 | H23: 11.9 | I23: =[24]Brewhouse!$AU662 -> 98.848571 | J23: =[24]Brewhouse!$AV662 -> 100.56929 | K23: =[24]Brewhouse!$Q662 -> 6.0036166 | L23: =[24]Brewhouse!$P662 -> 60 | M23: =[24]Brewhouse!$U662-[24]Brewhouse!$T662 -> 0.10833333 | N23: =[24]Brewhouse!$Z662 -> 0.24722222 | O23: =[24]Brewhouse!$AX662 -> R. Sookram | R23: =B23 -> CARIB | S23: =VLOOKUP($B23,$R$3:$X$9,2,FALSE) -> 11.6 | T23: =VLOOKUP($B23,$R$3:$X$9,3,FALSE) -> 12 | U23: =VLOOKUP($B23,$R$3:$X$9,4,FALSE) -> 0 | V23: =VLOOKUP($B23,$R$3:$X$9,5,FALSE) -> 0.11805556 | W23: =VLOOKUP($B23,$R$3:$X$9,6,FALSE) -> 0.22569444 | X23: =VLOOKUP($B23,$R$3:$X$9,7,FALSE) -> 0.26388889 | Y23: =VLOOKUP($B23,$R$3:$Z$9,8,FALSE) -> 0 | Z23: =VLOOKUP($B23,$R$3:$Z$9,9,FALSE) -> 60
B24: CARIB | C24: =[24]Brewhouse!$A663 -> CA555 | D24: =[24]Brewhouse!$AF663 -> 53.1 | E24: =[24]Brewhouse!$AI663 -> 50 | F24: =[24]Brewhouse!$V663 -> 59 | G24: =[24]Brewhouse!AG663 -> 11.8 | H24: 11.8 | I24: =[24]Brewhouse!$AU663 -> 95.560564 | J24: =[24]Brewhouse!$AV663 -> 97.156391 | K24: =[24]Brewhouse!$Q663 -> 6.8131868 | L24: =[24]Brewhouse!$P663 -> 61 | M24: =[24]Brewhouse!$U663-[24]Brewhouse!$T663 -> 0.11180556 | N24: =[24]Brewhouse!$Z663 -> 0.23819444 | O24: =[24]Brewhouse!$AX663 -> K.Benjamin | R24: =B24 -> CARIB | S24: =VLOOKUP($B24,$R$3:$X$9,2,FALSE) -> 11.6 | T24: =VLOOKUP($B24,$R$3:$X$9,3,FALSE) -> 12 | U24: =VLOOKUP($B24,$R$3:$X$9,4,FALSE) -> 0 | V24: =VLOOKUP($B24,$R$3:$X$9,5,FALSE) -> 0.11805556 | W24: =VLOOKUP($B24,$R$3:$X$9,6,FALSE) -> 0.22569444 | X24: =VLOOKUP($B24,$R$3:$X$9,7,FALSE) -> 0.26388889 | Y24: =VLOOKUP($B24,$R$3:$Z$9,8,FALSE) -> 0 | Z24: =VLOOKUP($B24,$R$3:$Z$9,9,FALSE) -> 60
B25: CARIB | C25: =[24]Brewhouse!$A664 -> CA556 | D25: =[24]Brewhouse!$AF664 -> 52 | E25: =[24]Brewhouse!$AI664 -> 50 | F25: =[24]Brewhouse!$V664 -> 54 | G25: =[24]Brewhouse!AG664 -> 11.9 | H25: 11.8 | I25: =[24]Brewhouse!$AU664 -> 96.767186 | J25: =[24]Brewhouse!$AV664 -> 98.382639 | K25: =[24]Brewhouse!$Q664 -> 7.2826087 | L25: =[24]Brewhouse!$P664 -> 61 | M25: =[24]Brewhouse!$U664-[24]Brewhouse!$T664 -> 0.10277778 | N25: =[24]Brewhouse!$Z664 -> 0.23541667 | O25: =[24]Brewhouse!$AX664 -> K.Benjamin | R25: =B25 -> CARIB | S25: =VLOOKUP($B25,$R$3:$X$9,2,FALSE) -> 11.6 | T25: =VLOOKUP($B25,$R$3:$X$9,3,FALSE) -> 12 | U25: =VLOOKUP($B25,$R$3:$X$9,4,FALSE) -> 0 | V25: =VLOOKUP($B25,$R$3:$X$9,5,FALSE) -> 0.11805556 | W25: =VLOOKUP($B25,$R$3:$X$9,6,FALSE) -> 0.22569444 | X25: =VLOOKUP($B25,$R$3:$X$9,7,FALSE) -> 0.26388889 | Y25: =VLOOKUP($B25,$R$3:$Z$9,8,FALSE) -> 0 | Z25: =VLOOKUP($B25,$R$3:$Z$9,9,FALSE) -> 60
B26: CARIB | C26: =[24]Brewhouse!$A665 -> CA557 | D26: =[24]Brewhouse!$AF665 -> 51.9 | E26: =[24]Brewhouse!$AI665 -> 50.7 | F26: =[24]Brewhouse!$V665 -> 58 | G26: =[24]Brewhouse!AG665 -> 12 | H26: 11.7 | I26: =[24]Brewhouse!$AU665 -> 98.867593 | J26: =[24]Brewhouse!$AV665 -> 100.51829 | K26: =[24]Brewhouse!$Q665 -> 6.1732852 | L26: =[24]Brewhouse!$P665 -> 62 | M26: =[24]Brewhouse!$U665-[24]Brewhouse!$T665 -> 0.11041667 | N26: =[24]Brewhouse!$Z665 -> 0.24444444 | O26: =[24]Brewhouse!$AX665 -> K.Benjamin | R26: =B26 -> CARIB | S26: =VLOOKUP($B26,$R$3:$X$9,2,FALSE) -> 11.6 | T26: =VLOOKUP($B26,$R$3:$X$9,3,FALSE) -> 12 | U26: =VLOOKUP($B26,$R$3:$X$9,4,FALSE) -> 0 | V26: =VLOOKUP($B26,$R$3:$X$9,5,FALSE) -> 0.11805556 | W26: =VLOOKUP($B26,$R$3:$X$9,6,FALSE) -> 0.22569444 | X26: =VLOOKUP($B26,$R$3:$X$9,7,FALSE) -> 0.26388889 | Y26: =VLOOKUP($B26,$R$3:$Z$9,8,FALSE) -> 0 | Z26: =VLOOKUP($B26,$R$3:$Z$9,9,FALSE) -> 60
B27: CARIB | C27: =[24]Brewhouse!$A666 -> CA558 | D27: =[24]Brewhouse!$AF666 -> 52.7 | E27: =[24]Brewhouse!$AI666 -> 50.9 | F27: =[24]Brewhouse!$V666 -> 59 | G27: =[24]Brewhouse!AG666 -> 11.7 | H27: 11.7 | I27: =[24]Brewhouse!$AU666 -> 97.323463 | J27: =[24]Brewhouse!$AV666 -> 99.017537 | K27: =[24]Brewhouse!$Q666 -> 5.8333333 | L27: =[24]Brewhouse!$P666 -> 60 | M27: =[24]Brewhouse!$U666-[24]Brewhouse!$T666 -> 0.10833333 | N27: =[24]Brewhouse!$Z666 -> 0.25 | O27: =[24]Brewhouse!$AX666 -> R. Regis | R27: =B27 -> CARIB | S27: =VLOOKUP($B27,$R$3:$X$9,2,FALSE) -> 11.6 | T27: =VLOOKUP($B27,$R$3:$X$9,3,FALSE) -> 12 | U27: =VLOOKUP($B27,$R$3:$X$9,4,FALSE) -> 0 | V27: =VLOOKUP($B27,$R$3:$X$9,5,FALSE) -> 0.11805556 | W27: =VLOOKUP($B27,$R$3:$X$9,6,FALSE) -> 0.22569444 | X27: =VLOOKUP($B27,$R$3:$X$9,7,FALSE) -> 0.26388889 | Y27: =VLOOKUP($B27,$R$3:$Z$9,8,FALSE) -> 0 | Z27: =VLOOKUP($B27,$R$3:$Z$9,9,FALSE) -> 60
B28: CARIB | C28: =[24]Brewhouse!$A667 -> CA559 | D28: =[24]Brewhouse!$AF667 -> 53.9 | E28: =[24]Brewhouse!$AI667 -> 52.2 | F28: =[24]Brewhouse!$V667 -> 65 | G28: =[24]Brewhouse!AG667 -> 11.6 | H28: 11.7 | I28: =[24]Brewhouse!$AU667 -> 99.15607 | J28: =[24]Brewhouse!$AV667 -> 100.88186 | K28: =[24]Brewhouse!$Q667 -> 6.6906475 | L28: =[24]Brewhouse!$P667 -> 60 | M28: =[24]Brewhouse!$U667-[24]Brewhouse!$T667 -> 0.12569444 | N28: =[24]Brewhouse!$Z667 -> 0.28125 | O28: =[24]Brewhouse!$AX667 -> R. Regis | R28: =B28 -> CARIB | S28: =VLOOKUP($B28,$R$3:$X$9,2,FALSE) -> 11.6 | T28: =VLOOKUP($B28,$R$3:$X$9,3,FALSE) -> 12 | U28: =VLOOKUP($B28,$R$3:$X$9,4,FALSE) -> 0 | V28: =VLOOKUP($B28,$R$3:$X$9,5,FALSE) -> 0.11805556 | W28: =VLOOKUP($B28,$R$3:$X$9,6,FALSE) -> 0.22569444 | X28: =VLOOKUP($B28,$R$3:$X$9,7,FALSE) -> 0.26388889 | Y28: =VLOOKUP($B28,$R$3:$Z$9,8,FALSE) -> 0 | Z28: =VLOOKUP($B28,$R$3:$Z$9,9,FALSE) -> 60
B29: CARIB | C29: =[24]Brewhouse!$A668 -> CA560 | D29: =[24]Brewhouse!$AF668 -> 51.8 | E29: =[24]Brewhouse!$AI668 -> 50.1 | F29: =[24]Brewhouse!$V668 -> 66 | G29: =[24]Brewhouse!AG668 -> 11.9 | H29: 11.8 | I29: =[24]Brewhouse!$AU668 -> 97.637465 | J29: =[24]Brewhouse!$AV668 -> 99.336912 | K29: =[24]Brewhouse!$Q668 -> 8.4587814 | L29: =[24]Brewhouse!$P668 -> 61 | M29: =[24]Brewhouse!$U668-[24]Brewhouse!$T668 -> 0.12708333 | N29: =[24]Brewhouse!$Z668 -> 0.30486111 | O29: =[24]Brewhouse!$AX668 -> R. Regis | R29: =B29 -> CARIB | S29: =VLOOKUP($B29,$R$3:$X$9,2,FALSE) -> 11.6 | T29: =VLOOKUP($B29,$R$3:$X$9,3,FALSE) -> 12 | U29: =VLOOKUP($B29,$R$3:$X$9,4,FALSE) -> 0 | V29: =VLOOKUP($B29,$R$3:$X$9,5,FALSE) -> 0.11805556 | W29: =VLOOKUP($B29,$R$3:$X$9,6,FALSE) -> 0.22569444 | X29: =VLOOKUP($B29,$R$3:$X$9,7,FALSE) -> 0.26388889 | Y29: =VLOOKUP($B29,$R$3:$Z$9,8,FALSE) -> 0 | Z29: =VLOOKUP($B29,$R$3:$Z$9,9,FALSE) -> 60
R30: =B30 -> 0 | S30: =VLOOKUP($B30,$R$3:$X$9,2,FALSE) -> #N/A | T30: =VLOOKUP($B30,$R$3:$X$9,3,FALSE) -> #N/A | U30: =VLOOKUP($B30,$R$3:$X$9,4,FALSE) -> #N/A | V30: =VLOOKUP($B30,$R$3:$X$9,5,FALSE) -> #N/A | W30: =VLOOKUP($B30,$R$3:$X$9,6,FALSE) -> #N/A | X30: =VLOOKUP($B30,$R$3:$X$9,7,FALSE) -> #N/A | Y30: =VLOOKUP($B30,$R$3:$Z$9,8,FALSE) -> #N/A | Z30: =VLOOKUP($B30,$R$3:$Z$9,9,FALSE) -> #N/A
R31: =B31 -> 0 | S31: =VLOOKUP($B31,$R$3:$X$9,2,FALSE) -> #N/A | T31: =VLOOKUP($B31,$R$3:$X$9,3,FALSE) -> #N/A | U31: =VLOOKUP($B31,$R$3:$X$9,4,FALSE) -> #N/A | V31: =VLOOKUP($B31,$R$3:$X$9,5,FALSE) -> #N/A | W31: =VLOOKUP($B31,$R$3:$X$9,6,FALSE) -> #N/A | X31: =VLOOKUP($B31,$R$3:$X$9,7,FALSE) -> #N/A | Y31: =VLOOKUP($B31,$R$3:$Z$9,8,FALSE) -> #N/A | Z31: =VLOOKUP($B31,$R$3:$Z$9,9,FALSE) -> #N/A
