Workbook

Sheet Entries August'25
B1: ENTRIES FOR DAILY CONS. MONITOR | O1: =B1 -> ENTRIES FOR DAILY CONS. MONITOR
C2: old | F2: old | O2: Service 227.3 cubic meters (2273 Hls)Filtered 189.3 cubic meters(1893 Hls)
D3: FUEL | J3: ELECT. | L3: CO2 | O3: WATER | AG3: CO2 Scrubber (m3) | AH3: Supply to Washdown Area (m3) | AI3: Supply to RUs (m3) | AJ3: Steam Mass Flow Meter | AL3: CO2 TANKS' READING | AQ3: TANK C
B4: Boilers tot. | C4: Boiler 1 | D4: Gen. meter | E4: Tank level | F4: Boiler 1 | G4: Boiler 2 | H4: Gen | I4: Meter1 | J4: Meter 2 | K4: Gen Meter | L4: Consumption (BMF) (kg) | M4: Consumption (Totalizer Flowmeter) | N4: Consumption (Filler) (kg) | O4: Nawasa Meter (m3) | P4: Annandale Supply (m3) | Q4: Service Supply to Plant (m3) | R4: Cellars/Filtration (m3) | S4: Brewhouse Meter (m3) | T4: Cellars/Process Areas (m3) | U4: Pasteuriser (m3) | V4: Water Plant-Nawasa Annadale (m3) | W4: Water Plant-Well # 1 (m3) | X4: CIP Process | Y4: Bottle Washer | Z4: Boiler | AA4: Permeate #1 | AB4: Permeate #2 | AC4: Bottle Filler (m3) | AD4: RO # 1 Totaliser (m3) | AE4: RO # 2 Totaliser (m3) | AF4: Recovered Water (m3) | AL4: Tank "C" | AM4: Tank "A" | AN4: Tank "B" | AO4: Mobile Tanker | AQ4: TAYLOR WHARTON CALIBRATION TANK | AU4: READING Today (inH2O)
A5: DATE | B5: (liters) | C5: (liters) | D5: (Imp. gals) | E5: (inches) | F5: Hrs | G5: Hrs | H5: Hrs. | I5: (Kwhr) | J5: (Kwhr) | K5: (Kwhr) | M5: (kg) | X5: (m3) | Y5: (m3) | Z5: (m3) | AL5: inH2O | AM5: (Kg.) | AN5: (Kg.) | AO5: (pounds) | AQ5: inH2O | AR5: LBS_CO2 | AS5: KG_CO2 | AV5: POUNDS | AW5: KG
A6: 1 | B6: 7562720 | E6: 64 | F6: 5058.2 | G6: 68225 | I6: 891906 | J6: 429397 | K6: 468000 | L6: 45.05 | M6: 29020.41 | N6: 5410.2 | O6: 189728 | P6: 30334 | Q6: 915114 | S6: 52233 | U6: 21119 | V6: 1308183 | X6: 36194 | Y6: 39473 | Z6: 8744 | AA6: 97122 | AC6: 316 | AD6: 259951 | AJ6: 7294807.8 | AL6: 221 | AM6: 0 | AN6: 0 | AO6: =2.20463*15600 -> 34392.228 | AQ6: 20 | AR6: 2857 | AS6: =AR6/2.204623 -> 1295.9132
A7: 2 | B7: 7562720 | E7: 64 | F7: 5058.2 | G7: 68225 | I7: 894827 | J7: 432071 | K7: 468000 | L7: 45.05 | M7: 29020.41 | N7: 5410.2 | O7: 189728 | P7: 30425 | Q7: 915126 | S7: 52233 | U7: 21119 | V7: 1308279 | X7: 36194 | Y7: 39473 | Z7: 8744 | AA7: 97122 | AC7: 316 | AD7: 259951 | AJ7: 7294807.8 | AL7: 220 | AM7: 0 | AN7: 0 | AQ7: 30 | AR7: 4344 | AS7: =AR7/2.204623 -> 1970.4049
A8: 3 | B8: 7562720 | E8: 64 | F8: 5058.2 | G8: 68225 | I8: 896662 | J8: 433747 | K8: 468000 | L8: 45.05 | M8: 29020.41 | N8: 5410.2 | O8: 189743 | P8: 30425 | Q8: 915140 | S8: 52233 | U8: 21119 | V8: 1308279 | X8: 36194 | Y8: 39473 | Z8: 8744 | AA8: 97122 | AC8: 316 | AD8: 259951 | AJ8: 7294807.8 | AL8: 220 | AM8: 0 | AN8: 0 | AQ8: 40 | AR8: 6143 | AS8: =AR8/2.204623 -> 2786.4175
A9: 4 | B9: 7563470 | E9: 64 | F9: 5062.9 | G9: 68225 | I9: 899475 | J9: 436322 | K9: 468000 | L9: 45.05 | M9: 29039.8 | N9: 5410.2 | O9: 189744 | P9: 30425 | Q9: 915157 | S9: 52233 | U9: 21119 | V9: 1308279 | X9: 36195 | Y9: 39476 | Z9: 8746 | AA9: 97122 | AC9: 316 | AD9: 259952 | AJ9: 7294807.8 | AL9: 190 | AM9: 0 | AN9: 0 | AQ9: 50 | AR9: 7941 | AS9: =AR9/2.204623 -> 3601.9764
A10: 5 | B10: 7566970 | E10: 64 | F10: 5085.2 | G10: 68225 | I10: 904678 | J10: 441097 | K10: 468000 | L10: 96.04 | M10: 31069.44 | N10: 5735.21 | O10: 189744 | P10: 30657 | Q10: 915450 | S10: 52354 | U10: 21119 | V10: 1308522 | X10: 36265 | Y10: 39613 | Z10: 8764 | AA10: 97122 | AC10: 348 | AD10: 259952 | AJ10: 7294912 | AM10: 0 | AN10: 0 | AQ10: 60 | AR10: 9739 | AS10: =AR10/2.204623 -> 4417.5353
A11: 6 | B11: 7569540 | E11: 64 | F11: 5103.8 | G11: 68225 | I11: 909158 | J11: 445208 | K11: 468000 | L11: 145.47 | M11: 33646.5 | N11: 6116.45 | O11: 190051 | P11: 30784 | Q11: 915701 | S11: 52471 | U11: 21119 | V11: 1308661 | X11: 36327 | Y11: 39733 | Z11: 8778 | AA11: 97122 | AC11: 372 | AD11: 259952 | AJ11: 7294912 | AM11: 0 | AN11: 0 | AQ11: 70 | AR11: 11537 | AS11: =AR11/2.204623 -> 5233.0943
A12: 7 | B12: 7572990 | E12: 64 | F12: 5124.8 | G12: 68225 | I12: 913814 | J12: 449476 | K12: 468000 | L12: 145.47 | M12: 35400.2 | N12: 6367.77 | O12: 190434 | P12: 30935 | Q12: 915917 | S12: 52691 | U12: 21119 | V12: 1308813 | X12: 36368 | Y12: 39821 | Z12: 8793 | AA12: 97122 | AC12: 398 | AD12: 259952 | AJ12: 7294912 | AL12: 160 | AM12: 0 | AN12: 0 | AQ12: 80 | AR12: 13335 | AS12: =AR12/2.204623 -> 6048.6532
A13: 8 | B13: 7576220 | E13: 64 | F13: 5145.8 | G13: 68225 | I13: 918644 | J13: 453906 | K13: 468000 | L13: 145.47 | M13: 37709.58 | N13: 6720.36 | O13: 190620 | P13: 31140 | Q13: 916140 | S13: 52855 | U13: 21120 | V13: 1309029 | X13: 36417 | Y13: 39919 | Z13: 8815 | AA13: 97122 | AC13: 427 | AD13: 259952 | AJ13: 7294912 | AL13: 140 | AM13: 0 | AN13: 0 | AO13: =2.204623*19100 -> 42108.299 | AQ13: 90 | AR13: 15134 | AS13: =AR13/2.204623 -> 6864.6658
A14: 9 | B14: 7578800 | E14: 64 | F14: 5162.5 | G14: 68225 | I14: 923191 | J14: 458075 | K14: 468000 | L14: 145.47 | M14: 39762.51 | N14: 7011.79 | O14: 190724 | P14: 31262 | Q14: 916334 | S14: 52976 | U14: 21120 | V14: 1309189 | X14: 36444 | Y14: 40010 | Z14: 8832 | AA14: 97122 | AC14: 452 | AD14: 259952 | AJ14: 7294912 | AL14: 140 | AM14: 0 | AN14: 0 | AO14: 21974 | AQ14: 100 | AR14: 16932 | AS14: =AR14/2.204623 -> 7680.2247
A15: 10 | B15: 7578800 | E15: 64 | F15: 5162.5 | G15: 68225 | I15: 925620 | J15: 460294 | K15: 468000 | L15: 145.47 | M15: 39762.51 | N15: 7011.79 | O15: 190724 | P15: 31325 | Q15: 916361 | S15: 52976 | U15: 21120 | V15: 1309224 | X15: 36444 | Y15: 40015 | Z15: 8838 | AA15: 97122 | AC15: 452 | AD15: 259952 | AJ15: 7294912 | AL15: 130 | AM15: 11400 | AN15: 4560 | AQ15: 110 | AR15: 18730 | AS15: =AR15/2.204623 -> 8495.7836
A16: 11 | B16: 7579210 | E16: 64 | F16: 5162.5 | G16: 68225 | I16: 928665 | J16: 463086 | K16: 468000 | L16: 145.47 | M16: 39762.51 | N16: 7011.79 | O16: 190724 | P16: 31430 | Q16: 916432 | S16: 52976 | U16: 21120 | V16: 1309334 | X16: 36444 | Y16: 40015 | Z16: 8841 | AA16: 97122 | AC16: 452 | AD16: 259952 | AJ16: 7294912 | AQ16: 120 | AR16: 20528 | AS16: =AR16/2.204623 -> 9311.3426
A17: 12 | B17: 7579210 | E17: 64 | F17: 5162.5 | G17: 68225 | I17: 930788 | J17: 465028 | K17: 468000 | L17: 145.47 | M17: 39762.51 | N17: 7011.79 | O17: 190724 | P17: 31430 | Q17: 916446 | S17: 52976 | U17: 21120 | V17: 1309334 | X17: 36444 | Y17: 40015 | Z17: 8841 | AA17: 97122 | AC17: 452 | AD17: 259952 | AJ17: 7294912 | AQ17: 130 | AR17: 22326 | AS17: =AR17/2.204623 -> 10126.902
A18: 13 | B18: 7580060 | E18: 64 | F18: 5171.4 | G18: 68225 | I18: 933246 | J18: 467277 | K18: 468000 | L18: 145.47 | M18: 39764.4 | N18: 7011.79 | O18: 190724 | P18: 31430 | Q18: 916458 | S18: 52980 | U18: 21120 | V18: 1309334 | X18: 36444 | Y18: 40044 | Z18: 8848 | AA18: 97122 | AC18: 452 | AD18: 259952 | AJ18: 7295013 | AQ18: 140 | AR18: 24125 | AS18: =AR18/2.204623 -> 10942.914
A19: 14 | B19: 7582760 | E19: 64 | F19: 5189.9 | G19: 68225 | I19: 937074 | J19: 470786 | K19: 468000 | L19: 145.47 | M19: 41086.88 | N19: 7227.93 | O19: 190923 | P19: 31570 | Q19: 916674 | S19: 53096 | U19: 21126 | V19: 1309480 | X19: 36512 | Y19: 40107 | Z19: 8871 | AA19: 97122 | AC19: 497 | AD19: 259962 | AJ19: 7295013 | AQ19: 150 | AR19: 25923 | AS19: =AR19/2.204623 -> 11758.473
A20: 15 | B20: 7585740 | E20: 64 | F20: 5210.1 | G20: 68225 | I20: 941977 | J20: 475257 | K20: 468000 | L20: 145.47 | M20: 43147.04 | N20: 7525.07 | O20: 191142 | P20: 31800 | Q20: 916877 | S20: 53324 | U20: 21126 | V20: 1309728 | X20: 36548 | Y20: 40191 | Z20: 8899 | AA20: 97122 | AC20: 523 | AD20: 260020 | AJ20: 7295091.7 | AQ20: 160 | AR20: 27721 | AS20: =AR20/2.204623 -> 12574.032
A21: 16 | B21: 7589070 | E21: 64 | F21: 5230.9 | G21: 68225 | I21: 946984 | J21: 479878 | K21: 468000 | L21: 145.17 | M21: 45166.96 | N21: 7851.15 | O21: 191407 | P21: 32054 | Q21: 917109 | S21: 53506 | U21: 21126 | V21: 1309987 | X21: 36601 | Y21: 40287 | Z21: 8927 | AA21: 97122 | AC21: 550 | AD21: 260040 | AJ21: 7295091.7 | AQ21: 170 | AR21: 29519 | AS21: =AR21/2.204623 -> 13389.591
A22: 17 | B22: 7590150 | E22: 64 | F22: 5240.5 | G22: 68225 | I22: 950058 | J22: 482689 | K22: 468000 | L22: 145.17 | M22: 45166.96 | N22: 7851.15 | O22: 191427 | P22: 32162 | Q22: 917163 | S22: 53644 | U22: 21126 | V22: 1310101 | X22: 36601 | Y22: 40292 | Z22: 8934 | AA22: 97122 | AC22: 550 | AD22: 260040 | AJ22: 7295091.7 | AQ22: 180 | AR22: 31317 | AS22: =AR22/2.204623 -> 14205.15
A23: 18 | B23: 7590890 | E23: 64 | F23: 5244.8 | G23: 68225 | I23: 952764 | J23: 485164 | K23: 468000 | L23: 145.17 | M23: 45166.96 | N23: 7851.15 | O23: 191491 | P23: 32210 | Q23: 917256 | S23: 53644 | U23: 21126 | V23: 1310158 | X23: 36601 | Y23: 40292 | Z23: 8938 | AA23: 97122 | AC23: 550 | AD23: 260040 | AJ23: 7295091.7 | AQ23: 190 | AR23: 33116 | AS23: =AR23/2.204623 -> 15021.162
A24: 19 | B24: 7594270 | E24: 64 | F24: 5265.7 | G24: 68225 | I24: 957567 | J24: 489565 | K24: 468000 | L24: 145.17 | M24: 46833.06 | N24: 8094.68 | O24: 191665 | P24: 32404 | Q24: 917492 | S24: 53800 | U24: 21132 | V24: 1310382 | X24: 36654 | Y24: 40465 | Z24: 8967 | AA24: 97122 | AC24: 576 | AD24: 260048 | AJ24: 7295091.7 | AQ24: 200 | AR24: 34914 | AS24: =AR24/2.204623 -> 15836.721
A25: 20 | B25: 7597380 | E25: 64 | F25: 5286.3 | G25: 68225 | I25: 962247 | J25: 493855 | K25: 468000 | L25: 194.72 | M25: 48641.21 | N25: 8258.3 | O25: 191790 | P25: 32636 | Q25: 917661 | S25: 54022 | U25: 21132 | V25: 1310598 | X25: 36706 | Y25: 40516 | Z25: 8993 | AA25: 97122 | AC25: 594 | AD25: 260121 | AJ25: 7295144.6 | AQ25: 210 | AR25: 36712 | AS25: =AR25/2.204623 -> 16652.28
A26: 21 | B26: 7600560 | E26: 64 | F26: 5306.4 | G26: 68225 | I26: 967139 | J26: 498344 | K26: 468000 | L26: 194.72 | M26: 50727.81 | N26: 8538.83 | O26: 192181 | P26: 32683 | Q26: 917946 | S26: 54218 | U26: 21132 | V26: 1310647 | X26: 36771 | Y26: 40652 | Z26: 9025 | AA26: 97122 | AC26: 620 | AD26: 260122 | AJ26: 7295144.6 | AQ26: 220 | AR26: 38510 | AS26: =AR26/2.204623 -> 17467.839
A27: 22 | B27: 7603650 | E27: 64 | F27: 5326.1 | G27: 68225 | I27: 971823 | J27: 502696 | K27: 468000 | L27: 227.7 | M27: 53455.7 | N27: 8918.1 | O27: 192458 | P27: 32958 | Q27: 918287 | S27: 54351 | U27: 21132 | V27: 1310934 | X27: 36823 | Y27: 40843 | Z27: 9052 | AA27: 97122 | AC27: 650 | AD27: 260122 | AJ27: 7295144.6 | AQ27: 230 | AR27: 40308 | AS27: =AR27/2.204623 -> 18283.398
... A37: 1 | B37: 7621570 | E37: 64 | F37: 5453.8 | G37: 68225 | I37: 7478 | J37: 535202 | K37: 468000 | L37: 227.79 | M37: 60838.97 | N37: 9964.36 | O37: 193319 | P37: 33963 | Q37: 919465 | S37: 55371 | U37: 21155 | V37: 1312021 | X37: 37047 | Y37: 41306 | Z37: 9181 | AA37: 97122 | AC37: 743 | AD37: 260127 | AJ37: 7297992.7 | AQ37: 330 | AR37: 58290 | AS37: =AR37/2.204623 -> 26439.895
AQ38: 340 | AR38: 60089 | AS38: =AR38/2.204623 -> 27255.907
AQ39: 350 | AR39: 60537 | AS39: =AR39/2.204623 -> 27459.117

Sheet Utility Analysis AugusT 2025
H2: GRENADA BREWERIES LIMITED
H3: UTILITY ANALYSIS
A5: MONTH: | G5: 39295
A7: DATE | D7: ELECTRICITY GRENLEC | E7: CARIB GENSET | F7: ELECTRICITY TOTAL | G7: WATER | H7: FUEL | I7: CO2 | J7: PRODUCTION - HL | O7: UTILITY RATIOS
B8: METER 1 | C8: METER 2 | O8: Elect | P8: Water | Q8: Fuel | R8: CO2
D9: USAGE (kwh) | E9: USAGE (kwh) | F9: USAGE (kwh) | G9: USAGE (Hl) | H9: USAGE (l) | I9: USAGE (Kg.) | J9: BREWED | K9: BOTTLED | L9: KEGS | M9: OTHER | N9: TOTAL | O9: KWH/Hl | P9: Hl/hl | Q9: Litres/hl | R9: kg./Hl
A10: 1 | B10: =IF('Entries August''25'!I7>='Entries August''25'!I6,'Entries August''25'!I7-'Entries August''25'!I6,(999999-'Entries August''25'!I6)+'Entries August''25'!I7+1) -> 2921 | C10: =IF('Entries August''25'!J7>='Entries August''25'!J6,'Entries August''25'!J7-'Entries August''25'!J6,(999999-'Entries August''25'!J6)+'Entries August''25'!J7+1) -> 2674 | D10: =B10+C10 -> 5595 | E10: =IF('Entries August''25'!K7>='Entries August''25'!K6,'Entries August''25'!K7-'Entries August''25'!K6,(999999-'Entries August''25'!K6)+'Entries August''25'!K7+1) -> 0 | F10: =D10+E10 -> 5595 | G10: ='Water '!Z7*10 -> 910 | H10: =IF('Entries August''25'!B7-'Entries August''25'!B6<1,"0",'Entries August''25'!B7-'Entries August''25'!B6) -> 0 | I10: ='CO2'!E7 -> 0 | J10: =+'PROD.FIG. '!F5 -> 0 | K10: =+'PROD.FIG. '!C5 -> 0 | L10: =+'PROD.FIG. '!D5 -> 0 | M10: =+'PROD.FIG. '!E5 -> 0 | N10: {=TRANSPOSE('Daily KPIs'!B9:AF9)} -> 0 | O10: =IF(N10=0,0,F10/N10) -> 0 | P10: =IF(O10=0,0,G10/N10) -> 0 | Q10: =IF(P10=0,0,H10/N10) -> 0 | R10: =IF(Q10=0,0,I10/N10) -> 0
A11: 2 | B11: =IF('Entries August''25'!I8>='Entries August''25'!I7,'Entries August''25'!I8-'Entries August''25'!I7,(999999-'Entries August''25'!I7)+'Entries August''25'!I8+1) -> 1835 | C11: =IF('Entries August''25'!J8>='Entries August''25'!J7,'Entries August''25'!J8-'Entries August''25'!J7,(999999-'Entries August''25'!J7)+'Entries August''25'!J8+1) -> 1676 | D11: =B11+C11 -> 3511 | E11: =IF('Entries August''25'!K8>='Entries August''25'!K7,'Entries August''25'!K8-'Entries August''25'!K7,(999999-'Entries August''25'!K7)+'Entries August''25'!K8+1) -> 0 | F11: =D11+E11 -> 3511 | G11: ='Water '!Z8*10 -> 150 | H11: =IF('Entries August''25'!B8-'Entries August''25'!B7<1,"0",'Entries August''25'!B8-'Entries August''25'!B7) -> 0 | I11: ='CO2'!E8 -> 0 | J11: =+'PROD.FIG. '!F6 -> 0 | K11: =+'PROD.FIG. '!C6 -> 0 | L11: =+'PROD.FIG. '!D6 -> 0 | M11: =+'PROD.FIG. '!E6 -> 0 | N11: 0 | O11: =IF(N11=0,0,F11/N11) -> 0 | P11: =IF(O11=0,0,G11/N11) -> 0 | Q11: =IF(P11=0,0,H11/N11) -> 0 | R11: =IF(Q11=0,0,I11/N11) -> 0
A12: 3 | B12: =IF('Entries August''25'!I9>='Entries August''25'!I8,'Entries August''25'!I9-'Entries August''25'!I8,(999999-'Entries August''25'!I8)+'Entries August''25'!I9+1) -> 2813 | C12: =IF('Entries August''25'!J9>='Entries August''25'!J8,'Entries August''25'!J9-'Entries August''25'!J8,(999999-'Entries August''25'!J8)+'Entries August''25'!J9+1) -> 2575 | D12: =B12+C12 -> 5388 | E12: =IF('Entries August''25'!K9>='Entries August''25'!K8,'Entries August''25'!K9-'Entries August''25'!K8,(999999-'Entries August''25'!K8)+'Entries August''25'!K9+1) -> 0 | F12: =D12+E12 -> 5388 | G12: ='Water '!Z9*10 -> 10 | H12: =IF('Entries August''25'!B9-'Entries August''25'!B8<1,"0",'Entries August''25'!B9-'Entries August''25'!B8) -> 750 | I12: ='CO2'!E9 -> 0 | J12: =+'PROD.FIG. '!F7 -> 0 | K12: =+'PROD.FIG. '!C7 -> 0 | L12: =+'PROD.FIG. '!D7 -> 0 | M12: =+'PROD.FIG. '!E7 -> 0 | N12: 0 | O12: =IF(N12=0,0,F12/N12) -> 0 | P12: =IF(O12=0,0,G12/N12) -> 0 | Q12: =IF(P12=0,0,H12/N12) -> 0 | R12: =IF(Q12=0,0,I12/N12) -> 0
A13: 4 | B13: =IF('Entries August''25'!I10>='Entries August''25'!I9,'Entries August''25'!I10-'Entries August''25'!I9,(999999-'Entries August''25'!I9)+'Entries August''25'!I10+1) -> 5203 | C13: =IF('Entries August''25'!J10>='Entries August''25'!J9,'Entries August''25'!J10-'Entries August''25'!J9,(999999-'Entries August''25'!J9)+'Entries August''25'!J10+1) -> 4775 | D13: =B13+C13 -> 9978 | E13: =IF('Entries August''25'!K10>='Entries August''25'!K9,'Entries August''25'!K10-'Entries August''25'!K9,(999999-'Entries August''25'!K9)+'Entries August''25'!K10+1) -> 0 | F13: =D13+E13 -> 9978 | G13: ='Water '!Z10*10 -> 2320 | H13: =IF('Entries August''25'!B10-'Entries August''25'!B9<1,"0",'Entries August''25'!B10-'Entries August''25'!B9) -> 3500 | I13: ='CO2'!E10 -> 2000 | J13: =+'PROD.FIG. '!F8 -> 0 | K13: =+'PROD.FIG. '!C8 -> 0 | L13: =+'PROD.FIG. '!D8 -> 0 | M13: =+'PROD.FIG. '!E8 -> 0 | N13: 478.104 | O13: =IF(N13=0,0,F13/N13) -> 20.869936 | P13: =IF(O13=0,0,G13/N13) -> 4.8525007 | Q13: =IF(P13=0,0,H13/N13) -> 7.320583 | R13: =IF(Q13=0,0,I13/N13) -> 4.1831903
A14: 5 | B14: =IF('Entries August''25'!I11>='Entries August''25'!I10,'Entries August''25'!I11-'Entries August''25'!I10,(999999-'Entries August''25'!I10)+'Entries August''25'!I11+1) -> 4480 | C14: =IF('Entries August''25'!J11>='Entries August''25'!J10,'Entries August''25'!J11-'Entries August''25'!J10,(999999-'Entries August''25'!J10)+'Entries August''25'!J11+1) -> 4111 | D14: =B14+C14 -> 8591 | E14: =IF('Entries August''25'!K11>='Entries August''25'!K10,'Entries August''25'!K11-'Entries August''25'!K10,(999999-'Entries August''25'!K10)+'Entries August''25'!K11+1) -> 0 | F14: =D14+E14 -> 8591 | G14: ='Water '!Z11*10 -> 4340 | H14: =IF('Entries August''25'!B11-'Entries August''25'!B10<1,"0",'Entries August''25'!B11-'Entries August''25'!B10) -> 2570 | I14: ='CO2'!E11 -> 2400 | J14: =+'PROD.FIG. '!F9 -> 0 | K14: =+'PROD.FIG. '!C9 -> 0 | L14: =+'PROD.FIG. '!D9 -> 0 | M14: =+'PROD.FIG. '!E9 -> 0 | N14: 680.196 | O14: =IF(N14=0,0,F14/N14) -> 12.630183 | P14: =IF(O14=0,0,G14/N14) -> 6.3805139 | Q14: =IF(P14=0,0,H14/N14) -> 3.7783227 | R14: =IF(Q14=0,0,I14/N14) -> 3.5283948
A15: 6 | B15: =IF('Entries August''25'!I12>='Entries August''25'!I11,'Entries August''25'!I12-'Entries August''25'!I11,(999999-'Entries August''25'!I11)+'Entries August''25'!I12+1) -> 4656 | C15: =IF('Entries August''25'!J12>='Entries August''25'!J11,'Entries August''25'!J12-'Entries August''25'!J11,(999999-'Entries August''25'!J11)+'Entries August''25'!J12+1) -> 4268 | D15: =B15+C15 -> 8924 | E15: =IF('Entries August''25'!K12>='Entries August''25'!K11,'Entries August''25'!K12-'Entries August''25'!K11,(999999-'Entries August''25'!K11)+'Entries August''25'!K12+1) -> 0 | F15: =D15+E15 -> 8924 | G15: ='Water '!Z12*10 -> 5340 | H15: =IF('Entries August''25'!B12-'Entries August''25'!B11<1,"0",'Entries August''25'!B12-'Entries August''25'!B11) -> 3450 | I15: ='CO2'!E12 -> 1200 | J15: =+'PROD.FIG. '!F10 -> 0 | K15: =+'PROD.FIG. '!C10 -> 0 | L15: =+'PROD.FIG. '!D10 -> 0 | M15: =+'PROD.FIG. '!E10 -> 0 | N15: 458.106 | O15: =IF(N15=0,0,F15/N15) -> 19.480208 | P15: =IF(O15=0,0,G15/N15) -> 11.656691 | Q15: =IF(P15=0,0,H15/N15) -> 7.5310081 | R15: =IF(Q15=0,0,I15/N15) -> 2.6194811
A16: 7 | B16: =IF('Entries August''25'!I13>='Entries August''25'!I12,'Entries August''25'!I13-'Entries August''25'!I12,(999999-'Entries August''25'!I12)+'Entries August''25'!I13+1) -> 4830 | C16: =IF('Entries August''25'!J13>='Entries August''25'!J12,'Entries August''25'!J13-'Entries August''25'!J12,(999999-'Entries August''25'!J12)+'Entries August''25'!J13+1) -> 4430 | D16: =B16+C16 -> 9260 | E16: =IF('Entries August''25'!K13>='Entries August''25'!K12,'Entries August''25'!K13-'Entries August''25'!K12,(999999-'Entries August''25'!K12)+'Entries August''25'!K13+1) -> 0 | F16: =D16+E16 -> 9260 | G16: ='Water '!Z13*10 -> 3910 | H16: =IF('Entries August''25'!B13-'Entries August''25'!B12<1,"0",'Entries August''25'!B13-'Entries August''25'!B12) -> 3230 | I16: ='CO2'!E13 -> 2500 | J16: =+'PROD.FIG. '!F11 -> 0 | K16: =+'PROD.FIG. '!C11 -> 0 | L16: =+'PROD.FIG. '!D11 -> 0 | M16: =+'PROD.FIG. '!E11 -> 0 | N16: 574.2228 | O16: =IF(N16=0,0,F16/N16) -> 16.126145 | P16: =IF(O16=0,0,G16/N16) -> 6.8092037 | Q16: =IF(P16=0,0,H16/N16) -> 5.6249943 | R16: =IF(Q16=0,0,I16/N16) -> 4.3537108
A17: 8 | B17: =IF('Entries August''25'!I14>='Entries August''25'!I13,'Entries August''25'!I14-'Entries August''25'!I13,(999999-'Entries August''25'!I13)+'Entries August''25'!I14+1) -> 4547 | C17: =IF('Entries August''25'!J14>='Entries August''25'!J13,'Entries August''25'!J14-'Entries August''25'!J13,(999999-'Entries August''25'!J13)+'Entries August''25'!J14+1) -> 4169 | D17: =B17+C17 -> 8716 | E17: =IF('Entries August''25'!K14>='Entries August''25'!K13,'Entries August''25'!K14-'Entries August''25'!K13,(999999-'Entries August''25'!K13)+'Entries August''25'!K14+1) -> 0 | F17: =D17+E17 -> 8716 | G17: ='Water '!Z14*10 -> 2260 | H17: =IF('Entries August''25'!B14-'Entries August''25'!B13<1,"0",'Entries August''25'!B14-'Entries August''25'!B13) -> 2580 | I17: ='CO2'!E14 -> 2000 | J17: =+'PROD.FIG. '!F12 -> 0 | K17: =+'PROD.FIG. '!C12 -> 0 | L17: =+'PROD.FIG. '!D12 -> 0 | M17: =+'PROD.FIG. '!E12 -> 0 | N17: 553.08 | O17: =IF(N17=0,0,F17/N17) -> 15.759022 | P17: =IF(O17=0,0,G17/N17) -> 4.0862081 | Q17: =IF(P17=0,0,H17/N17) -> 4.6647863 | R17: =IF(Q17=0,0,I17/N17) -> 3.6161134
A18: 9 | B18: =IF('Entries August''25'!I15>='Entries August''25'!I14,'Entries August''25'!I15-'Entries August''25'!I14,(999999-'Entries August''25'!I14)+'Entries August''25'!I15+1) -> 2429 | C18: =IF('Entries August''25'!J15>='Entries August''25'!J14,'Entries August''25'!J15-'Entries August''25'!J14,(999999-'Entries August''25'!J14)+'Entries August''25'!J15+1) -> 2219 | D18: =B18+C18 -> 4648 | E18: =IF('Entries August''25'!K15>='Entries August''25'!K14,'Entries August''25'!K15-'Entries August''25'!K14,(999999-'Entries August''25'!K14)+'Entries August''25'!K15+1) -> 0 | F18: =D18+E18 -> 4648 | G18: ='Water '!Z15*10 -> 630 | H18: =IF('Entries August''25'!B15-'Entries August''25'!B14<1,"0",'Entries August''25'!B15-'Entries August''25'!B14) -> 0 | I18: ='CO2'!E15 -> 0 | J18: =+'PROD.FIG. '!F13 -> 0 | K18: =+'PROD.FIG. '!C13 -> 0 | L18: =+'PROD.FIG. '!D13 -> 0 | M18: =+'PROD.FIG. '!E13 -> 0 | N18: 0 | O18: =IF(N18=0,0,F18/N18) -> 0 | P18: =IF(O18=0,0,G18/N18) -> 0 | Q18: =IF(P18=0,0,H18/N18) -> 0 | R18: =IF(Q18=0,0,I18/N18) -> 0
A19: 10 | B19: =IF('Entries August''25'!I16>='Entries August''25'!I15,'Entries August''25'!I16-'Entries August''25'!I15,(999999-'Entries August''25'!I15)+'Entries August''25'!I16+1) -> 3045 | C19: =IF('Entries August''25'!J16>='Entries August''25'!J15,'Entries August''25'!J16-'Entries August''25'!J15,(999999-'Entries August''25'!J15)+'Entries August''25'!J16+1) -> 2792 | D19: =B19+C19 -> 5837 | E19: =IF('Entries August''25'!K16>='Entries August''25'!K15,'Entries August''25'!K16-'Entries August''25'!K15,(999999-'Entries August''25'!K15)+'Entries August''25'!K16+1) -> 0 | F19: =D19+E19 -> 5837 | G19: ='Water '!Z16*10 -> 1050 | H19: =IF('Entries August''25'!B16-'Entries August''25'!B15<1,"0",'Entries August''25'!B16-'Entries August''25'!B15) -> 410 | I19: ='CO2'!E16 -> 1100 | J19: =+'PROD.FIG. '!F14 -> 0 | K19: =+'PROD.FIG. '!C14 -> 0 | L19: =+'PROD.FIG. '!D14 -> 0 | M19: =+'PROD.FIG. '!E14 -> 0 | N19: 0 | O19: =IF(N19=0,0,F19/N19) -> 0 | P19: =IF(O19=0,0,G19/N19) -> 0 | Q19: =IF(P19=0,0,H19/N19) -> 0 | R19: =IF(Q19=0,0,I19/N19) -> 0
A20: 11 | B20: =IF('Entries August''25'!I17>='Entries August''25'!I16,'Entries August''25'!I17-'Entries August''25'!I16,(999999-'Entries August''25'!I16)+'Entries August''25'!I17+1) -> 2123 | C20: =IF('Entries August''25'!J17>='Entries August''25'!J16,'Entries August''25'!J17-'Entries August''25'!J16,(999999-'Entries August''25'!J16)+'Entries August''25'!J17+1) -> 1942 | D20: =B20+C20 -> 4065 | E20: =IF('Entries August''25'!K17>='Entries August''25'!K16,'Entries August''25'!K17-'Entries August''25'!K16,(999999-'Entries August''25'!K16)+'Entries August''25'!K17+1) -> 0 | F20: =D20+E20 -> 4065 | G20: ='Water '!Z17*10 -> 0 | H20: =IF('Entries August''25'!B17-'Entries August''25'!B16<1,"0",'Entries August''25'!B17-'Entries August''25'!B16) -> 0 | I20: ='CO2'!E17 -> 0 | J20: =+'PROD.FIG. '!F15 -> 0 | K20: =+'PROD.FIG. '!C15 -> 0 | L20: =+'PROD.FIG. '!D15 -> 0 | M20: =+'PROD.FIG. '!E15 -> 0 | N20: 0 | O20: =IF(N20=0,0,F20/N20) -> 0 | P20: =IF(O20=0,0,G20/N20) -> 0 | Q20: =IF(P20=0,0,H20/N20) -> 0 | R20: =IF(Q20=0,0,I20/N20) -> 0
A21: 12 | B21: =IF('Entries August''25'!I18>='Entries August''25'!I17,'Entries August''25'!I18-'Entries August''25'!I17,(999999-'Entries August''25'!I17)+'Entries August''25'!I18+1) -> 2458 | C21: =IF('Entries August''25'!J18>='Entries August''25'!J17,'Entries August''25'!J18-'Entries August''25'!J17,(999999-'Entries August''25'!J17)+'Entries August''25'!J18+1) -> 2249 | D21: =B21+C21 -> 4707 | E21: =IF('Entries August''25'!K18>='Entries August''25'!K17,'Entries August''25'!K18-'Entries August''25'!K17,(999999-'Entries August''25'!K17)+'Entries August''25'!K18+1) -> 0 | F21: =D21+E21 -> 4707 | G21: ='Water '!Z18*10 -> 0 | H21: =IF('Entries August''25'!B18-'Entries August''25'!B17<1,"0",'Entries August''25'!B18-'Entries August''25'!B17) -> 850 | I21: ='CO2'!E18 -> 0 | J21: =+'PROD.FIG. '!F16 -> 0 | K21: =+'PROD.FIG. '!C16 -> 0 | L21: =+'PROD.FIG. '!D16 -> 0 | M21: =+'PROD.FIG. '!E16 -> 0 | N21: 0 | O21: =IF(N21=0,0,F21/N21) -> 0 | P21: =IF(O21=0,0,G21/N21) -> 0 | Q21: =IF(P21=0,0,H21/N21) -> 0 | R21: =IF(Q21=0,0,I21/N21) -> 0
A22: 13 | B22: =IF('Entries August''25'!I19>='Entries August''25'!I18,'Entries August''25'!I19-'Entries August''25'!I18,(999999-'Entries August''25'!I18)+'Entries August''25'!I19+1) -> 3828 | C22: =IF('Entries August''25'!J19>='Entries August''25'!J18,'Entries August''25'!J19-'Entries August''25'!J18,(999999-'Entries August''25'!J18)+'Entries August''25'!J19+1) -> 3509 | D22: =B22+C22 -> 7337 | E22: =IF('Entries August''25'!K19>='Entries August''25'!K18,'Entries August''25'!K19-'Entries August''25'!K18,(999999-'Entries August''25'!K18)+'Entries August''25'!K19+1) -> 0 | F22: =D22+E22 -> 7337 | G22: ='Water '!Z19*10 -> 3390 | H22: =IF('Entries August''25'!B19-'Entries August''25'!B18<1,"0",'Entries August''25'!B19-'Entries August''25'!B18) -> 2700 | I22: ='CO2'!E19 -> 1200 | J22: =+'PROD.FIG. '!F17 -> 0 | K22: =+'PROD.FIG. '!C17 -> 0 | L22: =+'PROD.FIG. '!D17 -> 0 | M22: =+'PROD.FIG. '!E17 -> 0 | N22: 293.37 | O22: =IF(N22=0,0,F22/N22) -> 25.009374 | P22: =IF(O22=0,0,G22/N22) -> 11.555374 | Q22: =IF(P22=0,0,H22/N22) -> 9.203395 | R22: =IF(Q22=0,0,I22/N22) -> 4.0903978
... A39: 30 | B39: =IF('Entries August''25'!I36>='Entries August''25'!I35,'Entries August''25'!I36-'Entries August''25'!I35,(999999-'Entries August''25'!I35)+'Entries August''25'!I36+1) -> 2394 | C39: =IF('Entries August''25'!J36>='Entries August''25'!J35,'Entries August''25'!J36-'Entries August''25'!J35,(999999-'Entries August''25'!J35)+'Entries August''25'!J36+1) -> 2175 | D39: =B39+C39 -> 4569 | E39: =IF('Entries August''25'!K36>='Entries August''25'!K35,'Entries August''25'!K36-'Entries August''25'!K35,(999999-'Entries August''25'!K35)+'Entries August''25'!K36+1) -> 0 | F39: =D39+E39 -> 4569 | G39: ='Water '!Z36*10 -> 740 | H39: =IF('Entries August''25'!B36-'Entries August''25'!B35<1,"0",'Entries August''25'!B36-'Entries August''25'!B35) -> 240 | I39: ='CO2'!E36 -> 0 | J39: =+'PROD.FIG. '!F34 -> 0 | K39: =+'PROD.FIG. '!C34 -> 0 | L39: =+'PROD.FIG. '!D34 -> 0 | M39: =+'PROD.FIG. '!E34 -> 0 | N39: 0 | O39: =IF(N39=0,0,F39/N39) -> 0 | P39: =IF(O39=0,0,G39/N39) -> 0 | Q39: =IF(P39=0,0,H39/N39) -> 0 | R39: =IF(Q39=0,0,I39/N39) -> 0
A40: 31 | B40: =IF('Entries August''25'!I37>='Entries August''25'!I36,'Entries August''25'!I37-'Entries August''25'!I36,(999999-'Entries August''25'!I36)+'Entries August''25'!I37+1) -> 2692 | C40: =IF('Entries August''25'!J37>='Entries August''25'!J36,'Entries August''25'!J37-'Entries August''25'!J36,(999999-'Entries August''25'!J36)+'Entries August''25'!J37+1) -> 2455 | D40: =B40+C40 -> 5147 | E40: =IF('Entries August''25'!K37>='Entries August''25'!K36,'Entries August''25'!K37-'Entries August''25'!K36,(999999-'Entries August''25'!K36)+'Entries August''25'!K37+1) -> 0 | F40: =D40+E40 -> 5147 | G40: ='Water '!Z37*10 -> 0 | H40: =IF('Entries August''25'!B37-'Entries August''25'!B36<1,"0",'Entries August''25'!B37-'Entries August''25'!B36) -> 520 | I40: ='CO2'!E37 -> 0 | N40: 30.855 | O40: =IF(N40=0,0,F40/N40) -> 166.81251 | P40: =IF(O40=0,0,G40/N40) -> 0 | Q40: =IF(P40=0,0,H40/N40) -> 0 | R40: =IF(Q40=0,0,I40/N40) -> 0
O41: MTD
D42: Kwhr | E42: Kwhr | F42: Kwhr | G42: Hl | H42: L | I42: kg. | J42: hl | K42: hl | L42: hl | M42: hl | N42: hl | O42: Elect | P42: Water | Q42: Fuel | R42: CO2
A43: Total | D43: =SUM(D10:D40) -> 221377 | E43: =SUM(E10:E40) -> 0 | F43: =SUM(F10:F40) -> 221377 | G43: =SUM(G10:G40) -> 72200 | H43: =SUM(H10:H40) -> 58850 | I43: =SUM(I10:I40) -> 35073 | J43: =SUM(J10:J40) -> 0 | K43: =SUM(K10:K40) -> 0 | ... N43: =SUM(N10:N40) -> 7279.8342 | O43: KWH/Hl | P43: Hl/hl | Q43: Litres/hl | R43: kg./Hl
O44: =IF(N43=0,0,F43/N43) -> 30.409621 | P44: =IF(O44=0,0,G43/N43) -> 9.9178083 | Q44: =IF(P44=0,0,H43/N43) -> 8.0839753 | R44: =IF(Q44=0,0,I43/N43) -> 4.8178295
D47: {=SI(B2>=A2, B2-A2, (999999 - A2 + B2 + 1))} -> #NAME?

Sheet Steam Mass Flow 
A3: DATE | B3: Steam Mass Flow Reading
A5: 1 | B5: =IF('Entries August''25'!AJ7-'Entries August''25'!AJ6<1,"0",'Entries August''25'!AJ7-'Entries August''25'!AJ6) -> 0
A6: 2 | B6: =IF('Entries August''25'!AJ8-'Entries August''25'!AJ7<1,"0",'Entries August''25'!AJ8-'Entries August''25'!AJ7) -> 0
A7: 3 | B7: =IF('Entries August''25'!AJ9-'Entries August''25'!AJ8<1,"0",'Entries August''25'!AJ9-'Entries August''25'!AJ8) -> 0
A8: 4 | B8: =IF('Entries August''25'!AJ10-'Entries August''25'!AJ9<1,"0",'Entries August''25'!AJ10-'Entries August''25'!AJ9) -> 104.239
A9: 5 | B9: =IF('Entries August''25'!AJ11-'Entries August''25'!AJ10<1,"0",'Entries August''25'!AJ11-'Entries August''25'!AJ10) -> 0
A10: 6 | B10: =IF('Entries August''25'!AJ12-'Entries August''25'!AJ11<1,"0",'Entries August''25'!AJ12-'Entries August''25'!AJ11) -> 0
A11: 7 | B11: =IF('Entries August''25'!AJ13-'Entries August''25'!AJ12<1,"0",'Entries August''25'!AJ13-'Entries August''25'!AJ12) -> 0
A12: 8 | B12: =IF('Entries August''25'!AJ14-'Entries August''25'!AJ13<1,"0",'Entries August''25'!AJ14-'Entries August''25'!AJ13) -> 0
A13: 9 | B13: =IF('Entries August''25'!AJ15-'Entries August''25'!AJ14<1,"0",'Entries August''25'!AJ15-'Entries August''25'!AJ14) -> 0
A14: 10 | B14: =IF('Entries August''25'!AJ16-'Entries August''25'!AJ15<1,"0",'Entries August''25'!AJ16-'Entries August''25'!AJ15) -> 0
A15: 11 | B15: =IF('Entries August''25'!AJ17-'Entries August''25'!AJ16<1,"0",'Entries August''25'!AJ17-'Entries August''25'!AJ16) -> 0
A16: 12 | B16: =IF('Entries August''25'!AJ18-'Entries August''25'!AJ17<1,"0",'Entries August''25'!AJ18-'Entries August''25'!AJ17) -> 100.962
... A35: 31 | B35: =IF('Entries August''25'!AJ37-'Entries August''25'!AJ36<1,"0",'Entries August''25'!AJ37-'Entries August''25'!AJ36) -> 0
B36: =SUM(B5:B35) -> 3184.491

Sheet Fuel 
A1: DAILY FUEL CONSUMPTION FOR AUGUST 2025
A4: DATE | B4: Boiler 1 | C4: Boiler 1 | D4: Boiler 2 | E4: Boiler 2 | F4: Gen. | G4: Gen | H4: Boiler 1 sp. | I4: Boiler 2 sp. | J4: Gen. sp | K4: Daily cons. | L4: Total Prod.(HL) | M4: Fuel(Litres/HL)
B5: Cons ( l ) | C5: Hrs | D5: Cons ( l ) | E5: Hrs | F5: Cons ( l ) | G5: Hrs | H5: cons (l/hr) | I5: cons (l/hr) | J5: Cons.(l/hr) | K5: (litres)
A7: 1 | B7: =IF('Entries August''25'!B7-'Entries August''25'!B6<1,"0",'Entries August''25'!B7-'Entries August''25'!B6) -> 0 | C7: =IF('Entries August''25'!F7-'Entries August''25'!F6<1,"0",'Entries August''25'!F7-'Entries August''25'!F6) -> 0 | D7: =IF('Entries August''25'!C6=0,0,+'Entries August''25'!C6-'Entries August''25'!#REF!) -> 0 | E7: =IF('Entries August''25'!G7-'Entries August''25'!G6<1,"0",'Entries August''25'!G7-'Entries August''25'!G6) -> 0 | H7: =IF(C7+E7=0,"0", B7/(C7+E7)) -> 0 | I7: =IF(E7=0,"0", D7/E7) -> 0 | J7: =IF(G7=0,"0", F7/G7) -> 0 | K7: =B7+D7+F7 -> 0 | L7: {=IF(TRANSPOSE('Daily KPIs'!B9:AF9)=0,"0",TRANSPOSE('Daily KPIs'!B9:AF9))} -> 0 | M7: =IF(L7=0,"0",(K7/L7)) -> 0
A8: 2 | B8: =IF('Entries August''25'!B8-'Entries August''25'!B7<1,"0",'Entries August''25'!B8-'Entries August''25'!B7) -> 0 | C8: =IF('Entries August''25'!F8-'Entries August''25'!F7<1,"0",'Entries August''25'!F8-'Entries August''25'!F7) -> 0 | D8: =IF('Entries August''25'!C7=0,0,+'Entries August''25'!C7-'Entries August''25'!C6) -> 0 | E8: =IF('Entries August''25'!G8-'Entries August''25'!G7<1,"0",'Entries August''25'!G8-'Entries August''25'!G7) -> 0 | H8: =IF(C8+E8=0,"0", B8/(C8+E8)) -> 0 | I8: =IF(E8=0,"0", D8/E8) -> 0 | J8: =IF(G8=0,"0", F8/G8) -> 0 | K8: =B8+D8+F8 -> 0 | L8: 0 | M8: =IF(L8=0,"0",(K8/L8)) -> 0
A9: 3 | B9: =IF('Entries August''25'!B9-'Entries August''25'!B8<1,"0",'Entries August''25'!B9-'Entries August''25'!B8) -> 750 | C9: =IF('Entries August''25'!F9-'Entries August''25'!F8<1,"0",'Entries August''25'!F9-'Entries August''25'!F8) -> 4.7 | D9: =IF('Entries August''25'!C8=0,0,+'Entries August''25'!C8-'Entries August''25'!C7) -> 0 | E9: =IF('Entries August''25'!G9-'Entries August''25'!G8<1,"0",'Entries August''25'!G9-'Entries August''25'!G8) -> 0 | H9: =IF(C9+E9=0,"0", B9/(C9+E9)) -> 159.57447 | I9: =IF(E9=0,"0", D9/E9) -> 0 | J9: =IF(G9=0,"0", F9/G9) -> 0 | K9: =B9+D9+F9 -> 750 | L9: 0 | M9: =IF(L9=0,"0",(K9/L9)) -> 0
A10: 4 | B10: =IF('Entries August''25'!B10-'Entries August''25'!B9<1,"0",'Entries August''25'!B10-'Entries August''25'!B9) -> 3500 | C10: =IF('Entries August''25'!F10-'Entries August''25'!F9<1,"0",'Entries August''25'!F10-'Entries August''25'!F9) -> 22.3 | D10: =IF('Entries August''25'!C11=0,0,+'Entries August''25'!C11-'Entries August''25'!C8) -> 0 | E10: =IF('Entries August''25'!G10-'Entries August''25'!G9<1,"0",'Entries August''25'!G10-'Entries August''25'!G9) -> 0 | H10: =IF(C10+E10=0,"0", B10/(C10+E10)) -> 156.95067 | I10: =IF(E10=0,"0", D10/E10) -> 0 | J10: =IF(G10=0,"0", F10/G10) -> 0 | K10: =B10+D10+F10 -> 3500 | L10: 478.104 | M10: =IF(L10=0,"0",(K10/L10)) -> 7.320583
A11: 5 | B11: =IF('Entries August''25'!B11-'Entries August''25'!B10<1,"0",'Entries August''25'!B11-'Entries August''25'!B10) -> 2570 | C11: =IF('Entries August''25'!F11-'Entries August''25'!F10<1,"0",'Entries August''25'!F11-'Entries August''25'!F10) -> 18.6 | D11: =IF('Entries August''25'!C10=0,0,+'Entries August''25'!C10-'Entries August''25'!C11) -> 0 | E11: =IF('Entries August''25'!G11-'Entries August''25'!G10<1,"0",'Entries August''25'!G11-'Entries August''25'!G10) -> 0 | H11: =IF(C11+E11=0,"0", B11/(C11+E11)) -> 138.17204 | I11: =IF(E11=0,"0", D11/E11) -> 0 | J11: =IF(G11=0,"0", F11/G11) -> 0 | K11: =B11+D11+F11 -> 2570 | L11: 680.196 | M11: =IF(L11=0,"0",(K11/L11)) -> 3.7783227
A12: 6 | B12: =IF('Entries August''25'!B12-'Entries August''25'!B11<1,"0",'Entries August''25'!B12-'Entries August''25'!B11) -> 3450 | C12: =IF('Entries August''25'!F12-'Entries August''25'!F11<1,"0",'Entries August''25'!F12-'Entries August''25'!F11) -> 21 | D12: =IF('Entries August''25'!C12=0,0,+'Entries August''25'!C12-'Entries August''25'!C10) -> 0 | E12: =IF('Entries August''25'!G12-'Entries August''25'!G11<1,"0",'Entries August''25'!G12-'Entries August''25'!G11) -> 0 | H12: =IF(C12+E12=0,"0", B12/(C12+E12)) -> 164.28571 | I12: =IF(E12=0,"0", D12/E12) -> 0 | J12: =IF(G12=0,"0", F12/G12) -> 0 | K12: =B12+D12+F12 -> 3450 | L12: 458.106 | M12: =IF(L12=0,"0",(K12/L12)) -> 7.5310081
A13: 7 | B13: =IF('Entries August''25'!B13-'Entries August''25'!B12<1,"0",'Entries August''25'!B13-'Entries August''25'!B12) -> 3230 | C13: =IF('Entries August''25'!F13-'Entries August''25'!F12<1,"0",'Entries August''25'!F13-'Entries August''25'!F12) -> 21 | D13: =IF('Entries August''25'!C13=0,0,+'Entries August''25'!C13-'Entries August''25'!C11) -> 0 | E13: =IF('Entries August''25'!G13-'Entries August''25'!G12<1,"0",'Entries August''25'!G13-'Entries August''25'!G12) -> 0 | H13: =IF(C13+E13=0,"0", B13/(C13+E13)) -> 153.80952 | I13: =IF(E13=0,"0", D13/E13) -> 0 | J13: =IF(G13=0,"0", F13/G13) -> 0 | K13: =B13+D13+F13 -> 3230 | L13: 574.2228 | M13: =IF(L13=0,"0",(K13/L13)) -> 5.6249943
A14: 8 | B14: =IF('Entries August''25'!B14-'Entries August''25'!B13<1,"0",'Entries August''25'!B14-'Entries August''25'!B13) -> 2580 | C14: =IF('Entries August''25'!F14-'Entries August''25'!F13<1,"0",'Entries August''25'!F14-'Entries August''25'!F13) -> 16.7 | D14: =IF('Entries August''25'!C13=0,0,+'Entries August''25'!C13-'Entries August''25'!#REF!) -> 0 | E14: =IF('Entries August''25'!G14-'Entries August''25'!G13<1,"0",'Entries August''25'!G14-'Entries August''25'!G13) -> 0 | H14: =IF(C14+E14=0,"0", B14/(C14+E14)) -> 154.49102 | I14: =IF(E14=0,"0", D14/E14) -> 0 | J14: =IF(G14=0,"0", F14/G14) -> 0 | K14: =B14+D14+F14 -> 2580 | L14: 553.08 | M14: =IF(L14=0,"0",(K14/L14)) -> 4.6647863
A15: 9 | B15: =IF('Entries August''25'!B15-'Entries August''25'!B14<1,"0",'Entries August''25'!B15-'Entries August''25'!B14) -> 0 | C15: =IF('Entries August''25'!F15-'Entries August''25'!F14<1,"0",'Entries August''25'!F15-'Entries August''25'!F14) -> 0 | D15: =IF('Entries August''25'!C14=0,0,+'Entries August''25'!C14-'Entries August''25'!C13) -> 0 | E15: =IF('Entries August''25'!G15-'Entries August''25'!G14<1,"0",'Entries August''25'!G15-'Entries August''25'!G14) -> 0 | H15: =IF(C15+E15=0,"0", B15/(C15+E15)) -> 0 | I15: =IF(E15=0,"0", D15/E15) -> 0 | J15: =IF(G15=0,"0", F15/G15) -> 0 | K15: =B15+D15+F15 -> 0 | L15: 0 | M15: =IF(L15=0,"0",(K15/L15)) -> 0
A16: 10 | B16: =IF('Entries August''25'!B16-'Entries August''25'!B15<1,"0",'Entries August''25'!B16-'Entries August''25'!B15) -> 410 | C16: =IF('Entries August''25'!F16-'Entries August''25'!F15<1,"0",'Entries August''25'!F16-'Entries August''25'!F15) -> 0 | D16: =IF('Entries August''25'!C15=0,0,+'Entries August''25'!C15-'Entries August''25'!C14) -> 0 | E16: =IF('Entries August''25'!G16-'Entries August''25'!G15<1,"0",'Entries August''25'!G16-'Entries August''25'!G15) -> 0 | H16: =IF(C16+E16=0,"0", B16/(C16+E16)) -> 0 | I16: =IF(E16=0,"0", D16/E16) -> 0 | J16: =IF(G16=0,"0", F16/G16) -> 0 | K16: =B16+D16+F16 -> 410 | L16: 0 | M16: =IF(L16=0,"0",(K16/L16)) -> 0
A17: 11 | B17: =IF('Entries August''25'!B17-'Entries August''25'!B16<1,"0",'Entries August''25'!B17-'Entries August''25'!B16) -> 0 | C17: =IF('Entries August''25'!F17-'Entries August''25'!F16<1,"0",'Entries August''25'!F17-'Entries August''25'!F16) -> 0 | D17: =IF('Entries August''25'!C16=0,0,+'Entries August''25'!C16-'Entries August''25'!C15) -> 0 | E17: =IF('Entries August''25'!G17-'Entries August''25'!G16<1,"0",'Entries August''25'!G17-'Entries August''25'!G16) -> 0 | H17: =IF(C17+E17=0,"0", B17/(C17+E17)) -> 0 | I17: =IF(E17=0,"0", D17/E17) -> 0 | J17: =IF(G17=0,"0", F17/G17) -> 0 | K17: =B17+D17+F17 -> 0 | L17: 0 | M17: =IF(L17=0,"0",(K17/L17)) -> 0
A18: 12 | B18: =IF('Entries August''25'!B18-'Entries August''25'!B17<1,"0",'Entries August''25'!B18-'Entries August''25'!B17) -> 850 | C18: =IF('Entries August''25'!F18-'Entries August''25'!F17<1,"0",'Entries August''25'!F18-'Entries August''25'!F17) -> 8.9 | D18: =IF('Entries August''25'!C17=0,0,+'Entries August''25'!C17-'Entries August''25'!C16) -> 0 | E18: =IF('Entries August''25'!G18-'Entries August''25'!G17<1,"0",'Entries August''25'!G18-'Entries August''25'!G17) -> 0 | H18: =IF(C18+E18=0,"0", B18/(C18+E18)) -> 95.505618 | I18: =IF(E18=0,"0", D18/E18) -> 0 | J18: =IF(G18=0,"0", F18/G18) -> 0 | K18: =B18+D18+F18 -> 850 | L18: 0 | M18: =IF(L18=0,"0",(K18/L18)) -> 0
A19: 13 | B19: =IF('Entries August''25'!B19-'Entries August''25'!B18<1,"0",'Entries August''25'!B19-'Entries August''25'!B18) -> 2700 | C19: =IF('Entries August''25'!F19-'Entries August''25'!F18<1,"0",'Entries August''25'!F19-'Entries August''25'!F18) -> 18.5 | D19: =IF('Entries August''25'!C18=0,0,+'Entries August''25'!C18-'Entries August''25'!C17) -> 0 | E19: =IF('Entries August''25'!G19-'Entries August''25'!G18<1,"0",'Entries August''25'!G19-'Entries August''25'!G18) -> 0 | H19: =IF(C19+E19=0,"0", B19/(C19+E19)) -> 145.94595 | I19: =IF(E19=0,"0", D19/E19) -> 0 | J19: =IF(G19=0,"0", F19/G19) -> 0 | K19: =B19+D19+F19 -> 2700 | L19: 293.37 | M19: =IF(L19=0,"0",(K19/L19)) -> 9.203395
A20: 14 | B20: =IF('Entries August''25'!B20-'Entries August''25'!B19<1,"0",'Entries August''25'!B20-'Entries August''25'!B19) -> 2980 | C20: =IF('Entries August''25'!F20-'Entries August''25'!F19<1,"0",'Entries August''25'!F20-'Entries August''25'!F19) -> 20.2 | D20: =IF('Entries August''25'!C19=0,0,+'Entries August''25'!C19-'Entries August''25'!C18) -> 0 | E20: =IF('Entries August''25'!G20-'Entries August''25'!G19<1,"0",'Entries August''25'!G20-'Entries August''25'!G19) -> 0 | H20: =IF(C20+E20=0,"0", B20/(C20+E20)) -> 147.52475 | I20: =IF(E20=0,"0", D20/E20) -> 0 | J20: =IF(G20=0,"0", F20/G20) -> 0 | K20: =B20+D20+F20 -> 2980 | L20: 459.162 | M20: =IF(L20=0,"0",(K20/L20)) -> 6.4900841
A21: 15 | B21: =IF('Entries August''25'!B21-'Entries August''25'!B20<1,"0",'Entries August''25'!B21-'Entries August''25'!B20) -> 3330 | C21: =IF('Entries August''25'!F21-'Entries August''25'!F20<1,"0",'Entries August''25'!F21-'Entries August''25'!F20) -> 20.8 | D21: =IF('Entries August''25'!C20=0,0,+'Entries August''25'!C20-'Entries August''25'!C19) -> 0 | E21: =IF('Entries August''25'!G21-'Entries August''25'!G20<1,"0",'Entries August''25'!G21-'Entries August''25'!G20) -> 0 | H21: =IF(C21+E21=0,"0", B21/(C21+E21)) -> 160.09615 | I21: =IF(E21=0,"0", D21/E21) -> 0 | J21: =IF(G21=0,"0", F21/G21) -> 0 | K21: =B21+D21+F21 -> 3330 | L21: 582.978 | M21: =IF(L21=0,"0",(K21/L21)) -> 5.7120509
A22: 16 | B22: =IF('Entries August''25'!B22-'Entries August''25'!B21<1,"0",'Entries August''25'!B22-'Entries August''25'!B21) -> 1080 | C22: =IF('Entries August''25'!F22-'Entries August''25'!F21<1,"0",'Entries August''25'!F22-'Entries August''25'!F21) -> 9.6 | D22: =IF('Entries August''25'!C21=0,0,+'Entries August''25'!C21-'Entries August''25'!C20) -> 0 | E22: =IF('Entries August''25'!G22-'Entries August''25'!G21<1,"0",'Entries August''25'!G22-'Entries August''25'!G21) -> 0 | H22: =IF(C22+E22=0,"0", B22/(C22+E22)) -> 112.5 | I22: =IF(E22=0,"0", D22/E22) -> 0 | J22: =IF(G22=0,"0", F22/G22) -> 0 | K22: =B22+D22+F22 -> 1080 | L22: 0 | M22: =IF(L22=0,"0",(K22/L22)) -> 0
A23: 17 | B23: =IF('Entries August''25'!B23-'Entries August''25'!B22<1,"0",'Entries August''25'!B23-'Entries August''25'!B22) -> 740 | C23: =IF('Entries August''25'!F23-'Entries August''25'!F22<1,"0",'Entries August''25'!F23-'Entries August''25'!F22) -> 4.3 | D23: =IF('Entries August''25'!C22=0,0,+'Entries August''25'!C22-'Entries August''25'!C21) -> 0 | E23: =IF('Entries August''25'!G23-'Entries August''25'!G22<1,"0",'Entries August''25'!G23-'Entries August''25'!G22) -> 0 | H23: =IF(C23+E23=0,"0", B23/(C23+E23)) -> 172.09302 | I23: =IF(E23=0,"0", D23/E23) -> 0 | J23: =IF(G23=0,"0", F23/G23) -> 0 | K23: =B23+D23+F23 -> 740 | L23: 0 | M23: =IF(L23=0,"0",(K23/L23)) -> 0
A24: 18 | B24: =IF('Entries August''25'!B24-'Entries August''25'!B23<1,"0",'Entries August''25'!B24-'Entries August''25'!B23) -> 3380 | C24: =IF('Entries August''25'!F24-'Entries August''25'!F23<1,"0",'Entries August''25'!F24-'Entries August''25'!F23) -> 20.9 | D24: =IF('Entries August''25'!C23=0,0,+'Entries August''25'!C23-'Entries August''25'!C22) -> 0 | E24: =IF('Entries August''25'!G24-'Entries August''25'!G23<1,"0",'Entries August''25'!G24-'Entries August''25'!G23) -> 0 | H24: =IF(C24+E24=0,"0", B24/(C24+E24)) -> 161.72249 | I24: =IF(E24=0,"0", D24/E24) -> 0 | J24: =IF(G24=0,"0", F24/G24) -> 0 | K24: =B24+D24+F24 -> 3380 | L24: 369.534 | M24: =IF(L24=0,"0",(K24/L24)) -> 9.146655
A25: 19 | B25: =IF('Entries August''25'!B25-'Entries August''25'!B24<1,"0",'Entries August''25'!B25-'Entries August''25'!B24) -> 3110 | C25: =IF('Entries August''25'!F25-'Entries August''25'!F24<1,"0",'Entries August''25'!F25-'Entries August''25'!F24) -> 20.6 | D25: =IF('Entries August''25'!C24=0,0,+'Entries August''25'!C24-'Entries August''25'!C23) -> 0 | E25: =IF('Entries August''25'!G25-'Entries August''25'!G24<1,"0",'Entries August''25'!G25-'Entries August''25'!G24) -> 0 | H25: =IF(C25+E25=0,"0", B25/(C25+E25)) -> 150.97087 | I25: =IF(E25=0,"0", D25/E25) -> 0 | J25: =IF(G25=0,"0", F25/G25) -> 0 | K25: =B25+D25+F25 -> 3110 | L25: 204.798 | M25: =IF(L25=0,"0",(K25/L25)) -> 15.185695
A26: 20 | B26: =IF('Entries August''25'!B26-'Entries August''25'!B25<1,"0",'Entries August''25'!B26-'Entries August''25'!B25) -> 3180 | C26: =IF('Entries August''25'!F26-'Entries August''25'!F25<1,"0",'Entries August''25'!F26-'Entries August''25'!F25) -> 20.1 | D26: =IF('Entries August''25'!C25=0,0,+'Entries August''25'!C25-'Entries August''25'!C24) -> 0 | E26: =IF('Entries August''25'!G26-'Entries August''25'!G25<1,"0",'Entries August''25'!G26-'Entries August''25'!G25) -> 0 | H26: =IF(C26+E26=0,"0", B26/(C26+E26)) -> 158.20896 | I26: =IF(E26=0,"0", D26/E26) -> 0 | J26: =IF(G26=0,"0", F26/G26) -> 0 | K26: =B26+D26+F26 -> 3180 | L26: 540.9804 | M26: =IF(L26=0,"0",(K26/L26)) -> 5.8782167
A27: 21 | B27: =IF('Entries August''25'!B27-'Entries August''25'!B26<1,"0",'Entries August''25'!B27-'Entries August''25'!B26) -> 3090 | C27: =IF('Entries August''25'!F27-'Entries August''25'!F26<1,"0",'Entries August''25'!F27-'Entries August''25'!F26) -> 19.7 | D27: =IF('Entries August''25'!C26=0,0,+'Entries August''25'!C26-'Entries August''25'!C25) -> 0 | E27: =IF('Entries August''25'!G27-'Entries August''25'!G26<1,"0",'Entries August''25'!G27-'Entries August''25'!G26) -> 0 | H27: =IF(C27+E27=0,"0", B27/(C27+E27)) -> 156.85279 | I27: =IF(E27=0,"0", D27/E27) -> 0 | J27: =IF(G27=0,"0", F27/G27) -> 0 | K27: =B27+D27+F27 -> 3090 | L27: 609.51 | M27: =IF(L27=0,"0",(K27/L27)) -> 5.0696461
A28: 22 | B28: =IF('Entries August''25'!B28-'Entries August''25'!B27<1,"0",'Entries August''25'!B28-'Entries August''25'!B27) -> 2400 | C28: =IF('Entries August''25'!F28-'Entries August''25'!F27<1,"0",'Entries August''25'!F28-'Entries August''25'!F27) -> 17.5 | D28: =IF('Entries August''25'!C27=0,0,+'Entries August''25'!C27-'Entries August''25'!C26) -> 0 | E28: =IF('Entries August''25'!G28-'Entries August''25'!G27<1,"0",'Entries August''25'!G28-'Entries August''25'!G27) -> 0 | H28: =IF(C28+E28=0,"0", B28/(C28+E28)) -> 137.14286 | I28: =IF(E28=0,"0", D28/E28) -> 0 | J28: =IF(G28=0,"0", F28/G28) -> 0 | K28: =B28+D28+F28 -> 2400 | L28: 218.526 | M28: =IF(L28=0,"0",(K28/L28)) -> 10.982675
A29: 23 | B29: =IF('Entries August''25'!B29-'Entries August''25'!B28<1,"0",'Entries August''25'!B29-'Entries August''25'!B28) -> 900 | C29: =IF('Entries August''25'!F29-'Entries August''25'!F28<1,"0",'Entries August''25'!F29-'Entries August''25'!F28) -> 8.4 | D29: =IF('Entries August''25'!C28=0,0,+'Entries August''25'!C28-'Entries August''25'!C27) -> 0 | E29: =IF('Entries August''25'!G29-'Entries August''25'!G28<1,"0",'Entries August''25'!G29-'Entries August''25'!G28) -> 0 | H29: =IF(C29+E29=0,"0", B29/(C29+E29)) -> 107.14286 | I29: =IF(E29=0,"0", D29/E29) -> 0 | J29: =IF(G29=0,"0", F29/G29) -> 0 | K29: =B29+D29+F29 -> 900 | L29: 0 | M29: =IF(L29=0,"0",(K29/L29)) -> 0
A30: 24 | B30: =IF('Entries August''25'!B30-'Entries August''25'!B29<1,"0",'Entries August''25'!B30-'Entries August''25'!B29) -> 50 | C30: =IF('Entries August''25'!F30-'Entries August''25'!F29<1,"0",'Entries August''25'!F30-'Entries August''25'!F29) -> 0 | D30: =IF('Entries August''25'!C29=0,0,+'Entries August''25'!C29-'Entries August''25'!C28) -> 0 | E30: =IF('Entries August''25'!G30-'Entries August''25'!G29<1,"0",'Entries August''25'!G30-'Entries August''25'!G29) -> 0 | H30: =IF(C30+E30=0,"0", B30/(C30+E30)) -> 0 | I30: =IF(E30=0,"0", D30/E30) -> 0 | J30: =IF(G30=0,"0", F30/G30) -> 0 | K30: =B30+D30+F30 -> 50 | L30: 0 | M30: =IF(L30=0,"0",(K30/L30)) -> 0
A31: 25 | B31: =IF('Entries August''25'!B31-'Entries August''25'!B30<1,"0",'Entries August''25'!B31-'Entries August''25'!B30) -> 1880 | C31: =IF('Entries August''25'!F31-'Entries August''25'!F30<1,"0",'Entries August''25'!F31-'Entries August''25'!F30) -> 18.1 | D31: =IF('Entries August''25'!C30=0,0,+'Entries August''25'!C30-'Entries August''25'!C29) -> 0 | E31: =IF('Entries August''25'!G31-'Entries August''25'!G30<1,"0",'Entries August''25'!G31-'Entries August''25'!G30) -> 0 | H31: =IF(C31+E31=0,"0", B31/(C31+E31)) -> 103.8674 | I31: =IF(E31=0,"0", D31/E31) -> 0 | J31: =IF(G31=0,"0", F31/G31) -> 0 | K31: =B31+D31+F31 -> 1880 | L31: 0 | M31: =IF(L31=0,"0",(K31/L31)) -> 0
A32: 26 | B32: =IF('Entries August''25'!B32-'Entries August''25'!B31<1,"0",'Entries August''25'!B32-'Entries August''25'!B31) -> 2300 | C32: =IF('Entries August''25'!F32-'Entries August''25'!F31<1,"0",'Entries August''25'!F32-'Entries August''25'!F31) -> 19 | D32: =IF('Entries August''25'!C31=0,0,+'Entries August''25'!C31-'Entries August''25'!C30) -> 0 | E32: =IF('Entries August''25'!G32-'Entries August''25'!G31<1,"0",'Entries August''25'!G32-'Entries August''25'!G31) -> 0 | H32: =IF(C32+E32=0,"0", B32/(C32+E32)) -> 121.05263 | I32: =IF(E32=0,"0", D32/E32) -> 0 | J32: =IF(G32=0,"0", F32/G32) -> 0 | K32: =B32+D32+F32 -> 2300 | L32: 0 | M32: =IF(L32=0,"0",(K32/L32)) -> 0
A33: 27 | B33: =IF('Entries August''25'!B33-'Entries August''25'!B32<1,"0",'Entries August''25'!B33-'Entries August''25'!B32) -> 3400 | C33: =IF('Entries August''25'!F33-'Entries August''25'!F32<1,"0",'Entries August''25'!F33-'Entries August''25'!F32) -> 22.1 | D33: =IF('Entries August''25'!C32=0,0,+'Entries August''25'!C32-'Entries August''25'!C31) -> 0 | E33: =IF('Entries August''25'!G33-'Entries August''25'!G32<1,"0",'Entries August''25'!G33-'Entries August''25'!G32) -> 0 | H33: =IF(C33+E33=0,"0", B33/(C33+E33)) -> 153.84615 | I33: =IF(E33=0,"0", D33/E33) -> 0 | J33: =IF(G33=0,"0", F33/G33) -> 0 | K33: =B33+D33+F33 -> 3400 | L33: 237.996 | M33: =IF(L33=0,"0",(K33/L33)) -> 14.285954
A34: 28 | B34: =IF('Entries August''25'!B34-'Entries August''25'!B33<1,"0",'Entries August''25'!B34-'Entries August''25'!B33) -> 3740 | C34: =IF('Entries August''25'!F34-'Entries August''25'!F33<1,"0",'Entries August''25'!F34-'Entries August''25'!F33) -> 21.4 | D34: =IF('Entries August''25'!C33=0,0,+'Entries August''25'!C33-'Entries August''25'!C32) -> 0 | E34: =IF('Entries August''25'!G34-'Entries August''25'!G33<1,"0",'Entries August''25'!G34-'Entries August''25'!G33) -> 0 | H34: =IF(C34+E34=0,"0", B34/(C34+E34)) -> 174.76636 | I34: =IF(E34=0,"0", D34/E34) -> 0 | J34: =IF(G34=0,"0", F34/G34) -> 0 | K34: =B34+D34+F34 -> 3740 | L34: 580.998 | M34: =IF(L34=0,"0",(K34/L34)) -> 6.4371994
A35: 29 | B35: =IF('Entries August''25'!B35-'Entries August''25'!B34<1,"0",'Entries August''25'!B35-'Entries August''25'!B34) -> 2490 | C35: =IF('Entries August''25'!F35-'Entries August''25'!F34<1,"0",'Entries August''25'!F35-'Entries August''25'!F34) -> 16.4 | E35: =IF('Entries August''25'!G35-'Entries August''25'!G34<1,"0",'Entries August''25'!G35-'Entries August''25'!G34) -> 0 | H35: =IF(C35+E35=0,"0", B35/(C35+E35)) -> 151.82927 | I35: =IF(E35=0,"0", D35/E35) -> 0 | J35: =IF(G35=0,"0", F35/G35) -> 0 | K35: =B35+D35+F35 -> 2490 | L35: 407.418 | M35: =IF(L35=0,"0",(K35/L35)) -> 6.1116593
A36: 30 | B36: =IF('Entries August''25'!B36-'Entries August''25'!B35<1,"0",'Entries August''25'!B36-'Entries August''25'!B35) -> 240 | C36: =IF('Entries August''25'!F36-'Entries August''25'!F35<1,"0",'Entries August''25'!F36-'Entries August''25'!F35) -> 1.7 | E36: =IF('Entries August''25'!G36-'Entries August''25'!G35<1,"0",'Entries August''25'!G36-'Entries August''25'!G35) -> 0 | H36: =IF(C36+E36=0,"0", B36/(C36+E36)) -> 141.17647 | I36: =IF(E36=0,"0", D36/E36) -> 0 | J36: =IF(G36=0,"0", F36/G36) -> 0 | K36: =B36+D36+F36 -> 240 | L36: 0 | M36: =IF(L36=0,"0",(K36/L36)) -> 0
A37: 31 | B37: =IF('Entries August''25'!B37-'Entries August''25'!B36<1,"0",'Entries August''25'!B37-'Entries August''25'!B36) -> 520 | C37: =IF('Entries August''25'!F37-'Entries August''25'!F36<1,"0",'Entries August''25'!F37-'Entries August''25'!F36) -> 2.8 | E37: =IF('Entries August''25'!G37-'Entries August''25'!G36<1,"0",'Entries August''25'!G37-'Entries August''25'!G36) -> 0 | H37: =IF(C37+E37=0,"0", B37/(C37+E37)) -> 185.71429 | I37: =IF(E37=0,"0", D37/E37) -> 0 | J37: =IF(G37=0,"0", F37/G37) -> 0 | K37: =B37+D37+F37 -> 520 | L37: 30.855
A38: MTD | B38: =SUM(B7:B37) -> 58850 | C38: =SUM(C7:C37) -> 395.3 | D38: =SUM(D7:D34) -> 0 | E38: =SUM(E7:E34) -> 0 | H38: =IF(C38+E38=0,"0", B38/(C38+E38)) -> 148.87427 | K38: =SUM(K7:K37) -> 58850 | L38: =SUM(L7:L37) -> 7279.8342 | M38: =IF(L38=0,"0",(K38/L38)) -> 8.0839753 | N38: 7.2 | O38: =M38/N38*100 -> 112.27743
A39: AVE. | B39: =AVERAGE(B7:B37) -> 2179.6296 | C39: =AVERAGE(C7:C37) -> 15.812 | H39: cons (l/hr)

Sheet Water 
B4: DATE | C4: Well Supply (m3) | D4: Nawasa Supply (m3) | E4: Annanale Supply (m3) | F4: RO Water Plant Nawasa (m3) | G4: Service Water Received (m3) | H4: Service Water Supply to Plant (m3) | I4: CO2 Scrubber (m3) | J4: Brewhouse / Old Pepsi Area (m3) | K4: Filtration/Cellars (m3) | L4: Cellars/Process Area (m3) | M4: Pasteuriser (m3) | R4: Permeate Produced (m3) | S4: Plant Cons. USAGE (Hl.) | U4: Bottle Filler (m3) | X4: Rus (m3) | Y4: Washdown Area (m3) | Z4: TOTAL SUPPLY (M3) | AA4: Total Prod.(HL) | AB4: Water KPI (Hl/Hl)
N5: CIP Process (m3) | O5: Bottles Washer (m3) | P5: Bottles Filler (m3) | Q5: Boiler Supply (m3) | T5: ∑ Service Water to Processes | V5: Water into RO #1 (m3) | W5: Water into RO #2 (m3)
B6: -
B7: 1 | C7: =IF('Entries August''25'!W7-'Entries August''25'!W6<1,"0",'Entries August''25'!W7-'Entries August''25'!W6) -> 0 | D7: =IF('Entries August''25'!O7-'Entries August''25'!O6<1,"0",'Entries August''25'!O7-'Entries August''25'!O6) -> 0 | E7: =IF('Entries August''25'!P7-'Entries August''25'!P6<1,"0",'Entries August''25'!P7-'Entries August''25'!P6) -> 91 | F7: =IF('Entries August''25'!V7-'Entries August''25'!V6<1,"0",'Entries August''25'!V7-'Entries August''25'!V6) -> 96 | G7: =(D7+E7)-F7 -> -5 | H7: =IF('Entries August''25'!Q7-'Entries August''25'!Q6<1,0,'Entries August''25'!Q7-'Entries August''25'!Q6) -> 12 | I7: =IF('Entries August''25'!AG7-'Entries August''25'!AG6<1,0,'Entries August''25'!AG7-'Entries August''25'!AG6) -> 0 | J7: =IF('Entries August''25'!S7-'Entries August''25'!S6<1,"0",'Entries August''25'!S7-'Entries August''25'!S6) -> 0 | K7: =IF('Entries August''25'!R7-'Entries August''25'!R6<1,"0",'Entries August''25'!R7-'Entries August''25'!R6) -> 0 | L7: =IF('Entries August''25'!T7-'Entries August''25'!T6<1,"0",'Entries August''25'!T7-'Entries August''25'!T6) -> 0 | M7: =IF('Entries August''25'!U7-'Entries August''25'!U6<1,"0",'Entries August''25'!U7-'Entries August''25'!U6) -> 0 | N7: =IF('Entries August''25'!X7-'Entries August''25'!X6<1,"0",'Entries August''25'!X7-'Entries August''25'!X6) -> 0 | O7: =IF('Entries August''25'!Y7-'Entries August''25'!Y6<1,"0",'Entries August''25'!Y7-'Entries August''25'!Y6) -> 0 | P7: =IF('Entries August''25'!AC7-'Entries August''25'!AC6<1,"0",'Entries August''25'!AC7-'Entries August''25'!AC6) -> 0 | Q7: =IF('Entries August''25'!Z7-'Entries August''25'!Z6<1,"0",'Entries August''25'!Z7-'Entries August''25'!Z6) -> 0 | R7: =IF(('Entries August''25'!AA7-'Entries August''25'!AA6)+('Entries August''25'!AB7-'Entries August''25'!AB6)<1,"0",('Entries August''25'!AA7-'Entries August''25'!AA6)+('Entries August''25'!AB7-'Entries August''25'!AB6)) -> 0 | S7: =(R7+G7)*10 -> -50 | T7: =O7+N7+M7+L7 -> 0 | U7: =IF('Entries August''25'!AC7-'Entries August''25'!AC6<1,"0",'Entries August''25'!AC7-'Entries August''25'!AC6) -> 0 | V7: =IF('Entries August''25'!AD7-'Entries August''25'!AD6<1,"0",'Entries August''25'!AD7-'Entries August''25'!AD6) -> 0 | W7: =IF('Entries August''25'!AE7-'Entries August''25'!AE6<1,"0",'Entries August''25'!AE7-'Entries August''25'!AE6) -> 0 | X7: =IF('Entries August''25'!AI7-'Entries August''25'!AI6<1,"0",'Entries August''25'!AI7-'Entries August''25'!AI6) -> 0 | Y7: =IF('Entries August''25'!AH7-'Entries August''25'!AH6<1,"0",'Entries August''25'!AH7-'Entries August''25'!AH6) -> 0 | Z7: =C7+D7+E7 -> 91 | AA7: {=IF(TRANSPOSE('Daily KPIs'!B9:AF9)=0,"0",TRANSPOSE('Daily KPIs'!B9:AF9))} -> 0 | AB7: =IF(AA7=0,"0",(Z7*10/AA7)) -> 0
B8: 2 | C8: =IF('Entries August''25'!W8-'Entries August''25'!W7<1,"0",'Entries August''25'!W8-'Entries August''25'!W7) -> 0 | D8: =IF('Entries August''25'!O8-'Entries August''25'!O7<1,"0",'Entries August''25'!O8-'Entries August''25'!O7) -> 15 | E8: =IF('Entries August''25'!P8-'Entries August''25'!P7<1,"0",'Entries August''25'!P8-'Entries August''25'!P7) -> 0 | F8: =IF('Entries August''25'!V8-'Entries August''25'!V7<1,"0",'Entries August''25'!V8-'Entries August''25'!V7) -> 0 | G8: =(D8+E8)-F8 -> 15 | H8: =IF('Entries August''25'!Q8-'Entries August''25'!Q7<1,0,'Entries August''25'!Q8-'Entries August''25'!Q7) -> 14 | I8: =IF('Entries August''25'!AG8-'Entries August''25'!AG7<1,0,'Entries August''25'!AG8-'Entries August''25'!AG7) -> 0 | J8: =IF('Entries August''25'!S8-'Entries August''25'!S7<1,"0",'Entries August''25'!S8-'Entries August''25'!S7) -> 0 | K8: =IF('Entries August''25'!R8-'Entries August''25'!R7<1,"0",'Entries August''25'!R8-'Entries August''25'!R7) -> 0 | L8: =IF('Entries August''25'!T8-'Entries August''25'!T7<1,"0",'Entries August''25'!T8-'Entries August''25'!T7) -> 0 | M8: =IF('Entries August''25'!U8-'Entries August''25'!U7<1,"0",'Entries August''25'!U8-'Entries August''25'!U7) -> 0 | N8: =IF('Entries August''25'!X8-'Entries August''25'!X7<1,"0",'Entries August''25'!X8-'Entries August''25'!X7) -> 0 | O8: =IF('Entries August''25'!Y8-'Entries August''25'!Y7<1,"0",'Entries August''25'!Y8-'Entries August''25'!Y7) -> 0 | P8: =IF('Entries August''25'!AC8-'Entries August''25'!AC7<1,"0",'Entries August''25'!AC8-'Entries August''25'!AC7) -> 0 | Q8: =IF('Entries August''25'!Z8-'Entries August''25'!Z7<1,"0",'Entries August''25'!Z8-'Entries August''25'!Z7) -> 0 | R8: =IF(('Entries August''25'!AA8-'Entries August''25'!AA7)+('Entries August''25'!AB8-'Entries August''25'!AB7)<1,"0",('Entries August''25'!AA8-'Entries August''25'!AA7)+('Entries August''25'!AB8-'Entries August''25'!AB7)) -> 0 | S8: =(R8+G8)*10 -> 150 | T8: =O8+N8+M8+L8 -> 0 | U8: =IF('Entries August''25'!AC8-'Entries August''25'!AC7<1,"0",'Entries August''25'!AC8-'Entries August''25'!AC7) -> 0 | V8: =IF('Entries August''25'!AD8-'Entries August''25'!AD7<1,"0",'Entries August''25'!AD8-'Entries August''25'!AD7) -> 0 | W8: =IF('Entries August''25'!AE8-'Entries August''25'!AE7<1,"0",'Entries August''25'!AE8-'Entries August''25'!AE7) -> 0 | X8: =IF('Entries August''25'!AI8-'Entries August''25'!AI7<1,"0",'Entries August''25'!AI8-'Entries August''25'!AI7) -> 0 | Y8: =IF('Entries August''25'!AH8-'Entries August''25'!AH7<1,"0",'Entries August''25'!AH8-'Entries August''25'!AH7) -> 0 | Z8: =C8+D8+E8 -> 15 | AA8: 0 | AB8: =IF(AA8=0,"0",(Z8*10/AA8)) -> 0
