Workbook

Sheet January 2026 (w Utilization)
C1: OEE Calculation | G1: CARIB BREWERY
A2: SKU | B2: Start Time dd/mm/yyyy h:mm | C2: End Time dd/mm/yyyy h:mm (when production actually ends) | D2: Available time /mins | E2: Changeover Standard time /mins | F2: Actual Changeover /mins | G2: Changeover Deviation /mins | H2: Total Breakdowns /mins | I2: Total Minor Stops /mins | J2: Availability (for OEE) | K2: Planned Downtime /mins | L2: External Downtime /mins | M2: Availability (for OEE Utilization) | N2: Nominal Speed | O2: Actual (Average) Speed | P2: Performance | Q2: Total Products Produced /Cases | R2: Low Fill /Cases | S2: Embargo /cases | T2: Embargo release date | U2: Embargo Residence time /days | V2: Quality | W2: OEE | X2: OEE Utilization
A3: Carib Amber | B3: 46024.385 | C3: 46024.794 | D3: =IF(B3="","",(C3-B3)*24*60) -> 589 | E3: 0 | F3: 0 | G3: =IF(E3="","",F3-E3) -> 0 | H3: =6+6+10+5+32+5+7+5+6+6 -> 88 | I3: =2+3+3+3+2+3+3+3+3 -> 25 | J3: =IF(B3="","",(D3-G3-H3-I3)/D3) -> 0.80814941 | K3: 0 | L3: =10+5+4+3+5+8 -> 35 | M3: =IF(B3="","",(D3-G3-H3-I3-K3-L3-E3)/D3) -> 0.74872666 | N3: 17000 | O3: =AVERAGE(15000,15000,15000,15000,15000,15000,15000,15000,15000) -> 15000 | P3: =IF(B3="","",O3/N3) -> 0.88235294 | Q3: 3360 | R3: 4 | S3: 139 | T3: 46028.708 | U3: =IF(S3="","",(T3-C3)) -> 3.9138889 | V3: =IF(B3="","",IF(U3<3,(Q3-R3)/Q3,(Q3-R3-S3)/Q3)) -> 0.95744048 | W3: =IF(B3="","",V3*P3*J3) -> 0.68272496 | X3: =IF(B3="","",V3*P3*M3) -> 0.63252459
A4: Carib Amber | B4: 46027.076 | C4: 46027.188 | D4: =IF(B4="","",(C4-B4)*24*60) -> 160 | E4: 0 | F4: 0 | G4: =IF(E4="","",F4-E4) -> 0 | H4: =60+60+30 -> 150 | I4: 0 | J4: =IF(B4="","",(D4-G4-H4-I4)/D4) -> 0.0625 | K4: 0 | L4: 0 | M4: =IF(B4="","",(D4-G4-H4-I4-K4-L4-E4)/D4) -> 0.0625 | N4: 17000 | O4: 15000 | P4: =IF(B4="","",O4/N4) -> 0.88235294 | Q4: 19 | U4: =IF(S4="","",(T4-C4)) | V4: =IF(B4="","",IF(U4<3,(Q4-R4)/Q4,(Q4-R4-S4)/Q4)) -> 1 | W4: =IF(B4="","",V4*P4*J4) -> 0.055147059 | X4: =IF(B4="","",V4*P4*M4) -> 0.055147059
A5: Carib Amber | B5: 46030.81 | C5: 46031 | D5: =IF(B5="","",(C5-B5)*24*60) -> 274 | E5: 0 | F5: 0 | G5: =IF(E5="","",F5-E5) -> 0 | H5: =6+5+26+7+11+10 -> 65 | I5: =2+4+1+3+4+2 -> 16 | J5: =IF(B5="","",(D5-G5-H5-I5)/D5) -> 0.70437956 | K5: 0 | L5: =3 -> 3 | M5: =IF(B5="","",(D5-G5-H5-I5-K5-L5-E5)/D5) -> 0.69343066 | N5: 17000 | O5: =AVERAGE(13000,13000,13000,13000) -> 13000 | P5: =IF(B5="","",Q5/N5) -> 0.091941176 | Q5: 1563 | R5: 4 | U5: =IF(S5="","",(T5-C5)) | V5: =IF(B5="","",IF(U5<3,(Q5-R5)/Q5,(Q5-R5-S5)/Q5)) -> 0.99744082 | W5: =IF(B5="","",V5*P5*J5) -> 0.064595749 | X5: =IF(B5="","",V5*P5*M5) -> 0.06359167
A6: Carib Amber to Starmalt | B6: 46031.01 | C6: 46031.833 | D6: =IF(B6="","",(C6-B6)*24*60) -> 1185 | E6: 45 | F6: 18 | G6: =IF(E6="","",F6-E6) -> -27 | H6: =5+6+57+37+11+10+5+7+18+6 -> 162 | I6: =2+3+3+2+4+2+3+2+3+3+2+2+3+4+1+4+2+4+2+2+2+2+4+4+3+2+4 -> 74 | J6: =IF(B6="","",(D6-G6-H6-I6)/D6) -> 0.82362869 | K6: 0 | L6: =30+10+5+15+6+7+6+13+7+6+3+10+15+3+11+2+4+3 -> 156 | M6: =IF(B6="","",(D6-G6-H6-I6-K6-L6-E6)/D6) -> 0.65400844 | N6: 17000 | O6: =AVERAGE(13000,13000,13000,13000,13000,13000,13000,14000,17000,20000,18000,18000,17000,18000,18000,18000,18000,18000) -> 15833.333 | P6: =IF(B6="","",Q6/N6) -> 0.36464706 | Q6: 6199 | R6: 29 | S6: 1 | U6: =IF(S6="","",(T6-C6)) -> -46031.833 | V6: =IF(B6="","",IF(U6<3,(Q6-R6)/Q6,(Q6-R6-S6)/Q6)) -> 0.99532183 | W6: =IF(B6="","",V6*P6*J6) -> 0.29892877 | X6: =IF(B6="","",V6*P6*M6) -> 0.23736659
A7: Starmalt | B7: 46032.351 | C7: 46032.604 | D7: =IF(B7="","",(C7-B7)*24*60) -> 365 | E7: 0 | F7: 0 | G7: =IF(E7="","",F7-E7) -> 0 | H7: =5+5+6+9+6+5+6 -> 42 | I7: =3+3+4+2+1+3+2+4+4+4+2+4 -> 36 | J7: =IF(B7="","",(D7-G7-H7-I7)/D7) -> 0.78630137 | K7: 0 | L7: =4 -> 4 | M7: =IF(B7="","",(D7-G7-H7-I7-K7-L7-E7)/D7) -> 0.77534247 | N7: 17000 | O7: =AVERAGE(17500,17000,17000,17000,17000) -> 17100 | P7: =IF(B7="","",Q7/N7) -> 0.15158824 | Q7: 2577 | R7: 32 | U7: =IF(S7="","",(T7-C7)) | V7: =IF(B7="","",IF(U7<3,(Q7-R7)/Q7,(Q7-R7-S7)/Q7)) -> 0.98758246 | W7: =IF(B7="","",V7*P7*J7) -> 0.11771394 | X7: =IF(B7="","",V7*P7*M7) -> 0.11607333
A8: Vitamalt to Starmalt to Stag | B8: 46034.135 | C8: 46035 | D8: =IF(B8="","",(C8-B8)*24*60) -> 1245 | E8: =100+45 -> 145 | F8: 238 | G8: =IF(E8="","",F8-E8) -> 93 | H8: =10+8+5+7+6+6+5+5+8+6+7+5+29+6+11 -> 124 | I8: =3+3+2+3+1+2+4+1+2+2+3+3+2+2+4+3+2+3+4+4+2+2+4+2+3+1+4+3+3+3+2+3+3 -> 88 | J8: =IF(B8="","",(D8-G8-H8-I8)/D8) -> 0.75502008 | K8: 0 | L8: =17+12+10+4 -> 43 | M8: =IF(B8="","",(D8-G8-H8-I8-K8-L8-E8)/D8) -> 0.60401606 | N8: 17000 | O8: =AVERAGE(17500,17000,17000,17000,17000) -> 17100 | P8: =IF(B8="","",O8/N8) -> 1.0058824 | Q8: 5669 | R8: 21 | U8: =IF(S8="","",(T8-C8)) | V8: =IF(B8="","",IF(U8<3,(Q8-R8)/Q8,(Q8-R8-S8)/Q8)) -> 0.99629564 | W8: =IF(B8="","",V8*P8*J8) -> 0.75664806 | X8: =IF(B8="","",V8*P8*M8) -> 0.60531845
A9: Stag to Carib Amber | B9: 46035.01 | C9: 46036 | D9: =IF(B9="","",(C9-B9)*24*60) -> 1425 | E9: 10 | F9: 30 | G9: =IF(E9="","",F9-E9) -> 20 | H9: =5+6+5+5+6+6+57+50+10+7+5+15+7+7+33+7+30+18+5 -> 284 | I9: =4+2+1+2+2+3+3+3+3+1+2+1+4+3+2+3+3+2+2+2+1+3+2+2+2+3+3+1+2+4+3+2+4+1+3+4+1+2 -> 91 | J9: =IF(B9="","",(D9-G9-H9-I9)/D9) -> 0.72280702 | K9: 0 | L9: =3+2+2+5+8+4 -> 24 | M9: =IF(B9="","",(D9-G9-H9-I9-K9-L9-E9)/D9) -> 0.69894737 | N9: 17000 | O9: =AVERAGE(16500,16500,15000,15000,15000,15000,15000,15000,15000,15000,15000,15000,15000,15000,15000,15000,16000,16000,16000,16000,15000,15000) -> 15318.182 | P9: =IF(B9="","",O9/N9) -> 0.90106952 | Q9: 7544 | R9: 18 | S9: 1517 | T9: 46066.833 | U9: =IF(S9="","",(T9-C9)) -> 30.833333 | V9: =IF(B9="","",IF(U9<3,(Q9-R9)/Q9,(Q9-R9-S9)/Q9)) -> 0.79652704 | W9: =IF(B9="","",V9*P9*J9) -> 0.51877756 | X9: =IF(B9="","",V9*P9*M9) -> 0.50165287
A10: Carib Amber to Stag | B10: 46036.008 | C10: 46036.982 | D10: =IF(B10="","",(C10-B10)*24*60) -> 1402 | E10: 10 | F10: 16 | G10: =IF(E10="","",F10-E10) -> 6 | H10: =11+9+24+15+5+5+16+5+11+10+5+5+6+5+6+7+9 -> 154 | I10: =1+2+2+3+1+2+4+3+2+3+2+2+3+1+3+1+3+3+2+3+2+1+3+2+1+2+4+2+4+1 -> 68 | J10: =IF(B10="","",(D10-G10-H10-I10)/D10) -> 0.83737518 | K10: 0 | L10: =4+11+4+4+9+5+60+25+18+14+12+16 -> 182 | M10: =IF(B10="","",(D10-G10-H10-I10-K10-L10-E10)/D10) -> 0.70042796 | N10: 17000 | O10: =AVERAGE(15000,15000,15000,15000,15000,15000,15000,15000,15000,15000,15000,15000,15000,15000,15000,15000,15000,15000,15000,15000) -> 15000 | P10: =IF(B10="","",O10/N10) -> 0.88235294 | Q10: 7396 | R10: 30 | U10: =IF(S10="","",(T10-C10)) | V10: =IF(B10="","",IF(U10<3,(Q10-R10)/Q10,(Q10-R10-S10)/Q10)) -> 0.99594375 | W10: =IF(B10="","",V10*P10*J10) -> 0.73586345 | X10: =IF(B10="","",V10*P10*M10) -> 0.61551781
A11: Mackeson to Shandy Sorrel | B11: 46037.022 | C11: 46037.957 | D11: =IF(B11="","",(C11-B11)*24*60) -> 1346 | E11: 60 | F11: 73 | G11: =IF(E11="","",F11-E11) -> 13 | H11: =5+5+11+8+5+6+6+6+29+5+9+5+5+6+5+7+15+5+5+14+6+5 -> 173 | I11: =2+3+2+1+2+3+1+2+2+2+1+2+2+3+4+3+4+3+4+2+2+4+3+4+3+2+2+4+2+3+1+3+4+2+4 -> 91 | J11: =IF(B11="","",(D11-G11-H11-I11)/D11) -> 0.79420505 | K11: 0 | L11: =10+22+10 -> 42 | M11: =IF(B11="","",(D11-G11-H11-I11-K11-L11-E11)/D11) -> 0.71842496 | N11: 17000 | O11: =AVERAGE(15000,15000,15000,14500,15000,15000,15000,15000,15000,15000,15000,15000,15000,15000,15000,15000,15000,15000) -> 14972.222 | P11: =IF(B11="","",O11/N11) -> 0.88071895 | Q11: 7088 | R11: 30 | U11: =IF(S11="","",(T11-C11)) | V11: =IF(B11="","",IF(U11<3,(Q11-R11)/Q11,(Q11-R11-S11)/Q11)) -> 0.99576749 | W11: =IF(B11="","",V11*P11*J11) -> 0.69651093 | X11: =IF(B11="","",V11*P11*M11) -> 0.63005245
A12: Ting to Carib Amber | B12: 46038.021 | C12: 46038.825 | D12: =IF(B12="","",(C12-B12)*24*60) -> 1158 | E12: 60 | F12: 120 | G12: =IF(E12="","",F12-E12) -> 60 | H12: =6+9+8+6+10+26+6+12+5+5+6+6+5+11+5 -> 126 | I12: =3+4+2+2+2+1+2+4+2+2+1+2+2+2+1+2+3+4+2+3+2+2+2+1+3+3+3+2+4+2+4+3+1+2+2+3+4+4+2+1 -> 96 | J12: =IF(B12="","",(D12-G12-H12-I12)/D12) -> 0.75647668 | K12: 0 | L12: =36+9+11 -> 56 | M12: =IF(B12="","",(D12-G12-H12-I12-K12-L12-E12)/D12) -> 0.65630397 | N12: 17000 | O12: =AVERAGE(15000,15000,15000,15000,15000,15000,15000,15000,15000,15000,15000,15000,15000,15000,15000) -> 15000 | P12: =IF(B12="","",O12/N12) -> 0.88235294 | Q12: 6434 | R12: 17 | U12: =IF(S12="","",(T12-C12)) | V12: =IF(B12="","",IF(U12<3,(Q12-R12)/Q12,(Q12-R12-S12)/Q12)) -> 0.99735779 | W12: =IF(B12="","",V12*P12*J12) -> 0.6657158 | X12: =IF(B12="","",V12*P12*M12) -> 0.57756166
A13: Carib Amber to Stag | B13: 46041.108 | C13: 46042 | D13: =IF(B13="","",(C13-B13)*24*60) -> 1285 | E13: 10 | F13: 24 | G13: =IF(E13="","",F13-E13) -> 14 | H13: =5+5+7+5+5+5+16+5+5+6+5+8 -> 77 | I13: =3+3+3+4+1+2+3+2+3+2+3+4+4+2+3+2+2+1+2+1+1+1+1+1+2+1+1+2+1+1+2+1+3+4+1+1+1+1+2+1+2+2+2+1+1+2+3+2+2+2+2+1+2+1+3+3+2+2+1+2 -> 117 | J13: =IF(B13="","",(D13-G13-H13-I13)/D13) -> 0.8381323 | K13: 0 | L13: =5+22+4+8+2 -> 41 | M13: =IF(B13="","",(D13-G13-H13-I13-K13-L13-E13)/D13) -> 0.79844358 | N13: 17000 | O13: =AVERAGE(15000,15000,15000,15000,15000,15000,14900,15000,15000,14000,14500,14500,15000,15000,15000,15000,15000,15000,15000,15000,15000) -> 14900 | P13: =IF(B13="","",O13/N13) -> 0.87647059 | Q13: 7967 | R13: 12 | U13: =IF(S13="","",(T13-C13)) | V13: =IF(B13="","",IF(U13<3,(Q13-R13)/Q13,(Q13-R13-S13)/Q13)) -> 0.99849379 | W13: =IF(B13="","",V13*P13*J13) -> 0.73349184 | X13: =IF(B13="","",V13*P13*M13) -> 0.69875825
A14: Stag to Ginseng up Original | B14: 46042.003 | C14: 46042.863 | D14: =IF(B14="","",(C14-B14)*24*60) -> 1238 | E14: 45 | F14: 76 | G14: =IF(E14="","",F14-E14) -> 31 | H14: =5+18+5+50+9+14+6+6+5+5+6+5+5+5+7 -> 151 | I14: =2+3+3+2+3+3+3+4+2+2+3+3+2+3+3+1+2+1+1+1+4+1+1+1+1+2+1+1+2+3+4+1+1+1+1+1+1+2+1+2+1+1+2+2+2+1+4 -> 92 | J14: =IF(B14="","",(D14-G14-H15-I14)/D14) -> 0.68336026 | K14: 0 | L14: 3 | M14: =IF(B14="","",(D14-G14-H14-I14-K14-L14-E14)/D14) -> 0.73990307 | N14: 17000 | O14: =AVERAGE(15000,15000,15000,15000,15000,15000,15000,14900,15000,15000,14800,15000,15000,15000,15000,15000,15000) -> 14982.353 | P14: =IF(B14="","",O14/N14) -> 0.88131488 | Q14: 6535 | R14: 21 | S14: 4.14 | T14: 46073.625 | U14: =IF(S14="","",(T14-C14)) -> 30.761806 | V14: =IF(B14="","",IF(U14<3,(Q14-R14)/Q14,(Q14-R14-S14)/Q14)) -> 0.99615302 | W14: =IF(B14="","",V14*P14*J14) -> 0.5999387 | X14: =IF(B14="","",V14*P14*M14) -> 0.64957902
A15: Soda water to Kola Champ to Cream Soda to Banana | B15: 46043.111 | C15: 46044 | D15: =IF(B15="","",(C15-B15)*24*60) -> 1280 | E15: =120+20+20+20 -> 180 | F15: 289 | G15: =IF(E15="","",F15-E15) -> 109 | H15: =25+60+60+30+8+8+5+15+25+33 -> 269 | I15: =4+4+3+1+2+1+1+2+3+2+2+2+2+2+4+2+4+4+2+3+2 -> 52 | J15: =IF(B15="","",(D15-G15-H15-I15)/D15) -> 0.6640625 | K15: 0 | L15: =30+36+3+4+8+8+5+5+4+57+2+20+27+36 -> 245 | M15: =IF(B15="","",(D15-G15-H15-I15-K15-L15-E15)/D15) -> 0.33203125 | N15: 17000 | O15: =AVERAGE(15000,15000,10900,10900,14500,14500,14500,14500,14000,14000) -> 13780 | P15: =IF(B15="","",O15/N15) -> 0.81058824 | Q15: 3535 | R15: 46 | S15: 70 | T15: 46075.583 | U15: =IF(S15="","",(T15-C15)) -> 31.583333 | V15: =IF(B15="","",IF(U15<3,(Q15-R15)/Q15,(Q15-R15-S15)/Q15)) -> 0.96718529 | W15: =IF(B15="","",V15*P15*J15) -> 0.52061771 | X15: =IF(B15="","",V15*P15*M15) -> 0.26030885
A16: Banana to Ginger to Grape to Sorrel | B16: 46045.276 | C16: 46045.848 | D16: =IF(B16="","",(C16-B16)*24*60) -> 823 | E16: =20+20+20 -> 60 | F16: 70 | G16: =IF(E16="","",F16-E16) -> 10 | H16: =9+25+8+6+5+7+6 -> 66 | I16: =1+3+2+4+2+1+1+1+2+2+2+2+3+3+2+1+3+2+3 -> 40 | J16: =IF(B16="","",(D16-G16-H16-I16)/D16) -> 0.85905225 | K16: 0 | L16: =8+26+6+12+32+6+39+2+4+3+13 -> 151 | M16: =IF(B16="","",(D16-G16-H16-I16-K16-L16-E16)/D16) -> 0.60267315 | N16: 17000 | O16: =AVERAGE(11000,10100,9300,13200,9000,9000,11000,9000,11000) -> 10288.889 | P16: =IF(B16="","",O16/N16) -> 0.60522876 | Q16: 2836 | R16: 21 | U16: =IF(S16="","",(T16-C16)) | V16: =IF(B16="","",IF(U16<3,(Q16-R16)/Q16,(Q16-R16-S16)/Q16)) -> 0.9925952 | W16: =IF(B16="","",V16*P16*J16) -> 0.5160732 | X16: =IF(B16="","",V16*P16*M16) -> 0.36205418
A17: J.Cool Sorrel to Carib Amber | B17: 46048.073 | C17: 46049 | D17: =IF(B17="","",(C17-B17)*24*60) -> 1335 | E17: 100 | F17: 32 | G17: =IF(E17="","",F17-E17) -> -68 | H17: =12+60+25+51+60+60+480+60+60+21+15+18+60+55+7+6+5 -> 1055 | I17: =2+3+2+4+4+2+2+2+3+2 -> 26 | J17: =IF(B17="","",(D17-G17-H17-I17)/D17) -> 0.2411985 | K17: 0 | L17: 0 | M17: =IF(B17="","",(D17-G17-H17-I17-K17-L17-E17)/D17) -> 0.16629213 | N17: 17000 | O17: =AVERAGE(12500,15000,15000,15000,15000,15000) -> 14583.333 | P17: =IF(B17="","",O17/N17) -> 0.85784314 | Q17: 2426 | R17: 15 | S17: =5*70 -> 350 | T17: 46080.375 | U17: =IF(S17="","",(T17-C17)) -> 31.375 | V17: =IF(B17="","",IF(U17<3,(Q17-R17)/Q17,(Q17-R17-S17)/Q17)) -> 0.84954658 | W17: =IF(B17="","",V17*P17*J17) -> 0.17578009 | X17: =IF(B17="","",V17*P17*M17) -> 0.12119
A18: Carib Amber to Pearsecco | B18: 46049.003 | C18: 46050 | D18: =IF(B18="","",(C18-B18)*24*60) -> 1435 | E18: 60 | F18: 60 | G18: =IF(E18="","",F18-E18) -> 0 | H18: =14+6+5+5+5+5+14+5+7+5+5+8+10 -> 94 | I18: =3+2+2+2+1+3+2+2+2+2+1+1+4+3+3+2+1+4+2+4+4+1+4+4+2+3+3+3+3+2+4+3+3+2+2+2 -> 91 | J18: =IF(B18="","",(D18-G18-H18-I18)/D18) -> 0.87108014 | K18: 0 | L18: =30+60+60+15+4+4+3+4+3+3+4+3 -> 193 | M18: =IF(B18="","",(D18-G18-H18-I18-K18-L18-E18)/D18) -> 0.69477352 | N18: 17000 | O18: =AVERAGE(15000,15000,15000,15000,15000,15000,15000,16000,16000,16000,15000,15000,15000,15000,15000,15000) -> 15187.5 | P18: =IF(B18="","",O18/N18) -> 0.89338235 | Q18: 7706 | R18: 10 | U18: =IF(S18="","",(T18-C18)) | V18: =IF(B18="","",IF(U18<3,(Q18-R18)/Q18,(Q18-R18-S18)/Q18)) -> 0.99870231 | W18: =IF(B18="","",V18*P18*J18) -> 0.77719775 | X18: =IF(B18="","",V18*P18*M18) -> 0.61989293
A19: Pearsecco to Rose (Export) to Rose to Vitamalt Classic | B19: 46050.003 | C19: 46051 | D19: =IF(B19="","",(C19-B19)*24*60) -> 1435 | E19: =45+45+60 -> 150 | F19: 155 | G19: =IF(E19="","",F19-E19) -> 5 | H19: =7+36+21+7+7+9+15+5+6+5+5+6+11+6+5+5+5+10+10+5+5+10 -> 201 | I19: =2+1+2+2+1+3+1+2+2+2+1+2+1+1+1+1+1+2+3+3+2+2+4+3+3+1+3+4+4+3+4+4+3+3+2+3+3+3+4+1+2+1+2+2+1+2 -> 103 | J19: =IF(B19="","",(D19-G19-H19-I19)/D19) -> 0.78466899 | K19: 0 | L19: =6+10+6+7+2 -> 31 | M19: =IF(B19="","",(D19-G19-H19-I19-K19-L19-E19)/D19) -> 0.65853659 | N19: 17000 | O19: =AVERAGE(15000,15000,15000,15000,15000,15000,15000,15000,15000,15000,15000,15000,15000,15000,15000,15000,15500) -> 15029.412 | P19: =IF(B19="","",O19/N19) -> 0.88408304 | Q19: 6199 | R19: 10 | U19: =IF(S19="","",(T19-C19)) | V19: =IF(B19="","",IF(U19<3,(Q19-R19)/Q19,(Q19-R19-S19)/Q19)) -> 0.99838684 | W19: =IF(B19="","",V19*P19*J19) -> 0.69259348 | X19: =IF(B19="","",V19*P19*M19) -> 0.58126184
A20: Vitamalt Classic to Vitamalt Ginger to Guinness to Carib Amber | B20: 46051.006 | C20: 46052 | D20: =IF(B20="","",(C20-B20)*24*60) -> 1432 | E20: =10+100+60 -> 170 | F20: 64 | G20: =IF(E20="","",F20-E20) -> -106 | H20: =5+5+8+5+6+15+8+6+10+6+35 -> 109 | I20: =4+3+4+3+3+3+2+1+2+2+1+2+2+1+2+2+4+4+3+3+1+3+3+4+3+4+2+4+1+1+1+3+2+2+4+3+2 -> 94 | J20: =IF(B20="","",(D20-G20-H20-I20)/D20) -> 0.93226257 | K20: 0 | L20: =8+2+2+8+25+50+9+2 -> 106 | M20: =IF(B20="","",(D20-G20-H20-I20-K20-L20-E20)/D20) -> 0.73952514 | N20: 17000 | O20: =AVERAGE(14000,14000,15000,15000,15000,15000,15000,15000) -> 14750 | P20: =IF(B20="","",O20/N20) -> 0.86764706 | Q20: 7217 | R20: 378 | U20: =IF(S20="","",(T20-C20)) | V20: =IF(B20="","",IF(U20<3,(Q20-R20)/Q20,(Q20-R20-S20)/Q20)) -> 0.94762367 | W20: =IF(B20="","",V20*P20*J20) -> 0.76650898 | X20: =IF(B20="","",V20*P20*M20) -> 0.6080397
A21: Carib Amber to Stag | B21: 46052.007 | C21: 46052.83 | D21: =IF(B21="","",(C21-B21)*24*60) -> 1185 | E21: 10 | F21: 30 | G21: =IF(E21="","",F21-E21) -> 20 | H21: =6+10+5+5+6+11+10+9 -> 62 | I21: =2+1+2+2+3+2+2+3+4+3+3+4+2+2+2+3+3+1+4+4+2+4+3+3+3+4+3+4+2+4+2+4+2+2+2+2 -> 98 | J21: =IF(B21="","",(D21-G21-H21-I21)/D21) -> 0.84810127 | K21: 0 | L21: =6+6+15+5+21+2+8 -> 63 | M21: =IF(B21="","",(D21-G21-H21-I21-K21-L21-E21)/D21) -> 0.78649789 | N21: 17000 | O21: =AVERAGE(15000,15000,15000,15000,15000,15000,15000,14000,14000,14000,14000,14000,14000,14000,14000,14000,14000,14000) -> 14388.889 | P21: =IF(B21="","",O21/N21) -> 0.84640523 | Q21: 6837 | R21: 16 | V21: =IF(B21="","",IF(U21<3,(Q21-R21)/Q21,(Q21-R21-S21)/Q21)) -> 0.99765979 | W21: =IF(B21="","",V21*P21*J21) -> 0.71615746 | X21: =IF(B21="","",V21*P21*M21) -> 0.66413806
D22: =IF(B22="","",(C22-B22)*24*60) | G22: =IF(E22="","",F22-E22) | J22: =IF(B22="","",(D22-G22-H22-I22)/D22) | M22: =IF(B22="","",(D22-G22-H22-I22-K22-L22-E22)/D22) | P22: =IF(B22="","",O22/N22) | U22: =IF(S22="","",(T22-C22)) | V22: =IF(B22="","",IF(U22<3,(Q22-R22)/Q22,(Q22-R22-S22)/Q22)) | W22: =IF(B22="","",V22*P22*J22) | X22: =IF(B22="","",V22*P22*M22)
D23: =IF(B23="","",(C23-B23)*24*60) | G23: =IF(E23="","",F23-E23) | J23: =IF(B23="","",(D23-G23-H23-I23)/D23) | M23: =IF(B23="","",(D23-G23-H23-I23-K23-L23-E23)/D23) | P23: =IF(B23="","",O23/N23) | U23: =IF(S23="","",(T23-C23)) | V23: =IF(B23="","",IF(U23<3,(Q23-R23)/Q23,(Q23-R23-S23)/Q23)) | W23: =IF(B23="","",V23*P23*J23) | X23: =IF(B23="","",V23*P23*M23)
D24: =IF(B24="","",(C24-B24)*24*60) | G24: =IF(E24="","",F24-E24) | J24: =IF(B24="","",(D24-G24-H24-I24)/D24) | M24: =IF(B24="","",(D24-G24-H24-I24-K24-L24-E24)/D24) | P24: =IF(B24="","",O24/N24) | U24: =IF(S24="","",(T24-C24)) | V24: =IF(B24="","",IF(U24<3,(Q24-R24)/Q24,(Q24-R24-S24)/Q24)) | W24: =IF(B24="","",V24*P24*J24) | X24: =IF(B24="","",V24*P24*M24)
D25: =IF(B25="","",(C25-B25)*24*60) | G25: =IF(E25="","",F25-E25) | J25: =IF(B25="","",(D25-G25-H25-I25)/D25) | M25: =IF(B25="","",(D25-G25-H25-I25-K25-L25-E25)/D25) | P25: =IF(B25="","",O25/N25) | U25: =IF(S25="","",(T25-C25)) | V25: =IF(B25="","",IF(U25<3,(Q25-R25)/Q25,(Q25-R25-S25)/Q25)) | W25: =IF(B25="","",V25*P25*J25) | X25: =IF(B25="","",V25*P25*M25)
D26: =IF(B26="","",(C26-B26)*24*60) | G26: =IF(E26="","",F26-E26) | J26: =IF(B26="","",(D26-G26-H26-I26)/D26) | M26: =IF(B26="","",(D26-G26-H26-I26-K26-L26-E26)/D26) | P26: =IF(B26="","",O26/N26) | U26: =IF(S26="","",(T26-C26)) | V26: =IF(B26="","",IF(U26<3,(Q26-R26)/Q26,(Q26-R26-S26)/Q26)) | W26: =IF(B26="","",V26*P26*J26) | X26: =IF(B26="","",V26*P26*M26)
D27: =IF(B27="","",(C27-B27)*24*60) | G27: =IF(E27="","",F27-E27) | J27: =IF(B27="","",(D27-G27-H27-I27)/D27) | M27: =IF(B27="","",(D27-G27-H27-I27-K27-L27-E27)/D27) | P27: =IF(B27="","",O27/N27) | U27: =IF(S27="","",(T27-C27)) | V27: =IF(B27="","",IF(U27<3,(Q27-R27)/Q27,(Q27-R27-S27)/Q27)) | W27: =IF(B27="","",V27*P27*J27) | X27: =IF(B27="","",V27*P27*M27)
D28: =IF(B28="","",(C28-B28)*24*60) | G28: =IF(E28="","",F28-E28) | J28: =IF(B28="","",(D28-G28-H28-I28)/D28) | M28: =IF(B28="","",(D28-G28-H28-I28-K28-L28-E28)/D28) | P28: =IF(B28="","",O28/N28) | U28: =IF(S28="","",(T28-C28)) | V28: =IF(B28="","",IF(U28<3,(Q28-R28)/Q28,(Q28-R28-S28)/Q28)) | W28: =IF(B28="","",V28*P28*J28) | X28: =IF(B28="","",V28*P28*M28)
D29: =IF(B29="","",(C29-B29)*24*60) | G29: =IF(E29="","",F29-E29) | J29: =IF(B29="","",(D29-G29-H29-I29)/D29) | M29: =IF(B29="","",(D29-G29-H29-I29-K29-L29-E29)/D29) | P29: =IF(B29="","",O29/N29) | U29: =IF(S29="","",(T29-C29)) | V29: =IF(B29="","",IF(U29<3,(Q29-R29)/Q29,(Q29-R29-S29)/Q29)) | W29: =IF(B29="","",V29*P29*J29) | X29: =IF(B29="","",V29*P29*M29)
D30: =IF(B30="","",(C30-B30)*24*60) | G30: =IF(E30="","",F30-E30) | J30: =IF(B30="","",(D30-G30-H30-I30)/D30) | M30: =IF(B30="","",(D30-G30-H30-I30-K30-L30-E30)/D30) | P30: =IF(B30="","",O30/N30) | U30: =IF(S30="","",(T30-C30)) | V30: =IF(B30="","",IF(U30<3,(Q30-R30)/Q30,(Q30-R30-S30)/Q30)) | W30: =IF(B30="","",V30*P30*J30) | X30: =IF(B30="","",V30*P30*M30)
D31: =IF(B31="","",(C31-B31)*24*60) | G31: =IF(E31="","",F31-E31) | J31: =IF(B31="","",(D31-G31-H31-I31)/D31) | M31: =IF(B31="","",(D31-G31-H31-I31-K31-L31-E31)/D31) | P31: =IF(B31="","",O31/N31) | U31: =IF(S31="","",(T31-C31)) | V31: =IF(B31="","",IF(U31<3,(Q31-R31)/Q31,(Q31-R31-S31)/Q31)) | W31: =IF(B31="","",V31*P31*J31) | X31: =IF(B31="","",V31*P31*M31)
D32: =IF(B32="","",(C32-B32)*24*60) | G32: =IF(E32="","",F32-E32) | J32: =IF(B32="","",(D32-G32-H32-I32)/D32) | M32: =IF(B32="","",(D32-G32-H32-I32-K32-L32-E32)/D32) | P32: =IF(B32="","",O32/N32) | U32: =IF(S32="","",(T32-C32)) | V32: =IF(B32="","",IF(U32<3,(Q32-R32)/Q32,(Q32-R32-S32)/Q32)) | W32: =IF(B32="","",V32*P32*J32) | X32: =IF(B32="","",V32*P32*M32)
D33: =IF(B33="","",(C33-B33)*24*60) | G33: =IF(E33="","",F33-E33) | J33: =IF(B33="","",(D33-G33-H33-I33)/D33) | M33: =IF(B33="","",(D33-G33-H33-I33-K33-L33-E33)/D33) | P33: =IF(B33="","",O33/N33) | U33: =IF(S33="","",(T33-C33)) | V33: =IF(B33="","",IF(U33<3,(Q33-R33)/Q33,(Q33-R33-S33)/Q33)) | W33: =IF(B33="","",V33*P33*J33) | X33: =IF(B33="","",V33*P33*M33)
... D37: =IF(B37="","",(C37-B37)*24*60) | G37: =IF(E37="","",F37-E37) | J37: =IF(B37="","",(D37-G37-H37-I37)/D37) | M37: =IF(B37="","",(D37-G37-H37-I37-K37-L37-E37)/D37) | P37: =IF(B37="","",O37/N37) | U37: =IF(S37="","",(T37-C37)) | V37: =IF(B37="","",IF(U37<3,(Q37-R37)/Q37,(Q37-R37-S37)/Q37)) | W37: =IF(B37="","",V37*P37*J37) | X37: =IF(B37="","",V37*P37*M37)
B38: Total | D38: =SUM(D3:D37) -> 20597 | E38: =SUM(E3:E37) -> 1115 | F38: =SUM(F3:F37) -> 1295 | G38: =SUM(G3:G37) -> 180 | H38: =SUM(H2:H37) -> 3452 | I38: =SUM(I3:I37) -> 1298 | J38: =(D38-G38-H38-I38)/D38 -> 0.76064475 | K38: =SUM(K3:K37) -> 0 | L38: =SUM(L3:L37) -> 1378 | M38: =(D38-G38-H38-I38-E38-K38-L38)/D38 -> 0.63960771 | N38: =AVERAGE(N3:N37) -> 17000 | O38: =AVERAGE(O3:O37) -> 14800.743 | P38: =O38/N38 -> 0.87063193 | Q38: =SUM(Q3:Q35) -> 99107 | V38: =AVERAGE(V3:V37) -> 0.97189599 | W38: =V38*P38*J38 -> 0.64362996 | X38: =V38*P38*M38 -> 0.54121281
O39: ytd | P39: =W38 -> 0.64362996
Q41: =O38 -> 14800.743
Q42: ='February 2026 (w Utilization) '!O38 -> 14704.378
Q43: ='March 2026 (w Utilization'!O38 -> 14373.164
Q44: ='April 2026 (w Utilization) '!O38 -> 14982.349
...

Sheet February 2026 (w Utilization) 
C1: OEE Calculation | G1: CARIB BREWERY
A2: SKU | B2: Start Time dd/mm/yyyy h:mm | C2: End Time dd/mm/yyyy h:mm (when production actually ends) | D2: Available time /mins | E2: Changeover Standard time /mins | F2: Actual Changeover /mins | G2: Changeover Deviation /mins | H2: Total Breakdowns /mins | I2: Total Minor Stops /mins | J2: Availability (for OEE) | K2: Planned Downtime /mins | L2: External Downtime /mins | M2: Availability (for OEE Utilization) | N2: Nominal Speed | O2: Actual (Average) Speed | P2: Performance | Q2: Total Products Produced /Cases | R2: Low Fill /Cases | S2: Embargo /cases | T2: Embargo release date | U2: Embargo Residence time /days | V2: Quality | W2: OEE | X2: OEE Utilization
A3: Stag to Carib Amber | B3: 46055.079 | C3: 46056 | D3: =IF(B3="","",(C3-B3)*24*60) -> 1326 | E3: 10 | F3: 13 | G3: =IF(E3="","",F3-E3) -> 3 | H3: =6+5+5+18+8+13+5+5+5+5 -> 75 | I3: =3+4+1+2+1+3+3+4+3+3+4+2+3+2+2+3+3+2+2+2+3+3+1+2+2+3+4+2+2+2+4+1+2+2+2 -> 87 | J3: =IF(B3="","",(D3-G3-H3-I3)/D3) -> 0.87556561 | K3: 0 | L3: =34+33+23+17+4+5+4+3+16+11 -> 150 | M3: =IF(B3="","",(D3-G3-H3-I3-K3-L3-E3)/D3) -> 0.75490196 | N3: 17000 | O3: =AVERAGE(15000,14000,14000,14000,14000,15000,15000,15000,12000,15000,15000,15000,15000,15000,15000,15000,15000,15000,15000,15000,14000) -> 14619.048 | P3: =IF(B3="","",O3/N3) -> 0.85994398 | Q3: 7920 | R3: 6 | U3: =IF(S3="","",(T3-C3)) | V3: =IF(B3="","",IF(U3<3,(Q3-R3)/Q3,(Q3-R3-S3)/Q3)) -> 0.99924242 | W3: =IF(B3="","",V3*P3*J3) -> 0.75236697 | X3: =IF(B3="","",V3*P3*M3) -> 0.6486816
A4: Carib Amber | B4: 46056.008 | C4: 46057 | D4: =IF(B4="","",(C4-B4)*24*60) -> 1428 | E4: 0 | F4: 0 | G4: =IF(E4="","",F4-E4) -> 0 | H4: =12+5+6+6+5+36+8+11+6+5+10 -> 110 | I4: =3+3+2+3+2+1+1+2+3+3+2+2+1+2+3+3+3+2+4+3+4+1+2+2+4+1+2+3 -> 67 | J4: =IF(B4="","",(D4-G4-H4-I4)/D4) -> 0.87605042 | K4: 0 | L4: =4+4+34+2+2+10+4+5+60+60+47+11 -> 243 | M4: =IF(B4="","",(D4-G4-H4-I4-K4-L4-E4)/D4) -> 0.70588235 | N4: 17000 | O4: =AVERAGE(15000,14000,14000,14000,14000,14000,14000,14000,14000,14500,14500,14500,14500,14500,14500,15000,15000,15000,15000,15000) -> 14450 | P4: =IF(B4="","",O4/N4) -> 0.85 | Q4: 8556 | R4: 7 | U4: =IF(S4="","",(T4-C4)) | V4: =IF(B4="","",IF(U4<3,(Q4-R4)/Q4,(Q4-R4-S4)/Q4)) -> 0.99918186 | W4: =IF(B4="","",V4*P4*J4) -> 0.74403364 | X4: =IF(B4="","",V4*P4*M4) -> 0.59950912
A5: Carib Flint (Export) to Caribe Rose | B5: 46057.012 | C5: 46058 | D5: =IF(B5="","",(C5-B5)*24*60) -> 1422 | E5: 60 | F5: 165 | G5: =IF(E5="","",F5-E5) -> 105 | H5: =14+6+5+8+6+13+8+6+22+25+10+20+5+9+9+10+7+6+38+60+6+8+5+8+14+6+13+7+45+10 -> 409 | I5: =4+4+2+3+3+2+2+2+4+3+2+1+2+1+4+3+3+1+1+2+2+2+2+3+2+3+4+1+4+3+3 -> 78 | J5: =IF(B5="","",(D5-G5-H5-I5)/D5) -> 0.58368495 | K5: 0 | L5: =16+3+5+11+3+10+7+6+4+12 -> 77 | M5: =IF(B5="","",(D5-G5-H5-I5-K5-L5-E5)/D5) -> 0.48734177 | N5: 17000 | O5: =AVERAGE(15000,15000,15000,15000,15000,14500,14500,14500,14500,14500,15000,15000,15000,15000,15000) -> 14833.333 | P5: =IF(B5="","",O5/N5) -> 0.87254902 | Q5: 4372 | R5: 12 | U5: =IF(S5="","",(T5-C5)) | V5: =IF(B5="","",IF(U5<3,(Q5-R5)/Q5,(Q5-R5-S5)/Q5)) -> 0.99725526 | W5: =IF(B5="","",V5*P5*J5) -> 0.50789585 | X5: =IF(B5="","",V5*P5*M5) -> 0.42406244
A6: Caribe Rose to Guinness to Carib Amber | B6: 46058.007 | C6: 46059 | D6: =IF(B6="","",(C6-B6)*24*60) -> 1430 | E6: 60 | F6: 132 | G6: =IF(E6="","",F6-E6) -> 72 | H6: =9+5+37+12+20+6+7+16+22+5+16+10+6+5+8+6+12+8+11+20+5+7 -> 253 | I6: =3+4+3+2+1+3+2+2+22+3+2+4+3+2+2+1+1+1+2+3+3+2+4+1+3+2+2+2 -> 85 | J6: =IF(B6="","",(D6-G6-H6-I6)/D6) -> 0.71328671 | K6: 0 | L6: =4+5+21+4+27+13+7+4+13 -> 98 | M6: =IF(B6="","",(D6-G6-H6-I6-K6-L6-E6)/D6) -> 0.6027972 | N6: 17000 | O6: =AVERAGE(15000,15000,15000,15000,15000,14500,14500,14500,14500,14500,14500,14500,15000,15000,15000,15000,15000) -> 14794.118 | P6: =IF(B6="","",O6/N6) -> 0.87024221 | Q6: 5501 | R6: 22 | U6: =IF(S6="","",(T6-C6)) | V6: =IF(B6="","",IF(U6<3,(Q6-R6)/Q6,(Q6-R6-S6)/Q6)) -> 0.99600073 | W6: =IF(B6="","",V6*P6*J6) -> 0.61824973 | X6: =IF(B6="","",V6*P6*M6) -> 0.52248164
A7: Carib Amber to Shandy Ginger | B7: 46059.007 | C7: 46059.844 | D7: =IF(B7="","",(C7-B7)*24*60) -> 1205 | E7: 20 | F7: 40 | G7: =IF(E7="","",F7-E7) -> 20 | H7: =10+60+27+15+11+10+9+6+5+9+19+17+5+10+8+7+13+11 -> 252 | I7: =1+3+2+2+2+3+1+2+2+3+3+1+1+4+2+2+3+2+3 -> 42 | J7: =IF(B7="","",(D7-G7-H7-I7)/D7) -> 0.73941909 | K7: 15 | L7: 0 | M7: =IF(B7="","",(D7-G7-H7-I7-K7-L7-E7)/D7) -> 0.71037344 | N7: 17000 | O7: =AVERAGE(15000,15000,14500,12000,12000,14500,14500,14500,14500,14500,16000,16000,16000) -> 14538.462 | P7: =IF(B7="","",O7/N7) -> 0.85520362 | Q7: 5998 | R7: 9 | U7: =IF(S7="","",(T7-C7)) | V7: =IF(B7="","",IF(U7<3,(Q7-R7)/Q7,(Q7-R7-S7)/Q7)) -> 0.9984995 | W7: =IF(B7="","",V7*P7*J7) -> 0.63140503 | X7: =IF(B7="","",V7*P7*M7) -> 0.60660237
A8: Shandy Ginger Local to Shandy Ginger Export to Stag | B8: 46062.122 | C8: 46062.886 | D8: =IF(B8="","",(C8-B8)*24*60) -> 1101 | E8: 45 | F8: 50 | G8: =IF(E8="","",F8-E8) -> 5 | H8: =5+18+7+11+7+6+22+9+5+7+5+37+12+6+29+40+5 -> 231 | I8: =4+3+4+2+2+2+3+4+3+3+3+3+3+4+3+4+3+4+2+4+3+2+2+3+1+2+1+1+3+3 -> 84 | J8: =IF(B8="","",(D8-G8-H8-I8)/D8) -> 0.70935513 | K8: 0 | L8: =6+10+9+50+60+5+7+8 -> 155 | M8: =IF(B8="","",(D8-G8-H8-I8-K8-L8-E8)/D8) -> 0.52770209 | N8: 17000 | O8: =AVERAGE( 15000,15000,15000,15000,15000,12000,12000,13000,14000,14000,14000,14000,14000) -> 14000 | P8: =IF(B8="","",O8/N8) -> 0.82352941 | Q8: 4432 | R8: 8 | U8: =IF(S8="","",(T8-C8)) | V8: =IF(B8="","",IF(U8<3,(Q8-R8)/Q8,(Q8-R8-S8)/Q8)) -> 0.99819495 | W8: =IF(B8="","",V8*P8*J8) -> 0.58312035 | X8: =IF(B8="","",V8*P8*M8) -> 0.43379375
A9: Pink Ting to Orginal Ting to Carib Amber | B9: 46063.028 | C9: 46064 | D9: =IF(B9="","",(C9-B9)*24*60) -> 1400 | E9: =30+45 -> 75 | F9: 150 | G9: =IF(E9="","",F9-E9) -> 75 | H9: =5+6+5+7+5+14+10 -> 52 | I9: =3+4+3+4+3+4+3+2+3+2+2+2+2+3+2+3+4+3+2+3+4+3+2 -> 66 | J9: =IF(B9="","",(D9-G9-H9-I9)/D9) -> 0.86214286 | K9: 0 | L9: =2+10+6+45+60+28+4+6+6+6+6+6+4+4+6 -> 199 | M9: =IF(B9="","",(D9-G9-H9-I9-K9-L9-E9)/D9) -> 0.66642857 | N9: 17000 | O9: =AVERAGE(14500,14500,14500,14500,14500,15000,15000,15000,15000) -> 14722.222 | P9: =IF(B9="","",O9/N9) -> 0.86601307 | Q9: 7015 | R9: 9 | U9: =IF(S9="","",(T9-C9)) | V9: =IF(B9="","",IF(U9<3,(Q9-R9)/Q9,(Q9-R9-S9)/Q9)) -> 0.99871703 | W9: =IF(B9="","",V9*P9*J9) -> 0.74566909 | X9: =IF(B9="","",V9*P9*M9) -> 0.57639541
A10: Carib Amber to Stag Local | B10: 46064.003 | C10: 46065 | D10: =IF(B10="","",(C10-B10)*24*60) -> 1435 | E10: 10 | F10: 48 | G10: =IF(E10="","",F10-E10) -> 38 | H10: =12+6+5+5+5+18+60+10+5+7+5+7+9+24+6+5 -> 189 | I10: =2+1+2+3+2+2+4+2+1+3+2+3+2+3+3+4+3+3+3+1+4+2+4+2+2+2+3+3+2+3+3+2+3+3+3+2+4+3+4+3+2+3+3+2+2+2+5 -> 125 | J10: =IF(B10="","",(D10-G10-H10-I10)/D10) -> 0.75470383 | K10: 0 | L10: =5+4+10+6+3+20+4+45+8+27+4 -> 136 | M10: =IF(B10="","",(D10-G10-H10-I10-K10-L10-E10)/D10) -> 0.65296167 | N10: 17000 | O10: =AVERAGE(15000,15000,15000,15000,15000,15000,15000,15000,15000,13000,11000,15000,15000,15000,15000,15000,15000,15000,15000,15000,15000) -> 14714.286 | P10: =IF(B10="","",O10/N10) -> 0.86554622 | Q10: 6898 | R10: 4 | U10: =IF(S10="","",(T10-C10)) | V10: =IF(B10="","",IF(U10<3,(Q10-R10)/Q10,(Q10-R10-S10)/Q10)) -> 0.99942012 | W10: =IF(B10="","",V10*P10*J10) -> 0.65285225 | X10: =IF(B10="","",V10*P10*M10) -> 0.56484078
A11: Stag Local | B11: 46065.007 | C11: 46066 | D11: =IF(B11="","",(C11-B11)*24*60) -> 1430 | E11: 0 | F11: 10 | G11: =IF(E11="","",F11-E11) -> 10 | H11: =7+14+10+10+6+9+5+5+7+7+7+7+13+5+7+5+17+21+20+6+12+5+8+21+10+5+5+8+19+38+18+6+20 -> 363 | I11: =3+3+3+1+4+4+1+3+2+3+3+3+2+3+1+2+3+3+2+2+2+2+2+2+1+2+1+2+2+2+1+1+2+2+2+2+1 -> 80 | J11: =IF(B11="","",(D11-G11-H11-I11)/D11) -> 0.68321678 | K11: 0 | L11: =28+6+5+30+3+4+3+3+4+3+4+9+4 -> 106 | M11: =IF(B11="","",(D11-G11-H11-I11-K11-L11-E11)/D11) -> 0.60909091 | N11: 17000 | O11: =AVERAGE(15000,15000,15000,15000,15000,15000,15000,15000,15000,15000,15000,15000,15000,15000,15000,15000,15000,15000,15000,15000,15000,15000) -> 15000 | P11: =IF(B11="","",O11/N11) -> 0.88235294 | Q11: 6114 | R11: 32 | U11: =IF(S11="","",(T11-C11)) | V11: =IF(B11="","",IF(U11<3,(Q11-R11)/Q11,(Q11-R11-S11)/Q11)) -> 0.99476611 | W11: =IF(B11="","",V11*P11*J11) -> 0.59968315 | X11: =IF(B11="","",V11*P11*M11) -> 0.53462029
A12: Stag Local to Shandy Sorrel | B12: 46066.007 | C12: 46066.836 | D12: =IF(B12="","",(C12-B12)*24*60) -> 1194 | E12: 60 | F12: 60 | G12: =IF(E12="","",F12-E12) -> 0 | H12: =7+5+9+5+6+11+9+6+12+8 -> 78 | I12: =1+4+3+2+3+4+3+2+3+1+4 -> 30 | J12: =IF(B12="","",(D12-G12-H12-I12)/D12) -> 0.90954774 | K12: 0 | L12: 675 | M12: =IF(B12="","",(D12-G12-H12-I12-K12-L12-E12)/D12) -> 0.29396985 | N12: 17000 | O12: =AVERAGE(15000, 15000,15000,11000,15000,15000,15000,15000) -> 14500 | P12: =IF(B12="","",O12/N12) -> 0.85294118 | Q12: 2856 | R12: 8 | U12: =IF(S12="","",(T12-C12)) | V12: =IF(B12="","",IF(U12<3,(Q12-R12)/Q12,(Q12-R12-S12)/Q12)) -> 0.99719888 | W12: =IF(B12="","",V12*P12*J12) -> 0.77361764 | X12: =IF(B12="","",V12*P12*M12) -> 0.25003664
A13: Carib Amber | B13: 46069.49 | C13: 46070 | D13: =IF(B13="","",(C13-B13)*24*60) -> 735 | E13: 0 | F13: 0 | G13: =IF(E13="","",F13-E13) -> 0 | H13: =15+6+5+11+6+7+7 -> 57 | I13: =3+3+3+2+4+4+2+2+1+3+2+2+4+4+1+4+2+2+4+3+4+3+1+1+3+4+2 -> 73 | J13: =IF(B13="","",(D13-G13-H13-I13)/D13) -> 0.82312925 | K13: 0 | L13: =2+12+6 -> 20 | M13: =IF(B13="","",(D13-G13-H13-I13-K13-L13-E13)/D13) -> 0.79591837 | N13: 17000 | O13: =AVERAGE(15000,15000,15000,15000,15000,15000,15000,17000,15000,15000,15000,15000) -> 15166.667 | P13: =IF(B13="","",O13/N13) -> 0.89215686 | Q13: 4596 | R13: 10 | S13: =177+43 -> 220 | T13: 46065 | U13: =IF(S13="","",(T13-C13)) -> -5 | V13: =IF(B13="","",IF(U13<3,(Q13-R13)/Q13,(Q13-R13-S13)/Q13)) -> 0.99782419 | W13: =IF(B13="","",V13*P13*J13) -> 0.73276259 | X13: =IF(B13="","",V13*P13*M13) -> 0.70853903
A14: Carib Amber | B14: 46070.012 | C14: 46070.4 | D14: =IF(B14="","",(C14-B14)*24*60) -> 559 | E14: 0 | F14: 0 | G14: =IF(E14="","",F14-E14) -> 0 | H14: =13+9+7+6+10+9+5+5+10+5 -> 79 | I14: =4+1+1+2+2+2+2+1+1+4+2+3+3+3+3+2+1 -> 37 | J14: =IF(B14="","",(D14-G14-H14-I14)/D14) -> 0.79248658 | K14: 0 | L14: =31 -> 31 | M14: =IF(B14="","",(D14-G14-H14-I14-K14-L14-E14)/D14) -> 0.73703041 | N14: 17000 | O14: =AVERAGE(15000,15000,15000,15000,15000,15000,15000,15000,15000,15000) -> 15000 | P14: =IF(B14="","",O14/N14) -> 0.88235294 | Q14: 2895 | R14: 13 | U14: =IF(S14="","",(T14-C14)) | V14: =IF(B14="","",IF(U14<3,(Q14-R14)/Q14,(Q14-R14-S14)/Q14)) -> 0.9955095 | W14: =IF(B14="","",V14*P14*J14) -> 0.69611287 | X14: =IF(B14="","",V14*P14*M14) -> 0.64740068
A15: Carib Amber to Shandy Sorrel to Ting Original | B15: 46072.083 | C15: 46073 | D15: =IF(B15="","",(C15-B15)*24*60) -> 1320 | E15: =60+60 -> 120 | F15: 103 | G15: =IF(E15="","",F15-E15) -> -17 | H15: =7+8+28+7+5+5+6+5+6+6+15+8+10+60+40+7+6+5+16+24+5+11+13+9+7+6+60 -> 385 | I15: =2+2+4+2+2+4+3+4+4+2+3+1+2+3+1+3+4+4+4+4+1+3+3+3+1 -> 69 | J15: =IF(B15="","",(D15-G15-H15-I15)/D15) -> 0.66893939 | K15: 0 | L15: =4+9+15+8+6+10 -> 52 | M15: =IF(B15="","",(D15-G15-H15-I15-K15-L15-E15)/D15) -> 0.53863636 | N15: 17000 | O15: =AVERAGE(12000,15000,15000,15000,15000,15000,15000,15000,15000,14000,15000,12000,12000) -> 14230.769 | P15: =IF(B15="","",O15/N15) -> 0.83710407 | Q15: 4680 | R15: 10 | S15: 350 | T15: 46073.392 | U15: =IF(S15="","",(T15-C15)) -> 0.39236111 | V15: =IF(B15="","",IF(U15<3,(Q15-R15)/Q15,(Q15-R15-S15)/Q15)) -> 0.99786325 | W15: =IF(B15="","",V15*P15*J15) -> 0.55877537 | X15: =IF(B15="","",V15*P15*M15) -> 0.44993124
A16: Ting Original to Carib Amber | B16: 46073.006 | C16: 46073.837 | D16: =IF(B16="","",(C16-B16)*24*60) -> 1196 | E16: 60 | F16: 79 | G16: =IF(E16="","",F16-E16) -> 19 | H16: =9+5+6+54+6+9+5+9+7+29+22+5+6+5+10+5+30+30+37+7+11+6+17 -> 330 | I16: =3+4+3+3+2+2+4+4+4+2+2+2+4+4+2+3+4+2+3+3+4+1+4+3+3+3+2+4+1+1+2 -> 88 | J16: =IF(B16="","",(D16-G16-H16-I16)/D16) -> 0.63461538 | K16: 0 | L16: =9+6+6+10+2+27+15 -> 75 | M16: =IF(B16="","",(D16-G16-H16-I16-K16-L16-E16)/D16) -> 0.52173913 | N16: 17000 | O16: =AVERAGE(14000,14000,14000,14000,14000,14000,14000,14000,15000,15000,14500,14500,13500,7500,13000,15000) -> 13750 | P16: =IF(B16="","",O16/N16) -> 0.80882353 | Q16: 3788 | R16: 6 | U16: =IF(S16="","",(T16-C16)) | V16: =IF(B16="","",IF(U16<3,(Q16-R16)/Q16,(Q16-R16-S16)/Q16)) -> 0.99841605 | W16: =IF(B16="","",V16*P16*J16) -> 0.51247883 | X16: =IF(B16="","",V16*P16*M16) -> 0.42132647
A17: Carib Amber | B17: 46076.442 | C17: 46077 | D17: =IF(B17="","",(C17-B17)*24*60) -> 803 | E17: 25 | F17: 0 | G17: =IF(E17="","",F17-E17) -> -25 | H17: =14+10+20+9+7+6+5+30+16+12+6+5+22+6+6+8+5+5+5+7+5+8+10 -> 227 | I17: =4+3+4+2+4+3+2+3+1+2+2+4+3+3+3+2+4+3+4+3+2+2+1+3+2+3 -> 72 | J17: =IF(B17="","",(D17-G17-H17-I17)/D17) -> 0.65877958 | K17: 0 | L17: =23+10+4 -> 37 | M17: =IF(B17="","",(D17-G17-H17-I17-K17-L17-E17)/D17) -> 0.58156912 | N17: 17000 | O17: =AVERAGE(15000,15000,15000,15000,15000,14000,14000,15000,15000,15000,15000,15000,15000,15000) -> 14857.143 | P17: =IF(B17="","",O17/N17) -> 0.87394958 | Q17: 3491 | R17: 4 | S17: 70 | T17: 46078 | U17: =IF(S17="","",(T17-C17)) -> 1 | V17: =IF(B17="","",IF(U17<3,(Q17-R17)/Q17,(Q17-R17-S17)/Q17)) -> 0.9988542 | W17: =IF(B17="","",V17*P17*J17) -> 0.57508045 | X17: =IF(B17="","",V17*P17*M17) -> 0.50767972
A18: Carib Amber to Guinness | B18: 46077.008 | C18: 46077.962 | D18: =IF(B18="","",(C18-B18)*24*60) -> 1373 | E18: 25 | F18: 31 | G18: =IF(E18="","",F18-E18) -> 6 | H18: =5+10+10+6+57+60+60+60+43+5+26+16+42+30+7+6+5+6 -> 454 | I18: =4+3+1+3+1+1+2+4+3+3+3+3+4+1+2+3+4+2+3+4+3+3+2+3+3+4+2+4+2+3+3+4+4+3+1+4+4+4+4+3+3+4+2+3+3 -> 132 | J18: =IF(B18="","",(D18-G18-H18-I18)/D18) -> 0.56882739 | K18: 0 | L18: =7+4+2+4+6+6 -> 29 | M18: =IF(B18="","",(D18-G18-H18-I18-K18-L18-E18)/D18) -> 0.52949745 | N18: 17000 | O18: =AVERAGE(15000,15000,15000,15000,15000,15000,15000,15000,15000,15000,15000,15000,15000,15000,16500,14000,13000,14500) -> 14888.889 | P18: =IF(B18="","",O18/N18) -> 0.87581699 | Q18: 5142 | R18: 15 | S18: =140+4+210 -> 354 | T18: 46097.524 | U18: =IF(S18="","",(T18-C18)) -> 19.5625 | V18: =IF(B18="","",IF(U18<3,(Q18-R18)/Q18,(Q18-R18-S18)/Q18)) -> 0.92823804 | W18: =IF(B18="","",V18*P18*J18) -> 0.46243769 | X18: =IF(B18="","",V18*P18*M18) -> 0.43046377
A19: Stag | B19: 46078.017 | C19: 46079 | D19: =IF(B19="","",(C19-B19)*24*60) -> 1415 | E19: 0 | F19: 0 | G19: =IF(E19="","",F19-E19) -> 0 | H19: =13+5+38+10+8+60+25+16+12+9+8+5+6+9+8+10+5+6+7+8+60+60+60+60+47+7+6+5+10+11+6+7+5+25+10+10+19 -> 676 | I19: =2+2+3+2+2+3+2+2+4+3+3+2+3+3+4+2+4+2+2+2+4+2+3+1+2+4+2+3+4+3+4+4+2+2+1+3 -> 96 | J19: =IF(B19="","",(D19-G19-H19-I19)/D19) -> 0.45441696 | K19: 0 | L19: 0 | M19: =IF(B19="","",(D19-G19-H19-I19-K19-L19-E19)/D19) -> 0.45441696 | N19: 17000 | O19: =AVERAGE(16000,16000,16000,16000,15000,14500,15000,15000,15000,15000,15000,15000,15000,15000,15000) -> 15233.333 | P19: =IF(B19="","",O19/N19) -> 0.89607843 | Q19: 4008 | R19: 12 | S19: 140 | T19: 46083.674 | U19: =IF(S19="","",(T19-C19)) -> 4.6736111 | V19: =IF(B19="","",IF(U19<3,(Q19-R19)/Q19,(Q19-R19-S19)/Q19)) -> 0.96207585 | W19: =IF(B19="","",V19*P19*J19) -> 0.39175078 | X19: =IF(B19="","",V19*P19*M19) -> 0.39175078
A20: Stag to Carib Amber | B20: 46079.01 | C20: 46080 | D20: =IF(B20="","",(C20-B20)*24*60) -> 1426 | E20: 10 | F20: 23 | G20: =IF(E20="","",F20-E20) -> 13 | H20: =44+60+60+60+60+60+47+5+60+60+60+60+60+5+6+6+16+12+11+5+7+5+7+6+40+10+10 -> 842 | I20: =2+2+3+4+1+1+4+4+3+3+3+2+4+4+1+3+4+4+1+3+2 -> 58 | J20: =IF(B20="","",(D20-G20-H20-I20)/D20) -> 0.35974755 | K20: 0 | L20: =3 -> 3 | M20: =IF(B20="","",(D20-G20-H20-I20-K20-L20-E20)/D20) -> 0.35063114 | N20: 17000 | O20: =AVERAGE(15000,15000,15000,15000,15000,15000,15000,15000,14000,15000) -> 14900 | P20: =IF(B20="","",O20/N20) -> 0.87647059 | Q20: 3264 | R20: 7 | U20: =IF(S20="","",(T20-C20)) | V20: =IF(B20="","",IF(U20<3,(Q20-R20)/Q20,(Q20-R20-S20)/Q20)) -> 0.99785539 | W20: =IF(B20="","",V20*P20*J20) -> 0.31463193 | X20: =IF(B20="","",V20*P20*M20) -> 0.3066588
A21: Carib Amber to Starmalt to Carib Amber | B21: 46080.007 | C21: 46080.84 | D21: =IF(B21="","",(C21-B21)*24*60) -> 1200 | E21: =30+45 -> 75 | F21: 73 | G21: =IF(E21="","",F21-E21) -> -2 | H21: =6 -> 6 | I21: =1+3+2+2 -> 8 | J21: =IF(B21="","",(D21-G21-H21-I21)/D21) -> 0.99 | L21: =9 -> 9 | M21: =IF(B21="","",(D21-G21-H21-I21-K21-L21-E21)/D21) -> 0.92 | N21: 17000 | O21: =AVERAGE(15000,15000,15000,15000,15000,15000,15000,15000,15000,15000,14800,14800,14800,14800,14800,14800) -> 14925 | P21: =IF(B21="","",O21/N21) -> 0.87794118 | Q21: 6071 | R21: 7 | S21: 490 | T21: 46086 | U21: =IF(S21="","",(T21-C21)) -> 5.1597222 | V21: =IF(B21="","",IF(U21<3,(Q21-R21)/Q21,(Q21-R21-S21)/Q21)) -> 0.9181354 | W21: =IF(B21="","",V21*P21*J21) -> 0.79800818 | X21: =IF(B21="","",V21*P21*M21) -> 0.74158336
A22: Starmalt to Carib Amber | B22: 46081.344 | C22: 46081.942 | D22: =IF(B22="","",(C22-B22)*24*60) -> 861 | E22: 45 | F22: 50 | G22: =IF(E22="","",F22-E22) -> 5 | H22: =5+29+6+20+6+5+5+6+5+5+5+5+7+7+8+7+6+30+12+7+8+8+6+8+7+5+6+15+6+6+7+5+5+6 -> 284 | I22: =3+4+2+4+4+3+3+2+1+1+3+3+1+3+2+4+2+4+4+4+4+4+3+3+3+2+4+2+4+3+4+2+2+4+4+2+2+3+1+4+2+3+3+3+3+2+4+3+3+2+4+1+1+3+1+2+1+2+2+1+2+2+2+3+4+3+4+2+2+2 -> 189 | J22: =IF(B22="","",(D22-G22-H22-I22)/D22) -> 0.44483159 | K22: 0 | L22: =7+5 -> 12 | M22: =IF(B22="","",(D22-G22-H22-I22-K22-L22-E22)/D22) -> 0.3786295 | N22: 17000 | O22: =AVERAGE(15000,15000,15000,15000,15000,15000,15000,14500,15000,15000,15000,15000,15000,15000) -> 14964.286 | P22: =IF(B22="","",O22/N22) -> 0.8802521 | Q22: 3938 | R22: 2 | U22: =IF(S22="","",(T22-C22)) | V22: =IF(B22="","",IF(U22<3,(Q22-R22)/Q22,(Q22-R22-S22)/Q22)) -> 0.99949213 | W22: =IF(B22="","",V22*P22*J22) -> 0.39136508 | X22: =IF(B22="","",V22*P22*M22) -> 0.33312014
D23: =IF(B23="","",(C23-B23)*24*60) | G23: =IF(E23="","",F23-E23) | J23: =IF(B23="","",(D23-G23-H23-I23)/D23) | M23: =IF(B23="","",(D23-G23-H23-I23-K23-L23-E23)/D23) | P23: =IF(B23="","",O23/N23) | U23: =IF(S23="","",(T23-C23)) | V23: =IF(B23="","",IF(U23<3,(Q23-R23)/Q23,(Q23-R23-S23)/Q23)) | W23: =IF(B23="","",V23*P23*J23) | X23: =IF(B23="","",V23*P23*M23)
D24: =IF(B24="","",(C24-B24)*24*60) | G24: =IF(E24="","",F24-E24) | J24: =IF(B24="","",(D24-G24-H24-I24)/D24) | M24: =IF(B24="","",(D24-G24-H24-I24-K24-L24-E24)/D24) | P24: =IF(B24="","",O24/N24) | U24: =IF(S24="","",(T24-C24)) | V24: =IF(B24="","",IF(U24<3,(Q24-R24)/Q24,(Q24-R24-S24)/Q24)) | W24: =IF(B24="","",V24*P24*J24) | X24: =IF(B24="","",V24*P24*M24)
D25: =IF(B25="","",(C25-B25)*24*60) | G25: =IF(E25="","",F25-E25) | J25: =IF(B25="","",(D25-G25-H25-I25)/D25) | M25: =IF(B25="","",(D25-G25-H25-I25-K25-L25-E25)/D25) | P25: =IF(B25="","",O25/N25) | U25: =IF(S25="","",(T25-C25)) | V25: =IF(B25="","",IF(U25<3,(Q25-R25)/Q25,(Q25-R25-S25)/Q25)) | W25: =IF(B25="","",V25*P25*J25) | X25: =IF(B25="","",V25*P25*M25)
D26: =IF(B26="","",(C26-B26)*24*60) | G26: =IF(E26="","",F26-E26) | J26: =IF(B26="","",(D26-G26-H26-I26)/D26) | M26: =IF(B26="","",(D26-G26-H26-I26-K26-L26-E26)/D26) | P26: =IF(B26="","",O26/N26) | U26: =IF(S26="","",(T26-C26)) | V26: =IF(B26="","",IF(U26<3,(Q26-R26)/Q26,(Q26-R26-S26)/Q26)) | W26: =IF(B26="","",V26*P26*J26) | X26: =IF(B26="","",V26*P26*M26)
D27: =IF(B27="","",(C27-B27)*24*60) | G27: =IF(E27="","",F27-E27) | J27: =IF(B27="","",(D27-G27-H27-I27)/D27) | M27: =IF(B27="","",(D27-G27-H27-I27-K27-L27-E27)/D27) | P27: =IF(B27="","",O27/N27) | U27: =IF(S27="","",(T27-C27)) | V27: =IF(B27="","",IF(U27<3,(Q27-R27)/Q27,(Q27-R27-S27)/Q27)) | W27: =IF(B27="","",V27*P27*J27) | X27: =IF(B27="","",V27*P27*M27)
D28: =IF(B28="","",(C28-B28)*24*60) | G28: =IF(E28="","",F28-E28) | J28: =IF(B28="","",(D28-G28-H28-I28)/D28) | M28: =IF(B28="","",(D28-G28-H28-I28-K28-L28-E28)/D28) | P28: =IF(B28="","",O28/N28) | U28: =IF(S28="","",(T28-C28)) | V28: =IF(B28="","",IF(U28<3,(Q28-R28)/Q28,(Q28-R28-S28)/Q28)) | W28: =IF(B28="","",V28*P28*J28) | X28: =IF(B28="","",V28*P28*M28)
D29: =IF(B29="","",(C29-B29)*24*60) | G29: =IF(E29="","",F29-E29) | J29: =IF(B29="","",(D29-G29-H29-I29)/D29) | M29: =IF(B29="","",(D29-G29-H29-I29-K29-L29-E29)/D29) | P29: =IF(B29="","",O29/N29) | U29: =IF(S29="","",(T29-C29)) | V29: =IF(B29="","",IF(U29<3,(Q29-R29)/Q29,(Q29-R29-S29)/Q29)) | W29: =IF(B29="","",V29*P29*J29) | X29: =IF(B29="","",V29*P29*M29)
D30: =IF(B30="","",(C30-B30)*24*60) | G30: =IF(E30="","",F30-E30) | J30: =IF(B30="","",(D30-G30-H30-I30)/D30) | M30: =IF(B30="","",(D30-G30-H30-I30-K30-L30-E30)/D30) | P30: =IF(B30="","",O30/N30) | U30: =IF(S30="","",(T30-C30)) | V30: =IF(B30="","",IF(U30<3,(Q30-R30)/Q30,(Q30-R30-S30)/Q30)) | W30: =IF(B30="","",V30*P30*J30) | X30: =IF(B30="","",V30*P30*M30)
D31: =IF(B31="","",(C31-B31)*24*60) | G31: =IF(E31="","",F31-E31) | J31: =IF(B31="","",(D31-G31-H31-I31)/D31) | M31: =IF(B31="","",(D31-G31-H31-I31-K31-L31-E31)/D31) | P31: =IF(B31="","",O31/N31) | U31: =IF(S31="","",(T31-C31)) | V31: =IF(B31="","",IF(U31<3,(Q31-R31)/Q31,(Q31-R31-S31)/Q31)) | W31: =IF(B31="","",V31*P31*J31) | X31: =IF(B31="","",V31*P31*M31)
D32: =IF(B32="","",(C32-B32)*24*60) | G32: =IF(E32="","",F32-E32) | J32: =IF(B32="","",(D32-G32-H32-I32)/D32) | M32: =IF(B32="","",(D32-G32-H32-I32-K32-L32-E32)/D32) | P32: =IF(B32="","",O32/N32) | U32: =IF(S32="","",(T32-C32)) | V32: =IF(B32="","",IF(U32<3,(Q32-R32)/Q32,(Q32-R32-S32)/Q32)) | W32: =IF(B32="","",V32*P32*J32) | X32: =IF(B32="","",V32*P32*M32)
D33: =IF(B33="","",(C33-B33)*24*60) | G33: =IF(E33="","",F33-E33) | J33: =IF(B33="","",(D33-G33-H33-I33)/D33) | M33: =IF(B33="","",(D33-G33-H33-I33-K33-L33-E33)/D33) | P33: =IF(B33="","",O33/N33) | U33: =IF(S33="","",(T33-C33)) | V33: =IF(B33="","",IF(U33<3,(Q33-R33)/Q33,(Q33-R33-S33)/Q33)) | W33: =IF(B33="","",V33*P33*J33) | X33: =IF(B33="","",V33*P33*M33)
D34: =IF(B34="","",(C34-B34)*24*60) | G34: =IF(E34="","",F34-E34) | J34: =IF(B34="","",(D34-G34-H34-I34)/D34) | M34: =IF(B34="","",(D34-G34-H34-I34-K34-L34-E34)/D34) | P34: =IF(B34="","",O34/N34) | U34: =IF(S34="","",(T34-C34)) | V34: =IF(B34="","",IF(U34<3,(Q34-R34)/Q34,(Q34-R34-S34)/Q34)) | W34: =IF(B34="","",V34*P34*J34) | X34: =IF(B34="","",V34*P34*M34)
... D36: =IF(B36="","",(C36-B36)*24*60) | G36: =IF(E36="","",F36-E36) | J36: =IF(B36="","",(D36-G36-H36-I36)/D36) | M36: =IF(B36="","",(D36-G36-H36-I36-K36-L36-E36)/D36) | P36: =IF(B36="","",O36/N36) | U36: =IF(S36="","",(T36-C36)) | V36: =IF(B36="","",IF(U36<3,(Q36-R36)/Q36,(Q36-R36-S36)/Q36)) | W36: =IF(B36="","",V36*P36*J36) | X36: =IF(B36="","",V36*P36*M36)
D37: =IF(B37="","",(C37-B37)*24*60) | G37: =IF(E37="","",F37-E37) | J37: =IF(B37="","",(D37-G37-H37-I37)/D37) | M37: =IF(B37="","",(D37-G37-H37-I37-K37-L37-E37)/D37) | P37: =IF(B37="","",O37/N37) | V37: =IF(B37="","",IF(U37<3,(Q37-R37)/Q37,(Q37-R37-S37)/Q37)) | W37: =IF(B37="","",V37*P37*J37) | X37: =IF(B37="","",V37*P37*M37)
B38: Total | D38: =SUM(D3:D37) -> 24259 | E38: =SUM(E3:E37) -> 700 | F38: =SUM(F3:F37) -> 1027 | G38: =SUM(G3:G37) -> 327 | H38: =SUM(H2:H37) -> 5352 | I38: =SUM(I3:I37) -> 1566 | J38: =(D38-G38-H38-I38)/D38 -> 0.70134795 | K38: =SUM(K3:K37) -> 15 | L38: =SUM(L3:L37) -> 2107 | M38: =(D38-G38-H38-I38-E38-K38-L38)/D38 -> 0.58501999 | N38: =AVERAGE(N3:N37) -> 17000 | O38: =AVERAGE(O3:O37) -> 14704.378 | P38: =O38/N38 -> 0.8649634 | Q38: =SUM(Q3:Q35) -> 101535 | V38: =AVERAGE(V3:V37) -> 0.98863704 | W38: 0.605 | X38: =V38*P38*M38 -> 0.50027099
D46: Real | E46: Opportunity
C47: OEE | D47: =W38 -> 0.605 | E47: =100%-D47 -> 0.395
C48: OEE Utilization | D48: =X38 -> 0.50027099 | E48: =100%-D48 -> 0.49972901
...

Sheet March 2026 (w Utilization
C1: OEE Calculation | G1: CARIB BREWERY
A2: SKU | B2: Start Time dd/mm/yyyy h:mm | C2: End Time dd/mm/yyyy h:mm (when production actually ends) | D2: Available time /mins | E2: Changeover Standard time /mins | F2: Actual Changeover /mins | G2: Changeover Deviation /mins | H2: Total Breakdowns /mins | I2: Total Minor Stops /mins | J2: Availability (for OEE) | K2: Planned Downtime /mins | L2: External Downtime /mins | M2: Availability (for OEE Utilization) | N2: Nominal Speed | O2: Actual (Average) Speed | P2: Performance | Q2: Total Products Produced /Cases | R2: Low Fill /Cases | S2: Embargo /cases | T2: Embargo release date | U2: Embargo Residence time /days | V2: Quality | W2: OEE | X2: OEE Utilization
A3: Carib Amber to Stag | B3: 46083.053 | C3: 46084 | D3: =IF(B3="","",(C3-B3)*24*60) -> 1364 | E3: 10 | F3: 9 | G3: =IF(E3="","",F3-E3) -> -1 | H3: =7+14+8+6+7+15+7+37+11+21+13+10+26+9+14+5+5+8+8+6 -> 237 | I3: =4+2+2+4+2+2+3+1+2+2+3+3+4+3+4+2+4+2+4+3+3+1+3+2+3+4+4+3+4+3+4+4+2+2+4+2+3+3+4+2+2+4+3+4+2+3+4+4+2+1+2 -> 147 | J3: =IF(B3="","",(D3-G3-H3-I3)/D3) -> 0.71920821 | K3: 0 | L3: =5+7 -> 12 | M3: =IF(B3="","",(D3-G3-H3-I3-K3-L3-E3)/D3) -> 0.70307918 | N3: 17000 | O3: =AVERAGE(14000,14000,14000,14500,15000,14000,14000,14000,14000,15000,14000,14000,14000,14000,14000,14000,15000,15000,15000,15000,15000) -> 14357.143 | P3: =IF(B3="","",O3/N3) -> 0.84453782 | Q3: 6587 | R3: 9 | U3: =IF(S3="","",(T3-C3)) | V3: =IF(B3="","",IF(U3<3,(Q3-R3)/Q3,(Q3-R3-S3)/Q3)) -> 0.99863367 | W3: =IF(B3="","",V3*P3*J3) -> 0.60656863 | X3: =IF(B3="","",V3*P3*M3) -> 0.59296566
A4: Stag | B4: 46084.003 | C4: 46085 | D4: =IF(B4="","",(C4-B4)*24*60) -> 1435 | E4: 0 | F4: 0 | G4: =IF(E4="","",F4-E4) -> 0 | H4: =15+12+6+5+5+10+5+11+5+14+12+15+23+60+18+11+7+14+7+8+6+18 -> 287 | I4: =2+2+2+3+4+2+3+3+3+1+2+2+2+2+4+2+4+2+2+4+4+2+4+3+3+2+2+1+3+2+3+4+3+3+4+3+3+4+2+1+4+2+2+2+3+4+1+3+2+1+1+2+4+2+3+4+3+4 -> 154 | J4: =IF(B4="","",(D4-G4-H4-I4)/D4) -> 0.69268293 | K4: 0 | L4: =4+3+2+6+24+7+14 -> 60 | M4: =IF(B4="","",(D4-G4-H4-I4-K4-L4-E4)/D4) -> 0.65087108 | N4: 17000 | O4: =AVERAGE(15000,1480,14800,14800,14800,14800) -> 12613.333 | P4: =IF(B4="","",O4/N4) -> 0.74196078 | Q4: 6137 | R4: 15 | U4: =IF(S4="","",(T4-C4)) | V4: =IF(B4="","",IF(U4<3,(Q4-R4)/Q4,(Q4-R4-S4)/Q4)) -> 0.99755581 | W4: =IF(B4="","",V4*P4*J4) -> 0.51268739 | X4: =IF(B4="","",V4*P4*M4) -> 0.48174047
A5: Stag to Carib Amber | B5: 46085.014 | C5: 46086 | D5: =IF(B5="","",(C5-B5)*24*60) -> 1420 | E5: 10 | F5: 9 | G5: =IF(E5="","",F5-E5) -> -1 | H5: =20+23+5+5+5+6+5+15+7+8+10+14+45+5+9+9+60+6+6+6+10 -> 279 | I5: =2+2+2+2+4+3+2+4+2+4+1+2+4+2+1+2+2+2+2+1+3+2+2+2+3+1+3+3+2+4+2+2+4+4+2+3+2+2+2+1+3+4+1+2+2+4+4 -> 115 | J5: =IF(B5="","",(D5-G5-H5-I5)/D5) -> 0.72323944 | K5: 0 | L5: =6+4+4+10+2+5+45+15 -> 91 | M5: =IF(B5="","",(D5-G5-H5-I5-K5-L5-E5)/D5) -> 0.65211268 | N5: 17000 | O5: =AVERAGE(13000,14500,15000,15000,14000,14000,14000,14000,14000,13500,14000,13500,14000,14000,14000,14000,14000) -> 14029.412 | P5: =IF(B5="","",O5/N5) -> 0.82525952 | Q5: 6354 | R5: 4 | S5: 140 | U5: =IF(S5="","",(T5-C5)) -> -46086 | V5: =IF(B5="","",IF(U5<3,(Q5-R5)/Q5,(Q5-R5-S5)/Q5)) -> 0.99937048 | W5: =IF(B5="","",V5*P5*J5) -> 0.59648449 | X5: =IF(B5="","",V5*P5*M5) -> 0.5378234
A6: Carib Amber to Vitamalt Classic | B6: 46086.003 | C6: 46087 | D6: =IF(B6="","",(C6-B6)*24*60) -> 1435 | E6: 100 | F6: 81 | G6: =IF(E6="","",F6-E6) -> -19 | H6: =5+40+47+60+60+27+30+52+5+5+6+10+8+17+6+6+9+6+5+5+5+6+5+8+26+5+6+5+43 -> 518 | I6: =2+2+4+2+4+3+3+3+4+2+4+1+2+3+3+4+3+3+2+3+2+1+1+4+4+3+3+2+3+4+4+3+3 -> 94 | J6: =IF(B6="","",(D6-G6-H6-I6)/D6) -> 0.58675958 | K6: 0 | L6: =3+10+2+3+3 -> 21 | M6: =IF(B6="","",(D6-G6-H6-I6-K6-L6-E6)/D6) -> 0.50243902 | N6: 17000 | O6: =AVERAGE(13500,13500,15000,15000,15000,13000,13000,13000,14000,14000,14000,14000,14000,14000,14000,14000,14000) -> 13941.176 | P6: =IF(B6="","",O6/N6) -> 0.8200692 | Q6: 3969 | R6: 17 | U6: =IF(S6="","",(T6-C6)) | V6: =IF(B6="","",IF(U6<3,(Q6-R6)/Q6,(Q6-R6-S6)/Q6)) -> 0.99571681 | W6: =IF(B6="","",V6*P6*J6) -> 0.47912246 | X6: =IF(B6="","",V6*P6*M6) -> 0.41026995
A7: Vitamalt Classic to Vitamalt Ginger to Guinness | B7: 46087 | C7: 46087.824 | D7: =IF(B7="","",(C7-B7)*24*60) -> 1187 | E7: =10+100 -> 110 | F7: 129 | G7: =IF(E7="","",F7-E7) -> 19 | H7: =45+60+37+5+6+5+6+5+12+6+15+20 -> 222 | I7: =2+4+2+4+2+2+4+3+2+4+1+3+2+1+2+1+2+3+4+2+1+3+2+2+3+3+2+3+3+4+4+3+3+3+2+2+4+3 -> 100 | J7: =IF(B7="","",(D7-G7-H7-I7)/D7) -> 0.71272115 | K7: 0 | L7: =7 -> 7 | M7: =IF(B7="","",(D7-G7-H7-I7-K7-L7-E7)/D7) -> 0.61415333 | N7: 17000 | O7: =AVERAGE(13000,14000,14000,14000,13000,13000,13000,12500,13500,13500,13500) -> 13363.636 | P7: =IF(B7="","",O7/N7) -> 0.78609626 | Q7: 4509 | R7: 6 | U7: =IF(S7="","",(T7-C7)) | V7: =IF(B7="","",IF(U7<3,(Q7-R7)/Q7,(Q7-R7-S7)/Q7)) -> 0.99866933 | W7: =IF(B7="","",V7*P7*J7) -> 0.55952189 | X7: =IF(B7="","",V7*P7*M7) -> 0.48214121
A8: Carib Amber | B8: 46089.444 | C8: 46090 | D8: =IF(B8="","",(C8-B8)*24*60) -> 800 | E8: 0 | F8: 0 | G8: =IF(E8="","",F8-E8) -> 0 | H8: =5+5+12+38+9+5+6+13+6+10+6+6+23+5+5+6 -> 160 | I8: =4+3+4+3+3+1+3+4+2+4+3+2+3+1+2+2+3+2+3+3+1+2+2+3+4+2+1+2+2+3 -> 77 | J8: =IF(B8="","",(D8-G8-H8-I8)/D8) -> 0.70375 | K8: 0 | L8: =4+3 -> 7 | M8: =IF(B8="","",(D8-G8-H8-I8-K8-L8-E8)/D8) -> 0.695 | N8: 17000 | O8: =AVERAGE(13000,14000,14000,14000,13000,13000,13000,12500,13500,13500,13500) -> 13363.636 | P8: =IF(B8="","",O8/N8) -> 0.78609626 | Q8: 3630 | R8: 8 | U8: =IF(S8="","",(T8-C8)) | V8: =IF(B8="","",IF(U8<3,(Q8-R8)/Q8,(Q8-R8-S8)/Q8)) -> 0.99779614 | W8: =IF(B8="","",V8*P8*J8) -> 0.55199603 | X8: =IF(B8="","",V8*P8*M8) -> 0.54513285
A9: Carib Amber | B9: 46090.008 | C9: 46091 | D9: =IF(B9="","",(C9-B9)*24*60) -> 1429 | E9: 0 | F9: 0 | G9: =IF(E9="","",F9-E9) -> 0 | H9: =20+8+8+5+5+5+10+6+5+6+5+5+24+30+5 -> 147 | I9: =4+2+1+3+4+1+2+2+2+1+3+2+1+2+1+3+4+4+3+3+3+2+3+1+3+1+2+2+3+1+3+4+3+3+3+2+2+2+1+3+1+1 -> 97 | J9: =IF(B9="","",(D9-G9-H9-I9)/D9) -> 0.82925122 | K9: 0 | L9: =31+60+60+10+60+60+27+60+30+30 -> 428 | M9: =IF(B9="","",(D9-G9-H9-I9-K9-L9-E9)/D9) -> 0.52974108 | N9: 17000 | O9: =AVERAGE(14000,14500,14500,14500,14500,14500,15000,15000) -> 14562.5 | P9: =IF(B9="","",O9/N9) -> 0.85661765 | Q9: 5423 | R9: 5 | U9: =IF(S9="","",(T9-C9)) | V9: =IF(B9="","",IF(U9<3,(Q9-R9)/Q9,(Q9-R9-S9)/Q9)) -> 0.999078 | W9: =IF(B9="","",V9*P9*J9) -> 0.70969629 | X9: =IF(B9="","",V9*P9*M9) -> 0.45336717
A10: Carib Amber to Caribe Pearsecco | B10: 46091.008 | C10: 46092 | D10: =IF(B10="","",(C10-B10)*24*60) -> 1429 | E10: 60 | F10: 80 | G10: =IF(E10="","",F10-E10) -> 20 | H10: =12+40+5+6+5+6+7+5+7+5+6+12+5+31+9+5+5+22 -> 193 | I10: =2+1+3+3+3+3+3+4+3+4+3+2+3+3+4+2+2+3+1+2+1+3+2+2+3+2+2+4+1+4+2+3+1+1+3+3+4+4+2+1+2 -> 104 | J10: =IF(B10="","",(D10-G10-H10-I10)/D10) -> 0.77816655 | K10: 10 | L10: =3+4+4+4+6+3+3+4+4+6+3+34+2+2+2 -> 84 | M10: =IF(B10="","",(D10-G10-H10-I10-K10-L10-E10)/D10) -> 0.67039888 | N10: 17000 | O10: =AVERAGE(14000,14500,16400,15000,15000,15000,15000,15000,15000,15000,14000,14000,14000,14000,14000,14000,14000,14000,14000) -> 14521.053 | P10: =IF(B10="","",O10/N10) -> 0.85417957 | Q10: 6959 | R10: 22 | U10: =IF(S10="","",(T10-C10)) | V10: =IF(B10="","",IF(U10<3,(Q10-R10)/Q10,(Q10-R10-S10)/Q10)) -> 0.99683863 | W10: =IF(B10="","",V10*P10*J10) -> 0.66259262 | X10: =IF(B10="","",V10*P10*M10) -> 0.57083069
A11: Caribe Pearsecco to Caribe Rose to Stag | B11: 46092.01 | C11: 46093 | D11: =IF(B11="","",(C11-B11)*24*60) -> 1425 | E11: =45+60 -> 105 | F11: 90 | G11: =IF(E11="","",F11-E11) -> -15 | H11: =8+42+17+5+5+6+30+45+10+5+10+50+25+8+13+8+10+10+5+5 -> 317 | I11: =1+4+4+2+4+2+3+4+4+3+4+3+4+2+2+1+1+2+2+2+2+4 +2+3+3+2+4+4 -> 78 | J11: =IF(B11="","",(D11-G11-H11-I11)/D11) -> 0.73333333 | K11: 0 | L11: =6+8+18+10+1 -> 43 | M11: =IF(B11="","",(D11-G11-H11-I11-K11-L11-E11)/D11) -> 0.62947368 | N11: 17000 | O11: =AVERAGE(14000,14000,14000,14000,14000,14000,14000,16000,15400,15400,15400,15000,15000,15000) -> 14657.143 | P11: =IF(B11="","",O11/N11) -> 0.86218487 | Q11: 6315 | R11: 11 | S11: 70 | T11: 46097.736 | U11: =IF(S11="","",(T11-C11)) -> 4.7361111 | V11: =IF(B11="","",IF(U11<3,(Q11-R11)/Q11,(Q11-R11-S11)/Q11)) -> 0.9871734 | W11: =IF(B11="","",V11*P11*J11) -> 0.62415905 | X11: =IF(B11="","",V11*P11*M11) -> 0.5357614
A12: Stag to Starmalt | B12: 46093.008 | C12: 46094 | D12: =IF(B12="","",(C12-B12)*24*60) -> 1428 | E12: 45 | F12: 32 | G12: =IF(E12="","",F12-E12) -> -13 | H12: =5+8+6+6+5+5+5+7+9+5+13+60+5+5+7+5+11+8+12+6+5+7+6+5 -> 216 | I12: =1+3+3+1+2+2+2+2+2+2+1+1+1+1+4+2+4+4+2+2+1+4+3+2+2+3+4+4+3+3+2+1+1+3+2+4+2+2+4 -> 92 | J12: =IF(B12="","",(D12-G12-H12-I12)/D12) -> 0.79341737 | K12: =27+60+60+60+30 -> 237 | L12: =5+7+8 -> 20 | M12: =IF(B12="","",(D12-G12-H12-I12-K12-L12-E12)/D12) -> 0.58193277 | N12: 17000 | O12: =AVERAGE(13500,13500,13000,1270,12500,14500,14500,14000,14000,13500,13000,13000,14000,14200,14400,14000,14000,14000,14000,14000,14000,14000) -> 13221.364 | P12: =IF(B12="","",O12/N12) -> 0.77772727 | Q12: 7804 | R12: 12 | S12: =350+44 -> 394 | T12: 46104 | U12: =IF(S12="","",(T12-C12)) -> 10 | V12: =IF(B12="","",IF(U12<3,(Q12-R12)/Q12,(Q12-R12-S12)/Q12)) -> 0.9479754 | W12: =IF(B12="","",V12*P12*J12) -> 0.5849599 | X12: =IF(B12="","",V12*P12*M12) -> 0.42903943
A13: Starmalt to Guinness | B13: 46094.007 | C13: 46094.833 | D13: =IF(B13="","",(C13-B13)*24*60) -> 1190 | E13: 45 | F13: 43 | G13: =IF(E13="","",F13-E13) -> -2 | H13: =20+9+5+5+23+60+30+5+32+8+5+6 -> 208 | I13: =4+2+2+1+4+3+2+3+2+2+2+2+3+2+3+2+2+1+2+3+2+2+4+3+2+4+4+2+4+2+2+2+2+2+3+2+1+4+3 -> 97 | J13: =IF(B13="","",(D13-G13-H13-I13)/D13) -> 0.74537815 | K13: 0 | L13: =10+17+120+45 -> 192 | M13: =IF(B13="","",(D13-G13-H13-I13-K13-L13-E13)/D13) -> 0.54621849 | N13: 17000 | O13: =AVERAGE(12500,12500,13500,15000,14000,14000,14000,14000,14000,14000,14000,14000,14000) -> 13807.692 | P13: =IF(B13="","",O13/N13) -> 0.81221719 | Q13: 4694 | R13: 12 | S13: =840+14 -> 854 | T13: 46113.958 | U13: =IF(S13="","",(T13-C13)) -> 19.125 | V13: =IF(B13="","",IF(U13<3,(Q13-R13)/Q13,(Q13-R13-S13)/Q13)) -> 0.81550916 | W13: =IF(B13="","",V13*P13*J13) -> 0.49371655 | X13: =IF(B13="","",V13*P13*M13) -> 0.36179905
A14: Guinness | B14: 46097.056 | C14: 46097.425 | D14: =IF(B14="","",(C14-B14)*24*60) -> 532 | E14: 0 | F14: 0 | G14: =IF(E14="","",F14-E14) -> 0 | H14: =5+7 -> 12 | I14: =1+1+2+3+3+2+3+3 -> 18 | J14: =IF(B14="","",(D14-G14-H14-I14)/D14) -> 0.94360902 | K14: 0 | L14: =45+60+60+43+4+4+5+7+3 -> 231 | M14: =IF(B14="","",(D14-G14-H14-I14-K14-L14-E14)/D14) -> 0.5093985 | N14: 17000 | O14: =AVERAGE(15000,12500,14000,15000,15000) -> 14300 | P14: =IF(B14="","",O14/N14) -> 0.84117647 | Q14: 1735 | R14: 6 | U14: =IF(S14="","",(T14-C14)) | V14: =IF(B14="","",IF(U14<3,(Q14-R14)/Q14,(Q14-R14-S14)/Q14)) -> 0.99654179 | W14: =IF(B14="","",V14*P14*J14) -> 0.79099678 | X14: =IF(B14="","",V14*P14*M14) -> 0.42701221
A15: Guinness to Carib Amber | B15: 46099.333 | C15: 46100 | D15: =IF(B15="","",(C15-B15)*24*60) -> 960 | E15: 60 | F15: 66 | G15: =IF(E15="","",F15-E15) -> 6 | H15: =5+5+23+8+8+5+7+5+6+9+8 -> 89 | I15: =4+4+3+4+4+3+2+3+3+2+3+2+3+3+4+2+4+4+2+3+3+1+4+4+2 -> 76 | J15: =IF(B15="","",(D15-G15-H15-I15)/D15) -> 0.821875 | K15: 0 | L15: =15+7+9+4 -> 35 | M15: =IF(B15="","",(D15-G15-H15-I15-K15-L15-E15)/D15) -> 0.72291667 | N15: 17000 | O15: =AVERAGE(15000,15000,15000,15000,15000,15000,15000,15000,15000,15000,15000,15000,15000,15000,15000,15000) -> 15000 | P15: =IF(B15="","",O15/N15) -> 0.88235294 | Q15: 5524 | R15: 10 | U15: =IF(S15="","",(T15-C15)) | V15: =IF(B15="","",IF(U15<3,(Q15-R15)/Q15,(Q15-R15-S15)/Q15)) -> 0.99818972 | W15: =IF(B15="","",V15*P15*J15) -> 0.72387104 | X15: =IF(B15="","",V15*P15*M15) -> 0.63671293
A16: Carib Amber to Flint Local to Carib Amber | B16: 46100.007 | C16: 46101 | D16: =IF(B16="","",(C16-B16)*24*60) -> 1430 | E16: =30+30 -> 60 | F16: 14 | G16: =IF(E16="","",F16-E16) -> -46 | H16: =6+7+8+5+6+6+5 -> 43 | I16: =1+3+2+2+2+2+3+2+2+4+2+2+2+2+2+2+2+4+2+1+1+2+3+3+3+4+2+4+2+2+1+2+4+2+2+4+2+4+4+1+3+3+4+2+2+1 -> 111 | J16: =IF(B16="","",(D16-G16-H16-I16)/D16) -> 0.92447552 | K16: 0 | L16: =3+2+33+5+3+2+4+10+2 -> 64 | M16: =IF(B16="","",(D16-G16-H16-I16-K16-L16-E16)/D16) -> 0.83776224 | N16: 17000 | O16: =AVERAGE(15000,15000,15000,15000,15000,15000,15000,15000,15000,15000,15000,15000,15000,15000,15000,15000,15000,15000,15000,15000,15000,15000,15000) -> 15000 | P16: =IF(B16="","",O16/N16) -> 0.88235294 | Q16: 11008 | R16: 12 | U16: =IF(S16="","",(T16-C16)) | V16: =IF(B16="","",IF(U16<3,(Q16-R16)/Q16,(Q16-R16-S16)/Q16)) -> 0.99890988 | W16: =IF(B16="","",V16*P16*J16) -> 0.81482448 | X16: =IF(B16="","",V16*P16*M16) -> 0.73839616
A17: Carib Amber to Stag | B17: 46101.007 | C17: 46101.847 | D17: =IF(B17="","",(C17-B17)*24*60) -> 1209 | E17: 10 | F17: 17 | G17: =IF(E17="","",F17-E17) -> 7 | H17: =9+7+9+8+15+11+7+5+5+6+12 -> 94 | I17: =2+2+1+2+3+2+3+4+1+4+4+2+2+2+4+3+3+4+4+3+3+3+2+1+2+4+3+3+4+4 -> 84 | J17: =IF(B17="","",(D17-G17-H17-I17)/D17) -> 0.84698098 | K17: 0 | L17: =7+2+2+2+12+3+13+2+12+4+3+3+2+4+4+4+2+18+7+6 -> 112 | M17: =IF(B17="","",(D17-G17-H17-I17-K17-L17-E17)/D17) -> 0.74607113 | N17: 17000 | O17: =AVERAGE(15000,15000,15000,15000,15000,15000,15000,15000,15000,13000,13000,15500,15000,15000,15000,15000,15000,15000) -> 14805.556 | P17: =IF(B17="","",O17/N17) -> 0.87091503 | Q17: 7390 | R17: 18 | S17: 398 | T17: 46134 | U17: =IF(S17="","",(T17-C17)) -> 32.153472 | V17: =IF(B17="","",IF(U17<3,(Q17-R17)/Q17,(Q17-R17-S17)/Q17)) -> 0.94370771 | W17: =IF(B17="","",V17*P17*J17) -> 0.69612455 | X17: =IF(B17="","",V17*P17*M17) -> 0.61318783
A18: Stag to Carib Amber to Carib Flint | B18: 46104.073 | C18: 46104.992 | D18: =IF(B18="","",(C18-B18)*24*60) -> 1323 | E18: =10+30 -> 40 | F18: 28 | G18: =IF(E18="","",F18-E18) -> -12 | H18: =7+5+6+5+12+5+8+6 -> 54 | I18: =3+3+2+2+4+3+4+2+1+2+3+3+2+2+2+1+2+2+2+1+1+2+1+2+2+2+2+1+2+2+1+4+4+2+2+3+2 -> 81 | J18: =IF(B18="","",(D18-G18-H18-I18)/D18) -> 0.90702948 | K18: 0 | L18: =3+2+2+5+4+4+2+1+4+3+3+2+1+5+4 -> 45 | M18: =IF(B18="","",(D18-G18-H18-I18-K18-L18-E18)/D18) -> 0.84278156 | N18: 17000 | O18: =AVERAGE(15000,15000,15000,15000,15000,15000,15000,15000,15000,15000,15000,15000,15000,15000,15000,15000,15000,15500,15500) -> 15052.632 | P18: =IF(B18="","",O18/N18) -> 0.88544892 | Q18: 9289 | R18: 30 | U18: =IF(S18="","",(T18-C18)) | V18: =IF(B18="","",IF(U18<3,(Q18-R18)/Q18,(Q18-R18-S18)/Q18)) -> 0.99677037 | W18: =IF(B18="","",V18*P18*J18) -> 0.80053446 | X18: =IF(B18="","",V18*P18*M18) -> 0.74382994
