Workbook

Sheet January 2025 (w Utilization)
C1: OEE Calculation | G1: CARIB BREWERY
A2: SKU | B2: Start Time dd/mm/yyyy h:mm | C2: End Time dd/mm/yyyy h:mm (when production actually ends) | D2: Available time /mins | E2: Changeover Standard time /mins | F2: Actual Changeover /mins | G2: Changeover Deviation /mins | H2: Total Breakdowns /mins | I2: Total Minor Stops /mins | J2: Availability (for OEE) | K2: Planned Downtime /mins | L2: External Downtime /mins | M2: Availability (for OEE Utilization) | N2: Nominal Speed | O2: Actual (Average) Speed | P2: Performance | Q2: Total Products Produced /Cases | R2: Low Fill /Cases | S2: Embargo /cases | T2: Embargo release date | U2: Embargo Residence time /days | V2: Quality | W2: OEE | X2: OEE Utilization
A3: Stag Local to Carib Amber | B3: 45659.315 | C3: 45660 | D3: =IF(B3="","",(C3-B3)*24*60) -> 987 | E3: 10 | F3: 7 | G3: =IF(E3="","",F3-E3) -> -3 | H3: =7+9+15+17+14+5+15+5+30+46+6+9+8+8+5+21+8 -> 228 | I3: =2+3+3+1+3+2+4+2+3+3+2+1+3+3+3+4 -> 42 | J3: =IF(B3="","",(D3-G3-H3-I3)/D3) -> 0.72948328 | K3: 0 | L3: =50+11+14+10+7+3+5 -> 100 | M3: =IF(B3="","",(D3-G3-H3-I3-K3-L3-E3)/D3) -> 0.61803445 | N3: 17000 | O3: =AVERAGE(11000,17000,18000,17000,9000,17000,17500,17500,17500,17500,17000,17000,17500,17500) -> 16285.714 | P3: =IF(B3="","",O3/N3) -> 0.95798319 | Q3: =2153+3344 -> 5497 | R3: =3+1+3 -> 7 | U3: =IF(S3="","",(T3-C3)) | V3: =IF(B3="","",IF(U3<3,(Q3-R3)/Q3,(Q3-R3-S3)/Q3)) -> 0.99872658 | W3: =IF(B3="","",V3*P3*J3) -> 0.69794282 | X3: =IF(B3="","",V3*P3*M3) -> 0.59131266
A4: Carib Flint | B4: 45660.007 | C4: 45660.129 | D4: =IF(B4="","",(C4-B4)*24*60) -> 176 | E4: 7 | F4: 10 | G4: =IF(E4="","",F4-E4) -> 3 | H4: =8+6+6 -> 20 | I4: =4+4+4+4+4 -> 20 | J4: =IF(B4="","",(D4-G4-H4-I4)/D4) -> 0.75568182 | K4: 0 | L4: =5+2 -> 7 | M4: =IF(B4="","",(D4-G4-H4-I4-K4-L4-E4)/D4) -> 0.67613636 | N4: 17000 | O4: =AVERAGE(9000,18000,17000) -> 14666.667 | P4: =IF(B4="","",O4/N4) -> 0.8627451 | Q4: 1292 | R4: 9 | U4: =IF(S4="","",(T4-C4)) | V4: =IF(B4="","",IF(U4<3,(Q4-R4)/Q4,(Q4-R4-S4)/Q4)) -> 0.99303406 | W4: =IF(B4="","",V4*P4*J4) -> 0.64741926 | X4: =IF(B4="","",V4*P4*M4) -> 0.57926987
A5: Carib Amber to Stag | B5: 45663.169 | C5: 45664 | D5: =IF(B5="","",(C5-B5)*24*60) -> 1197 | E5: 10 | F5: 54 | G5: =IF(E5="","",F5-E5) -> 44 | H5: =5+6+6+6+28+25+10+7+9+5+38+5+5+5+5+11+7 -> 183 | I5: =4+4+1+4+2+3+3+4+3+3+1+4+4+2+2+4+3+4+4+2+1+2+2+1+2+1+2+2+1+1+1+1+1 -> 79 | J5: =IF(B5="","",(D5-G5-H5-I5)/D5) -> 0.7443609 | K5: 0 | L5: =6+2+10+2+2+6 -> 28 | M5: =IF(B5="","",(D5-G5-H5-I5-K5-L5-E5)/D5) -> 0.71261487 | N5: 17000 | O5: =AVERAGE(15600,15600,15500,15500,15500,15500,15600,15600) -> 15550 | P5: =IF(B5="","",Q5/N5) -> 0.495 | Q5: =5928+2487 -> 8415 | R5: =9+25 -> 34 | U5: =IF(S5="","",(T5-C5)) | V5: =IF(B5="","",IF(U5<3,(Q5-R5)/Q5,(Q5-R5-S5)/Q5)) -> 0.9959596 | W5: =IF(B5="","",V5*P5*J5) -> 0.36696992 | X5: =IF(B5="","",V5*P5*M5) -> 0.35131913
A6: Stag to Carib Amber to Vitamal Classic | B6: 45664 | C6: 45665 | D6: =IF(B6="","",(C6-B6)*24*60) -> 1440 | E6: =10+100 -> 110 | F6: 188 | G6: =IF(E6="","",F6-E6) -> 78 | H6: =17+5+5+6+21+7+5+5+11+5+38+59+59+60+34+6 -> 343 | I6: =4+1+3+2+2+4+3+2+2+3+2+2+2+4+3+1+4+2+3+1+4+3+1+4+4+1+3 -> 70 | J6: =IF(B6="","",(D6-G6-H6-I6)/D6) -> 0.65902778 | K6: 0 | L6: =10+3+5+9+4+6+2 -> 39 | M6: =IF(B6="","",(D6-G6-H6-I6-K6-L6-E6)/D6) -> 0.55555556 | N6: 17000 | O6: =AVERAGE(16000,16000,16000,16000,16000,16000,16000,9000,17000,9000,17000,17000,17000,17000,17000,17000) -> 15562.5 | P6: =IF(B6="","",O6/N6) -> 0.91544118 | Q6: =3335+3057+360 -> 6752 | R6: =15+5+2 -> 22 | U6: =IF(S6="","",(T6-C6)) | V6: =IF(B6="","",IF(U6<3,(Q6-R6)/Q6,(Q6-R6-S6)/Q6)) -> 0.99674171 | W6: =IF(B6="","",V6*P6*J6) -> 0.60133543 | X6: =IF(B6="","",V6*P6*M6) -> 0.50692133
A7: VitaMalt Classic to Vitamalt Ginger to Guinness to Carib Amber | B7: 45665 | C7: 45666 | D7: =IF(B7="","",(C7-B7)*24*60) -> 1440 | E7: =100+60 -> 160 | F7: =5+68+79+18 -> 170 | G7: =IF(E7="","",F7-E7) -> 10 | H7: =52+56+5+8+6+18+5+15+7+38+18+9+6+13 -> 256 | I7: =1+3+2+2+2+1+1+3+2+3+1+1+1+3+2+4+2+1+2+1+2+1+2+2+1+1+1+1+4+3+4+2+3+2+4+4+3+1+4+2 -> 85 | J7: =IF(B7="","",(D7-G7-H7-I7)/D7) -> 0.75625 | K7: 0 | L7: =2+4+2+10+27+4+40 -> 89 | M7: =IF(B7="","",(D7-G7-H7-I7-K7-L7-E7)/D7) -> 0.58333333 | N7: 17000 | O7: =AVERAGE(17000,17000,17000,17000,9000,9000,16000,16000,17000,17000,17000,15000,16000,16000,16000,16000,16000,17000,17000) -> 15684.211 | P7: =IF(B7="","",O7/N7) -> 0.92260062 | Q7: =1606+686+4437+356 -> 7085 | R7: =9+32+3 -> 44 | U7: =IF(S7="","",(T7-C7)) | V7: =IF(B7="","",IF(U7<3,(Q7-R7)/Q7,(Q7-R7-S7)/Q7)) -> 0.9937897 | W7: =IF(B7="","",V7*P7*J7) -> 0.69338369 | X7: =IF(B7="","",V7*P7*M7) -> 0.53484141
A8: Carib Amber | B8: 45666 | C8: 45666.67 | D8: =IF(B8="","",(C8-B8)*24*60) -> 965 | E8: 0 | F8: 0 | G8: =IF(E8="","",F8-E8) -> 0 | H8: =25+5+7+5+11+16+11+5+10 -> 95 | I8: =3+2+4+2+2+3+2+2+2+3+1+2+4+2+4+1+3+3+2+2+4+1+3+4+2+2+4+3+2+3 -> 77 | J8: =IF(B8="","",(D8-G8-H8-I8)/D8) -> 0.82176166 | K8: 0 | L8: =4+2+20+11+3+5+4+5 -> 54 | M8: =IF(B8="","",(D8-G8-H8-I8-K8-L8-E8)/D8) -> 0.76580311 | N8: 17000 | O8: =AVERAGE(17000,17000,17000,16400,16500,16500,16500,16500,17000,17000,17000,17000,17000,17000,17000,17000,17000,) -> 15911.111 | P8: =IF(B8="","",O8/N8) -> 0.93594771 | Q8: 6459 | R8: 35 | U8: =IF(S8="","",(T8-C8)) | V8: =IF(B8="","",IF(U8<3,(Q8-R8)/Q8,(Q8-R8-S8)/Q8)) -> 0.9945812 | W8: =IF(B8="","",V8*P8*J8) -> 0.76495821 | X8: =IF(B8="","",V8*P8*M8) -> 0.71286774
A9: Carib Amber to Stag | B9: 45673.65 | C9: 45673.933 | D9: =IF(B9="","",(C9-B9)*24*60) -> 407 | E9: 10 | F9: 32 | G9: =IF(E9="","",F9-E9) -> 22 | H9: =36+7+7+6 -> 56 | I9: =4+4+1+2+3+3+3+1+4 -> 25 | J9: =IF(B9="","",(D9-G9-H9-I9)/D9) -> 0.74692875 | K9: 0 | L9: =3+3+3 -> 9 | M9: =IF(B9="","",(D9-G9-H9-I9-K9-L9-E9)/D9) -> 0.7002457 | N9: 17000 | O9: =AVERAGE(9000,17500,17000,17000,17000,17500,18000) -> 16142.857 | P9: =IF(B9="","",O9/N9) -> 0.94957983 | Q9: =2589+509 -> 3098 | R9: =5+1 -> 6 | U9: =IF(S9="","",(T9-C9)) | V9: =IF(B9="","",IF(U9<3,(Q9-R9)/Q9,(Q9-R9-S9)/Q9)) -> 0.99806327 | W9: =IF(B9="","",V9*P9*J9) -> 0.70789481 | X9: =IF(B9="","",V9*P9*M9) -> 0.66365138
A10: Stag to Carib Amber | B10: 45674.344 | C10: 45674.831 | D10: =IF(B10="","",(C10-B10)*24*60) -> 701 | E10: 10 | F10: 15 | G10: =IF(E10="","",F10-E10) -> 5 | H10: =6+5+10+13+6+7+6+5+18 -> 76 | I10: =4+2+1+1+2+1+2+1+2+2+2+2+3+2+3+2+3+2+1 -> 38 | J10: =IF(B10="","",(D10-G10-H10-I10)/D10) -> 0.83024251 | K10: 0 | L10: =5+4+15+35 -> 59 | M10: =IF(B10="","",(D10-G10-H10-I10-K10-L10-E10)/D10) -> 0.7318117 | N10: 17000 | O10: =AVERAGE(11000,17600,17500,17500,17000,17000,17000,17000,17000,17000,9000,17000) -> 15966.667 | P10: =IF(B10="","",O10/N10) -> 0.93921569 | Q10: =846+3943 -> 4789 | R10: 6 | U10: =IF(S10="","",(T10-C10)) | V10: =IF(B10="","",IF(U10<3,(Q10-R10)/Q10,(Q10-R10-S10)/Q10)) -> 0.99874713 | W10: =IF(B10="","",V10*P10*J10) -> 0.77879983 | X10: =IF(B10="","",V10*P10*M10) -> 0.68646789
A11: Carib to Stag | B11: 45677.403 | C11: 45677.926 | D11: =IF(B11="","",(C11-B11)*24*60) -> 753 | E11: 10 | F11: 14 | G11: =IF(E11="","",F11-E11) -> 4 | H11: =15+16+14+10+6+6+5+9+5+6+5+15+11+16 -> 139 | I11: =2+2+4+4+3+2+3+2+2+2+3+4+2+2+2+3+2+4+2+1+4+4+4+2 -> 65 | J11: =IF(B11="","",(D11-G11-H11-I11)/D11) -> 0.72377158 | K11: 0 | L11: =5+2+2+3+9 -> 21 | M11: =IF(B11="","",(D11-G11-H11-I11-K11-L11-E11)/D11) -> 0.68260292 | N11: 17000 | O11: =AVERAGE(9000,17000,17000,17000,11000,17200,17100,17100,17100,17100,17100,17100,) -> 14676.923 | P11: =IF(B11="","",O11/N11) -> 0.86334842 | Q11: =1575+3354 -> 4929 | R11: 7 | U11: =IF(S11="","",(T11-C11)) | V11: =IF(B11="","",IF(U11<3,(Q11-R11)/Q11,(Q11-R11-S11)/Q11)) -> 0.99857983 | W11: =IF(B11="","",V11*P11*J11) -> 0.62397963 | X11: =IF(B11="","",V11*P11*M11) -> 0.58848721
A12: Stag Local to Mackason | B12: 45678.333 | C12: 45678.902 | D12: =IF(B12="","",(C12-B12)*24*60) -> 819 | E12: 60 | F12: 12 | G12: =IF(E12="","",F12-E12) -> -48 | H12: =15+23+5+7+6+12+15+7+9+5+8+8 -> 120 | I12: =4+3+4+1+3+3+1+2+2+3+2+2+3+2+2 -> 37 | J12: =IF(B12="","",(D12-G12-H12-I12)/D12) -> 0.86691087 | K12: 0 | L12: =29+50 -> 79 | M12: =IF(B12="","",(D12-G12-H12-I12-K12-L12-E12)/D12) -> 0.6971917 | N12: 17000 | O12: =AVERAGE(9000,17000,17000,17000,9000,17000,17000,17000,17000,17000,17000,17000) -> 15666.667 | P12: =IF(B12="","",O12/N12) -> 0.92156863 | Q12: =1585+3600 -> 5185 | R12: =3+3+6 -> 12 | U12: =IF(S12="","",(T12-C12)) | V12: =IF(B12="","",IF(U12<3,(Q12-R12)/Q12,(Q12-R12-S12)/Q12)) -> 0.99768563 | W12: =IF(B12="","",V12*P12*J12) -> 0.79706887 | X12: =IF(B12="","",V12*P12*M12) -> 0.64102299
A13: Starmalt | B13: 45679.344 | C13: 45679.888 | D13: =IF(B13="","",(C13-B13)*24*60) -> 784 | E13: 0 | F13: 0 | G13: =IF(E13="","",F13-E13) -> 0 | H13: =24+6+6+15+34+5+5+6+6 -> 107 | I13: =2+4+1+4+3+1+4+2+2+2+1+2+3+2+1+3+3+4+1+2+1+1+1+1+1 -> 52 | J13: =IF(B13="","",(D13-G13-H13-I13)/D13) -> 0.79719388 | K13: 0 | L13: 0 | M13: =IF(B13="","",(D13-G13-H13-I13-K13-L13-E13)/D13) -> 0.79719388 | N13: 17000 | O13: =AVERAGE(9000,17000,17000,17000,17000,17000,17200,17500,17300,17000,18000,18000,) -> 15307.692 | P13: =IF(B13="","",O13/N13) -> 0.90045249 | Q13: 5884 | R13: 10 | U13: =IF(S13="","",(T13-C13)) | V13: =IF(B13="","",IF(U13<3,(Q13-R13)/Q13,(Q13-R13-S13)/Q13)) -> 0.99830048 | W13: =IF(B13="","",V13*P13*J13) -> 0.71661523 | X13: =IF(B13="","",V13*P13*M13) -> 0.71661523
A14: Carib to Mackeson | B14: 45680.34 | C14: 45680.912 | D14: =IF(B14="","",(C14-B14)*24*60) -> 824 | E14: 20 | F14: 48 | G14: =IF(E14="","",F14-E14) -> 28 | H14: =30+47+10+6+6+6+5+5+12+42 -> 169 | I14: =3+2+2+4+3+3+4+4+2+1+1+3+1+2+2+3 -> 40 | J14: =IF(B14="","",(D14-G14-H15-I14)/D14) -> 0.77548544 | K14: 0 | L14: =6+5 -> 11 | M14: =IF(B14="","",(D14-G14-H14-I14-K14-L14-E14)/D14) -> 0.67475728 | N14: 17000 | O14: =AVERAGE(9000,17000,17000,17000,17000,17000,17000,17000,17000,18000,9000,18000) -> 15833.333 | P14: =IF(B14="","",O14/N14) -> 0.93137255 | Q14: =4090+419 -> 4509 | S14: 130 | T14: 45688.5 | U14: =IF(S14="","",(T14-C14)) -> 7.5875 | V14: =IF(B14="","",IF(U14<3,(Q14-R14)/Q14,(Q14-R14-S14)/Q14)) -> 0.97116877 | W14: =IF(B14="","",V14*P14*J14) -> 0.70144204 | X14: =IF(B14="","",V14*P14*M14) -> 0.61033141
A15: Carib Amber to Ginseng Original | B15: 45681.351 | C15: 45681.844 | D15: =IF(B15="","",(C15-B15)*24*60) -> 711 | E15: 60 | F15: 53 | G15: =IF(E15="","",F15-E15) -> -7 | H15: =25+7+15+6+7+8+5+44 -> 117 | I15: =4+3+4+2+3+4+3+2+1+3+4+2+4+2+2+1 -> 44 | J15: =IF(B15="","",(D15-G15-H16-I15)/D15) -> 0.66807314 | K15: 0 | L15: 0 | M15: =IF(B15="","",(D15-G15-H15-I15-K15-L15-E15)/D15) -> 0.69901547 | N15: 17000 | O15: =AVERAGE(9000,18000,17500,9000,17000,17000,17000,17000,17000,17000) -> 15550 | P15: =IF(B15="","",O15/N15) -> 0.91470588 | Q15: =1602+3350 -> 4952 | R15: =7+4 -> 11 | U15: =IF(S15="","",(T15-C15)) | V15: =IF(B15="","",IF(U15<3,(Q15-R15)/Q15,(Q15-R15-S15)/Q15)) -> 0.99777868 | W15: =IF(B15="","",V15*P15*J15) -> 0.609733 | X15: =IF(B15="","",V15*P15*M15) -> 0.63797326
A16: Stag Local to Carib Amber | B16: 45684.469 | C16: 45684.903 | D16: =IF(B16="","",(C16-B16)*24*60) -> 626 | E16: 10 | F16: 18 | G16: =IF(E16="","",F16-E16) -> 8 | H16: =5+9+21+6+7+5+54+10+5+9+9+5+18+36 -> 199 | I16: =3+3+2+4+2+3+4+3+4+1 -> 29 | J16: =IF(B16="","",(D16-G16-H16-I16)/D16) -> 0.62300319 | K16: 0 | L16: 0 | M16: =IF(B16="","",(D16-G16-H16-I16-K16-L16-E16)/D16) -> 0.60702875 | N16: 17000 | O16: =AVERAGE(9000,17500,17500,17500,17000,17000,11000,17000) -> 15437.5 | P16: =IF(B16="","",O16/N16) -> 0.90808824 | Q16: =963+2594 -> 3557 | R16: =5+3+2 -> 10 | U16: =IF(S16="","",(T16-C16)) | V16: =IF(B16="","",IF(U16<3,(Q16-R16)/Q16,(Q16-R16-S16)/Q16)) -> 0.99718864 | W16: =IF(B16="","",V16*P16*J16) -> 0.56415137 | X16: =IF(B16="","",V16*P16*M16) -> 0.54968595
A17: Carib Amber to Shandy lime | B17: 45685.34 | C17: 45685.891 | D17: =IF(B17="","",(C17-B17)*24*60) -> 793 | E17: 20 | F17: 96 | G17: =IF(E17="","",F17-E17) -> 76 | H17: =5+5+9+5+5+60+60+34+5+5+11+8+10 -> 222 | I17: =4+3+3+2+3+4+2+4+2+3+4+3+4+2+1+3 -> 47 | J17: =IF(B17="","",(D17-G17-H17-I17)/D17) -> 0.56494325 | K17: 0 | L17: 26 | M17: =IF(B17="","",(D17-G17-H17-I17-K17-L17-E17)/D17) -> 0.50693569 | N17: 17000 | O17: =AVERAGE(9000,17000,17000,17000,17000,17000,9000,18000,18000,18000) -> 15700 | P17: =IF(B17="","",O17/N17) -> 0.92352941 | Q17: =1895+1548 -> 3443 | R17: =5+3 -> 8 | S17: 13 | U17: =IF(S17="","",(T17-C17)) -> -45685.891 | V17: =IF(B17="","",IF(U17<3,(Q17-R17)/Q17,(Q17-R17-S17)/Q17)) -> 0.99767644 | W17: =IF(B17="","",V17*P17*J17) -> 0.52052941 | X17: =IF(B17="","",V17*P17*M17) -> 0.4670822
A18: Shandy Lime to Cider Pearcecco | B18: 45686.344 | C18: 45686.896 | D18: =IF(B18="","",(C18-B18)*24*60) -> 795 | E18: 60 | F18: 35 | G18: =IF(E18="","",F18-E18) -> -25 | H18: =50+32+14+5+60+8+24+36+6+7+11+5+6+5 -> 269 | I18: =3+4+3+4+4+3+1+4+3+2+3 -> 34 | J18: =IF(B18="","",(D18-G18-H18-I18)/D18) -> 0.65031447 | K18: 0 | L18: =20+24+43+27 -> 114 | M18: =IF(B18="","",(D18-G18-H18-I18-K18-L18-E18)/D18) -> 0.43144654 | N18: 17000 | O18: =AVERAGE(9000,17000,17000,15000,15000,15000,9000,17500) -> 14312.5 | P18: =IF(B18="","",O18/N18) -> 0.84191176 | Q18: =626+2006 -> 2632 | R18: =6+4+15 -> 25 | S18: =19+1 -> 20 | T18: 45740.37 | U18: =IF(S18="","",(T18-C18)) -> 53.474306 | V18: =IF(B18="","",IF(U18<3,(Q18-R18)/Q18,(Q18-R18-S18)/Q18)) -> 0.98290274 | W18: =IF(B18="","",V18*P18*J18) -> 0.53814652 | X18: =IF(B18="","",V18*P18*M18) -> 0.35702951
A19: Cider Pearcecco to Carib | B19: 45687.337 | C19: 45687.747 | D19: =IF(B19="","",(C19-B19)*24*60) -> 591 | E19: 60 | F19: 62 | G19: =IF(E19="","",F19-E19) -> 2 | H19: =11+8+7+6+19+6+5+6+6+5 -> 79 | I19: =2+2+2+3+3+4+3+2+3+1+4+4 -> 33 | J19: =IF(B19="","",(D19-G19-H19-I19)/D19) -> 0.8071066 | K19: 0 | L19: =13+20+4 -> 37 | M19: =IF(B19="","",(D19-G19-H19-I19-K19-L19-E19)/D19) -> 0.642978 | N19: 17000 | O19: =AVERAGE(17500,17500,17500,17500,17000,17000,17000,17000,17000,17000,17000) -> 17181.818 | P19: =IF(B19="","",O19/N19) -> 1.0106952 | Q19: =3609+1979 -> 5588 | R19: =10+12 -> 22 | S19: =14.13+5 -> 19.13 | T19: 45750.285 | U19: =IF(S19="","",(T19-C19)) -> 62.5375 | V19: =IF(B19="","",IF(U19<3,(Q19-R19)/Q19,(Q19-R19-S19)/Q19)) -> 0.99263958 | W19: =IF(B19="","",V19*P19*J19) -> 0.80973458 | X19: =IF(B19="","",V19*P19*M19) -> 0.64507157
A20: Carib to Vitamalt Classic | B20: 45688.294 | C20: 45688.801 | D20: =IF(B20="","",(C20-B20)*24*60) -> 730 | E20: 100 | F20: 117 | G20: =IF(E20="","",F20-E20) -> 17 | H20: =14+6+6+15+29 -> 70 | I20: =2+2+2+1+4+3+3+3+3+3 -> 26 | J20: =IF(B20="","",(D20-G20-H20-I20)/D20) -> 0.84520548 | K20: 0 | L20: =5+10 -> 15 | M20: =IF(B20="","",(D20-G20-H20-I20-K20-L20-E20)/D20) -> 0.68767123 | N20: 17000 | O20: =AVERAGE(17200,17500,16800,16800,16800,17000,18000) -> 17157.143 | P20: =IF(B20="","",O20/N20) -> 1.0092437 | Q20: =1235+3269 -> 4504 | R20: =4 -> 4 | U20: =IF(S20="","",(T20-C20)) | V20: =IF(B20="","",IF(U20<3,(Q20-R20)/Q20,(Q20-R20-S20)/Q20)) -> 0.9991119 | W20: =IF(B20="","",V20*P20*J20) -> 0.85226074 | X20: =IF(B20="","",V20*P20*M20) -> 0.69341149
D22: =IF(B22="","",(C22-B22)*24*60) | G22: =IF(E22="","",F22-E22) | J22: =IF(B22="","",(D22-G22-H22-I22)/D22) | M22: =IF(B22="","",(D22-G22-H22-I22-K22-L22-E22)/D22) | P22: =IF(B22="","",O22/N22) | U22: =IF(S22="","",(T22-C22)) | V22: =IF(B22="","",IF(U22<3,(Q22-R22)/Q22,(Q22-R22-S22)/Q22)) | W22: =IF(B22="","",V22*P22*J22) | X22: =IF(B22="","",V22*P22*M22)
D23: =IF(B23="","",(C23-B23)*24*60) | G23: =IF(E23="","",F23-E23) | J23: =IF(B23="","",(D23-G23-H23-I23)/D23) | M23: =IF(B23="","",(D23-G23-H23-I23-K23-L23-E23)/D23) | P23: =IF(B23="","",O23/N23) | U23: =IF(S23="","",(T23-C23)) | V23: =IF(B23="","",IF(U23<3,(Q23-R23)/Q23,(Q23-R23-S23)/Q23)) | W23: =IF(B23="","",V23*P23*J23) | X23: =IF(B23="","",V23*P23*M23)
D24: =IF(B24="","",(C24-B24)*24*60) | G24: =IF(E24="","",F24-E24) | J24: =IF(B24="","",(D24-G24-H24-I24)/D24) | M24: =IF(B24="","",(D24-G24-H24-I24-K24-L24-E24)/D24) | P24: =IF(B24="","",O24/N24) | U24: =IF(S24="","",(T24-C24)) | V24: =IF(B24="","",IF(U24<3,(Q24-R24)/Q24,(Q24-R24-S24)/Q24)) | W24: =IF(B24="","",V24*P24*J24) | X24: =IF(B24="","",V24*P24*M24)
D25: =IF(B25="","",(C25-B25)*24*60) | G25: =IF(E25="","",F25-E25) | J25: =IF(B25="","",(D25-G25-H25-I25)/D25) | M25: =IF(B25="","",(D25-G25-H25-I25-K25-L25-E25)/D25) | P25: =IF(B25="","",O25/N25) | U25: =IF(S25="","",(T25-C25)) | V25: =IF(B25="","",IF(U25<3,(Q25-R25)/Q25,(Q25-R25-S25)/Q25)) | W25: =IF(B25="","",V25*P25*J25) | X25: =IF(B25="","",V25*P25*M25)
D26: =IF(B26="","",(C26-B26)*24*60) | G26: =IF(E26="","",F26-E26) | J26: =IF(B26="","",(D26-G26-H26-I26)/D26) | M26: =IF(B26="","",(D26-G26-H26-I26-K26-L26-E26)/D26) | P26: =IF(B26="","",O26/N26) | U26: =IF(S26="","",(T26-C26)) | V26: =IF(B26="","",IF(U26<3,(Q26-R26)/Q26,(Q26-R26-S26)/Q26)) | W26: =IF(B26="","",V26*P26*J26) | X26: =IF(B26="","",V26*P26*M26)
D27: =IF(B27="","",(C27-B27)*24*60) | G27: =IF(E27="","",F27-E27) | J27: =IF(B27="","",(D27-G27-H27-I27)/D27) | M27: =IF(B27="","",(D27-G27-H27-I27-K27-L27-E27)/D27) | P27: =IF(B27="","",O27/N27) | U27: =IF(S27="","",(T27-C27)) | V27: =IF(B27="","",IF(U27<3,(Q27-R27)/Q27,(Q27-R27-S27)/Q27)) | W27: =IF(B27="","",V27*P27*J27) | X27: =IF(B27="","",V27*P27*M27)
D28: =IF(B28="","",(C28-B28)*24*60) | G28: =IF(E28="","",F28-E28) | J28: =IF(B28="","",(D28-G28-H28-I28)/D28) | M28: =IF(B28="","",(D28-G28-H28-I28-K28-L28-E28)/D28) | P28: =IF(B28="","",O28/N28) | U28: =IF(S28="","",(T28-C28)) | V28: =IF(B28="","",IF(U28<3,(Q28-R28)/Q28,(Q28-R28-S28)/Q28)) | W28: =IF(B28="","",V28*P28*J28) | X28: =IF(B28="","",V28*P28*M28)
D29: =IF(B29="","",(C29-B29)*24*60) | G29: =IF(E29="","",F29-E29) | J29: =IF(B29="","",(D29-G29-H29-I29)/D29) | M29: =IF(B29="","",(D29-G29-H29-I29-K29-L29-E29)/D29) | P29: =IF(B29="","",O29/N29) | U29: =IF(S29="","",(T29-C29)) | V29: =IF(B29="","",IF(U29<3,(Q29-R29)/Q29,(Q29-R29-S29)/Q29)) | W29: =IF(B29="","",V29*P29*J29) | X29: =IF(B29="","",V29*P29*M29)
D30: =IF(B30="","",(C30-B30)*24*60) | G30: =IF(E30="","",F30-E30) | J30: =IF(B30="","",(D30-G30-H30-I30)/D30) | M30: =IF(B30="","",(D30-G30-H30-I30-K30-L30-E30)/D30) | P30: =IF(B30="","",O30/N30) | U30: =IF(S30="","",(T30-C30)) | V30: =IF(B30="","",IF(U30<3,(Q30-R30)/Q30,(Q30-R30-S30)/Q30)) | W30: =IF(B30="","",V30*P30*J30) | X30: =IF(B30="","",V30*P30*M30)
D31: =IF(B31="","",(C31-B31)*24*60) | G31: =IF(E31="","",F31-E31) | J31: =IF(B31="","",(D31-G31-H31-I31)/D31) | M31: =IF(B31="","",(D31-G31-H31-I31-K31-L31-E31)/D31) | P31: =IF(B31="","",O31/N31) | U31: =IF(S31="","",(T31-C31)) | V31: =IF(B31="","",IF(U31<3,(Q31-R31)/Q31,(Q31-R31-S31)/Q31)) | W31: =IF(B31="","",V31*P31*J31) | X31: =IF(B31="","",V31*P31*M31)
D32: =IF(B32="","",(C32-B32)*24*60) | G32: =IF(E32="","",F32-E32) | J32: =IF(B32="","",(D32-G32-H32-I32)/D32) | M32: =IF(B32="","",(D32-G32-H32-I32-K32-L32-E32)/D32) | P32: =IF(B32="","",O32/N32) | U32: =IF(S32="","",(T32-C32)) | V32: =IF(B32="","",IF(U32<3,(Q32-R32)/Q32,(Q32-R32-S32)/Q32)) | W32: =IF(B32="","",V32*P32*J32) | X32: =IF(B32="","",V32*P32*M32)
D33: =IF(B33="","",(C33-B33)*24*60) | G33: =IF(E33="","",F33-E33) | J33: =IF(B33="","",(D33-G33-H33-I33)/D33) | M33: =IF(B33="","",(D33-G33-H33-I33-K33-L33-E33)/D33) | P33: =IF(B33="","",O33/N33) | U33: =IF(S33="","",(T33-C33)) | V33: =IF(B33="","",IF(U33<3,(Q33-R33)/Q33,(Q33-R33-S33)/Q33)) | W33: =IF(B33="","",V33*P33*J33) | X33: =IF(B33="","",V33*P33*M33)
... D37: =IF(B37="","",(C37-B37)*24*60) | G37: =IF(E37="","",F37-E37) | J37: =IF(B37="","",(D37-G37-H37-I37)/D37) | M37: =IF(B37="","",(D37-G37-H37-I37-K37-L37-E37)/D37) | P37: =IF(B37="","",O37/N37) | U37: =IF(S37="","",(T37-C37)) | V37: =IF(B37="","",IF(U37<3,(Q37-R37)/Q37,(Q37-R37-S37)/Q37)) | W37: =IF(B37="","",V37*P37*J37) | X37: =IF(B37="","",V37*P37*M37)
B38: Total | D38: =SUM(D3:D37) -> 14739 | E38: =SUM(E3:E37) -> 717 | F38: =SUM(F3:F37) -> 931 | G38: =SUM(G3:G37) -> 214 | H38: =SUM(H2:H37) -> 2748 | I38: =SUM(I3:I37) -> 843 | J38: =(D38-G38-H38-I38)/D38 -> 0.74184137 | K38: =SUM(K3:K37) -> 0 | L38: =SUM(L3:L37) -> 688 | M38: =(D38-G38-H38-I38-E38-K38-L38)/D38 -> 0.64651605 | N38: =AVERAGE(N3:N37) -> 17000 | O38: =AVERAGE(O3:O37) -> 15699.628 | P38: =O38/N38 -> 0.92350753 | Q38: =SUM(Q3:Q35) -> 88570 | V38: =AVERAGE(V3:V37) -> 0.99459311 | W38: =V38*P38*J38 -> 0.68139185 | X38: =V38*P38*M38 -> 0.59383418
O39: ytd | P39: =W38 -> 0.68139185
D46: Real | E46: Opportunity
C47: OEE | D47: =W38 -> 0.68139185 | E47: =100%-D47 -> 0.31860815
C48: OEE Utilization | D48: =X38 -> 0.59383418 | E48: =100%-D48 -> 0.40616582
C49: Availability (for OEE) | D49: =J38 -> 0.74184137 | E49: =100%-D49 -> 0.25815863
C50: Availability (for OEE Utilization) | D50: =M38 -> 0.64651605 | E50: =100%-D50 -> 0.35348395
...

Sheet February 2025 (w Utilization) 
C1: OEE Calculation | G1: CARIB BREWERY
A2: SKU | B2: Start Time dd/mm/yyyy h:mm | C2: End Time dd/mm/yyyy h:mm (when production actually ends) | D2: Available time /mins | E2: Changeover Standard time /mins | F2: Actual Changeover /mins | G2: Changeover Deviation /mins | H2: Total Breakdowns /mins | I2: Total Minor Stops /mins | J2: Availability (for OEE) | K2: Planned Downtime /mins | L2: External Downtime /mins | M2: Availability (for OEE Utilization) | N2: Nominal Speed | O2: Actual (Average) Speed | P2: Performance | Q2: Total Products Produced /Cases | R2: Low Fill /Cases | S2: Embargo /cases | T2: Embargo release date | U2: Embargo Residence time /days | V2: Quality | W2: OEE | X2: OEE Utilization
A3: Vitamalt Classic to Vitamalt Ginger to Stag Local | B3: 45691.071 | C3: 45692 | D3: =IF(B3="","",(C3-B3)*24*60) -> 1338 | E3: =10+100 -> 110 | F3: =10+133 -> 143 | G3: =IF(E3="","",F3-E3) -> 33 | H3: =23+11+29+5+25+15+5+10+5+9+9+7+9+7+5+8+11+5 -> 198 | I3: =2+2+2+3+2+3+2+2+1+3+2+3+2+3+3+3+2+2+2+4+2+2+1+4+2+3+2+2+3 -> 69 | J3: =IF(B3="","",(D3-G3-H3-I3)/D3) -> 0.77578475 | K3: 0 | L3: =7+5+4+3+7+13+4 -> 43 | M3: =IF(B3="","",(D3-G3-H3-I3-K3-L3-E3)/D3) -> 0.66143498 | N3: 17000 | O3: =AVERAGE(17300,17500,17000,17000,17500,17000,17000,17000,17000,17000,17000,17000,17000,17000) -> 17092.857 | P3: =IF(B3="","",O3/N3) -> 1.0054622 | Q3: 7710 | R3: =6+8 -> 14 | S3: 8 | T3: 45691 | U3: =IF(S3="","",(T3-C3)) -> -1 | V3: =IF(B3="","",IF(U3<3,(Q3-R3)/Q3,(Q3-R3-S3)/Q3)) -> 0.99818418 | W3: =IF(B3="","",V3*P3*J3) -> 0.77860585 | X3: =IF(B3="","",V3*P3*M3) -> 0.66384025
A4: Stag Local to Carib Amber | B4: 45692.093 | C4: 45693 | D4: =IF(B4="","",(C4-B4)*24*60) -> 1306 | E4: 10 | F4: 13 | G4: =IF(E4="","",F4-E4) -> 3 | H4: =6+10+7+19+88+5+6+6+22+40+7+9+11+8+6 -> 250 | I4: =3+2+4+2+2+4+2+2+3+1+2+4+2+1+2+2+2+2+1 -> 43 | J4: =IF(B4="","",(D4-G4-H4-I4)/D4) -> 0.77335375 | K4: 215 | L4: =4+2+8+12+7 -> 33 | M4: =IF(B4="","",(D4-G4-H4-I4-K4-L4-E4)/D4) -> 0.57580398 | N4: 17000 | O4: =AVERAGE(17500,17500,17500,17500,17500,17000,17000,17000,17000,17000,17000,17000,17000,17000,17000,17000) -> 17156.25 | P4: =IF(B4="","",O4/N4) -> 1.0091912 | Q4: 8123 | R4: 1 | U4: =IF(S4="","",(T4-C4)) | V4: =IF(B4="","",IF(U4<3,(Q4-R4)/Q4,(Q4-R4-S4)/Q4)) -> 0.99987689 | W4: =IF(B4="","",V4*P4*J4) -> 0.7803657 | X4: =IF(B4="","",V4*P4*M4) -> 0.58102476
A5: Carib Amber to Guinness | B5: 45693 | C5: 45694 | D5: =IF(B5="","",(C5-B5)*24*60) -> 1440 | E5: 25 | F5: 13 | G5: =IF(E5="","",F5-E5) -> -12 | H5: =6+5+5+6+5+5+5+5+5+7+9+19+11 -> 93 | I5: =3+1+1+1+2+2+2+3+3+2+2+2+2+3+4+3+4+2+1+3+4+1+2+3+2+2+3+3+3+3+1 -> 73 | J5: =IF(B5="","",(D5-G5-H5-I5)/D5) -> 0.89305556 | K5: 0 | L5: =22+10+4+28+18+45+20+4+5+3+16+2+50 -> 227 | M5: =IF(B5="","",(D5-G5-H5-I5-K5-L5-E5)/D5) -> 0.71805556 | N5: 17000 | O5: =AVERAGE(17000,17000,17000,17500,17500,17500,17500,17500,18000,17500,17500,17500,17500,17500,17500,17500,17000,17000,17000,17000,17000) -> 17333.333 | P5: =IF(B5="","",O5/N5) -> 1.0196078 | Q5: 9422 | R5: =3+16+6 -> 25 | S5: 11 | T5: 45693 | U5: =IF(S5="","",(T5-C5)) -> -1 | V5: =IF(B5="","",IF(U5<3,(Q5-R5)/Q5,(Q5-R5-S5)/Q5)) -> 0.99734664 | W5: =IF(B5="","",V5*P5*J5) -> 0.90815038 | X5: =IF(B5="","",V5*P5*M5) -> 0.73019246
A6: Guinness to Hurricane Reef to Stag Local | B6: 45694 | C6: 45694.913 | D6: =IF(B6="","",(C6-B6)*24*60) -> 1315 | E6: =60+45 -> 105 | F6: =61+80 -> 141 | G6: =IF(E6="","",F6-E6) -> 36 | H6: =5+10+14+5+20+42+60+35+15+15+7+5+5+5+9+11+10 -> 273 | I6: =3+4+3+2+1+2+3+4+2+4+3+2+2+1+2 -> 38 | J6: =IF(B6="","",(D6-G6-H6-I6)/D6) -> 0.73612167 | K6: 0 | L6: =35+2+35+10+7+34+3+3 -> 129 | M6: =IF(B6="","",(D6-G6-H6-I6-K6-L6-E6)/D6) -> 0.5581749 | N6: 17000 | O6: =AVERAGE(17000,18000,17000,17000,17000,17000,17000,17000,17000,17000,17000,17000) -> 17083.333 | P6: =IF(B6="","",O6/N6) -> 1.004902 | Q6: 6025 | R6: 32 | U6: =IF(S6="","",(T6-C6)) | V6: =IF(B6="","",IF(U6<3,(Q6-R6)/Q6,(Q6-R6-S6)/Q6)) -> 0.9946888 | W6: =IF(B6="","",V6*P6*J6) -> 0.73580126 | X6: =IF(B6="","",V6*P6*M6) -> 0.55793194
A7: Stag Local to Carib Amber | B7: 45698.107 | C7: 45699 | D7: =IF(B7="","",(C7-B7)*24*60) -> 1286 | E7: 10 | F7: 22 | G7: =IF(E7="","",F7-E7) -> 12 | H7: =5+8+23+7+44+11+11+10+24+45+47+44+9+28+21+5+6+8+7+6+10+14+5+5 -> 403 | I7: =3+3+3+1+4+1+4+2+4+3+3+2+4+4+1+3+2 -> 47 | J7: =IF(B7="","",(D7-G7-H7-I7)/D7) -> 0.6407465 | K7: 0 | L7: =9 -> 9 | M7: =IF(B7="","",(D7-G7-H7-I7-K7-L7-E7)/D7) -> 0.62597201 | N7: 17000 | O7: =AVERAGE(17000,17000,17000,17000,17500,17500,17000,17000,17000,17000,17000,17000) -> 17083.333 | P7: =IF(B7="","",O7/N7) -> 1.004902 | Q7: 6249 | R7: 16 | S7: 7 | T7: 45699.369 | U7: =IF(S7="","",(T7-C7)) -> 0.36944444 | V7: =IF(B7="","",IF(U7<3,(Q7-R7)/Q7,(Q7-R7-S7)/Q7)) -> 0.99743959 | W7: =IF(B7="","",V7*P7*J7) -> 0.6422388 | X7: =IF(B7="","",V7*P7*M7) -> 0.6274299
A8: Carib Amber to Stag Local to Carib Amber | B8: 45699 | C8: 45700 | D8: =IF(B8="","",(C8-B8)*24*60) -> 1440 | E8: =10+10 -> 20 | F8: =16+15 -> 31 | G8: =IF(E8="","",F8-E8) -> 11 | H8: =5+7+6+19+5+12+6+5+5 -> 70 | I8: =3+1+2+2+2+3+1+1+3+4+4+3+3+2+3+1+3+3+1+2+2+1+4+3+3+4+3+2+3+3+3+4+4+2+1+4+2+3 -> 98 | J8: =IF(B8="","",(D8-G8-H8-I8)/D8) -> 0.87569444 | K8: 0 | L8: =10+2+2+3+16+8+2+2+4+9+3+4+4+5+6+4+6+11 -> 101 | M8: =IF(B8="","",(D8-G8-H8-I8-K8-L8-E8)/D8) -> 0.79166667 | N8: 17000 | O8: =AVERAGE(17000,17000,17000,17000,17000,17000,17000,18000,18000,18000,18000,18000,18000,18000,18000,17000,17000,17000,17000,17000,17000,17000,17000) -> 17347.826 | P8: =IF(B8="","",O8/N8) -> 1.0204604 | Q8: 10439 | R8: =13+6 -> 19 | U8: =IF(S8="","",(T8-C8)) | V8: =IF(B8="","",IF(U8<3,(Q8-R8)/Q8,(Q8-R8-S8)/Q8)) -> 0.9981799 | W8: =IF(B8="","",V8*P8*J8) -> 0.89198501 | X8: =IF(B8="","",V8*P8*M8) -> 0.80639406
A9: Carib Amber to Stag Local | B9: 45700 | C9: 45700.994 | D9: =IF(B9="","",(C9-B9)*24*60) -> 1432 | E9: 10 | F9: 18 | G9: =IF(E9="","",F9-E9) -> 8 | H9: =8+5+6+17+13+5+5+9+11+5+8+7+8+7+11+15+5+5+9 -> 159 | I9: =4+3+2+1+3+2+3+3+2+1+3+2+3+3+3+2+3+2+1+2+1+2+3+3+3+2+1+1+3+2+4 -> 73 | J9: =IF(B9="","",(D9-G9-H9-I9)/D9) -> 0.83240223 | K9: 0 | L9: =5+3+3+5+12+4+6+2+3+45+4+7+8+4+13+6+3+14+4 -> 151 | M9: =IF(B9="","",(D9-G9-H9-I9-K9-L9-E9)/D9) -> 0.71997207 | N9: 17000 | O9: =AVERAGE(17000,17000,17000,18000,18000,18000,17000,17000,17000,17000,17000,17000,17000,17000,17500,17000,17000,17000,17000,17500,17000,17500,17500) -> 17217.391 | P9: =IF(B9="","",O9/N9) -> 1.0127877 | Q9: 9388 | R9: =28+7 -> 35 | U9: =IF(S9="","",(T9-C9)) | V9: =IF(B9="","",IF(U9<3,(Q9-R9)/Q9,(Q9-R9-S9)/Q9)) -> 0.99627184 | W9: =IF(B9="","",V9*P9*J9) -> 0.83990375 | X9: =IF(B9="","",V9*P9*M9) -> 0.72646037
A10: Starmalt to Guinness | B10: 45701 | C10: 45702.033 | D10: =IF(B10="","",(C10-B10)*24*60) -> 1487 | E10: =25+45 -> 70 | F10: =45+8 -> 53 | G10: =IF(E10="","",F10-E10) -> -17 | H10: =5+15+7+5+6+7+5+8+5+6+13+11+6+11+28+10+8 -> 156 | I10: =2+2+2+2+2+2+1+1+3+3+4+4+3+3+2+1+3+3+3+4+2+2+4+3+2+3+3+2+1+1+2+2+3+2+3+2+2+1 -> 90 | J10: =IF(B10="","",(D10-G10-H10-I10)/D10) -> 0.84599866 | K10: 0 | L10: =3+4+2+2+1+16+3+4+2+4+2+3 -> 46 | M10: =IF(B10="","",(D10-G10-H10-I10-K10-L10-E10)/D10) -> 0.76798924 | N10: 17000 | O10: =AVERAGE(17000,17000,17000,17000,17000,17000,17000,17000,17000,17000,17500,17000,17000,17000,17000,17000,17000,17000,17000,17000,17000) -> 17023.81 | P10: =IF(B10="","",O10/N10) -> 1.0014006 | Q10: 8459 | R10: =10+5 -> 15 | U10: =IF(S10="","",(T10-C10)) | V10: =IF(B10="","",IF(U10<3,(Q10-R10)/Q10,(Q10-R10-S10)/Q10)) -> 0.99822674 | W10: =IF(B10="","",V10*P10*J10) -> 0.84568125 | X10: =IF(B10="","",V10*P10*M10) -> 0.7677011
A11: Carib Amber to Stag Local | B11: 45702.129 | C11: 45703 | D11: =IF(B11="","",(C11-B11)*24*60) -> 1254 | E11: =60+10 -> 70 | F11: =43+60 -> 103 | G11: =IF(E11="","",F11-E11) -> 33 | H11: =53+60+15+5+15+5+6+5+23+60+60+60+60 -> 427 | I11: =2+3+3+2+1+2+1+2+2+2+2+2+1 -> 25 | J11: =IF(B11="","",(D11-G11-H11-I11)/D11) -> 0.61323764 | K11: 0 | L11: =28+60+6+10+3+13+20+7+5+6+5 -> 163 | M11: =IF(B11="","",(D11-G11-H11-I11-K11-L11-E11)/D11) -> 0.42743222 | N11: 17000 | O11: =AVERAGE(17000,17000,17000,17000,17000,17000,17000,17000,17000) -> 17000 | P11: =IF(B11="","",O11/N11) -> 1 | Q11: 4501 | R11: =10 -> 10 | S11: 294 | T11: 45712 | U11: =IF(S11="","",(T11-C11)) -> 9 | V11: =IF(B11="","",IF(U11<3,(Q11-R11)/Q11,(Q11-R11-S11)/Q11)) -> 0.93245945 | W11: =IF(B11="","",V11*P11*J11) -> 0.57181923 | X11: =IF(B11="","",V11*P11*M11) -> 0.39856321
A12: Stag Local to Carib Amber | B12: 45705.069 | C12: 45706 | D12: =IF(B12="","",(C12-B12)*24*60) -> 1340 | E12: 10 | F12: 38 | G12: =IF(E12="","",F12-E12) -> 28 | H12: =49+60+36+53+7+10+19+7+6+5+5+5+9+60+60+60+60+21+5+5 -> 542 | I12: =2+4+3+2+2+2+2+3+2+1+1+2+2+1+3+2+2 -> 36 | J12: =IF(B12="","",(D12-G12-H12-I12)/D12) -> 0.54776119 | K12: 0 | L12: =3+8+3+60+60+3+6+3+4+3 -> 153 | M12: =IF(B12="","",(D12-G12-H12-I12-K12-L12-E12)/D12) -> 0.4261194 | N12: 17000 | O12: =AVERAGE(17000,17000,18000,18000,18000,18000,16000,15600,16500,16000) -> 17010 | P12: =IF(B12="","",O12/N12) -> 1.0005882 | Q12: 4751 | R12: =5+29 -> 34 | S12: =44+25 -> 69 | U12: =IF(S12="","",(T12-C12)) -> -45706 | V12: =IF(B12="","",IF(U12<3,(Q12-R12)/Q12,(Q12-R12-S12)/Q12)) -> 0.99284361 | W12: =IF(B12="","",V12*P12*J12) -> 0.54416111 | X12: =IF(B12="","",V12*P12*M12) -> 0.42331879
A13: Carib Amber to Pearsecco to Rose to Shandy Ginger | B13: 45706 | C13: 45707 | D13: =IF(B13="","",(C13-B13)*24*60) -> 1440 | E13: =60+45+60 -> 165 | F13: =62+22+105 -> 189 | G13: =IF(E13="","",F13-E13) -> 24 | H13: =6+8+9+5+12+5+5+22+16+6+12+6+21+8+12+14+26+23 -> 216 | I13: =3+3+3+2+2+2+2+2+3+2+2+4+2+3+2+1+1+1+1+1+3+3+2+3+1+1+1+3 -> 59 | J13: =IF(B13="","",(D13-G13-H13-I13)/D13) -> 0.79236111 | K13: 0 | L13: =2+180+2+14+2+3+3+5+2+2+3+8+48+2+1+9+2+1+2+2+2+8 -> 303 | M13: =IF(B13="","",(D13-G13-H13-I13-K13-L13-E13)/D13) -> 0.46736111 | N13: 17000 | O13: =AVERAGE(16000,16000,16000,17000,17000,17000,11000,17000,17000,17000,17000,17000,17000,17000,17000,18000) -> 16500 | P13: =IF(B13="","",O13/N13) -> 0.97058824 | Q13: 5335 | R13: 21 | S13: =280+2+2 -> 284 | T13: 45721 | U13: =IF(S13="","",(T13-C13)) -> 14 | V13: =IF(B13="","",IF(U13<3,(Q13-R13)/Q13,(Q13-R13-S13)/Q13)) -> 0.94283037 | W13: =IF(B13="","",V13*P13*J13) -> 0.7250897 | X13: =IF(B13="","",V13*P13*M13) -> 0.42768218
A14: Shandy Ginger to Ting to Shandy Sorrel | B14: 45707 | C14: 45708 | D14: =IF(B14="","",(C14-B14)*24*60) -> 1440 | E14: =45+60 -> 105 | F14: =78+88 -> 166 | G14: =IF(E14="","",F14-E14) -> 61 | H14: =9+7+9+11+15+9+22+12+5+15+5+10+5+9+16+6+5 -> 170 | I14: =3+2+4+32+4+2+2+3+3+3+3+3+1+2+2+4+1+2+2+1+3+4+2+3 -> 91 | J14: =IF(B14="","",(D14-G14-H14-I14)/D14) -> 0.77638889 | K14: 0 | L14: =4+11+21+13+26+60+16+43+30+7+4+4+5+19+10+8+4+9+5 -> 299 | M14: =IF(B14="","",(D14-G14-H14-I14-K14-L14-E14)/D14) -> 0.49583333 | N14: 17000 | O14: =AVERAGE(17000,17000,17000,17000,17000,17000,17000,17000,17000,17000,17000,17000,17000,17500,17000) -> 17033.333 | P14: =IF(B14="","",O14/N14) -> 1.0019608 | Q14: 5911 | R14: =16+11 -> 27 | U14: =IF(S14="","",(T14-C14)) | V14: =IF(B14="","",IF(U14<3,(Q14-R14)/Q14,(Q14-R14-S14)/Q14)) -> 0.99543224 | W14: =IF(B14="","",V14*P14*J14) -> 0.77435791 | X14: =IF(B14="","",V14*P14*M14) -> 0.49453627
A15: Shandy Sorrel to Vita Malt to Club Soda to J Cool Kola Champayne | B15: 45708 | C15: 45709 | D15: =IF(B15="","",(C15-B15)*24*60) -> 1440 | E15: =100+150+20 -> 270 | F15: =118+279+4 -> 401 | G15: =IF(E15="","",F15-E15) -> 131 | H15: =6+6+8+7+8+6+49+5+13+13+23 -> 144 | I15: =2+4+4+3+4+3+2+2+1+3+1+2+1+3+4+3+1 -> 43 | J15: =IF(B15="","",(D15-G15-H15-I15)/D15) -> 0.77916667 | K15: 0 | L15: =11+3+2+5+2+2+2+2+3+4+2+13+9+2+11 -> 73 | M15: =IF(B15="","",(D15-G15-H15-I15-K15-L15-E15)/D15) -> 0.54097222 | N15: 17000 | O15: =AVERAGE(17000,17000,17000,17000,17000,17000,17000,17000,13000,15000,16000,17000) -> 16416.667 | P15: =IF(B15="","",O15/N15) -> 0.96568627 | Q15: 4927 | R15: 19 | S15: =50+63 -> 113 | T15: 45712 | U15: =IF(S15="","",(T15-C15)) -> 3 | V15: =IF(B15="","",IF(U15<3,(Q15-R15)/Q15,(Q15-R15-S15)/Q15)) -> 0.97320885 | W15: =IF(B15="","",V15*P15*J15) -> 0.73227208 | X15: =IF(B15="","",V15*P15*M15) -> 0.5084135
A16: J Cool Kola Champayne to Cream Soda to Grape to Carib Amber | B16: 45709 | C16: 45709.85 | D16: =IF(B16="","",(C16-B16)*24*60) -> 1224 | E16: =20+20+45 -> 85 | F16: =35+44+103 -> 182 | G16: =IF(E16="","",F16-E16) -> 97 | H16: =7+5+7+5+5+12+15+6+17 -> 79 | I16: =1+2+2+2+4+1+3+3+1+3+3+3+2+3+3+2+2+1+3+2+2+3+2+2+2+3+2+2+3+3+2+1 -> 73 | J16: =IF(B16="","",(D16-G16-H16-I16)/D16) -> 0.79656863 | K16: 0 | L16: =29+5+11+6+6+2+3+18+2+2+3+2 -> 89 | M16: =IF(B16="","",(D16-G16-H16-I16-K16-L16-E16)/D16) -> 0.65441176 | N16: 17000 | O16: =AVERAGE(17000,17000,17000,17000,17000,17000,17000,17000,17000,18000,17000,17000,17000,17000,17000,17000,17000) -> 17058.824 | P16: =IF(B16="","",O16/N16) -> 1.0034602 | Q16: 6836 | R16: =15+15+11 -> 41 | S16: 50 | U16: =IF(S16="","",(T16-C16)) -> -45709.85 | V16: =IF(B16="","",IF(U16<3,(Q16-R16)/Q16,(Q16-R16-S16)/Q16)) -> 0.99400234 | W16: =IF(B16="","",V16*P16*J16) -> 0.79453084 | X16: =IF(B16="","",V16*P16*M16) -> 0.65273765
A17: Carib Amber to Stag Local | B17: 45712.417 | C17: 45713 | D17: =IF(B17="","",(C17-B17)*24*60) -> 840 | E17: 10 | F17: 17 | G17: =IF(E17="","",F17-E17) -> 7 | H17: =6+23+7+5+25+60+51+8+4+10+6 -> 205 | I17: =4+3+2+3+3+2+3+3+1+2+2+3+3+1+4+2+2+3+1 -> 47 | J17: =IF(B17="","",(D17-G17-H17-I17)/D17) -> 0.69166667 | K17: 0 | L17: =30+15+5+4+2+2+6 -> 64 | M17: =IF(B17="","",(D17-G17-H17-I17-K17-L17-E17)/D17) -> 0.60357143 | N17: 17000 | O17: =AVERAGE(17000,17000,17000,17000,17000,17000,17000) -> 17000 | P17: =IF(B17="","",O17/N17) -> 1 | Q17: 4711 | R17: 18 | U17: =IF(S17="","",(T17-C17)) | V17: =IF(B17="","",IF(U17<3,(Q17-R17)/Q17,(Q17-R17-S17)/Q17)) -> 0.99617916 | W17: =IF(B17="","",V17*P17*J17) -> 0.68902392 | X17: =IF(B17="","",V17*P17*M17) -> 0.60126528
A18: Stag Local to Carib Amber | B18: 45713 | C18: 45713.917 | D18: =IF(B18="","",(C18-B18)*24*60) -> 1320 | E18: 10 | F18: 15 | G18: =IF(E18="","",F18-E18) -> 5 | H18: =7+6+7+7+7+6+6+7+11+8+12+12+24+10+7 -> 137 | I18: =1+1+1+2+2+4+2+2+1+3+2+3+2+1+4+1+2+1+3+3+1+3+2+1+3+2+1+2+1+2+2+1+2+2 -> 66 | J18: =IF(B18="","",(D18-G18-H18-I18)/D18) -> 0.84242424 | K18: 0 | L18: =16+26+5+20+25+15+4+5+2+2+4+3+3+55 -> 185 | M18: =IF(B18="","",(D18-G18-H18-I18-K18-L18-E18)/D18) -> 0.69469697 | N18: 17000 | O18: =AVERAGE(17500,17500,17500,18000,17500,17500,17500,17500,17000,17000,17000,17000,17000,17000,17000,17000) -> 17281.25 | P18: =IF(B18="","",O18/N18) -> 1.0165441 | Q18: 8715 | R18: 12 | U18: =IF(S18="","",(T18-C18)) | V18: =IF(B18="","",IF(U18<3,(Q18-R18)/Q18,(Q18-R18-S18)/Q18)) -> 0.99862306 | W18: =IF(B18="","",V18*P18*J18) -> 0.85518225 | X18: =IF(B18="","",V18*P18*M18) -> 0.70521774
A19: Carib Amber | B19: 45713.312 | C19: 45714 | D19: =IF(B19="","",(C19-B19)*24*60) -> 990 | E19: 0 | F19: 0 | G19: =IF(E19="","",F19-E19) -> 0 | H19: =6+24+6+14+6+30+28+7+8+11+6+5+5+6+6+6 -> 174 | I19: =2+3+2+1+3+1+1+2+3+2+1+2+1+2 -> 26 | J19: =IF(B19="","",(D19-G19-H19-I19)/D19) -> 0.7979798 | K19: 0 | L19: =17+13+5+20+3+5+3 -> 66 | M19: =IF(B19="","",(D19-G19-H19-I19-K19-L19-E19)/D19) -> 0.73131313 | N19: 17000 | O19: =AVERAGE(17000,17000,17000,17000,17000,17000,17000,17000,17000,17000,17000,17000,17000,17000,17000,17000) -> 17000 | P19: =IF(B19="","",O19/N19) -> 1 | Q19: 6251 | R19: 92 | U19: =IF(S19="","",(T19-C19)) | V19: =IF(B19="","",IF(U19<3,(Q19-R19)/Q19,(Q19-R19-S19)/Q19)) -> 0.98528235 | W19: =IF(B19="","",V19*P19*J19) -> 0.78623541 | X19: =IF(B19="","",V19*P19*M19) -> 0.72054992
A20: Carib Amber to Guinness to Carib Amber | B20: 45715 | C20: 45716 | D20: =IF(B20="","",(C20-B20)*24*60) -> 1440 | E20: =25+60 -> 85 | F20: 110 | G20: =IF(E20="","",F20-E20) -> 25 | H20: =9+24+13+5+5+6+28+7+7+7+5+32+24+60+60+44+9+51 -> 396 | I20: =2+3+2+4+1+2+2+4+4+3+2+2+2+1+4+4+4+3+4+2+2+1+3 -> 61 | J20: =IF(B20="","",(D20-G20-H20-I20)/D20) -> 0.66527778 | K20: 0 | L20: =10+10+8+9+4+2+5+5+16+25+13 -> 107 | M20: =IF(B20="","",(D20-G20-H20-I20-K20-L20-E20)/D20) -> 0.53194444 | N20: 17000 | O20: =AVERAGE(17000,16000,16000,16000,16000,16000,15500,17000,17000,17000,17000,17000,17000,17000,17000,17000,17000) -> 16617.647 | P20: =IF(B20="","",O20/N20) -> 0.97750865 | Q20: 5900 | R20: 33 | S20: =70+2 -> 72 | T20: 45723.396 | U20: =IF(S20="","",(T20-C20)) -> 7.3958333 | V20: =IF(B20="","",IF(U20<3,(Q20-R20)/Q20,(Q20-R20-S20)/Q20)) -> 0.98220339 | W20: =IF(B20="","",V20*P20*J20) -> 0.63874138 | X20: =IF(B20="","",V20*P20*M20) -> 0.51072641
A21: Carib Amber to Carib Flint Local to Stag | B21: 45716 | C21: 45716.833 | D21: =IF(B21="","",(C21-B21)*24*60) -> 1200 | E21: =7+10 -> 17 | F21: =11+18 -> 29 | G21: =IF(E21="","",F21-E21) -> 12 | H21: =9+5+5+14+8+5+6+11+9+13+5+45+5+6+6 -> 152 | I21: =4+2+1+2+2+2+3+4+2+3+4+3+2+4+3+1+3+2 -> 47 | J21: =IF(B21="","",(D21-G21-H21-I21)/D21) -> 0.82416667 | K21: 0 | L21: =8+7+2+5+15+5+5+5+3+9+10+6+3 -> 83 | M21: =IF(B21="","",(D21-G21-H21-I21-K21-L21-E21)/D21) -> 0.74083333 | N21: 17000 | O21: =AVERAGE(17000,17000,17000,17000,17000,17000,17000,17000,17000,17000,17000,17000,17000,17000,17000,17000,17000,17000,17000) -> 17000 | P21: =IF(B21="","",O21/N21) -> 1 | Q21: 7608 | R21: 49 | U21: =IF(S21="","",(T21-C21)) | V21: =IF(B21="","",IF(U21<3,(Q21-R21)/Q21,(Q21-R21-S21)/Q21)) -> 0.99355941 | W21: =IF(B21="","",V21*P21*J21) -> 0.81885855 | X21: =IF(B21="","",V21*P21*M21) -> 0.73606193
D22: =IF(B22="","",(C22-B22)*24*60) | G22: =IF(E22="","",F22-E22) | J22: =IF(B22="","",(D22-G22-H22-I22)/D22) | M22: =IF(B22="","",(D22-G22-H22-I22-K22-L22-E22)/D22) | P22: =IF(B22="","",O22/N22) | U22: =IF(S22="","",(T22-C22)) | V22: =IF(B22="","",IF(U22<3,(Q22-R22)/Q22,(Q22-R22-S22)/Q22)) | W22: =IF(B22="","",V22*P22*J22) | X22: =IF(B22="","",V22*P22*M22)
D23: =IF(B23="","",(C23-B23)*24*60) | G23: =IF(E23="","",F23-E23) | J23: =IF(B23="","",(D23-G23-H23-I23)/D23) | M23: =IF(B23="","",(D23-G23-H23-I23-K23-L23-E23)/D23) | P23: =IF(B23="","",O23/N23) | U23: =IF(S23="","",(T23-C23)) | V23: =IF(B23="","",IF(U23<3,(Q23-R23)/Q23,(Q23-R23-S23)/Q23)) | W23: =IF(B23="","",V23*P23*J23) | X23: =IF(B23="","",V23*P23*M23)
D24: =IF(B24="","",(C24-B24)*24*60) | G24: =IF(E24="","",F24-E24) | J24: =IF(B24="","",(D24-G24-H24-I24)/D24) | M24: =IF(B24="","",(D24-G24-H24-I24-K24-L24-E24)/D24) | P24: =IF(B24="","",O24/N24) | U24: =IF(S24="","",(T24-C24)) | V24: =IF(B24="","",IF(U24<3,(Q24-R24)/Q24,(Q24-R24-S24)/Q24)) | W24: =IF(B24="","",V24*P24*J24) | X24: =IF(B24="","",V24*P24*M24)
D25: =IF(B25="","",(C25-B25)*24*60) | G25: =IF(E25="","",F25-E25) | J25: =IF(B25="","",(D25-G25-H25-I25)/D25) | M25: =IF(B25="","",(D25-G25-H25-I25-K25-L25-E25)/D25) | P25: =IF(B25="","",O25/N25) | U25: =IF(S25="","",(T25-C25)) | V25: =IF(B25="","",IF(U25<3,(Q25-R25)/Q25,(Q25-R25-S25)/Q25)) | W25: =IF(B25="","",V25*P25*J25) | X25: =IF(B25="","",V25*P25*M25)
D26: =IF(B26="","",(C26-B26)*24*60) | G26: =IF(E26="","",F26-E26) | J26: =IF(B26="","",(D26-G26-H26-I26)/D26) | M26: =IF(B26="","",(D26-G26-H26-I26-K26-L26-E26)/D26) | P26: =IF(B26="","",O26/N26) | U26: =IF(S26="","",(T26-C26)) | V26: =IF(B26="","",IF(U26<3,(Q26-R26)/Q26,(Q26-R26-S26)/Q26)) | W26: =IF(B26="","",V26*P26*J26) | X26: =IF(B26="","",V26*P26*M26)
D27: =IF(B27="","",(C27-B27)*24*60) | G27: =IF(E27="","",F27-E27) | J27: =IF(B27="","",(D27-G27-H27-I27)/D27) | M27: =IF(B27="","",(D27-G27-H27-I27-K27-L27-E27)/D27) | P27: =IF(B27="","",O27/N27) | U27: =IF(S27="","",(T27-C27)) | V27: =IF(B27="","",IF(U27<3,(Q27-R27)/Q27,(Q27-R27-S27)/Q27)) | W27: =IF(B27="","",V27*P27*J27) | X27: =IF(B27="","",V27*P27*M27)
D28: =IF(B28="","",(C28-B28)*24*60) | G28: =IF(E28="","",F28-E28) | J28: =IF(B28="","",(D28-G28-H28-I28)/D28) | M28: =IF(B28="","",(D28-G28-H28-I28-K28-L28-E28)/D28) | P28: =IF(B28="","",O28/N28) | U28: =IF(S28="","",(T28-C28)) | V28: =IF(B28="","",IF(U28<3,(Q28-R28)/Q28,(Q28-R28-S28)/Q28)) | W28: =IF(B28="","",V28*P28*J28) | X28: =IF(B28="","",V28*P28*M28)
D29: =IF(B29="","",(C29-B29)*24*60) | G29: =IF(E29="","",F29-E29) | J29: =IF(B29="","",(D29-G29-H29-I29)/D29) | M29: =IF(B29="","",(D29-G29-H29-I29-K29-L29-E29)/D29) | P29: =IF(B29="","",O29/N29) | U29: =IF(S29="","",(T29-C29)) | V29: =IF(B29="","",IF(U29<3,(Q29-R29)/Q29,(Q29-R29-S29)/Q29)) | W29: =IF(B29="","",V29*P29*J29) | X29: =IF(B29="","",V29*P29*M29)
D30: =IF(B30="","",(C30-B30)*24*60) | G30: =IF(E30="","",F30-E30) | J30: =IF(B30="","",(D30-G30-H30-I30)/D30) | M30: =IF(B30="","",(D30-G30-H30-I30-K30-L30-E30)/D30) | P30: =IF(B30="","",O30/N30) | U30: =IF(S30="","",(T30-C30)) | V30: =IF(B30="","",IF(U30<3,(Q30-R30)/Q30,(Q30-R30-S30)/Q30)) | W30: =IF(B30="","",V30*P30*J30) | X30: =IF(B30="","",V30*P30*M30)
D31: =IF(B31="","",(C31-B31)*24*60) | G31: =IF(E31="","",F31-E31) | J31: =IF(B31="","",(D31-G31-H31-I31)/D31) | M31: =IF(B31="","",(D31-G31-H31-I31-K31-L31-E31)/D31) | P31: =IF(B31="","",O31/N31) | U31: =IF(S31="","",(T31-C31)) | V31: =IF(B31="","",IF(U31<3,(Q31-R31)/Q31,(Q31-R31-S31)/Q31)) | W31: =IF(B31="","",V31*P31*J31) | X31: =IF(B31="","",V31*P31*M31)
D32: =IF(B32="","",(C32-B32)*24*60) | G32: =IF(E32="","",F32-E32) | J32: =IF(B32="","",(D32-G32-H32-I32)/D32) | M32: =IF(B32="","",(D32-G32-H32-I32-K32-L32-E32)/D32) | P32: =IF(B32="","",O32/N32) | U32: =IF(S32="","",(T32-C32)) | V32: =IF(B32="","",IF(U32<3,(Q32-R32)/Q32,(Q32-R32-S32)/Q32)) | W32: =IF(B32="","",V32*P32*J32) | X32: =IF(B32="","",V32*P32*M32)
D33: =IF(B33="","",(C33-B33)*24*60) | G33: =IF(E33="","",F33-E33) | J33: =IF(B33="","",(D33-G33-H33-I33)/D33) | M33: =IF(B33="","",(D33-G33-H33-I33-K33-L33-E33)/D33) | P33: =IF(B33="","",O33/N33) | U33: =IF(S33="","",(T33-C33)) | V33: =IF(B33="","",IF(U33<3,(Q33-R33)/Q33,(Q33-R33-S33)/Q33)) | W33: =IF(B33="","",V33*P33*J33) | X33: =IF(B33="","",V33*P33*M33)
... D36: =IF(B36="","",(C36-B36)*24*60) | G36: =IF(E36="","",F36-E36) | J36: =IF(B36="","",(D36-G36-H36-I36)/D36) | M36: =IF(B36="","",(D36-G36-H36-I36-K36-L36-E36)/D36) | P36: =IF(B36="","",O36/N36) | U36: =IF(S36="","",(T36-C36)) | V36: =IF(B36="","",IF(U36<3,(Q36-R36)/Q36,(Q36-R36-S36)/Q36)) | W36: =IF(B36="","",V36*P36*J36) | X36: =IF(B36="","",V36*P36*M36)
D37: =IF(B37="","",(C37-B37)*24*60) | G37: =IF(E37="","",F37-E37) | J37: =IF(B37="","",(D37-G37-H37-I37)/D37) | M37: =IF(B37="","",(D37-G37-H37-I37-K37-L37-E37)/D37) | P37: =IF(B37="","",O37/N37) | V37: =IF(B37="","",IF(U37<3,(Q37-R37)/Q37,(Q37-R37-S37)/Q37)) | W37: =IF(B37="","",V37*P37*J37) | X37: =IF(B37="","",V37*P37*M37)
B38: Total | D38: =SUM(D3:D37) -> 24972 | E38: =SUM(E3:E37) -> 1187 | F38: =SUM(F3:F37) -> 1684 | G38: =SUM(G3:G37) -> 497 | H38: =SUM(H2:H37) -> 4244 | I38: =SUM(I3:I37) -> 1105 | J38: =(D38-G38-H38-I38)/D38 -> 0.76589781 | K38: =SUM(K3:K37) -> 215 | L38: =SUM(L3:L37) -> 2324 | M38: =(D38-G38-H38-I38-E38-K38-L38)/D38 -> 0.61669069 | N38: =AVERAGE(N3:N37) -> 17000 | O38: =AVERAGE(O3:O37) -> 17013.466 | P38: =O38/N38 -> 1.0007921 | Q38: =SUM(Q3:Q35) -> 131261 | V38: =AVERAGE(V3:V37) -> 0.98772836 | W38: =V38*P38*J38 -> 0.75709822 | X38: =V38*P38*M38 -> 0.60960538
D46: Real | E46: Opportunity
C47: OEE | D47: =W38 -> 0.75709822 | E47: =100%-D47 -> 0.24290178
C48: OEE Utilization | D48: =X38 -> 0.60960538 | E48: =100%-D48 -> 0.39039462
C49: Availability (for OEE) | D49: =J38 -> 0.76589781 | E49: =100%-D49 -> 0.23410219
...

Sheet March 2025 (w Utilization
C1: OEE Calculation | G1: CARIB BREWERY
A2: SKU | B2: Start Time dd/mm/yyyy h:mm | C2: End Time dd/mm/yyyy h:mm (when production actually ends) | D2: Available time /mins | E2: Changeover Standard time /mins | F2: Actual Changeover /mins | G2: Changeover Deviation /mins | H2: Total Breakdowns /mins | I2: Total Minor Stops /mins | J2: Availability (for OEE) | K2: Planned Downtime /mins | L2: External Downtime /mins | M2: Availability (for OEE Utilization) | N2: Nominal Speed | O2: Actual (Average) Speed | P2: Performance | Q2: Total Products Produced /Cases | R2: Low Fill /Cases | S2: Embargo /cases | T2: Embargo release date | U2: Embargo Residence time /days | V2: Quality | W2: OEE | X2: OEE Utilization
A3: Juicy Cool Club Soda to Banana to Cream Soda to Kola Champagne to Ginger to Grape | B3: 45719.115 | C3: 45719.928 | D3: =IF(B3="","",(C3-B3)*24*60) -> 1171 | E3: =20+20+20+20+20 -> 100 | F3: 106 | G3: =IF(E3="","",F3-E3) -> 6 | H3: =7+38+10+24+5 -> 84 | I3: =2+4+3+3+2+4+3+2+3+1+1+2+1+3+2+3+2+4+3+3+3+4+2+4 -> 64 | J3: =IF(B3="","",(D3-G3-H3-I3)/D3) -> 0.86848847 | K3: 0 | L3: =6+7+5+47+13+23 -> 101 | M3: =IF(B3="","",(D3-G3-H3-I3-K3-L3-E3)/D3) -> 0.69684031 | N3: 17000 | O3: =AVERAGE(17000,17000,17000,17000,15000,15000,17000,17000,17000) -> 16555.556 | P3: =IF(B3="","",O3/N3) -> 0.97385621 | Q3: =698+1290+657+661+1393+701 -> 5400 | R3: 33 | U3: =IF(S3="","",(T3-C3)) | V3: =IF(B3="","",IF(U3<3,(Q3-R3)/Q3,(Q3-R3-S3)/Q3)) -> 0.99388889 | W3: =IF(B3="","",V3*P3*J3) -> 0.84061422 | X3: =IF(B3="","",V3*P3*M3) -> 0.67447512
A4: Stag Local to Carib Amber to Ginseng Up Original | B4: 45720.115 | C4: 45720.904 | D4: =IF(B4="","",(C4-B4)*24*60) -> 1137 | E4: =10+40 -> 50 | F4: =104+15+56 -> 175 | G4: =IF(E4="","",F4-E4) -> 125 | H4: =20+7+13+5+5+13+6+9+7+6+12+7+5+5+24+32 -> 176 | I4: =2+3+4+1+2+1+2+1+2+2+2+1+1+1+1+2+3+3+2+3+2+4+1+1+4+1+3+4+4+3+2+2 -> 70 | J4: =IF(B4="","",(D4-G4-H4-I4)/D4) -> 0.67370273 | K4: 0 | L4: =9+2+41+8+5+3 -> 68 | M4: =IF(B4="","",(D4-G4-H4-I4-K4-L4-E4)/D4) -> 0.56992084 | N4: 17000 | O4: =AVERAGE(17000,17000,17000,17000,17000,17000,17000,17000,17000,17000,17000,17000,17000,17000,17000,17000) -> 17000 | P4: =IF(B4="","",O4/N4) -> 1 | Q4: =1703+5524 -> 7227 | R4: 46 | U4: =IF(S4="","",(T4-C4)) | V4: =IF(B4="","",IF(U4<3,(Q4-R4)/Q4,(Q4-R4-S4)/Q4)) -> 0.99363498 | W4: =IF(B4="","",V4*P4*J4) -> 0.6694146 | X4: =IF(B4="","",V4*P4*M4) -> 0.56629329
A5: Ginseng Up Original to Ginseng Up Apple to Juicy Cool Grape to Guinness | B5: 45721.005 | C5: 45722.925 | D5: =IF(B5="","",(C5-B5)*24*60) -> 2765 | E5: =45+120+100 -> 265 | F5: =35+218+48 -> 301 | G5: =IF(E5="","",F5-E5) -> 36 | H5: =12+6+9+6+7+5+12+8+5+9+9+6+5+6+6+6+15+6 -> 138 | I5: =2+3+4+3+2+4+4+2+1+4+4+4+4+2+3+2+3+3+2+2+4+2+3+3+2+3+3+2+2+3+4+2+4+3+3+3+4 -> 108 | J5: =IF(B5="","",(D5-G5-H5-I5)/D5) -> 0.89801085 | K5: 0 | L5: =2+11+30 -> 43 | M5: =IF(B5="","",(D5-G5-H5-I5-K5-L5-E5)/D5) -> 0.78661844 | N5: 17000 | O5: =AVERAGE(17000,17000,17000,17000,17000,17000,17000,17000,16500,16500,16500,16500,15000,17000) -> 16714.286 | P5: =IF(B5="","",O5/N5) -> 0.98319328 | Q5: =2856+1789+584 -> 5229 | R5: =11+14 -> 25 | U5: =IF(S5="","",(T5-C5)) | V5: =IF(B5="","",IF(U5<3,(Q5-R5)/Q5,(Q5-R5-S5)/Q5)) -> 0.99521897 | W5: =IF(B5="","",V5*P5*J5) -> 0.87869697 | X5: =IF(B5="","",V5*P5*M5) -> 0.76970033
A6: Guinness to Starmalt | B6: 45722.021 | C6: 45723.028 | D6: =IF(B6="","",(C6-B6)*24*60) -> 1450 | E6: 45 | F6: 79 | G6: =IF(E6="","",F6-E6) -> 34 | H6: =5+5+13+23+7+13+23+7+7+10+7+6+8+6+6+18+9+20+7+24+6+12+5+60+64+21+19+50+15+7+10+7 -> 500 | I6: =4+3+3+4+4+1+3+3+4+3+3+3+3+2+2+2+4+4+4+2+2+1+2+4+4+1+3+4+4+4 -> 90 | J6: =IF(B6="","",(D6-G6-H6-I6)/D6) -> 0.56965517 | K6: 0 | L6: =9+35+9+3 -> 56 | M6: =IF(B6="","",(D6-G6-H6-I6-K6-L6-E6)/D6) -> 0.5 | N6: 17000 | O6: =AVERAGE(17000,17000,17000,17000,17000,17000,17000,16500,16500,16500,16500,16500,17000,17000,17000,17000,17000) -> 16852.941 | P6: =IF(B6="","",O6/N6) -> 0.99134948 | Q6: =2928+2887 -> 5815 | R6: 29 | S6: =6+18 -> 24 | T6: 45723.396 | U6: =IF(S6="","",(T6-C6)) -> 0.36805556 | V6: =IF(B6="","",IF(U6<3,(Q6-R6)/Q6,(Q6-R6-S6)/Q6)) -> 0.9950129 | W6: =IF(B6="","",V6*P6*J6) -> 0.56191101 | X6: =IF(B6="","",V6*P6*M6) -> 0.49320276
A7: Stag local | B7: 45723.066 | C7: 45723.839 | D7: =IF(B7="","",(C7-B7)*24*60) -> 1113 | E7: 45 | F7: 55 | G7: =IF(E7="","",F7-E7) -> 10 | H7: =6+10+11+5+12+7+7+11 -> 69 | I7: =2+2+2+2+1+4+2+1+2+2+3+4+2+1+2+2+1+2+2+2 -> 41 | J7: =IF(B7="","",(D7-G7-H7-I7)/D7) -> 0.89218329 | K7: 0 | L7: =20+60+60+60+140+1+43+26+8 -> 418 | M7: =IF(B7="","",(D7-G7-H7-I7-K7-L7-E7)/D7) -> 0.47619048 | N7: 17000 | O7: =AVERAGE(17000,17000,17000,16600,16600,16500,16500,17000,17000) -> 16800 | P7: =IF(B7="","",O7/N7) -> 0.98823529 | Q7: 4977 | R7: =1+8 -> 9 | U7: =IF(S7="","",(T7-C7)) | V7: =IF(B7="","",IF(U7<3,(Q7-R7)/Q7,(Q7-R7-S7)/Q7)) -> 0.99819168 | W7: =IF(B7="","",V7*P7*J7) -> 0.88009264 | X7: =IF(B7="","",V7*P7*M7) -> 0.46973726
A8: Carib Amber | B8: 45726.389 | C8: 45726.912 | D8: =IF(B8="","",(C8-B8)*24*60) -> 754 | E8: 0 | F8: 0 | G8: =IF(E8="","",F8-E8) -> 0 | H8: =40+32+21+7+6+23+5+5+16+30+13+20 -> 218 | I8: 2 | J8: =IF(B8="","",(D8-G8-H8-I8)/D8) -> 0.70822281 | K8: 0 | L8: 18 | M8: =IF(B8="","",(D8-G8-H8-I8-K8-L8-E8)/D8) -> 0.68435013 | N8: 17000 | O8: =AVERAGE(11000,11000,11000,11000,11000,11000,11300,11300,11300,11300,11300,11300) -> 11150 | P8: =IF(B8="","",O8/N8) -> 0.65588235 | Q8: 3495 | R8: 85 | U8: =IF(S8="","",(T8-C8)) | V8: =IF(B8="","",IF(U8<3,(Q8-R8)/Q8,(Q8-R8-S8)/Q8)) -> 0.97567954 | W8: =IF(B8="","",V8*P8*J8) -> 0.45321373 | X8: =IF(B8="","",V8*P8*M8) -> 0.43793686
A9: Carib Amber to Stag to Starmalt | B9: 45727.347 | C9: 45727.951 | D9: =IF(B9="","",(C9-B9)*24*60) -> 870 | E9: =10+25 -> 35 | F9: =23+55 -> 78 | G9: =IF(E9="","",F9-E9) -> 43 | H9: =42+14+60+22+10+47+60+17+19 -> 291 | I9: =1+2+3 -> 6 | J9: =IF(B9="","",(D9-G9-H9-I9)/D9) -> 0.6091954 | K9: 0 | L9: 1 | M9: =IF(B9="","",(D9-G9-H9-I9-K9-L9-E9)/D9) -> 0.56781609 | N9: 17000 | O9: =AVERAGE(11000,11000,11000,11000,11000,11000,11000,11000) -> 11000 | P9: =IF(B9="","",O9/N9) -> 0.64705882 | Q9: 2831 | R9: 100 | U9: =IF(S9="","",(T9-C9)) | V9: =IF(B9="","",IF(U9<3,(Q9-R9)/Q9,(Q9-R9-S9)/Q9)) -> 0.96467679 | W9: =IF(B9="","",V9*P9*J9) -> 0.38026137 | X9: =IF(B9="","",V9*P9*M9) -> 0.3544323
A10: Starmalt | B10: 45728.614 | C10: 45728.86 | D10: =IF(B10="","",(C10-B10)*24*60) -> 355 | E10: 0 | F10: 0 | G10: =IF(E10="","",F10-E10) -> 0 | H10: =5+6+27+10+6+7 -> 61 | I10: =1+4+4+2 -> 11 | J10: =IF(B10="","",(D10-G10-H10-I10)/D10) -> 0.7971831 | K10: 0 | L10: =12+6+5 -> 23 | M10: =IF(B10="","",(D10-G10-H10-I10-K10-L10-E10)/D10) -> 0.73239437 | N10: 17000 | O10: =AVERAGE(11000,17000,17000,17000,17000,17000) -> 16000 | P10: =IF(B10="","",O10/N10) -> 0.94117647 | Q10: 2046 | R10: 30 | U10: =IF(S10="","",(T10-C10)) | V10: =IF(B10="","",IF(U10<3,(Q10-R10)/Q10,(Q10-R10-S10)/Q10)) -> 0.98533724 | W10: =IF(B10="","",V10*P10*J10) -> 0.73928866 | X10: =IF(B10="","",V10*P10*M10) -> 0.67920513
A11: Carib Amber | B11: 45729.414 | C11: 45729.919 | D11: =IF(B11="","",(C11-B11)*24*60) -> 727 | E11: 0 | F11: 0 | G11: =IF(E11="","",F11-E11) -> 0 | H11: =5+5+6+6+5 -> 27 | I11: =2+3+2+1+2+1+4+1+3+2+2+4+4+4+4+4+2+3+1 -> 49 | J11: =IF(B11="","",(D11-G11-H11-I11)/D11) -> 0.8954608 | K11: 0 | L11: =7+5+6+25 -> 43 | M11: =IF(B11="","",(D11-G11-H11-I11-K11-L11-E11)/D11) -> 0.83631362 | N11: 17000 | O11: =AVERAGE(17000,17000,17000,17000,17000,17000,17000,17000,17000,17000,17000,17000,17000) -> 17000 | P11: =IF(B11="","",O11/N11) -> 1 | Q11: 5465 | R11: =10.5+16 -> 26.5 | U11: =IF(S11="","",(T11-C11)) | V11: =IF(B11="","",IF(U11<3,(Q11-R11)/Q11,(Q11-R11-S11)/Q11)) -> 0.99515096 | W11: =IF(B11="","",V11*P11*J11) -> 0.89111867 | X11: =IF(B11="","",V11*P11*M11) -> 0.8322583
A12: Stag Local to Carib Amber | B12: 45730.374 | C12: 45730.831 | D12: =IF(B12="","",(C12-B12)*24*60) -> 659 | E12: 10 | F12: 10 | G12: =IF(E12="","",F12-E12) -> 0 | H12: =11+5+5+8 -> 29 | I12: =2+1+2+1+3+3+4+4+1 -> 21 | J12: =IF(B12="","",(D12-G12-H12-I12)/D12) -> 0.92412747 | K12: 0 | L12: =15+7+15+15 -> 52 | M12: =IF(B12="","",(D12-G12-H12-I12-K12-L12-E12)/D12) -> 0.83004552 | N12: 17000 | O12: =AVERAGE(17000,17000,17000,17000,17000,17000,17000,17000) -> 17000 | P12: =IF(B12="","",O12/N12) -> 1 | Q12: =2717+1403 -> 4120 | R12: =14+9 -> 23 | U12: =IF(S12="","",(T12-C12)) | V12: =IF(B12="","",IF(U12<3,(Q12-R12)/Q12,(Q12-R12-S12)/Q12)) -> 0.99441748 | W12: =IF(B12="","",V12*P12*J12) -> 0.9189685 | X12: =IF(B12="","",V12*P12*M12) -> 0.82541177
A13: Carib Amber to Stag | B13: 45733.625 | C13: 45734 | D13: =IF(B13="","",(C13-B13)*24*60) -> 540 | E13: 10 | F13: 21 | G13: =IF(E13="","",F13-E13) -> 11 | H13: =45+60+20+30+6+20+6+6+6+6+6 -> 211 | I13: =4+1+2+4+1+2+3+1+3+3 -> 24 | J13: =IF(B13="","",(D13-G13-H13-I13)/D13) -> 0.54444444 | K13: 0 | L13: =2+3+10 -> 15 | M13: =IF(B13="","",(D13-G13-H13-I13-K13-L13-E13)/D13) -> 0.49814815 | N13: 17000 | O13: =AVERAGE(17000,17000,17000,17000,17000) -> 17000 | P13: =IF(B13="","",O13/N13) -> 1 | Q13: 2299 | R13: 16 | U13: =IF(S13="","",(T13-C13)) | V13: =IF(B13="","",IF(U13<3,(Q13-R13)/Q13,(Q13-R13-S13)/Q13)) -> 0.99304045 | W13: =IF(B13="","",V13*P13*J13) -> 0.54065536 | X13: =IF(B13="","",V13*P13*M13) -> 0.49468126
A14: Stag Local to Carib Amber | B14: 45734 | C14: 45735 | D14: =IF(B14="","",(C14-B14)*24*60) -> 1440 | E14: 10 | F14: 10 | G14: =IF(E14="","",F14-E14) -> 0 | H14: =5+8+10+7+5+9+18+6+5+13+6+7 -> 99 | I14: =2+4+4+3+1+1+2+2+3+2+3+3+2+2+3+4+3+2+2+2+3+4+1+2+2 -> 62 | J14: =IF(B14="","",(D14-G14-H14-I14)/D14) -> 0.88819444 | K14: 0 | L14: =5+245+56+60+50+10+10+15+30+20+4+8+25+6+5 -> 549 | M14: =IF(B14="","",(D14-G14-H14-I14-K14-L14-E14)/D14) -> 0.5 | N14: 17000 | O14: =AVERAGE(17000,17000,17000,17000,17000,17000,17000,17000,17000,17000) -> 17000 | P14: =IF(B14="","",O14/N14) -> 1 | Q14: 6440 | R14: =5+14 -> 19 | S14: =70+40 -> 110 | T14: 45737.604 | U14: =IF(S14="","",(T14-C14)) -> 2.6041667 | V14: =IF(B14="","",IF(U14<3,(Q14-R14)/Q14,(Q14-R14-S14)/Q14)) -> 0.99704969 | W14: =IF(B14="","",V14*P14*J14) -> 0.88557399 | X14: =IF(B14="","",V14*P14*M14) -> 0.49852484
A15: Carib Amber to Carib Flint Local to Stag Local | B15: 45735 | C15: 45736.069 | D15: =IF(B15="","",(C15-B15)*24*60) -> 1540 | E15: =7+10 -> 17 | F15: =5+15 -> 20 | G15: =IF(E15="","",F15-E15) -> 3 | H15: =8+7+8+11+11+16+26+54+6+26+60+60+60+14+13+6+9+5+5+9+5+5 -> 424 | I15: =1+2+1+1+3+4+2+3+2+3+2+2+4+1+1+4+4+4+1+1+3+2+1+4+1+2+4+4+3+2+3+4+2+4+4+1+2+4+4+1+1+2 -> 104 | J15: =IF(B15="","",(D15-G15-H15-I15)/D15) -> 0.65519481 | K15: 0 | L15: =13 -> 13 | M15: =IF(B15="","",(D15-G15-H15-I15-K15-L15-E15)/D15) -> 0.63571429 | N15: 17000 | O15: =AVERAGE(17000,17000,17000,17000,17000,17000,17000,17000,17000,17000,17000,17000,17000,17000,17000,17000,17000,17000,17000) -> 17000 | P15: =IF(B15="","",O15/N15) -> 1 | Q15: 7597 | R15: 23 | S15: =22+10.18 -> 32.18 | T15: 45750.278 | U15: =IF(S15="","",(T15-C15)) -> 14.208333 | V15: =IF(B15="","",IF(U15<3,(Q15-R15)/Q15,(Q15-R15-S15)/Q15)) -> 0.99273661 | W15: =IF(B15="","",V15*P15*J15) -> 0.65043587 | X15: =IF(B15="","",V15*P15*M15) -> 0.63109684
A16: Guinness | B16: 45736.103 | C16: 45737 | D16: =IF(B16="","",(C16-B16)*24*60) -> 1292 | E16: 0 | F16: 48 | G16: =IF(E16="","",F16-E16) -> 48 | H16: =16+9+5+10+22+5+9+10+60+60+60+60+25+60+60+60+60+25+6 -> 622 | I16: =1+3+2+3+3+2+3+2+1+4+2+2+2+1+2+1+2+2+2+2+1+4+3+1+4+1+3+3+4+2+3+2+4+2+3+4+3+1 -> 90 | J16: =IF(B16="","",(D16-G16-H16-I16)/D16) -> 0.41176471 | K16: 0 | L16: =5+4+4+2+4+2+3+3+3 -> 30 | M16: =IF(B16="","",(D16-G16-H16-I16-K16-L16-E16)/D16) -> 0.38854489 | N16: 17000 | O16: =AVERAGE(15000,15000,15000,17000,17000,17000) -> 16000 | P16: =IF(B16="","",O16/N16) -> 0.94117647 | Q16: 4053 | R16: 8 | S16: 833 | T16: 45748.639 | U16: =IF(S16="","",(T16-C16)) -> 11.638889 | V16: =IF(B16="","",IF(U16<3,(Q16-R16)/Q16,(Q16-R16-S16)/Q16)) -> 0.79249938 | W16: =IF(B16="","",V16*P16*J16) -> 0.30712779 | X16: =IF(B16="","",V16*P16*M16) -> 0.28980855
A17: Guinness | B17: 45737.011 | C17: 45738.217 | D17: =IF(B17="","",(C17-B17)*24*60) -> 1736 | E17: 0 | F17: 0 | G17: =IF(E17="","",F17-E17) -> 0 | H17: =6+7+5+9 -> 27 | I17: =2+1+2+2+2+4+1+3+3+4+3 -> 27 | J17: =IF(B17="","",(D17-G17-H17-I17)/D17) -> 0.96889401 | K17: 0 | L17: =1+11+6+9 -> 27 | M17: =IF(B17="","",(D17-G17-H17-I17-K17-L17-E17)/D17) -> 0.95334101 | N17: 17000 | O17: =AVERAGE(17000,17000,17000,17000,17000) -> 17000 | P17: =IF(B17="","",O17/N17) -> 1 | Q17: 1771 | R17: 9 | U17: =IF(S17="","",(T17-C17)) | V17: =IF(B17="","",IF(U17<3,(Q17-R17)/Q17,(Q17-R17-S17)/Q17)) -> 0.99491813 | W17: =IF(B17="","",V17*P17*J17) -> 0.96397021 | X17: =IF(B17="","",V17*P17*M17) -> 0.94849625
A18: Carib Amber | B18: 45740.122 | C18: 45741 | D18: =IF(B18="","",(C18-B18)*24*60) -> 1265 | E18: 0 | F18: 0 | G18: =IF(E18="","",F18-E18) -> 0 | H18: =45+60+60+60+60+60+60+60+60+60+60+60+60+60+60+60+60+30+7+29+16+5+32 -> 1124 | I18: =2+4+3 -> 9 | J18: =IF(B18="","",(D18-G18-H18-I18)/D18) -> 0.10434783 | K18: 0 | L18: 0 | M18: =IF(B18="","",(D18-G18-H18-I18-K18-L18-E18)/D18) -> 0.10434783 | N18: 17000 | O18: =AVERAGE(17000,17000,17000) -> 17000 | P18: =IF(B18="","",O18/N18) -> 1 | Q18: 1021 | R18: 12 | U18: =IF(S18="","",(T18-C18)) | V18: =IF(B18="","",IF(U18<3,(Q18-R18)/Q18,(Q18-R18-S18)/Q18)) -> 0.98824682 | W18: =IF(B18="","",V18*P18*J18) -> 0.10312141 | X18: =IF(B18="","",V18*P18*M18) -> 0.10312141
A19: Carib Amber to Stag Local | B19: 45741 | C19: 45742 | D19: =IF(B19="","",(C19-B19)*24*60) -> 1440 | E19: 10 | F19: 14 | G19: =IF(E19="","",F19-E19) -> 4 | H19: =14+5+7+5+5+16+10+9+5+7+15+6+5+5+5+44+20+23+8+43+8+6+11+14 -> 296 | I19: =1+1+2+2+3+2+1+1+2+1+4+1+3+3+2+1+4+3+2+2+3+2+3+3+4+2+3+2+2+2+2+1+3+2+3+3+2+3+2+3+3+3+4+3+3+3+1+4+4+4+2+4+1+1 -> 131 | J19: =IF(B19="","",(D19-G19-H19-I19)/D19) -> 0.70069444 | K19: 0 | L19: =2+4+3+2+5+2+3+3+3+3+4+21+4 -> 59 | M19: =IF(B19="","",(D19-G19-H19-I19-K19-L19-E19)/D19) -> 0.65277778 | N19: 17000 | O19: =AVERAGE(1700,17000,17000,15000,17000,17000,17000,18000,18000,18000,18000,18000,18000,18000,18000,18000,18000,18000,18000) -> 16721.053 | P19: =IF(B19="","",O19/N19) -> 0.98359133 | Q19: 9446 | R19: =45+10 -> 55 | S19: 29.21 | T19: 45749.781 | U19: =IF(S19="","",(T19-C19)) -> 7.78125 | V19: =IF(B19="","",IF(U19<3,(Q19-R19)/Q19,(Q19-R19-S19)/Q19)) -> 0.99108512 | W19: =IF(B19="","",V19*P19*J19) -> 0.68305287 | X19: =IF(B19="","",V19*P19*M19) -> 0.63634261
A20: Stag Local to Carib Amber | B20: 45742.007 | C20: 45743 | D20: =IF(B20="","",(C20-B20)*24*60) -> 1430 | E20: 10 | F20: =14+35 -> 49 | G20: =IF(E20="","",F20-E20) -> 39 | H20: =38+50+7+7+6+9+35+5+15+6+5+10+8+16+10+45+5+6+12+5 -> 300 | I20: =2+3+1+1+2+2+3+1+4+2+1+3+3+4+2+4+1+3+3+1+3+3+1+1+3+2+2+2+4+4+2+2+2+2+1+1+4+2+1+3 -> 91 | J20: =IF(B20="","",(D20-G20-H20-I20)/D20) -> 0.6993007 | K20: 0 | L20: =2+3+4+3+20+5 -> 37 | M20: =IF(B20="","",(D20-G20-H20-I20-K20-L20-E20)/D20) -> 0.66643357 | N20: 17000 | O20: =AVERAGE(18000,18000,18000,17000,18000,18000,17000,17000,17000,17000,17000,17000,17000,17000,17000,17000,17000,18000,18000,18000,17000,17000) -> 17363.636 | P20: =IF(B20="","",O20/N20) -> 1.0213904 | Q20: 8929 | R20: =9+16 -> 25 | U20: =IF(S20="","",(T20-C20)) | V20: =IF(B20="","",IF(U20<3,(Q20-R20)/Q20,(Q20-R20-S20)/Q20)) -> 0.99720013 | W20: =IF(B20="","",V20*P20*J20) -> 0.71225917 | X20: =IF(B20="","",V20*P20*M20) -> 0.67878299
