Workbook

Sheet Entries December'25
B1: ENTRIES FOR DAILY CONS. MONITOR | O1: =B1 -> ENTRIES FOR DAILY CONS. MONITOR
C2: old | F2: old | O2: Service 227.3 cubic meters (2273 Hls)Filtered 189.3 cubic meters(1893 Hls)
D3: FUEL | J3: ELECT. | L3: CO2 | O3: WATER | AG3: CO2 Scrubber (m3) | AH3: Supply to Washdown Area (m3) | AI3: Supply to RUs (m3) | AJ3: Steam Mass Flow Meter | AL3: CO2 TANKS' READING
B4: Boilers tot. | C4: Boiler 1 | D4: Gen. meter | E4: Tank level | F4: Boiler 1 | G4: Boiler 2 | H4: Gen | I4: Meter1 | J4: Meter 2 | K4: Gen Meter | L4: Consumption (FILTRATION) (kg) | M4: Consumption (Totalizer Flowmeter) | N4: Consumption (Filler) (kg) | O4: Nawasa Meter (m3) | P4: Annandale Supply (m3) | Q4: Service Supply to Plant (m3) | R4: Cellars/Filtration (m3) | S4: Brewhouse Meter (m3) | T4: Cellars/Process Areas (m3) | U4: Pasteuriser (m3) | V4: Water Plant-Nawasa Annadale (m3) | W4: Water Plant-Well # 1 (m3) | X4: CIP Process | Y4: Bottle Washer | Z4: Boiler | AA4: Permeate #1 | AB4: Permeate #2 | AC4: Bottle Filler (m3) | AD4: RO # 1 Totaliser (m3) | AE4: RO # 2 Totaliser (m3) | AF4: Recovered Water (m3) | AL4: Tank "C" | AM4: Tank "A" | AN4: Tank "B" | AO4: Mobile Tanker
A5: DATE | B5: (liters) | C5: (liters) | D5: (Imp. gals) | E5: (inches) | F5: Hrs | G5: Hrs | H5: Hrs. | I5: (Kwhr) | J5: (Kwhr) | K5: (Kwhr) | M5: (kg) | X5: (m3) | Y5: (m3) | Z5: (m3) | AL5: inH2O | AM5: (Kg.) | AN5: (Kg.) | AO5: (pounds)
A6: 1 | B6: 7825550 | E6: 64 | F6: 6790.6 | G6: 68225 | I6: 129866 | K6: 468000 | L6: 6015.1 | M6: 199070.83 | N6: 31301.52 | O6: 207339 | P6: 45518 | Q6: 935429 | S6: 66072 | U6: 21879 | V6: 1324115 | X6: 40013 | Y6: 47792 | Z6: 10423 | AA6: 97122 | AC6: 2184 | AD6: 261383 | AJ6: 7316083.7
A7: 2 | B7: 7828340 | E7: 64 | F7: 6809.4 | G7: 68225 | I7: 136224 | K7: 468000 | L7: 6240.02 | M7: 201685.73 | N7: 31865.52 | O7: 207437 | P7: 45661 | Q7: 935697 | S7: 66100 | U7: 21897 | V7: 1324266 | X7: 40041 | Y7: 47959 | Z7: 10483 | AA7: 97122 | AC7: 2211 | AD7: 261383 | AJ7: 7316155.1
A8: 3 | B8: 7831470 | E8: 64 | F8: 6830.2 | G8: 68225 | I8: 142660 | K8: 468000 | L8: 6298.44 | M8: 202905.14 | N8: 32128.58 | O8: 207675 | P8: 45792 | Q8: 935862 | S8: 66252 | U8: 21904 | V8: 1324403 | X8: 40044 | Y8: 48043 | Z8: 10531 | AA8: 97122 | AC8: 2225 | AD8: 261383 | AJ8: 7316155.1
A9: 4 | B9: 7834620 | E9: 64 | F9: 6849.8 | G9: 68225 | I9: 150220 | K9: 468000 | L9: 6357.95 | M9: 205059 | N9: 32501.08 | O9: 207814 | P9: 46001 | Q9: 936091 | S9: 66369 | U9: 21914 | V9: 1324621 | X9: 40069 | Y9: 48161 | Z9: 10608 | AA9: 97122 | AC9: 2255 | AD9: 261424 | AJ9: 7316155.1
A10: 5 | B10: 7837540 | E10: 64 | F10: 6868 | G10: 68225 | I10: 158246 | K10: 468000 | L10: 6449.7 | M10: 206755.69 | N10: 32797.96 | O10: 208018 | P10: 46222 | Q10: 936317 | S10: 66509 | U10: 21921 | V10: 1324862 | X10: 40123 | Y10: 48246 | Z10: 10662 | AA10: 97122 | AC10: 2282 | AD10: 261445 | AJ10: 7316155.1
A11: 6 | B11: 7840360 | E11: 64 | F11: 6886.8 | G11: 68225 | I11: 164131 | K11: 468000 | L11: 6696.03 | M11: 208492.86 | N11: 33098.96 | O11: 208175 | P11: 46467 | Q11: 936514 | S11: 66592 | U11: 21927 | V11: 1325109 | X11: 40152 | Y11: 48338 | Z11: 10710 | AA11: 97122 | AC11: 2299 | AD11: 261493 | AJ11: 7316155.1
A12: 7 | B12: 7843730 | E12: 64 | F12: 6908.4 | G12: 68225 | I12: 170956 | K12: 468000 | L12: 6935.71 | M12: 210263.42 | N12: 33424 | O12: 208375 | P12: 46632 | Q12: 936721 | S12: 66714 | U12: 21941 | V12: 1325283 | X12: 40185 | Y12: 48439 | Z12: 10757 | AA12: 97122 | AC12: 2316 | AD12: 261443 | AJ12: 7316155.1
A13: 8 | B13: 7847150 | E13: 64 | F13: 6930.2 | G13: 68225 | I13: 178510 | K13: 468000 | L13: 7120.07 | M13: 212592.33 | N13: 33787.57 | O13: 208458 | P13: 46788 | Q13: 936907 | S13: 66833 | U13: 21947 | V13: 1325446 | X13: 40197 | Y13: 48544 | Z13: 10790 | AA13: 97122 | AC13: 2339 | AD13: 261443 | AJ13: 7316155.1
A14: 9 | B14: 7850780 | E14: 64 | F14: 6951.8 | G14: 68225 | I14: 185840 | K14: 468000 | L14: 7303.6 | M14: 215098.28 | N14: 34264.88 | O14: 208501 | P14: 47067 | Q14: 937158 | S14: 66929 | U14: 21951 | V14: 1325738 | X14: 40249 | Y14: 48654 | Z14: 10818 | AA14: 97122 | AC14: 2367 | AD14: 261443 | AJ14: 7316155.1
A15: 10 | B15: 7853640 | E15: 64 | F15: 6969.9 | G15: 68225 | I15: 192265 | K15: 468000 | L15: 7436.3 | M15: 216655.69 | N15: 34532.83 | O15: 208597 | P15: 47257 | Q15: 937345 | S15: 67093 | U15: 21954 | V15: 1325937 | X15: 40262 | Y15: 48744 | Z15: 10842 | AA15: 97122 | AC15: 2385 | AD15: 261443 | AJ15: 7316155.1
A16: 11 | B16: 7857440 | E16: 64 | F16: 6992.8 | G16: 68225 | I16: 200753 | K16: 468000 | L16: 7507.07 | M16: 219974.23 | N16: 35007.93 | O16: 208864 | P16: 47533 | Q16: 937678 | S16: 67258 | U16: 21964 | V16: 1326228 | X16: 40321 | Y16: 48887 | Z16: 10874 | AA16: 97122 | AC16: 2412 | AD16: 261505 | AJ16: 7316155.1
A17: 12 | B17: 7860120 | E17: 64 | F17: 7010.3 | G17: 68225 | I17: 207485 | K17: 468000 | L17: 7717.82 | M17: 222404.34 | N17: 35332.72 | O17: 209065 | P17: 47788 | Q17: 937913 | S17: 67339 | U17: 21982 | V17: 1326495 | X17: 40342 | Y17: 49018 | Z17: 10899 | AA17: 97122 | AC17: 2433 | AD17: 261596 | AJ17: 7316155.1
... A37: 1 | B37: 7901540 | E37: 64 | F37: 7271.9 | G37: 68225 | I37: 321444 | K37: 468000 | L37: 10303.43 | M37: 254572.72 | N37: 40557.95 | O37: 211566 | P37: 50353 | Q37: 941791 | S37: 68637 | U37: 22072 | V37: 1329822 | X37: 40874 | Y37: 50971 | Z37: 11281 | AA37: 97122 | AC37: 2788 | AD37: 261621 | AJ37: 7335297

Sheet Utility Analysis December'25 
K2: GRENADA BREWERIES LIMITED
K3: UTILITY ANALYSIS
A5: MONTH: | J5: 39295
A7: DATE | D7: ELECTRICITY GRENLEC | E7: Solar System CARIB | G7: % (Solar/Total Usage) | H7: CARIB GENSET | I7: ELECTRICITY TOTAL | J7: WATER | K7: FUEL | L7: CO2 | M7: PRODUCTION - HL | R7: UTILITY RATIOS
B8: METER 1 | C8: METER 2 | F8: TOTAL (KWH) | R8: Elect | S8: Water | T8: Fuel | U8: CO2
H9: USAGE (kwh) | I9: USAGE (kwh) | J9: USAGE (Hl) | K9: USAGE (l) | L9: USAGE (Kg.) | M9: BREWED | N9: BOTTLED | O9: KEGS | P9: OTHER | Q9: TOTAL | R9: KWH/Hl | S9: Hl/hl | T9: Litres/hl | U9: kg./Hl
A10: 1 | B10: =IF('Entries December''25'!I7<'Entries December''25'!I6,"0",(IF('Entries December''25'!I7>='Entries December''25'!I6,'Entries December''25'!I7-'Entries December''25'!I6,(999999-'Entries December''25'!I6)+'Entries December''25'!I7+1))) -> 6358 | C10: =IF('Entries December''25'!J7<='Entries December''25'!J6,"0",IF('Entries December''25'!J7>='Entries December''25'!J6,'Entries December''25'!J7-'Entries December''25'!J6,(999999-'Entries December''25'!J6)+'Entries December''25'!J7+1)) -> 0 | D10: =B10+C10 -> 6358 | E10: 1096.9 | F10: =D10+E10 -> 7454.9 | G10: =E10/(D10+E10) -> 0.14713812 | H10: =IF('Entries December''25'!K7<'Entries December''25'!K6,"0",IF('Entries December''25'!K7>='Entries December''25'!K6,'Entries December''25'!K7-'Entries December''25'!K6,(999999-'Entries December''25'!K6)+'Entries December''25'!K7+1)) -> 0 | I10: =D10+H10 -> 6358 | J10: ='Water '!Z7*10 -> 2410 | K10: =IF('Entries December''25'!B7-'Entries December''25'!B6<1,"0",'Entries December''25'!B7-'Entries December''25'!B6) -> 2790 | L10: ='CO2'!E7 -> 3000 | M10: =+'PROD.FIG. '!F5 -> 0 | N10: =+'PROD.FIG. '!C5 -> 0 | O10: =+'PROD.FIG. '!D5 -> 0 | P10: =+'PROD.FIG. '!E5 -> 0 | Q10: {=TRANSPOSE('Daily KPIs'!B9:AF9)} -> 455.136 | R10: =IF(Q10=0,0,I10/Q10) -> 13.969451 | S10: =IF(R10=0,0,J10/Q10) -> 5.2951206 | T10: =IF(S10=0,0,K10/Q10) -> 6.1300359 | U10: =IF(T10=0,0,L10/Q10) -> 6.5914364
A11: 2 | B11: =IF('Entries December''25'!I8<'Entries December''25'!I7,"0",(IF('Entries December''25'!I8>='Entries December''25'!I7,'Entries December''25'!I8-'Entries December''25'!I7,(999999-'Entries December''25'!I7)+'Entries December''25'!I8+1))) -> 6436 | C11: =IF('Entries December''25'!J8<='Entries December''25'!J7,"0",IF('Entries December''25'!J8>='Entries December''25'!J7,'Entries December''25'!J8-'Entries December''25'!J7,(999999-'Entries December''25'!J7)+'Entries December''25'!J8+1)) -> 0 | D11: =B11+C11 -> 6436 | E11: 891.6 | F11: =D11+E11 -> 7327.6 | G11: =E11/(D11+E11) -> 0.12167695 | H11: =IF('Entries December''25'!K8<'Entries December''25'!K7,"0",IF('Entries December''25'!K8>='Entries December''25'!K7,'Entries December''25'!K8-'Entries December''25'!K7,(999999-'Entries December''25'!K7)+'Entries December''25'!K8+1)) -> 0 | I11: =D11+H11 -> 6436 | J11: ='Water '!Z8*10 -> 3690 | K11: =IF('Entries December''25'!B8-'Entries December''25'!B7<1,"0",'Entries December''25'!B8-'Entries December''25'!B7) -> 3130 | L11: ='CO2'!E8 -> 1200 | M11: =+'PROD.FIG. '!F6 -> 0 | N11: =+'PROD.FIG. '!C6 -> 0 | O11: =+'PROD.FIG. '!D6 -> 0 | P11: =+'PROD.FIG. '!E6 -> 0 | Q11: 211.926 | R11: =IF(Q11=0,0,I11/Q11) -> 30.369091 | S11: =IF(R11=0,0,J11/Q11) -> 17.411738 | T11: =IF(S11=0,0,K11/Q11) -> 14.769306 | U11: =IF(T11=0,0,L11/Q11) -> 5.6623538
A12: 3 | B12: =IF('Entries December''25'!I9<'Entries December''25'!I8,"0",(IF('Entries December''25'!I9>='Entries December''25'!I8,'Entries December''25'!I9-'Entries December''25'!I8,(999999-'Entries December''25'!I8)+'Entries December''25'!I9+1))) -> 7560 | C12: =IF('Entries December''25'!J9<='Entries December''25'!J8,"0",IF('Entries December''25'!J9>='Entries December''25'!J8,'Entries December''25'!J9-'Entries December''25'!J8,(999999-'Entries December''25'!J8)+'Entries December''25'!J9+1)) -> 0 | D12: =B12+C12 -> 7560 | E12: 373.6 | F12: =D12+E12 -> 7933.6 | G12: =E12/(D12+E12) -> 0.047090854 | H12: =IF('Entries December''25'!K9<'Entries December''25'!K8,"0",IF('Entries December''25'!K9>='Entries December''25'!K8,'Entries December''25'!K9-'Entries December''25'!K8,(999999-'Entries December''25'!K8)+'Entries December''25'!K9+1)) -> 0 | I12: =D12+H12 -> 7560 | J12: ='Water '!Z9*10 -> 3480 | K12: =IF('Entries December''25'!B9-'Entries December''25'!B8<1,"0",'Entries December''25'!B9-'Entries December''25'!B8) -> 3150 | L12: ='CO2'!E9 -> 1700 | M12: =+'PROD.FIG. '!F7 -> 0 | N12: =+'PROD.FIG. '!C7 -> 0 | O12: =+'PROD.FIG. '!D7 -> 0 | P12: =+'PROD.FIG. '!E7 -> 0 | Q12: 346.5 | R12: =IF(Q12=0,0,I12/Q12) -> 21.818182 | S12: =IF(R12=0,0,J12/Q12) -> 10.04329 | T12: =IF(S12=0,0,K12/Q12) -> 9.0909091 | U12: =IF(T12=0,0,L12/Q12) -> 4.9062049
A13: 4 | B13: =IF('Entries December''25'!I10<'Entries December''25'!I9,"0",(IF('Entries December''25'!I10>='Entries December''25'!I9,'Entries December''25'!I10-'Entries December''25'!I9,(999999-'Entries December''25'!I9)+'Entries December''25'!I10+1))) -> 8026 | C13: =IF('Entries December''25'!J10<='Entries December''25'!J9,"0",IF('Entries December''25'!J10>='Entries December''25'!J9,'Entries December''25'!J10-'Entries December''25'!J9,(999999-'Entries December''25'!J9)+'Entries December''25'!J10+1)) -> 0 | D13: =B13+C13 -> 8026 | E13: 501.5 | F13: =D13+E13 -> 8527.5 | G13: =E13/(D13+E13) -> 0.058809733 | H13: =IF('Entries December''25'!K10<'Entries December''25'!K9,"0",IF('Entries December''25'!K10>='Entries December''25'!K9,'Entries December''25'!K10-'Entries December''25'!K9,(999999-'Entries December''25'!K9)+'Entries December''25'!K10+1)) -> 0 | I13: =D13+H13 -> 8026 | J13: ='Water '!Z10*10 -> 4250 | K13: =IF('Entries December''25'!B10-'Entries December''25'!B9<1,"0",'Entries December''25'!B10-'Entries December''25'!B9) -> 2920 | L13: ='CO2'!E10 -> 1600 | M13: =+'PROD.FIG. '!F8 -> 0 | N13: =+'PROD.FIG. '!C8 -> 0 | O13: =+'PROD.FIG. '!D8 -> 0 | P13: =+'PROD.FIG. '!E8 -> 0 | Q13: 253.836 | R13: =IF(Q13=0,0,I13/Q13) -> 31.618841 | S13: =IF(R13=0,0,J13/Q13) -> 16.743094 | T13: =IF(S13=0,0,K13/Q13) -> 11.50349 | U13: =IF(T13=0,0,L13/Q13) -> 6.3032824
A14: 5 | B14: =IF('Entries December''25'!I11<'Entries December''25'!I10,"0",(IF('Entries December''25'!I11>='Entries December''25'!I10,'Entries December''25'!I11-'Entries December''25'!I10,(999999-'Entries December''25'!I10)+'Entries December''25'!I11+1))) -> 5885 | C14: =IF('Entries December''25'!J11<='Entries December''25'!J10,"0",IF('Entries December''25'!J11>='Entries December''25'!J10,'Entries December''25'!J11-'Entries December''25'!J10,(999999-'Entries December''25'!J10)+'Entries December''25'!J11+1)) -> 0 | D14: =B14+C14 -> 5885 | E14: 1161.1 | F14: =D14+E14 -> 7046.1 | G14: =E14/(D14+E14) -> 0.16478619 | H14: =IF('Entries December''25'!K11<'Entries December''25'!K10,"0",IF('Entries December''25'!K11>='Entries December''25'!K10,'Entries December''25'!K11-'Entries December''25'!K10,(999999-'Entries December''25'!K10)+'Entries December''25'!K11+1)) -> 0 | I14: =D14+H14 -> 5885 | J14: ='Water '!Z11*10 -> 4020 | K14: =IF('Entries December''25'!B11-'Entries December''25'!B10<1,"0",'Entries December''25'!B11-'Entries December''25'!B10) -> 2820 | L14: ='CO2'!E11 -> 1600 | M14: =+'PROD.FIG. '!F9 -> 0 | N14: =+'PROD.FIG. '!C9 -> 0 | O14: =+'PROD.FIG. '!D9 -> 0 | P14: =+'PROD.FIG. '!E9 -> 0 | Q14: 262.746 | R14: =IF(Q14=0,0,I14/Q14) -> 22.398057 | S14: =IF(R14=0,0,J14/Q14) -> 15.299947 | T14: =IF(S14=0,0,K14/Q14) -> 10.732799 | U14: =IF(T14=0,0,L14/Q14) -> 6.0895313
A15: 6 | B15: =IF('Entries December''25'!I12<'Entries December''25'!I11,"0",(IF('Entries December''25'!I12>='Entries December''25'!I11,'Entries December''25'!I12-'Entries December''25'!I11,(999999-'Entries December''25'!I11)+'Entries December''25'!I12+1))) -> 6825 | C15: =IF('Entries December''25'!J12<='Entries December''25'!J11,"0",IF('Entries December''25'!J12>='Entries December''25'!J11,'Entries December''25'!J12-'Entries December''25'!J11,(999999-'Entries December''25'!J11)+'Entries December''25'!J12+1)) -> 0 | D15: =B15+C15 -> 6825 | E15: 1390.7 | F15: =D15+E15 -> 8215.7 | G15: =E15/(D15+E15) -> 0.16927346 | H15: =IF('Entries December''25'!K12<'Entries December''25'!K11,"0",IF('Entries December''25'!K12>='Entries December''25'!K11,'Entries December''25'!K12-'Entries December''25'!K11,(999999-'Entries December''25'!K11)+'Entries December''25'!K12+1)) -> 0 | I15: =D15+H15 -> 6825 | J15: ='Water '!Z12*10 -> 3650 | K15: =IF('Entries December''25'!B12-'Entries December''25'!B11<1,"0",'Entries December''25'!B12-'Entries December''25'!B11) -> 3370 | L15: ='CO2'!E12 -> 800 | M15: =+'PROD.FIG. '!F10 -> 0 | N15: =+'PROD.FIG. '!C10 -> 0 | O15: =+'PROD.FIG. '!D10 -> 0 | P15: =+'PROD.FIG. '!E10 -> 0 | Q15: 302.676 | R15: =IF(Q15=0,0,I15/Q15) -> 22.548864 | S15: =IF(R15=0,0,J15/Q15) -> 12.059099 | T15: =IF(S15=0,0,K15/Q15) -> 11.134018 | U15: =IF(T15=0,0,L15/Q15) -> 2.6430903
A16: 7 | B16: =IF('Entries December''25'!I13<'Entries December''25'!I12,"0",(IF('Entries December''25'!I13>='Entries December''25'!I12,'Entries December''25'!I13-'Entries December''25'!I12,(999999-'Entries December''25'!I12)+'Entries December''25'!I13+1))) -> 7554 | C16: =IF('Entries December''25'!J13<='Entries December''25'!J12,"0",IF('Entries December''25'!J13>='Entries December''25'!J12,'Entries December''25'!J13-'Entries December''25'!J12,(999999-'Entries December''25'!J12)+'Entries December''25'!J13+1)) -> 0 | D16: =B16+C16 -> 7554 | E16: 808.8 | F16: =D16+E16 -> 8362.8 | G16: =E16/(D16+E16) -> 0.096714019 | H16: =IF('Entries December''25'!K13<'Entries December''25'!K12,"0",IF('Entries December''25'!K13>='Entries December''25'!K12,'Entries December''25'!K13-'Entries December''25'!K12,(999999-'Entries December''25'!K12)+'Entries December''25'!K13+1)) -> 0 | I16: =D16+H16 -> 7554 | J16: ='Water '!Z13*10 -> 2390 | K16: =IF('Entries December''25'!B13-'Entries December''25'!B12<1,"0",'Entries December''25'!B13-'Entries December''25'!B12) -> 3420 | L16: ='CO2'!E13 -> 2900 | M16: =+'PROD.FIG. '!F11 -> 0 | N16: =+'PROD.FIG. '!C11 -> 0 | O16: =+'PROD.FIG. '!D11 -> 0 | P16: =+'PROD.FIG. '!E11 -> 0 | Q16: 388.5504 | R16: =IF(Q16=0,0,I16/Q16) -> 19.441493 | S16: =IF(R16=0,0,J16/Q16) -> 6.1510682 | T16: =IF(S16=0,0,K16/Q16) -> 8.8019469 | U16: =IF(T16=0,0,L16/Q16) -> 7.4636392
A17: 8 | B17: =IF('Entries December''25'!I14<'Entries December''25'!I13,"0",(IF('Entries December''25'!I14>='Entries December''25'!I13,'Entries December''25'!I14-'Entries December''25'!I13,(999999-'Entries December''25'!I13)+'Entries December''25'!I14+1))) -> 7330 | C17: =IF('Entries December''25'!J14<='Entries December''25'!J13,"0",IF('Entries December''25'!J14>='Entries December''25'!J13,'Entries December''25'!J14-'Entries December''25'!J13,(999999-'Entries December''25'!J13)+'Entries December''25'!J14+1)) -> 0 | D17: =B17+C17 -> 7330 | E17: 1313.3 | F17: =D17+E17 -> 8643.3 | G17: =E17/(D17+E17) -> 0.15194428 | H17: =IF('Entries December''25'!K14<'Entries December''25'!K13,"0",IF('Entries December''25'!K14>='Entries December''25'!K13,'Entries December''25'!K14-'Entries December''25'!K13,(999999-'Entries December''25'!K13)+'Entries December''25'!K14+1)) -> 0 | I17: =D17+H17 -> 7330 | J17: ='Water '!Z14*10 -> 3220 | K17: =IF('Entries December''25'!B14-'Entries December''25'!B13<1,"0",'Entries December''25'!B14-'Entries December''25'!B13) -> 3630 | L17: ='CO2'!E14 -> 2000 | M17: =+'PROD.FIG. '!F12 -> 0 | N17: =+'PROD.FIG. '!C12 -> 0 | O17: =+'PROD.FIG. '!D12 -> 0 | P17: =+'PROD.FIG. '!E12 -> 0 | Q17: 447.8844 | R17: =IF(Q17=0,0,I17/Q17) -> 16.36583 | S17: =IF(R17=0,0,J17/Q17) -> 7.1893551 | T17: =IF(S17=0,0,K17/Q17) -> 8.1047699 | U17: =IF(T17=0,0,L17/Q17) -> 4.465438
A18: 9 | B18: =IF('Entries December''25'!I15<'Entries December''25'!I14,"0",(IF('Entries December''25'!I15>='Entries December''25'!I14,'Entries December''25'!I15-'Entries December''25'!I14,(999999-'Entries December''25'!I14)+'Entries December''25'!I15+1))) -> 6425 | C18: =IF('Entries December''25'!J15<='Entries December''25'!J14,"0",IF('Entries December''25'!J15>='Entries December''25'!J14,'Entries December''25'!J15-'Entries December''25'!J14,(999999-'Entries December''25'!J14)+'Entries December''25'!J15+1)) -> 0 | D18: =B18+C18 -> 6425 | E18: 1380 | F18: =D18+E18 -> 7805 | G18: =E18/(D18+E18) -> 0.17680974 | H18: =IF('Entries December''25'!K15<'Entries December''25'!K14,"0",IF('Entries December''25'!K15>='Entries December''25'!K14,'Entries December''25'!K15-'Entries December''25'!K14,(999999-'Entries December''25'!K14)+'Entries December''25'!K15+1)) -> 0 | I18: =D18+H18 -> 6425 | J18: ='Water '!Z15*10 -> 2860 | K18: =IF('Entries December''25'!B15-'Entries December''25'!B14<1,"0",'Entries December''25'!B15-'Entries December''25'!B14) -> 2860 | L18: ='CO2'!E15 -> 900 | M18: =+'PROD.FIG. '!F13 -> 0 | N18: =+'PROD.FIG. '!C13 -> 0 | O18: =+'PROD.FIG. '!D13 -> 0 | P18: =+'PROD.FIG. '!E13 -> 0 | Q18: 214.764 | R18: =IF(Q18=0,0,I18/Q18) -> 29.91656 | S18: =IF(R18=0,0,J18/Q18) -> 13.316943 | T18: =IF(S18=0,0,K18/Q18) -> 13.316943 | U18: =IF(T18=0,0,L18/Q18) -> 4.1906465
A19: 10 | B19: =IF('Entries December''25'!I16<'Entries December''25'!I15,"0",(IF('Entries December''25'!I16>='Entries December''25'!I15,'Entries December''25'!I16-'Entries December''25'!I15,(999999-'Entries December''25'!I15)+'Entries December''25'!I16+1))) -> 8488 | C19: =IF('Entries December''25'!J16<='Entries December''25'!J15,"0",IF('Entries December''25'!J16>='Entries December''25'!J15,'Entries December''25'!J16-'Entries December''25'!J15,(999999-'Entries December''25'!J15)+'Entries December''25'!J16+1)) -> 0 | D19: =B19+C19 -> 8488 | E19: 1372.1 | F19: =D19+E19 -> 9860.1 | G19: =E19/(D19+E19) -> 0.1391568 | H19: =IF('Entries December''25'!K16<'Entries December''25'!K15,"0",IF('Entries December''25'!K16>='Entries December''25'!K15,'Entries December''25'!K16-'Entries December''25'!K15,(999999-'Entries December''25'!K15)+'Entries December''25'!K16+1)) -> 0 | I19: =D19+H19 -> 8488 | J19: ='Water '!Z16*10 -> 5430 | K19: =IF('Entries December''25'!B16-'Entries December''25'!B15<1,"0",'Entries December''25'!B16-'Entries December''25'!B15) -> 3800 | L19: ='CO2'!E16 -> 4800 | M19: =+'PROD.FIG. '!F14 -> 0 | N19: =+'PROD.FIG. '!C14 -> 0 | O19: =+'PROD.FIG. '!D14 -> 0 | P19: =+'PROD.FIG. '!E14 -> 0 | Q19: 437.052 | R19: =IF(Q19=0,0,I19/Q19) -> 19.42103 | S19: =IF(R19=0,0,J19/Q19) -> 12.424151 | T19: =IF(S19=0,0,K19/Q19) -> 8.6946176 | U19: =IF(T19=0,0,L19/Q19) -> 10.982675
A20: 11 | B20: =IF('Entries December''25'!I17<'Entries December''25'!I16,"0",(IF('Entries December''25'!I17>='Entries December''25'!I16,'Entries December''25'!I17-'Entries December''25'!I16,(999999-'Entries December''25'!I16)+'Entries December''25'!I17+1))) -> 6732 | C20: =IF('Entries December''25'!J17<='Entries December''25'!J16,"0",IF('Entries December''25'!J17>='Entries December''25'!J16,'Entries December''25'!J17-'Entries December''25'!J16,(999999-'Entries December''25'!J16)+'Entries December''25'!J17+1)) -> 0 | D20: =B20+C20 -> 6732 | E20: 1466.4 | F20: =D20+E20 -> 8198.4 | G20: =E20/(D20+E20) -> 0.17886417 | H20: =IF('Entries December''25'!K17<'Entries December''25'!K16,"0",IF('Entries December''25'!K17>='Entries December''25'!K16,'Entries December''25'!K17-'Entries December''25'!K16,(999999-'Entries December''25'!K16)+'Entries December''25'!K17+1)) -> 0 | I20: =D20+H20 -> 6732 | J20: ='Water '!Z17*10 -> 4560 | K20: =IF('Entries December''25'!B17-'Entries December''25'!B16<1,"0",'Entries December''25'!B17-'Entries December''25'!B16) -> 2680 | L20: ='CO2'!E17 -> 2000 | M20: =+'PROD.FIG. '!F15 -> 0 | N20: =+'PROD.FIG. '!C15 -> 0 | O20: =+'PROD.FIG. '!D15 -> 0 | P20: =+'PROD.FIG. '!E15 -> 0 | Q20: 332.838 | R20: =IF(Q20=0,0,I20/Q20) -> 20.226056 | S20: =IF(R20=0,0,J20/Q20) -> 13.700359 | T20: =IF(S20=0,0,K20/Q20) -> 8.0519652 | U20: =IF(T20=0,0,L20/Q20) -> 6.0089293
A21: 12 | B21: =IF('Entries December''25'!I18<'Entries December''25'!I17,"0",(IF('Entries December''25'!I18>='Entries December''25'!I17,'Entries December''25'!I18-'Entries December''25'!I17,(999999-'Entries December''25'!I17)+'Entries December''25'!I18+1))) -> 6620 | C21: =IF('Entries December''25'!J18<='Entries December''25'!J17,"0",IF('Entries December''25'!J18>='Entries December''25'!J17,'Entries December''25'!J18-'Entries December''25'!J17,(999999-'Entries December''25'!J17)+'Entries December''25'!J18+1)) -> 0 | D21: =B21+C21 -> 6620 | E21: 1166.2 | F21: =D21+E21 -> 7786.2 | G21: =E21/(D21+E21) -> 0.14977781 | H21: =IF('Entries December''25'!K18<'Entries December''25'!K17,"0",IF('Entries December''25'!K18>='Entries December''25'!K17,'Entries December''25'!K18-'Entries December''25'!K17,(999999-'Entries December''25'!K17)+'Entries December''25'!K18+1)) -> 0 | I21: =D21+H21 -> 6620 | J21: ='Water '!Z18*10 -> 2370 | K21: =IF('Entries December''25'!B18-'Entries December''25'!B17<1,"0",'Entries December''25'!B18-'Entries December''25'!B17) -> 3090 | L21: ='CO2'!E18 -> 1600 | M21: =+'PROD.FIG. '!F16 -> 0 | N21: =+'PROD.FIG. '!C16 -> 0 | O21: =+'PROD.FIG. '!D16 -> 0 | P21: =+'PROD.FIG. '!E16 -> 0 | Q21: 259.05 | R21: =IF(Q21=0,0,I21/Q21) -> 25.554912 | S21: =IF(R21=0,0,J21/Q21) -> 9.148813 | T21: =IF(S21=0,0,K21/Q21) -> 11.928199 | U21: =IF(T21=0,0,L21/Q21) -> 6.1764138
A22: 13 | B22: =IF('Entries December''25'!I19<'Entries December''25'!I18,"0",(IF('Entries December''25'!I19>='Entries December''25'!I18,'Entries December''25'!I19-'Entries December''25'!I18,(999999-'Entries December''25'!I18)+'Entries December''25'!I19+1))) -> 4519 | C22: =IF('Entries December''25'!J19<='Entries December''25'!J18,"0",IF('Entries December''25'!J19>='Entries December''25'!J18,'Entries December''25'!J19-'Entries December''25'!J18,(999999-'Entries December''25'!J18)+'Entries December''25'!J19+1)) -> 0 | D22: =B22+C22 -> 4519 | E22: 1223.1 | F22: =D22+E22 -> 5742.1 | G22: =E22/(D22+E22) -> 0.21300569 | H22: =IF('Entries December''25'!K19<'Entries December''25'!K18,"0",IF('Entries December''25'!K19>='Entries December''25'!K18,'Entries December''25'!K19-'Entries December''25'!K18,(999999-'Entries December''25'!K18)+'Entries December''25'!K19+1)) -> 0 | I22: =D22+H22 -> 4519 | J22: ='Water '!Z19*10 -> 1460 | K22: =IF('Entries December''25'!B19-'Entries December''25'!B18<1,"0",'Entries December''25'!B19-'Entries December''25'!B18) -> 1470 | L22: ='CO2'!E19 -> 200 | M22: =+'PROD.FIG. '!F17 -> 0 | N22: =+'PROD.FIG. '!C17 -> 0 | O22: =+'PROD.FIG. '!D17 -> 0 | P22: =+'PROD.FIG. '!E17 -> 0 | Q22: 190.608 | R22: =IF(Q22=0,0,I22/Q22) -> 23.708344 | S22: =IF(R22=0,0,J22/Q22) -> 7.6596995 | T22: =IF(S22=0,0,K22/Q22) -> 7.7121632 | U22: =IF(T22=0,0,L22/Q22) -> 1.0492739
... A39: 30 | B39: =IF('Entries December''25'!I36<'Entries December''25'!I35,"0",(IF('Entries December''25'!I36>='Entries December''25'!I35,'Entries December''25'!I36-'Entries December''25'!I35,(999999-'Entries December''25'!I35)+'Entries December''25'!I36+1))) -> 7806 | C39: =IF('Entries December''25'!J36<='Entries December''25'!J35,"0",IF('Entries December''25'!J36>='Entries December''25'!J35,'Entries December''25'!J36-'Entries December''25'!J35,(999999-'Entries December''25'!J35)+'Entries December''25'!J36+1)) -> 0 | D39: =B39+C39 -> 7806 | E39: 1196.3 | F39: =D39+E39 -> 9002.3 | G39: =E39/(D39+E39) -> 0.13288826 | H39: =IF('Entries December''25'!K36<'Entries December''25'!K35,"0",IF('Entries December''25'!K36>='Entries December''25'!K35,'Entries December''25'!K36-'Entries December''25'!K35,(999999-'Entries December''25'!K35)+'Entries December''25'!K36+1)) -> 0 | I39: =D39+H39 -> 7806 | J39: ='Water '!Z36*10 -> 3510 | K39: =IF('Entries December''25'!B36-'Entries December''25'!B35<1,"0",'Entries December''25'!B36-'Entries December''25'!B35) -> 3660 | L39: ='CO2'!E36 -> 1700 | M39: =+'PROD.FIG. '!F34 -> 0 | N39: =+'PROD.FIG. '!C34 -> 0 | O39: =+'PROD.FIG. '!D34 -> 0 | P39: =+'PROD.FIG. '!E34 -> 0 | Q39: 513.018 | R39: =IF(Q39=0,0,I39/Q39) -> 15.21584 | S39: =IF(R39=0,0,J39/Q39) -> 6.8418652 | T39: =IF(S39=0,0,K39/Q39) -> 7.1342526 | U39: =IF(T39=0,0,L39/Q39) -> 3.3137239
A40: 31 | B40: =IF('Entries December''25'!I37<'Entries December''25'!I36,"0",(IF('Entries December''25'!I37>='Entries December''25'!I36,'Entries December''25'!I37-'Entries December''25'!I36,(999999-'Entries December''25'!I36)+'Entries December''25'!I37+1))) -> 7082 | C40: =IF('Entries December''25'!J37<='Entries December''25'!J36,"0",IF('Entries December''25'!J37>='Entries December''25'!J36,'Entries December''25'!J37-'Entries December''25'!J36,(999999-'Entries December''25'!J36)+'Entries December''25'!J37+1)) -> 0 | D40: =B40+C40 -> 7082 | E40: 1307.3 | F40: =D40+E40 -> 8389.3 | G40: =E40/(D40+E40) -> 0.15582945 | H40: =IF('Entries December''25'!K37<'Entries December''25'!K36,"0",IF('Entries December''25'!K37>='Entries December''25'!K36,'Entries December''25'!K37-'Entries December''25'!K36,(999999-'Entries December''25'!K36)+'Entries December''25'!K37+1)) -> 0 | I40: =D40+H40 -> 7082 | J40: ='Water '!Z37*10 -> 3150 | K40: =IF('Entries December''25'!B37-'Entries December''25'!B36<1,"0",'Entries December''25'!B37-'Entries December''25'!B36) -> 2570 | L40: ='CO2'!E37 -> 1600 | Q40: 430.518 | R40: =IF(Q40=0,0,I40/Q40) -> 16.449951 | S40: =IF(R40=0,0,J40/Q40) -> 7.3167672 | T40: =IF(S40=0,0,K40/Q40) -> 5.969553 | U40: =IF(T40=0,0,L40/Q40) -> 3.7164532
R41: MTD
D42: Kwhr | H42: Kwhr | I42: Kwhr | J42: Hl | K42: L | L42: kg. | M42: hl | N42: hl | O42: hl | P42: hl | Q42: hl | R42: Elect | S42: Water | T42: Fuel | U42: CO2
A43: Total | D43: =SUM(D10:D40) -> 191578 | E43: =SUM(E10:E40) -> 35002.7 | F43: =SUM(F10:F40) -> 226580.7 | G43: =E43/(D43+E43) -> 0.15448227 | H43: =SUM(H10:H40) -> 0 | I43: =SUM(I10:I40) -> 191578 | J43: =SUM(J10:J40) -> 90620 | K43: =SUM(K10:K40) -> 75990 | L43: =SUM(L10:L40) -> 54700 | M43: =SUM(M10:M40) -> 0 | N43: =SUM(N10:N40) -> 0 | O43: =SUM(O10:O40) -> 0 | ... Q43: =SUM(Q10:Q40) -> 9272.0823 | R43: KWH/Hl | S43: Hl/hl | T43: Litres/hl | U43: kg./Hl
R44: =IF(Q43=0,0,I43/Q43) -> 20.66181 | S44: =IF(R44=0,0,J43/Q43) -> 9.7734249 | T44: =IF(S44=0,0,K43/Q43) -> 8.1955701 | U44: =IF(T44=0,0,L43/Q43) -> 5.8994299

Sheet Steam Mass Flow 
A3: DATE | B3: Steam Mass Flow Reading
A5: 1 | B5: =IF('Entries December''25'!AJ7-'Entries December''25'!AJ6<1,"0",'Entries December''25'!AJ7-'Entries December''25'!AJ6) -> 71.316
A6: 2 | B6: =IF('Entries December''25'!AJ8-'Entries December''25'!AJ7<1,"0",'Entries December''25'!AJ8-'Entries December''25'!AJ7) -> 0
A7: 3 | B7: =IF('Entries December''25'!AJ9-'Entries December''25'!AJ8<1,"0",'Entries December''25'!AJ9-'Entries December''25'!AJ8) -> 0
A8: 4 | B8: =IF('Entries December''25'!AJ10-'Entries December''25'!AJ9<1,"0",'Entries December''25'!AJ10-'Entries December''25'!AJ9) -> 0
A9: 5 | B9: =IF('Entries December''25'!AJ11-'Entries December''25'!AJ10<1,"0",'Entries December''25'!AJ11-'Entries December''25'!AJ10) -> 0
A10: 6 | B10: =IF('Entries December''25'!AJ12-'Entries December''25'!AJ11<1,"0",'Entries December''25'!AJ12-'Entries December''25'!AJ11) -> 0
A11: 7 | B11: =IF('Entries December''25'!AJ13-'Entries December''25'!AJ12<1,"0",'Entries December''25'!AJ13-'Entries December''25'!AJ12) -> 0
A12: 8 | B12: =IF('Entries December''25'!AJ14-'Entries December''25'!AJ13<1,"0",'Entries December''25'!AJ14-'Entries December''25'!AJ13) -> 0
A13: 9 | B13: =IF('Entries December''25'!AJ15-'Entries December''25'!AJ14<1,"0",'Entries December''25'!AJ15-'Entries December''25'!AJ14) -> 0
A14: 10 | B14: =IF('Entries December''25'!AJ16-'Entries December''25'!AJ15<1,"0",'Entries December''25'!AJ16-'Entries December''25'!AJ15) -> 0
A15: 11 | B15: =IF('Entries December''25'!AJ17-'Entries December''25'!AJ16<1,"0",'Entries December''25'!AJ17-'Entries December''25'!AJ16) -> 0
A16: 12 | B16: =IF('Entries December''25'!AJ18-'Entries December''25'!AJ17<1,"0",'Entries December''25'!AJ18-'Entries December''25'!AJ17) -> 0
... A35: 31 | B35: =IF('Entries December''25'!AJ37-'Entries December''25'!AJ36<1,"0",'Entries December''25'!AJ37-'Entries December''25'!AJ36) -> 19044.02
B36: =SUM(B5:B35) -> 19213.26

Sheet Fuel 
A1: DAILY FUEL CONSUMPTION FOR DECEMBER 2025
A4: DATE | B4: Boiler 1 | C4: Boiler 1 | D4: Boiler 2 | E4: Boiler 2 | F4: Gen. | G4: Gen | H4: Boiler 1 sp. | I4: Boiler 2 sp. | J4: Gen. sp | K4: Daily cons. | L4: Total Prod.(HL) | M4: Fuel(Litres/HL)
B5: Cons ( l ) | C5: Hrs | D5: Cons ( l ) | E5: Hrs | F5: Cons ( l ) | G5: Hrs | H5: cons (l/hr) | I5: cons (l/hr) | J5: Cons.(l/hr) | K5: (litres)
A7: 1 | B7: =IF('Entries December''25'!B7-'Entries December''25'!B6<1,"0",'Entries December''25'!B7-'Entries December''25'!B6) -> 2790 | C7: =IF('Entries December''25'!F7-'Entries December''25'!F6<1,"0",'Entries December''25'!F7-'Entries December''25'!F6) -> 18.8 | D7: =IF('Entries December''25'!C6=0,0,+'Entries December''25'!C6-'Entries December''25'!#REF!) -> 0 | E7: =IF('Entries December''25'!G7-'Entries December''25'!G6<1,"0",'Entries December''25'!G7-'Entries December''25'!G6) -> 0 | H7: =IF(C7+E7=0,"0", B7/(C7+E7)) -> 148.40426 | I7: =IF(E7=0,"0", D7/E7) -> 0 | J7: =IF(G7=0,"0", F7/G7) -> 0 | K7: =B7+D7+F7 -> 2790 | L7: {=IF(TRANSPOSE('Daily KPIs'!B9:AF9)=0,"0",TRANSPOSE('Daily KPIs'!B9:AF9))} -> 455.136 | M7: =IF(L7=0,"0",(K7/L7)) -> 6.1300359
A8: 2 | B8: =IF('Entries December''25'!B8-'Entries December''25'!B7<1,"0",'Entries December''25'!B8-'Entries December''25'!B7) -> 3130 | C8: =IF('Entries December''25'!F8-'Entries December''25'!F7<1,"0",'Entries December''25'!F8-'Entries December''25'!F7) -> 20.8 | D8: =IF('Entries December''25'!C7=0,0,+'Entries December''25'!C7-'Entries December''25'!C6) -> 0 | E8: =IF('Entries December''25'!G8-'Entries December''25'!G7<1,"0",'Entries December''25'!G8-'Entries December''25'!G7) -> 0 | H8: =IF(C8+E8=0,"0", B8/(C8+E8)) -> 150.48077 | I8: =IF(E8=0,"0", D8/E8) -> 0 | J8: =IF(G8=0,"0", F8/G8) -> 0 | K8: =B8+D8+F8 -> 3130 | L8: 211.926 | M8: =IF(L8=0,"0",(K8/L8)) -> 14.769306
A9: 3 | B9: =IF('Entries December''25'!B9-'Entries December''25'!B8<1,"0",'Entries December''25'!B9-'Entries December''25'!B8) -> 3150 | C9: =IF('Entries December''25'!F9-'Entries December''25'!F8<1,"0",'Entries December''25'!F9-'Entries December''25'!F8) -> 19.6 | D9: =IF('Entries December''25'!C8=0,0,+'Entries December''25'!C8-'Entries December''25'!C7) -> 0 | E9: =IF('Entries December''25'!G9-'Entries December''25'!G8<1,"0",'Entries December''25'!G9-'Entries December''25'!G8) -> 0 | H9: =IF(C9+E9=0,"0", B9/(C9+E9)) -> 160.71429 | I9: =IF(E9=0,"0", D9/E9) -> 0 | J9: =IF(G9=0,"0", F9/G9) -> 0 | K9: =B9+D9+F9 -> 3150 | L9: 346.5 | M9: =IF(L9=0,"0",(K9/L9)) -> 9.0909091
A10: 4 | B10: =IF('Entries December''25'!B10-'Entries December''25'!B9<1,"0",'Entries December''25'!B10-'Entries December''25'!B9) -> 2920 | C10: =IF('Entries December''25'!F10-'Entries December''25'!F9<1,"0",'Entries December''25'!F10-'Entries December''25'!F9) -> 18.2 | D10: =IF('Entries December''25'!C11=0,0,+'Entries December''25'!C11-'Entries December''25'!C8) -> 0 | E10: =IF('Entries December''25'!G10-'Entries December''25'!G9<1,"0",'Entries December''25'!G10-'Entries December''25'!G9) -> 0 | H10: =IF(C10+E10=0,"0", B10/(C10+E10)) -> 160.43956 | I10: =IF(E10=0,"0", D10/E10) -> 0 | J10: =IF(G10=0,"0", F10/G10) -> 0 | K10: =B10+D10+F10 -> 2920 | L10: 253.836 | M10: =IF(L10=0,"0",(K10/L10)) -> 11.50349
A11: 5 | B11: =IF('Entries December''25'!B11-'Entries December''25'!B10<1,"0",'Entries December''25'!B11-'Entries December''25'!B10) -> 2820 | C11: =IF('Entries December''25'!F11-'Entries December''25'!F10<1,"0",'Entries December''25'!F11-'Entries December''25'!F10) -> 18.8 | D11: =IF('Entries December''25'!C10=0,0,+'Entries December''25'!C10-'Entries December''25'!C11) -> 0 | E11: =IF('Entries December''25'!G11-'Entries December''25'!G10<1,"0",'Entries December''25'!G11-'Entries December''25'!G10) -> 0 | H11: =IF(C11+E11=0,"0", B11/(C11+E11)) -> 150 | I11: =IF(E11=0,"0", D11/E11) -> 0 | J11: =IF(G11=0,"0", F11/G11) -> 0 | K11: =B11+D11+F11 -> 2820 | L11: 262.746 | M11: =IF(L11=0,"0",(K11/L11)) -> 10.732799
A12: 6 | B12: =IF('Entries December''25'!B12-'Entries December''25'!B11<1,"0",'Entries December''25'!B12-'Entries December''25'!B11) -> 3370 | C12: =IF('Entries December''25'!F12-'Entries December''25'!F11<1,"0",'Entries December''25'!F12-'Entries December''25'!F11) -> 21.6 | D12: =IF('Entries December''25'!C12=0,0,+'Entries December''25'!C12-'Entries December''25'!C10) -> 0 | E12: =IF('Entries December''25'!G12-'Entries December''25'!G11<1,"0",'Entries December''25'!G12-'Entries December''25'!G11) -> 0 | H12: =IF(C12+E12=0,"0", B12/(C12+E12)) -> 156.01852 | I12: =IF(E12=0,"0", D12/E12) -> 0 | J12: =IF(G12=0,"0", F12/G12) -> 0 | K12: =B12+D12+F12 -> 3370 | L12: 302.676 | M12: =IF(L12=0,"0",(K12/L12)) -> 11.134018
A13: 7 | B13: =IF('Entries December''25'!B13-'Entries December''25'!B12<1,"0",'Entries December''25'!B13-'Entries December''25'!B12) -> 3420 | C13: =IF('Entries December''25'!F13-'Entries December''25'!F12<1,"0",'Entries December''25'!F13-'Entries December''25'!F12) -> 21.8 | D13: =IF('Entries December''25'!C13=0,0,+'Entries December''25'!C13-'Entries December''25'!C11) -> 0 | E13: =IF('Entries December''25'!G13-'Entries December''25'!G12<1,"0",'Entries December''25'!G13-'Entries December''25'!G12) -> 0 | H13: =IF(C13+E13=0,"0", B13/(C13+E13)) -> 156.88073 | I13: =IF(E13=0,"0", D13/E13) -> 0 | J13: =IF(G13=0,"0", F13/G13) -> 0 | K13: =B13+D13+F13 -> 3420 | L13: 388.5504 | M13: =IF(L13=0,"0",(K13/L13)) -> 8.8019469
A14: 8 | B14: =IF('Entries December''25'!B14-'Entries December''25'!B13<1,"0",'Entries December''25'!B14-'Entries December''25'!B13) -> 3630 | C14: =IF('Entries December''25'!F14-'Entries December''25'!F13<1,"0",'Entries December''25'!F14-'Entries December''25'!F13) -> 21.6 | D14: =IF('Entries December''25'!C13=0,0,+'Entries December''25'!C13-'Entries December''25'!#REF!) -> 0 | E14: =IF('Entries December''25'!G14-'Entries December''25'!G13<1,"0",'Entries December''25'!G14-'Entries December''25'!G13) -> 0 | H14: =IF(C14+E14=0,"0", B14/(C14+E14)) -> 168.05556 | I14: =IF(E14=0,"0", D14/E14) -> 0 | J14: =IF(G14=0,"0", F14/G14) -> 0 | K14: =B14+D14+F14 -> 3630 | L14: 447.8844 | M14: =IF(L14=0,"0",(K14/L14)) -> 8.1047699
A15: 9 | B15: =IF('Entries December''25'!B15-'Entries December''25'!B14<1,"0",'Entries December''25'!B15-'Entries December''25'!B14) -> 2860 | C15: =IF('Entries December''25'!F15-'Entries December''25'!F14<1,"0",'Entries December''25'!F15-'Entries December''25'!F14) -> 18.1 | D15: =IF('Entries December''25'!C14=0,0,+'Entries December''25'!C14-'Entries December''25'!C13) -> 0 | E15: =IF('Entries December''25'!G15-'Entries December''25'!G14<1,"0",'Entries December''25'!G15-'Entries December''25'!G14) -> 0 | H15: =IF(C15+E15=0,"0", B15/(C15+E15)) -> 158.01105 | I15: =IF(E15=0,"0", D15/E15) -> 0 | J15: =IF(G15=0,"0", F15/G15) -> 0 | K15: =B15+D15+F15 -> 2860 | L15: 214.764 | M15: =IF(L15=0,"0",(K15/L15)) -> 13.316943
A16: 10 | B16: =IF('Entries December''25'!B16-'Entries December''25'!B15<1,"0",'Entries December''25'!B16-'Entries December''25'!B15) -> 3800 | C16: =IF('Entries December''25'!F16-'Entries December''25'!F15<1,"0",'Entries December''25'!F16-'Entries December''25'!F15) -> 22.9 | D16: =IF('Entries December''25'!C15=0,0,+'Entries December''25'!C15-'Entries December''25'!C14) -> 0 | E16: =IF('Entries December''25'!G16-'Entries December''25'!G15<1,"0",'Entries December''25'!G16-'Entries December''25'!G15) -> 0 | H16: =IF(C16+E16=0,"0", B16/(C16+E16)) -> 165.93886 | I16: =IF(E16=0,"0", D16/E16) -> 0 | J16: =IF(G16=0,"0", F16/G16) -> 0 | K16: =B16+D16+F16 -> 3800 | L16: 437.052 | M16: =IF(L16=0,"0",(K16/L16)) -> 8.6946176
A17: 11 | B17: =IF('Entries December''25'!B17-'Entries December''25'!B16<1,"0",'Entries December''25'!B17-'Entries December''25'!B16) -> 2680 | C17: =IF('Entries December''25'!F17-'Entries December''25'!F16<1,"0",'Entries December''25'!F17-'Entries December''25'!F16) -> 17.5 | D17: =IF('Entries December''25'!C16=0,0,+'Entries December''25'!C16-'Entries December''25'!C15) -> 0 | E17: =IF('Entries December''25'!G17-'Entries December''25'!G16<1,"0",'Entries December''25'!G17-'Entries December''25'!G16) -> 0 | H17: =IF(C17+E17=0,"0", B17/(C17+E17)) -> 153.14286 | I17: =IF(E17=0,"0", D17/E17) -> 0 | J17: =IF(G17=0,"0", F17/G17) -> 0 | K17: =B17+D17+F17 -> 2680 | L17: 332.838 | M17: =IF(L17=0,"0",(K17/L17)) -> 8.0519652
A18: 12 | B18: =IF('Entries December''25'!B18-'Entries December''25'!B17<1,"0",'Entries December''25'!B18-'Entries December''25'!B17) -> 3090 | C18: =IF('Entries December''25'!F18-'Entries December''25'!F17<1,"0",'Entries December''25'!F18-'Entries December''25'!F17) -> 18.4 | D18: =IF('Entries December''25'!C17=0,0,+'Entries December''25'!C17-'Entries December''25'!C16) -> 0 | E18: =IF('Entries December''25'!G18-'Entries December''25'!G17<1,"0",'Entries December''25'!G18-'Entries December''25'!G17) -> 0 | H18: =IF(C18+E18=0,"0", B18/(C18+E18)) -> 167.93478 | I18: =IF(E18=0,"0", D18/E18) -> 0 | J18: =IF(G18=0,"0", F18/G18) -> 0 | K18: =B18+D18+F18 -> 3090 | L18: 259.05 | M18: =IF(L18=0,"0",(K18/L18)) -> 11.928199
A19: 13 | B19: =IF('Entries December''25'!B19-'Entries December''25'!B18<1,"0",'Entries December''25'!B19-'Entries December''25'!B18) -> 1470 | C19: =IF('Entries December''25'!F19-'Entries December''25'!F18<1,"0",'Entries December''25'!F19-'Entries December''25'!F18) -> 10.3 | D19: =IF('Entries December''25'!C18=0,0,+'Entries December''25'!C18-'Entries December''25'!C17) -> 0 | E19: =IF('Entries December''25'!G19-'Entries December''25'!G18<1,"0",'Entries December''25'!G19-'Entries December''25'!G18) -> 0 | H19: =IF(C19+E19=0,"0", B19/(C19+E19)) -> 142.71845 | I19: =IF(E19=0,"0", D19/E19) -> 0 | J19: =IF(G19=0,"0", F19/G19) -> 0 | K19: =B19+D19+F19 -> 1470 | L19: 190.608 | M19: =IF(L19=0,"0",(K19/L19)) -> 7.7121632
A20: 14 | B20: =IF('Entries December''25'!B20-'Entries December''25'!B19<1,"0",'Entries December''25'!B20-'Entries December''25'!B19) -> 2140 | C20: =IF('Entries December''25'!F20-'Entries December''25'!F19<1,"0",'Entries December''25'!F20-'Entries December''25'!F19) -> 14.8 | D20: =IF('Entries December''25'!C19=0,0,+'Entries December''25'!C19-'Entries December''25'!C18) -> 0 | E20: =IF('Entries December''25'!G20-'Entries December''25'!G19<1,"0",'Entries December''25'!G20-'Entries December''25'!G19) -> 0 | H20: =IF(C20+E20=0,"0", B20/(C20+E20)) -> 144.59459 | I20: =IF(E20=0,"0", D20/E20) -> 0 | J20: =IF(G20=0,"0", F20/G20) -> 0 | K20: =B20+D20+F20 -> 2140 | L20: 389.154 | M20: =IF(L20=0,"0",(K20/L20)) -> 5.4991083
A21: 15 | B21: =IF('Entries December''25'!B21-'Entries December''25'!B20<1,"0",'Entries December''25'!B21-'Entries December''25'!B20) -> 3070 | C21: =IF('Entries December''25'!F21-'Entries December''25'!F20<1,"0",'Entries December''25'!F21-'Entries December''25'!F20) -> 18.4 | D21: =IF('Entries December''25'!C20=0,0,+'Entries December''25'!C20-'Entries December''25'!C19) -> 0 | E21: =IF('Entries December''25'!G21-'Entries December''25'!G20<1,"0",'Entries December''25'!G21-'Entries December''25'!G20) -> 0 | H21: =IF(C21+E21=0,"0", B21/(C21+E21)) -> 166.84783 | I21: =IF(E21=0,"0", D21/E21) -> 0 | J21: =IF(G21=0,"0", F21/G21) -> 0 | K21: =B21+D21+F21 -> 3070 | L21: 369.456 | M21: =IF(L21=0,"0",(K21/L21)) -> 8.3095145
A22: 16 | B22: =IF('Entries December''25'!B22-'Entries December''25'!B21<1,"0",'Entries December''25'!B22-'Entries December''25'!B21) -> 3560 | C22: =IF('Entries December''25'!F22-'Entries December''25'!F21<1,"0",'Entries December''25'!F22-'Entries December''25'!F21) -> 22.4 | D22: =IF('Entries December''25'!C21=0,0,+'Entries December''25'!C21-'Entries December''25'!C20) -> 0 | E22: =IF('Entries December''25'!G22-'Entries December''25'!G21<1,"0",'Entries December''25'!G22-'Entries December''25'!G21) -> 0 | H22: =IF(C22+E22=0,"0", B22/(C22+E22)) -> 158.92857 | I22: =IF(E22=0,"0", D22/E22) -> 0 | J22: =IF(G22=0,"0", F22/G22) -> 0 | K22: =B22+D22+F22 -> 3560 | L22: 362.802 | M22: =IF(L22=0,"0",(K22/L22)) -> 9.8125148
A23: 17 | B23: =IF('Entries December''25'!B23-'Entries December''25'!B22<1,"0",'Entries December''25'!B23-'Entries December''25'!B22) -> 3260 | C23: =IF('Entries December''25'!F23-'Entries December''25'!F22<1,"0",'Entries December''25'!F23-'Entries December''25'!F22) -> 19.7 | D23: =IF('Entries December''25'!C22=0,0,+'Entries December''25'!C22-'Entries December''25'!C21) -> 0 | E23: =IF('Entries December''25'!G23-'Entries December''25'!G22<1,"0",'Entries December''25'!G23-'Entries December''25'!G22) -> 0 | H23: =IF(C23+E23=0,"0", B23/(C23+E23)) -> 165.48223 | I23: =IF(E23=0,"0", D23/E23) -> 0 | J23: =IF(G23=0,"0", F23/G23) -> 0 | K23: =B23+D23+F23 -> 3260 | L23: 489.06 | M23: =IF(L23=0,"0",(K23/L23)) -> 6.6658488
A24: 18 | B24: =IF('Entries December''25'!B24-'Entries December''25'!B23<1,"0",'Entries December''25'!B24-'Entries December''25'!B23) -> 3530 | C24: =IF('Entries December''25'!F24-'Entries December''25'!F23<1,"0",'Entries December''25'!F24-'Entries December''25'!F23) -> 22 | D24: =IF('Entries December''25'!C23=0,0,+'Entries December''25'!C23-'Entries December''25'!C22) -> 0 | E24: =IF('Entries December''25'!G24-'Entries December''25'!G23<1,"0",'Entries December''25'!G24-'Entries December''25'!G23) -> 0 | H24: =IF(C24+E24=0,"0", B24/(C24+E24)) -> 160.45455 | I24: =IF(E24=0,"0", D24/E24) -> 0 | J24: =IF(G24=0,"0", F24/G24) -> 0 | K24: =B24+D24+F24 -> 3530 | L24: 459.624 | M24: =IF(L24=0,"0",(K24/L24)) -> 7.6801908
A25: 19 | B25: =IF('Entries December''25'!B25-'Entries December''25'!B24<1,"0",'Entries December''25'!B25-'Entries December''25'!B24) -> 2420 | C25: =IF('Entries December''25'!F25-'Entries December''25'!F24<1,"0",'Entries December''25'!F25-'Entries December''25'!F24) -> 16.4 | D25: =IF('Entries December''25'!C24=0,0,+'Entries December''25'!C24-'Entries December''25'!C23) -> 0 | E25: =IF('Entries December''25'!G25-'Entries December''25'!G24<1,"0",'Entries December''25'!G25-'Entries December''25'!G24) -> 0 | H25: =IF(C25+E25=0,"0", B25/(C25+E25)) -> 147.56098 | I25: =IF(E25=0,"0", D25/E25) -> 0 | J25: =IF(G25=0,"0", F25/G25) -> 0 | K25: =B25+D25+F25 -> 2420 | L25: 479.226 | M25: =IF(L25=0,"0",(K25/L25)) -> 5.0498095
A26: 20 | B26: =IF('Entries December''25'!B26-'Entries December''25'!B25<1,"0",'Entries December''25'!B26-'Entries December''25'!B25) -> 130 | C26: =IF('Entries December''25'!F26-'Entries December''25'!F25<1,"0",'Entries December''25'!F26-'Entries December''25'!F25) -> 0 | D26: =IF('Entries December''25'!C25=0,0,+'Entries December''25'!C25-'Entries December''25'!C24) -> 0 | E26: =IF('Entries December''25'!G26-'Entries December''25'!G25<1,"0",'Entries December''25'!G26-'Entries December''25'!G25) -> 0 | H26: =IF(C26+E26=0,"0", B26/(C26+E26)) -> 0 | I26: =IF(E26=0,"0", D26/E26) -> 0 | J26: =IF(G26=0,"0", F26/G26) -> 0 | K26: =B26+D26+F26 -> 130 | L26: 0 | M26: =IF(L26=0,"0",(K26/L26)) -> 0
A27: 21 | B27: =IF('Entries December''25'!B27-'Entries December''25'!B26<1,"0",'Entries December''25'!B27-'Entries December''25'!B26) -> 700 | C27: =IF('Entries December''25'!F27-'Entries December''25'!F26<1,"0",'Entries December''25'!F27-'Entries December''25'!F26) -> 5.3 | D27: =IF('Entries December''25'!C26=0,0,+'Entries December''25'!C26-'Entries December''25'!C25) -> 0 | E27: =IF('Entries December''25'!G27-'Entries December''25'!G26<1,"0",'Entries December''25'!G27-'Entries December''25'!G26) -> 0 | H27: =IF(C27+E27=0,"0", B27/(C27+E27)) -> 132.07547 | I27: =IF(E27=0,"0", D27/E27) -> 0 | J27: =IF(G27=0,"0", F27/G27) -> 0 | K27: =B27+D27+F27 -> 700 | L27: 0 | M27: =IF(L27=0,"0",(K27/L27)) -> 0
A28: 22 | B28: =IF('Entries December''25'!B28-'Entries December''25'!B27<1,"0",'Entries December''25'!B28-'Entries December''25'!B27) -> 2600 | C28: =IF('Entries December''25'!F28-'Entries December''25'!F27<1,"0",'Entries December''25'!F28-'Entries December''25'!F27) -> 17.8 | D28: =IF('Entries December''25'!C27=0,0,+'Entries December''25'!C27-'Entries December''25'!C26) -> 0 | E28: =IF('Entries December''25'!G28-'Entries December''25'!G27<1,"0",'Entries December''25'!G28-'Entries December''25'!G27) -> 0 | H28: =IF(C28+E28=0,"0", B28/(C28+E28)) -> 146.06742 | I28: =IF(E28=0,"0", D28/E28) -> 0 | J28: =IF(G28=0,"0", F28/G28) -> 0 | K28: =B28+D28+F28 -> 2600 | L28: 542.982 | M28: =IF(L28=0,"0",(K28/L28)) -> 4.7883724
A29: 23 | B29: =IF('Entries December''25'!B29-'Entries December''25'!B28<1,"0",'Entries December''25'!B29-'Entries December''25'!B28) -> 2700 | C29: =IF('Entries December''25'!F29-'Entries December''25'!F28<1,"0",'Entries December''25'!F29-'Entries December''25'!F28) -> 18 | D29: =IF('Entries December''25'!C28=0,0,+'Entries December''25'!C28-'Entries December''25'!C27) -> 0 | E29: =IF('Entries December''25'!G29-'Entries December''25'!G28<1,"0",'Entries December''25'!G29-'Entries December''25'!G28) -> 0 | H29: =IF(C29+E29=0,"0", B29/(C29+E29)) -> 150 | I29: =IF(E29=0,"0", D29/E29) -> 0 | J29: =IF(G29=0,"0", F29/G29) -> 0 | K29: =B29+D29+F29 -> 2700 | L29: 451.638 | M29: =IF(L29=0,"0",(K29/L29)) -> 5.9782392
A30: 24 | B30: =IF('Entries December''25'!B30-'Entries December''25'!B29<1,"0",'Entries December''25'!B30-'Entries December''25'!B29) -> 2270 | C30: =IF('Entries December''25'!F30-'Entries December''25'!F29<1,"0",'Entries December''25'!F30-'Entries December''25'!F29) -> 14.7 | D30: =IF('Entries December''25'!C29=0,0,+'Entries December''25'!C29-'Entries December''25'!C28) -> 0 | E30: =IF('Entries December''25'!G30-'Entries December''25'!G29<1,"0",'Entries December''25'!G30-'Entries December''25'!G29) -> 0 | H30: =IF(C30+E30=0,"0", B30/(C30+E30)) -> 154.42177 | I30: =IF(E30=0,"0", D30/E30) -> 0 | J30: =IF(G30=0,"0", F30/G30) -> 0 | K30: =B30+D30+F30 -> 2270 | L30: 292.38 | M30: =IF(L30=0,"0",(K30/L30)) -> 7.7638689
A31: 25 | B31: =IF('Entries December''25'!B31-'Entries December''25'!B30<1,"0",'Entries December''25'!B31-'Entries December''25'!B30) -> 0 | C31: =IF('Entries December''25'!F31-'Entries December''25'!F30<1,"0",'Entries December''25'!F31-'Entries December''25'!F30) -> 0 | D31: =IF('Entries December''25'!C30=0,0,+'Entries December''25'!C30-'Entries December''25'!C29) -> 0 | E31: =IF('Entries December''25'!G31-'Entries December''25'!G30<1,"0",'Entries December''25'!G31-'Entries December''25'!G30) -> 0 | H31: =IF(C31+E31=0,"0", B31/(C31+E31)) -> 0 | I31: =IF(E31=0,"0", D31/E31) -> 0 | J31: =IF(G31=0,"0", F31/G31) -> 0 | K31: =B31+D31+F31 -> 0 | L31: 0 | M31: =IF(L31=0,"0",(K31/L31)) -> 0
A32: 26 | B32: =IF('Entries December''25'!B32-'Entries December''25'!B31<1,"0",'Entries December''25'!B32-'Entries December''25'!B31) -> 0 | C32: =IF('Entries December''25'!F32-'Entries December''25'!F31<1,"0",'Entries December''25'!F32-'Entries December''25'!F31) -> 0 | D32: =IF('Entries December''25'!C31=0,0,+'Entries December''25'!C31-'Entries December''25'!C30) -> 0 | E32: =IF('Entries December''25'!G32-'Entries December''25'!G31<1,"0",'Entries December''25'!G32-'Entries December''25'!G31) -> 0 | H32: =IF(C32+E32=0,"0", B32/(C32+E32)) -> 0 | I32: =IF(E32=0,"0", D32/E32) -> 0 | J32: =IF(G32=0,"0", F32/G32) -> 0 | K32: =B32+D32+F32 -> 0 | L32: 0 | M32: =IF(L32=0,"0",(K32/L32)) -> 0
A33: 27 | B33: =IF('Entries December''25'!B33-'Entries December''25'!B32<1,"0",'Entries December''25'!B33-'Entries December''25'!B32) -> 0 | C33: =IF('Entries December''25'!F33-'Entries December''25'!F32<1,"0",'Entries December''25'!F33-'Entries December''25'!F32) -> 0 | D33: =IF('Entries December''25'!C32=0,0,+'Entries December''25'!C32-'Entries December''25'!C31) -> 0 | E33: =IF('Entries December''25'!G33-'Entries December''25'!G32<1,"0",'Entries December''25'!G33-'Entries December''25'!G32) -> 0 | H33: =IF(C33+E33=0,"0", B33/(C33+E33)) -> 0 | I33: =IF(E33=0,"0", D33/E33) -> 0 | J33: =IF(G33=0,"0", F33/G33) -> 0 | K33: =B33+D33+F33 -> 0 | L33: 0 | M33: =IF(L33=0,"0",(K33/L33)) -> 0
A34: 28 | B34: =IF('Entries December''25'!B34-'Entries December''25'!B33<1,"0",'Entries December''25'!B34-'Entries December''25'!B33) -> 1020 | C34: =IF('Entries December''25'!F34-'Entries December''25'!F33<1,"0",'Entries December''25'!F34-'Entries December''25'!F33) -> 5.8 | D34: =IF('Entries December''25'!C33=0,0,+'Entries December''25'!C33-'Entries December''25'!C32) -> 0 | E34: =IF('Entries December''25'!G34-'Entries December''25'!G33<1,"0",'Entries December''25'!G34-'Entries December''25'!G33) -> 0 | H34: =IF(C34+E34=0,"0", B34/(C34+E34)) -> 175.86207 | I34: =IF(E34=0,"0", D34/E34) -> 0 | J34: =IF(G34=0,"0", F34/G34) -> 0 | K34: =B34+D34+F34 -> 1020 | L34: 15.4275 | M34: =IF(L34=0,"0",(K34/L34)) -> 66.115702
A35: 29 | B35: =IF('Entries December''25'!B35-'Entries December''25'!B34<1,"0",'Entries December''25'!B35-'Entries December''25'!B34) -> 3230 | C35: =IF('Entries December''25'!F35-'Entries December''25'!F34<1,"0",'Entries December''25'!F35-'Entries December''25'!F34) -> 19.5 | E35: =IF('Entries December''25'!G35-'Entries December''25'!G34<1,"0",'Entries December''25'!G35-'Entries December''25'!G34) -> 0 | H35: =IF(C35+E35=0,"0", B35/(C35+E35)) -> 165.64103 | I35: =IF(E35=0,"0", D35/E35) -> 0 | J35: =IF(G35=0,"0", F35/G35) -> 0 | K35: =B35+D35+F35 -> 3230 | L35: 373.23 | M35: =IF(L35=0,"0",(K35/L35)) -> 8.6541811
A36: 30 | B36: =IF('Entries December''25'!B36-'Entries December''25'!B35<1,"0",'Entries December''25'!B36-'Entries December''25'!B35) -> 3660 | C36: =IF('Entries December''25'!F36-'Entries December''25'!F35<1,"0",'Entries December''25'!F36-'Entries December''25'!F35) -> 21.3 | E36: =IF('Entries December''25'!G36-'Entries December''25'!G35<1,"0",'Entries December''25'!G36-'Entries December''25'!G35) -> 0 | H36: =IF(C36+E36=0,"0", B36/(C36+E36)) -> 171.83099 | I36: =IF(E36=0,"0", D36/E36) -> 0 | J36: =IF(G36=0,"0", F36/G36) -> 0 | K36: =B36+D36+F36 -> 3660 | L36: 513.018 | M36: =IF(L36=0,"0",(K36/L36)) -> 7.1342526
A37: 31 | B37: =IF('Entries December''25'!B37-'Entries December''25'!B36<1,"0",'Entries December''25'!B37-'Entries December''25'!B36) -> 2570 | C37: =IF('Entries December''25'!F37-'Entries December''25'!F36<1,"0",'Entries December''25'!F37-'Entries December''25'!F36) -> 16 | E37: =IF('Entries December''25'!G37-'Entries December''25'!G36<1,"0",'Entries December''25'!G37-'Entries December''25'!G36) -> 0 | H37: =IF(C37+E37=0,"0", B37/(C37+E37)) -> 160.625 | I37: =IF(E37=0,"0", D37/E37) -> 0 | J37: =IF(G37=0,"0", F37/G37) -> 0 | K37: =B37+D37+F37 -> 2570 | L37: 430.518
A38: MTD | B38: =SUM(B7:B37) -> 75990 | C38: =SUM(C7:C37) -> 480.5 | D38: =SUM(D7:D34) -> 0 | E38: =SUM(E7:E34) -> 0 | H38: =IF(C38+E38=0,"0", B38/(C38+E38)) -> 158.14776 | K38: =SUM(K7:K37) -> 75990 | L38: =SUM(L7:L37) -> 9272.0823 | M38: =IF(L38=0,"0",(K38/L38)) -> 8.1955701 | N38: 7.2 | O38: =M38/N38*100 -> 113.82736
A39: AVE. | B39: =AVERAGE(B7:B37) -> 2713.9286 | C39: =AVERAGE(C7:C37) -> 17.796296 | H39: cons (l/hr)

Sheet Water 
B4: DATE | C4: Well Supply (m3) | D4: Nawasa Supply (m3) | E4: Annanale Supply (m3) | F4: RO Water Plant Nawasa (m3) | G4: Service Water Received (m3) | H4: Service Water Supply to Plant (m3) | I4: CO2 Scrubber (m3) | J4: Brewhouse / Old Pepsi Area (m3) | K4: Filtration/Cellars (m3) | L4: Cellars/Process Area (m3) | M4: Pasteuriser (m3) | R4: Permeate Produced (m3) | S4: Plant Cons. USAGE (Hl.) | U4: Bottle Filler (m3) | X4: Rus (m3) | Y4: Washdown Area (m3) | Z4: TOTAL SUPPLY (M3) | AA4: Total Prod.(HL) | AB4: Water KPI (Hl/Hl)
N5: CIP Process (m3) | O5: Bottles Washer (m3) | P5: Bottles Filler (m3) | Q5: Boiler Supply (m3) | T5: ∑ Service Water to Processes | V5: Water into RO #1 (m3) | W5: Water into RO #2 (m3)
B6: -
B7: 1 | C7: =IF('Entries December''25'!W7-'Entries December''25'!W6<1,"0",'Entries December''25'!W7-'Entries December''25'!W6) -> 0 | D7: =IF('Entries December''25'!O7-'Entries December''25'!O6<1,"0",'Entries December''25'!O7-'Entries December''25'!O6) -> 98 | E7: =IF('Entries December''25'!P7-'Entries December''25'!P6<1,"0",'Entries December''25'!P7-'Entries December''25'!P6) -> 143 | F7: =IF('Entries December''25'!V7-'Entries December''25'!V6<1,"0",'Entries December''25'!V7-'Entries December''25'!V6) -> 151 | G7: =(D7+E7)-F7 -> 90 | H7: =IF('Entries December''25'!Q7-'Entries December''25'!Q6<1,0,'Entries December''25'!Q7-'Entries December''25'!Q6) -> 268 | I7: =IF('Entries December''25'!AG7-'Entries December''25'!AG6<1,0,'Entries December''25'!AG7-'Entries December''25'!AG6) -> 0 | J7: =IF('Entries December''25'!S7-'Entries December''25'!S6<1,"0",'Entries December''25'!S7-'Entries December''25'!S6) -> 28 | K7: =IF('Entries December''25'!R7-'Entries December''25'!R6<1,"0",'Entries December''25'!R7-'Entries December''25'!R6) -> 0 | L7: =IF('Entries December''25'!T7-'Entries December''25'!T6<1,"0",'Entries December''25'!T7-'Entries December''25'!T6) -> 0 | M7: =IF('Entries December''25'!U7-'Entries December''25'!U6<1,"0",'Entries December''25'!U7-'Entries December''25'!U6) -> 18 | N7: =IF('Entries December''25'!X7-'Entries December''25'!X6<1,"0",'Entries December''25'!X7-'Entries December''25'!X6) -> 28 | O7: =IF('Entries December''25'!Y7-'Entries December''25'!Y6<1,"0",'Entries December''25'!Y7-'Entries December''25'!Y6) -> 167 | P7: =IF('Entries December''25'!AC7-'Entries December''25'!AC6<1,"0",'Entries December''25'!AC7-'Entries December''25'!AC6) -> 27 | Q7: =IF('Entries December''25'!Z7-'Entries December''25'!Z6<1,"0",'Entries December''25'!Z7-'Entries December''25'!Z6) -> 60 | R7: =IF(('Entries December''25'!AA7-'Entries December''25'!AA6)+('Entries December''25'!AB7-'Entries December''25'!AB6)<1,"0",('Entries December''25'!AA7-'Entries December''25'!AA6)+('Entries December''25'!AB7-'Entries December''25'!AB6)) -> 0 | S7: =(R7+G7)*10 -> 900 | T7: =O7+N7+M7+L7 -> 213 | U7: =IF('Entries December''25'!AC7-'Entries December''25'!AC6<1,"0",'Entries December''25'!AC7-'Entries December''25'!AC6) -> 27 | V7: =IF('Entries December''25'!AD7-'Entries December''25'!AD6<1,"0",'Entries December''25'!AD7-'Entries December''25'!AD6) -> 0 | W7: =IF('Entries December''25'!AE7-'Entries December''25'!AE6<1,"0",'Entries December''25'!AE7-'Entries December''25'!AE6) -> 0 | X7: =IF('Entries December''25'!AI7-'Entries December''25'!AI6<1,"0",'Entries December''25'!AI7-'Entries December''25'!AI6) -> 0 | Y7: =IF('Entries December''25'!AH7-'Entries December''25'!AH6<1,"0",'Entries December''25'!AH7-'Entries December''25'!AH6) -> 0 | Z7: =C7+D7+E7 -> 241 | AA7: {=IF(TRANSPOSE('Daily KPIs'!B9:AF9)=0,"0",TRANSPOSE('Daily KPIs'!B9:AF9))} -> 455.136 | AB7: =IF(AA7=0,"0",(Z7*10/AA7)) -> 5.2951206
B8: 2 | C8: =IF('Entries December''25'!W8-'Entries December''25'!W7<1,"0",'Entries December''25'!W8-'Entries December''25'!W7) -> 0 | D8: =IF('Entries December''25'!O8-'Entries December''25'!O7<1,"0",'Entries December''25'!O8-'Entries December''25'!O7) -> 238 | E8: =IF('Entries December''25'!P8-'Entries December''25'!P7<1,"0",'Entries December''25'!P8-'Entries December''25'!P7) -> 131 | F8: =IF('Entries December''25'!V8-'Entries December''25'!V7<1,"0",'Entries December''25'!V8-'Entries December''25'!V7) -> 137 | G8: =(D8+E8)-F8 -> 232 | H8: =IF('Entries December''25'!Q8-'Entries December''25'!Q7<1,0,'Entries December''25'!Q8-'Entries December''25'!Q7) -> 165 | I8: =IF('Entries December''25'!AG8-'Entries December''25'!AG7<1,0,'Entries December''25'!AG8-'Entries December''25'!AG7) -> 0 | J8: =IF('Entries December''25'!S8-'Entries December''25'!S7<1,"0",'Entries December''25'!S8-'Entries December''25'!S7) -> 152 | K8: =IF('Entries December''25'!R8-'Entries December''25'!R7<1,"0",'Entries December''25'!R8-'Entries December''25'!R7) -> 0 | L8: =IF('Entries December''25'!T8-'Entries December''25'!T7<1,"0",'Entries December''25'!T8-'Entries December''25'!T7) -> 0 | M8: =IF('Entries December''25'!U8-'Entries December''25'!U7<1,"0",'Entries December''25'!U8-'Entries December''25'!U7) -> 7 | N8: =IF('Entries December''25'!X8-'Entries December''25'!X7<1,"0",'Entries December''25'!X8-'Entries December''25'!X7) -> 3 | O8: =IF('Entries December''25'!Y8-'Entries December''25'!Y7<1,"0",'Entries December''25'!Y8-'Entries December''25'!Y7) -> 84 | P8: =IF('Entries December''25'!AC8-'Entries December''25'!AC7<1,"0",'Entries December''25'!AC8-'Entries December''25'!AC7) -> 14 | Q8: =IF('Entries December''25'!Z8-'Entries December''25'!Z7<1,"0",'Entries December''25'!Z8-'Entries December''25'!Z7) -> 48 | R8: =IF(('Entries December''25'!AA8-'Entries December''25'!AA7)+('Entries December''25'!AB8-'Entries December''25'!AB7)<1,"0",('Entries December''25'!AA8-'Entries December''25'!AA7)+('Entries December''25'!AB8-'Entries December''25'!AB7)) -> 0 | S8: =(R8+G8)*10 -> 2320 | T8: =O8+N8+M8+L8 -> 94 | U8: =IF('Entries December''25'!AC8-'Entries December''25'!AC7<1,"0",'Entries December''25'!AC8-'Entries December''25'!AC7) -> 14 | V8: =IF('Entries December''25'!AD8-'Entries December''25'!AD7<1,"0",'Entries December''25'!AD8-'Entries December''25'!AD7) -> 0 | W8: =IF('Entries December''25'!AE8-'Entries December''25'!AE7<1,"0",'Entries December''25'!AE8-'Entries December''25'!AE7) -> 0 | X8: =IF('Entries December''25'!AI8-'Entries December''25'!AI7<1,"0",'Entries December''25'!AI8-'Entries December''25'!AI7) -> 0 | Y8: =IF('Entries December''25'!AH8-'Entries December''25'!AH7<1,"0",'Entries December''25'!AH8-'Entries December''25'!AH7) -> 0 | Z8: =C8+D8+E8 -> 369 | AA8: 211.926 | AB8: =IF(AA8=0,"0",(Z8*10/AA8)) -> 17.411738
