Workbook
Name ProductList: [1]November15!$R$3:$R$9
Name ProductList: [2]November15!$R$3:$R$9

Sheet Dec 18th
T1: P.G. | V1: Hot Time | X1: Process Time | Z1: Cooling Time
B2: Brewing Department Daily Process Loss Report | T2: Lower | U2: Upper | V2: Lower | W2: Upper | X2: Lower | Y2: Upper | Z2: Lower | AA2: Upper
S3: CARIB | T3: 11.6 | U3: 12 | V3: 0 | W3: 0.11805556 | X3: 0.17361111 | Y3: 0.21180556 | Z3: 0 | AA3: 60 | AC3: HR- PISNER
B4: Date: | C4: 45278 | J4: LOT WORT COLOUR: 3.4 | M4: Filter Sheets (Target 20 days) | S4: STAG | T4: 11.6 | U4: 12 | V4: 0 | W4: 0.11805556 | X4: 0.17361111 | Y4: 0.21180556 | Z4: 0 | AA4: 60
M5: Double | N5: Single | S5: GUINNESS | T5: 17 | U5: 17.5 | V5: 0 | W5: 0.10763889 | X5: 0.19444444 | Y5: 0.23263889 | Z5: 0 | AA5: 60
J6: MALT LOT: Lot 8 | L6: Sheet Day | S6: MACKESON | T6: 13.3 | U6: 13.5 | V6: 0 | W6: 0.12905093 | X6: 0.22222222 | Y6: 0.25347222 | Z6: 0
S7: STARMALT | T7: 17.1 | U7: 17.5 | V7: 0 | W7: 0.13605324 | X7: 0.20833333 | Y7: 0.24305556 | Z7: 0 | AA7: 60
B8: Brand | C8: Brew no. | D8: Kett. Hls | E8: Wort | F8: Cool Time(Mins) | G8: Cast. P.G. (Lab Result) | H8: Cast P.G. (Cellar Operator)-gravity | I8: Extr. Rec (79.1%) | J8: Theor. Extr. (77.5%) | K8: Boil Off /Vol. (4-6%) | L8: Boil Time | M8: Total Hot | N8: Brewing | P8: Comments | Q8: Actual Pilsen Malt | S8: Hurricane Reef | T8: 16.6 | U8: 17 | V8: 0 | W8: 0.12905093 | X8: 0.22222222 | Y8: 0.25347222 | Z8: 0
E9: Meter (Hls) | F9: Target(< 60Mins) | M9: Time | S9: VITAMALT | T9: 14.4 | U9: 14.6 | V9: 0 | W9: 0.13905093 | X9: 0.19097222 | Y9: 0.22569444 | Z9: 0 | AA9: 75
S10: =B10 -> 0 | T10: =VLOOKUP($B10,$S$3:$Y$9,2,FALSE) -> #N/A | U10: =VLOOKUP($B10,$S$3:$Y$9,3,FALSE) -> #N/A | V10: =VLOOKUP($B10,$S$3:$Y$9,4,FALSE) -> #N/A | W10: =VLOOKUP($B10,$S$3:$Y$9,5,FALSE) -> #N/A | X10: =VLOOKUP($B10,$S$3:$Y$9,6,FALSE) -> #N/A | Y10: =VLOOKUP($B10,$S$3:$Y$9,7,FALSE) -> #N/A | Z10: =VLOOKUP($B10,$S$3:$AA$9,8,FALSE) -> #N/A | AA10: =VLOOKUP($B10,$S$3:$AA$9,9,FALSE) -> #N/A
S11: =B11 -> 0 | T11: =VLOOKUP($B11,$S$3:$Y$9,2,FALSE) -> #N/A | U11: =VLOOKUP($B11,$S$3:$Y$9,3,FALSE) -> #N/A | V11: =VLOOKUP($B11,$S$3:$Y$9,4,FALSE) -> #N/A | W11: =VLOOKUP($B11,$S$3:$Y$9,5,FALSE) -> #N/A | X11: =VLOOKUP($B11,$S$3:$Y$9,6,FALSE) -> #N/A | Y11: =VLOOKUP($B11,$S$3:$Y$9,7,FALSE) -> #N/A | Z11: =VLOOKUP($B11,$S$3:$AA$9,8,FALSE) -> #N/A | AA11: =VLOOKUP($B11,$S$3:$AA$9,9,FALSE) -> #N/A
S12: =B12 -> 0 | T12: =VLOOKUP($B12,$S$3:$Y$9,2,FALSE) -> #N/A | U12: =VLOOKUP($B12,$S$3:$Y$9,3,FALSE) -> #N/A | V12: =VLOOKUP($B12,$S$3:$Y$9,4,FALSE) -> #N/A | W12: =VLOOKUP($B12,$S$3:$Y$9,5,FALSE) -> #N/A | X12: =VLOOKUP($B12,$S$3:$Y$9,6,FALSE) -> #N/A | Y12: =VLOOKUP($B12,$S$3:$Y$9,7,FALSE) -> #N/A | Z12: =VLOOKUP($B12,$S$3:$AA$9,8,FALSE) -> #N/A | AA12: =VLOOKUP($B12,$S$3:$AA$9,9,FALSE) -> #N/A
S13: =B13 -> 0 | T13: =VLOOKUP($B13,$S$3:$Y$9,2,FALSE) -> #N/A | U13: =VLOOKUP($B13,$S$3:$Y$9,3,FALSE) -> #N/A | V13: =VLOOKUP($B13,$S$3:$Y$9,4,FALSE) -> #N/A | W13: =VLOOKUP($B13,$S$3:$Y$9,5,FALSE) -> #N/A | X13: =VLOOKUP($B13,$S$3:$Y$9,6,FALSE) -> #N/A | Y13: =VLOOKUP($B13,$S$3:$Y$9,7,FALSE) -> #N/A | Z13: =VLOOKUP($B13,$S$3:$AA$9,8,FALSE) -> #N/A | AA13: =VLOOKUP($B13,$S$3:$AA$9,9,FALSE) -> #N/A
S14: =B14 -> 0 | T14: =VLOOKUP($B14,$S$3:$Y$9,2,FALSE) -> #N/A | U14: =VLOOKUP($B14,$S$3:$Y$9,3,FALSE) -> #N/A | V14: =VLOOKUP($B14,$S$3:$Y$9,4,FALSE) -> #N/A | W14: =VLOOKUP($B14,$S$3:$Y$9,5,FALSE) -> #N/A | X14: =VLOOKUP($B14,$S$3:$Y$9,6,FALSE) -> #N/A | Y14: =VLOOKUP($B14,$S$3:$Y$9,7,FALSE) -> #N/A | Z14: =VLOOKUP($B14,$S$3:$AA$9,8,FALSE) -> #N/A | AA14: =VLOOKUP($B14,$S$3:$AA$9,9,FALSE) -> #N/A
S15: =B15 -> 0 | T15: =VLOOKUP($B15,$S$3:$Y$9,2,FALSE) -> #N/A | U15: =VLOOKUP($B15,$S$3:$Y$9,3,FALSE) -> #N/A | V15: =VLOOKUP($B15,$S$3:$Y$9,4,FALSE) -> #N/A | W15: =VLOOKUP($B15,$S$3:$Y$9,5,FALSE) -> #N/A | X15: =VLOOKUP($B15,$S$3:$Y$9,6,FALSE) -> #N/A | Y15: =VLOOKUP($B15,$S$3:$Y$9,7,FALSE) -> #N/A | Z15: =VLOOKUP($B15,$S$3:$AA$9,8,FALSE) -> #N/A | AA15: =VLOOKUP($B15,$S$3:$AA$9,9,FALSE) -> #N/A
S16: =B16 -> 0 | T16: =VLOOKUP($B16,$S$3:$Y$9,2,FALSE) -> #N/A | U16: =VLOOKUP($B16,$S$3:$Y$9,3,FALSE) -> #N/A | V16: =VLOOKUP($B16,$S$3:$Y$9,4,FALSE) -> #N/A | W16: =VLOOKUP($B16,$S$3:$Y$9,5,FALSE) -> #N/A | X16: =VLOOKUP($B16,$S$3:$Y$9,6,FALSE) -> #N/A | Y16: =VLOOKUP($B16,$S$3:$Y$9,7,FALSE) -> #N/A | Z16: =VLOOKUP($B16,$S$3:$AA$9,8,FALSE) -> #N/A | AA16: =VLOOKUP($B16,$S$3:$AA$9,9,FALSE) -> #N/A
S17: =B17 -> 0 | T17: =VLOOKUP($B17,$S$3:$Y$9,2,FALSE) -> #N/A | U17: =VLOOKUP($B17,$S$3:$Y$9,3,FALSE) -> #N/A | V17: =VLOOKUP($B17,$S$3:$Y$9,4,FALSE) -> #N/A | W17: =VLOOKUP($B17,$S$3:$Y$9,5,FALSE) -> #N/A | X17: =VLOOKUP($B17,$S$3:$Y$9,6,FALSE) -> #N/A | Y17: =VLOOKUP($B17,$S$3:$Y$9,7,FALSE) -> #N/A | Z17: =VLOOKUP($B17,$S$3:$AA$9,8,FALSE) -> #N/A | AA17: =VLOOKUP($B17,$S$3:$AA$9,9,FALSE) -> #N/A
S18: =B18 -> 0 | T18: =VLOOKUP($B18,$S$3:$Y$9,2,FALSE) -> #N/A | U18: =VLOOKUP($B18,$S$3:$Y$9,3,FALSE) -> #N/A | V18: =VLOOKUP($B18,$S$3:$Y$9,4,FALSE) -> #N/A | W18: =VLOOKUP($B18,$S$3:$Y$9,5,FALSE) -> #N/A | X18: =VLOOKUP($B18,$S$3:$Y$9,6,FALSE) -> #N/A | Y18: =VLOOKUP($B18,$S$3:$Y$9,7,FALSE) -> #N/A | Z18: =VLOOKUP($B18,$S$3:$AA$9,8,FALSE) -> #N/A | AA18: =VLOOKUP($B18,$S$3:$AA$9,9,FALSE) -> #N/A
S19: =B19 -> 0 | T19: =VLOOKUP($B19,$S$3:$Y$9,2,FALSE) -> #N/A | U19: =VLOOKUP($B19,$S$3:$Y$9,3,FALSE) -> #N/A | V19: =VLOOKUP($B19,$S$3:$Y$9,4,FALSE) -> #N/A | W19: =VLOOKUP($B19,$S$3:$Y$9,5,FALSE) -> #N/A | X19: =VLOOKUP($B19,$S$3:$Y$9,6,FALSE) -> #N/A | Y19: =VLOOKUP($B19,$S$3:$Y$9,7,FALSE) -> #N/A | Z19: =VLOOKUP($B19,$S$3:$AA$9,8,FALSE) -> #N/A | AA19: =VLOOKUP($B19,$S$3:$AA$9,9,FALSE) -> #N/A
S20: =B20 -> 0 | T20: =VLOOKUP($B20,$S$3:$Y$9,2,FALSE) -> #N/A | U20: =VLOOKUP($B20,$S$3:$Y$9,3,FALSE) -> #N/A | V20: =VLOOKUP($B20,$S$3:$Y$9,4,FALSE) -> #N/A | W20: =VLOOKUP($B20,$S$3:$Y$9,5,FALSE) -> #N/A | X20: =VLOOKUP($B20,$S$3:$Y$9,6,FALSE) -> #N/A | Y20: =VLOOKUP($B20,$S$3:$Y$9,7,FALSE) -> #N/A | Z20: =VLOOKUP($B20,$S$3:$AA$9,8,FALSE) -> #N/A | AA20: =VLOOKUP($B20,$S$3:$AA$9,9,FALSE) -> #N/A
S21: =B21 -> 0 | T21: =VLOOKUP($B21,$S$3:$Y$9,2,FALSE) -> #N/A | U21: =VLOOKUP($B21,$S$3:$Y$9,3,FALSE) -> #N/A | V21: =VLOOKUP($B21,$S$3:$Y$9,4,FALSE) -> #N/A | W21: =VLOOKUP($B21,$S$3:$Y$9,5,FALSE) -> #N/A | X21: =VLOOKUP($B21,$S$3:$Y$9,6,FALSE) -> #N/A | Y21: =VLOOKUP($B21,$S$3:$Y$9,7,FALSE) -> #N/A | Z21: =VLOOKUP($B21,$S$3:$AA$9,8,FALSE) -> #N/A | AA21: =VLOOKUP($B21,$S$3:$AA$9,9,FALSE) -> #N/A
... S47: =B47 -> 0 | T47: =VLOOKUP($B47,$S$3:$Y$9,2,FALSE) -> #N/A | U47: =VLOOKUP($B47,$S$3:$Y$9,3,FALSE) -> #N/A | V47: =VLOOKUP($B47,$S$3:$Y$9,4,FALSE) -> #N/A | W47: =VLOOKUP($B47,$S$3:$Y$9,5,FALSE) -> #N/A | X47: =VLOOKUP($B47,$S$3:$Y$9,6,FALSE) -> #N/A | Y47: =VLOOKUP($B47,$S$3:$Y$9,7,FALSE) -> #N/A | Z47: =VLOOKUP($B47,$S$3:$AA$9,8,FALSE) -> #N/A | AA47: =VLOOKUP($B47,$S$3:$AA$9,9,FALSE) -> #N/A
I48: EXTRACT RECOVERY
B49: BRAND | D49: BBT P.G./ O.G | I49: Brand | J49: Actual | K49: MTD No. of Brews | L49: MTD | M49: YTD | N49: Target
B50: STAG | C50: 11.8 | D50: 11.73 | I50: CARIB | K50: =COUNTA([3]Brewhouse!$A$1596:$A$1619) -> 24 | L50: =AVERAGE([3]Brewhouse!$AU$1529,[3]Brewhouse!$AU$1531:$AU$1594,[3]Brewhouse!$AU$1596:$AU$1619) -> 98.205761 | M50: =AVERAGE([3]Brewhouse!$AU$849:$AU$924,[3]Brewhouse!$AU$926:$AU$971,[3]Brewhouse!$AU$973:$AU$1066,[3]Brewhouse!$AU$1068:$AU$1111,[3]Brewhouse!$AU$1113:$AU$1132,[3]Brewhouse!$AU$1134:$AU$1167,[3]Brewhouse!$AU$1169:$AU$1230,[3]Brewhouse!$AU$1232:$AU$1299,[3]Brewhouse!$AU$1301:$AU$1363,[3]Brewhouse!$AU$1365:$AU$1444,[3]Brewhouse!$AU$1446:$AU$1527,[3]Brewhouse!$AU$1529,[3]Brewhouse!$AU$1531:$AU$1594,[3]Brewhouse!$AU$1596:$AU$1619) -> 98.381806 | N50: 98
C51: 11.9 | I51: STAG | K51: =COUNTA([4]Brewhouse!$A$976:$A$1007) -> 32 | L51: =AVERAGE([4]Brewhouse!$AS$976:$AS$979,[4]Brewhouse!$AS$981:$AS$1007) -> 98.538567 | M51: =AVERAGE([4]Brewhouse!$AS$577:$AS$618,[4]Brewhouse!$AS$620:$AS$651,[4]Brewhouse!$AS$653:$AS$696,[4]Brewhouse!$AS$698:$AS$708,[4]Brewhouse!$AS$710:$AS$733,[4]Brewhouse!$AS$735:$AS$777,[4]Brewhouse!$AS$779:$AS$822,[4]Brewhouse!$AS$824:$AS$863,[4]Brewhouse!$AS$865:$AS$974,[4]Brewhouse!$AS$976:$AS$979,[4]Brewhouse!$AS$981:$AS$1007) -> 98.489671 | N51: 98
I52: GUINNESS | K52: =COUNTA([5]Brewhouse!$A$282:$A$289) -> 8 | L52: =AVERAGE([5]Brewhouse!$AU$269:$AU$279,[5]Brewhouse!$AU$282:$AU$289) -> 96.186177 | M52: =AVERAGE([5]Brewhouse!$AU$161:$AU$176,[5]Brewhouse!$AU$178:$AU$195,[5]Brewhouse!$AU$197:$AU$208,[5]Brewhouse!$AU$210:$AU$221,[5]Brewhouse!$AU$223:$AU$232,[5]Brewhouse!$AU$234:$AU$279,[5]Brewhouse!$AU$282:$AU$289) -> 96.64916 | N52: 98
I53: VITAMALT | K53: =COUNTA([6]Brewhouse!$A$158:$A$163) -> 6 | L53: =AVERAGE([6]Brewhouse!$AU$158:$AU$163) -> 94.60305 | M53: =AVERAGE([6]Brewhouse!$AU$91:$AU$101,[6]Brewhouse!$AU$103:$AU$112,[6]Brewhouse!$AU$114:$AU$123,[6]Brewhouse!$AU$125:$AU$134,[6]Brewhouse!$AU$136:$AU$145,[6]Brewhouse!$AU$147:$AU$156,[6]Brewhouse!$AU$158:$AU$163) -> 96.240014 | N53: 98
I54: MAXIMALT | N54: 98
I55: MACKESON | M55: =AVERAGE([7]Brewhouse!$AT$74:$AT$79) -> 93.959836 | N55: 98
I56: STARMALT | K56: =COUNTA([8]Brewhouse!$A$249:$A$254) -> 6 | L56: =AVERAGE([8]Brewhouse!$AY$249:$AY$254) -> 99.681996 | M56: =AVERAGE([8]Brewhouse!$AY$138:$AY$143,[8]Brewhouse!$AY$145:$AY$153,[8]Brewhouse!$AY$155,[8]Brewhouse!$AY$156:$AY$174,[8]Brewhouse!$AY$176:$AY$185,[8]Brewhouse!$AY$187:$AY$198,[8]Brewhouse!$AY$200:$AY$247,[8]Brewhouse!$AY$249:$AY$254) -> 98.774703 | N56: 98
I57: HR- P | M57: =AVERAGE([9]Brewhouse!$AW$13:$AW$14,[9]Brewhouse!$AW$16:$AW$17) -> 92.042628 | N57: 98
I58: Hurricane Reef | M58: =AVERAGE([9]Brewhouse!$AW$13:$AW$14) -> 88.376943 | N58: 98
K59: =SUM(K50:K58) -> 76 | L59: =((L50*K50)+(L51*K51)+(L52*K52)+(L53*K53)+(L54*K54)+(K57*L57)+(L55*K55)+(L56*K56)+(L58*K58))/(K59) -> 97.965422 | M59: =AVERAGE('[10]Closing- January 2023'!$L$42,'[11]Feb. 28th'!$L$42,'[12]March 31st'!$L$75,'[13]Apri 28th'!$L$51,L59) -> 98.06926 | N59: 98
J62: Daily Brewing Plan
J63: Brand | K63: Brews Achieved | L63: Average Brews per day
J64: CARIB | L64: MTD | M64: YTD | N64: TARGET
J65: STAG | K65: 5 | L65: =AVERAGE(#REF!,#REF!,K74,#REF!,#REF!,#REF!,#REF!,#REF!,#REF!,#REF!,#REF!) -> #REF! | M65: =AVERAGE(6,6,'[12]March 31st'!$L$80,'[14]June 30th '!$L$71,6,L65,'[15]July 31st'!$L$108,'[16]Aug 30th'!$L$124,7,[17]Oct.31st!$L$51) -> #REF! | N65: 9
J66: GUINN
J67: VITAMALT
...

Sheet Dec 1st
S1: P.G. | U1: Hot Time | W1: Process Time | Y1: Cooling Time
B2: Brewing Department Daily Process Loss Report | S2: Lower | T2: Upper | U2: Lower | V2: Upper | W2: Lower | X2: Upper | Y2: Lower | Z2: Upper
R3: CARIB | S3: 11.6 | T3: 12 | U3: 0 | V3: 0.11805556 | W3: 0.22569444 | X3: 0.26388889 | Y3: 0 | Z3: 60 | AB3: HR- PISNER
B4: Date: | C4: 45993 | J4: LOT WORT COLOUR: | M4: Filter Sheets (Target 20 days) | R4: STAG | S4: 11.6 | T4: 12 | U4: 0 | V4: 0.11805556 | W4: 0.22569444 | X4: 0.26388889 | Y4: 0 | Z4: 60
M5: Double | N5: Single | R5: GUINNESS | S5: 17 | T5: 17.5 | U5: 0 | V5: 0.10763889 | W5: 0.24652778 | X5: 0.28472222 | Y5: 0 | Z5: 60
J6: MALT LOT: Lot #8 | L6: Sheet Day | R6: MACKESON | S6: 13.3 | T6: 13.5 | U6: 0 | V6: 0.12905093 | W6: 0.27430556 | X6: 0.30208333 | Y6: 0
R7: STARMALT | S7: 17 | T7: 17.4 | U7: 0 | V7: 0.13605324 | W7: 0.27430556 | X7: 0.30902778 | Y7: 0 | Z7: 85
B8: Brand | C8: Brew no. | D8: Kett. Hls | E8: Wort | F8: Cool Time(Mins) | G8: Cast. P.G. (Lab Result) | H8: Cast P.G. (Cellar Operator)-gravity | I8: Extr. Rec (77.9%) | J8: Theor. Extr. (77.5%) | K8: Boil Off /Vol. (4-6%) | L8: Boil Time | M8: Total Hot | N8: Brewing | O8: Operator | R8: Hurricane Reef | S8: 16.6 | T8: 17 | U8: 0 | V8: 0.12905093 | W8: 0.27430556 | X8: 0.30208333 | Y8: 0
E9: Meter (Hls) | F9: Target(< 60Mins) | M9: Time | R9: VITAMALT | S9: 14.2 | T9: 14.6 | U9: 0 | V9: 0.13905093 | W9: 0.26041667 | X9: 0.29513889 | Y9: 0 | Z9: 75
B10: VITAMALT | C10: =[22]Brewhouse!A106 -> VM091 | D10: BREW DUMPED
B11: VITAMALT | C11: =[22]Brewhouse!A107 -> VM092 | D11: =[22]Brewhouse!AE107 -> 50.1 | E11: =[22]Brewhouse!AJ107 -> 47.4 | F11: =[22]Brewhouse!X107 -> 85 | G11: =[22]Brewhouse!AH107 -> 14.3 | H11: 14.4 | I11: =[22]Brewhouse!AV107 -> 96.1527 | J11: =[22]Brewhouse!AW107 -> 96.178035 | K11: =[22]Brewhouse!S107 -> 12.095808 | L11: =[22]Brewhouse!R107 -> 58 | M11: =[22]Brewhouse!$W107-[22]Brewhouse!$V107 -> 0.14513889 | N11: =[22]Brewhouse!AB107 -> 0.28055556 | O11: =[22]Brewhouse!$AZ107 -> R.Sookram
R15: =B15 -> 0 | S15: =VLOOKUP($B15,$R$3:$X$9,2,FALSE) -> #N/A | T15: =VLOOKUP($B15,$R$3:$X$9,3,FALSE) -> #N/A | U15: =VLOOKUP($B15,$R$3:$X$9,4,FALSE) -> #N/A | V15: =VLOOKUP($B15,$R$3:$X$9,5,FALSE) -> #N/A | W15: =VLOOKUP($B15,$R$3:$X$9,6,FALSE) -> #N/A | X15: =VLOOKUP($B15,$R$3:$X$9,7,FALSE) -> #N/A | Y15: =VLOOKUP($B15,$R$3:$Z$9,8,FALSE) -> #N/A | Z15: =VLOOKUP($B15,$R$3:$Z$9,9,FALSE) -> #N/A
R16: =B16 -> 0 | S16: =VLOOKUP($B16,$R$3:$X$9,2,FALSE) -> #N/A | T16: =VLOOKUP($B16,$R$3:$X$9,3,FALSE) -> #N/A | U16: =VLOOKUP($B16,$R$3:$X$9,4,FALSE) -> #N/A | V16: =VLOOKUP($B16,$R$3:$X$9,5,FALSE) -> #N/A | W16: =VLOOKUP($B16,$R$3:$X$9,6,FALSE) -> #N/A | X16: =VLOOKUP($B16,$R$3:$X$9,7,FALSE) -> #N/A | Y16: =VLOOKUP($B16,$R$3:$Z$9,8,FALSE) -> #N/A | Z16: =VLOOKUP($B16,$R$3:$Z$9,9,FALSE) -> #N/A
R17: =B17 -> 0 | S17: =VLOOKUP($B17,$R$3:$X$9,2,FALSE) -> #N/A | T17: =VLOOKUP($B17,$R$3:$X$9,3,FALSE) -> #N/A | U17: =VLOOKUP($B17,$R$3:$X$9,4,FALSE) -> #N/A | V17: =VLOOKUP($B17,$R$3:$X$9,5,FALSE) -> #N/A | W17: =VLOOKUP($B17,$R$3:$X$9,6,FALSE) -> #N/A | X17: =VLOOKUP($B17,$R$3:$X$9,7,FALSE) -> #N/A | Y17: =VLOOKUP($B17,$R$3:$Z$9,8,FALSE) -> #N/A | Z17: =VLOOKUP($B17,$R$3:$Z$9,9,FALSE) -> #N/A
B18: BRAND | D18: BBT P.G./ O.G | I18: Brand | K18: MTD No. of Brews | L18: MTD | M18: YTD | N18: Target | R18: =B18 -> BRAND | S18: =VLOOKUP($B18,$R$3:$X$9,2,FALSE) -> #N/A | T18: =VLOOKUP($B18,$R$3:$X$9,3,FALSE) -> #N/A | U18: =VLOOKUP($B18,$R$3:$X$9,4,FALSE) -> #N/A | V18: =VLOOKUP($B18,$R$3:$X$9,5,FALSE) -> #N/A | W18: =VLOOKUP($B18,$R$3:$X$9,6,FALSE) -> #N/A | X18: =VLOOKUP($B18,$R$3:$X$9,7,FALSE) -> #N/A | Y18: =VLOOKUP($B18,$R$3:$Z$9,8,FALSE) -> #N/A | Z18: =VLOOKUP($B18,$R$3:$Z$9,9,FALSE) -> #N/A
B19: =I19 -> CARIB | C19: {=[23]Process!$D$922:$D$925} -> 11.9 | D19: 12 | I19: CARIB | M19: =AVERAGE([23]Brewhouse!$AU$102:$AU$171,[23]Brewhouse!$AU$173:$AU$253,[23]Brewhouse!$AU$255:$AU$339,[23]Brewhouse!$AU$341:$AU$346,[23]Brewhouse!$AU$348,[23]Brewhouse!$AU$349:$AU$406,[23]Brewhouse!$AU$408:$AU$491,[23]Brewhouse!$AU$493:$AU$578,[23]Brewhouse!$AU$580:$AU$652,[23]Brewhouse!$AU$655:$AU$738,[23]Brewhouse!$A$740:$A$821,[23]Brewhouse!$AU$823:$AU$862,[24]Brewhouse!$AS$420:$AS$423,[23]Brewhouse!$AU$867:$AU$912,[23]Brewhouse!$AU$914:$AU$1003) -> 97.751831 | N19: 98 | R19: =B19 -> CARIB | S19: =VLOOKUP($B19,$R$3:$X$9,2,FALSE) -> 11.6 | T19: =VLOOKUP($B19,$R$3:$X$9,3,FALSE) -> 12 | U19: =VLOOKUP($B19,$R$3:$X$9,4,FALSE) -> 0 | V19: =VLOOKUP($B19,$R$3:$X$9,5,FALSE) -> 0.11805556 | W19: =VLOOKUP($B19,$R$3:$X$9,6,FALSE) -> 0.22569444 | X19: =VLOOKUP($B19,$R$3:$X$9,7,FALSE) -> 0.26388889 | Y19: =VLOOKUP($B19,$R$3:$Z$9,8,FALSE) -> 0 | Z19: =VLOOKUP($B19,$R$3:$Z$9,9,FALSE) -> 60
C20: 11.8 | I20: STAG | M20: =AVERAGE([24]Brewhouse!$AS$15:$AS$64,[24]Brewhouse!$AS$66:$AS$103,[24]Brewhouse!$AS$105:$AS$140,[24]Brewhouse!$AS$142:$AS$193,[24]Brewhouse!$AS$195:$AS$240,[24]Brewhouse!$AS$242:$AS$273,[24]Brewhouse!$AS$275:$AS$322,[24]Brewhouse!$AS$324:$AS$359,[24]Brewhouse!$AS$361:$AS$397,[24]Brewhouse!$AS$399:$AS$419,[24]Brewhouse!$AS$424:$AS$447,[24]Brewhouse!$AS$449:$AS$484) -> 97.847962 | N20: 98 | R20: =B20 -> 0 | S20: =VLOOKUP($B20,$R$3:$X$9,2,FALSE) -> #N/A | T20: =VLOOKUP($B20,$R$3:$X$9,3,FALSE) -> #N/A | U20: =VLOOKUP($B20,$R$3:$X$9,4,FALSE) -> #N/A | V20: =VLOOKUP($B20,$R$3:$X$9,5,FALSE) -> #N/A | W20: =VLOOKUP($B20,$R$3:$X$9,6,FALSE) -> #N/A | X20: =VLOOKUP($B20,$R$3:$X$9,7,FALSE) -> #N/A | Y20: =VLOOKUP($B20,$R$3:$Z$9,8,FALSE) -> #N/A | Z20: =VLOOKUP($B20,$R$3:$Z$9,9,FALSE) -> #N/A
C21: 11.6 | D21: 11.6 | I21: GUINNESS | M21: =AVERAGE([25]Brewhouse!$AU$4:$AU$7,[25]Brewhouse!$AU$9:$AU$22,[25]Brewhouse!$AU$24:$AU$35,[25]Brewhouse!$AU$37:$AU$45,[25]Brewhouse!$AU$47:$AU$62,[25]Brewhouse!$AU$64:$AU$79,[25]Brewhouse!$AU$81:$AU$92,[25]Brewhouse!$AU$94:$AU$97,[25]Brewhouse!$AU$99:$AU$106,[25]Brewhouse!$AU$116:$AU$123) -> 96.481277 | N21: 98 | R21: =B21 -> 0 | S21: =VLOOKUP($B21,$R$3:$X$9,2,FALSE) -> #N/A | T21: =VLOOKUP($B21,$R$3:$X$9,3,FALSE) -> #N/A | U21: =VLOOKUP($B21,$R$3:$X$9,4,FALSE) -> #N/A | V21: =VLOOKUP($B21,$R$3:$X$9,5,FALSE) -> #N/A | W21: =VLOOKUP($B21,$R$3:$X$9,6,FALSE) -> #N/A | X21: =VLOOKUP($B21,$R$3:$X$9,7,FALSE) -> #N/A | Y21: =VLOOKUP($B21,$R$3:$Z$9,8,FALSE) -> #N/A | Z21: =VLOOKUP($B21,$R$3:$Z$9,9,FALSE) -> #N/A
C22: 12 | I22: VITAMALT | J22: =I11 -> 96.1527 | K22: =COUNTA([22]Brewhouse!$A$107) -> 1 | L22: =AVERAGE([22]Brewhouse!$AV$107) -> 96.1527 | M22: =AVERAGE([22]Brewhouse!$AV$5:$AV$14,[22]Brewhouse!$AV$16:$AV$19,[22]Brewhouse!$AV$21:$AV$24,[22]Brewhouse!$AV$26:$AV$33,[22]Brewhouse!$AV$35:$AV$46,[22]Brewhouse!$AV$48:$AV$53,[22]Brewhouse!$AV$55:$AV$62,[22]Brewhouse!$AV$64:$AV$77,[22]Brewhouse!$AV$79:$AV$86,[22]Brewhouse!$AV$88:$AV$95,[22]Brewhouse!$AV$97:$AV$104,[22]Brewhouse!$AV$107) -> 98.24711 | N22: 98 | R22: =B22 -> 0 | S22: =VLOOKUP($B22,$R$3:$X$9,2,FALSE) -> #N/A | T22: =VLOOKUP($B22,$R$3:$X$9,3,FALSE) -> #N/A | U22: =VLOOKUP($B22,$R$3:$X$9,4,FALSE) -> #N/A | V22: =VLOOKUP($B22,$R$3:$X$9,5,FALSE) -> #N/A | W22: =VLOOKUP($B22,$R$3:$X$9,6,FALSE) -> #N/A | X22: =VLOOKUP($B22,$R$3:$X$9,7,FALSE) -> #N/A | Y22: =VLOOKUP($B22,$R$3:$Z$9,8,FALSE) -> #N/A | Z22: =VLOOKUP($B22,$R$3:$Z$9,9,FALSE) -> #N/A
C23: {=[23]Process!$D$933:$D$940} -> 11.6 | D23: 11.93 | I23: MAXIMALT | N23: 98 | R23: =B23 -> 0 | S23: =VLOOKUP($B23,$R$3:$X$9,2,FALSE) -> #N/A | T23: =VLOOKUP($B23,$R$3:$X$9,3,FALSE) -> #N/A | U23: =VLOOKUP($B23,$R$3:$X$9,4,FALSE) -> #N/A | V23: =VLOOKUP($B23,$R$3:$X$9,5,FALSE) -> #N/A | W23: =VLOOKUP($B23,$R$3:$X$9,6,FALSE) -> #N/A | X23: =VLOOKUP($B23,$R$3:$X$9,7,FALSE) -> #N/A | Y23: =VLOOKUP($B23,$R$3:$Z$9,8,FALSE) -> #N/A | Z23: =VLOOKUP($B23,$R$3:$Z$9,9,FALSE) -> #N/A
C24: 11.6 | I24: MACKESON | M24: =AVERAGE([26]Brewhouse!$AT$4:$AT$11,[26]Brewhouse!$AT$13:$AT$16,[26]Brewhouse!$AT$18:$AT$21,[26]Brewhouse!$AT$26,[26]Brewhouse!$AT$28:$AT$35) -> 94.794664 | N24: 98 | R24: =B24 -> 0 | S24: =VLOOKUP($B24,$R$3:$X$9,2,FALSE) -> #N/A | T24: =VLOOKUP($B24,$R$3:$X$9,3,FALSE) -> #N/A | U24: =VLOOKUP($B24,$R$3:$X$9,4,FALSE) -> #N/A | V24: =VLOOKUP($B24,$R$3:$X$9,5,FALSE) -> #N/A | W24: =VLOOKUP($B24,$R$3:$X$9,6,FALSE) -> #N/A | X24: =VLOOKUP($B24,$R$3:$X$9,7,FALSE) -> #N/A | Y24: =VLOOKUP($B24,$R$3:$Z$9,8,FALSE) -> #N/A | Z24: =VLOOKUP($B24,$R$3:$Z$9,9,FALSE) -> #N/A
C25: 11.7 | D25: 11.66 | I25: STARMALT | M25: =AVERAGE([27]Brewhouse!$AY$6:$AY$13,[27]Brewhouse!$AY$15:$AY$20,[27]Brewhouse!$AY$22:$AY$29,[27]Brewhouse!$AY$31:$AY$34,[27]Brewhouse!$AY$36:$AY$43,[27]Brewhouse!$AY$45:$AY$50, [27]Brewhouse!$AY$56:$AY$73,[27]Brewhouse!$AY$75:$AY$92,[27]Brewhouse!$AY$94:$AY$97) -> 97.370193 | N25: 98 | R25: =B25 -> 0 | S25: =VLOOKUP($B25,$R$3:$X$9,2,FALSE) -> #N/A | T25: =VLOOKUP($B25,$R$3:$X$9,3,FALSE) -> #N/A | U25: =VLOOKUP($B25,$R$3:$X$9,4,FALSE) -> #N/A | V25: =VLOOKUP($B25,$R$3:$X$9,5,FALSE) -> #N/A | W25: =VLOOKUP($B25,$R$3:$X$9,6,FALSE) -> #N/A | X25: =VLOOKUP($B25,$R$3:$X$9,7,FALSE) -> #N/A | Y25: =VLOOKUP($B25,$R$3:$Z$9,8,FALSE) -> #N/A | Z25: =VLOOKUP($B25,$R$3:$Z$9,9,FALSE) -> #N/A
C26: 11.8 | I26: HR- Pils | M26: =AVERAGE([28]Brewhouse!$AU$5:$AU$8,[28]Brewhouse!$AU$10:$AU$13,[27]Brewhouse!$AY$75:$AY$77) -> 94.749192 | N26: 98 | R26: =B26 -> 0 | S26: =VLOOKUP($B26,$R$3:$X$9,2,FALSE) -> #N/A | T26: =VLOOKUP($B26,$R$3:$X$9,3,FALSE) -> #N/A | U26: =VLOOKUP($B26,$R$3:$X$9,4,FALSE) -> #N/A | V26: =VLOOKUP($B26,$R$3:$X$9,5,FALSE) -> #N/A | W26: =VLOOKUP($B26,$R$3:$X$9,6,FALSE) -> #N/A | X26: =VLOOKUP($B26,$R$3:$X$9,7,FALSE) -> #N/A | Y26: =VLOOKUP($B26,$R$3:$Z$9,8,FALSE) -> #N/A | Z26: =VLOOKUP($B26,$R$3:$Z$9,9,FALSE) -> #N/A
C27: 11.7 | D27: 11.77 | I27: HR- IPA | M27: =AVERAGE([29]Brewhouse!$AW$26:$AW$27) -> 95.310681 | N27: 98 | R27: =B27 -> 0 | S27: =VLOOKUP($B27,$R$3:$X$9,2,FALSE) -> #N/A | T27: =VLOOKUP($B27,$R$3:$X$9,3,FALSE) -> #N/A | U27: =VLOOKUP($B27,$R$3:$X$9,4,FALSE) -> #N/A | V27: =VLOOKUP($B27,$R$3:$X$9,5,FALSE) -> #N/A | W27: =VLOOKUP($B27,$R$3:$X$9,6,FALSE) -> #N/A | X27: =VLOOKUP($B27,$R$3:$X$9,7,FALSE) -> #N/A | Y27: =VLOOKUP($B27,$R$3:$Z$9,8,FALSE) -> #N/A | Z27: =VLOOKUP($B27,$R$3:$Z$9,9,FALSE) -> #N/A
C28: 11.6 | I28: HR- APA | M28: =AVERAGE([30]Brewhouse!$AU$13:$AU$14) -> 97.110575 | N28: 98 | R28: =B28 -> 0 | S28: =VLOOKUP($B28,$R$3:$X$9,2,FALSE) -> #N/A | T28: =VLOOKUP($B28,$R$3:$X$9,3,FALSE) -> #N/A | U28: =VLOOKUP($B28,$R$3:$X$9,4,FALSE) -> #N/A | V28: =VLOOKUP($B28,$R$3:$X$9,5,FALSE) -> #N/A | W28: =VLOOKUP($B28,$R$3:$X$9,6,FALSE) -> #N/A | X28: =VLOOKUP($B28,$R$3:$X$9,7,FALSE) -> #N/A | Y28: =VLOOKUP($B28,$R$3:$Z$9,8,FALSE) -> #N/A | Z28: =VLOOKUP($B28,$R$3:$Z$9,9,FALSE) -> #N/A
C29: 12 | D29: 11.83 | K29: =SUM(K19:K28) -> 1 | L29: =((L19*K19)+(L20*K20)+(L21*K21)+(L22*K22)+(L23*K23)+(K26*L26)+(L24*K24)+(L25*K25)+(L28*K28))/(K29) -> 96.1527 | M29: =AVERAGE('[31]Jan 31st'!$L$65,'[32]Feb 28th'!$L$35,'[33]Mar. 31st'!$L$35,'[34]Apr. 30th'!$L$45,'[35]May 30th'!$L$37,'[36]June 30th'!$L$57,'[37]July 29th '!$L$44,'[38]Aug 29th'!$L$29,'[39]Sept 30th'!$L$35,L29) -> 97.43322 | N29: 98 | R29: =B29 -> 0 | S29: =VLOOKUP($B29,$R$3:$X$9,2,FALSE) -> #N/A | T29: =VLOOKUP($B29,$R$3:$X$9,3,FALSE) -> #N/A | U29: =VLOOKUP($B29,$R$3:$X$9,4,FALSE) -> #N/A | V29: =VLOOKUP($B29,$R$3:$X$9,5,FALSE) -> #N/A | W29: =VLOOKUP($B29,$R$3:$X$9,6,FALSE) -> #N/A | X29: =VLOOKUP($B29,$R$3:$X$9,7,FALSE) -> #N/A | Y29: =VLOOKUP($B29,$R$3:$Z$9,8,FALSE) -> #N/A | Z29: =VLOOKUP($B29,$R$3:$Z$9,9,FALSE) -> #N/A
C30: 11.7 | R30: =B30 -> 0 | S30: =VLOOKUP($B30,$R$3:$X$9,2,FALSE) -> #N/A | T30: =VLOOKUP($B30,$R$3:$X$9,3,FALSE) -> #N/A | U30: =VLOOKUP($B30,$R$3:$X$9,4,FALSE) -> #N/A | V30: =VLOOKUP($B30,$R$3:$X$9,5,FALSE) -> #N/A | W30: =VLOOKUP($B30,$R$3:$X$9,6,FALSE) -> #N/A | X30: =VLOOKUP($B30,$R$3:$X$9,7,FALSE) -> #N/A | Y30: =VLOOKUP($B30,$R$3:$Z$9,8,FALSE) -> #N/A | Z30: =VLOOKUP($B30,$R$3:$Z$9,9,FALSE) -> #N/A
J31: Daily Brewing Plan
J32: Brand | K32: Brews Achieved (30th) | L32: Average Brews per day
J33: CARIB | L33: MTD | M33: YTD | N33: TARGET
J34: STAG | L34: =K43 -> 1 | M34: =AVERAGE('[31]Jan 29th '!$M$70,'[32]Feb 28th'!$L$40,'[33]Mar. 31st'!$L$40,'[34]Apr. 30th'!$L$50,'[35]May 30th'!$L$42,'[36]June 30th'!$L$62,'[37]July 29th '!$L$49,'[38]Aug 29th'!$L$34,'[39]Sept 30th'!$L$40,[40]Oct.31st!$L$43,'[41]Nov 28th-30th'!$L$45,L34) -> 6.4728644 | N34: 9.2
J35: GUINN
J36: VITAMALT | K36: 1
J37: STARMALT
J38: MACKESON
J39: HURRICANE REEF- IPA
J40: HURRICANE REEF- APA
B41: AVERAGE | J41: HR- PILSNER
J42: CARIBE
J43: Total | K43: =SUM(K33:K42) -> 1
...

Sheet Dec 2nd
S1: P.G. | U1: Hot Time | W1: Process Time | Y1: Cooling Time
B2: Brewing Department Daily Process Loss Report | S2: Lower | T2: Upper | U2: Lower | V2: Upper | W2: Lower | X2: Upper | Y2: Lower | Z2: Upper
R3: CARIB | S3: 11.6 | T3: 12 | U3: 0 | V3: 0.11805556 | W3: 0.22569444 | X3: 0.26388889 | Y3: 0 | Z3: 60 | AB3: HR- PISNER
B4: Date: | C4: 45994 | J4: LOT WORT COLOUR: | M4: Filter Sheets (Target 20 days) | R4: STAG | S4: 11.6 | T4: 12 | U4: 0 | V4: 0.11805556 | W4: 0.22569444 | X4: 0.26388889 | Y4: 0 | Z4: 60
M5: Double | N5: Single | R5: GUINNESS | S5: 17 | T5: 17.5 | U5: 0 | V5: 0.10763889 | W5: 0.24652778 | X5: 0.28472222 | Y5: 0 | Z5: 60
J6: MALT LOT: Lot #8 | L6: Sheet Day | R6: MACKESON | S6: 13.3 | T6: 13.5 | U6: 0 | V6: 0.12905093 | W6: 0.27430556 | X6: 0.30208333 | Y6: 0
R7: STARMALT | S7: 17 | T7: 17.4 | U7: 0 | V7: 0.13605324 | W7: 0.27430556 | X7: 0.30902778 | Y7: 0 | Z7: 85
B8: Brand | C8: Brew no. | D8: Kett. Hls | E8: Wort | F8: Cool Time(Mins) | G8: Cast. P.G. (Lab Result) | H8: Cast P.G. (Cellar Operator)-gravity | I8: Extr. Rec (77.9%) | J8: Theor. Extr. (77.5%) | K8: Boil Off /Vol. (4-6%) | L8: Boil Time | M8: Total Hot | N8: Brewing | O8: Operator | R8: Hurricane Reef | S8: 16.6 | T8: 17 | U8: 0 | V8: 0.12905093 | W8: 0.27430556 | X8: 0.30208333 | Y8: 0
E9: Meter (Hls) | F9: Target(< 60Mins) | M9: Time | R9: VITAMALT | S9: 14.2 | T9: 14.6 | U9: 0 | V9: 0.13905093 | W9: 0.26041667 | X9: 0.29513889 | Y9: 0 | Z9: 75
B10: VITAMALT | C10: =[22]Brewhouse!A108 -> VM093 | D10: =[22]Brewhouse!AE108 -> 50.1 | E10: =[22]Brewhouse!AJ108 -> 47 | F10: =[22]Brewhouse!X108 -> 83 | G10: =[22]Brewhouse!AH108 -> 14.3 | H10: 14.4 | I10: =[22]Brewhouse!AV108 -> 95.341284 | J10: =[22]Brewhouse!AW108 -> 95.366406 | K10: =[22]Brewhouse!S108 -> 8.7025948 | L10: =[22]Brewhouse!R108 -> 60 | M10: =[22]Brewhouse!$W108-[22]Brewhouse!$V108 -> 0.1375 | N10: =[22]Brewhouse!AB108 -> 0.27569444 | O10: =[22]Brewhouse!$AZ108 -> R.Sookram | R10: =B10 -> VITAMALT | S10: =VLOOKUP($B10,$R$3:$X$9,2,FALSE) -> 14.2 | T10: =VLOOKUP($B10,$R$3:$X$9,3,FALSE) -> 14.6 | U10: =VLOOKUP($B10,$R$3:$X$9,4,FALSE) -> 0 | V10: =VLOOKUP($B10,$R$3:$X$9,5,FALSE) -> 0.13905093 | W10: =VLOOKUP($B10,$R$3:$X$9,6,FALSE) -> 0.26041667 | X10: =VLOOKUP($B10,$R$3:$X$9,7,FALSE) -> 0.29513889 | Y10: =VLOOKUP($B10,$R$3:$Z$9,8,FALSE) -> 0 | Z10: =VLOOKUP($B10,$R$3:$Z$9,9,FALSE) -> 75
B11: VITAMALT | C11: =[22]Brewhouse!A109 -> VM094 | D11: =[22]Brewhouse!AE109 -> 50 | E11: =[22]Brewhouse!AJ109 -> 47.2 | F11: =[22]Brewhouse!X109 -> 77 | G11: =[22]Brewhouse!AH109 -> 14.4 | H11: 14.4 | I11: =[22]Brewhouse!AV109 -> 96.709535 | J11: =[22]Brewhouse!AW109 -> 96.734806 | K11: =[22]Brewhouse!S109 -> 10.32 | L11: =[22]Brewhouse!R109 -> 61 | M11: =[22]Brewhouse!$W109-[22]Brewhouse!$V109 -> 0.1375 | N11: =[22]Brewhouse!AB109 -> 0.28263889 | O11: =[22]Brewhouse!$AZ109 -> R.Sookram | R11: =B11 -> VITAMALT | S11: =VLOOKUP($B11,$R$3:$X$9,2,FALSE) -> 14.2 | T11: =VLOOKUP($B11,$R$3:$X$9,3,FALSE) -> 14.6 | U11: =VLOOKUP($B11,$R$3:$X$9,4,FALSE) -> 0 | V11: =VLOOKUP($B11,$R$3:$X$9,5,FALSE) -> 0.13905093 | W11: =VLOOKUP($B11,$R$3:$X$9,6,FALSE) -> 0.26041667 | X11: =VLOOKUP($B11,$R$3:$X$9,7,FALSE) -> 0.29513889 | Y11: =VLOOKUP($B11,$R$3:$Z$9,8,FALSE) -> 0 | Z11: =VLOOKUP($B11,$R$3:$Z$9,9,FALSE) -> 75
B12: VITAMALT | C12: =[22]Brewhouse!A110 -> VM095 | D12: =[22]Brewhouse!AE110 -> 50 | E12: =[22]Brewhouse!AJ110 -> 47.3 | F12: =[22]Brewhouse!X110 -> 74 | G12: =[22]Brewhouse!AH110 -> 14.5 | H12: 14.5 | I12: =[22]Brewhouse!AV110 -> 97.716944 | J12: =[22]Brewhouse!AW110 -> 97.742371 | K12: =[22]Brewhouse!S110 -> 5.52 | L12: =[22]Brewhouse!R110 -> 60 | M12: =[22]Brewhouse!$W110-[22]Brewhouse!$V110 -> 0.13263889 | N12: =[22]Brewhouse!AB110 -> 0.26944444 | O12: =[22]Brewhouse!$AZ110 -> K. Benjamin | R12: =B12 -> VITAMALT | S12: =VLOOKUP($B12,$R$3:$X$9,2,FALSE) -> 14.2 | T12: =VLOOKUP($B12,$R$3:$X$9,3,FALSE) -> 14.6 | U12: =VLOOKUP($B12,$R$3:$X$9,4,FALSE) -> 0 | V12: =VLOOKUP($B12,$R$3:$X$9,5,FALSE) -> 0.13905093 | W12: =VLOOKUP($B12,$R$3:$X$9,6,FALSE) -> 0.26041667 | X12: =VLOOKUP($B12,$R$3:$X$9,7,FALSE) -> 0.29513889 | Y12: =VLOOKUP($B12,$R$3:$Z$9,8,FALSE) -> 0 | Z12: =VLOOKUP($B12,$R$3:$Z$9,9,FALSE) -> 75
B13: VITAMALT | C13: =[22]Brewhouse!A111 -> VM096 | D13: =[22]Brewhouse!AE111 -> 50 | E13: =[22]Brewhouse!AJ111 -> 47.47 | F13: =[22]Brewhouse!X111 -> 81 | G13: =[22]Brewhouse!AH111 -> 14.3 | H13: 14.34 | I13: =[22]Brewhouse!AV111 -> 96.596804 | J13: =[22]Brewhouse!AW111 -> 96.62194 | K13: =[22]Brewhouse!S111 -> 6.72 | L13: =[22]Brewhouse!R111 -> 60 | M13: =[22]Brewhouse!$W111-[22]Brewhouse!$V111 -> 0.13888889 | N13: =[22]Brewhouse!AB111 -> 0.275 | O13: =[22]Brewhouse!$AZ111 -> K. Benjamin | R13: =B13 -> VITAMALT | S13: =VLOOKUP($B13,$R$3:$X$9,2,FALSE) -> 14.2 | T13: =VLOOKUP($B13,$R$3:$X$9,3,FALSE) -> 14.6 | U13: =VLOOKUP($B13,$R$3:$X$9,4,FALSE) -> 0 | V13: =VLOOKUP($B13,$R$3:$X$9,5,FALSE) -> 0.13905093 | W13: =VLOOKUP($B13,$R$3:$X$9,6,FALSE) -> 0.26041667 | X13: =VLOOKUP($B13,$R$3:$X$9,7,FALSE) -> 0.29513889 | Y13: =VLOOKUP($B13,$R$3:$Z$9,8,FALSE) -> 0 | Z13: =VLOOKUP($B13,$R$3:$Z$9,9,FALSE) -> 75
B14: VITAMALT | C14: =[22]Brewhouse!A112 -> VM097 | D14: =[22]Brewhouse!AE112 -> 50 | E14: =[22]Brewhouse!AJ112 -> 48 | F14: =[22]Brewhouse!X112 -> 85 | G14: =[22]Brewhouse!AH112 -> 14.3 | H14: 14.4 | I14: =[22]Brewhouse!AV112 -> 97.675302 | J14: =[22]Brewhouse!AW112 -> 97.700719 | K14: =[22]Brewhouse!S112 -> 6.12 | L14: =[22]Brewhouse!R112 -> 60 | M14: =[22]Brewhouse!$W112-[22]Brewhouse!$V112 -> 0.14305556 | N14: =[22]Brewhouse!AB112 -> 0.2875 | O14: =[22]Brewhouse!$AZ112 -> K. Benjamin | R14: =B14 -> VITAMALT | S14: =VLOOKUP($B14,$R$3:$X$9,2,FALSE) -> 14.2 | T14: =VLOOKUP($B14,$R$3:$X$9,3,FALSE) -> 14.6 | U14: =VLOOKUP($B14,$R$3:$X$9,4,FALSE) -> 0 | V14: =VLOOKUP($B14,$R$3:$X$9,5,FALSE) -> 0.13905093 | W14: =VLOOKUP($B14,$R$3:$X$9,6,FALSE) -> 0.26041667 | X14: =VLOOKUP($B14,$R$3:$X$9,7,FALSE) -> 0.29513889 | Y14: =VLOOKUP($B14,$R$3:$Z$9,8,FALSE) -> 0 | Z14: =VLOOKUP($B14,$R$3:$Z$9,9,FALSE) -> 75
B15: VITAMALT | C15: =[22]Brewhouse!A113 -> VM098 | D15: =[22]Brewhouse!AE113 -> 50 | E15: =[22]Brewhouse!AJ113 -> 47.3 | F15: =[22]Brewhouse!X113 -> 85 | G15: =[22]Brewhouse!AH113 -> 14.6 | H15: 14.7 | I15: =[22]Brewhouse!AV113 -> 98.52114 | J15: =[22]Brewhouse!AW113 -> 98.546668 | K15: =[22]Brewhouse!S113 -> 5.92 | L15: =[22]Brewhouse!R113 -> 60 | M15: =[22]Brewhouse!$W113-[22]Brewhouse!$V113 -> 0.13888889 | N15: =[22]Brewhouse!AB113 -> 0.28611111 | O15: =[22]Brewhouse!$AZ113 -> R. Regis | R15: =B15 -> VITAMALT | S15: =VLOOKUP($B15,$R$3:$X$9,2,FALSE) -> 14.2 | T15: =VLOOKUP($B15,$R$3:$X$9,3,FALSE) -> 14.6 | U15: =VLOOKUP($B15,$R$3:$X$9,4,FALSE) -> 0 | V15: =VLOOKUP($B15,$R$3:$X$9,5,FALSE) -> 0.13905093 | W15: =VLOOKUP($B15,$R$3:$X$9,6,FALSE) -> 0.26041667 | X15: =VLOOKUP($B15,$R$3:$X$9,7,FALSE) -> 0.29513889 | Y15: =VLOOKUP($B15,$R$3:$Z$9,8,FALSE) -> 0 | Z15: =VLOOKUP($B15,$R$3:$Z$9,9,FALSE) -> 75
B16: VITAMALT | C16: =[22]Brewhouse!A114 -> VM099 | D16: =[22]Brewhouse!AE114 -> 50 | E16: =[22]Brewhouse!AJ114 -> 48.4 | F16: =[22]Brewhouse!X114 -> 86 | G16: =[22]Brewhouse!AH114 -> 14.3 | H16: 14.4 | I16: =[22]Brewhouse!AV114 -> 98.69569 | J16: =[22]Brewhouse!AW114 -> 98.721154 | K16: =[22]Brewhouse!S114 -> 5.52 | L16: =[22]Brewhouse!R114 -> 62 | M16: =[22]Brewhouse!$W114-[22]Brewhouse!$V114 -> 0.12569444 | N16: =[22]Brewhouse!AB114 -> 0.27083333 | O16: =[22]Brewhouse!$AZ114 -> R. Regis | R16: =B16 -> VITAMALT | S16: =VLOOKUP($B16,$R$3:$X$9,2,FALSE) -> 14.2 | T16: =VLOOKUP($B16,$R$3:$X$9,3,FALSE) -> 14.6 | U16: =VLOOKUP($B16,$R$3:$X$9,4,FALSE) -> 0 | V16: =VLOOKUP($B16,$R$3:$X$9,5,FALSE) -> 0.13905093 | W16: =VLOOKUP($B16,$R$3:$X$9,6,FALSE) -> 0.26041667 | X16: =VLOOKUP($B16,$R$3:$X$9,7,FALSE) -> 0.29513889 | Y16: =VLOOKUP($B16,$R$3:$Z$9,8,FALSE) -> 0 | Z16: =VLOOKUP($B16,$R$3:$Z$9,9,FALSE) -> 75
B17: VITAMALT | C17: =[22]Brewhouse!A115 -> VM100 | D17: =[22]Brewhouse!AE115 -> 50 | E17: =[22]Brewhouse!AJ115 -> 47.9 | F17: =[22]Brewhouse!X115 -> 88 | G17: =[22]Brewhouse!AH115 -> 14.2 | H17: 14.2 | I17: =[22]Brewhouse!AV115 -> 96.358676 | J17: =[22]Brewhouse!AW115 -> 96.384171 | K17: =[22]Brewhouse!S115 -> 6.12 | L17: =[22]Brewhouse!R115 -> 61 | M17: =[22]Brewhouse!$W115-[22]Brewhouse!$V115 -> 0.14027778 | N17: =[22]Brewhouse!AB115 -> 0.27847222 | O17: =[22]Brewhouse!$AZ115 -> R. Regis | R17: =B17 -> VITAMALT | S17: =VLOOKUP($B17,$R$3:$X$9,2,FALSE) -> 14.2 | T17: =VLOOKUP($B17,$R$3:$X$9,3,FALSE) -> 14.6 | U17: =VLOOKUP($B17,$R$3:$X$9,4,FALSE) -> 0 | V17: =VLOOKUP($B17,$R$3:$X$9,5,FALSE) -> 0.13905093 | W17: =VLOOKUP($B17,$R$3:$X$9,6,FALSE) -> 0.26041667 | X17: =VLOOKUP($B17,$R$3:$X$9,7,FALSE) -> 0.29513889 | Y17: =VLOOKUP($B17,$R$3:$Z$9,8,FALSE) -> 0 | Z17: =VLOOKUP($B17,$R$3:$Z$9,9,FALSE) -> 75
B18: VITAMALT | C18: =[22]Brewhouse!A116 -> VM101 | D18: =[22]Brewhouse!AE116 -> 50.1 | E18: =[22]Brewhouse!AJ116 -> 47.8 | F18: =[22]Brewhouse!X116 -> 82 | G18: =[22]Brewhouse!AH116 -> 14.3 | H18: 14.4 | I18: =[22]Brewhouse!AV116 -> 97.166708 | J18: =[22]Brewhouse!AW116 -> 97.192098 | K18: =[22]Brewhouse!S116 -> 6.7065868 | L18: =[22]Brewhouse!R116 -> 58 | M18: =[22]Brewhouse!$W116-[22]Brewhouse!$V116 -> 0.13611111 | N18: =[22]Brewhouse!AB116 -> 0.30347222 | O18: =[22]Brewhouse!$AZ116 -> R.Sookram | R18: =B18 -> VITAMALT | S18: =VLOOKUP($B18,$R$3:$X$9,2,FALSE) -> 14.2 | T18: =VLOOKUP($B18,$R$3:$X$9,3,FALSE) -> 14.6 | U18: =VLOOKUP($B18,$R$3:$X$9,4,FALSE) -> 0 | V18: =VLOOKUP($B18,$R$3:$X$9,5,FALSE) -> 0.13905093 | W18: =VLOOKUP($B18,$R$3:$X$9,6,FALSE) -> 0.26041667 | X18: =VLOOKUP($B18,$R$3:$X$9,7,FALSE) -> 0.29513889 | Y18: =VLOOKUP($B18,$R$3:$Z$9,8,FALSE) -> 0 | Z18: =VLOOKUP($B18,$R$3:$Z$9,9,FALSE) -> 75
R19: =B19 -> 0 | S19: =VLOOKUP($B19,$R$3:$X$9,2,FALSE) -> #N/A | T19: =VLOOKUP($B19,$R$3:$X$9,3,FALSE) -> #N/A | U19: =VLOOKUP($B19,$R$3:$X$9,4,FALSE) -> #N/A | V19: =VLOOKUP($B19,$R$3:$X$9,5,FALSE) -> #N/A | W19: =VLOOKUP($B19,$R$3:$X$9,6,FALSE) -> #N/A | X19: =VLOOKUP($B19,$R$3:$X$9,7,FALSE) -> #N/A | Y19: =VLOOKUP($B19,$R$3:$Z$9,8,FALSE) -> #N/A | Z19: =VLOOKUP($B19,$R$3:$Z$9,9,FALSE) -> #N/A
R20: =B20 -> 0 | S20: =VLOOKUP($B20,$R$3:$X$9,2,FALSE) -> #N/A | T20: =VLOOKUP($B20,$R$3:$X$9,3,FALSE) -> #N/A | U20: =VLOOKUP($B20,$R$3:$X$9,4,FALSE) -> #N/A | V20: =VLOOKUP($B20,$R$3:$X$9,5,FALSE) -> #N/A | W20: =VLOOKUP($B20,$R$3:$X$9,6,FALSE) -> #N/A | X20: =VLOOKUP($B20,$R$3:$X$9,7,FALSE) -> #N/A | Y20: =VLOOKUP($B20,$R$3:$Z$9,8,FALSE) -> #N/A | Z20: =VLOOKUP($B20,$R$3:$Z$9,9,FALSE) -> #N/A
R21: =B21 -> 0 | S21: =VLOOKUP($B21,$R$3:$X$9,2,FALSE) -> #N/A | T21: =VLOOKUP($B21,$R$3:$X$9,3,FALSE) -> #N/A | U21: =VLOOKUP($B21,$R$3:$X$9,4,FALSE) -> #N/A | V21: =VLOOKUP($B21,$R$3:$X$9,5,FALSE) -> #N/A | W21: =VLOOKUP($B21,$R$3:$X$9,6,FALSE) -> #N/A | X21: =VLOOKUP($B21,$R$3:$X$9,7,FALSE) -> #N/A | Y21: =VLOOKUP($B21,$R$3:$Z$9,8,FALSE) -> #N/A | Z21: =VLOOKUP($B21,$R$3:$Z$9,9,FALSE) -> #N/A
R22: =B22 -> 0 | S22: =VLOOKUP($B22,$R$3:$X$9,2,FALSE) -> #N/A | T22: =VLOOKUP($B22,$R$3:$X$9,3,FALSE) -> #N/A | U22: =VLOOKUP($B22,$R$3:$X$9,4,FALSE) -> #N/A | V22: =VLOOKUP($B22,$R$3:$X$9,5,FALSE) -> #N/A | W22: =VLOOKUP($B22,$R$3:$X$9,6,FALSE) -> #N/A | X22: =VLOOKUP($B22,$R$3:$X$9,7,FALSE) -> #N/A | Y22: =VLOOKUP($B22,$R$3:$Z$9,8,FALSE) -> #N/A | Z22: =VLOOKUP($B22,$R$3:$Z$9,9,FALSE) -> #N/A
R23: =B23 -> 0 | S23: =VLOOKUP($B23,$R$3:$X$9,2,FALSE) -> #N/A | T23: =VLOOKUP($B23,$R$3:$X$9,3,FALSE) -> #N/A | U23: =VLOOKUP($B23,$R$3:$X$9,4,FALSE) -> #N/A | V23: =VLOOKUP($B23,$R$3:$X$9,5,FALSE) -> #N/A | W23: =VLOOKUP($B23,$R$3:$X$9,6,FALSE) -> #N/A | X23: =VLOOKUP($B23,$R$3:$X$9,7,FALSE) -> #N/A | Y23: =VLOOKUP($B23,$R$3:$Z$9,8,FALSE) -> #N/A | Z23: =VLOOKUP($B23,$R$3:$Z$9,9,FALSE) -> #N/A
B24: BRAND | D24: BBT P.G./ O.G | I24: Brand | K24: MTD No. of Brews | L24: MTD | M24: YTD | N24: Target | R24: =B24 -> BRAND | S24: =VLOOKUP($B24,$R$3:$X$9,2,FALSE) -> #N/A | T24: =VLOOKUP($B24,$R$3:$X$9,3,FALSE) -> #N/A | U24: =VLOOKUP($B24,$R$3:$X$9,4,FALSE) -> #N/A | V24: =VLOOKUP($B24,$R$3:$X$9,5,FALSE) -> #N/A | W24: =VLOOKUP($B24,$R$3:$X$9,6,FALSE) -> #N/A | X24: =VLOOKUP($B24,$R$3:$X$9,7,FALSE) -> #N/A | Y24: =VLOOKUP($B24,$R$3:$Z$9,8,FALSE) -> #N/A | Z24: =VLOOKUP($B24,$R$3:$Z$9,9,FALSE) -> #N/A
B25: =I25 -> CARIB | C25: {=[23]Process!$D$941:$D$945} -> 11.8 | D25: 11.94 | I25: CARIB | M25: =AVERAGE([23]Brewhouse!$AU$102:$AU$171,[23]Brewhouse!$AU$173:$AU$253,[23]Brewhouse!$AU$255:$AU$339,[23]Brewhouse!$AU$341:$AU$346,[23]Brewhouse!$AU$348,[23]Brewhouse!$AU$349:$AU$406,[23]Brewhouse!$AU$408:$AU$491,[23]Brewhouse!$AU$493:$AU$578,[23]Brewhouse!$AU$580:$AU$652,[23]Brewhouse!$AU$655:$AU$738,[23]Brewhouse!$A$740:$A$821,[23]Brewhouse!$AU$823:$AU$862,[24]Brewhouse!$AS$420:$AS$423,[23]Brewhouse!$AU$867:$AU$912,[23]Brewhouse!$AU$914:$AU$1003) -> 97.751831 | N25: 98 | R25: =B25 -> CARIB | S25: =VLOOKUP($B25,$R$3:$X$9,2,FALSE) -> 11.6 | T25: =VLOOKUP($B25,$R$3:$X$9,3,FALSE) -> 12 | U25: =VLOOKUP($B25,$R$3:$X$9,4,FALSE) -> 0 | V25: =VLOOKUP($B25,$R$3:$X$9,5,FALSE) -> 0.11805556 | W25: =VLOOKUP($B25,$R$3:$X$9,6,FALSE) -> 0.22569444 | X25: =VLOOKUP($B25,$R$3:$X$9,7,FALSE) -> 0.26388889 | Y25: =VLOOKUP($B25,$R$3:$Z$9,8,FALSE) -> 0 | Z25: =VLOOKUP($B25,$R$3:$Z$9,9,FALSE) -> 60
C26: 11.7 | I26: STAG | M26: =AVERAGE([24]Brewhouse!$AS$15:$AS$64,[24]Brewhouse!$AS$66:$AS$103,[24]Brewhouse!$AS$105:$AS$140,[24]Brewhouse!$AS$142:$AS$193,[24]Brewhouse!$AS$195:$AS$240,[24]Brewhouse!$AS$242:$AS$273,[24]Brewhouse!$AS$275:$AS$322,[24]Brewhouse!$AS$324:$AS$359,[24]Brewhouse!$AS$361:$AS$397,[24]Brewhouse!$AS$399:$AS$419,[24]Brewhouse!$AS$424:$AS$447,[24]Brewhouse!$AS$449:$AS$484) -> 97.847962 | N26: 98 | R26: =B26 -> 0 | S26: =VLOOKUP($B26,$R$3:$X$9,2,FALSE) -> #N/A | T26: =VLOOKUP($B26,$R$3:$X$9,3,FALSE) -> #N/A | U26: =VLOOKUP($B26,$R$3:$X$9,4,FALSE) -> #N/A | V26: =VLOOKUP($B26,$R$3:$X$9,5,FALSE) -> #N/A | W26: =VLOOKUP($B26,$R$3:$X$9,6,FALSE) -> #N/A | X26: =VLOOKUP($B26,$R$3:$X$9,7,FALSE) -> #N/A | Y26: =VLOOKUP($B26,$R$3:$Z$9,8,FALSE) -> #N/A | Z26: =VLOOKUP($B26,$R$3:$Z$9,9,FALSE) -> #N/A
C27: 11.6 | D27: 11.93 | I27: GUINNESS | M27: =AVERAGE([25]Brewhouse!$AU$4:$AU$7,[25]Brewhouse!$AU$9:$AU$22,[25]Brewhouse!$AU$24:$AU$35,[25]Brewhouse!$AU$37:$AU$45,[25]Brewhouse!$AU$47:$AU$62,[25]Brewhouse!$AU$64:$AU$79,[25]Brewhouse!$AU$81:$AU$92,[25]Brewhouse!$AU$94:$AU$97,[25]Brewhouse!$AU$99:$AU$106,[25]Brewhouse!$AU$116:$AU$123) -> 96.481277 | N27: 98 | R27: =B27 -> 0 | S27: =VLOOKUP($B27,$R$3:$X$9,2,FALSE) -> #N/A | T27: =VLOOKUP($B27,$R$3:$X$9,3,FALSE) -> #N/A | U27: =VLOOKUP($B27,$R$3:$X$9,4,FALSE) -> #N/A | V27: =VLOOKUP($B27,$R$3:$X$9,5,FALSE) -> #N/A | W27: =VLOOKUP($B27,$R$3:$X$9,6,FALSE) -> #N/A | X27: =VLOOKUP($B27,$R$3:$X$9,7,FALSE) -> #N/A | Y27: =VLOOKUP($B27,$R$3:$Z$9,8,FALSE) -> #N/A | Z27: =VLOOKUP($B27,$R$3:$Z$9,9,FALSE) -> #N/A
C28: 11.8 | I28: VITAMALT | J28: =AVERAGE(I10:I18) -> 97.198009 | K28: =COUNTA([22]Brewhouse!$A$107:$A$116) -> 10 | L28: =AVERAGE([22]Brewhouse!$AV$107:$AV$116) -> 97.093478 | M28: =AVERAGE([22]Brewhouse!$AV$5:$AV$14,[22]Brewhouse!$AV$16:$AV$19,[22]Brewhouse!$AV$21:$AV$24,[22]Brewhouse!$AV$26:$AV$33,[22]Brewhouse!$AV$35:$AV$46,[22]Brewhouse!$AV$48:$AV$53,[22]Brewhouse!$AV$55:$AV$62,[22]Brewhouse!$AV$64:$AV$77,[22]Brewhouse!$AV$79:$AV$86,[22]Brewhouse!$AV$88:$AV$95,[22]Brewhouse!$AV$97:$AV$104,[22]Brewhouse!$AV$107:$AV$116) -> 98.152691 | N28: 98 | R28: =B28 -> 0 | S28: =VLOOKUP($B28,$R$3:$X$9,2,FALSE) -> #N/A | T28: =VLOOKUP($B28,$R$3:$X$9,3,FALSE) -> #N/A | U28: =VLOOKUP($B28,$R$3:$X$9,4,FALSE) -> #N/A | V28: =VLOOKUP($B28,$R$3:$X$9,5,FALSE) -> #N/A | W28: =VLOOKUP($B28,$R$3:$X$9,6,FALSE) -> #N/A | X28: =VLOOKUP($B28,$R$3:$X$9,7,FALSE) -> #N/A | Y28: =VLOOKUP($B28,$R$3:$Z$9,8,FALSE) -> #N/A | Z28: =VLOOKUP($B28,$R$3:$Z$9,9,FALSE) -> #N/A
C29: 11.6 | I29: MAXIMALT | N29: 98 | R29: =B29 -> 0 | S29: =VLOOKUP($B29,$R$3:$X$9,2,FALSE) -> #N/A | T29: =VLOOKUP($B29,$R$3:$X$9,3,FALSE) -> #N/A | U29: =VLOOKUP($B29,$R$3:$X$9,4,FALSE) -> #N/A | V29: =VLOOKUP($B29,$R$3:$X$9,5,FALSE) -> #N/A | W29: =VLOOKUP($B29,$R$3:$X$9,6,FALSE) -> #N/A | X29: =VLOOKUP($B29,$R$3:$X$9,7,FALSE) -> #N/A | Y29: =VLOOKUP($B29,$R$3:$Z$9,8,FALSE) -> #N/A | Z29: =VLOOKUP($B29,$R$3:$Z$9,9,FALSE) -> #N/A
I30: MACKESON | M30: =AVERAGE([26]Brewhouse!$AT$4:$AT$11,[26]Brewhouse!$AT$13:$AT$16,[26]Brewhouse!$AT$18:$AT$21,[26]Brewhouse!$AT$26,[26]Brewhouse!$AT$28:$AT$35) -> 94.794664 | N30: 98 | R30: =B30 -> 0 | S30: =VLOOKUP($B30,$R$3:$X$9,2,FALSE) -> #N/A | T30: =VLOOKUP($B30,$R$3:$X$9,3,FALSE) -> #N/A | U30: =VLOOKUP($B30,$R$3:$X$9,4,FALSE) -> #N/A | V30: =VLOOKUP($B30,$R$3:$X$9,5,FALSE) -> #N/A | W30: =VLOOKUP($B30,$R$3:$X$9,6,FALSE) -> #N/A | X30: =VLOOKUP($B30,$R$3:$X$9,7,FALSE) -> #N/A | Y30: =VLOOKUP($B30,$R$3:$Z$9,8,FALSE) -> #N/A | Z30: =VLOOKUP($B30,$R$3:$Z$9,9,FALSE) -> #N/A
I31: STARMALT | M31: =AVERAGE([27]Brewhouse!$AY$6:$AY$13,[27]Brewhouse!$AY$15:$AY$20,[27]Brewhouse!$AY$22:$AY$29,[27]Brewhouse!$AY$31:$AY$34,[27]Brewhouse!$AY$36:$AY$43,[27]Brewhouse!$AY$45:$AY$50, [27]Brewhouse!$AY$56:$AY$73,[27]Brewhouse!$AY$75:$AY$92,[27]Brewhouse!$AY$94:$AY$97) -> 97.370193 | N31: 98 | R31: =B31 -> 0 | S31: =VLOOKUP($B31,$R$3:$X$9,2,FALSE) -> #N/A | T31: =VLOOKUP($B31,$R$3:$X$9,3,FALSE) -> #N/A | U31: =VLOOKUP($B31,$R$3:$X$9,4,FALSE) -> #N/A | V31: =VLOOKUP($B31,$R$3:$X$9,5,FALSE) -> #N/A | W31: =VLOOKUP($B31,$R$3:$X$9,6,FALSE) -> #N/A | X31: =VLOOKUP($B31,$R$3:$X$9,7,FALSE) -> #N/A | Y31: =VLOOKUP($B31,$R$3:$Z$9,8,FALSE) -> #N/A | Z31: =VLOOKUP($B31,$R$3:$Z$9,9,FALSE) -> #N/A
I32: HR- Pils | M32: =AVERAGE([28]Brewhouse!$AU$5:$AU$8,[28]Brewhouse!$AU$10:$AU$13,[27]Brewhouse!$AY$75:$AY$77) -> 94.749192 | N32: 98 | R32: =B32 -> 0 | S32: =VLOOKUP($B32,$R$3:$X$9,2,FALSE) -> #N/A | T32: =VLOOKUP($B32,$R$3:$X$9,3,FALSE) -> #N/A | U32: =VLOOKUP($B32,$R$3:$X$9,4,FALSE) -> #N/A | V32: =VLOOKUP($B32,$R$3:$X$9,5,FALSE) -> #N/A | W32: =VLOOKUP($B32,$R$3:$X$9,6,FALSE) -> #N/A | X32: =VLOOKUP($B32,$R$3:$X$9,7,FALSE) -> #N/A | Y32: =VLOOKUP($B32,$R$3:$Z$9,8,FALSE) -> #N/A | Z32: =VLOOKUP($B32,$R$3:$Z$9,9,FALSE) -> #N/A
I33: HR- IPA | M33: =AVERAGE([29]Brewhouse!$AW$26:$AW$27) -> 95.310681 | N33: 98 | R33: =B33 -> 0 | S33: =VLOOKUP($B33,$R$3:$X$9,2,FALSE) -> #N/A | T33: =VLOOKUP($B33,$R$3:$X$9,3,FALSE) -> #N/A | U33: =VLOOKUP($B33,$R$3:$X$9,4,FALSE) -> #N/A | V33: =VLOOKUP($B33,$R$3:$X$9,5,FALSE) -> #N/A | W33: =VLOOKUP($B33,$R$3:$X$9,6,FALSE) -> #N/A | X33: =VLOOKUP($B33,$R$3:$X$9,7,FALSE) -> #N/A | Y33: =VLOOKUP($B33,$R$3:$Z$9,8,FALSE) -> #N/A | Z33: =VLOOKUP($B33,$R$3:$Z$9,9,FALSE) -> #N/A
I34: HR- APA | M34: =AVERAGE([30]Brewhouse!$AU$13:$AU$14) -> 97.110575 | N34: 98 | R34: =B34 -> 0 | S34: =VLOOKUP($B34,$R$3:$X$9,2,FALSE) -> #N/A | T34: =VLOOKUP($B34,$R$3:$X$9,3,FALSE) -> #N/A | U34: =VLOOKUP($B34,$R$3:$X$9,4,FALSE) -> #N/A | V34: =VLOOKUP($B34,$R$3:$X$9,5,FALSE) -> #N/A | W34: =VLOOKUP($B34,$R$3:$X$9,6,FALSE) -> #N/A | X34: =VLOOKUP($B34,$R$3:$X$9,7,FALSE) -> #N/A | Y34: =VLOOKUP($B34,$R$3:$Z$9,8,FALSE) -> #N/A | Z34: =VLOOKUP($B34,$R$3:$Z$9,9,FALSE) -> #N/A
K35: =SUM(K25:K34) -> 10 | L35: =((L25*K25)+(L26*K26)+(L27*K27)+(L28*K28)+(L29*K29)+(K32*L32)+(L30*K30)+(L31*K31)+(L34*K34))/(K35) -> 97.093478 | M35: =AVERAGE('[31]Jan 31st'!$L$65,'[32]Feb 28th'!$L$35,'[33]Mar. 31st'!$L$35,'[34]Apr. 30th'!$L$45,'[35]May 30th'!$L$37,'[36]June 30th'!$L$57,'[37]July 29th '!$L$44,'[38]Aug 29th'!$L$29,'[39]Sept 30th'!$L$35,L35) -> 97.527298 | N35: 98 | R35: =B35 -> 0 | S35: =VLOOKUP($B35,$R$3:$X$9,2,FALSE) -> #N/A | T35: =VLOOKUP($B35,$R$3:$X$9,3,FALSE) -> #N/A | U35: =VLOOKUP($B35,$R$3:$X$9,4,FALSE) -> #N/A | V35: =VLOOKUP($B35,$R$3:$X$9,5,FALSE) -> #N/A | W35: =VLOOKUP($B35,$R$3:$X$9,6,FALSE) -> #N/A | X35: =VLOOKUP($B35,$R$3:$X$9,7,FALSE) -> #N/A | Y35: =VLOOKUP($B35,$R$3:$Z$9,8,FALSE) -> #N/A | Z35: =VLOOKUP($B35,$R$3:$Z$9,9,FALSE) -> #N/A
R36: =B36 -> 0 | S36: =VLOOKUP($B36,$R$3:$X$9,2,FALSE) -> #N/A | T36: =VLOOKUP($B36,$R$3:$X$9,3,FALSE) -> #N/A | U36: =VLOOKUP($B36,$R$3:$X$9,4,FALSE) -> #N/A | V36: =VLOOKUP($B36,$R$3:$X$9,5,FALSE) -> #N/A | W36: =VLOOKUP($B36,$R$3:$X$9,6,FALSE) -> #N/A | X36: =VLOOKUP($B36,$R$3:$X$9,7,FALSE) -> #N/A | Y36: =VLOOKUP($B36,$R$3:$Z$9,8,FALSE) -> #N/A | Z36: =VLOOKUP($B36,$R$3:$Z$9,9,FALSE) -> #N/A
J37: Daily Brewing Plan
J38: Brand | K38: Brews Achieved | L38: Average Brews per day
J39: CARIB | L39: MTD | M39: YTD | N39: TARGET
J40: STAG | L40: =AVERAGE(K49,'Dec 1st'!K43) -> 5 | M40: =AVERAGE('[31]Jan 29th '!$M$70,'[32]Feb 28th'!$L$40,'[33]Mar. 31st'!$L$40,'[34]Apr. 30th'!$L$50,'[35]May 30th'!$L$42,'[36]June 30th'!$L$62,'[37]July 29th '!$L$49,'[38]Aug 29th'!$L$34,'[39]Sept 30th'!$L$40,[40]Oct.31st!$L$43,'[41]Nov 28th-30th'!$L$45,L40) -> 6.8061978 | N40: 9.2
...

Sheet Dec 3rd 
S1: P.G. | U1: Hot Time | W1: Process Time | Y1: Cooling Time
B2: Brewing Department Daily Process Loss Report | S2: Lower | T2: Upper | U2: Lower | V2: Upper | W2: Lower | X2: Upper | Y2: Lower | Z2: Upper
R3: CARIB | S3: 11.6 | T3: 12 | U3: 0 | V3: 0.11805556 | W3: 0.22569444 | X3: 0.26388889 | Y3: 0 | Z3: 60 | AB3: HR- PISNER
B4: Date: | C4: 45994 | J4: LOT WORT COLOUR: | M4: Filter Sheets (Target 20 days) | R4: STAG | S4: 11.6 | T4: 12 | U4: 0 | V4: 0.11805556 | W4: 0.22569444 | X4: 0.26388889 | Y4: 0 | Z4: 60
M5: Double | N5: Single | R5: GUINNESS | S5: 17 | T5: 17.5 | U5: 0 | V5: 0.10763889 | W5: 0.24652778 | X5: 0.28472222 | Y5: 0 | Z5: 60
J6: MALT LOT: Lot #8 | L6: Sheet Day | R6: MACKESON | S6: 13.3 | T6: 13.5 | U6: 0 | V6: 0.12905093 | W6: 0.27430556 | X6: 0.30208333 | Y6: 0
R7: STARMALT | S7: 17 | T7: 17.4 | U7: 0 | V7: 0.13605324 | W7: 0.27430556 | X7: 0.30902778 | Y7: 0 | Z7: 85
B8: Brand | C8: Brew no. | D8: Kett. Hls | E8: Wort | F8: Cool Time(Mins) | G8: Cast. P.G. (Lab Result) | H8: Cast P.G. (Cellar Operator)-gravity | I8: Extr. Rec (77.9%) | J8: Theor. Extr. (77.5%) | K8: Boil Off /Vol. (4-6%) | L8: Boil Time | M8: Total Hot | N8: Brewing | O8: Operator | R8: Hurricane Reef | S8: 16.6 | T8: 17 | U8: 0 | V8: 0.12905093 | W8: 0.27430556 | X8: 0.30208333 | Y8: 0
E9: Meter (Hls) | F9: Target(< 60Mins) | M9: Time | R9: VITAMALT | S9: 14.2 | T9: 14.6 | U9: 0 | V9: 0.13905093 | W9: 0.26041667 | X9: 0.29513889 | Y9: 0 | Z9: 75
B10: STAG | C10: =[24]Brewhouse!$A486 -> ST461 | D10: =[24]Brewhouse!$AD486 -> 46.7 | E10: =[24]Brewhouse!$AG486 -> 49.81 | F10: =[24]Brewhouse!$V486 -> 50 | G10: =[24]Brewhouse!$AE486 -> 11.8 | H10: 11.7 | I10: =[24]Brewhouse!$AS486 -> 98.902019 | J10: =[24]Brewhouse!$AT486 -> 99.004797 | K10: =[24]Brewhouse!$Q486 -> 15.336538 | L10: =[24]Brewhouse!$P486 -> 59 | M10: =[24]Brewhouse!$U486-[24]Brewhouse!$T486 -> 0.10694444 | N10: =[24]Brewhouse!$AW486 -> 0.24305556 | O10: =[24]Brewhouse!$AV486 -> K. Benjamin | R10: =B10 -> STAG | S10: =VLOOKUP($B10,$R$3:$X$9,2,FALSE) -> 11.6 | T10: =VLOOKUP($B10,$R$3:$X$9,3,FALSE) -> 12 | U10: =VLOOKUP($B10,$R$3:$X$9,4,FALSE) -> 0 | V10: =VLOOKUP($B10,$R$3:$X$9,5,FALSE) -> 0.11805556 | W10: =VLOOKUP($B10,$R$3:$X$9,6,FALSE) -> 0.22569444 | X10: =VLOOKUP($B10,$R$3:$X$9,7,FALSE) -> 0.26388889 | Y10: =VLOOKUP($B10,$R$3:$Z$9,8,FALSE) -> 0 | Z10: =VLOOKUP($B10,$R$3:$Z$9,9,FALSE) -> 60
B11: STAG | C11: =[24]Brewhouse!$A487 -> ST462 | D11: =[24]Brewhouse!$AD487 -> 48.2 | E11: =[24]Brewhouse!$AG487 -> 48.5 | F11: =[24]Brewhouse!$V487 -> 58 | G11: =[24]Brewhouse!$AE487 -> 12 | H11: 12 | I11: =[24]Brewhouse!$AS487 -> 98.263169 | J11: =[24]Brewhouse!$AT487 -> 98.365215 | K11: =[24]Brewhouse!$Q487 -> 11.105769 | L11: =[24]Brewhouse!$P487 -> 59 | M11: =[24]Brewhouse!$U487-[24]Brewhouse!$T487 -> 0.10833333 | N11: =[24]Brewhouse!$AW487 -> 0.24375 | O11: =[24]Brewhouse!$AV487 -> K. Benjamin | R11: =B11 -> STAG | S11: =VLOOKUP($B11,$R$3:$X$9,2,FALSE) -> 11.6 | T11: =VLOOKUP($B11,$R$3:$X$9,3,FALSE) -> 12 | U11: =VLOOKUP($B11,$R$3:$X$9,4,FALSE) -> 0 | V11: =VLOOKUP($B11,$R$3:$X$9,5,FALSE) -> 0.11805556 | W11: =VLOOKUP($B11,$R$3:$X$9,6,FALSE) -> 0.22569444 | X11: =VLOOKUP($B11,$R$3:$X$9,7,FALSE) -> 0.26388889 | Y11: =VLOOKUP($B11,$R$3:$Z$9,8,FALSE) -> 0 | Z11: =VLOOKUP($B11,$R$3:$Z$9,9,FALSE) -> 60
B12: STAG | C12: =[24]Brewhouse!$A488 -> ST463 | D12: =[24]Brewhouse!$AD488 -> 47.1 | E12: =[24]Brewhouse!$AG488 -> 47.2 | F12: =[24]Brewhouse!$V488 -> 55 | G12: =[24]Brewhouse!$AE488 -> 11.9 | H12: 11.8 | I12: =[24]Brewhouse!$AS488 -> 94.9106 | J12: =[24]Brewhouse!$AT488 -> 95.009133 | K12: =[24]Brewhouse!$Q488 -> 11.852207 | L12: =[24]Brewhouse!$P488 -> 61 | M12: =[24]Brewhouse!$U488-[24]Brewhouse!$T488 -> 0.10625 | N12: =[24]Brewhouse!$AW488 -> 0.24791667 | O12: =[24]Brewhouse!$AV488 -> R. Regis | R12: =B12 -> STAG | S12: =VLOOKUP($B12,$R$3:$X$9,2,FALSE) -> 11.6 | T12: =VLOOKUP($B12,$R$3:$X$9,3,FALSE) -> 12 | U12: =VLOOKUP($B12,$R$3:$X$9,4,FALSE) -> 0 | V12: =VLOOKUP($B12,$R$3:$X$9,5,FALSE) -> 0.11805556 | W12: =VLOOKUP($B12,$R$3:$X$9,6,FALSE) -> 0.22569444 | X12: =VLOOKUP($B12,$R$3:$X$9,7,FALSE) -> 0.26388889 | Y12: =VLOOKUP($B12,$R$3:$Z$9,8,FALSE) -> 0 | Z12: =VLOOKUP($B12,$R$3:$Z$9,9,FALSE) -> 60
B13: STAG | C13: =[24]Brewhouse!$A489 -> ST464 | D13: =[24]Brewhouse!$AD489 -> 48.2 | E13: =[24]Brewhouse!$AG489 -> 47.26 | F13: =[24]Brewhouse!$V489 -> 58 | G13: =[24]Brewhouse!$AE489 -> 12 | H13: 11.7 | I13: =[24]Brewhouse!$AS489 -> 94.333844 | J13: =[24]Brewhouse!$AT489 -> 94.43219 | K13: =[24]Brewhouse!$Q489 -> 11.276392 | L13: =[24]Brewhouse!$P489 -> 60 | M13: =[24]Brewhouse!$U489-[24]Brewhouse!$T489 -> 0.10833333 | N13: =[24]Brewhouse!$AW489 -> 0.24652778 | O13: =[24]Brewhouse!$AV489 -> R. Regis | R13: =B13 -> STAG | S13: =VLOOKUP($B13,$R$3:$X$9,2,FALSE) -> 11.6 | T13: =VLOOKUP($B13,$R$3:$X$9,3,FALSE) -> 12 | U13: =VLOOKUP($B13,$R$3:$X$9,4,FALSE) -> 0 | V13: =VLOOKUP($B13,$R$3:$X$9,5,FALSE) -> 0.11805556 | W13: =VLOOKUP($B13,$R$3:$X$9,6,FALSE) -> 0.22569444 | X13: =VLOOKUP($B13,$R$3:$X$9,7,FALSE) -> 0.26388889 | Y13: =VLOOKUP($B13,$R$3:$Z$9,8,FALSE) -> 0 | Z13: =VLOOKUP($B13,$R$3:$Z$9,9,FALSE) -> 60
B14: STAG | C14: =[24]Brewhouse!$A490 -> ST465 | D14: =[24]Brewhouse!$AD490 -> 50.5 | E14: =[24]Brewhouse!$AG490 -> 49.48 | F14: =[24]Brewhouse!$V490 -> 59 | G14: =[24]Brewhouse!$AE490 -> 11.7 | H14: 11.8 | I14: =[24]Brewhouse!$AS490 -> 97.249563 | J14: =[24]Brewhouse!$AT490 -> 97.350656 | K14: =[24]Brewhouse!$Q490 -> 10.700576 | L14: =[24]Brewhouse!$P490 -> 58 | M14: =[24]Brewhouse!$U490-[24]Brewhouse!$T490 -> 0.16458333 | N14: =[24]Brewhouse!$AW490 -> 0.30208333 | O14: =[24]Brewhouse!$AV490 -> R. Regis | R14: =B14 -> STAG | S14: =VLOOKUP($B14,$R$3:$X$9,2,FALSE) -> 11.6 | T14: =VLOOKUP($B14,$R$3:$X$9,3,FALSE) -> 12 | U14: =VLOOKUP($B14,$R$3:$X$9,4,FALSE) -> 0 | V14: =VLOOKUP($B14,$R$3:$X$9,5,FALSE) -> 0.11805556 | W14: =VLOOKUP($B14,$R$3:$X$9,6,FALSE) -> 0.22569444 | X14: =VLOOKUP($B14,$R$3:$X$9,7,FALSE) -> 0.26388889 | Y14: =VLOOKUP($B14,$R$3:$Z$9,8,FALSE) -> 0 | Z14: =VLOOKUP($B14,$R$3:$Z$9,9,FALSE) -> 60
B15: STAG | C15: =[24]Brewhouse!$A491 -> ST466 | D15: =[24]Brewhouse!$AD491 -> 49.4 | E15: =[24]Brewhouse!$AG491 -> 48.43 | F15: =[24]Brewhouse!$V491 -> 58 | G15: =[24]Brewhouse!$AE491 -> 11.7 | H15: 11.8 | I15: =[24]Brewhouse!$AS491 -> 95.18586 | J15: =[24]Brewhouse!$AT491 -> 95.284807 | K15: =[24]Brewhouse!$Q491 -> 10.144231 | L15: =[24]Brewhouse!$P491 -> 61 | M15: =[24]Brewhouse!$U491-[24]Brewhouse!$T491 -> 0.11319444 | N15: =[24]Brewhouse!$AW491 -> 0.29097222 | O15: =[24]Brewhouse!$AV491 -> R.Sookram | R15: =B15 -> STAG | S15: =VLOOKUP($B15,$R$3:$X$9,2,FALSE) -> 11.6 | T15: =VLOOKUP($B15,$R$3:$X$9,3,FALSE) -> 12 | U15: =VLOOKUP($B15,$R$3:$X$9,4,FALSE) -> 0 | V15: =VLOOKUP($B15,$R$3:$X$9,5,FALSE) -> 0.11805556 | W15: =VLOOKUP($B15,$R$3:$X$9,6,FALSE) -> 0.22569444 | X15: =VLOOKUP($B15,$R$3:$X$9,7,FALSE) -> 0.26388889 | Y15: =VLOOKUP($B15,$R$3:$Z$9,8,FALSE) -> 0 | Z15: =VLOOKUP($B15,$R$3:$Z$9,9,FALSE) -> 60
B16: 45995 | R16: =B16 -> 45995 | S16: =VLOOKUP($B16,$R$3:$X$9,2,FALSE) -> #N/A | T16: =VLOOKUP($B16,$R$3:$X$9,3,FALSE) -> #N/A | U16: =VLOOKUP($B16,$R$3:$X$9,4,FALSE) -> #N/A | V16: =VLOOKUP($B16,$R$3:$X$9,5,FALSE) -> #N/A | W16: =VLOOKUP($B16,$R$3:$X$9,6,FALSE) -> #N/A | X16: =VLOOKUP($B16,$R$3:$X$9,7,FALSE) -> #N/A | Y16: =VLOOKUP($B16,$R$3:$Z$9,8,FALSE) -> #N/A | Z16: =VLOOKUP($B16,$R$3:$Z$9,9,FALSE) -> #N/A
B17: STAG | C17: =[24]Brewhouse!$A492 -> ST467 | D17: =[24]Brewhouse!$AD492 -> 48.1 | E17: =[24]Brewhouse!$AG492 -> 47.4 | F17: =[24]Brewhouse!$V492 -> 56 | G17: =[24]Brewhouse!$AE492 -> 11.9 | H17: 11.9 | I17: =[24]Brewhouse!$AS492 -> 95.193453 | J17: =[24]Brewhouse!$AT492 -> 95.292311 | K17: =[24]Brewhouse!$Q492 -> 12.8119 | L17: =[24]Brewhouse!$P492 -> 56 | M17: =[24]Brewhouse!$U492-[24]Brewhouse!$T492 -> 0.10416667 | N17: =[24]Brewhouse!$AW492 -> 0.25694444 | O17: =[24]Brewhouse!$AV492 -> R.Sookram | R17: =B17 -> STAG | S17: =VLOOKUP($B17,$R$3:$X$9,2,FALSE) -> 11.6 | T17: =VLOOKUP($B17,$R$3:$X$9,3,FALSE) -> 12 | U17: =VLOOKUP($B17,$R$3:$X$9,4,FALSE) -> 0 | V17: =VLOOKUP($B17,$R$3:$X$9,5,FALSE) -> 0.11805556 | W17: =VLOOKUP($B17,$R$3:$X$9,6,FALSE) -> 0.22569444 | X17: =VLOOKUP($B17,$R$3:$X$9,7,FALSE) -> 0.26388889 | Y17: =VLOOKUP($B17,$R$3:$Z$9,8,FALSE) -> 0 | Z17: =VLOOKUP($B17,$R$3:$Z$9,9,FALSE) -> 60
R18: =B18 -> 0 | S18: =VLOOKUP($B18,$R$3:$X$9,2,FALSE) -> #N/A | T18: =VLOOKUP($B18,$R$3:$X$9,3,FALSE) -> #N/A | U18: =VLOOKUP($B18,$R$3:$X$9,4,FALSE) -> #N/A | V18: =VLOOKUP($B18,$R$3:$X$9,5,FALSE) -> #N/A | W18: =VLOOKUP($B18,$R$3:$X$9,6,FALSE) -> #N/A | X18: =VLOOKUP($B18,$R$3:$X$9,7,FALSE) -> #N/A | Y18: =VLOOKUP($B18,$R$3:$Z$9,8,FALSE) -> #N/A | Z18: =VLOOKUP($B18,$R$3:$Z$9,9,FALSE) -> #N/A
R19: =B19 -> 0 | S19: =VLOOKUP($B19,$R$3:$X$9,2,FALSE) -> #N/A | T19: =VLOOKUP($B19,$R$3:$X$9,3,FALSE) -> #N/A | U19: =VLOOKUP($B19,$R$3:$X$9,4,FALSE) -> #N/A | V19: =VLOOKUP($B19,$R$3:$X$9,5,FALSE) -> #N/A | W19: =VLOOKUP($B19,$R$3:$X$9,6,FALSE) -> #N/A | X19: =VLOOKUP($B19,$R$3:$X$9,7,FALSE) -> #N/A | Y19: =VLOOKUP($B19,$R$3:$Z$9,8,FALSE) -> #N/A | Z19: =VLOOKUP($B19,$R$3:$Z$9,9,FALSE) -> #N/A
R20: =B20 -> 0 | S20: =VLOOKUP($B20,$R$3:$X$9,2,FALSE) -> #N/A | T20: =VLOOKUP($B20,$R$3:$X$9,3,FALSE) -> #N/A | U20: =VLOOKUP($B20,$R$3:$X$9,4,FALSE) -> #N/A | V20: =VLOOKUP($B20,$R$3:$X$9,5,FALSE) -> #N/A | W20: =VLOOKUP($B20,$R$3:$X$9,6,FALSE) -> #N/A | X20: =VLOOKUP($B20,$R$3:$X$9,7,FALSE) -> #N/A | Y20: =VLOOKUP($B20,$R$3:$Z$9,8,FALSE) -> #N/A | Z20: =VLOOKUP($B20,$R$3:$Z$9,9,FALSE) -> #N/A
R21: =B21 -> 0 | S21: =VLOOKUP($B21,$R$3:$X$9,2,FALSE) -> #N/A | T21: =VLOOKUP($B21,$R$3:$X$9,3,FALSE) -> #N/A | U21: =VLOOKUP($B21,$R$3:$X$9,4,FALSE) -> #N/A | V21: =VLOOKUP($B21,$R$3:$X$9,5,FALSE) -> #N/A | W21: =VLOOKUP($B21,$R$3:$X$9,6,FALSE) -> #N/A | X21: =VLOOKUP($B21,$R$3:$X$9,7,FALSE) -> #N/A | Y21: =VLOOKUP($B21,$R$3:$Z$9,8,FALSE) -> #N/A | Z21: =VLOOKUP($B21,$R$3:$Z$9,9,FALSE) -> #N/A
R22: =B22 -> 0 | S22: =VLOOKUP($B22,$R$3:$X$9,2,FALSE) -> #N/A | T22: =VLOOKUP($B22,$R$3:$X$9,3,FALSE) -> #N/A | U22: =VLOOKUP($B22,$R$3:$X$9,4,FALSE) -> #N/A | V22: =VLOOKUP($B22,$R$3:$X$9,5,FALSE) -> #N/A | W22: =VLOOKUP($B22,$R$3:$X$9,6,FALSE) -> #N/A | X22: =VLOOKUP($B22,$R$3:$X$9,7,FALSE) -> #N/A | Y22: =VLOOKUP($B22,$R$3:$Z$9,8,FALSE) -> #N/A | Z22: =VLOOKUP($B22,$R$3:$Z$9,9,FALSE) -> #N/A
R23: =B23 -> 0 | S23: =VLOOKUP($B23,$R$3:$X$9,2,FALSE) -> #N/A | T23: =VLOOKUP($B23,$R$3:$X$9,3,FALSE) -> #N/A | U23: =VLOOKUP($B23,$R$3:$X$9,4,FALSE) -> #N/A | V23: =VLOOKUP($B23,$R$3:$X$9,5,FALSE) -> #N/A | W23: =VLOOKUP($B23,$R$3:$X$9,6,FALSE) -> #N/A | X23: =VLOOKUP($B23,$R$3:$X$9,7,FALSE) -> #N/A | Y23: =VLOOKUP($B23,$R$3:$Z$9,8,FALSE) -> #N/A | Z23: =VLOOKUP($B23,$R$3:$Z$9,9,FALSE) -> #N/A
R24: =B24 -> 0 | S24: =VLOOKUP($B24,$R$3:$X$9,2,FALSE) -> #N/A | T24: =VLOOKUP($B24,$R$3:$X$9,3,FALSE) -> #N/A | U24: =VLOOKUP($B24,$R$3:$X$9,4,FALSE) -> #N/A | V24: =VLOOKUP($B24,$R$3:$X$9,5,FALSE) -> #N/A | W24: =VLOOKUP($B24,$R$3:$X$9,6,FALSE) -> #N/A | X24: =VLOOKUP($B24,$R$3:$X$9,7,FALSE) -> #N/A | Y24: =VLOOKUP($B24,$R$3:$Z$9,8,FALSE) -> #N/A | Z24: =VLOOKUP($B24,$R$3:$Z$9,9,FALSE) -> #N/A
R25: =B25 -> 0 | S25: =VLOOKUP($B25,$R$3:$X$9,2,FALSE) -> #N/A | T25: =VLOOKUP($B25,$R$3:$X$9,3,FALSE) -> #N/A | U25: =VLOOKUP($B25,$R$3:$X$9,4,FALSE) -> #N/A | V25: =VLOOKUP($B25,$R$3:$X$9,5,FALSE) -> #N/A | W25: =VLOOKUP($B25,$R$3:$X$9,6,FALSE) -> #N/A | X25: =VLOOKUP($B25,$R$3:$X$9,7,FALSE) -> #N/A | Y25: =VLOOKUP($B25,$R$3:$Z$9,8,FALSE) -> #N/A | Z25: =VLOOKUP($B25,$R$3:$Z$9,9,FALSE) -> #N/A
R26: =B26 -> 0 | S26: =VLOOKUP($B26,$R$3:$X$9,2,FALSE) -> #N/A | T26: =VLOOKUP($B26,$R$3:$X$9,3,FALSE) -> #N/A | U26: =VLOOKUP($B26,$R$3:$X$9,4,FALSE) -> #N/A | V26: =VLOOKUP($B26,$R$3:$X$9,5,FALSE) -> #N/A | W26: =VLOOKUP($B26,$R$3:$X$9,6,FALSE) -> #N/A | X26: =VLOOKUP($B26,$R$3:$X$9,7,FALSE) -> #N/A | Y26: =VLOOKUP($B26,$R$3:$Z$9,8,FALSE) -> #N/A | Z26: =VLOOKUP($B26,$R$3:$Z$9,9,FALSE) -> #N/A
R27: =B27 -> 0 | S27: =VLOOKUP($B27,$R$3:$X$9,2,FALSE) -> #N/A | T27: =VLOOKUP($B27,$R$3:$X$9,3,FALSE) -> #N/A | U27: =VLOOKUP($B27,$R$3:$X$9,4,FALSE) -> #N/A | V27: =VLOOKUP($B27,$R$3:$X$9,5,FALSE) -> #N/A | W27: =VLOOKUP($B27,$R$3:$X$9,6,FALSE) -> #N/A | X27: =VLOOKUP($B27,$R$3:$X$9,7,FALSE) -> #N/A | Y27: =VLOOKUP($B27,$R$3:$Z$9,8,FALSE) -> #N/A | Z27: =VLOOKUP($B27,$R$3:$Z$9,9,FALSE) -> #N/A
R28: =B28 -> 0 | S28: =VLOOKUP($B28,$R$3:$X$9,2,FALSE) -> #N/A | T28: =VLOOKUP($B28,$R$3:$X$9,3,FALSE) -> #N/A | U28: =VLOOKUP($B28,$R$3:$X$9,4,FALSE) -> #N/A | V28: =VLOOKUP($B28,$R$3:$X$9,5,FALSE) -> #N/A | W28: =VLOOKUP($B28,$R$3:$X$9,6,FALSE) -> #N/A | X28: =VLOOKUP($B28,$R$3:$X$9,7,FALSE) -> #N/A | Y28: =VLOOKUP($B28,$R$3:$Z$9,8,FALSE) -> #N/A | Z28: =VLOOKUP($B28,$R$3:$Z$9,9,FALSE) -> #N/A
R29: =B29 -> 0 | S29: =VLOOKUP($B29,$R$3:$X$9,2,FALSE) -> #N/A | T29: =VLOOKUP($B29,$R$3:$X$9,3,FALSE) -> #N/A | U29: =VLOOKUP($B29,$R$3:$X$9,4,FALSE) -> #N/A | V29: =VLOOKUP($B29,$R$3:$X$9,5,FALSE) -> #N/A | W29: =VLOOKUP($B29,$R$3:$X$9,6,FALSE) -> #N/A | X29: =VLOOKUP($B29,$R$3:$X$9,7,FALSE) -> #N/A | Y29: =VLOOKUP($B29,$R$3:$Z$9,8,FALSE) -> #N/A | Z29: =VLOOKUP($B29,$R$3:$Z$9,9,FALSE) -> #N/A
... R32: =B32 -> 0 | S32: =VLOOKUP($B32,$R$3:$X$9,2,FALSE) -> #N/A | T32: =VLOOKUP($B32,$R$3:$X$9,3,FALSE) -> #N/A | U32: =VLOOKUP($B32,$R$3:$X$9,4,FALSE) -> #N/A | V32: =VLOOKUP($B32,$R$3:$X$9,5,FALSE) -> #N/A | W32: =VLOOKUP($B32,$R$3:$X$9,6,FALSE) -> #N/A | X32: =VLOOKUP($B32,$R$3:$X$9,7,FALSE) -> #N/A | Y32: =VLOOKUP($B32,$R$3:$Z$9,8,FALSE) -> #N/A | Z32: =VLOOKUP($B32,$R$3:$Z$9,9,FALSE) -> #N/A
B33: BRAND | D33: BBT P.G./ O.G | I33: Brand | K33: MTD No. of Brews | L33: MTD | M33: YTD | N33: Target | R33: =B33 -> BRAND | S33: =VLOOKUP($B33,$R$3:$X$9,2,FALSE) -> #N/A | T33: =VLOOKUP($B33,$R$3:$X$9,3,FALSE) -> #N/A | U33: =VLOOKUP($B33,$R$3:$X$9,4,FALSE) -> #N/A | V33: =VLOOKUP($B33,$R$3:$X$9,5,FALSE) -> #N/A | W33: =VLOOKUP($B33,$R$3:$X$9,6,FALSE) -> #N/A | X33: =VLOOKUP($B33,$R$3:$X$9,7,FALSE) -> #N/A | Y33: =VLOOKUP($B33,$R$3:$Z$9,8,FALSE) -> #N/A | Z33: =VLOOKUP($B33,$R$3:$Z$9,9,FALSE) -> #N/A
B34: =J57 -> CARIBE | I34: CARIB | M34: =AVERAGE([23]Brewhouse!$AU$102:$AU$171,[23]Brewhouse!$AU$173:$AU$253,[23]Brewhouse!$AU$255:$AU$339,[23]Brewhouse!$AU$341:$AU$346,[23]Brewhouse!$AU$348,[23]Brewhouse!$AU$349:$AU$406,[23]Brewhouse!$AU$408:$AU$491,[23]Brewhouse!$AU$493:$AU$578,[23]Brewhouse!$AU$580:$AU$652,[23]Brewhouse!$AU$655:$AU$738,[23]Brewhouse!$A$740:$A$821,[23]Brewhouse!$AU$823:$AU$862,[24]Brewhouse!$AS$420:$AS$423,[23]Brewhouse!$AU$867:$AU$912,[23]Brewhouse!$AU$914:$AU$1003) -> 97.751831 | N34: 98 | R34: =B34 -> CARIBE | S34: =VLOOKUP($B34,$R$3:$X$9,2,FALSE) -> #N/A | T34: =VLOOKUP($B34,$R$3:$X$9,3,FALSE) -> #N/A | U34: =VLOOKUP($B34,$R$3:$X$9,4,FALSE) -> #N/A | V34: =VLOOKUP($B34,$R$3:$X$9,5,FALSE) -> #N/A | W34: =VLOOKUP($B34,$R$3:$X$9,6,FALSE) -> #N/A | X34: =VLOOKUP($B34,$R$3:$X$9,7,FALSE) -> #N/A | Y34: =VLOOKUP($B34,$R$3:$Z$9,8,FALSE) -> #N/A | Z34: =VLOOKUP($B34,$R$3:$Z$9,9,FALSE) -> #N/A
I35: STAG | J35: =AVERAGE(I10:I17) -> 96.291215 | K35: =COUNTA([24]Brewhouse!$A$486:$A$492) -> 7 | L35: =AVERAGE([24]Brewhouse!$AS$486:$AS$492) -> 96.291215 | M35: =AVERAGE([24]Brewhouse!$AS$15:$AS$64,[24]Brewhouse!$AS$66:$AS$103,[24]Brewhouse!$AS$105:$AS$140,[24]Brewhouse!$AS$142:$AS$193,[24]Brewhouse!$AS$195:$AS$240,[24]Brewhouse!$AS$242:$AS$273,[24]Brewhouse!$AS$275:$AS$322,[24]Brewhouse!$AS$324:$AS$359,[24]Brewhouse!$AS$361:$AS$397,[24]Brewhouse!$AS$399:$AS$419,[24]Brewhouse!$AS$424:$AS$447,[24]Brewhouse!$AS$449:$AS$484,[24]Brewhouse!$AS$486:$AS$492) -> 97.824425 | N35: 98 | R35: =B35 -> 0 | S35: =VLOOKUP($B35,$R$3:$X$9,2,FALSE) -> #N/A | T35: =VLOOKUP($B35,$R$3:$X$9,3,FALSE) -> #N/A | U35: =VLOOKUP($B35,$R$3:$X$9,4,FALSE) -> #N/A | V35: =VLOOKUP($B35,$R$3:$X$9,5,FALSE) -> #N/A | W35: =VLOOKUP($B35,$R$3:$X$9,6,FALSE) -> #N/A | X35: =VLOOKUP($B35,$R$3:$X$9,7,FALSE) -> #N/A | Y35: =VLOOKUP($B35,$R$3:$Z$9,8,FALSE) -> #N/A | Z35: =VLOOKUP($B35,$R$3:$Z$9,9,FALSE) -> #N/A
