Workbook
Name ProductList: [1]November15!$R$3:$R$9
Name ProductList: [2]November15!$R$3:$R$9

Sheet Dec 18th
T1: P.G. | V1: Hot Time | X1: Process Time | Z1: Cooling Time
B2: Brewing Department Daily Process Loss Report | T2: Lower | U2: Upper | V2: Lower | W2: Upper | X2: Lower | Y2: Upper | Z2: Lower | AA2: Upper
S3: CARIB | T3: 11.6 | U3: 12 | V3: 0 | W3: 0.11805556 | X3: 0.17361111 | Y3: 0.21180556 | Z3: 0 | AA3: 60 | AC3: HR- PISNER
B4: Date: | C4: 45278 | J4: LOT WORT COLOUR: 3.4 | M4: Filter Sheets (Target 20 days) | S4: STAG | T4: 11.6 | U4: 12 | V4: 0 | W4: 0.11805556 | X4: 0.17361111 | Y4: 0.21180556 | Z4: 0 | AA4: 60
M5: Double | N5: Single | S5: GUINNESS | T5: 17 | U5: 17.5 | V5: 0 | W5: 0.10763889 | X5: 0.19444444 | Y5: 0.23263889 | Z5: 0 | AA5: 60
J6: MALT LOT: Lot 8 | L6: Sheet Day | S6: MACKESON | T6: 13.3 | U6: 13.5 | V6: 0 | W6: 0.12905093 | X6: 0.22222222 | Y6: 0.25347222 | Z6: 0
S7: STARMALT | T7: 17.1 | U7: 17.5 | V7: 0 | W7: 0.13605324 | X7: 0.20833333 | Y7: 0.24305556 | Z7: 0 | AA7: 60
B8: Brand | C8: Brew no. | D8: Kett. Hls | E8: Wort | F8: Cool Time(Mins) | G8: Cast. P.G. (Lab Result) | H8: Cast P.G. (Cellar Operator)-gravity | I8: Extr. Rec (79.1%) | J8: Theor. Extr. (77.5%) | K8: Boil Off /Vol. (4-6%) | L8: Boil Time | M8: Total Hot | N8: Brewing | P8: Comments | Q8: Actual Pilsen Malt | S8: Hurricane Reef | T8: 16.6 | U8: 17 | V8: 0 | W8: 0.12905093 | X8: 0.22222222 | Y8: 0.25347222 | Z8: 0
E9: Meter (Hls) | F9: Target(< 60Mins) | M9: Time | S9: VITAMALT | T9: 14.4 | U9: 14.6 | V9: 0 | W9: 0.13905093 | X9: 0.19097222 | Y9: 0.22569444 | Z9: 0 | AA9: 75
S10: =B10 -> 0 | T10: =VLOOKUP($B10,$S$3:$Y$9,2,FALSE) -> #N/A | U10: =VLOOKUP($B10,$S$3:$Y$9,3,FALSE) -> #N/A | V10: =VLOOKUP($B10,$S$3:$Y$9,4,FALSE) -> #N/A | W10: =VLOOKUP($B10,$S$3:$Y$9,5,FALSE) -> #N/A | X10: =VLOOKUP($B10,$S$3:$Y$9,6,FALSE) -> #N/A | Y10: =VLOOKUP($B10,$S$3:$Y$9,7,FALSE) -> #N/A | Z10: =VLOOKUP($B10,$S$3:$AA$9,8,FALSE) -> #N/A | AA10: =VLOOKUP($B10,$S$3:$AA$9,9,FALSE) -> #N/A
S11: =B11 -> 0 | T11: =VLOOKUP($B11,$S$3:$Y$9,2,FALSE) -> #N/A | U11: =VLOOKUP($B11,$S$3:$Y$9,3,FALSE) -> #N/A | V11: =VLOOKUP($B11,$S$3:$Y$9,4,FALSE) -> #N/A | W11: =VLOOKUP($B11,$S$3:$Y$9,5,FALSE) -> #N/A | X11: =VLOOKUP($B11,$S$3:$Y$9,6,FALSE) -> #N/A | Y11: =VLOOKUP($B11,$S$3:$Y$9,7,FALSE) -> #N/A | Z11: =VLOOKUP($B11,$S$3:$AA$9,8,FALSE) -> #N/A | AA11: =VLOOKUP($B11,$S$3:$AA$9,9,FALSE) -> #N/A
S12: =B12 -> 0 | T12: =VLOOKUP($B12,$S$3:$Y$9,2,FALSE) -> #N/A | U12: =VLOOKUP($B12,$S$3:$Y$9,3,FALSE) -> #N/A | V12: =VLOOKUP($B12,$S$3:$Y$9,4,FALSE) -> #N/A | W12: =VLOOKUP($B12,$S$3:$Y$9,5,FALSE) -> #N/A | X12: =VLOOKUP($B12,$S$3:$Y$9,6,FALSE) -> #N/A | Y12: =VLOOKUP($B12,$S$3:$Y$9,7,FALSE) -> #N/A | Z12: =VLOOKUP($B12,$S$3:$AA$9,8,FALSE) -> #N/A | AA12: =VLOOKUP($B12,$S$3:$AA$9,9,FALSE) -> #N/A
S13: =B13 -> 0 | T13: =VLOOKUP($B13,$S$3:$Y$9,2,FALSE) -> #N/A | U13: =VLOOKUP($B13,$S$3:$Y$9,3,FALSE) -> #N/A | V13: =VLOOKUP($B13,$S$3:$Y$9,4,FALSE) -> #N/A | W13: =VLOOKUP($B13,$S$3:$Y$9,5,FALSE) -> #N/A | X13: =VLOOKUP($B13,$S$3:$Y$9,6,FALSE) -> #N/A | Y13: =VLOOKUP($B13,$S$3:$Y$9,7,FALSE) -> #N/A | Z13: =VLOOKUP($B13,$S$3:$AA$9,8,FALSE) -> #N/A | AA13: =VLOOKUP($B13,$S$3:$AA$9,9,FALSE) -> #N/A
S14: =B14 -> 0 | T14: =VLOOKUP($B14,$S$3:$Y$9,2,FALSE) -> #N/A | U14: =VLOOKUP($B14,$S$3:$Y$9,3,FALSE) -> #N/A | V14: =VLOOKUP($B14,$S$3:$Y$9,4,FALSE) -> #N/A | W14: =VLOOKUP($B14,$S$3:$Y$9,5,FALSE) -> #N/A | X14: =VLOOKUP($B14,$S$3:$Y$9,6,FALSE) -> #N/A | Y14: =VLOOKUP($B14,$S$3:$Y$9,7,FALSE) -> #N/A | Z14: =VLOOKUP($B14,$S$3:$AA$9,8,FALSE) -> #N/A | AA14: =VLOOKUP($B14,$S$3:$AA$9,9,FALSE) -> #N/A
S15: =B15 -> 0 | T15: =VLOOKUP($B15,$S$3:$Y$9,2,FALSE) -> #N/A | U15: =VLOOKUP($B15,$S$3:$Y$9,3,FALSE) -> #N/A | V15: =VLOOKUP($B15,$S$3:$Y$9,4,FALSE) -> #N/A | W15: =VLOOKUP($B15,$S$3:$Y$9,5,FALSE) -> #N/A | X15: =VLOOKUP($B15,$S$3:$Y$9,6,FALSE) -> #N/A | Y15: =VLOOKUP($B15,$S$3:$Y$9,7,FALSE) -> #N/A | Z15: =VLOOKUP($B15,$S$3:$AA$9,8,FALSE) -> #N/A | AA15: =VLOOKUP($B15,$S$3:$AA$9,9,FALSE) -> #N/A
S16: =B16 -> 0 | T16: =VLOOKUP($B16,$S$3:$Y$9,2,FALSE) -> #N/A | U16: =VLOOKUP($B16,$S$3:$Y$9,3,FALSE) -> #N/A | V16: =VLOOKUP($B16,$S$3:$Y$9,4,FALSE) -> #N/A | W16: =VLOOKUP($B16,$S$3:$Y$9,5,FALSE) -> #N/A | X16: =VLOOKUP($B16,$S$3:$Y$9,6,FALSE) -> #N/A | Y16: =VLOOKUP($B16,$S$3:$Y$9,7,FALSE) -> #N/A | Z16: =VLOOKUP($B16,$S$3:$AA$9,8,FALSE) -> #N/A | AA16: =VLOOKUP($B16,$S$3:$AA$9,9,FALSE) -> #N/A
S17: =B17 -> 0 | T17: =VLOOKUP($B17,$S$3:$Y$9,2,FALSE) -> #N/A | U17: =VLOOKUP($B17,$S$3:$Y$9,3,FALSE) -> #N/A | V17: =VLOOKUP($B17,$S$3:$Y$9,4,FALSE) -> #N/A | W17: =VLOOKUP($B17,$S$3:$Y$9,5,FALSE) -> #N/A | X17: =VLOOKUP($B17,$S$3:$Y$9,6,FALSE) -> #N/A | Y17: =VLOOKUP($B17,$S$3:$Y$9,7,FALSE) -> #N/A | Z17: =VLOOKUP($B17,$S$3:$AA$9,8,FALSE) -> #N/A | AA17: =VLOOKUP($B17,$S$3:$AA$9,9,FALSE) -> #N/A
S18: =B18 -> 0 | T18: =VLOOKUP($B18,$S$3:$Y$9,2,FALSE) -> #N/A | U18: =VLOOKUP($B18,$S$3:$Y$9,3,FALSE) -> #N/A | V18: =VLOOKUP($B18,$S$3:$Y$9,4,FALSE) -> #N/A | W18: =VLOOKUP($B18,$S$3:$Y$9,5,FALSE) -> #N/A | X18: =VLOOKUP($B18,$S$3:$Y$9,6,FALSE) -> #N/A | Y18: =VLOOKUP($B18,$S$3:$Y$9,7,FALSE) -> #N/A | Z18: =VLOOKUP($B18,$S$3:$AA$9,8,FALSE) -> #N/A | AA18: =VLOOKUP($B18,$S$3:$AA$9,9,FALSE) -> #N/A
S19: =B19 -> 0 | T19: =VLOOKUP($B19,$S$3:$Y$9,2,FALSE) -> #N/A | U19: =VLOOKUP($B19,$S$3:$Y$9,3,FALSE) -> #N/A | V19: =VLOOKUP($B19,$S$3:$Y$9,4,FALSE) -> #N/A | W19: =VLOOKUP($B19,$S$3:$Y$9,5,FALSE) -> #N/A | X19: =VLOOKUP($B19,$S$3:$Y$9,6,FALSE) -> #N/A | Y19: =VLOOKUP($B19,$S$3:$Y$9,7,FALSE) -> #N/A | Z19: =VLOOKUP($B19,$S$3:$AA$9,8,FALSE) -> #N/A | AA19: =VLOOKUP($B19,$S$3:$AA$9,9,FALSE) -> #N/A
S20: =B20 -> 0 | T20: =VLOOKUP($B20,$S$3:$Y$9,2,FALSE) -> #N/A | U20: =VLOOKUP($B20,$S$3:$Y$9,3,FALSE) -> #N/A | V20: =VLOOKUP($B20,$S$3:$Y$9,4,FALSE) -> #N/A | W20: =VLOOKUP($B20,$S$3:$Y$9,5,FALSE) -> #N/A | X20: =VLOOKUP($B20,$S$3:$Y$9,6,FALSE) -> #N/A | Y20: =VLOOKUP($B20,$S$3:$Y$9,7,FALSE) -> #N/A | Z20: =VLOOKUP($B20,$S$3:$AA$9,8,FALSE) -> #N/A | AA20: =VLOOKUP($B20,$S$3:$AA$9,9,FALSE) -> #N/A
S21: =B21 -> 0 | T21: =VLOOKUP($B21,$S$3:$Y$9,2,FALSE) -> #N/A | U21: =VLOOKUP($B21,$S$3:$Y$9,3,FALSE) -> #N/A | V21: =VLOOKUP($B21,$S$3:$Y$9,4,FALSE) -> #N/A | W21: =VLOOKUP($B21,$S$3:$Y$9,5,FALSE) -> #N/A | X21: =VLOOKUP($B21,$S$3:$Y$9,6,FALSE) -> #N/A | Y21: =VLOOKUP($B21,$S$3:$Y$9,7,FALSE) -> #N/A | Z21: =VLOOKUP($B21,$S$3:$AA$9,8,FALSE) -> #N/A | AA21: =VLOOKUP($B21,$S$3:$AA$9,9,FALSE) -> #N/A
... S47: =B47 -> 0 | T47: =VLOOKUP($B47,$S$3:$Y$9,2,FALSE) -> #N/A | U47: =VLOOKUP($B47,$S$3:$Y$9,3,FALSE) -> #N/A | V47: =VLOOKUP($B47,$S$3:$Y$9,4,FALSE) -> #N/A | W47: =VLOOKUP($B47,$S$3:$Y$9,5,FALSE) -> #N/A | X47: =VLOOKUP($B47,$S$3:$Y$9,6,FALSE) -> #N/A | Y47: =VLOOKUP($B47,$S$3:$Y$9,7,FALSE) -> #N/A | Z47: =VLOOKUP($B47,$S$3:$AA$9,8,FALSE) -> #N/A | AA47: =VLOOKUP($B47,$S$3:$AA$9,9,FALSE) -> #N/A
I48: EXTRACT RECOVERY
B49: BRAND | D49: BBT P.G./ O.G | I49: Brand | J49: Actual | K49: MTD No. of Brews | L49: MTD | M49: YTD | N49: Target
B50: STAG | C50: 11.8 | D50: 11.73 | I50: CARIB | K50: =COUNTA([3]Brewhouse!$A$1596:$A$1619) -> 24 | L50: =AVERAGE([3]Brewhouse!$AU$1529,[3]Brewhouse!$AU$1531:$AU$1594,[3]Brewhouse!$AU$1596:$AU$1619) -> 98.205761 | M50: =AVERAGE([3]Brewhouse!$AU$849:$AU$924,[3]Brewhouse!$AU$926:$AU$971,[3]Brewhouse!$AU$973:$AU$1066,[3]Brewhouse!$AU$1068:$AU$1111,[3]Brewhouse!$AU$1113:$AU$1132,[3]Brewhouse!$AU$1134:$AU$1167,[3]Brewhouse!$AU$1169:$AU$1230,[3]Brewhouse!$AU$1232:$AU$1299,[3]Brewhouse!$AU$1301:$AU$1363,[3]Brewhouse!$AU$1365:$AU$1444,[3]Brewhouse!$AU$1446:$AU$1527,[3]Brewhouse!$AU$1529,[3]Brewhouse!$AU$1531:$AU$1594,[3]Brewhouse!$AU$1596:$AU$1619) -> 98.381806 | N50: 98
C51: 11.9 | I51: STAG | K51: =COUNTA([4]Brewhouse!$A$976:$A$1007) -> 32 | L51: =AVERAGE([4]Brewhouse!$AS$976:$AS$979,[4]Brewhouse!$AS$981:$AS$1007) -> 98.538567 | M51: =AVERAGE([4]Brewhouse!$AS$577:$AS$618,[4]Brewhouse!$AS$620:$AS$651,[4]Brewhouse!$AS$653:$AS$696,[4]Brewhouse!$AS$698:$AS$708,[4]Brewhouse!$AS$710:$AS$733,[4]Brewhouse!$AS$735:$AS$777,[4]Brewhouse!$AS$779:$AS$822,[4]Brewhouse!$AS$824:$AS$863,[4]Brewhouse!$AS$865:$AS$974,[4]Brewhouse!$AS$976:$AS$979,[4]Brewhouse!$AS$981:$AS$1007) -> 98.489671 | N51: 98
I52: GUINNESS | K52: =COUNTA([5]Brewhouse!$A$282:$A$289) -> 8 | L52: =AVERAGE([5]Brewhouse!$AU$269:$AU$279,[5]Brewhouse!$AU$282:$AU$289) -> 96.186177 | M52: =AVERAGE([5]Brewhouse!$AU$161:$AU$176,[5]Brewhouse!$AU$178:$AU$195,[5]Brewhouse!$AU$197:$AU$208,[5]Brewhouse!$AU$210:$AU$221,[5]Brewhouse!$AU$223:$AU$232,[5]Brewhouse!$AU$234:$AU$279,[5]Brewhouse!$AU$282:$AU$289) -> 96.64916 | N52: 98
I53: VITAMALT | K53: =COUNTA([6]Brewhouse!$A$158:$A$163) -> 6 | L53: =AVERAGE([6]Brewhouse!$AU$158:$AU$163) -> 94.60305 | M53: =AVERAGE([6]Brewhouse!$AU$91:$AU$101,[6]Brewhouse!$AU$103:$AU$112,[6]Brewhouse!$AU$114:$AU$123,[6]Brewhouse!$AU$125:$AU$134,[6]Brewhouse!$AU$136:$AU$145,[6]Brewhouse!$AU$147:$AU$156,[6]Brewhouse!$AU$158:$AU$163) -> 96.240014 | N53: 98
I54: MAXIMALT | N54: 98
I55: MACKESON | M55: =AVERAGE([7]Brewhouse!$AT$74:$AT$79) -> 93.959836 | N55: 98
I56: STARMALT | K56: =COUNTA([8]Brewhouse!$A$249:$A$254) -> 6 | L56: =AVERAGE([8]Brewhouse!$AY$249:$AY$254) -> 99.681996 | M56: =AVERAGE([8]Brewhouse!$AY$138:$AY$143,[8]Brewhouse!$AY$145:$AY$153,[8]Brewhouse!$AY$155,[8]Brewhouse!$AY$156:$AY$174,[8]Brewhouse!$AY$176:$AY$185,[8]Brewhouse!$AY$187:$AY$198,[8]Brewhouse!$AY$200:$AY$247,[8]Brewhouse!$AY$249:$AY$254) -> 98.774703 | N56: 98
I57: HR- P | M57: =AVERAGE([9]Brewhouse!$AW$13:$AW$14,[9]Brewhouse!$AW$16:$AW$17) -> 92.042628 | N57: 98
I58: Hurricane Reef | M58: =AVERAGE([9]Brewhouse!$AW$13:$AW$14) -> 88.376943 | N58: 98
K59: =SUM(K50:K58) -> 76 | L59: =((L50*K50)+(L51*K51)+(L52*K52)+(L53*K53)+(L54*K54)+(K57*L57)+(L55*K55)+(L56*K56)+(L58*K58))/(K59) -> 97.965422 | M59: =AVERAGE('[10]Closing- January 2023'!$L$42,'[11]Feb. 28th'!$L$42,'[12]March 31st'!$L$75,'[13]Apri 28th'!$L$51,L59) -> 98.06926 | N59: 98
J62: Daily Brewing Plan
J63: Brand | K63: Brews Achieved | L63: Average Brews per day
J64: CARIB | L64: MTD | M64: YTD | N64: TARGET
J65: STAG | K65: 5 | L65: =AVERAGE(#REF!,#REF!,K74,#REF!,#REF!,#REF!,#REF!,#REF!,#REF!,#REF!,#REF!) -> #REF! | M65: =AVERAGE(6,6,'[12]March 31st'!$L$80,'[14]June 30th '!$L$71,6,L65,'[15]July 31st'!$L$108,'[16]Aug 30th'!$L$124,7,[17]Oct.31st!$L$51) -> #REF! | N65: 9
J66: GUINN
J67: VITAMALT
...

Sheet Feb 3rd
T1: P.G. | V1: Hot Time | X1: Process Time | Z1: Cooling Time
B2: Brewing Department Daily Process Loss Report | T2: Lower | U2: Upper | V2: Lower | W2: Upper | X2: Lower | Y2: Upper | Z2: Lower | AA2: Upper
S3: CARIB | T3: 11.6 | U3: 12 | V3: 0 | W3: 0.11805556 | X3: 0.22569444 | Y3: 0.26388889 | Z3: 0 | AA3: 60 | AC3: HR- PISNER
B4: Date: | C4: 45691 | J4: LOT WORT COLOUR: 3.5 | M4: Filter Sheets (Target 20 days) | S4: STAG | T4: 11.6 | U4: 12 | V4: 0 | W4: 0.11805556 | X4: 0.22569444 | Y4: 0.26388889 | Z4: 0 | AA4: 60
M5: Double | N5: Single | S5: GUINNESS | T5: 17 | U5: 17.5 | V5: 0 | W5: 0.10763889 | X5: 0.24652778 | Y5: 0.28472222 | Z5: 0 | AA5: 60
J6: MALT LOT: Lot 24 | L6: Sheet Day | S6: MACKESON | T6: 13.3 | U6: 13.5 | V6: 0 | W6: 0.12905093 | X6: 0.27430556 | Y6: 0.30208333 | Z6: 0
S7: STARMALT | T7: 17.1 | U7: 17.5 | V7: 0 | W7: 0.13605324 | X7: 0.27430556 | Y7: 0.30902778 | Z7: 0 | AA7: 60
B8: Brand | C8: Brew no. | D8: Kett. Hls | E8: Wort | F8: Cool Time(Mins) | G8: Cast. P.G. (Lab Result) | H8: Cast P.G. (Cellar Operator)-gravity | I8: Extr. Rec (80.9%) | J8: Theor. Extr. (77.5%) | K8: Boil Off /Vol. (4-6%) | L8: Boil Time | M8: Total Hot | N8: Brewing | O8: Operator | P8: Comments | Q8: Actual Pilsen Malt | S8: Hurricane Reef | T8: 16.6 | U8: 17 | V8: 0 | W8: 0.12905093 | X8: 0.27430556 | Y8: 0.30208333 | Z8: 0
E9: Meter (Hls) | F9: Target(< 60Mins) | M9: Time | S9: VITAMALT | T9: 14.4 | U9: 14.6 | V9: 0 | W9: 0.13905093 | X9: 0.26041667 | Y9: 0.29513889 | Z9: 0 | AA9: 75
B10: CARIB | C10: =[22]Brewhouse!$A173 -> CA071 | D10: =[22]Brewhouse!$AF173 -> 53.2 | E10: =[22]Brewhouse!$AI173 -> 49.3 | F10: =[22]Brewhouse!$V173 -> 77 | G10: =[22]Brewhouse!$AG173 -> 11.6 | H10: 11.6 | I10: =[22]Brewhouse!$AU173 -> 91.322447 | J10: =[22]Brewhouse!$AV173 -> 95.159712 | K10: =[22]Brewhouse!$Q173 -> 7.4426808 | L10: =[22]Brewhouse!$P173 -> 63 | M10: =[22]Brewhouse!$U173-[22]Brewhouse!$T173 -> 0.12013889 | N10: =[22]Brewhouse!$Z173 -> 0.26875 | O10: =[22]Brewhouse!$AX173 -> K.Benjamin | S10: =B10 -> CARIB | T10: =VLOOKUP($B10,$S$3:$Y$9,2,FALSE) -> 11.6 | U10: =VLOOKUP($B10,$S$3:$Y$9,3,FALSE) -> 12 | V10: =VLOOKUP($B10,$S$3:$Y$9,4,FALSE) -> 0 | W10: =VLOOKUP($B10,$S$3:$Y$9,5,FALSE) -> 0.11805556 | X10: =VLOOKUP($B10,$S$3:$Y$9,6,FALSE) -> 0.22569444 | Y10: =VLOOKUP($B10,$S$3:$Y$9,7,FALSE) -> 0.26388889 | Z10: =VLOOKUP($B10,$S$3:$AA$9,8,FALSE) -> 0 | AA10: =VLOOKUP($B10,$S$3:$AA$9,9,FALSE) -> 60
B11: CARIB | C11: =[22]Brewhouse!$A174 -> CA072 | D11: =[22]Brewhouse!$AF174 -> 53.1 | E11: =[22]Brewhouse!$AI174 -> 49.8 | F11: =[22]Brewhouse!$V174 -> 77 | G11: =[22]Brewhouse!$AG174 -> 11.9 | H11: 11.9 | I11: =[22]Brewhouse!$AU174 -> 94.643337 | J11: =[22]Brewhouse!$AV174 -> 98.620358 | K11: =[22]Brewhouse!$Q174 -> 7.2432432 | L11: =[22]Brewhouse!$P174 -> 62 | M11: =[22]Brewhouse!$U174-[22]Brewhouse!$T174 -> 0.12569444 | N11: =[22]Brewhouse!$Z174 -> 0.27291667 | O11: =[22]Brewhouse!$AX174 -> K.Benjamin | S11: =B11 -> CARIB | T11: =VLOOKUP($B11,$S$3:$Y$9,2,FALSE) -> 11.6 | U11: =VLOOKUP($B11,$S$3:$Y$9,3,FALSE) -> 12 | V11: =VLOOKUP($B11,$S$3:$Y$9,4,FALSE) -> 0 | W11: =VLOOKUP($B11,$S$3:$Y$9,5,FALSE) -> 0.11805556 | X11: =VLOOKUP($B11,$S$3:$Y$9,6,FALSE) -> 0.22569444 | Y11: =VLOOKUP($B11,$S$3:$Y$9,7,FALSE) -> 0.26388889 | Z11: =VLOOKUP($B11,$S$3:$AA$9,8,FALSE) -> 0 | AA11: =VLOOKUP($B11,$S$3:$AA$9,9,FALSE) -> 60
S12: =B12 -> 0 | T12: =VLOOKUP($B12,$S$3:$Y$9,2,FALSE) -> #N/A | U12: =VLOOKUP($B12,$S$3:$Y$9,3,FALSE) -> #N/A | V12: =VLOOKUP($B12,$S$3:$Y$9,4,FALSE) -> #N/A | W12: =VLOOKUP($B12,$S$3:$Y$9,5,FALSE) -> #N/A | X12: =VLOOKUP($B12,$S$3:$Y$9,6,FALSE) -> #N/A | Y12: =VLOOKUP($B12,$S$3:$Y$9,7,FALSE) -> #N/A | Z12: =VLOOKUP($B12,$S$3:$AA$9,8,FALSE) -> #N/A | AA12: =VLOOKUP($B12,$S$3:$AA$9,9,FALSE) -> #N/A
B13: GUINNESS | C13: =[23]Brewhouse!$A9 -> GU005 | D13: =[23]Brewhouse!$AF9 -> 60 | E13: =[23]Brewhouse!$AI9 -> 54 | F13: =[23]Brewhouse!$V9 -> 122 | G13: =[23]Brewhouse!$AG9 -> 17.2 | H13: 17.1 | I13: =[23]Brewhouse!$AU9 -> 96.878659 | J13: =[23]Brewhouse!$AV9 -> 99.01592 | K13: =[23]Brewhouse!$R9 -> 0.99145299 | L13: =[23]Brewhouse!$O9 -> 60 | M13: =[23]Brewhouse!$U9-[23]Brewhouse!$T9 -> 0.13472222 | N13: =[23]Brewhouse!$Z9 -> 0.27847222 | O13: =[23]Brewhouse!$AW9 -> K. Benjamin | S13: =B13 -> GUINNESS | T13: =VLOOKUP($B13,$S$3:$Y$9,2,FALSE) -> 17 | U13: =VLOOKUP($B13,$S$3:$Y$9,3,FALSE) -> 17.5 | V13: =VLOOKUP($B13,$S$3:$Y$9,4,FALSE) -> 0 | W13: =VLOOKUP($B13,$S$3:$Y$9,5,FALSE) -> 0.10763889 | X13: =VLOOKUP($B13,$S$3:$Y$9,6,FALSE) -> 0.24652778 | Y13: =VLOOKUP($B13,$S$3:$Y$9,7,FALSE) -> 0.28472222 | Z13: =VLOOKUP($B13,$S$3:$AA$9,8,FALSE) -> 0 | AA13: =VLOOKUP($B13,$S$3:$AA$9,9,FALSE) -> 60
B14: GUINNESS | C14: =[23]Brewhouse!$A10 -> GU006 | D14: =[23]Brewhouse!$AF10 -> 58.2 | E14: =[23]Brewhouse!$AI10 -> 53.3 | F14: =[23]Brewhouse!$V10 -> 82 | G14: =[23]Brewhouse!$AG10 -> 17.2 | H14: 17.1 | I14: =[23]Brewhouse!$AU10 -> 95.77155 | J14: =[23]Brewhouse!$AV10 -> 97.883574 | K14: =[23]Brewhouse!$R10 -> 0.83333333 | L14: =[23]Brewhouse!$O10 -> 59 | M14: =[23]Brewhouse!$U10-[23]Brewhouse!$T10 -> 0.125 | N14: =[23]Brewhouse!$Z10 -> 0.27916667 | O14: =[23]Brewhouse!$AW10 -> R. Regis | S14: =B14 -> GUINNESS | T14: =VLOOKUP($B14,$S$3:$Y$9,2,FALSE) -> 17 | U14: =VLOOKUP($B14,$S$3:$Y$9,3,FALSE) -> 17.5 | V14: =VLOOKUP($B14,$S$3:$Y$9,4,FALSE) -> 0 | W14: =VLOOKUP($B14,$S$3:$Y$9,5,FALSE) -> 0.10763889 | X14: =VLOOKUP($B14,$S$3:$Y$9,6,FALSE) -> 0.24652778 | Y14: =VLOOKUP($B14,$S$3:$Y$9,7,FALSE) -> 0.28472222 | Z14: =VLOOKUP($B14,$S$3:$AA$9,8,FALSE) -> 0 | AA14: =VLOOKUP($B14,$S$3:$AA$9,9,FALSE) -> 60
B15: GUINNESS | C15: =[23]Brewhouse!$A11 -> GU007 | D15: =[23]Brewhouse!$AF11 -> 58.3 | E15: =[23]Brewhouse!$AI11 -> 53.4 | F15: =[23]Brewhouse!$V11 -> 84 | G15: =[23]Brewhouse!$AG11 -> 17.12 | H15: 17.1 | I15: =[23]Brewhouse!$AU11 -> 97.655043 | J15: =[23]Brewhouse!$AV11 -> 99.863657 | K15: =[23]Brewhouse!$R11 -> 1.0086957 | L15: =[23]Brewhouse!$O11 -> 58 | M15: =[23]Brewhouse!$U11-[23]Brewhouse!$T11 -> 0.13263889 | N15: =[23]Brewhouse!$Z11 -> 0.29652778 | O15: =[23]Brewhouse!$AW11 -> R. Regis | S15: =B15 -> GUINNESS | T15: =VLOOKUP($B15,$S$3:$Y$9,2,FALSE) -> 17 | U15: =VLOOKUP($B15,$S$3:$Y$9,3,FALSE) -> 17.5 | V15: =VLOOKUP($B15,$S$3:$Y$9,4,FALSE) -> 0 | W15: =VLOOKUP($B15,$S$3:$Y$9,5,FALSE) -> 0.10763889 | X15: =VLOOKUP($B15,$S$3:$Y$9,6,FALSE) -> 0.24652778 | Y15: =VLOOKUP($B15,$S$3:$Y$9,7,FALSE) -> 0.28472222 | Z15: =VLOOKUP($B15,$S$3:$AA$9,8,FALSE) -> 0 | AA15: =VLOOKUP($B15,$S$3:$AA$9,9,FALSE) -> 60
B16: GUINNESS | C16: =[23]Brewhouse!$A12 -> GU008 | D16: =[23]Brewhouse!$AF12 -> 57.7 | E16: =[23]Brewhouse!$AI12 -> 52.7 | F16: =[23]Brewhouse!$V12 -> 81 | G16: =[23]Brewhouse!$AG12 -> 17.3 | H16: 17.1 | I16: =[23]Brewhouse!$AU12 -> 97.588179 | J16: =[23]Brewhouse!$AV12 -> 99.795281 | K16: =[23]Brewhouse!$R12 -> -1.5944541 | L16: =[23]Brewhouse!$O12 -> 58 | M16: =[23]Brewhouse!$U12-[23]Brewhouse!$T12 -> 0.14375 | N16: =[23]Brewhouse!$Z12 -> 0.31736111 | O16: =[23]Brewhouse!$AW12 -> R.Sookram | S16: =B16 -> GUINNESS | T16: =VLOOKUP($B16,$S$3:$Y$9,2,FALSE) -> 17 | U16: =VLOOKUP($B16,$S$3:$Y$9,3,FALSE) -> 17.5 | V16: =VLOOKUP($B16,$S$3:$Y$9,4,FALSE) -> 0 | W16: =VLOOKUP($B16,$S$3:$Y$9,5,FALSE) -> 0.10763889 | X16: =VLOOKUP($B16,$S$3:$Y$9,6,FALSE) -> 0.24652778 | Y16: =VLOOKUP($B16,$S$3:$Y$9,7,FALSE) -> 0.28472222 | Z16: =VLOOKUP($B16,$S$3:$AA$9,8,FALSE) -> 0 | AA16: =VLOOKUP($B16,$S$3:$AA$9,9,FALSE) -> 60
B17: GUINNESS | C17: =[23]Brewhouse!$A13 -> GU009 | D17: =[23]Brewhouse!$AF13 -> 57.3 | E17: =[23]Brewhouse!$AI13 -> 52.5 | F17: =[23]Brewhouse!$V13 -> 82 | G17: =[23]Brewhouse!$AG13 -> 17.4 | H17: 17.1 | I17: =[23]Brewhouse!$AU13 -> 95.484973 | J17: =[23]Brewhouse!$AV13 -> 97.590271 | K17: =[23]Brewhouse!$R13 -> -0.035523979 | L17: =[23]Brewhouse!$O13 -> 55 | M17: =[23]Brewhouse!$U13-[23]Brewhouse!$T13 -> 0.12361111 | N17: =[23]Brewhouse!$Z13 -> 0.29305556 | O17: =[23]Brewhouse!$AW13 -> R.Sookram | S17: =B17 -> GUINNESS | T17: =VLOOKUP($B17,$S$3:$Y$9,2,FALSE) -> 17 | U17: =VLOOKUP($B17,$S$3:$Y$9,3,FALSE) -> 17.5 | V17: =VLOOKUP($B17,$S$3:$Y$9,4,FALSE) -> 0 | W17: =VLOOKUP($B17,$S$3:$Y$9,5,FALSE) -> 0.10763889 | X17: =VLOOKUP($B17,$S$3:$Y$9,6,FALSE) -> 0.24652778 | Y17: =VLOOKUP($B17,$S$3:$Y$9,7,FALSE) -> 0.28472222 | Z17: =VLOOKUP($B17,$S$3:$AA$9,8,FALSE) -> 0 | AA17: =VLOOKUP($B17,$S$3:$AA$9,9,FALSE) -> 60
B18: GUINNESS | C18: =[23]Brewhouse!$A14 -> GU010 | D18: =[23]Brewhouse!$AF14 -> 57.3 | E18: =[23]Brewhouse!$AI14 -> 52.5 | F18: =[23]Brewhouse!$V14 -> 85 | G18: =[23]Brewhouse!$AG14 -> 17.1 | H18: 17.1 | I18: =[23]Brewhouse!$AU14 -> 96.085762 | J18: =[23]Brewhouse!$AV14 -> 98.258509 | K18: =[23]Brewhouse!$R14 -> -0.035587189 | L18: =[23]Brewhouse!$O14 -> 56 | M18: =[23]Brewhouse!$U14-[23]Brewhouse!$T14 -> 0.14652778 | N18: =[23]Brewhouse!$Z14 -> 0.33541667 | O18: =[23]Brewhouse!$AW14 -> R.Sookram | S18: =B18 -> GUINNESS | T18: =VLOOKUP($B18,$S$3:$Y$9,2,FALSE) -> 17 | U18: =VLOOKUP($B18,$S$3:$Y$9,3,FALSE) -> 17.5 | V18: =VLOOKUP($B18,$S$3:$Y$9,4,FALSE) -> 0 | W18: =VLOOKUP($B18,$S$3:$Y$9,5,FALSE) -> 0.10763889 | X18: =VLOOKUP($B18,$S$3:$Y$9,6,FALSE) -> 0.24652778 | Y18: =VLOOKUP($B18,$S$3:$Y$9,7,FALSE) -> 0.28472222 | Z18: =VLOOKUP($B18,$S$3:$AA$9,8,FALSE) -> 0 | AA18: =VLOOKUP($B18,$S$3:$AA$9,9,FALSE) -> 60
S19: =B19 -> 0 | T19: =VLOOKUP($B19,$S$3:$Y$9,2,FALSE) -> #N/A | U19: =VLOOKUP($B19,$S$3:$Y$9,3,FALSE) -> #N/A | V19: =VLOOKUP($B19,$S$3:$Y$9,4,FALSE) -> #N/A | W19: =VLOOKUP($B19,$S$3:$Y$9,5,FALSE) -> #N/A | X19: =VLOOKUP($B19,$S$3:$Y$9,6,FALSE) -> #N/A | Y19: =VLOOKUP($B19,$S$3:$Y$9,7,FALSE) -> #N/A | Z19: =VLOOKUP($B19,$S$3:$AA$9,8,FALSE) -> #N/A | AA19: =VLOOKUP($B19,$S$3:$AA$9,9,FALSE) -> #N/A
S20: =B20 -> 0 | T20: =VLOOKUP($B20,$S$3:$Y$9,2,FALSE) -> #N/A | U20: =VLOOKUP($B20,$S$3:$Y$9,3,FALSE) -> #N/A | V20: =VLOOKUP($B20,$S$3:$Y$9,4,FALSE) -> #N/A | W20: =VLOOKUP($B20,$S$3:$Y$9,5,FALSE) -> #N/A | X20: =VLOOKUP($B20,$S$3:$Y$9,6,FALSE) -> #N/A | Y20: =VLOOKUP($B20,$S$3:$Y$9,7,FALSE) -> #N/A | Z20: =VLOOKUP($B20,$S$3:$AA$9,8,FALSE) -> #N/A | AA20: =VLOOKUP($B20,$S$3:$AA$9,9,FALSE) -> #N/A
S21: =B21 -> 0 | T21: =VLOOKUP($B21,$S$3:$Y$9,2,FALSE) -> #N/A | U21: =VLOOKUP($B21,$S$3:$Y$9,3,FALSE) -> #N/A | V21: =VLOOKUP($B21,$S$3:$Y$9,4,FALSE) -> #N/A | W21: =VLOOKUP($B21,$S$3:$Y$9,5,FALSE) -> #N/A | X21: =VLOOKUP($B21,$S$3:$Y$9,6,FALSE) -> #N/A | Y21: =VLOOKUP($B21,$S$3:$Y$9,7,FALSE) -> #N/A | Z21: =VLOOKUP($B21,$S$3:$AA$9,8,FALSE) -> #N/A | AA21: =VLOOKUP($B21,$S$3:$AA$9,9,FALSE) -> #N/A
S22: =B22 -> 0 | T22: =VLOOKUP($B22,$S$3:$Y$9,2,FALSE) -> #N/A | U22: =VLOOKUP($B22,$S$3:$Y$9,3,FALSE) -> #N/A | V22: =VLOOKUP($B22,$S$3:$Y$9,4,FALSE) -> #N/A | W22: =VLOOKUP($B22,$S$3:$Y$9,5,FALSE) -> #N/A | X22: =VLOOKUP($B22,$S$3:$Y$9,6,FALSE) -> #N/A | Y22: =VLOOKUP($B22,$S$3:$Y$9,7,FALSE) -> #N/A | Z22: =VLOOKUP($B22,$S$3:$AA$9,8,FALSE) -> #N/A | AA22: =VLOOKUP($B22,$S$3:$AA$9,9,FALSE) -> #N/A
S23: =B23 -> 0 | T23: =VLOOKUP($B23,$S$3:$Y$9,2,FALSE) -> #N/A | U23: =VLOOKUP($B23,$S$3:$Y$9,3,FALSE) -> #N/A | V23: =VLOOKUP($B23,$S$3:$Y$9,4,FALSE) -> #N/A | W23: =VLOOKUP($B23,$S$3:$Y$9,5,FALSE) -> #N/A | X23: =VLOOKUP($B23,$S$3:$Y$9,6,FALSE) -> #N/A | Y23: =VLOOKUP($B23,$S$3:$Y$9,7,FALSE) -> #N/A | Z23: =VLOOKUP($B23,$S$3:$AA$9,8,FALSE) -> #N/A | AA23: =VLOOKUP($B23,$S$3:$AA$9,9,FALSE) -> #N/A
S24: =B24 -> 0 | T24: =VLOOKUP($B24,$S$3:$Y$9,2,FALSE) -> #N/A | U24: =VLOOKUP($B24,$S$3:$Y$9,3,FALSE) -> #N/A | V24: =VLOOKUP($B24,$S$3:$Y$9,4,FALSE) -> #N/A | W24: =VLOOKUP($B24,$S$3:$Y$9,5,FALSE) -> #N/A | X24: =VLOOKUP($B24,$S$3:$Y$9,6,FALSE) -> #N/A | Y24: =VLOOKUP($B24,$S$3:$Y$9,7,FALSE) -> #N/A | Z24: =VLOOKUP($B24,$S$3:$AA$9,8,FALSE) -> #N/A | AA24: =VLOOKUP($B24,$S$3:$AA$9,9,FALSE) -> #N/A
S25: =B25 -> 0 | T25: =VLOOKUP($B25,$S$3:$Y$9,2,FALSE) -> #N/A | U25: =VLOOKUP($B25,$S$3:$Y$9,3,FALSE) -> #N/A | V25: =VLOOKUP($B25,$S$3:$Y$9,4,FALSE) -> #N/A | W25: =VLOOKUP($B25,$S$3:$Y$9,5,FALSE) -> #N/A | X25: =VLOOKUP($B25,$S$3:$Y$9,6,FALSE) -> #N/A | Y25: =VLOOKUP($B25,$S$3:$Y$9,7,FALSE) -> #N/A | Z25: =VLOOKUP($B25,$S$3:$AA$9,8,FALSE) -> #N/A | AA25: =VLOOKUP($B25,$S$3:$AA$9,9,FALSE) -> #N/A
S26: =B26 -> 0 | T26: =VLOOKUP($B26,$S$3:$Y$9,2,FALSE) -> #N/A | U26: =VLOOKUP($B26,$S$3:$Y$9,3,FALSE) -> #N/A | V26: =VLOOKUP($B26,$S$3:$Y$9,4,FALSE) -> #N/A | W26: =VLOOKUP($B26,$S$3:$Y$9,5,FALSE) -> #N/A | X26: =VLOOKUP($B26,$S$3:$Y$9,6,FALSE) -> #N/A | Y26: =VLOOKUP($B26,$S$3:$Y$9,7,FALSE) -> #N/A | Z26: =VLOOKUP($B26,$S$3:$AA$9,8,FALSE) -> #N/A | AA26: =VLOOKUP($B26,$S$3:$AA$9,9,FALSE) -> #N/A
S27: =B27 -> 0 | T27: =VLOOKUP($B27,$S$3:$Y$9,2,FALSE) -> #N/A | U27: =VLOOKUP($B27,$S$3:$Y$9,3,FALSE) -> #N/A | V27: =VLOOKUP($B27,$S$3:$Y$9,4,FALSE) -> #N/A | W27: =VLOOKUP($B27,$S$3:$Y$9,5,FALSE) -> #N/A | X27: =VLOOKUP($B27,$S$3:$Y$9,6,FALSE) -> #N/A | Y27: =VLOOKUP($B27,$S$3:$Y$9,7,FALSE) -> #N/A | Z27: =VLOOKUP($B27,$S$3:$AA$9,8,FALSE) -> #N/A | AA27: =VLOOKUP($B27,$S$3:$AA$9,9,FALSE) -> #N/A
S28: =B28 -> 0 | T28: =VLOOKUP($B28,$S$3:$Y$9,2,FALSE) -> #N/A | U28: =VLOOKUP($B28,$S$3:$Y$9,3,FALSE) -> #N/A | V28: =VLOOKUP($B28,$S$3:$Y$9,4,FALSE) -> #N/A | W28: =VLOOKUP($B28,$S$3:$Y$9,5,FALSE) -> #N/A | X28: =VLOOKUP($B28,$S$3:$Y$9,6,FALSE) -> #N/A | Y28: =VLOOKUP($B28,$S$3:$Y$9,7,FALSE) -> #N/A | Z28: =VLOOKUP($B28,$S$3:$AA$9,8,FALSE) -> #N/A | AA28: =VLOOKUP($B28,$S$3:$AA$9,9,FALSE) -> #N/A
S29: =B29 -> 0 | T29: =VLOOKUP($B29,$S$3:$Y$9,2,FALSE) -> #N/A | U29: =VLOOKUP($B29,$S$3:$Y$9,3,FALSE) -> #N/A | V29: =VLOOKUP($B29,$S$3:$Y$9,4,FALSE) -> #N/A | W29: =VLOOKUP($B29,$S$3:$Y$9,5,FALSE) -> #N/A | X29: =VLOOKUP($B29,$S$3:$Y$9,6,FALSE) -> #N/A | Y29: =VLOOKUP($B29,$S$3:$Y$9,7,FALSE) -> #N/A | Z29: =VLOOKUP($B29,$S$3:$AA$9,8,FALSE) -> #N/A | AA29: =VLOOKUP($B29,$S$3:$AA$9,9,FALSE) -> #N/A
S30: =B30 -> 0 | T30: =VLOOKUP($B30,$S$3:$Y$9,2,FALSE) -> #N/A | U30: =VLOOKUP($B30,$S$3:$Y$9,3,FALSE) -> #N/A | V30: =VLOOKUP($B30,$S$3:$Y$9,4,FALSE) -> #N/A | W30: =VLOOKUP($B30,$S$3:$Y$9,5,FALSE) -> #N/A | X30: =VLOOKUP($B30,$S$3:$Y$9,6,FALSE) -> #N/A | Y30: =VLOOKUP($B30,$S$3:$Y$9,7,FALSE) -> #N/A | Z30: =VLOOKUP($B30,$S$3:$AA$9,8,FALSE) -> #N/A | AA30: =VLOOKUP($B30,$S$3:$AA$9,9,FALSE) -> #N/A
... S52: =B52 -> 0 | T52: =VLOOKUP($B52,$S$3:$Y$9,2,FALSE) -> #N/A | U52: =VLOOKUP($B52,$S$3:$Y$9,3,FALSE) -> #N/A | V52: =VLOOKUP($B52,$S$3:$Y$9,4,FALSE) -> #N/A | W52: =VLOOKUP($B52,$S$3:$Y$9,5,FALSE) -> #N/A | X52: =VLOOKUP($B52,$S$3:$Y$9,6,FALSE) -> #N/A | Y52: =VLOOKUP($B52,$S$3:$Y$9,7,FALSE) -> #N/A | Z52: =VLOOKUP($B52,$S$3:$AA$9,8,FALSE) -> #N/A | AA52: =VLOOKUP($B52,$S$3:$AA$9,9,FALSE) -> #N/A
I53: EXTRACT RECOVERY
B54: BRAND | D54: BBT P.G./ O.G | I54: Brand | J54: Actual | K54: MTD No. of Brews | L54: MTD | M54: YTD | N54: Target
B55: CARIB | C55: {=[22]Process!$D$119:$D$126} -> 11.58 | D55: 11.7 | I55: CARIB | J55: =AVERAGE(I10:I11) -> 92.982892 | K55: =COUNTA([22]Brewhouse!$A$173:$A$174) -> 2 | L55: =AVERAGE([22]Brewhouse!$AU$173:$AU$174) -> 92.982892 | M55: =AVERAGE([22]Brewhouse!$AU$102:$AU$171,[22]Brewhouse!$AU$173:$AU$174) -> 94.53179 | N55: 98
C56: 11.81 | I56: STAG | M56: =AVERAGE([24]Brewhouse!$AS$15:$AS$64) -> 96.077332 | N56: 98
C57: 11.83 | D57: 11.7 | I57: GUINNESS | J57: =AVERAGE(I13:I18) -> 96.577361 | K57: =COUNTA([23]Brewhouse!$A$9:$A$14) -> 6 | L57: =AVERAGE([23]Brewhouse!$AU$9:$AU$14) -> 96.577361 | M57: =AVERAGE([23]Brewhouse!$AU$4:$AU$7,[23]Brewhouse!$AU$9:$AU$14) -> 96.787192 | N57: 98
C58: 11.8 | I58: VITAMALT | M58: =AVERAGE([25]Brewhouse!$AV$5:$AV$14) -> 97.717673 | N58: 98
C59: 11.8 | D59: 11.8 | I59: MAXIMALT | N59: 98
C60: 11.9 | I60: MACKESON | M60: =AVERAGE([26]Brewhouse!$AT$4:$AT$11) -> 94.812617 | N60: 98
C61: 11.7 | D61: 11.8 | I61: STARMALT | M61: =AVERAGE([27]Brewhouse!$AY$6:$AY$13) -> 93.094806 | N61: 98
...

Sheet Feb 4th
T1: P.G. | V1: Hot Time | X1: Process Time | Z1: Cooling Time
B2: Brewing Department Daily Process Loss Report | T2: Lower | U2: Upper | V2: Lower | W2: Upper | X2: Lower | Y2: Upper | Z2: Lower | AA2: Upper
S3: CARIB | T3: 11.6 | U3: 12 | V3: 0 | W3: 0.11805556 | X3: 0.22569444 | Y3: 0.26388889 | Z3: 0 | AA3: 60 | AC3: HR- PISNER
B4: Date: | C4: 45692 | J4: LOT WORT COLOUR: 3.5 | M4: Filter Sheets (Target 20 days) | S4: STAG | T4: 11.6 | U4: 12 | V4: 0 | W4: 0.11805556 | X4: 0.22569444 | Y4: 0.26388889 | Z4: 0 | AA4: 60
M5: Double | N5: Single | S5: GUINNESS | T5: 17 | U5: 17.5 | V5: 0 | W5: 0.10763889 | X5: 0.24652778 | Y5: 0.28472222 | Z5: 0 | AA5: 60
J6: MALT LOT: Lot 24 | L6: Sheet Day | S6: MACKESON | T6: 13.3 | U6: 13.5 | V6: 0 | W6: 0.12905093 | X6: 0.27430556 | Y6: 0.30208333 | Z6: 0
S7: STARMALT | T7: 17.1 | U7: 17.5 | V7: 0 | W7: 0.13605324 | X7: 0.27430556 | Y7: 0.30902778 | Z7: 0 | AA7: 60
B8: Brand | C8: Brew no. | D8: Kett. Hls | E8: Wort | F8: Cool Time(Mins) | G8: Cast. P.G. (Lab Result) | H8: Cast P.G. (Cellar Operator)-gravity | I8: Extr. Rec (80.9%) | J8: Theor. Extr. (77.5%) | K8: Boil Off /Vol. (4-6%) | L8: Boil Time | M8: Total Hot | N8: Brewing | O8: Operator | P8: Comments | Q8: Actual Pilsen Malt | S8: Hurricane Reef | T8: 16.6 | U8: 17 | V8: 0 | W8: 0.12905093 | X8: 0.27430556 | Y8: 0.30208333 | Z8: 0
E9: Meter (Hls) | F9: Target(< 60Mins) | M9: Time | S9: VITAMALT | T9: 14.4 | U9: 14.6 | V9: 0 | W9: 0.13905093 | X9: 0.26041667 | Y9: 0.29513889 | Z9: 0 | AA9: 75
B10: CARIB | C10: =[22]Brewhouse!$A175 -> CA073 | D10: =[22]Brewhouse!$AF175 -> 53.3 | E10: =[22]Brewhouse!$AI175 -> 49.4 | F10: =[22]Brewhouse!$V175 -> 57 | G10: =[22]Brewhouse!$AG175 -> 11.6 | H10: 11.6 | I10: =[22]Brewhouse!$AU175 -> 90.625658 | J10: =[22]Brewhouse!$AV175 -> 94.279176 | K10: =[22]Brewhouse!$Q175 -> 7.754386 | L10: =[22]Brewhouse!$P175 -> 57 | M10: =[22]Brewhouse!$U175-[22]Brewhouse!$T175 -> 0.10763889 | N10: =[22]Brewhouse!$Z175 -> 0.27777778 | O10: =[22]Brewhouse!$AX175 -> R.Sookram | S10: =B10 -> CARIB | T10: =VLOOKUP($B10,$S$3:$Y$9,2,FALSE) -> 11.6 | U10: =VLOOKUP($B10,$S$3:$Y$9,3,FALSE) -> 12 | V10: =VLOOKUP($B10,$S$3:$Y$9,4,FALSE) -> 0 | W10: =VLOOKUP($B10,$S$3:$Y$9,5,FALSE) -> 0.11805556 | X10: =VLOOKUP($B10,$S$3:$Y$9,6,FALSE) -> 0.22569444 | Y10: =VLOOKUP($B10,$S$3:$Y$9,7,FALSE) -> 0.26388889 | Z10: =VLOOKUP($B10,$S$3:$AA$9,8,FALSE) -> 0 | AA10: =VLOOKUP($B10,$S$3:$AA$9,9,FALSE) -> 60
B11: CARIB | C11: =[22]Brewhouse!$A176 -> CA074 | D11: =[22]Brewhouse!$AF176 -> 54.1 | E11: =[22]Brewhouse!$AI176 -> 50.4 | F11: =[22]Brewhouse!$V176 -> 60 | G11: =[22]Brewhouse!$AG176 -> 12.1 | H11: 12 | I11: =[22]Brewhouse!$AU176 -> 96.877996 | J11: =[22]Brewhouse!$AV176 -> 100.95002 | K11: =[22]Brewhouse!$Q176 -> 6.6422018 | L11: =[22]Brewhouse!$P176 -> 57 | M11: =[22]Brewhouse!$U176-[22]Brewhouse!$T176 -> 0.10972222 | N11: =[22]Brewhouse!$Z176 -> 0.28402778 | O11: =[22]Brewhouse!$AX176 -> R.Sookram | S11: =B11 -> CARIB | T11: =VLOOKUP($B11,$S$3:$Y$9,2,FALSE) -> 11.6 | U11: =VLOOKUP($B11,$S$3:$Y$9,3,FALSE) -> 12 | V11: =VLOOKUP($B11,$S$3:$Y$9,4,FALSE) -> 0 | W11: =VLOOKUP($B11,$S$3:$Y$9,5,FALSE) -> 0.11805556 | X11: =VLOOKUP($B11,$S$3:$Y$9,6,FALSE) -> 0.22569444 | Y11: =VLOOKUP($B11,$S$3:$Y$9,7,FALSE) -> 0.26388889 | Z11: =VLOOKUP($B11,$S$3:$AA$9,8,FALSE) -> 0 | AA11: =VLOOKUP($B11,$S$3:$AA$9,9,FALSE) -> 60
B12: CARIB | C12: =[22]Brewhouse!$A177 -> CA075 | D12: =[22]Brewhouse!$AF177 -> 52.3 | E12: =[22]Brewhouse!$AI177 -> 48.6 | F12: =[22]Brewhouse!$V177 -> 57 | G12: =[22]Brewhouse!$AG177 -> 11.9 | I12: =[22]Brewhouse!$AU177 -> 92.135215 | J12: =[22]Brewhouse!$AV177 -> 96.007261 | K12: =[22]Brewhouse!$Q177 -> 8.9323843 | L12: =[22]Brewhouse!$P177 -> 60 | M12: =[22]Brewhouse!$U177-[22]Brewhouse!$T177 -> 0.10763889 | N12: =[22]Brewhouse!$Z177 -> 0.27083333 | O12: =[22]Brewhouse!$AX177 -> R.Sookram | S12: =B12 -> CARIB | T12: =VLOOKUP($B12,$S$3:$Y$9,2,FALSE) -> 11.6 | U12: =VLOOKUP($B12,$S$3:$Y$9,3,FALSE) -> 12 | V12: =VLOOKUP($B12,$S$3:$Y$9,4,FALSE) -> 0 | W12: =VLOOKUP($B12,$S$3:$Y$9,5,FALSE) -> 0.11805556 | X12: =VLOOKUP($B12,$S$3:$Y$9,6,FALSE) -> 0.22569444 | Y12: =VLOOKUP($B12,$S$3:$Y$9,7,FALSE) -> 0.26388889 | Z12: =VLOOKUP($B12,$S$3:$AA$9,8,FALSE) -> 0 | AA12: =VLOOKUP($B12,$S$3:$AA$9,9,FALSE) -> 60
B13: CARIB | C13: =[22]Brewhouse!$A178 -> CA076 | D13: =[22]Brewhouse!$AF178 -> 53.4 | E13: =[22]Brewhouse!$AI178 -> 49.9 | F13: =[22]Brewhouse!$V178 -> 57 | G13: =[22]Brewhouse!$AG178 -> 11.8 | H13: 11.8 | I13: =[22]Brewhouse!$AU178 -> 93.533472 | J13: =[22]Brewhouse!$AV178 -> 97.464704 | K13: =[22]Brewhouse!$Q178 -> 7.3049645 | L13: =[22]Brewhouse!$P178 -> 60 | M13: =[22]Brewhouse!$U178-[22]Brewhouse!$T178 -> 0.10416667 | N13: =[22]Brewhouse!$Z178 -> 0.26319444 | O13: =[22]Brewhouse!$AX178 -> K.Benjamin | S13: =B13 -> CARIB | T13: =VLOOKUP($B13,$S$3:$Y$9,2,FALSE) -> 11.6 | U13: =VLOOKUP($B13,$S$3:$Y$9,3,FALSE) -> 12 | V13: =VLOOKUP($B13,$S$3:$Y$9,4,FALSE) -> 0 | W13: =VLOOKUP($B13,$S$3:$Y$9,5,FALSE) -> 0.11805556 | X13: =VLOOKUP($B13,$S$3:$Y$9,6,FALSE) -> 0.22569444 | Y13: =VLOOKUP($B13,$S$3:$Y$9,7,FALSE) -> 0.26388889 | Z13: =VLOOKUP($B13,$S$3:$AA$9,8,FALSE) -> 0 | AA13: =VLOOKUP($B13,$S$3:$AA$9,9,FALSE) -> 60
B14: CARIB | C14: =[22]Brewhouse!$A179 -> CA077 | D14: =[22]Brewhouse!$AF179 -> 53.5 | E14: =[22]Brewhouse!$AI179 -> 50.1 | F14: =[22]Brewhouse!$V179 -> 61 | G14: =[22]Brewhouse!$AG179 -> 11.8 | H14: 11.8 | I14: =[22]Brewhouse!$AU179 -> 94.139723 | J14: =[22]Brewhouse!$AV179 -> 98.09601 | K14: =[22]Brewhouse!$Q179 -> 6.797153 | L14: =[22]Brewhouse!$P179 -> 62 | M14: =[22]Brewhouse!$U179-[22]Brewhouse!$T179 -> 0.11388889 | N14: =[22]Brewhouse!$Z179 -> 0.26805556 | O14: =[22]Brewhouse!$AX179 -> K.Benjamin | S14: =B14 -> CARIB | T14: =VLOOKUP($B14,$S$3:$Y$9,2,FALSE) -> 11.6 | U14: =VLOOKUP($B14,$S$3:$Y$9,3,FALSE) -> 12 | V14: =VLOOKUP($B14,$S$3:$Y$9,4,FALSE) -> 0 | W14: =VLOOKUP($B14,$S$3:$Y$9,5,FALSE) -> 0.11805556 | X14: =VLOOKUP($B14,$S$3:$Y$9,6,FALSE) -> 0.22569444 | Y14: =VLOOKUP($B14,$S$3:$Y$9,7,FALSE) -> 0.26388889 | Z14: =VLOOKUP($B14,$S$3:$AA$9,8,FALSE) -> 0 | AA14: =VLOOKUP($B14,$S$3:$AA$9,9,FALSE) -> 60
S15: =B15 -> 0 | T15: =VLOOKUP($B15,$S$3:$Y$9,2,FALSE) -> #N/A | U15: =VLOOKUP($B15,$S$3:$Y$9,3,FALSE) -> #N/A | V15: =VLOOKUP($B15,$S$3:$Y$9,4,FALSE) -> #N/A | W15: =VLOOKUP($B15,$S$3:$Y$9,5,FALSE) -> #N/A | X15: =VLOOKUP($B15,$S$3:$Y$9,6,FALSE) -> #N/A | Y15: =VLOOKUP($B15,$S$3:$Y$9,7,FALSE) -> #N/A | Z15: =VLOOKUP($B15,$S$3:$AA$9,8,FALSE) -> #N/A | AA15: =VLOOKUP($B15,$S$3:$AA$9,9,FALSE) -> #N/A
S16: =B16 -> 0 | T16: =VLOOKUP($B16,$S$3:$Y$9,2,FALSE) -> #N/A | U16: =VLOOKUP($B16,$S$3:$Y$9,3,FALSE) -> #N/A | V16: =VLOOKUP($B16,$S$3:$Y$9,4,FALSE) -> #N/A | W16: =VLOOKUP($B16,$S$3:$Y$9,5,FALSE) -> #N/A | X16: =VLOOKUP($B16,$S$3:$Y$9,6,FALSE) -> #N/A | Y16: =VLOOKUP($B16,$S$3:$Y$9,7,FALSE) -> #N/A | Z16: =VLOOKUP($B16,$S$3:$AA$9,8,FALSE) -> #N/A | AA16: =VLOOKUP($B16,$S$3:$AA$9,9,FALSE) -> #N/A
S17: =B17 -> 0 | T17: =VLOOKUP($B17,$S$3:$Y$9,2,FALSE) -> #N/A | U17: =VLOOKUP($B17,$S$3:$Y$9,3,FALSE) -> #N/A | V17: =VLOOKUP($B17,$S$3:$Y$9,4,FALSE) -> #N/A | W17: =VLOOKUP($B17,$S$3:$Y$9,5,FALSE) -> #N/A | X17: =VLOOKUP($B17,$S$3:$Y$9,6,FALSE) -> #N/A | Y17: =VLOOKUP($B17,$S$3:$Y$9,7,FALSE) -> #N/A | Z17: =VLOOKUP($B17,$S$3:$AA$9,8,FALSE) -> #N/A | AA17: =VLOOKUP($B17,$S$3:$AA$9,9,FALSE) -> #N/A
S18: =B18 -> 0 | T18: =VLOOKUP($B18,$S$3:$Y$9,2,FALSE) -> #N/A | U18: =VLOOKUP($B18,$S$3:$Y$9,3,FALSE) -> #N/A | V18: =VLOOKUP($B18,$S$3:$Y$9,4,FALSE) -> #N/A | W18: =VLOOKUP($B18,$S$3:$Y$9,5,FALSE) -> #N/A | X18: =VLOOKUP($B18,$S$3:$Y$9,6,FALSE) -> #N/A | Y18: =VLOOKUP($B18,$S$3:$Y$9,7,FALSE) -> #N/A | Z18: =VLOOKUP($B18,$S$3:$AA$9,8,FALSE) -> #N/A | AA18: =VLOOKUP($B18,$S$3:$AA$9,9,FALSE) -> #N/A
S19: =B19 -> 0 | T19: =VLOOKUP($B19,$S$3:$Y$9,2,FALSE) -> #N/A | U19: =VLOOKUP($B19,$S$3:$Y$9,3,FALSE) -> #N/A | V19: =VLOOKUP($B19,$S$3:$Y$9,4,FALSE) -> #N/A | W19: =VLOOKUP($B19,$S$3:$Y$9,5,FALSE) -> #N/A | X19: =VLOOKUP($B19,$S$3:$Y$9,6,FALSE) -> #N/A | Y19: =VLOOKUP($B19,$S$3:$Y$9,7,FALSE) -> #N/A | Z19: =VLOOKUP($B19,$S$3:$AA$9,8,FALSE) -> #N/A | AA19: =VLOOKUP($B19,$S$3:$AA$9,9,FALSE) -> #N/A
S20: =B20 -> 0 | T20: =VLOOKUP($B20,$S$3:$Y$9,2,FALSE) -> #N/A | U20: =VLOOKUP($B20,$S$3:$Y$9,3,FALSE) -> #N/A | V20: =VLOOKUP($B20,$S$3:$Y$9,4,FALSE) -> #N/A | W20: =VLOOKUP($B20,$S$3:$Y$9,5,FALSE) -> #N/A | X20: =VLOOKUP($B20,$S$3:$Y$9,6,FALSE) -> #N/A | Y20: =VLOOKUP($B20,$S$3:$Y$9,7,FALSE) -> #N/A | Z20: =VLOOKUP($B20,$S$3:$AA$9,8,FALSE) -> #N/A | AA20: =VLOOKUP($B20,$S$3:$AA$9,9,FALSE) -> #N/A
S21: =B21 -> 0 | T21: =VLOOKUP($B21,$S$3:$Y$9,2,FALSE) -> #N/A | U21: =VLOOKUP($B21,$S$3:$Y$9,3,FALSE) -> #N/A | V21: =VLOOKUP($B21,$S$3:$Y$9,4,FALSE) -> #N/A | W21: =VLOOKUP($B21,$S$3:$Y$9,5,FALSE) -> #N/A | X21: =VLOOKUP($B21,$S$3:$Y$9,6,FALSE) -> #N/A | Y21: =VLOOKUP($B21,$S$3:$Y$9,7,FALSE) -> #N/A | Z21: =VLOOKUP($B21,$S$3:$AA$9,8,FALSE) -> #N/A | AA21: =VLOOKUP($B21,$S$3:$AA$9,9,FALSE) -> #N/A
S22: =B22 -> 0 | T22: =VLOOKUP($B22,$S$3:$Y$9,2,FALSE) -> #N/A | U22: =VLOOKUP($B22,$S$3:$Y$9,3,FALSE) -> #N/A | V22: =VLOOKUP($B22,$S$3:$Y$9,4,FALSE) -> #N/A | W22: =VLOOKUP($B22,$S$3:$Y$9,5,FALSE) -> #N/A | X22: =VLOOKUP($B22,$S$3:$Y$9,6,FALSE) -> #N/A | Y22: =VLOOKUP($B22,$S$3:$Y$9,7,FALSE) -> #N/A | Z22: =VLOOKUP($B22,$S$3:$AA$9,8,FALSE) -> #N/A | AA22: =VLOOKUP($B22,$S$3:$AA$9,9,FALSE) -> #N/A
S23: =B23 -> 0 | T23: =VLOOKUP($B23,$S$3:$Y$9,2,FALSE) -> #N/A | U23: =VLOOKUP($B23,$S$3:$Y$9,3,FALSE) -> #N/A | V23: =VLOOKUP($B23,$S$3:$Y$9,4,FALSE) -> #N/A | W23: =VLOOKUP($B23,$S$3:$Y$9,5,FALSE) -> #N/A | X23: =VLOOKUP($B23,$S$3:$Y$9,6,FALSE) -> #N/A | Y23: =VLOOKUP($B23,$S$3:$Y$9,7,FALSE) -> #N/A | Z23: =VLOOKUP($B23,$S$3:$AA$9,8,FALSE) -> #N/A | AA23: =VLOOKUP($B23,$S$3:$AA$9,9,FALSE) -> #N/A
S24: =B24 -> 0 | T24: =VLOOKUP($B24,$S$3:$Y$9,2,FALSE) -> #N/A | U24: =VLOOKUP($B24,$S$3:$Y$9,3,FALSE) -> #N/A | V24: =VLOOKUP($B24,$S$3:$Y$9,4,FALSE) -> #N/A | W24: =VLOOKUP($B24,$S$3:$Y$9,5,FALSE) -> #N/A | X24: =VLOOKUP($B24,$S$3:$Y$9,6,FALSE) -> #N/A | Y24: =VLOOKUP($B24,$S$3:$Y$9,7,FALSE) -> #N/A | Z24: =VLOOKUP($B24,$S$3:$AA$9,8,FALSE) -> #N/A | AA24: =VLOOKUP($B24,$S$3:$AA$9,9,FALSE) -> #N/A
S25: =B25 -> 0 | T25: =VLOOKUP($B25,$S$3:$Y$9,2,FALSE) -> #N/A | U25: =VLOOKUP($B25,$S$3:$Y$9,3,FALSE) -> #N/A | V25: =VLOOKUP($B25,$S$3:$Y$9,4,FALSE) -> #N/A | W25: =VLOOKUP($B25,$S$3:$Y$9,5,FALSE) -> #N/A | X25: =VLOOKUP($B25,$S$3:$Y$9,6,FALSE) -> #N/A | Y25: =VLOOKUP($B25,$S$3:$Y$9,7,FALSE) -> #N/A | Z25: =VLOOKUP($B25,$S$3:$AA$9,8,FALSE) -> #N/A | AA25: =VLOOKUP($B25,$S$3:$AA$9,9,FALSE) -> #N/A
S26: =B26 -> 0 | T26: =VLOOKUP($B26,$S$3:$Y$9,2,FALSE) -> #N/A | U26: =VLOOKUP($B26,$S$3:$Y$9,3,FALSE) -> #N/A | V26: =VLOOKUP($B26,$S$3:$Y$9,4,FALSE) -> #N/A | W26: =VLOOKUP($B26,$S$3:$Y$9,5,FALSE) -> #N/A | X26: =VLOOKUP($B26,$S$3:$Y$9,6,FALSE) -> #N/A | Y26: =VLOOKUP($B26,$S$3:$Y$9,7,FALSE) -> #N/A | Z26: =VLOOKUP($B26,$S$3:$AA$9,8,FALSE) -> #N/A | AA26: =VLOOKUP($B26,$S$3:$AA$9,9,FALSE) -> #N/A
... S50: =B50 -> 0 | T50: =VLOOKUP($B50,$S$3:$Y$9,2,FALSE) -> #N/A | U50: =VLOOKUP($B50,$S$3:$Y$9,3,FALSE) -> #N/A | V50: =VLOOKUP($B50,$S$3:$Y$9,4,FALSE) -> #N/A | W50: =VLOOKUP($B50,$S$3:$Y$9,5,FALSE) -> #N/A | X50: =VLOOKUP($B50,$S$3:$Y$9,6,FALSE) -> #N/A | Y50: =VLOOKUP($B50,$S$3:$Y$9,7,FALSE) -> #N/A | Z50: =VLOOKUP($B50,$S$3:$AA$9,8,FALSE) -> #N/A | AA50: =VLOOKUP($B50,$S$3:$AA$9,9,FALSE) -> #N/A
I51: EXTRACT RECOVERY
B52: BRAND | D52: BBT P.G./ O.G | I52: Brand | J52: Actual | K52: MTD No. of Brews | L52: MTD | M52: YTD | N52: Target
B53: CARIB | C53: {=[22]Process!$D$132:$D$135} -> 11.6 | D53: 11.76 | I53: CARIB | J53: =AVERAGE(I10:I14) -> 93.462413 | K53: =COUNTA([22]Brewhouse!$A$173:$A$174) -> 2 | L53: =AVERAGE([22]Brewhouse!$AU$173:$AU$179) -> 93.325407 | M53: =AVERAGE([22]Brewhouse!$AU$102:$AU$171,[22]Brewhouse!$AU$173:$AU$179) -> 94.46235 | N53: 98
C54: 11.9 | I54: STAG | M54: =AVERAGE([24]Brewhouse!$AS$15:$AS$64) -> 96.077332 | N54: 98
C55: 12 | D55: 11.73 | I55: GUINNESS | K55: =COUNTA([23]Brewhouse!$A$9:$A$14) -> 6 | L55: =AVERAGE([23]Brewhouse!$AU$9:$AU$14) -> 96.577361 | M55: =AVERAGE([23]Brewhouse!$AU$4:$AU$7,[23]Brewhouse!$AU$9:$AU$14) -> 96.787192 | N55: 98
C56: 11.8 | I56: VITAMALT | M56: =AVERAGE([25]Brewhouse!$AV$5:$AV$14) -> 97.717673 | N56: 98
C57: {=[22]Process!$D$140:$D$143} -> 12 | D57: 11.69 | I57: MAXIMALT | N57: 98
C58: 11.9 | I58: MACKESON | M58: =AVERAGE([26]Brewhouse!$AT$4:$AT$11) -> 94.812617 | N58: 98
C59: 11.6 | D59: 11.86 | I59: STARMALT | M59: =AVERAGE([27]Brewhouse!$AY$6:$AY$13) -> 93.094806 | N59: 98
C60: 11.9 | I60: HR- Pils | M60: =AVERAGE([28]Brewhouse!$AU$5:$AU$8) -> 91.006888 | N60: 98
I61: HR- IPA
I62: HR- APA | N62: 98
K63: =SUM(K53:K62) -> 8 | L63: =((L53*K53)+(L54*K54)+(L55*K55)+(L56*K56)+(L57*K57)+(K60*L60)+(L58*K58)+(L59*K59)+(L62*K62))/(K63) -> 95.764373 | M63: =L63 -> 95.764373 | N63: 98
...

Sheet Feb 5th
T1: P.G. | V1: Hot Time | X1: Process Time | Z1: Cooling Time
B2: Brewing Department Daily Process Loss Report | T2: Lower | U2: Upper | V2: Lower | W2: Upper | X2: Lower | Y2: Upper | Z2: Lower | AA2: Upper
S3: CARIB | T3: 11.6 | U3: 12 | V3: 0 | W3: 0.11805556 | X3: 0.22569444 | Y3: 0.26388889 | Z3: 0 | AA3: 60 | AC3: HR- PISNER
B4: Date: | C4: 45693 | J4: LOT WORT COLOUR: 3.5 | M4: Filter Sheets (Target 20 days) | S4: STAG | T4: 11.6 | U4: 12 | V4: 0 | W4: 0.11805556 | X4: 0.22569444 | Y4: 0.26388889 | Z4: 0 | AA4: 60
M5: Double | N5: Single | S5: GUINNESS | T5: 17 | U5: 17.5 | V5: 0 | W5: 0.10763889 | X5: 0.24652778 | Y5: 0.28472222 | Z5: 0 | AA5: 60
J6: MALT LOT: Lot 24 | L6: Sheet Day | M6: 15 | N6: 15 | S6: MACKESON | T6: 13.3 | U6: 13.5 | V6: 0 | W6: 0.12905093 | X6: 0.27430556 | Y6: 0.30208333 | Z6: 0
S7: STARMALT | T7: 17.1 | U7: 17.5 | V7: 0 | W7: 0.13605324 | X7: 0.27430556 | Y7: 0.30902778 | Z7: 0 | AA7: 60
B8: Brand | C8: Brew no. | D8: Kett. Hls | E8: Wort | F8: Cool Time(Mins) | G8: Cast. P.G. (Lab Result) | H8: Cast P.G. (Cellar Operator)-gravity | I8: Extr. Rec (80.9%) | J8: Theor. Extr. (77.5%) | K8: Boil Off /Vol. (4-6%) | L8: Boil Time | M8: Total Hot | N8: Brewing | O8: Operator | P8: Comments | Q8: Actual Pilsen Malt | S8: Hurricane Reef | T8: 16.6 | U8: 17 | V8: 0 | W8: 0.12905093 | X8: 0.27430556 | Y8: 0.30208333 | Z8: 0
E9: Meter (Hls) | F9: Target(< 60Mins) | M9: Time | S9: VITAMALT | T9: 14.4 | U9: 14.6 | V9: 0 | W9: 0.13905093 | X9: 0.26041667 | Y9: 0.29513889 | Z9: 0 | AA9: 75
B10: CARIB | C10: =[22]Brewhouse!$A180 -> CA078 | D10: =[22]Brewhouse!$AF180 -> 53.1 | E10: =[22]Brewhouse!$AI180 -> 50 | F10: =[22]Brewhouse!$V180 -> 65 | G10: =[22]Brewhouse!$AG180 -> 11.9 | H10: 11.7 | I10: =[22]Brewhouse!$AU180 -> 95.023431 | J10: =[22]Brewhouse!$AV180 -> 99.016423 | K10: =[22]Brewhouse!$Q180 -> 6.5107914 | L10: =[22]Brewhouse!$P180 -> 60 | M10: =[22]Brewhouse!$U180-[22]Brewhouse!$T180 -> 0.21527778 | N10: =[22]Brewhouse!$Z180 -> 0.29236111 | O10: =[22]Brewhouse!$AX180 -> K.Benjamin | S10: =B10 -> CARIB | T10: =VLOOKUP($B10,$S$3:$Y$9,2,FALSE) -> 11.6 | U10: =VLOOKUP($B10,$S$3:$Y$9,3,FALSE) -> 12 | V10: =VLOOKUP($B10,$S$3:$Y$9,4,FALSE) -> 0 | W10: =VLOOKUP($B10,$S$3:$Y$9,5,FALSE) -> 0.11805556 | X10: =VLOOKUP($B10,$S$3:$Y$9,6,FALSE) -> 0.22569444 | Y10: =VLOOKUP($B10,$S$3:$Y$9,7,FALSE) -> 0.26388889 | Z10: =VLOOKUP($B10,$S$3:$AA$9,8,FALSE) -> 0 | AA10: =VLOOKUP($B10,$S$3:$AA$9,9,FALSE) -> 60
B11: CARIB | C11: =[22]Brewhouse!$A181 -> CA079 | D11: =[22]Brewhouse!$AF181 -> 50 | E11: =[22]Brewhouse!$AI181 -> 47 | F11: =[22]Brewhouse!$V181 -> 63 | G11: =[22]Brewhouse!$AG181 -> 11.8 | H11: 11.6 | I11: =[22]Brewhouse!$AU181 -> 88.206051 | J11: =[22]Brewhouse!$AV181 -> 91.913171 | K11: =[22]Brewhouse!$Q181 -> 6.9512195 | L11: =[22]Brewhouse!$P181 -> 60 | M11: =[22]Brewhouse!$U181-[22]Brewhouse!$T181 -> 0.21041667 | N11: =[22]Brewhouse!$Z181 -> 0.28333333 | O11: =[22]Brewhouse!$AX181 -> R. Regis | S11: =B11 -> CARIB | T11: =VLOOKUP($B11,$S$3:$Y$9,2,FALSE) -> 11.6 | U11: =VLOOKUP($B11,$S$3:$Y$9,3,FALSE) -> 12 | V11: =VLOOKUP($B11,$S$3:$Y$9,4,FALSE) -> 0 | W11: =VLOOKUP($B11,$S$3:$Y$9,5,FALSE) -> 0.11805556 | X11: =VLOOKUP($B11,$S$3:$Y$9,6,FALSE) -> 0.22569444 | Y11: =VLOOKUP($B11,$S$3:$Y$9,7,FALSE) -> 0.26388889 | Z11: =VLOOKUP($B11,$S$3:$AA$9,8,FALSE) -> 0 | AA11: =VLOOKUP($B11,$S$3:$AA$9,9,FALSE) -> 60
B12: CARIB | C12: =[22]Brewhouse!$A182 -> CA080 | D12: =[22]Brewhouse!$AF182 -> 55.4 | E12: =[22]Brewhouse!$AI182 -> 52.1 | F12: =[22]Brewhouse!$V182 -> 73 | G12: =[22]Brewhouse!$AG182 -> 11.9 | H12: 11.7 | I12: =[22]Brewhouse!$AU182 -> 98.770467 | J12: =[22]Brewhouse!$AV182 -> 102.92136 | K12: =[22]Brewhouse!$Q182 -> 5.3641208 | L12: =[22]Brewhouse!$P182 -> 60 | M12: =[22]Brewhouse!$U182-[22]Brewhouse!$T182 -> 0.19791667 | N12: =[22]Brewhouse!$Z182 -> 0.27638889 | O12: =[22]Brewhouse!$AX182 -> R. Regis | S12: =B12 -> CARIB | T12: =VLOOKUP($B12,$S$3:$Y$9,2,FALSE) -> 11.6 | U12: =VLOOKUP($B12,$S$3:$Y$9,3,FALSE) -> 12 | V12: =VLOOKUP($B12,$S$3:$Y$9,4,FALSE) -> 0 | W12: =VLOOKUP($B12,$S$3:$Y$9,5,FALSE) -> 0.11805556 | X12: =VLOOKUP($B12,$S$3:$Y$9,6,FALSE) -> 0.22569444 | Y12: =VLOOKUP($B12,$S$3:$Y$9,7,FALSE) -> 0.26388889 | Z12: =VLOOKUP($B12,$S$3:$AA$9,8,FALSE) -> 0 | AA12: =VLOOKUP($B12,$S$3:$AA$9,9,FALSE) -> 60
S13: =B13 -> 0 | T13: =VLOOKUP($B13,$S$3:$Y$9,2,FALSE) -> #N/A | U13: =VLOOKUP($B13,$S$3:$Y$9,3,FALSE) -> #N/A | V13: =VLOOKUP($B13,$S$3:$Y$9,4,FALSE) -> #N/A | W13: =VLOOKUP($B13,$S$3:$Y$9,5,FALSE) -> #N/A | X13: =VLOOKUP($B13,$S$3:$Y$9,6,FALSE) -> #N/A | Y13: =VLOOKUP($B13,$S$3:$Y$9,7,FALSE) -> #N/A | Z13: =VLOOKUP($B13,$S$3:$AA$9,8,FALSE) -> #N/A | AA13: =VLOOKUP($B13,$S$3:$AA$9,9,FALSE) -> #N/A
B14: STAG | C14: =[24]Brewhouse!$A66 -> ST051 | D14: =[24]Brewhouse!$AD66 -> 52.1 | E14: =[24]Brewhouse!$AG66 -> 48.5 | F14: =[24]Brewhouse!$V66 -> 61 | G14: =[24]Brewhouse!$AE66 -> 11.8 | H14: 11.8 | I14: =[24]Brewhouse!$AS66 -> 92.002637 | J14: =[24]Brewhouse!$AT66 -> 95.21242 | K14: =[24]Brewhouse!$Q66 -> 7.3126143 | L14: =[24]Brewhouse!$P66 -> 60 | M14: =[24]Brewhouse!$U66-[24]Brewhouse!$T66 -> 0.18819444 | N14: =[24]Brewhouse!$AW66 -> 0.25763889 | O14: =[24]Brewhouse!$AV66 -> R. Regis | S14: =B14 -> STAG | T14: =VLOOKUP($B14,$S$3:$Y$9,2,FALSE) -> 11.6 | U14: =VLOOKUP($B14,$S$3:$Y$9,3,FALSE) -> 12 | V14: =VLOOKUP($B14,$S$3:$Y$9,4,FALSE) -> 0 | W14: =VLOOKUP($B14,$S$3:$Y$9,5,FALSE) -> 0.11805556 | X14: =VLOOKUP($B14,$S$3:$Y$9,6,FALSE) -> 0.22569444 | Y14: =VLOOKUP($B14,$S$3:$Y$9,7,FALSE) -> 0.26388889 | Z14: =VLOOKUP($B14,$S$3:$AA$9,8,FALSE) -> 0 | AA14: =VLOOKUP($B14,$S$3:$AA$9,9,FALSE) -> 60
B15: STAG | C15: =[24]Brewhouse!$A67 -> ST052 | D15: =[24]Brewhouse!$AD67 -> 53 | E15: =[24]Brewhouse!$AG67 -> 49.6 | F15: =[24]Brewhouse!$V67 -> 61 | G15: =[24]Brewhouse!$AE67 -> 12 | H15: 11.8 | I15: =[24]Brewhouse!$AS67 -> 95.885985 | J15: =[24]Brewhouse!$AT67 -> 99.230186 | K15: =[24]Brewhouse!$Q67 -> 6.6666667 | L15: =[24]Brewhouse!$P67 -> 57 | M15: =[24]Brewhouse!$U67-[24]Brewhouse!$T67 -> 0.17916667 | N15: =[24]Brewhouse!$AW67 -> 0.25486111 | O15: =[24]Brewhouse!$AV67 -> R.Sookram | S15: =B15 -> STAG | T15: =VLOOKUP($B15,$S$3:$Y$9,2,FALSE) -> 11.6 | U15: =VLOOKUP($B15,$S$3:$Y$9,3,FALSE) -> 12 | V15: =VLOOKUP($B15,$S$3:$Y$9,4,FALSE) -> 0 | W15: =VLOOKUP($B15,$S$3:$Y$9,5,FALSE) -> 0.11805556 | X15: =VLOOKUP($B15,$S$3:$Y$9,6,FALSE) -> 0.22569444 | Y15: =VLOOKUP($B15,$S$3:$Y$9,7,FALSE) -> 0.26388889 | Z15: =VLOOKUP($B15,$S$3:$AA$9,8,FALSE) -> 0 | AA15: =VLOOKUP($B15,$S$3:$AA$9,9,FALSE) -> 60
B16: STAG | C16: =[24]Brewhouse!$A68 -> ST053 | D16: =[24]Brewhouse!$AD68 -> 53.2 | E16: =[24]Brewhouse!$AG68 -> 49.9 | F16: =[24]Brewhouse!$V68 -> 60 | G16: =[24]Brewhouse!$AE68 -> 11.8 | H16: 11.8 | I16: =[24]Brewhouse!$AS68 -> 95.012867 | J16: =[24]Brewhouse!$AT68 -> 98.324501 | K16: =[24]Brewhouse!$Q68 -> 5.7301294 | L16: =[24]Brewhouse!$P68 -> 57 | M16: =[24]Brewhouse!$U68-[24]Brewhouse!$T68 -> 0.18125 | N16: =[24]Brewhouse!$AW68 -> 0.2625 | O16: =[24]Brewhouse!$AV68 -> R.Sookram | S16: =B16 -> STAG | T16: =VLOOKUP($B16,$S$3:$Y$9,2,FALSE) -> 11.6 | U16: =VLOOKUP($B16,$S$3:$Y$9,3,FALSE) -> 12 | V16: =VLOOKUP($B16,$S$3:$Y$9,4,FALSE) -> 0 | W16: =VLOOKUP($B16,$S$3:$Y$9,5,FALSE) -> 0.11805556 | X16: =VLOOKUP($B16,$S$3:$Y$9,6,FALSE) -> 0.22569444 | Y16: =VLOOKUP($B16,$S$3:$Y$9,7,FALSE) -> 0.26388889 | Z16: =VLOOKUP($B16,$S$3:$AA$9,8,FALSE) -> 0 | AA16: =VLOOKUP($B16,$S$3:$AA$9,9,FALSE) -> 60
B17: STAG | C17: =[24]Brewhouse!$A69 -> ST054 | D17: =[24]Brewhouse!$AD69 -> 53.1 | E17: =[24]Brewhouse!$AG69 -> 49.7 | F17: =[24]Brewhouse!$V69 -> 62 | G17: =[24]Brewhouse!$AE69 -> 11.9 | H17: 11.8 | I17: =[24]Brewhouse!$AS69 -> 95.834501 | J17: =[24]Brewhouse!$AT69 -> 99.171553 | K17: =[24]Brewhouse!$Q69 -> 3.4155598 | L17: =[24]Brewhouse!$P69 -> 59 | M17: =[24]Brewhouse!$U69-[24]Brewhouse!$T69 -> 0.17777778 | N17: =[24]Brewhouse!$AW69 -> 0.26527778 | O17: =[24]Brewhouse!$AV69 -> R.Sookram | S17: =B17 -> STAG | T17: =VLOOKUP($B17,$S$3:$Y$9,2,FALSE) -> 11.6 | U17: =VLOOKUP($B17,$S$3:$Y$9,3,FALSE) -> 12 | V17: =VLOOKUP($B17,$S$3:$Y$9,4,FALSE) -> 0 | W17: =VLOOKUP($B17,$S$3:$Y$9,5,FALSE) -> 0.11805556 | X17: =VLOOKUP($B17,$S$3:$Y$9,6,FALSE) -> 0.22569444 | Y17: =VLOOKUP($B17,$S$3:$Y$9,7,FALSE) -> 0.26388889 | Z17: =VLOOKUP($B17,$S$3:$AA$9,8,FALSE) -> 0 | AA17: =VLOOKUP($B17,$S$3:$AA$9,9,FALSE) -> 60
B18: STAG | C18: =[24]Brewhouse!$A70 -> ST055 | D18: =[24]Brewhouse!$AD70 -> 53.2 | E18: =[24]Brewhouse!$AG70 -> 50.2 | F18: =[24]Brewhouse!$V70 -> 79 | G18: =[24]Brewhouse!$AE70 -> 11.8 | H18: 11.8 | I18: =[24]Brewhouse!$AS70 -> 95.943382 | J18: =[24]Brewhouse!$AT70 -> 99.284226 | K18: =[24]Brewhouse!$Q70 -> 6.0773481 | L18: =[24]Brewhouse!$P70 -> 60 | M18: =[24]Brewhouse!$U70-[24]Brewhouse!$T70 -> 0.21041667 | N18: =[24]Brewhouse!$AW70 -> 0.2875 | O18: =[24]Brewhouse!$AV70 -> K. Benjamin | S18: =B18 -> STAG | T18: =VLOOKUP($B18,$S$3:$Y$9,2,FALSE) -> 11.6 | U18: =VLOOKUP($B18,$S$3:$Y$9,3,FALSE) -> 12 | V18: =VLOOKUP($B18,$S$3:$Y$9,4,FALSE) -> 0 | W18: =VLOOKUP($B18,$S$3:$Y$9,5,FALSE) -> 0.11805556 | X18: =VLOOKUP($B18,$S$3:$Y$9,6,FALSE) -> 0.22569444 | Y18: =VLOOKUP($B18,$S$3:$Y$9,7,FALSE) -> 0.26388889 | Z18: =VLOOKUP($B18,$S$3:$AA$9,8,FALSE) -> 0 | AA18: =VLOOKUP($B18,$S$3:$AA$9,9,FALSE) -> 60
S19: =B19 -> 0 | T19: =VLOOKUP($B19,$S$3:$Y$9,2,FALSE) -> #N/A | U19: =VLOOKUP($B19,$S$3:$Y$9,3,FALSE) -> #N/A | V19: =VLOOKUP($B19,$S$3:$Y$9,4,FALSE) -> #N/A | W19: =VLOOKUP($B19,$S$3:$Y$9,5,FALSE) -> #N/A | X19: =VLOOKUP($B19,$S$3:$Y$9,6,FALSE) -> #N/A | Y19: =VLOOKUP($B19,$S$3:$Y$9,7,FALSE) -> #N/A | Z19: =VLOOKUP($B19,$S$3:$AA$9,8,FALSE) -> #N/A | AA19: =VLOOKUP($B19,$S$3:$AA$9,9,FALSE) -> #N/A
S20: =B20 -> 0 | T20: =VLOOKUP($B20,$S$3:$Y$9,2,FALSE) -> #N/A | U20: =VLOOKUP($B20,$S$3:$Y$9,3,FALSE) -> #N/A | V20: =VLOOKUP($B20,$S$3:$Y$9,4,FALSE) -> #N/A | W20: =VLOOKUP($B20,$S$3:$Y$9,5,FALSE) -> #N/A | X20: =VLOOKUP($B20,$S$3:$Y$9,6,FALSE) -> #N/A | Y20: =VLOOKUP($B20,$S$3:$Y$9,7,FALSE) -> #N/A | Z20: =VLOOKUP($B20,$S$3:$AA$9,8,FALSE) -> #N/A | AA20: =VLOOKUP($B20,$S$3:$AA$9,9,FALSE) -> #N/A
S21: =B21 -> 0 | T21: =VLOOKUP($B21,$S$3:$Y$9,2,FALSE) -> #N/A | U21: =VLOOKUP($B21,$S$3:$Y$9,3,FALSE) -> #N/A | V21: =VLOOKUP($B21,$S$3:$Y$9,4,FALSE) -> #N/A | W21: =VLOOKUP($B21,$S$3:$Y$9,5,FALSE) -> #N/A | X21: =VLOOKUP($B21,$S$3:$Y$9,6,FALSE) -> #N/A | Y21: =VLOOKUP($B21,$S$3:$Y$9,7,FALSE) -> #N/A | Z21: =VLOOKUP($B21,$S$3:$AA$9,8,FALSE) -> #N/A | AA21: =VLOOKUP($B21,$S$3:$AA$9,9,FALSE) -> #N/A
S22: =B22 -> 0 | T22: =VLOOKUP($B22,$S$3:$Y$9,2,FALSE) -> #N/A | U22: =VLOOKUP($B22,$S$3:$Y$9,3,FALSE) -> #N/A | V22: =VLOOKUP($B22,$S$3:$Y$9,4,FALSE) -> #N/A | W22: =VLOOKUP($B22,$S$3:$Y$9,5,FALSE) -> #N/A | X22: =VLOOKUP($B22,$S$3:$Y$9,6,FALSE) -> #N/A | Y22: =VLOOKUP($B22,$S$3:$Y$9,7,FALSE) -> #N/A | Z22: =VLOOKUP($B22,$S$3:$AA$9,8,FALSE) -> #N/A | AA22: =VLOOKUP($B22,$S$3:$AA$9,9,FALSE) -> #N/A
S23: =B23 -> 0 | T23: =VLOOKUP($B23,$S$3:$Y$9,2,FALSE) -> #N/A | U23: =VLOOKUP($B23,$S$3:$Y$9,3,FALSE) -> #N/A | V23: =VLOOKUP($B23,$S$3:$Y$9,4,FALSE) -> #N/A | W23: =VLOOKUP($B23,$S$3:$Y$9,5,FALSE) -> #N/A | X23: =VLOOKUP($B23,$S$3:$Y$9,6,FALSE) -> #N/A | Y23: =VLOOKUP($B23,$S$3:$Y$9,7,FALSE) -> #N/A | Z23: =VLOOKUP($B23,$S$3:$AA$9,8,FALSE) -> #N/A | AA23: =VLOOKUP($B23,$S$3:$AA$9,9,FALSE) -> #N/A
S24: =B24 -> 0 | T24: =VLOOKUP($B24,$S$3:$Y$9,2,FALSE) -> #N/A | U24: =VLOOKUP($B24,$S$3:$Y$9,3,FALSE) -> #N/A | V24: =VLOOKUP($B24,$S$3:$Y$9,4,FALSE) -> #N/A | W24: =VLOOKUP($B24,$S$3:$Y$9,5,FALSE) -> #N/A | X24: =VLOOKUP($B24,$S$3:$Y$9,6,FALSE) -> #N/A | Y24: =VLOOKUP($B24,$S$3:$Y$9,7,FALSE) -> #N/A | Z24: =VLOOKUP($B24,$S$3:$AA$9,8,FALSE) -> #N/A | AA24: =VLOOKUP($B24,$S$3:$AA$9,9,FALSE) -> #N/A
S25: =B25 -> 0 | T25: =VLOOKUP($B25,$S$3:$Y$9,2,FALSE) -> #N/A | U25: =VLOOKUP($B25,$S$3:$Y$9,3,FALSE) -> #N/A | V25: =VLOOKUP($B25,$S$3:$Y$9,4,FALSE) -> #N/A | W25: =VLOOKUP($B25,$S$3:$Y$9,5,FALSE) -> #N/A | X25: =VLOOKUP($B25,$S$3:$Y$9,6,FALSE) -> #N/A | Y25: =VLOOKUP($B25,$S$3:$Y$9,7,FALSE) -> #N/A | Z25: =VLOOKUP($B25,$S$3:$AA$9,8,FALSE) -> #N/A | AA25: =VLOOKUP($B25,$S$3:$AA$9,9,FALSE) -> #N/A
S26: =B26 -> 0 | T26: =VLOOKUP($B26,$S$3:$Y$9,2,FALSE) -> #N/A | U26: =VLOOKUP($B26,$S$3:$Y$9,3,FALSE) -> #N/A | V26: =VLOOKUP($B26,$S$3:$Y$9,4,FALSE) -> #N/A | W26: =VLOOKUP($B26,$S$3:$Y$9,5,FALSE) -> #N/A | X26: =VLOOKUP($B26,$S$3:$Y$9,6,FALSE) -> #N/A | Y26: =VLOOKUP($B26,$S$3:$Y$9,7,FALSE) -> #N/A | Z26: =VLOOKUP($B26,$S$3:$AA$9,8,FALSE) -> #N/A | AA26: =VLOOKUP($B26,$S$3:$AA$9,9,FALSE) -> #N/A
S27: =B27 -> 0 | T27: =VLOOKUP($B27,$S$3:$Y$9,2,FALSE) -> #N/A | U27: =VLOOKUP($B27,$S$3:$Y$9,3,FALSE) -> #N/A | V27: =VLOOKUP($B27,$S$3:$Y$9,4,FALSE) -> #N/A | W27: =VLOOKUP($B27,$S$3:$Y$9,5,FALSE) -> #N/A | X27: =VLOOKUP($B27,$S$3:$Y$9,6,FALSE) -> #N/A | Y27: =VLOOKUP($B27,$S$3:$Y$9,7,FALSE) -> #N/A | Z27: =VLOOKUP($B27,$S$3:$AA$9,8,FALSE) -> #N/A | AA27: =VLOOKUP($B27,$S$3:$AA$9,9,FALSE) -> #N/A
S28: =B28 -> 0 | T28: =VLOOKUP($B28,$S$3:$Y$9,2,FALSE) -> #N/A | U28: =VLOOKUP($B28,$S$3:$Y$9,3,FALSE) -> #N/A | V28: =VLOOKUP($B28,$S$3:$Y$9,4,FALSE) -> #N/A | W28: =VLOOKUP($B28,$S$3:$Y$9,5,FALSE) -> #N/A | X28: =VLOOKUP($B28,$S$3:$Y$9,6,FALSE) -> #N/A | Y28: =VLOOKUP($B28,$S$3:$Y$9,7,FALSE) -> #N/A | Z28: =VLOOKUP($B28,$S$3:$AA$9,8,FALSE) -> #N/A | AA28: =VLOOKUP($B28,$S$3:$AA$9,9,FALSE) -> #N/A
S29: =B29 -> 0 | T29: =VLOOKUP($B29,$S$3:$Y$9,2,FALSE) -> #N/A | U29: =VLOOKUP($B29,$S$3:$Y$9,3,FALSE) -> #N/A | V29: =VLOOKUP($B29,$S$3:$Y$9,4,FALSE) -> #N/A | W29: =VLOOKUP($B29,$S$3:$Y$9,5,FALSE) -> #N/A | X29: =VLOOKUP($B29,$S$3:$Y$9,6,FALSE) -> #N/A | Y29: =VLOOKUP($B29,$S$3:$Y$9,7,FALSE) -> #N/A | Z29: =VLOOKUP($B29,$S$3:$AA$9,8,FALSE) -> #N/A | AA29: =VLOOKUP($B29,$S$3:$AA$9,9,FALSE) -> #N/A
S30: =B30 -> 0 | T30: =VLOOKUP($B30,$S$3:$Y$9,2,FALSE) -> #N/A | U30: =VLOOKUP($B30,$S$3:$Y$9,3,FALSE) -> #N/A | V30: =VLOOKUP($B30,$S$3:$Y$9,4,FALSE) -> #N/A | W30: =VLOOKUP($B30,$S$3:$Y$9,5,FALSE) -> #N/A | X30: =VLOOKUP($B30,$S$3:$Y$9,6,FALSE) -> #N/A | Y30: =VLOOKUP($B30,$S$3:$Y$9,7,FALSE) -> #N/A | Z30: =VLOOKUP($B30,$S$3:$AA$9,8,FALSE) -> #N/A | AA30: =VLOOKUP($B30,$S$3:$AA$9,9,FALSE) -> #N/A
... S50: =B50 -> 0 | T50: =VLOOKUP($B50,$S$3:$Y$9,2,FALSE) -> #N/A | U50: =VLOOKUP($B50,$S$3:$Y$9,3,FALSE) -> #N/A | V50: =VLOOKUP($B50,$S$3:$Y$9,4,FALSE) -> #N/A | W50: =VLOOKUP($B50,$S$3:$Y$9,5,FALSE) -> #N/A | X50: =VLOOKUP($B50,$S$3:$Y$9,6,FALSE) -> #N/A | Y50: =VLOOKUP($B50,$S$3:$Y$9,7,FALSE) -> #N/A | Z50: =VLOOKUP($B50,$S$3:$AA$9,8,FALSE) -> #N/A | AA50: =VLOOKUP($B50,$S$3:$AA$9,9,FALSE) -> #N/A
I51: EXTRACT RECOVERY
B52: BRAND | D52: BBT P.G./ O.G | I52: Brand | J52: Actual | K52: MTD No. of Brews | L52: MTD | M52: YTD | N52: Target
I53: CARIB | J53: =AVERAGE(I10:I12) -> 93.999983 | K53: =COUNTA([22]Brewhouse!$A$173:$A$182) -> 10 | L53: =AVERAGE([22]Brewhouse!$AU$173:$AU$182) -> 93.52778 | M53: =AVERAGE([22]Brewhouse!$AU$102:$AU$171,[22]Brewhouse!$AU$173:$AU$182) -> 94.445011 | N53: 98
I54: STAG | J54: =AVERAGE(I14:I18) -> 94.935874 | K54: =COUNTA([24]Brewhouse!$A$66:$A$70) -> 5 | L54: =AVERAGE([24]Brewhouse!$AS$66:$AS$70) -> 94.935874 | M54: =AVERAGE([24]Brewhouse!$AS$15:$AS$64,[24]Brewhouse!$AS$66:$AS$70) -> 95.973563 | N54: 98
I55: GUINNESS | K55: =COUNTA([23]Brewhouse!$A$9:$A$14) -> 6 | L55: =AVERAGE([23]Brewhouse!$AU$9:$AU$14) -> 96.577361 | M55: =AVERAGE([23]Brewhouse!$AU$4:$AU$7,[23]Brewhouse!$AU$9:$AU$14) -> 96.787192 | N55: 98
I56: VITAMALT | M56: =AVERAGE([25]Brewhouse!$AV$5:$AV$14) -> 97.717673 | N56: 98
B57: =I55 -> GUINNESS | C57: {=[23]Process!$D$16:$D$19} -> 17.7 | D57: 16.77 | I57: MAXIMALT | N57: 98
C58: 17.5 | I58: MACKESON | M58: =AVERAGE([26]Brewhouse!$AT$4:$AT$11) -> 94.812617 | N58: 98
C59: 17.6 | D59: 17.3 | I59: STARMALT | M59: =AVERAGE([27]Brewhouse!$AY$6:$AY$13) -> 93.094806 | N59: 98
...

Sheet Feb 6th
T1: P.G. | V1: Hot Time | X1: Process Time | Z1: Cooling Time
B2: Brewing Department Daily Process Loss Report | T2: Lower | U2: Upper | V2: Lower | W2: Upper | X2: Lower | Y2: Upper | Z2: Lower | AA2: Upper
S3: CARIB | T3: 11.6 | U3: 12 | V3: 0 | W3: 0.11805556 | X3: 0.22569444 | Y3: 0.26388889 | Z3: 0 | AA3: 60 | AC3: HR- PISNER
B4: Date: | C4: 45694 | J4: LOT WORT COLOUR: 3.5 | M4: Filter Sheets (Target 20 days) | S4: STAG | T4: 11.6 | U4: 12 | V4: 0 | W4: 0.11805556 | X4: 0.22569444 | Y4: 0.26388889 | Z4: 0 | AA4: 60
M5: Double | N5: Single | S5: GUINNESS | T5: 17 | U5: 17.5 | V5: 0 | W5: 0.10763889 | X5: 0.24652778 | Y5: 0.28472222 | Z5: 0 | AA5: 60
J6: MALT LOT: Lot 24 | L6: Sheet Day | M6: 15 | N6: 15 | S6: MACKESON | T6: 13.3 | U6: 13.5 | V6: 0 | W6: 0.12905093 | X6: 0.27430556 | Y6: 0.30208333 | Z6: 0
S7: STARMALT | T7: 17.1 | U7: 17.5 | V7: 0 | W7: 0.13605324 | X7: 0.27430556 | Y7: 0.30902778 | Z7: 0 | AA7: 60
B8: Brand | C8: Brew no. | D8: Kett. Hls | E8: Wort | F8: Cool Time(Mins) | G8: Cast. P.G. (Lab Result) | H8: Cast P.G. (Cellar Operator)-gravity | I8: Extr. Rec (80.9%) | J8: Theor. Extr. (77.5%) | K8: Boil Off /Vol. (4-6%) | L8: Boil Time | M8: Total Hot | N8: Brewing | O8: Operator | P8: Comments | Q8: Actual Pilsen Malt | S8: Hurricane Reef | T8: 16.6 | U8: 17 | V8: 0 | W8: 0.12905093 | X8: 0.27430556 | Y8: 0.30208333 | Z8: 0
E9: Meter (Hls) | F9: Target(< 60Mins) | M9: Time | S9: VITAMALT | T9: 14.4 | U9: 14.6 | V9: 0 | W9: 0.13905093 | X9: 0.26041667 | Y9: 0.29513889 | Z9: 0 | AA9: 75
B10: STAG | C10: =[24]Brewhouse!$A71 -> ST056 | D10: =[24]Brewhouse!$AD71 -> 54.2 | E10: =[24]Brewhouse!$AG71 -> 51.2 | F10: =[24]Brewhouse!$V71 -> 68 | G10: =[24]Brewhouse!$AE71 -> 11.7 | H10: 11.5 | I10: =[24]Brewhouse!$AS71 -> 96.860954 | J10: =[24]Brewhouse!$AT71 -> 100.23484 | K10: =[24]Brewhouse!$Q71 -> 4.7272727 | L10: =[24]Brewhouse!$P71 -> 61 | M10: =[24]Brewhouse!$U71-[24]Brewhouse!$T71 -> 0.19027778 | N10: =[24]Brewhouse!$AW71 -> 0.25694444 | O10: =[24]Brewhouse!$AV71 -> K. Benjamin
B11: STAG | C11: =[24]Brewhouse!$A72 -> ST057 | D11: =[24]Brewhouse!$AD72 -> 53.2 | E11: =[24]Brewhouse!$AG72 -> 50 | F11: =[24]Brewhouse!$V72 -> 66 | G11: =[24]Brewhouse!$AE72 -> 11.9 | H11: 11.9 | I11: =[24]Brewhouse!$AS72 -> 96.412979 | J11: =[24]Brewhouse!$AT72 -> 99.770174 | K11: =[24]Brewhouse!$Q72 -> 5.5454545 | L11: =[24]Brewhouse!$P72 -> 59 | M11: =[24]Brewhouse!$U72-[24]Brewhouse!$T72 -> 0.12083333 | N11: =[24]Brewhouse!$AW72 -> 0.26597222 | O11: =[24]Brewhouse!$AV72 -> K. Benjamin | S11: =B11 -> STAG | T11: =VLOOKUP($B11,$S$3:$Y$9,2,FALSE) -> 11.6 | U11: =VLOOKUP($B11,$S$3:$Y$9,3,FALSE) -> 12 | V11: =VLOOKUP($B11,$S$3:$Y$9,4,FALSE) -> 0 | W11: =VLOOKUP($B11,$S$3:$Y$9,5,FALSE) -> 0.11805556 | X11: =VLOOKUP($B11,$S$3:$Y$9,6,FALSE) -> 0.22569444 | Y11: =VLOOKUP($B11,$S$3:$Y$9,7,FALSE) -> 0.26388889 | Z11: =VLOOKUP($B11,$S$3:$AA$9,8,FALSE) -> 0 | AA11: =VLOOKUP($B11,$S$3:$AA$9,9,FALSE) -> 60
B12: STAG | C12: =[24]Brewhouse!$A73 -> ST058 | D12: =[24]Brewhouse!$AD73 -> 53.4 | E12: =[24]Brewhouse!$AG73 -> 50.3 | F12: =[24]Brewhouse!$V73 -> 60 | G12: =[24]Brewhouse!$AE73 -> 11.8 | H12: 11.9 | I12: =[24]Brewhouse!$AS73 -> 96.134504 | J12: =[24]Brewhouse!$AT73 -> 99.482003 | K12: =[24]Brewhouse!$Q73 -> 4.7186933 | L12: =[24]Brewhouse!$P73 -> 60 | M12: =[24]Brewhouse!$U73-[24]Brewhouse!$T73 -> 0.12361111 | N12: =[24]Brewhouse!$AW73 -> 0.25902778 | O12: =[24]Brewhouse!$AV73 -> R.Regis | S12: =B12 -> STAG | T12: =VLOOKUP($B12,$S$3:$Y$9,2,FALSE) -> 11.6 | U12: =VLOOKUP($B12,$S$3:$Y$9,3,FALSE) -> 12 | V12: =VLOOKUP($B12,$S$3:$Y$9,4,FALSE) -> 0 | W12: =VLOOKUP($B12,$S$3:$Y$9,5,FALSE) -> 0.11805556 | X12: =VLOOKUP($B12,$S$3:$Y$9,6,FALSE) -> 0.22569444 | Y12: =VLOOKUP($B12,$S$3:$Y$9,7,FALSE) -> 0.26388889 | Z12: =VLOOKUP($B12,$S$3:$AA$9,8,FALSE) -> 0 | AA12: =VLOOKUP($B12,$S$3:$AA$9,9,FALSE) -> 60
S13: =B13 -> 0 | T13: =VLOOKUP($B13,$S$3:$Y$9,2,FALSE) -> #N/A | U13: =VLOOKUP($B13,$S$3:$Y$9,3,FALSE) -> #N/A | V13: =VLOOKUP($B13,$S$3:$Y$9,4,FALSE) -> #N/A | W13: =VLOOKUP($B13,$S$3:$Y$9,5,FALSE) -> #N/A | X13: =VLOOKUP($B13,$S$3:$Y$9,6,FALSE) -> #N/A | Y13: =VLOOKUP($B13,$S$3:$Y$9,7,FALSE) -> #N/A | Z13: =VLOOKUP($B13,$S$3:$AA$9,8,FALSE) -> #N/A | AA13: =VLOOKUP($B13,$S$3:$AA$9,9,FALSE) -> #N/A
B14: CARIB | C14: =[22]Brewhouse!$A183 -> CA081 | D14: =[22]Brewhouse!$AF183 -> 53.8 | E14: =[22]Brewhouse!$AI183 -> 50.1 | F14: =[22]Brewhouse!$V183 -> 72 | G14: =[22]Brewhouse!$AG183 -> 11.6 | H14: 11.7 | I14: =[22]Brewhouse!$AU183 -> 92.689747 | J14: =[22]Brewhouse!$AV183 -> 96.584676 | K14: =[22]Brewhouse!$Q183 -> 5.3832442 | L14: =[22]Brewhouse!$P183 -> 60 | M14: =[22]Brewhouse!$U183-[22]Brewhouse!$T183 -> 0.12569444 | N14: =[22]Brewhouse!$Z183 -> 0.26736111 | O14: =[22]Brewhouse!$AX183 -> R. Regis | S14: =B14 -> CARIB | T14: =VLOOKUP($B14,$S$3:$Y$9,2,FALSE) -> 11.6 | U14: =VLOOKUP($B14,$S$3:$Y$9,3,FALSE) -> 12 | V14: =VLOOKUP($B14,$S$3:$Y$9,4,FALSE) -> 0 | W14: =VLOOKUP($B14,$S$3:$Y$9,5,FALSE) -> 0.11805556 | X14: =VLOOKUP($B14,$S$3:$Y$9,6,FALSE) -> 0.22569444 | Y14: =VLOOKUP($B14,$S$3:$Y$9,7,FALSE) -> 0.26388889 | Z14: =VLOOKUP($B14,$S$3:$AA$9,8,FALSE) -> 0 | AA14: =VLOOKUP($B14,$S$3:$AA$9,9,FALSE) -> 60
