Workbook

Sheet Entries Feb.'25
B1: ENTRIES FOR DAILY CONS. MONITOR | P1: =B1 -> ENTRIES FOR DAILY CONS. MONITOR
C2: old | F2: old | P2: Service 227.3 cubic meters (2273 Hls)Filtered 189.3 cubic meters(1893 Hls)
D3: FUEL | J3: ELECT. | L3: CO2 | P3: WATER | AH3: CO2 Scrubber (m3) | AI3: Supply to Washdown Area (m3) | AJ3: Supply to RUs (m3) | AK3: Steam Mass Flow Meter | AL3: CO2 TANKS' READING
B4: Boilers tot. | C4: Boiler 1 | D4: Gen. meter | E4: Tank level | F4: Boiler 1 | G4: Boiler 2 | H4: Gen | I4: Meter1 | J4: Meter 2 | K4: Gen Meter | L4: Collection | M4: Consumption | N4: Consumption (Filler) (kg) | P4: Nawasa Meter (m3) | Q4: Annandale Supply (m3) | R4: Service Supply to Plant (m3) | S4: Cellars/Filtration (m3) | T4: Brewhouse Meter (m3) | U4: Cellars/Process Areas (m3) | V4: Pasteuriser (m3) | W4: Water Plant-Nawasa Annadale (m3) | X4: Water Plant-Well # 1 (m3) | Y4: CIP Process | Z4: Bottle Washer | AA4: Boiler | AB4: Permeate #1 | AC4: Permeate #2 | AD4: Bottle Filler (m3) | AE4: RO # 1 Totaliser (m3) | AF4: RO # 2 Totaliser (m3) | AG4: Recovered Water (m3) | AL4: (Kg.) | AM4: ` | AN4: (Lbs.) | AO4: (Kg.)
A5: DATE | B5: (l) | C5: (l) | D5: (Imp. gals) | E5: (inches) | F5: Hrs | G5: Hrs | H5: Hrs. | I5: (Kwhr) | J5: (Kwhr) | K5: (Kwhr) | L5: Meter (kg) | M5: Meter (kg) | O5: DATE | Y5: (m3) | Z5: (m3) | AA5: (m3) | AL5: Tank "A" | AM5: Tank "B" | AN5: Mobile Tanker | AO5: Inside Tank
A6: - | S6: 5140
A7: 1 | B7: 7160920 | E7: 70 | F7: 2366.4 | G7: 68208 | I7: 212780 | J7: 791664 | K7: 466400 | N7: 262.89 | O7: 1 | P7: 166764 | Q7: 3348 | R7: 885472 | T7: 30820 | V7: 20538 | W7: 1280318 | Y7: 30060 | Z7: 27709 | AA7: 4869 | AB7: 97122 | AD7: 38942 | AE7: 258494 | AK7: 7258604.7
A8: 2 | B8: 7161120 | E8: 70 | F8: 2367.7 | G8: 68208 | I8: 216276 | J8: 794023 | K8: 466400 | N8: 262.89 | O8: 2 | P8: 166764 | Q8: 3603 | R8: 885492 | T8: 30820 | V8: 20538 | W8: 1280318 | Y8: 30060 | Z8: 27742 | AA8: 4910 | AB8: 97122 | AD8: 38942 | AE8: 258494 | AK8: 7258604.7
A9: 3 | B9: 7161880 | E9: 70 | F9: 2372 | G9: 68208 | I9: 217568 | J9: 796191 | K9: 466400 | N9: 262.89 | O9: 3 | P9: 166766 | Q9: 3682 | R9: 885575 | T9: 30820 | V9: 20538 | W9: 1280670 | Y9: 30060 | Z9: 27744 | AA9: 4928 | AB9: 97122 | AD9: 38942 | AE9: 258494 | AK9: 7258604.7
A10: 4 | B10: 7164980 | E10: 70 | F10: 2393.9 | G10: 68208 | I10: 221617 | J10: 800017 | K10: 466400 | N10: 292.23 | O10: 4 | P10: 166838 | Q10: 3870 | R10: 885824 | T10: 31018 | V10: 20545 | W10: 1280867 | Y10: 30139 | Z10: 27825 | AA10: 4988 | AB10: 97122 | AD10: 38969 | AE10: 258494 | AK10: 7258886.6
A11: 5 | B11: 7168010 | E11: 70 | F11: 2413.4 | G11: 68208 | I11: 225604 | J11: 803786 | K11: 466400 | N11: 335.28 | O11: 5 | P11: 166991 | Q11: 4077 | R11: 886034 | T11: 31199 | V11: 20548 | W11: 1281086 | Y11: 30183 | Z11: 27895 | AA11: 5039 | AB11: 97122 | AD11: 38993 | AE11: 258494 | AK11: 7258886.6
A12: 6 | B12: 7171410 | E12: 70 | F12: 2435.7 | G12: 68208 | I12: 229962 | J12: 807905 | K12: 466400 | N12: 376 | O12: ='Entries Feb.''25'!A12 -> 6 | P12: 167279 | Q12: 4219 | R12: 886287 | T12: 31477 | V12: 20553 | W12: 1281235 | Y12: 30244 | Z12: 27986 | AA12: 5081 | AB12: 97122 | AD12: 39017 | AE12: 258494 | AK12: 7258886.6
A13: 7 | B13: 7174330 | E13: 70 | F13: 2456.2 | G13: 68208 | I13: 233971 | J13: 811693 | K13: 466400 | N13: 380.39 | O13: ='Entries Feb.''25'!A13 -> 7 | P13: 167426 | Q13: 4432 | R13: 886495 | T13: 31695 | V13: 20553 | W13: 1281459 | Y13: 30295 | Z13: 28046 | AA13: 5113 | AB13: 97122 | AD13: 39037 | AE13: 258494 | AK13: 7258887.2
A14: 8 | B14: 7174330 | E14: 70 | F14: 2456.2 | G14: 68208 | I14: 235871 | J14: 813490 | K14: 466400 | N14: 380.39 | O14: ='Entries Feb.''25'!A14 -> 8 | P14: 167725 | Q14: 4432 | R14: 886507 | T14: 31695 | V14: 20553 | W14: 1281459 | Y14: 30295 | Z14: 28046 | AA14: 5113 | AB14: 97122 | AD14: 39037 | AE14: 258494 | AK14: 7258887.2
A15: 9 | B15: 7174740 | E15: 70 | F15: 2459.9 | G15: 68209 | I15: 238265 | J15: 815755 | K15: 466400 | N15: 380.39 | O15: ='Entries Feb.''25'!A15 -> 9 | P15: 167780 | Q15: 4432 | R15: 886579 | T15: 31700 | V15: 20553 | W15: 1281495 | Y15: 30295 | Z15: 28046 | AA15: 5121 | AB15: 97122 | AD15: 39037 | AE15: 258494 | AK15: 7258887.2
A16: 10 | B16: 7175840 | E16: 70 | F16: 2467 | G16: 68209 | I16: 241040 | J16: 818387 | K16: 466400 | N16: 380.39 | O16: ='Entries Feb.''25'!A16 -> 10 | P16: 167897 | Q16: 4432 | R16: 886597 | T16: 31700 | V16: 20553 | W16: 1281495 | Y16: 30295 | Z16: 28078 | AA16: 5129 | AB16: 97122 | AD16: 39037 | AE16: 258494 | AK16: 7258923.6
A17: 11 | B17: 7178550 | E17: 70 | F17: 2485 | G17: 68209 | I17: 244511 | J17: 821671 | K17: 466400 | N17: 400.39 | O17: ='Entries Feb.''25'!A17 -> 11 | P17: 168104 | Q17: 4538 | R17: 886820 | T17: 31885 | V17: 20567 | W17: 1281570 | Y17: 30360 | Z17: 28153 | AA17: 5151 | AB17: 97122 | AD17: 39060 | AE17: 258494 | AK17: 7258937
A18: 12 | B18: 7181770 | E18: 70 | F18: 2505.9 | G18: 68209 | I18: 248842 | J18: 825769 | K18: 466400 | N18: 434.97 | O18: ='Entries Feb.''25'!A18 -> 12 | P18: 168260 | Q18: 4756 | R18: 887095 | T18: 32150 | V18: 20577 | W18: 1281800 | Y18: 30415 | Z18: 28250 | AA18: 5178 | AB18: 97122 | AD18: 39086 | AE18: 258494 | AK18: 7258954.9
A19: 13 | B19: 7185050 | E19: 70 | F19: 2526.6 | G19: 68209 | I19: 253095 | J19: 829789 | K19: 466400 | N19: 466.37 | O19: ='Entries Feb.''25'!A19 -> 13 | P19: 168537 | Q19: 4924 | R19: 887294 | T19: 32365 | V19: 20577 | W19: 1281977 | Y19: 30444 | Z19: 28336 | AA19: 5209 | AB19: 97122 | AD19: 39110 | AE19: 258494 | AK19: 7258954.9
A20: 14 | B20: 7188620 | E20: 70 | F20: 2548.9 | G20: 68209 | I20: 257441 | J20: 833895 | K20: 466400 | N20: 503.51 | O20: ='Entries Feb.''25'!A20 -> 14 | P20: 168708 | Q20: 5180 | R20: 887530 | T20: 32623 | V20: 20582 | W20: 1282247 | Y20: 30506 | Z20: 28421 | AA20: 5237 | AB20: 97122 | AD20: 39133 | AE20: 258494 | AK20: 7258954.9
A21: 15 | B21: 7191430 | E21: 70 | F21: 2568.4 | G21: 68209 | I21: 261216 | J21: 837460 | K21: 466400 | N21: 526.71 | O21: ='Entries Feb.''25'!A21 -> 15 | P21: 168922 | Q21: 5436 | R21: 887699 | T21: 32832 | V21: 20586 | W21: 1282516 | Y21: 30544 | Z21: 28478 | AA21: 5259 | AB21: 97122 | AD21: 39150 | AE21: 258494 | AK21: 7258954.9
A22: 16 | B22: 7191810 | E22: 70 | F22: 2572.1 | G22: 68209 | I22: 263327 | J22: 839449 | K22: 466400 | N22: 526.71 | O22: ='Entries Feb.''25'!A22 -> 16 | P22: 168922 | Q22: 5626 | R22: 887760 | T22: 32832 | V22: 20586 | W22: 1282716 | Y22: 30544 | Z22: 28501 | AA22: 5267 | AB22: 97122 | AD22: 39152 | AE22: 258494 | AK22: 7258954.9
A23: 17 | B23: 7192460 | E23: 70 | F23: 2577.3 | G23: 68209 | I23: 265516 | J23: 841516 | K23: 466400 | N23: 526.71 | O23: ='Entries Feb.''25'!A23 -> 17 | P23: 168972 | Q23: 5626 | R23: 887786 | T23: 32832 | V23: 20586 | W23: 1282716 | Y23: 30546 | Z23: 28508 | AA23: 5278 | AB23: 97122 | AD23: 39152 | AE23: 258496 | AK23: 7258954.9
... A34: 28 | B34: 7220330 | E34: 70 | F34: 2772.4 | G34: 68209 | I34: 308594 | J34: 882226 | K34: 466400 | N34: 694 | O34: ='Entries Feb.''25'!A34 -> 28 | P34: 170538 | Q34: 7748 | R34: 889677 | T34: 34865 | V34: 20633 | W34: 1284954 | Y34: 31006 | Z34: 29106 | AA34: 5476 | AB34: 97122 | AD34: 39320 | AE34: 258781 | AK34: 7266613
A35: 29 | B35: 7222980 | E35: 70 | F35: 2791 | G35: 68209 | I35: 312699 | J35: 886109 | K35: 466400 | N35: 710 | O35: 29 | P35: 170538 | Q35: 8010 | R35: 889883 | T35: 35099 | V35: 20636 | W35: 1285230 | Y35: 31073 | Z35: 29173 | AA35: 5490 | AB35: 97122 | AD35: 39340 | AE35: 258781 | AK35: 7266613
A36: 1 | O36: ='Entries Feb.''25'!A36 -> 1
A37: 2 | O37: ='Entries Feb.''25'!A37 -> 2
A38: 3 | O38: ='Entries Feb.''25'!A38 -> 3
B39: =B35-B7 -> 62060 | C39: =C35-C7 -> 0 | D39: =D35-D7 -> 0 | E39: =E35-E7 -> 0 | F39: =F35-F7 -> 424.6 | G39: =G35-G7 -> 1 | H39: =H35-H7 -> 0 | I39: =I35-I7 -> 99919 | ... AO39: =AO35-AO7 -> 0
B40: =B16-B12 -> 4430 | C40: =C16-C13 -> 0
K42: =J42+I42 -> 0
I47: =I31-I30 -> 4040 | J47: =J31-J30 -> 3817
N50: 2339980.8
N51: 2339980.8
N52: 2354366.5
N53: 2373680.2

Sheet Utility Analysis Feb. 2025
D2: GRENADA BREWERIES LIMITED
D3: UTILITY ANALYSIS
A5: MONTH: | C5: 39295
A7: DATE | B7: ELECTRICITY | C7: WATER | D7: FUEL | E7: CO2 | F7: PRODUCTION - HL | K7: UTILITY RATIOS
K8: Elect | L8: Water | M8: Fuel | N8: CO2 | O8: Comments
B9: USAGE (kwh) | C9: USAGE (Hl) | D9: USAGE (l) | E9: USAGE (Kg.) | F9: BREWED | G9: BOTTLED | H9: KEGS | I9: OTHER | J9: TOTAL | K9: KWH/Hl | L9: Hl/hl | M9: Litres/hl | N9: kg./Hl
A10: 1 | B10: =IF(('Entries Feb.''25'!I8-'Entries Feb.''25'!I7)+('Entries Feb.''25'!J8-'Entries Feb.''25'!J7)<1,"0",('Entries Feb.''25'!I8-'Entries Feb.''25'!I7)+('Entries Feb.''25'!J8-'Entries Feb.''25'!J7)) -> 5855 | C10: ='Water '!$R$7 -> 2550 | D10: =IF('Entries Feb.''25'!B8-'Entries Feb.''25'!B7<1,"0",'Entries Feb.''25'!B8-'Entries Feb.''25'!B7) -> 200 | E10: ='Co2 '!B7 -> 0 | F10: =+'PROD.FIG. '!F5 -> 0 | G10: =+'PROD.FIG. '!C5 -> 0 | H10: =+'PROD.FIG. '!D5 -> 0 | I10: =+'PROD.FIG. '!E5 -> 0 | K10: =IF(SUM($G10:$H10)<1,0,B10/SUM($G10:$H10)) -> 0 | L10: =IF(SUM($G10:$H10)<1,0,C10/SUM($G10:$H10)) -> 0 | M10: =IF(SUM($G10:$H10)<1,0,D10/SUM($G10:$H10)) -> 0 | N10: =IF(SUM($G10:$H10)<1,0,E10/SUM($G10:$H10)) -> 0
A11: 2 | B11: =IF(('Entries Feb.''25'!I9-'Entries Feb.''25'!I8)+('Entries Feb.''25'!J9-'Entries Feb.''25'!J8)<1,"0",('Entries Feb.''25'!I9-'Entries Feb.''25'!I8)+('Entries Feb.''25'!J9-'Entries Feb.''25'!J8)) -> 3460 | C11: ='Water '!$R$8 -> -2710 | D11: =IF('Entries Feb.''25'!B9-'Entries Feb.''25'!B8<1,"0",'Entries Feb.''25'!B9-'Entries Feb.''25'!B8) -> 760 | E11: ='Co2 '!B8 -> 0 | F11: =+'PROD.FIG. '!F6 -> 0 | G11: =+'PROD.FIG. '!C6 -> 0 | H11: =+'PROD.FIG. '!D6 -> 0 | I11: =+'PROD.FIG. '!E6 -> 0 | K11: =IF(SUM($G11:$H11)<1,0,B11/SUM($G11:$H11)) -> 0 | L11: =IF(SUM($G11:$H11)<1,0,C11/SUM($G11:$H11)) -> 0 | M11: =IF(SUM($G11:$H11)<1,0,D11/SUM($G11:$H11)) -> 0 | N11: =IF(SUM($G11:$H11)<1,0,E11/SUM($G11:$H11)) -> 0
A12: 3 | B12: =IF(('Entries Feb.''25'!I10-'Entries Feb.''25'!I9)+('Entries Feb.''25'!J10-'Entries Feb.''25'!J9)<1,"0",('Entries Feb.''25'!I10-'Entries Feb.''25'!I9)+('Entries Feb.''25'!J10-'Entries Feb.''25'!J9)) -> 7875 | C12: ='Water '!$R$9 -> 630 | D12: =IF('Entries Feb.''25'!B10-'Entries Feb.''25'!B9<1,"0",'Entries Feb.''25'!B10-'Entries Feb.''25'!B9) -> 3100 | E12: ='Co2 '!B9 -> 29.34 | F12: =+'PROD.FIG. '!F7 -> 0 | G12: =+'PROD.FIG. '!C7 -> 0 | H12: =+'PROD.FIG. '!D7 -> 0 | I12: =+'PROD.FIG. '!E7 -> 0 | K12: =IF(SUM($G12:$H12)<1,0,B12/SUM($G12:$H12)) -> 0 | L12: =IF(SUM($G12:$H12)<1,0,C12/SUM($G12:$H12)) -> 0 | M12: =IF(SUM($G12:$H12)<1,0,D12/SUM($G12:$H12)) -> 0 | N12: =IF(SUM($G12:$H12)<1,0,E12/SUM($G12:$H12)) -> 0
A13: 4 | B13: =IF(('Entries Feb.''25'!I11-'Entries Feb.''25'!I10)+('Entries Feb.''25'!J11-'Entries Feb.''25'!J10)<1,"0",('Entries Feb.''25'!I11-'Entries Feb.''25'!I10)+('Entries Feb.''25'!J11-'Entries Feb.''25'!J10)) -> 7756 | C13: ='Water '!$R$10 -> 1410 | D13: =IF('Entries Feb.''25'!B11-'Entries Feb.''25'!B10<1,"0",'Entries Feb.''25'!B11-'Entries Feb.''25'!B10) -> 3030 | E13: ='Co2 '!B10 -> 43.05 | F13: =+'PROD.FIG. '!F8 -> 0 | G13: =+'PROD.FIG. '!C8 -> 0 | H13: =+'PROD.FIG. '!D8 -> 0 | I13: =+'PROD.FIG. '!E8 -> 0 | K13: =IF(SUM($G13:$H13)<1,0,B13/SUM($G13:$H13)) -> 0 | L13: =IF(SUM($G13:$H13)<1,0,C13/SUM($G13:$H13)) -> 0 | M13: =IF(SUM($G13:$H13)<1,0,D13/SUM($G13:$H13)) -> 0 | N13: =IF(SUM($G13:$H13)<1,0,E13/SUM($G13:$H13)) -> 0
A14: 5 | B14: =IF(('Entries Feb.''25'!I12-'Entries Feb.''25'!I11)+('Entries Feb.''25'!J12-'Entries Feb.''25'!J11)<1,"0",('Entries Feb.''25'!I12-'Entries Feb.''25'!I11)+('Entries Feb.''25'!J12-'Entries Feb.''25'!J11)) -> 8477 | C14: ='Water '!$R$11 -> 2810 | D14: =IF('Entries Feb.''25'!B12-'Entries Feb.''25'!B11<1,"0",'Entries Feb.''25'!B12-'Entries Feb.''25'!B11) -> 3400 | E14: ='Co2 '!B11 -> 40.72 | F14: =+'PROD.FIG. '!F9 -> 0 | G14: =+'PROD.FIG. '!C9 -> 0 | H14: =+'PROD.FIG. '!D9 -> 0 | I14: =+'PROD.FIG. '!E9 -> 0 | K14: =IF(SUM($G14:$H14)<1,0,B14/SUM($G14:$H14)) -> 0 | L14: =IF(SUM($G14:$H14)<1,0,C14/SUM($G14:$H14)) -> 0 | M14: =IF(SUM($G14:$H14)<1,0,D14/SUM($G14:$H14)) -> 0 | N14: =IF(SUM($G14:$H14)<1,0,E14/SUM($G14:$H14)) -> 0
A15: 6 | B15: =IF(('Entries Feb.''25'!I13-'Entries Feb.''25'!I12)+('Entries Feb.''25'!J13-'Entries Feb.''25'!J12)<1,"0",('Entries Feb.''25'!I13-'Entries Feb.''25'!I12)+('Entries Feb.''25'!J13-'Entries Feb.''25'!J12)) -> 7797 | C15: ='Water '!$R$12 -> 1360 | D15: =IF('Entries Feb.''25'!B13-'Entries Feb.''25'!B12<1,"0",'Entries Feb.''25'!B13-'Entries Feb.''25'!B12) -> 2920 | E15: ='Co2 '!B12 -> 4.39 | F15: =+'PROD.FIG. '!F10 -> 0 | G15: =+'PROD.FIG. '!C10 -> 0 | H15: =+'PROD.FIG. '!D10 -> 0 | I15: =+'PROD.FIG. '!E10 -> 0 | K15: =IF(SUM($G15:$H15)<1,0,B15/SUM($G15:$H15)) -> 0 | L15: =IF(SUM($G15:$H15)<1,0,C15/SUM($G15:$H15)) -> 0 | M15: =IF(SUM($G15:$H15)<1,0,D15/SUM($G15:$H15)) -> 0 | N15: =IF(SUM($G15:$H15)<1,0,E15/SUM($G15:$H15)) -> 0
A16: 7 | B16: =IF(('Entries Feb.''25'!I14-'Entries Feb.''25'!I13)+('Entries Feb.''25'!J14-'Entries Feb.''25'!J13)<1,"0",('Entries Feb.''25'!I14-'Entries Feb.''25'!I13)+('Entries Feb.''25'!J14-'Entries Feb.''25'!J13)) -> 3697 | C16: ='Water '!$R$13 -> 2990 | D16: =IF('Entries Feb.''25'!B14-'Entries Feb.''25'!B13<1,"0",'Entries Feb.''25'!B14-'Entries Feb.''25'!B13) -> 0 | E16: ='Co2 '!B13 -> 0 | F16: =+'PROD.FIG. '!F11 -> 0 | G16: =+'PROD.FIG. '!C11 -> 0 | H16: =+'PROD.FIG. '!D11 -> 0 | I16: =+'PROD.FIG. '!E11 -> 0 | K16: =IF(SUM($G16:$H16)<1,0,B16/SUM($G16:$H16)) -> 0 | L16: =IF(SUM($G16:$H16)<1,0,C16/SUM($G16:$H16)) -> 0 | M16: =IF(SUM($G16:$H16)<1,0,D16/SUM($G16:$H16)) -> 0 | N16: =IF(SUM($G16:$H16)<1,0,E16/SUM($G16:$H16)) -> 0
A17: 8 | B17: =IF(('Entries Feb.''25'!I15-'Entries Feb.''25'!I14)+('Entries Feb.''25'!J15-'Entries Feb.''25'!J14)<1,"0",('Entries Feb.''25'!I15-'Entries Feb.''25'!I14)+('Entries Feb.''25'!J15-'Entries Feb.''25'!J14)) -> 4659 | C17: ='Water '!$R$14 -> 190 | D17: =IF('Entries Feb.''25'!B15-'Entries Feb.''25'!B14<1,"0",'Entries Feb.''25'!B15-'Entries Feb.''25'!B14) -> 410 | E17: ='Co2 '!B14 -> 0 | F17: =+'PROD.FIG. '!F12 -> 0 | G17: =+'PROD.FIG. '!C12 -> 0 | H17: =+'PROD.FIG. '!D12 -> 0 | I17: =+'PROD.FIG. '!E12 -> 0 | K17: =IF(SUM($G17:$H17)<1,0,B17/SUM($G17:$H17)) -> 0 | L17: =IF(SUM($G17:$H17)<1,0,C17/SUM($G17:$H17)) -> 0 | M17: =IF(SUM($G17:$H17)<1,0,D17/SUM($G17:$H17)) -> 0 | N17: =IF(SUM($G17:$H17)<1,0,E17/SUM($G17:$H17)) -> 0
A18: 9 | B18: =IF(('Entries Feb.''25'!I16-'Entries Feb.''25'!I15)+('Entries Feb.''25'!J16-'Entries Feb.''25'!J15)<1,"0",('Entries Feb.''25'!I16-'Entries Feb.''25'!I15)+('Entries Feb.''25'!J16-'Entries Feb.''25'!J15)) -> 5407 | C18: ='Water '!$R$15 -> 1170 | D18: =IF('Entries Feb.''25'!B16-'Entries Feb.''25'!B15<1,"0",'Entries Feb.''25'!B16-'Entries Feb.''25'!B15) -> 1100 | E18: ='Co2 '!B15 -> 0 | F18: =+'PROD.FIG. '!F13 -> 0 | G18: =+'PROD.FIG. '!C13 -> 0 | H18: =+'PROD.FIG. '!D13 -> 0 | I18: =+'PROD.FIG. '!E13 -> 0 | K18: =IF(SUM($G18:$H18)<1,0,B18/SUM($G18:$H18)) -> 0 | L18: =IF(SUM($G18:$H18)<1,0,C18/SUM($G18:$H18)) -> 0 | M18: =IF(SUM($G18:$H18)<1,0,D18/SUM($G18:$H18)) -> 0 | N18: =IF(SUM($G18:$H18)<1,0,E18/SUM($G18:$H18)) -> 0
A19: 10 | B19: =IF(('Entries Feb.''25'!I17-'Entries Feb.''25'!I16)+('Entries Feb.''25'!J17-'Entries Feb.''25'!J16)<1,"0",('Entries Feb.''25'!I17-'Entries Feb.''25'!I16)+('Entries Feb.''25'!J17-'Entries Feb.''25'!J16)) -> 6755 | C19: ='Water '!$R$16 -> 2380 | D19: =IF('Entries Feb.''25'!B17-'Entries Feb.''25'!B16<1,"0",'Entries Feb.''25'!B17-'Entries Feb.''25'!B16) -> 2710 | E19: ='Co2 '!B16 -> 20 | F19: =+'PROD.FIG. '!F14 -> 0 | G19: =+'PROD.FIG. '!C14 -> 0 | H19: =+'PROD.FIG. '!D14 -> 0 | I19: =+'PROD.FIG. '!E14 -> 0 | K19: =IF(SUM($G19:$H19)<1,0,B19/SUM($G19:$H19)) -> 0 | L19: =IF(SUM($G19:$H19)<1,0,C19/SUM($G19:$H19)) -> 0 | M19: =IF(SUM($G19:$H19)<1,0,D19/SUM($G19:$H19)) -> 0 | N19: =IF(SUM($G19:$H19)<1,0,E19/SUM($G19:$H19)) -> 0
A20: 11 | B20: =IF(('Entries Feb.''25'!I18-'Entries Feb.''25'!I17)+('Entries Feb.''25'!J18-'Entries Feb.''25'!J17)<1,"0",('Entries Feb.''25'!I18-'Entries Feb.''25'!I17)+('Entries Feb.''25'!J18-'Entries Feb.''25'!J17)) -> 8429 | C20: ='Water '!$R$17 -> 1440 | D20: =IF('Entries Feb.''25'!B18-'Entries Feb.''25'!B17<1,"0",'Entries Feb.''25'!B18-'Entries Feb.''25'!B17) -> 3220 | E20: ='Co2 '!B17 -> 34.58 | F20: =+'PROD.FIG. '!F15 -> 0 | G20: =+'PROD.FIG. '!C15 -> 0 | H20: =+'PROD.FIG. '!D15 -> 0 | I20: =+'PROD.FIG. '!E15 -> 0 | K20: =IF(SUM($G20:$H20)<1,0,B20/SUM($G20:$H20)) -> 0 | L20: =IF(SUM($G20:$H20)<1,0,C20/SUM($G20:$H20)) -> 0 | M20: =IF(SUM($G20:$H20)<1,0,D20/SUM($G20:$H20)) -> 0 | N20: =IF(SUM($G20:$H20)<1,0,E20/SUM($G20:$H20)) -> 0
A21: 12 | B21: =IF(('Entries Feb.''25'!I19-'Entries Feb.''25'!I18)+('Entries Feb.''25'!J19-'Entries Feb.''25'!J18)<1,"0",('Entries Feb.''25'!I19-'Entries Feb.''25'!I18)+('Entries Feb.''25'!J19-'Entries Feb.''25'!J18)) -> 8273 | C21: ='Water '!$R$18 -> 2680 | D21: =IF('Entries Feb.''25'!B19-'Entries Feb.''25'!B18<1,"0",'Entries Feb.''25'!B19-'Entries Feb.''25'!B18) -> 3280 | E21: ='Co2 '!B18 -> 31.4 | F21: =+'PROD.FIG. '!F16 -> 0 | G21: =+'PROD.FIG. '!C16 -> 0 | H21: =+'PROD.FIG. '!D16 -> 0 | I21: =+'PROD.FIG. '!E16 -> 0 | K21: =IF(SUM($G21:$H21)<1,0,B21/SUM($G21:$H21)) -> 0 | L21: =IF(SUM($G21:$H21)<1,0,C21/SUM($G21:$H21)) -> 0 | M21: =IF(SUM($G21:$H21)<1,0,D21/SUM($G21:$H21)) -> 0 | N21: =IF(SUM($G21:$H21)<1,0,E21/SUM($G21:$H21)) -> 0
A22: 13 | B22: =IF(('Entries Feb.''25'!I20-'Entries Feb.''25'!I19)+('Entries Feb.''25'!J20-'Entries Feb.''25'!J19)<1,"0",('Entries Feb.''25'!I20-'Entries Feb.''25'!I19)+('Entries Feb.''25'!J20-'Entries Feb.''25'!J19)) -> 8452 | C22: ='Water '!$R$19 -> 1570 | D22: =IF('Entries Feb.''25'!B20-'Entries Feb.''25'!B19<1,"0",'Entries Feb.''25'!B20-'Entries Feb.''25'!B19) -> 3570 | E22: ='Co2 '!B19 -> 37.14 | F22: =+'PROD.FIG. '!F17 -> 0 | G22: =+'PROD.FIG. '!C17 -> 0 | H22: =+'PROD.FIG. '!D17 -> 0 | I22: =+'PROD.FIG. '!E17 -> 0 | K22: =IF(SUM($G22:$H22)<1,0,B22/SUM($G22:$H22)) -> 0 | L22: =IF(SUM($G22:$H22)<1,0,C22/SUM($G22:$H22)) -> 0 | M22: =IF(SUM($G22:$H22)<1,0,D22/SUM($G22:$H22)) -> 0 | N22: =IF(SUM($G22:$H22)<1,0,E22/SUM($G22:$H22)) -> 0
A23: 14 | B23: =IF(('Entries Feb.''25'!I21-'Entries Feb.''25'!I20)+('Entries Feb.''25'!J21-'Entries Feb.''25'!J20)<1,"0",('Entries Feb.''25'!I21-'Entries Feb.''25'!I20)+('Entries Feb.''25'!J21-'Entries Feb.''25'!J20)) -> 7340 | C23: ='Water '!$R$20 -> 2010 | D23: =IF('Entries Feb.''25'!B21-'Entries Feb.''25'!B20<1,"0",'Entries Feb.''25'!B21-'Entries Feb.''25'!B20) -> 2810 | E23: ='Co2 '!B20 -> 23.2 | F23: =+'PROD.FIG. '!F18 -> 0 | G23: =+'PROD.FIG. '!C18 -> 0 | H23: =+'PROD.FIG. '!D18 -> 0 | I23: =+'PROD.FIG. '!E18 -> 0 | K23: =IF(SUM($G23:$H23)<1,0,B23/SUM($G23:$H23)) -> 0 | L23: =IF(SUM($G23:$H23)<1,0,C23/SUM($G23:$H23)) -> 0 | M23: =IF(SUM($G23:$H23)<1,0,D23/SUM($G23:$H23)) -> 0 | N23: =IF(SUM($G23:$H23)<1,0,E23/SUM($G23:$H23)) -> 0
A24: 15 | B24: =IF(('Entries Feb.''25'!I22-'Entries Feb.''25'!I21)+('Entries Feb.''25'!J22-'Entries Feb.''25'!J21)<1,"0",('Entries Feb.''25'!I22-'Entries Feb.''25'!I21)+('Entries Feb.''25'!J22-'Entries Feb.''25'!J21)) -> 4100 | C24: ='Water '!$R$21 -> -100 | D24: =IF('Entries Feb.''25'!B22-'Entries Feb.''25'!B21<1,"0",'Entries Feb.''25'!B22-'Entries Feb.''25'!B21) -> 380 | E24: ='Co2 '!B21 -> 0 | F24: =+'PROD.FIG. '!F19 -> 0 | G24: =+'PROD.FIG. '!C19 -> 0 | H24: =+'PROD.FIG. '!D19 -> 0 | I24: =+'PROD.FIG. '!E19 -> 0 | K24: =IF(SUM($G24:$H24)<1,0,B24/SUM($G24:$H24)) -> 0 | L24: =IF(SUM($G24:$H24)<1,0,C24/SUM($G24:$H24)) -> 0 | M24: =IF(SUM($G24:$H24)<1,0,D24/SUM($G24:$H24)) -> 0 | N24: =IF(SUM($G24:$H24)<1,0,E24/SUM($G24:$H24)) -> 0
A25: 16 | B25: =IF(('Entries Feb.''25'!I23-'Entries Feb.''25'!I22)+('Entries Feb.''25'!J23-'Entries Feb.''25'!J22)<1,"0",('Entries Feb.''25'!I23-'Entries Feb.''25'!I22)+('Entries Feb.''25'!J23-'Entries Feb.''25'!J22)) -> 4256 | C25: ='Water '!$R$22 -> 500 | D25: =IF('Entries Feb.''25'!B23-'Entries Feb.''25'!B22<1,"0",'Entries Feb.''25'!B23-'Entries Feb.''25'!B22) -> 650 | E25: ='Co2 '!B22 -> 0 | F25: =+'PROD.FIG. '!F20 -> 0 | G25: =+'PROD.FIG. '!C20 -> 0 | H25: =+'PROD.FIG. '!D20 -> 0 | I25: =+'PROD.FIG. '!E20 -> 0 | K25: =IF(SUM($G25:$H25)<1,0,B25/SUM($G25:$H25)) -> 0 | L25: =IF(SUM($G25:$H25)<1,0,C25/SUM($G25:$H25)) -> 0 | M25: =IF(SUM($G25:$H25)<1,0,D25/SUM($G25:$H25)) -> 0 | N25: =IF(SUM($G25:$H25)<1,0,E25/SUM($G25:$H25)) -> 0
A26: 17 | B26: =IF(('Entries Feb.''25'!I24-'Entries Feb.''25'!I23)+('Entries Feb.''25'!J24-'Entries Feb.''25'!J23)<1,"0",('Entries Feb.''25'!I24-'Entries Feb.''25'!I23)+('Entries Feb.''25'!J24-'Entries Feb.''25'!J23)) -> 7897 | C26: ='Water '!$R$23 -> 1250 | D26: =IF('Entries Feb.''25'!B24-'Entries Feb.''25'!B23<1,"0",'Entries Feb.''25'!B24-'Entries Feb.''25'!B23) -> 2850 | E26: ='Co2 '!B23 -> 21.09 | F26: =+'PROD.FIG. '!F21 -> 0 | G26: =+'PROD.FIG. '!C21 -> 0 | H26: =+'PROD.FIG. '!D21 -> 0 | I26: =+'PROD.FIG. '!E21 -> 0 | K26: =IF(SUM($G26:$H26)<1,0,B26/SUM($G26:$H26)) -> 0 | L26: =IF(SUM($G26:$H26)<1,0,C26/SUM($G26:$H26)) -> 0 | M26: =IF(SUM($G26:$H26)<1,0,D26/SUM($G26:$H26)) -> 0 | N26: =IF(SUM($G26:$H26)<1,0,E26/SUM($G26:$H26)) -> 0
A27: 18 | B27: =IF(('Entries Feb.''25'!I25-'Entries Feb.''25'!I24)+('Entries Feb.''25'!J25-'Entries Feb.''25'!J24)<1,"0",('Entries Feb.''25'!I25-'Entries Feb.''25'!I24)+('Entries Feb.''25'!J25-'Entries Feb.''25'!J24)) -> 8686 | C27: ='Water '!$R$24 -> 2540 | D27: =IF('Entries Feb.''25'!B25-'Entries Feb.''25'!B24<1,"0",'Entries Feb.''25'!B25-'Entries Feb.''25'!B24) -> 3020 | E27: ='Co2 '!B24 -> 20.29 | F27: =+'PROD.FIG. '!F22 -> 0 | G27: =+'PROD.FIG. '!C22 -> 0 | H27: =+'PROD.FIG. '!D22 -> 0 | I27: =+'PROD.FIG. '!E22 -> 0 | K27: =IF(SUM($G27:$H27)<1,0,B27/SUM($G27:$H27)) -> 0 | L27: =IF(SUM($G27:$H27)<1,0,C27/SUM($G27:$H27)) -> 0 | M27: =IF(SUM($G27:$H27)<1,0,D27/SUM($G27:$H27)) -> 0 | N27: =IF(SUM($G27:$H27)<1,0,E27/SUM($G27:$H27)) -> 0
A28: 19 | B28: =IF(('Entries Feb.''25'!I26-'Entries Feb.''25'!I25)+('Entries Feb.''25'!J26-'Entries Feb.''25'!J25)<1,"0",('Entries Feb.''25'!I26-'Entries Feb.''25'!I25)+('Entries Feb.''25'!J26-'Entries Feb.''25'!J25)) -> 8826 | C28: ='Water '!$R$25 -> 1670 | D28: =IF('Entries Feb.''25'!B26-'Entries Feb.''25'!B25<1,"0",'Entries Feb.''25'!B26-'Entries Feb.''25'!B25) -> 3160 | E28: ='Co2 '!B25 -> 24.34 | F28: =+'PROD.FIG. '!F23 -> 0 | G28: =+'PROD.FIG. '!C23 -> 0 | H28: =+'PROD.FIG. '!D23 -> 0 | I28: =+'PROD.FIG. '!E23 -> 0 | K28: =IF(SUM($G28:$H28)<1,0,B28/SUM($G28:$H28)) -> 0 | L28: =IF(SUM($G28:$H28)<1,0,C28/SUM($G28:$H28)) -> 0 | M28: =IF(SUM($G28:$H28)<1,0,D28/SUM($G28:$H28)) -> 0 | N28: =IF(SUM($G28:$H28)<1,0,E28/SUM($G28:$H28)) -> 0
A29: 20 | B29: =IF(('Entries Feb.''25'!I27-'Entries Feb.''25'!I26)+('Entries Feb.''25'!J27-'Entries Feb.''25'!J26)<1,"0",('Entries Feb.''25'!I27-'Entries Feb.''25'!I26)+('Entries Feb.''25'!J27-'Entries Feb.''25'!J26)) -> 8615 | C29: ='Water '!$R$26 -> 1490 | D29: =IF('Entries Feb.''25'!B27-'Entries Feb.''25'!B26<1,"0",'Entries Feb.''25'!B27-'Entries Feb.''25'!B26) -> 2970 | E29: ='Co2 '!B26 -> 18.44 | F29: =+'PROD.FIG. '!F24 -> 0 | G29: =+'PROD.FIG. '!C24 -> 0 | H29: =+'PROD.FIG. '!D24 -> 0 | I29: =+'PROD.FIG. '!E24 -> 0 | K29: =IF(SUM($G29:$H29)<1,0,B29/SUM($G29:$H29)) -> 0 | L29: =IF(SUM($G29:$H29)<1,0,C29/SUM($G29:$H29)) -> 0 | M29: =IF(SUM($G29:$H29)<1,0,D29/SUM($G29:$H29)) -> 0 | N29: =IF(SUM($G29:$H29)<1,0,E29/SUM($G29:$H29)) -> 0
A30: 21 | B30: =IF(('Entries Feb.''25'!I28-'Entries Feb.''25'!I27)+('Entries Feb.''25'!J28-'Entries Feb.''25'!J27)<1,"0",('Entries Feb.''25'!I28-'Entries Feb.''25'!I27)+('Entries Feb.''25'!J28-'Entries Feb.''25'!J27)) -> 8074 | C30: ='Water '!$R$27 -> 1400 | D30: =IF('Entries Feb.''25'!B28-'Entries Feb.''25'!B27<1,"0",'Entries Feb.''25'!B28-'Entries Feb.''25'!B27) -> 2410 | E30: ='Co2 '!B27 -> 14.92 | F30: =+'PROD.FIG. '!F25 -> 0 | G30: =+'PROD.FIG. '!C25 -> 0 | H30: =+'PROD.FIG. '!D25 -> 0 | I30: =+'PROD.FIG. '!E25 -> 0 | K30: =IF(SUM($G30:$H30)<1,0,B30/SUM($G30:$H30)) -> 0 | L30: =IF(SUM($G30:$H30)<1,0,C30/SUM($G30:$H30)) -> 0 | M30: =IF(SUM($G30:$H30)<1,0,D30/SUM($G30:$H30)) -> 0 | N30: =IF(SUM($G30:$H30)<1,0,E30/SUM($G30:$H30)) -> 0
A31: 22 | B31: =IF(('Entries Feb.''25'!I29-'Entries Feb.''25'!I28)+('Entries Feb.''25'!J29-'Entries Feb.''25'!J28)<1,"0",('Entries Feb.''25'!I29-'Entries Feb.''25'!I28)+('Entries Feb.''25'!J29-'Entries Feb.''25'!J28)) -> 4355 | C31: ='Water '!$R$28 -> 1150 | D31: =IF('Entries Feb.''25'!B29-'Entries Feb.''25'!B28<1,"0",'Entries Feb.''25'!B29-'Entries Feb.''25'!B28) -> 340 | E31: ='Co2 '!B28 -> 0 | F31: =+'PROD.FIG. '!F26 -> 0 | G31: =+'PROD.FIG. '!C26 -> 0 | H31: =+'PROD.FIG. '!D26 -> 0 | I31: =+'PROD.FIG. '!E26 -> 0 | K31: =IF(SUM($G31:$H31)<1,0,B31/SUM($G31:$H31)) -> 0 | L31: =IF(SUM($G31:$H31)<1,0,C31/SUM($G31:$H31)) -> 0 | M31: =IF(SUM($G31:$H31)<1,0,D31/SUM($G31:$H31)) -> 0 | N31: =IF(SUM($G31:$H31)<1,0,E31/SUM($G31:$H31)) -> 0
A32: 23 | B32: =IF(('Entries Feb.''25'!I30-'Entries Feb.''25'!I29)+('Entries Feb.''25'!J30-'Entries Feb.''25'!J29)<1,"0",('Entries Feb.''25'!I30-'Entries Feb.''25'!I29)+('Entries Feb.''25'!J30-'Entries Feb.''25'!J29)) -> 4880 | C32: ='Water '!$R$29 -> -40 | D32: =IF('Entries Feb.''25'!B31-'Entries Feb.''25'!B29<1,"0",'Entries Feb.''25'!B31-'Entries Feb.''25'!B29) -> 4120 | E32: ='Co2 '!B29 -> 0.2 | F32: =+'PROD.FIG. '!F27 -> 0 | G32: =+'PROD.FIG. '!C27 -> 0 | H32: =+'PROD.FIG. '!D27 -> 0 | I32: =+'PROD.FIG. '!E27 -> 0 | K32: =IF(SUM($G32:$H32)<1,0,B32/SUM($G32:$H32)) -> 0 | L32: =IF(SUM($G32:$H32)<1,0,C32/SUM($G32:$H32)) -> 0 | M32: =IF(SUM($G32:$H32)<1,0,D32/SUM($G32:$H32)) -> 0 | N32: =IF(SUM($G32:$H32)<1,0,E32/SUM($G32:$H32)) -> 0
A33: 24 | B33: =IF(('Entries Feb.''25'!I31-'Entries Feb.''25'!I30)+('Entries Feb.''25'!J31-'Entries Feb.''25'!J30)<1,"0",('Entries Feb.''25'!I31-'Entries Feb.''25'!I30)+('Entries Feb.''25'!J31-'Entries Feb.''25'!J30)) -> 7857 | C33: ='Water '!$R$30 -> 320 | D33: =IF('Entries Feb.''25'!B32-'Entries Feb.''25'!B31<1,"0",'Entries Feb.''25'!B32-'Entries Feb.''25'!B31) -> 3250 | E33: ='Co2 '!B30 -> 14.34 | F33: =+'PROD.FIG. '!F28 -> 0 | G33: =+'PROD.FIG. '!C28 -> 0 | H33: =+'PROD.FIG. '!D28 -> 0 | I33: =+'PROD.FIG. '!E28 -> 0 | K33: =IF(SUM($G33:$H33)<1,0,B33/SUM($G33:$H33)) -> 0 | L33: =IF(SUM($G33:$H33)<1,0,C33/SUM($G33:$H33)) -> 0 | M33: =IF(SUM($G33:$H33)<1,0,D33/SUM($G33:$H33)) -> 0 | N33: =IF(SUM($G33:$H33)<1,0,E33/SUM($G33:$H33)) -> 0
A34: 25 | B34: =IF(('Entries Feb.''25'!I32-'Entries Feb.''25'!I31)+('Entries Feb.''25'!J32-'Entries Feb.''25'!J31)<1,"0",('Entries Feb.''25'!I32-'Entries Feb.''25'!I31)+('Entries Feb.''25'!J32-'Entries Feb.''25'!J31)) -> 8306 | C34: ='Water '!$R$31 -> -130 | D34: =IF('Entries Feb.''25'!B33-'Entries Feb.''25'!B32<1,"0",'Entries Feb.''25'!B33-'Entries Feb.''25'!B32) -> 2810 | E34: ='Co2 '!B31 -> 19.01 | F34: =+'PROD.FIG. '!F29 -> 0 | G34: =+'PROD.FIG. '!C29 -> 0 | H34: =+'PROD.FIG. '!D29 -> 0 | I34: =+'PROD.FIG. '!E29 -> 0 | K34: =IF(SUM($G34:$H34)<1,0,B34/SUM($G34:$H34)) -> 0 | L34: =IF(SUM($G34:$H34)<1,0,C34/SUM($G34:$H34)) -> 0 | M34: =IF(SUM($G34:$H34)<1,0,D34/SUM($G34:$H34)) -> 0 | N34: =IF(SUM($G34:$H34)<1,0,E34/SUM($G34:$H34)) -> 0
A35: 26 | B35: =IF(('Entries Feb.''25'!I33-'Entries Feb.''25'!I32)+('Entries Feb.''25'!J33-'Entries Feb.''25'!J32)<1,"0",('Entries Feb.''25'!I33-'Entries Feb.''25'!I32)+('Entries Feb.''25'!J33-'Entries Feb.''25'!J32)) -> 7906 | C35: ='Water '!$R$32 -> 3640 | D35: =IF('Entries Feb.''25'!B34-'Entries Feb.''25'!B33<1,"0",'Entries Feb.''25'!B34-'Entries Feb.''25'!B33) -> 2940 | E35: ='Co2 '!B32 -> 28.09 | F35: =+'PROD.FIG. '!F30 -> 0 | G35: =+'PROD.FIG. '!C30 -> 0 | H35: =+'PROD.FIG. '!D30 -> 0 | I35: =+'PROD.FIG. '!E30 -> 0 | K35: =IF(SUM($G35:$H35)<1,0,B35/SUM($G35:$H35)) -> 0 | L35: =IF(SUM($G35:$H35)<1,0,C35/SUM($G35:$H35)) -> 0 | M35: =IF(SUM($G35:$H35)<1,0,D35/SUM($G35:$H35)) -> 0 | N35: =IF(SUM($G35:$H35)<1,0,E35/SUM($G35:$H35)) -> 0
A36: 27 | B36: =IF(('Entries Feb.''25'!I34-'Entries Feb.''25'!I33)+('Entries Feb.''25'!J34-'Entries Feb.''25'!J33)<1,"0",('Entries Feb.''25'!I34-'Entries Feb.''25'!I33)+('Entries Feb.''25'!J34-'Entries Feb.''25'!J33)) -> 8386 | C36: ='Water '!$R$33 -> 1210 | D36: =IF('Entries Feb.''25'!B35-'Entries Feb.''25'!B34<1,"0",'Entries Feb.''25'!B35-'Entries Feb.''25'!B34) -> 2650 | E36: ='Co2 '!B33 -> 6.57 | F36: =+'PROD.FIG. '!F31 -> 0 | G36: =+'PROD.FIG. '!C31 -> 0 | H36: =+'PROD.FIG. '!D31 -> 0 | I36: =+'PROD.FIG. '!E31 -> 0 | K36: =IF(SUM($G36:$H36)<1,0,B36/SUM($G36:$H36)) -> 0 | L36: =IF(SUM($G36:$H36)<1,0,C36/SUM($G36:$H36)) -> 0 | M36: =IF(SUM($G36:$H36)<1,0,D36/SUM($G36:$H36)) -> 0 | N36: =IF(SUM($G36:$H36)<1,0,E36/SUM($G36:$H36)) -> 0
A37: 28 | B37: =IF(('Entries Feb.''25'!I35-'Entries Feb.''25'!I34)+('Entries Feb.''25'!J35-'Entries Feb.''25'!J34)<1,"0",('Entries Feb.''25'!I35-'Entries Feb.''25'!I34)+('Entries Feb.''25'!J35-'Entries Feb.''25'!J34)) -> 7988 | C37: ='Water '!$R$34 -> -140 | D37: =IF('Entries Feb.''25'!B36-'Entries Feb.''25'!B35<1,"0",'Entries Feb.''25'!B36-'Entries Feb.''25'!B35) -> 0 | E37: ='Co2 '!B34 -> 16 | F37: =+'PROD.FIG. '!F32 -> 0 | G37: =+'PROD.FIG. '!C32 -> 0 | H37: =+'PROD.FIG. '!D32 -> 0 | I37: =+'PROD.FIG. '!E32 -> 0 | K37: =IF(SUM($G37:$H37)<1,0,B37/SUM($G37:$H37)) -> 0 | L37: =IF(SUM($G37:$H37)<1,0,C37/SUM($G37:$H37)) -> 0 | M37: =IF(SUM($G37:$H37)<1,0,D37/SUM($G37:$H37)) -> 0 | N37: =IF(SUM($G37:$H37)<1,0,E37/SUM($G37:$H37)) -> 0
A38: 29 | B38: =IF(('Entries Feb.''25'!I36-'Entries Feb.''25'!I35)+('Entries Feb.''25'!J36-'Entries Feb.''25'!J35)<1,"0",('Entries Feb.''25'!I36-'Entries Feb.''25'!I35)+('Entries Feb.''25'!J36-'Entries Feb.''25'!J35)) -> 0 | C38: ='Water '!$R$35 -> 0 | D38: =IF('Entries Feb.''25'!B37-'Entries Feb.''25'!B36<1,"0",'Entries Feb.''25'!B37-'Entries Feb.''25'!B36) -> 0 | E38: ='Co2 '!B35 -> 0 | F38: =+'PROD.FIG. '!F33 -> 0 | G38: =+'PROD.FIG. '!C33 -> 0 | H38: =+'PROD.FIG. '!D33 -> 0 | I38: =+'PROD.FIG. '!E33 -> 0 | K38: =IF(SUM($G38:$H38)<1,0,B38/SUM($G38:$H38)) -> 0 | L38: =IF(SUM($G38:$H38)<1,0,C38/SUM($G38:$H38)) -> 0 | M38: =IF(SUM($G38:$H38)<1,0,D38/SUM($G38:$H38)) -> 0 | N38: =IF(SUM($G38:$H38)<1,0,E38/SUM($G38:$H38)) -> 0
A39: 30 | B39: =IF(('Entries Feb.''25'!AD37-'Entries Feb.''25'!AD36)+('Entries Feb.''25'!AE37-'Entries Feb.''25'!AE36)<1,"0",('Entries Feb.''25'!AD37-'Entries Feb.''25'!AD36)+('Entries Feb.''25'!AE37-'Entries Feb.''25'!AE36)) -> 0 | C39: ='Water '!$R$36 -> 0 | D39: =IF('Entries Feb.''25'!B38-'Entries Feb.''25'!B37<1,"0",'Entries Feb.''25'!B38-'Entries Feb.''25'!B37) -> 0 | E39: ='Co2 '!B36 -> 0 | F39: =+'PROD.FIG. '!F34 -> 0 | G39: =+'PROD.FIG. '!C34 -> 0 | H39: =+'PROD.FIG. '!D34 -> 0 | I39: =+'PROD.FIG. '!E34 -> 0 | K39: =IF(SUM($G39:$H39)<1,0,B39/SUM($G39:$H39)) -> 0 | L39: =IF(SUM($G39:$H39)<1,0,C39/SUM($G39:$H39)) -> 0 | M39: =IF(SUM($G39:$H39)<1,0,D39/SUM($G39:$H39)) -> 0 | N39: =IF(SUM($G39:$H39)<1,0,E39/SUM($G39:$H39)) -> 0
A40: 31 | B40: ='Elec.Feb''25'!B37 -> 0 | C40: ='Water '!$R$37 -> 0 | D40: =IF('Entries Feb.''25'!B39-'Entries Feb.''25'!B38<1,"0",'Entries Feb.''25'!B39-'Entries Feb.''25'!B38) -> 62060 | E40: ='Co2 '!B37 -> 0 | F40: =+'PROD.FIG. '!F35 -> 0 | G40: =+'PROD.FIG. '!C35 -> 0 | H40: =+'PROD.FIG. '!D35 -> 0 | I40: =+'PROD.FIG. '!E35 -> 0 | K40: =IF(SUM($G40:$H40)<1,0,B40/SUM($G40:$H40)) -> 0 | L40: =IF(SUM($G40:$H40)<1,0,C40/SUM($G40:$H40)) -> 0 | M40: =IF(SUM($G40:$H40)<1,0,D40/SUM($G40:$H40)) -> 0 | N40: =IF(SUM($G40:$H40)<1,0,E40/SUM($G40:$H40)) -> 0
B42: Kwhr | C42: Hl | D42: L | E42: kg. | F42: hl | G42: hl | H42: hl | I42: hl | J42: hl | K42: KWH/Hl | L42: Hl/hl | M42: Litres/hl | N42: kg./Hl
A43: Total | B43: =SUM(B10:B40) -> 194364 | C43: =SUM(C10:C40) -> 35240 | D43: =SUM(D10:D37) -> 62060 | E43: =SUM(E10:E37) -> 447.11 | F43: =SUM(F10:F41) -> 0 | G43: =SUM(G10:G42) -> 0 | H43: =SUM(H10:H42) -> 0 | I43: =SUM(I10:I42) -> 0 | J43: =SUM(J10:J42) -> 0 | K43: =IF(SUM($G43:$H43)<1,0,B43/SUM($G43:$H43)) -> 0 | L43: =IF(SUM($G43:$H43)<1,0,C43/SUM($G43:$H43)) -> 0 | M43: =IF(SUM($G43:$H43)<1,0,D43/SUM($G43:$H43)) -> 0 | N43: =IF(SUM($G43:$H43)<1,0,E43/SUM($G43:$H43)) -> 0

Sheet Steam Mass Flow 
A3: DATE | B3: Steam Mass Flow Reading
A5: 1 | B5: =IF('Entries Feb.''25'!AK8-'Entries Feb.''25'!AK7<1,0,'Entries Feb.''25'!AK8-'Entries Feb.''25'!AK7) -> 0
A6: 2 | B6: =IF('Entries Feb.''25'!AK9-'Entries Feb.''25'!AK8<1,0,'Entries Feb.''25'!AK9-'Entries Feb.''25'!AK8) -> 0
A7: 3 | B7: =IF('Entries Feb.''25'!AK10-'Entries Feb.''25'!AK9<1,0,'Entries Feb.''25'!AK10-'Entries Feb.''25'!AK9) -> 281.877
A8: 4 | B8: =IF('Entries Feb.''25'!AK11-'Entries Feb.''25'!AK10<1,0,'Entries Feb.''25'!AK11-'Entries Feb.''25'!AK10) -> 0
A9: 5 | B9: =IF('Entries Feb.''25'!AK12-'Entries Feb.''25'!AK11<1,0,'Entries Feb.''25'!AK12-'Entries Feb.''25'!AK11) -> 0
A10: 6 | B10: =IF('Entries Feb.''25'!AK13-'Entries Feb.''25'!AK12<1,0,'Entries Feb.''25'!AK13-'Entries Feb.''25'!AK12) -> 0
A11: 7 | B11: =IF('Entries Feb.''25'!AK14-'Entries Feb.''25'!AK13<1,0,'Entries Feb.''25'!AK14-'Entries Feb.''25'!AK13) -> 0
A12: 8 | B12: =IF('Entries Feb.''25'!AK15-'Entries Feb.''25'!AK14<1,0,'Entries Feb.''25'!AK15-'Entries Feb.''25'!AK14) -> 0
A13: 9 | B13: =IF('Entries Feb.''25'!AK16-'Entries Feb.''25'!AK15<1,0,'Entries Feb.''25'!AK16-'Entries Feb.''25'!AK15) -> 36.402
A14: 10 | B14: =IF('Entries Feb.''25'!AK17-'Entries Feb.''25'!AK16<1,0,'Entries Feb.''25'!AK17-'Entries Feb.''25'!AK16) -> 13.365
A15: 11 | B15: =IF('Entries Feb.''25'!AK18-'Entries Feb.''25'!AK17<1,0,'Entries Feb.''25'!AK18-'Entries Feb.''25'!AK17) -> 17.898
A16: 12 | B16: =IF('Entries Feb.''25'!AK19-'Entries Feb.''25'!AK18<1,0,'Entries Feb.''25'!AK19-'Entries Feb.''25'!AK18) -> 0
... A35: 31 | B35: =IF('Entries Feb.''25'!AK38-'Entries Feb.''25'!AK37<1,0,'Entries Feb.''25'!AK38-'Entries Feb.''25'!AK37) -> 0

Sheet Co2 
A3: CO2 Daily Consumption for MAR. '12
A5: DATE | B5: Total Cons. (Kg.) | C5: CO2 ( Kg./Hl.) | I5: Tank A | J5: Tank B | K5: Mobile | L5: Inside Tank | R5: 4 | S5: Usage | T5: time | U5: 5 | V5: Usage | W5: Time | X5: 6 | Y5: Usage | Z5: time | AA5: 7 | AB5: Usage | AC5: Time | AD5: 8 | AE5: Usage | AF5: time | AG5: 9 | AH5: Usage | AI5: Time | AJ5: 10 | AK5: Usage | AL5: time | AM5: 11 | AN5: Usage | AO5: Time | AP5: 12 | AQ5: Usage | AR5: time | AS5: 13 | AT5: Usage | AU5: Time | AV5: 14 | AW5: Usage | AX5: time | AY5: 15 | AZ5: Usage | BA5: Time | BB5: 16 | BC5: Usage | BD5: time | BE5: 17 | BF5: Usage | BG5: Time | BH5: 18 | BI5: Usage | BJ5: time | BK5: 19 | BL5: Usage | BM5: Time | BN5: 20 | BO5: Usage | BP5: time | BQ5: 21 | BR5: Usage | BS5: Time | BT5: 22 | BU5: Usage | BV5: time | BW5: 23 | BX5: Usage | BY5: Time | BZ5: 24 | CA5: Usage | CB5: time | CC5: 25 | CD5: Usage | CE5: Time | CF5: 26 | CG5: Usage | CH5: time | CI5: 27 | CJ5: Usage | CK5: Time | CL5: 28 | CM5: Usage | CN5: time | CO5: 29 | CP5: Usage | CQ5: Time | CR5: 30 | CS5: Usage | CT5: time | CU5: 31 | CV5: Usage | CW5: Time | CX5: 2 | CY5: Usage
E6: Collection | T6: 630 | Z6: 630 | AF6: 630 | AL6: 630 | AR6: 630 | AX6: 630 | BD6: 630 | BJ6: 630 | BP6: 630 | BV6: 630 | CB6: 630 | CH6: 630 | CN6: 630 | CT6: 630
A7: 1 | B7: ='Entries Feb.''25'!N8-'Entries Feb.''25'!N7 -> 0 | C7: =IF(B7/'PROD.FIG. '!H5<1,0,B7/'PROD.FIG. '!H5) -> #DIV/0! | E7: ='Entries Feb.''25'!L8-'Entries Feb.''25'!L7 -> 0 | F7: =+$B7 -> 0 | I7: =IF((('Entries Feb.''25'!AL7-'Entries Feb.''25'!AL8)/10)*5455<0,"0",(('Entries Feb.''25'!AL7-'Entries Feb.''25'!AL8)/10)*5455) -> 0 | J7: =IF((('Entries Feb.''25'!AM7-'Entries Feb.''25'!AM8)/10)*5455<0,"0",(('Entries Feb.''25'!AM7-'Entries Feb.''25'!AM8)/10)*5455) -> 0 | K7: =IF(('Entries Feb.''25'!AN7-'Entries Feb.''25'!AN8)/2.2<0,"0",('Entries Feb.''25'!AN7-'Entries Feb.''25'!AN8)/2.2) -> 0 | L7: =IF(('Entries Feb.''25'!AO7-'Entries Feb.''25'!AO8)<0,"0",('Entries Feb.''25'!AO7-'Entries Feb.''25'!AO8)) -> 0 | S7: =R7-R6 -> 0 | T7: 730 | V7: =U7-U6 -> 0 | Y7: =X7-X6 -> 0 | Z7: 730 | AB7: =AA7-AA6 -> 0 | AE7: =AD7-AD6 -> 0 | AF7: 730 | AH7: =AG7-AG6 -> 0 | AK7: =AJ7-AJ6 -> 0 | AL7: 730 | AN7: =AM7-AM6 -> 0 | AQ7: =AP7-AP6 -> 0 | AR7: 730 | AT7: =AS7-AS6 -> 0 | AW7: =AV7-AV6 -> 0 | AX7: 730 | AZ7: =AY7-AY6 -> 0 | BC7: =BB7-BB6 -> 0 | BD7: 730 | BF7: =BE7-BE6 -> 0 | BI7: =BH7-BH6 -> 0 | BJ7: 730 | BL7: =BK7-BK6 -> 0 | BO7: =BN7-BN6 -> 0 | BP7: 730 | BR7: =BQ7-BQ6 -> 0 | BU7: =BT7-BT6 -> 0 | BV7: 730 | BX7: =BW7-BW6 -> 0 | CA7: =BZ7-BZ6 -> 0 | CB7: 730 | CD7: =CC7-CC6 -> 0 | CG7: =CF7-CF6 -> 0 | CH7: 730 | CJ7: =CI7-CI6 -> 0 | CM7: =CL7-CL6 -> 0 | CN7: 730 | CP7: =CO7-CO6 -> 0 | CS7: =CR7-CR6 -> 0 | CT7: 730 | CV7: =CU7-CU6 -> 0 | CY7: =CX7-CX6 -> 0
A8: 2 | B8: ='Entries Feb.''25'!N9-'Entries Feb.''25'!N8 -> 0 | C8: =IF(B8/'PROD.FIG. '!H6<1,0,B8/'PROD.FIG. '!H6) -> #DIV/0! | E8: ='Entries Feb.''25'!L9-'Entries Feb.''25'!L8 -> 0 | F8: =+$B8 -> 0 | I8: =IF((('Entries Feb.''25'!AL8-'Entries Feb.''25'!AL9)/10)*5455<0,"0",(('Entries Feb.''25'!AL8-'Entries Feb.''25'!AL9)/10)*5455) -> 0 | J8: =IF((('Entries Feb.''25'!AM8-'Entries Feb.''25'!AM9)/10)*5455<0,"0",(('Entries Feb.''25'!AM8-'Entries Feb.''25'!AM9)/10)*5455) -> 0 | K8: =IF(('Entries Feb.''25'!AN8-'Entries Feb.''25'!AN9)/2.2<0,"0",('Entries Feb.''25'!AN8-'Entries Feb.''25'!AN9)/2.2) -> 0 | L8: =IF(('Entries Feb.''25'!AO8-'Entries Feb.''25'!AO9)<0,"0",('Entries Feb.''25'!AO8-'Entries Feb.''25'!AO9)) -> 0 | S8: =R8-R7 -> 0 | V8: =U8-U7 -> 0 | Y8: =X8-X7 -> 0 | AB8: =AA8-AA7 -> 0 | AE8: =AD8-AD7 -> 0 | AH8: =AG8-AG7 -> 0 | AK8: =AJ8-AJ7 -> 0 | AN8: =AM8-AM7 -> 0 | AQ8: =AP8-AP7 -> 0 | AT8: =AS8-AS7 -> 0 | AW8: =AV8-AV7 -> 0 | AZ8: =AY8-AY7 -> 0 | BC8: =BB8-BB7 -> 0 | BF8: =BE8-BE7 -> 0 | BI8: =BH8-BH7 -> 0 | BL8: =BK8-BK7 -> 0 | BO8: =BN8-BN7 -> 0 | BR8: =BQ8-BQ7 -> 0 | BU8: =BT8-BT7 -> 0 | BX8: =BW8-BW7 -> 0 | CA8: =BZ8-BZ7 -> 0 | CD8: =CC8-CC7 -> 0 | CG8: =CF8-CF7 -> 0 | CJ8: =CI8-CI7 -> 0 | CM8: =CL8-CL7 -> 0 | CP8: =CO8-CO7 -> 0 | CS8: =CR8-CR7 -> 0 | CV8: =CU8-CU7 -> 0 | CY8: =CX8-CX7 -> 0
A9: 3 | B9: ='Entries Feb.''25'!N10-'Entries Feb.''25'!N9 -> 29.34 | C9: =IF(B9/'PROD.FIG. '!H7<1,0,B9/'PROD.FIG. '!H7) -> #DIV/0! | E9: ='Entries Feb.''25'!L10-'Entries Feb.''25'!L9 -> 0 | F9: =+$B9 -> 29.34 | I9: =IF((('Entries Feb.''25'!AL9-'Entries Feb.''25'!AL10)/10)*5455<0,"0",(('Entries Feb.''25'!AL9-'Entries Feb.''25'!AL10)/10)*5455) -> 0 | J9: =IF((('Entries Feb.''25'!AM9-'Entries Feb.''25'!AM10)/10)*5455<0,"0",(('Entries Feb.''25'!AM9-'Entries Feb.''25'!AM10)/10)*5455) -> 0 | K9: =IF(('Entries Feb.''25'!AN9-'Entries Feb.''25'!AN10)/2.2<0,"0",('Entries Feb.''25'!AN9-'Entries Feb.''25'!AN10)/2.2) -> 0 | L9: =IF(('Entries Feb.''25'!AO9-'Entries Feb.''25'!AO10)<0,"0",('Entries Feb.''25'!AO9-'Entries Feb.''25'!AO10)) -> 0 | S9: =R9-R8 -> 0 | V9: =U9-U8 -> 0 | Y9: =X9-X8 -> 0 | AB9: =AA9-AA8 -> 0 | AE9: =AD9-AD8 -> 0 | AH9: =AG9-AG8 -> 0 | AK9: =AJ9-AJ8 -> 0 | AN9: =AM9-AM8 -> 0 | AQ9: =AP9-AP8 -> 0 | AT9: =AS9-AS8 -> 0 | AW9: =AV9-AV8 -> 0 | AZ9: =AY9-AY8 -> 0 | BC9: =BB9-BB8 -> 0 | BF9: =BE9-BE8 -> 0 | BI9: =BH9-BH8 -> 0 | BL9: =BK9-BK8 -> 0 | BO9: =BN9-BN8 -> 0 | BR9: =BQ9-BQ8 -> 0 | BU9: =BT9-BT8 -> 0 | BX9: =BW9-BW8 -> 0 | CA9: =BZ9-BZ8 -> 0 | CD9: =CC9-CC8 -> 0 | CG9: =CF9-CF8 -> 0 | CJ9: =CI9-CI8 -> 0 | CM9: =CL9-CL8 -> 0 | CP9: =CO9-CO8 -> 0 | CS9: =CR9-CR8 -> 0 | CV9: =CU9-CU8 -> 0 | CY9: =CX9-CX8 -> 0
A10: 4 | B10: ='Entries Feb.''25'!N11-'Entries Feb.''25'!N10 -> 43.05 | C10: =IF(B10/'PROD.FIG. '!H8<1,0,B10/'PROD.FIG. '!H8) -> #DIV/0! | E10: ='Entries Feb.''25'!L11-'Entries Feb.''25'!L10 -> 0 | F10: =+$B10 -> 43.05 | I10: =IF((('Entries Feb.''25'!AL10-'Entries Feb.''25'!AL11)/10)*5455<0,"0",(('Entries Feb.''25'!AL10-'Entries Feb.''25'!AL11)/10)*5455) -> 0 | J10: =IF((('Entries Feb.''25'!AM10-'Entries Feb.''25'!AM11)/10)*5455<0,"0",(('Entries Feb.''25'!AM10-'Entries Feb.''25'!AM11)/10)*5455) -> 0 | K10: =IF(('Entries Feb.''25'!AN10-'Entries Feb.''25'!AN11)/2.2<0,"0",('Entries Feb.''25'!AN10-'Entries Feb.''25'!AN11)/2.2) -> 0 | L10: =IF(('Entries Feb.''25'!AO10-'Entries Feb.''25'!AO11)<0,"0",('Entries Feb.''25'!AO10-'Entries Feb.''25'!AO11)) -> 0 | S10: =R10-R9 -> 0 | V10: =U10-U9 -> 0 | Y10: =X10-X9 -> 0 | AB10: =AA10-AA9 -> 0 | AE10: =AD10-AD9 -> 0 | AH10: =AG10-AG9 -> 0 | AK10: =AJ10-AJ9 -> 0 | AN10: =AM10-AM9 -> 0 | AQ10: =AP10-AP9 -> 0 | AT10: =AS10-AS9 -> 0 | AW10: =AV10-AV9 -> 0 | AZ10: =AY10-AY9 -> 0 | BC10: =BB10-BB9 -> 0 | BF10: =BE10-BE9 -> 0 | BI10: =BH10-BH9 -> 0 | BL10: =BK10-BK9 -> 0 | BO10: =BN10-BN9 -> 0 | BR10: =BQ10-BQ9 -> 0 | BU10: =BT10-BT9 -> 0 | BX10: =BW10-BW9 -> 0 | CA10: =BZ10-BZ9 -> 0 | CD10: =CC10-CC9 -> 0 | CG10: =CF10-CF9 -> 0 | CJ10: =CI10-CI9 -> 0 | CM10: =CL10-CL9 -> 0 | CP10: =CO10-CO9 -> 0 | CS10: =CR10-CR9 -> 0 | CV10: =CU10-CU9 -> 0 | CY10: =CX10-CX9 -> 0
A11: 5 | B11: ='Entries Feb.''25'!N12-'Entries Feb.''25'!N11 -> 40.72 | C11: =IF(B11/'PROD.FIG. '!H9<1,0,B11/'PROD.FIG. '!H9) -> #DIV/0! | E11: ='Entries Feb.''25'!L12-'Entries Feb.''25'!L11 -> 0 | F11: =+$B11 -> 40.72 | I11: =IF((('Entries Feb.''25'!AL11-'Entries Feb.''25'!AL12)/10)*5455<0,"0",(('Entries Feb.''25'!AL11-'Entries Feb.''25'!AL12)/10)*5455) -> 0 | J11: =IF((('Entries Feb.''25'!AM11-'Entries Feb.''25'!AM12)/10)*5455<0,"0",(('Entries Feb.''25'!AM11-'Entries Feb.''25'!AM12)/10)*5455) -> 0 | K11: =IF(('Entries Feb.''25'!AN11-'Entries Feb.''25'!AN12)/2.2<0,"0",('Entries Feb.''25'!AN11-'Entries Feb.''25'!AN12)/2.2) -> 0 | L11: =IF(('Entries Feb.''25'!AO11-'Entries Feb.''25'!AO12)<0,"0",('Entries Feb.''25'!AO11-'Entries Feb.''25'!AO12)) -> 0 | S11: =R11-R10 -> 0 | V11: =U11-U10 -> 0 | Y11: =X11-X10 -> 0 | AB11: =AA11-AA10 -> 0 | AE11: =AD11-AD10 -> 0 | AH11: =AG11-AG10 -> 0 | AK11: =AJ11-AJ10 -> 0 | AN11: =AM11-AM10 -> 0 | AQ11: =AP11-AP10 -> 0 | AT11: =AS11-AS10 -> 0 | AW11: =AV11-AV10 -> 0 | AZ11: =AY11-AY10 -> 0 | BC11: =BB11-BB10 -> 0 | BF11: =BE11-BE10 -> 0 | BI11: =BH11-BH10 -> 0 | BL11: =BK11-BK10 -> 0 | BO11: =BN11-BN10 -> 0 | BR11: =BQ11-BQ10 -> 0 | BU11: =BT11-BT10 -> 0 | BX11: =BW11-BW10 -> 0 | CA11: =BZ11-BZ10 -> 0 | CD11: =CC11-CC10 -> 0 | CG11: =CF11-CF10 -> 0 | CJ11: =CI11-CI10 -> 0 | CM11: =CL11-CL10 -> 0 | CP11: =CO11-CO10 -> 0 | CS11: =CR11-CR10 -> 0 | CV11: =CU11-CU10 -> 0 | CY11: =CX11-CX10 -> 0
A12: 6 | B12: ='Entries Feb.''25'!N13-'Entries Feb.''25'!N12 -> 4.39 | C12: =IF(B12/'PROD.FIG. '!H10<1,0,B12/'PROD.FIG. '!H10) -> #DIV/0! | E12: ='Entries Feb.''25'!L13-'Entries Feb.''25'!L12 -> 0 | F12: =+$B12 -> 4.39 | I12: =IF((('Entries Feb.''25'!AL12-'Entries Feb.''25'!AL13)/10)*5455<0,"0",(('Entries Feb.''25'!AL12-'Entries Feb.''25'!AL13)/10)*5455) -> 0 | J12: =IF((('Entries Feb.''25'!AM12-'Entries Feb.''25'!AM13)/10)*5455<0,"0",(('Entries Feb.''25'!AM12-'Entries Feb.''25'!AM13)/10)*5455) -> 0 | K12: =IF(('Entries Feb.''25'!AN12-'Entries Feb.''25'!AN13)/2.2<0,"0",('Entries Feb.''25'!AN12-'Entries Feb.''25'!AN13)/2.2) -> 0 | L12: =IF(('Entries Feb.''25'!AO12-'Entries Feb.''25'!AO13)<0,"0",('Entries Feb.''25'!AO12-'Entries Feb.''25'!AO13)) -> 0 | S12: =R12-R11 -> 0 | V12: =U12-U11 -> 0 | Y12: =X12-X11 -> 0 | AB12: =AA12-AA11 -> 0 | AE12: =AD12-AD11 -> 0 | AH12: =AG12-AG11 -> 0 | AK12: =AJ12-AJ11 -> 0 | AN12: =AM12-AM11 -> 0 | AQ12: =AP12-AP11 -> 0 | AT12: =AS12-AS11 -> 0 | AW12: =AV12-AV11 -> 0 | AZ12: =AY12-AY11 -> 0 | BC12: =BB12-BB11 -> 0 | BF12: =BE12-BE11 -> 0 | BI12: =BH12-BH11 -> 0 | BL12: =BK12-BK11 -> 0 | BO12: =BN12-BN11 -> 0 | BR12: =BQ12-BQ11 -> 0 | BU12: =BT12-BT11 -> 0 | BX12: =BW12-BW11 -> 0 | CA12: =BZ12-BZ11 -> 0 | CD12: =CC12-CC11 -> 0 | CG12: =CF12-CF11 -> 0 | CJ12: =CI12-CI11 -> 0 | CM12: =CL12-CL11 -> 0 | CP12: =CO12-CO11 -> 0 | CS12: =CR12-CR11 -> 0 | CV12: =CU12-CU11 -> 0 | CY12: =CX12-CX11 -> 0
A13: 7 | B13: ='Entries Feb.''25'!N14-'Entries Feb.''25'!N13 -> 0 | C13: =IF(B13/'PROD.FIG. '!H11<1,0,B13/'PROD.FIG. '!H11) -> #DIV/0! | E13: ='Entries Feb.''25'!L14-'Entries Feb.''25'!L13 -> 0 | F13: =+$B13 -> 0 | I13: =IF((('Entries Feb.''25'!AL13-'Entries Feb.''25'!AL14)/10)*5455<0,"0",(('Entries Feb.''25'!AL13-'Entries Feb.''25'!AL14)/10)*5455) -> 0 | J13: =IF((('Entries Feb.''25'!AM13-'Entries Feb.''25'!AM14)/10)*5455<0,"0",(('Entries Feb.''25'!AM13-'Entries Feb.''25'!AM14)/10)*5455) -> 0 | K13: =IF(('Entries Feb.''25'!AN13-'Entries Feb.''25'!AN14)/2.2<0,"0",('Entries Feb.''25'!AN13-'Entries Feb.''25'!AN14)/2.2) -> 0 | L13: =IF(('Entries Feb.''25'!AO13-'Entries Feb.''25'!AO14)<0,"0",('Entries Feb.''25'!AO13-'Entries Feb.''25'!AO14)) -> 0 | S13: =R13-R12 -> 0 | V13: =U13-U12 -> 0 | Y13: =X13-X12 -> 0 | AB13: =AA13-AA12 -> 0 | AE13: =AD13-AD12 -> 0 | AH13: =AG13-AG12 -> 0 | AK13: =AJ13-AJ12 -> 0 | AN13: =AM13-AM12 -> 0 | AQ13: =AP13-AP12 -> 0 | AT13: =AS13-AS12 -> 0 | AW13: =AV13-AV12 -> 0 | AZ13: =AY13-AY12 -> 0 | BC13: =BB13-BB12 -> 0 | BF13: =BE13-BE12 -> 0 | BI13: =BH13-BH12 -> 0 | BL13: =BK13-BK12 -> 0 | BO13: =BN13-BN12 -> 0 | BR13: =BQ13-BQ12 -> 0 | BU13: =BT13-BT12 -> 0 | BX13: =BW13-BW12 -> 0 | CA13: =BZ13-BZ12 -> 0 | CD13: =CC13-CC12 -> 0 | CG13: =CF13-CF12 -> 0 | CJ13: =CI13-CI12 -> 0 | CM13: =CL13-CL12 -> 0 | CP13: =CO13-CO12 -> 0 | CS13: =CR13-CR12 -> 0 | CV13: =CU13-CU12 -> 0 | CY13: =CX13-CX12 -> 0
A14: 8 | B14: ='Entries Feb.''25'!N15-'Entries Feb.''25'!N14 -> 0 | C14: =IF(B14/'PROD.FIG. '!H12<1,0,B14/'PROD.FIG. '!H12) -> #DIV/0! | E14: ='Entries Feb.''25'!L15-'Entries Feb.''25'!L14 -> 0 | F14: =+$B14 -> 0 | I14: =IF((('Entries Feb.''25'!AL14-'Entries Feb.''25'!AL15)/10)*5455<0,"0",(('Entries Feb.''25'!AL14-'Entries Feb.''25'!AL15)/10)*5455) -> 0 | J14: =IF((('Entries Feb.''25'!AM14-'Entries Feb.''25'!AM15)/10)*5455<0,"0",(('Entries Feb.''25'!AM14-'Entries Feb.''25'!AM15)/10)*5455) -> 0 | K14: =IF(('Entries Feb.''25'!AN14-'Entries Feb.''25'!AN15)/2.2<0,"0",('Entries Feb.''25'!AN14-'Entries Feb.''25'!AN15)/2.2) -> 0 | L14: =IF(('Entries Feb.''25'!AO14-'Entries Feb.''25'!AO15)<0,"0",('Entries Feb.''25'!AO14-'Entries Feb.''25'!AO15)) -> 0 | S14: =R14-R13 -> 0 | V14: =U14-U13 -> 0 | Y14: =X14-X13 -> 0 | AB14: =AA14-AA13 -> 0 | AE14: =AD14-AD13 -> 0 | AH14: =AG14-AG13 -> 0 | AK14: =AJ14-AJ13 -> 0 | AN14: =AM14-AM13 -> 0 | AQ14: =AP14-AP13 -> 0 | AT14: =AS14-AS13 -> 0 | AW14: =AV14-AV13 -> 0 | AZ14: =AY14-AY13 -> 0 | BC14: =BB14-BB13 -> 0 | BF14: =BE14-BE13 -> 0 | BI14: =BH14-BH13 -> 0 | BL14: =BK14-BK13 -> 0 | BO14: =BN14-BN13 -> 0 | BR14: =BQ14-BQ13 -> 0 | BU14: =BT14-BT13 -> 0 | BX14: =BW14-BW13 -> 0 | CA14: =BZ14-BZ13 -> 0 | CD14: =CC14-CC13 -> 0 | CG14: =CF14-CF13 -> 0 | CJ14: =CI14-CI13 -> 0 | CM14: =CL14-CL13 -> 0 | CP14: =CO14-CO13 -> 0 | CS14: =CR14-CR13 -> 0 | CV14: =CU14-CU13 -> 0 | CY14: =CX14-CX13 -> 0
A15: 9 | B15: ='Entries Feb.''25'!N16-'Entries Feb.''25'!N15 -> 0 | C15: =IF(B15/'PROD.FIG. '!H13<1,0,B15/'PROD.FIG. '!H13) -> #DIV/0! | E15: ='Entries Feb.''25'!L16-'Entries Feb.''25'!L15 -> 0 | F15: =+$B15 -> 0 | I15: =IF((('Entries Feb.''25'!AL15-'Entries Feb.''25'!AL16)/10)*5455<0,"0",(('Entries Feb.''25'!AL15-'Entries Feb.''25'!AL16)/10)*5455) -> 0 | J15: =IF((('Entries Feb.''25'!AM15-'Entries Feb.''25'!AM16)/10)*5455<0,"0",(('Entries Feb.''25'!AM15-'Entries Feb.''25'!AM16)/10)*5455) -> 0 | K15: =IF(('Entries Feb.''25'!AN15-'Entries Feb.''25'!AN16)/2.2<0,"0",('Entries Feb.''25'!AN15-'Entries Feb.''25'!AN16)/2.2) -> 0 | L15: =IF(('Entries Feb.''25'!AO15-'Entries Feb.''25'!AO16)<0,"0",('Entries Feb.''25'!AO15-'Entries Feb.''25'!AO16)) -> 0 | S15: =R15-R14 -> 0 | V15: =U15-U14 -> 0 | Y15: =X15-X14 -> 0 | AB15: =AA15-AA14 -> 0 | AE15: =AD15-AD14 -> 0 | AH15: =AG15-AG14 -> 0 | AK15: =AJ15-AJ14 -> 0 | AN15: =AM15-AM14 -> 0 | AQ15: =AP15-AP14 -> 0 | AT15: =AS15-AS14 -> 0 | AW15: =AV15-AV14 -> 0 | AZ15: =AY15-AY14 -> 0 | BC15: =BB15-BB14 -> 0 | BF15: =BE15-BE14 -> 0 | BI15: =BH15-BH14 -> 0 | BL15: =BK15-BK14 -> 0 | BO15: =BN15-BN14 -> 0 | BR15: =BQ15-BQ14 -> 0 | BU15: =BT15-BT14 -> 0 | BX15: =BW15-BW14 -> 0 | CA15: =BZ15-BZ14 -> 0 | CD15: =CC15-CC14 -> 0 | CG15: =CF15-CF14 -> 0 | CJ15: =CI15-CI14 -> 0 | CM15: =CL15-CL14 -> 0 | CP15: =CO15-CO14 -> 0 | CS15: =CR15-CR14 -> 0 | CV15: =CU15-CU14 -> 0 | CY15: =CX15-CX14 -> 0
A16: 10 | B16: ='Entries Feb.''25'!N17-'Entries Feb.''25'!N16 -> 20 | C16: =IF(B16/'PROD.FIG. '!H14<1,0,B16/'PROD.FIG. '!H14) -> #DIV/0! | E16: ='Entries Feb.''25'!L17-'Entries Feb.''25'!L16 -> 0 | F16: =+$B16 -> 20 | I16: =IF((('Entries Feb.''25'!AL16-'Entries Feb.''25'!AL17)/10)*5455<0,"0",(('Entries Feb.''25'!AL16-'Entries Feb.''25'!AL17)/10)*5455) -> 0 | J16: =IF((('Entries Feb.''25'!AM16-'Entries Feb.''25'!AM17)/10)*5455<0,"0",(('Entries Feb.''25'!AM16-'Entries Feb.''25'!AM17)/10)*5455) -> 0 | K16: =IF(('Entries Feb.''25'!AN16-'Entries Feb.''25'!AN17)/2.2<0,"0",('Entries Feb.''25'!AN16-'Entries Feb.''25'!AN17)/2.2) -> 0 | L16: =IF(('Entries Feb.''25'!AO16-'Entries Feb.''25'!AO17)<0,"0",('Entries Feb.''25'!AO16-'Entries Feb.''25'!AO17)) -> 0 | S16: =R16-R15 -> 0 | V16: =U16-U15 -> 0 | Y16: =X16-X15 -> 0 | AB16: =AA16-AA15 -> 0 | AE16: =AD16-AD15 -> 0 | AH16: =AG16-AG15 -> 0 | AK16: =AJ16-AJ15 -> 0 | AN16: =AM16-AM15 -> 0 | AQ16: =AP16-AP15 -> 0 | AT16: =AS16-AS15 -> 0 | AW16: =AV16-AV15 -> 0 | AZ16: =AY16-AY15 -> 0 | BC16: =BB16-BB15 -> 0 | BF16: =BE16-BE15 -> 0 | BI16: =BH16-BH15 -> 0 | BL16: =BK16-BK15 -> 0 | BO16: =BN16-BN15 -> 0 | BR16: =BQ16-BQ15 -> 0 | BU16: =BT16-BT15 -> 0 | BX16: =BW16-BW15 -> 0 | CA16: =BZ16-BZ15 -> 0 | CD16: =CC16-CC15 -> 0 | CG16: =CF16-CF15 -> 0 | CJ16: =CI16-CI15 -> 0 | CM16: =CL16-CL15 -> 0 | CP16: =CO16-CO15 -> 0 | CS16: =CR16-CR15 -> 0 | CV16: =CU16-CU15 -> 0 | CY16: =CX16-CX15 -> 0
A17: 11 | B17: ='Entries Feb.''25'!N18-'Entries Feb.''25'!N17 -> 34.58 | C17: =IF(B17/'PROD.FIG. '!H15<1,0,B17/'PROD.FIG. '!H15) -> #DIV/0! | E17: ='Entries Feb.''25'!L18-'Entries Feb.''25'!L17 -> 0 | F17: =+$B17 -> 34.58 | I17: =IF((('Entries Feb.''25'!AL17-'Entries Feb.''25'!AL18)/10)*5455<0,"0",(('Entries Feb.''25'!AL17-'Entries Feb.''25'!AL18)/10)*5455) -> 0 | J17: =IF((('Entries Feb.''25'!AM17-'Entries Feb.''25'!AM18)/10)*5455<0,"0",(('Entries Feb.''25'!AM17-'Entries Feb.''25'!AM18)/10)*5455) -> 0 | K17: =IF(('Entries Feb.''25'!AN17-'Entries Feb.''25'!AN18)/2.2<0,"0",('Entries Feb.''25'!AN17-'Entries Feb.''25'!AN18)/2.2) -> 0 | L17: =IF(('Entries Feb.''25'!AO17-'Entries Feb.''25'!AO18)<0,"0",('Entries Feb.''25'!AO17-'Entries Feb.''25'!AO18)) -> 0 | S17: =R17-R16 -> 0 | V17: =U17-U16 -> 0 | Y17: =X17-X16 -> 0 | AB17: =AA17-AA16 -> 0 | AE17: =AD17-AD16 -> 0 | AH17: =AG17-AG16 -> 0 | AK17: =AJ17-AJ16 -> 0 | AN17: =AM17-AM16 -> 0 | AQ17: =AP17-AP16 -> 0 | AT17: =AS17-AS16 -> 0 | AW17: =AV17-AV16 -> 0 | AZ17: =AY17-AY16 -> 0 | BC17: =BB17-BB16 -> 0 | BF17: =BE17-BE16 -> 0 | BI17: =BH17-BH16 -> 0 | BL17: =BK17-BK16 -> 0 | BO17: =BN17-BN16 -> 0 | BR17: =BQ17-BQ16 -> 0 | BU17: =BT17-BT16 -> 0 | BX17: =BW17-BW16 -> 0 | CA17: =BZ17-BZ16 -> 0 | CD17: =CC17-CC16 -> 0 | CG17: =CF17-CF16 -> 0 | CJ17: =CI17-CI16 -> 0 | CM17: =CL17-CL16 -> 0 | CP17: =CO17-CO16 -> 0 | CS17: =CR17-CR16 -> 0 | CV17: =CU17-CU16 -> 0 | CY17: =CX17-CX16 -> 0
A18: 12 | B18: ='Entries Feb.''25'!N19-'Entries Feb.''25'!N18 -> 31.4 | C18: =IF(B18/'PROD.FIG. '!H16<1,0,B18/'PROD.FIG. '!H16) -> #DIV/0! | E18: ='Entries Feb.''25'!L19-'Entries Feb.''25'!L18 -> 0 | F18: =+$B18 -> 31.4 | I18: =IF((('Entries Feb.''25'!AL18-'Entries Feb.''25'!AL19)/10)*5455<0,"0",(('Entries Feb.''25'!AL18-'Entries Feb.''25'!AL19)/10)*5455) -> 0 | J18: =IF((('Entries Feb.''25'!AM18-'Entries Feb.''25'!AM19)/10)*5455<0,"0",(('Entries Feb.''25'!AM18-'Entries Feb.''25'!AM19)/10)*5455) -> 0 | K18: =IF(('Entries Feb.''25'!AN18-'Entries Feb.''25'!AN19)/2.2<0,"0",('Entries Feb.''25'!AN18-'Entries Feb.''25'!AN19)/2.2) -> 0 | L18: =IF(('Entries Feb.''25'!AO18-'Entries Feb.''25'!AO19)<0,"0",('Entries Feb.''25'!AO18-'Entries Feb.''25'!AO19)) -> 0 | S18: =R18-R17 -> 0 | V18: =U18-U17 -> 0 | Y18: =X18-X17 -> 0 | AB18: =AA18-AA17 -> 0 | AE18: =AD18-AD17 -> 0 | AH18: =AG18-AG17 -> 0 | AK18: =AJ18-AJ17 -> 0 | AN18: =AM18-AM17 -> 0 | AQ18: =AP18-AP17 -> 0 | AT18: =AS18-AS17 -> 0 | AW18: =AV18-AV17 -> 0 | AZ18: =AY18-AY17 -> 0 | BC18: =BB18-BB17 -> 0 | BF18: =BE18-BE17 -> 0 | BI18: =BH18-BH17 -> 0 | BL18: =BK18-BK17 -> 0 | BO18: =BN18-BN17 -> 0 | BR18: =BQ18-BQ17 -> 0 | BU18: =BT18-BT17 -> 0 | BX18: =BW18-BW17 -> 0 | CA18: =BZ18-BZ17 -> 0 | CD18: =CC18-CC17 -> 0 | CG18: =CF18-CF17 -> 0 | CJ18: =CI18-CI17 -> 0 | CM18: =CL18-CL17 -> 0 | CP18: =CO18-CO17 -> 0 | CS18: =CR18-CR17 -> 0 | CV18: =CU18-CU17 -> 0 | CY18: =CX18-CX17 -> 0
A19: 13 | B19: ='Entries Feb.''25'!N20-'Entries Feb.''25'!N19 -> 37.14 | C19: =IF(B19/'PROD.FIG. '!H17<1,0,B19/'PROD.FIG. '!H17) -> #DIV/0! | E19: ='Entries Feb.''25'!L20-'Entries Feb.''25'!L19 -> 0 | F19: =+$B19 -> 37.14 | I19: =IF((('Entries Feb.''25'!AL19-'Entries Feb.''25'!AL20)/10)*5455<0,"0",(('Entries Feb.''25'!AL19-'Entries Feb.''25'!AL20)/10)*5455) -> 0 | J19: =IF((('Entries Feb.''25'!AM19-'Entries Feb.''25'!AM20)/10)*5455<0,"0",(('Entries Feb.''25'!AM19-'Entries Feb.''25'!AM20)/10)*5455) -> 0 | K19: =IF(('Entries Feb.''25'!AN19-'Entries Feb.''25'!AN20)/2.2<0,"0",('Entries Feb.''25'!AN19-'Entries Feb.''25'!AN20)/2.2) -> 0 | L19: =IF(('Entries Feb.''25'!AO19-'Entries Feb.''25'!AO20)<0,"0",('Entries Feb.''25'!AO19-'Entries Feb.''25'!AO20)) -> 0 | S19: =R19-R18 -> 0 | V19: =U19-U18 -> 0 | Y19: =X19-X18 -> 0 | AB19: =AA19-AA18 -> 0 | AE19: =AD19-AD18 -> 0 | AH19: =AG19-AG18 -> 0 | AK19: =AJ19-AJ18 -> 0 | AN19: =AM19-AM18 -> 0 | AQ19: =AP19-AP18 -> 0 | AT19: =AS19-AS18 -> 0 | AW19: =AV19-AV18 -> 0 | AZ19: =AY19-AY18 -> 0 | BC19: =BB19-BB18 -> 0 | BF19: =BE19-BE18 -> 0 | BI19: =BH19-BH18 -> 0 | BL19: =BK19-BK18 -> 0 | BO19: =BN19-BN18 -> 0 | BR19: =BQ19-BQ18 -> 0 | BU19: =BT19-BT18 -> 0 | BX19: =BW19-BW18 -> 0 | CA19: =BZ19-BZ18 -> 0 | CD19: =CC19-CC18 -> 0 | CG19: =CF19-CF18 -> 0 | CJ19: =CI19-CI18 -> 0 | CM19: =CL19-CL18 -> 0 | CP19: =CO19-CO18 -> 0 | CS19: =CR19-CR18 -> 0 | CV19: =CU19-CU18 -> 0 | CY19: =CX19-CX18 -> 0
... A30: 24 | B30: ='Entries Feb.''25'!N31-'Entries Feb.''25'!N30 -> 14.34 | C30: =IF(B30/'PROD.FIG. '!H28<1,0,B30/'PROD.FIG. '!H28) -> #DIV/0! | E30: ='Entries Feb.''25'!L31-'Entries Feb.''25'!L30 -> 0 | F30: =+$B30 -> 14.34 | I30: =IF((('Entries Feb.''25'!AL30-'Entries Feb.''25'!AL31)/10)*5455<0,"0",(('Entries Feb.''25'!AL30-'Entries Feb.''25'!AL31)/10)*5455) -> 0 | J30: =IF((('Entries Feb.''25'!AM30-'Entries Feb.''25'!AM31)/10)*5455<0,"0",(('Entries Feb.''25'!AM30-'Entries Feb.''25'!AM31)/10)*5455) -> 0 | K30: =IF(('Entries Feb.''25'!AN30-'Entries Feb.''25'!AN31)/2.2<0,"0",('Entries Feb.''25'!AN30-'Entries Feb.''25'!AN31)/2.2) -> 0 | L30: =IF(('Entries Feb.''25'!AO30-'Entries Feb.''25'!AO31)<0,"0",('Entries Feb.''25'!AO30-'Entries Feb.''25'!AO31)) -> 0 | S30: =R30-R29 -> 0 | V30: =U30-U29 -> 0 | Y30: =X30-X29 -> 0 | AB30: =AA30-AA29 -> 0 | AE30: =AD30-AD29 -> 0 | AH30: =AG30-AG29 -> 0 | AK30: =AJ30-AJ29 -> 0 | AN30: =AM30-AM29 -> 0 | AQ30: =AP30-AP29 -> 0 | AT30: =AS30-AS29 -> 0 | AW30: =AV30-AV29 -> 0 | AZ30: =AY30-AY29 -> 0 | BC30: =BB30-BB29 -> 0 | BF30: =BE30-BE29 -> 0 | BI30: =BH30-BH29 -> 0 | BL30: =BK30-BK29 -> 0 | BO30: =BN30-BN29 -> 0 | BR30: =BQ30-BQ29 -> 0 | BU30: =BT30-BT29 -> 0 | BX30: =BW30-BW29 -> 0 | CA30: =BZ30-BZ29 -> 0 | CD30: =CC30-CC29 -> 0 | CG30: =CF30-CF29 -> 0 | CJ30: =CI30-CI29 -> 0 | CM30: =CL30-CL29 -> 0 | CP30: =CO30-CO29 -> 0 | CS30: =CR30-CR29 -> 0 | CV30: =CU30-CU29 -> 0 | CY30: =CX30-CX29 -> 0
A31: 25 | B31: ='Entries Feb.''25'!N32-'Entries Feb.''25'!N31 -> 19.01 | C31: =IF(B31/'PROD.FIG. '!H29<1,0,B31/'PROD.FIG. '!H29) -> #DIV/0! | E31: ='Entries Feb.''25'!L32-'Entries Feb.''25'!L31 -> 0 | F31: =+$B31 -> 19.01 | I31: =IF((('Entries Feb.''25'!AL31-'Entries Feb.''25'!AL32)/10)*5455<0,"0",(('Entries Feb.''25'!AL31-'Entries Feb.''25'!AL32)/10)*5455) -> 0 | J31: =IF((('Entries Feb.''25'!AM31-'Entries Feb.''25'!AM32)/10)*5455<0,"0",(('Entries Feb.''25'!AM31-'Entries Feb.''25'!AM32)/10)*5455) -> 0 | K31: =IF(('Entries Feb.''25'!AN31-'Entries Feb.''25'!AN32)/2.2<0,"0",('Entries Feb.''25'!AN31-'Entries Feb.''25'!AN32)/2.2) -> 0 | L31: =IF(('Entries Feb.''25'!AO31-'Entries Feb.''25'!AO32)<0,"0",('Entries Feb.''25'!AO31-'Entries Feb.''25'!AO32)) -> 0 | S31: =SUM(S6:S29) -> 0 | V31: =SUM(V6:V29) -> 0 | Y31: =SUM(Y6:Y29) -> 0 | AB31: =SUM(AB6:AB29) -> 0 | AE31: =SUM(AE6:AE29) -> 0 | AH31: =SUM(AH6:AH29) -> 0 | AK31: =SUM(AK6:AK29) -> 0 | AN31: =SUM(AN6:AN29) -> 0 | AQ31: =SUM(AQ6:AQ29) -> 0 | AT31: =SUM(AT6:AT29) -> 0 | AW31: =SUM(AW6:AW29) -> 0 | AZ31: =SUM(AZ6:AZ29) -> 0 | BC31: =SUM(BC6:BC29) -> 0 | BF31: =SUM(BF6:BF29) -> 0 | BI31: =SUM(BI6:BI29) -> 0 | BL31: =SUM(BL6:BL29) -> 0 | BO31: =SUM(BO6:BO29) -> 0 | BR31: =SUM(BR6:BR29) -> 0 | BU31: =SUM(BU6:BU29) -> 0 | BX31: =SUM(BX6:BX29) -> 0 | CA31: =SUM(CA6:CA29) -> 0 | CD31: =SUM(CD6:CD29) -> 0 | CG31: =SUM(CG6:CG29) -> 0 | CJ31: =SUM(CJ6:CJ29) -> 0 | CM31: =SUM(CM6:CM29) -> 0 | CP31: =SUM(CP6:CP29) -> 0 | CS31: =SUM(CS6:CS29) -> 0 | CV31: =SUM(CV6:CV29) -> 0 | CY31: =SUM(CY6:CY29) -> 0
A32: 26 | B32: ='Entries Feb.''25'!N33-'Entries Feb.''25'!N32 -> 28.09 | C32: =IF(B32/'PROD.FIG. '!H30<1,0,B32/'PROD.FIG. '!H30) -> #DIV/0! | E32: ='Entries Feb.''25'!L33-'Entries Feb.''25'!L32 -> 0 | F32: =+$B32 -> 28.09 | I32: =IF((('Entries Feb.''25'!AL32-'Entries Feb.''25'!AL33)/10)*5455<0,"0",(('Entries Feb.''25'!AL32-'Entries Feb.''25'!AL33)/10)*5455) -> 0 | J32: =IF((('Entries Feb.''25'!AM32-'Entries Feb.''25'!AM33)/10)*5455<0,"0",(('Entries Feb.''25'!AM32-'Entries Feb.''25'!AM33)/10)*5455) -> 0 | K32: =IF(('Entries Feb.''25'!AN32-'Entries Feb.''25'!AN33)/2.2<0,"0",('Entries Feb.''25'!AN32-'Entries Feb.''25'!AN33)/2.2) -> 0 | L32: =IF(('Entries Feb.''25'!AO32-'Entries Feb.''25'!AO33)<0,"0",('Entries Feb.''25'!AO32-'Entries Feb.''25'!AO33)) -> 0
A33: 27 | B33: ='Entries Feb.''25'!N34-'Entries Feb.''25'!N33 -> 6.57 | C33: =IF(B33/'PROD.FIG. '!H31<1,0,B33/'PROD.FIG. '!H31) -> #DIV/0! | E33: ='Entries Feb.''25'!L34-'Entries Feb.''25'!L33 -> 0 | F33: =+$B33 -> 6.57 | I33: =IF((('Entries Feb.''25'!AL33-'Entries Feb.''25'!AL34)/10)*5455<0,"0",(('Entries Feb.''25'!AL33-'Entries Feb.''25'!AL34)/10)*5455) -> 0 | J33: =IF((('Entries Feb.''25'!AM33-'Entries Feb.''25'!AM34)/10)*5455<0,"0",(('Entries Feb.''25'!AM33-'Entries Feb.''25'!AM34)/10)*5455) -> 0 | K33: =IF(('Entries Feb.''25'!AN33-'Entries Feb.''25'!AN34)/2.2<0,"0",('Entries Feb.''25'!AN33-'Entries Feb.''25'!AN34)/2.2) -> 0 | L33: =IF(('Entries Feb.''25'!AO33-'Entries Feb.''25'!AO34)<0,"0",('Entries Feb.''25'!AO33-'Entries Feb.''25'!AO34)) -> 0
A34: 28 | B34: ='Entries Feb.''25'!N35-'Entries Feb.''25'!N34 -> 16 | C34: =IF(B34/'PROD.FIG. '!H32<1,0,B34/'PROD.FIG. '!H32) -> #DIV/0! | E34: ='Entries Feb.''25'!L35-'Entries Feb.''25'!L34 -> 0 | F34: =+$B34 -> 16 | I34: =IF((('Entries Feb.''25'!AL34-'Entries Feb.''25'!AL35)/10)*5455<0,"0",(('Entries Feb.''25'!AL34-'Entries Feb.''25'!AL35)/10)*5455) -> 0 | J34: =IF((('Entries Feb.''25'!AM34-'Entries Feb.''25'!AM35)/10)*5455<0,"0",(('Entries Feb.''25'!AM34-'Entries Feb.''25'!AM35)/10)*5455) -> 0 | K34: =IF(('Entries Feb.''25'!AN34-'Entries Feb.''25'!AN35)/2.2<0,"0",('Entries Feb.''25'!AN34-'Entries Feb.''25'!AN35)/2.2) -> 0 | L34: =IF(('Entries Feb.''25'!AO34-'Entries Feb.''25'!AO35)<0,"0",('Entries Feb.''25'!AO34-'Entries Feb.''25'!AO35)) -> 0
A35: 29 | C35: =IF(B35/'PROD.FIG. '!H33<1,0,B35/'PROD.FIG. '!H33) -> #DIV/0! | E35: ='Entries Feb.''25'!L36-'Entries Feb.''25'!L35 -> 0 | F35: =+$B35 -> 0 | I35: =IF((('Entries Feb.''25'!AL35-'Entries Feb.''25'!AL36)/10)*5455<0,"0",(('Entries Feb.''25'!AL35-'Entries Feb.''25'!AL36)/10)*5455) -> 0 | J35: =IF((('Entries Feb.''25'!AM35-'Entries Feb.''25'!AM36)/10)*5455<0,"0",(('Entries Feb.''25'!AM35-'Entries Feb.''25'!AM36)/10)*5455) -> 0 | K35: =IF(('Entries Feb.''25'!AN35-'Entries Feb.''25'!AN36)/2.2<0,"0",('Entries Feb.''25'!AN35-'Entries Feb.''25'!AN36)/2.2) -> 0 | L35: =IF(('Entries Feb.''25'!AO35-'Entries Feb.''25'!AO36)<0,"0",('Entries Feb.''25'!AO35-'Entries Feb.''25'!AO36)) -> 0
