Workbook
Name Products: #REF!
Name Products: #REF!
Name Products: #REF!
Name Products: #REF!
Name Products: #REF!
Name Products: #REF!
Name Products: #REF!

Sheet MTD Performance
C2: FTR OVERALL PERFORMANCE ACHIEVEMENT
C3: January | D3: February | E3: March | F3: April | G3: May | H3: June | I3: July | J3: August | K3: September | L3: October | M3: November | N3: December | O3: YTD
B4: R. Regis | C4: =AVERAGEIF('FTR Brewhouse'!$J$17:$J$19,'MTD Performance'!$B4,'FTR Brewhouse'!$I$17:$I$19) -> #DIV/0! | D4: =AVERAGEIF('FTR Brewhouse'!#REF!,'MTD Performance'!$B4,'FTR Brewhouse'!#REF!) -> #REF! | E4: =AVERAGEIF('FTR Brewhouse'!#REF!,'MTD Performance'!$B4,'FTR Brewhouse'!#REF!) -> #REF! | F4: =AVERAGEIF('FTR Brewhouse'!#REF!,'MTD Performance'!$B4,'FTR Brewhouse'!#REF!) -> #REF! | G4: =AVERAGEIF('FTR Brewhouse'!#REF!,'MTD Performance'!$B4,'FTR Brewhouse'!#REF!) -> #REF! | H4: =AVERAGEIF('FTR Brewhouse'!#REF!,'MTD Performance'!$B4,'FTR Brewhouse'!#REF!) -> #REF! | J4: =AVERAGEIF('FTR Brewhouse'!#REF!,'MTD Performance'!$B4,'FTR Brewhouse'!#REF!) -> #REF! | O4: =AVERAGE(C4:N4) -> #DIV/0!
B5: J.Greenidge | C5: =AVERAGEIF('FTR Brewhouse'!$J$17:$J$19,'MTD Performance'!$B5,'FTR Brewhouse'!$I$17:$I$19) -> #DIV/0! | D5: =AVERAGEIF('FTR Brewhouse'!#REF!,'MTD Performance'!$B5,'FTR Brewhouse'!#REF!) -> #REF! | E5: =AVERAGEIF('FTR Brewhouse'!#REF!,'MTD Performance'!$B5,'FTR Brewhouse'!#REF!) -> #REF! | F5: =AVERAGEIF('FTR Brewhouse'!#REF!,'MTD Performance'!$B5,'FTR Brewhouse'!#REF!) -> #REF! | G5: =AVERAGEIF('FTR Brewhouse'!#REF!,'MTD Performance'!$B5,'FTR Brewhouse'!#REF!) -> #REF! | H5: =AVERAGEIF('FTR Brewhouse'!#REF!,'MTD Performance'!$B5,'FTR Brewhouse'!#REF!) -> #REF! | I5: =AVERAGEIF('FTR Brewhouse'!#REF!,'MTD Performance'!$B5,'FTR Brewhouse'!#REF!) -> #REF! | J5: =AVERAGEIF('FTR Brewhouse'!#REF!,'MTD Performance'!$B5,'FTR Brewhouse'!#REF!) -> #REF! | O5: =AVERAGE(C5:N5) -> #DIV/0!
B6: K. Williams | C6: =AVERAGEIF('FTR Brewhouse'!$J$17:$J$19,'MTD Performance'!$B6,'FTR Brewhouse'!$I$17:$I$19) -> #DIV/0! | D6: =AVERAGEIF('FTR Brewhouse'!#REF!,'MTD Performance'!$B6,'FTR Brewhouse'!#REF!) -> #REF! | J6: =AVERAGEIF('FTR Brewhouse'!#REF!,'MTD Performance'!$B6,'FTR Brewhouse'!#REF!) -> #REF! | O6: =AVERAGE(C6:N6) -> #DIV/0!
B7: K. Benjamin | D7: =AVERAGEIF('FTR Brewhouse'!#REF!,'MTD Performance'!$B7,'FTR Brewhouse'!#REF!) -> #REF! | E7: =AVERAGEIF('FTR Brewhouse'!#REF!,'MTD Performance'!$B7,'FTR Brewhouse'!#REF!) -> #REF! | F7: =AVERAGEIF('FTR Brewhouse'!#REF!,'MTD Performance'!$B7,'FTR Brewhouse'!#REF!) -> #REF! | G7: =AVERAGEIF('FTR Brewhouse'!#REF!,'MTD Performance'!$B7,'FTR Brewhouse'!#REF!) -> #REF! | H7: =AVERAGEIF('FTR Brewhouse'!#REF!,'MTD Performance'!$B7,'FTR Brewhouse'!#REF!) -> #REF! | I7: =AVERAGEIF('FTR Brewhouse'!#REF!,'MTD Performance'!$B7,'FTR Brewhouse'!#REF!) -> #REF! | J7: =AVERAGEIF('FTR Brewhouse'!#REF!,'MTD Performance'!$B7,'FTR Brewhouse'!#REF!) -> #REF! | O7: =AVERAGE(C7:N7) -> #REF!
B8: J.Grant | I8: =AVERAGEIF('FTR Brewhouse'!#REF!,'MTD Performance'!$B8,'FTR Brewhouse'!#REF!) -> #REF! | J8: =AVERAGEIF('FTR Brewhouse'!#REF!,'MTD Performance'!$B8,'FTR Brewhouse'!#REF!) -> #REF! | O8: =AVERAGE(C8:N8) -> #REF!
B9: K. Bridgeman | G9: =AVERAGEIF('FTR Brewhouse'!#REF!,'MTD Performance'!$B9,'FTR Brewhouse'!#REF!) -> #REF! | O9: =AVERAGE(C9:N9) -> #REF!
C11: January | E11: February | G11: March | I11: April | K11: May | M11: June | O11: July
C12: Original Extract (°P) | D12: Total Brewing time | E12: Original Extract (°P) | F12: Total Brewing time | G12: Original Extract (°P) | H12: Total Brewing time | I12: Original Extract (°P) | J12: Total Brewing time | K12: Original Extract (°P) | L12: Total Brewing time | M12: Original Extract (°P) | N12: Total Brewing time | O12: Original Extract (°P) | P12: Total Brewing time
B13: R. Regis | C13: =AVERAGEIF('FTR Brewhouse'!$J$17:$J$19,'MTD Performance'!$B13,'FTR Brewhouse'!$D$17:$D$19) -> #DIV/0! | D13: =AVERAGEIF('FTR Brewhouse'!$J$17:$J$19,'MTD Performance'!$B13,'FTR Brewhouse'!#REF!) -> #REF! | E13: =AVERAGEIF('FTR Brewhouse'!#REF!,'MTD Performance'!$B13,'FTR Brewhouse'!#REF!) -> #REF! | F13: =AVERAGEIF('FTR Brewhouse'!#REF!,'MTD Performance'!$B13,'FTR Brewhouse'!#REF!) -> #REF! | G13: =AVERAGEIF('FTR Brewhouse'!#REF!,'MTD Performance'!$B13,'FTR Brewhouse'!#REF!) -> #REF! | H13: =AVERAGEIF('FTR Brewhouse'!#REF!,'MTD Performance'!$B13,'FTR Brewhouse'!#REF!) -> #REF! | I13: =AVERAGEIF('FTR Brewhouse'!#REF!,'MTD Performance'!$B13,'FTR Brewhouse'!#REF!) -> #REF! | J13: =AVERAGEIF('FTR Brewhouse'!#REF!,'MTD Performance'!$B13,'FTR Brewhouse'!#REF!) -> #REF! | K13: =AVERAGEIF('FTR Brewhouse'!#REF!,'MTD Performance'!$B13,'FTR Brewhouse'!#REF!) -> #REF! | L13: =AVERAGEIF('FTR Brewhouse'!#REF!,'MTD Performance'!$B13,'FTR Brewhouse'!#REF!) -> #REF! | ... N13: =AVERAGEIF('FTR Brewhouse'!#REF!,'MTD Performance'!$B13,'FTR Brewhouse'!#REF!) -> #REF!
B14: J.Greenidge | C14: =AVERAGEIF('FTR Brewhouse'!$J$17:$J$19,'MTD Performance'!$B14,'FTR Brewhouse'!$D$17:$D$19) -> #DIV/0! | D14: =AVERAGEIF('FTR Brewhouse'!$J$17:$J$19,'MTD Performance'!$B14,'FTR Brewhouse'!#REF!) -> #REF! | E14: =AVERAGEIF('FTR Brewhouse'!#REF!,'MTD Performance'!$B14,'FTR Brewhouse'!#REF!) -> #REF! | F14: =AVERAGEIF('FTR Brewhouse'!#REF!,'MTD Performance'!$B14,'FTR Brewhouse'!#REF!) -> #REF! | G14: =AVERAGEIF('FTR Brewhouse'!#REF!,'MTD Performance'!$B14,'FTR Brewhouse'!#REF!) -> #REF! | H14: =AVERAGEIF('FTR Brewhouse'!#REF!,'MTD Performance'!$B14,'FTR Brewhouse'!#REF!) -> #REF! | I14: =AVERAGEIF('FTR Brewhouse'!#REF!,'MTD Performance'!$B14,'FTR Brewhouse'!#REF!) -> #REF! | J14: =AVERAGEIF('FTR Brewhouse'!#REF!,'MTD Performance'!$B14,'FTR Brewhouse'!#REF!) -> #REF! | K14: =AVERAGEIF('FTR Brewhouse'!#REF!,'MTD Performance'!$B14,'FTR Brewhouse'!#REF!) -> #REF! | L14: =AVERAGEIF('FTR Brewhouse'!#REF!,'MTD Performance'!$B14,'FTR Brewhouse'!#REF!) -> #REF! | ... P14: =AVERAGEIF('FTR Brewhouse'!#REF!,'MTD Performance'!$B14,'FTR Brewhouse'!#REF!) -> #REF!
B15: K. Williams | C15: =AVERAGEIF('FTR Brewhouse'!$J$17:$J$19,'MTD Performance'!$B15,'FTR Brewhouse'!$D$17:$D$19) -> #DIV/0! | D15: =AVERAGEIF('FTR Brewhouse'!$J$17:$J$19,'MTD Performance'!$B15,'FTR Brewhouse'!#REF!) -> #REF! | E15: =AVERAGEIF('FTR Brewhouse'!#REF!,'MTD Performance'!$B15,'FTR Brewhouse'!#REF!) -> #REF! | F15: =AVERAGEIF('FTR Brewhouse'!#REF!,'MTD Performance'!$B15,'FTR Brewhouse'!#REF!) -> #REF!
B16: K. Benjamin | E16: =AVERAGEIF('FTR Brewhouse'!#REF!,'MTD Performance'!$B16,'FTR Brewhouse'!#REF!) -> #REF! | F16: =AVERAGEIF('FTR Brewhouse'!#REF!,'MTD Performance'!$B16,'FTR Brewhouse'!#REF!) -> #REF! | G16: =AVERAGEIF('FTR Brewhouse'!#REF!,'MTD Performance'!$B16,'FTR Brewhouse'!#REF!) -> #REF! | H16: =AVERAGEIF('FTR Brewhouse'!#REF!,'MTD Performance'!$B16,'FTR Brewhouse'!#REF!) -> #REF! | I16: =AVERAGEIF('FTR Brewhouse'!#REF!,'MTD Performance'!$B16,'FTR Brewhouse'!#REF!) -> #REF! | J16: =AVERAGEIF('FTR Brewhouse'!#REF!,'MTD Performance'!$B16,'FTR Brewhouse'!#REF!) -> #REF! | K16: =AVERAGEIF('FTR Brewhouse'!#REF!,'MTD Performance'!$B16,'FTR Brewhouse'!#REF!) -> #REF! | L16: =AVERAGEIF('FTR Brewhouse'!#REF!,'MTD Performance'!$B16,'FTR Brewhouse'!#REF!) -> #REF! | ... P16: =AVERAGEIF('FTR Brewhouse'!#REF!,'MTD Performance'!$B16,'FTR Brewhouse'!#REF!) -> #REF!
B17: J.Grant | O17: =AVERAGEIF('FTR Brewhouse'!#REF!,'MTD Performance'!$B17,'FTR Brewhouse'!#REF!) -> #REF! | P17: =AVERAGEIF('FTR Brewhouse'!#REF!,'MTD Performance'!$B17,'FTR Brewhouse'!#REF!) -> #REF!
B18: K. Bridgeman | K18: =AVERAGEIF('FTR Brewhouse'!#REF!,'MTD Performance'!$B18,'FTR Brewhouse'!#REF!) -> #REF! | L18: =AVERAGEIF('FTR Brewhouse'!#REF!,'MTD Performance'!$B18,'FTR Brewhouse'!#REF!) -> #REF!

Sheet Brewer's Performance 
C3: January
C4: Original Extract (°P) | D4: Total Brewing time | E4: Extract Recovery | F4: Percentage
B5: R. Regis | C5: =AVERAGEIF('FTR Brewhouse'!$J$17:$J$19,'Brewer''s Performance '!$B5,'FTR Brewhouse'!$D$17:$D$19) -> #DIV/0! | D5: =AVERAGEIF('FTR Brewhouse'!$J$17:$J$19,'Brewer''s Performance '!$B5,'FTR Brewhouse'!#REF!) -> #REF! | E5: 0.9793 | F5: =(C5+D5+E5)/3 -> #DIV/0!
B6: J.Greenidge | C6: =AVERAGEIF('FTR Brewhouse'!$J$17:$J$19,'Brewer''s Performance '!$B6,'FTR Brewhouse'!$D$17:$D$19) -> #DIV/0! | D6: =AVERAGEIF('FTR Brewhouse'!$J$17:$J$19,'Brewer''s Performance '!$B6,'FTR Brewhouse'!#REF!) -> #REF! | E6: 0.9907 | F6: =(C6+D6+E6)/3 -> #DIV/0!
B7: K. Williams | C7: =AVERAGEIF('FTR Brewhouse'!$J$17:$J$19,'Brewer''s Performance '!$B7,'FTR Brewhouse'!$D$17:$D$19) -> #DIV/0! | D7: =AVERAGEIF('FTR Brewhouse'!$J$17:$J$19,'Brewer''s Performance '!$B7,'FTR Brewhouse'!#REF!) -> #REF! | E7: 0.9798 | F7: =(C7+D7+E7)/3 -> #DIV/0!
B8: K. Benjamin
B9: J.Grant
B10: K. Bridgeman
C12: February
C13: Original Extract (°P) | D13: Total Brewing time | E13: Extract Recovery | F13: Percentage
B14: R. Regis | C14: =AVERAGEIF('FTR Brewhouse'!#REF!,'Brewer''s Performance '!$B14,'FTR Brewhouse'!#REF!) -> #REF! | D14: =AVERAGEIF('FTR Brewhouse'!#REF!,'Brewer''s Performance '!$B14,'FTR Brewhouse'!#REF!) -> #REF! | E14: 0.9825 | F14: =(C14+D14+E14)/3 -> #REF!
B15: J.Greenidge | C15: =AVERAGEIF('FTR Brewhouse'!#REF!,'Brewer''s Performance '!$B15,'FTR Brewhouse'!#REF!) -> #REF! | D15: =AVERAGEIF('FTR Brewhouse'!#REF!,'Brewer''s Performance '!$B15,'FTR Brewhouse'!#REF!) -> #REF! | E15: 0.9798 | F15: =(C15+D15+E15)/3 -> #REF!
B16: K. Williams | C16: =AVERAGEIF('FTR Brewhouse'!#REF!,'Brewer''s Performance '!$B16,'FTR Brewhouse'!#REF!) -> #REF! | D16: =AVERAGEIF('FTR Brewhouse'!#REF!,'Brewer''s Performance '!$B16,'FTR Brewhouse'!#REF!) -> #REF! | E16: 0.9709 | F16: =(C16+D16+E16)/3 -> #REF!
B17: K. Benjamin | C17: =AVERAGEIF('FTR Brewhouse'!#REF!,'Brewer''s Performance '!$B17,'FTR Brewhouse'!#REF!) -> #REF! | D17: =AVERAGEIF('FTR Brewhouse'!#REF!,'Brewer''s Performance '!$B17,'FTR Brewhouse'!#REF!) -> #REF! | E17: 0.9808 | F17: =(C17+D17+E17)/3 -> #REF!
B18: J.Grant
B19: K. Bridgeman
C21: March
C22: Original Extract (°P) | D22: Total Brewing time | E22: Extract Recovery | F22: Percentage
B23: R. Regis | C23: =AVERAGEIF('FTR Brewhouse'!#REF!,'Brewer''s Performance '!$B23,'FTR Brewhouse'!#REF!) -> #REF! | D23: =AVERAGEIF('FTR Brewhouse'!#REF!,'Brewer''s Performance '!$B23,'FTR Brewhouse'!#REF!) -> #REF! | E23: 0.9694 | F23: =(C23+D23+E23)/3 -> #REF!
B24: J.Greenidge | C24: =AVERAGEIF('FTR Brewhouse'!#REF!,'Brewer''s Performance '!$B24,'FTR Brewhouse'!#REF!) -> #REF! | D24: =AVERAGEIF('FTR Brewhouse'!#REF!,'Brewer''s Performance '!$B24,'FTR Brewhouse'!#REF!) -> #REF! | E24: 0.9757 | F24: =(C24+D24+E24)/3 -> #REF!
B25: K. Williams
B26: K. Benjamin | C26: =AVERAGEIF('FTR Brewhouse'!#REF!,'Brewer''s Performance '!$B26,'FTR Brewhouse'!#REF!) -> #REF! | D26: =AVERAGEIF('FTR Brewhouse'!#REF!,'Brewer''s Performance '!$B26,'FTR Brewhouse'!#REF!) -> #REF! | E26: 0.9601 | F26: =(C26+D26+E26)/3 -> #REF!
B27: J.Grant
B28: K. Bridgeman
C30: April
C31: Original Extract (°P) | D31: Total Brewing time | E31: Extract Recovery | F31: Percentage
B32: R. Regis | C32: =AVERAGEIF('FTR Brewhouse'!#REF!,'Brewer''s Performance '!$B32,'FTR Brewhouse'!#REF!) -> #REF! | D32: =AVERAGEIF('FTR Brewhouse'!#REF!,'Brewer''s Performance '!$B32,'FTR Brewhouse'!#REF!) -> #REF! | E32: 0.985 | F32: =(C32+D32+E32)/3 -> #REF!
B33: J.Greenidge | C33: =AVERAGEIF('FTR Brewhouse'!#REF!,'Brewer''s Performance '!$B33,'FTR Brewhouse'!#REF!) -> #REF! | D33: =AVERAGEIF('FTR Brewhouse'!#REF!,'Brewer''s Performance '!$B33,'FTR Brewhouse'!#REF!) -> #REF! | E33: 0.985 | F33: =(C33+D33+E33)/3 -> #REF!
B34: K. Williams
B35: K. Benjamin | C35: =AVERAGEIF('FTR Brewhouse'!#REF!,'Brewer''s Performance '!$B35,'FTR Brewhouse'!#REF!) -> #REF! | D35: =AVERAGEIF('FTR Brewhouse'!#REF!,'Brewer''s Performance '!$B35,'FTR Brewhouse'!#REF!) -> #REF! | E35: 0.9777 | F35: =(C35+D35+E35)/3 -> #REF!
B36: J.Grant
B37: K. Bridgeman
C39: May
C40: Original Extract (°P) | D40: Total Brewing time | E40: Extract Recovery | F40: Percentage
B41: R. Regis | C41: =AVERAGEIF('FTR Brewhouse'!#REF!,'Brewer''s Performance '!$B41,'FTR Brewhouse'!#REF!) -> #REF! | D41: =AVERAGEIF('FTR Brewhouse'!#REF!,'Brewer''s Performance '!$B41,'FTR Brewhouse'!#REF!) -> #REF! | E41: 0.987 | F41: =(C41+D41+E41)/3 -> #REF!
B42: J.Greenidge | C42: =AVERAGEIF('FTR Brewhouse'!#REF!,'Brewer''s Performance '!$B42,'FTR Brewhouse'!#REF!) -> #REF! | D42: =AVERAGEIF('FTR Brewhouse'!#REF!,'Brewer''s Performance '!$B42,'FTR Brewhouse'!#REF!) -> #REF! | E42: 0.987 | F42: =(C42+D42+E42)/3 -> #REF!
B43: K. Williams
B44: K. Benjamin | C44: =AVERAGEIF('FTR Brewhouse'!#REF!,'Brewer''s Performance '!$B44,'FTR Brewhouse'!#REF!) -> #REF! | D44: =AVERAGEIF('FTR Brewhouse'!#REF!,'Brewer''s Performance '!$B44,'FTR Brewhouse'!#REF!) -> #REF! | E44: 0.987 | F44: =(C44+D44+E44)/3 -> #REF!
B45: J.Grant
B46: K. Bridgeman | C46: =AVERAGEIF('FTR Brewhouse'!#REF!,'Brewer''s Performance '!$B46,'FTR Brewhouse'!#REF!) -> #REF! | D46: =AVERAGEIF('FTR Brewhouse'!#REF!,'Brewer''s Performance '!$B46,'FTR Brewhouse'!#REF!) -> #REF! | E46: 0.9897 | F46: =(C46+D46+E46)/3 -> #REF!
...

Sheet MTD - Time & OG
C3: January | F3: February | I3: March | L3: April | O3: May | R3: June | U3: July | X3: August
C4: Original Extract (°P) | D4: Total Brewing time | E4: OVERALL FTR PERFORMANCE | F4: Original Extract (°P) | G4: Total Brewing time | H4: OVERALL FTR PERFORMANCE | I4: Original Extract (°P) | J4: Total Brewing time | K4: OVERALL FTR PERFORMANCE | L4: Original Extract (°P) | M4: Total Brewing time | N4: OVERALL FTR PERFORMANCE | O4: Original Extract (°P) | P4: Total Brewing time | Q4: OVERALL FTR PERFORMANCE | R4: Original Extract (°P) | S4: Total Brewing time | T4: OVERALL FTR PERFORMANCE | U4: Original Extract (°P) | V4: Total Brewing time | W4: OVERALL FTR PERFORMANCE | X4: Original Extract (°P) | Y4: Total Brewing time | Z4: OVERALL FTR PERFORMANCE
B5: R. Regis | C5: =AVERAGEIF('FTR Brewhouse'!$J$17:$J$19,'MTD - Time & OG'!$B5,'FTR Brewhouse'!$D$17:$D$19) -> #DIV/0! | D5: =AVERAGEIF('FTR Brewhouse'!$J$17:$J$19,'MTD - Time & OG'!$B5,'FTR Brewhouse'!#REF!) -> #REF! | E5: ='MTD Performance'!C4 -> #DIV/0! | F5: =AVERAGEIF('FTR Brewhouse'!#REF!,'MTD - Time & OG'!$B5,'FTR Brewhouse'!#REF!) -> #REF! | G5: =AVERAGEIF('FTR Brewhouse'!#REF!,'MTD - Time & OG'!$B5,'FTR Brewhouse'!#REF!) -> #REF! | H5: ='MTD Performance'!D4 -> #REF! | I5: =AVERAGEIF('FTR Brewhouse'!#REF!,'MTD - Time & OG'!$B5,'FTR Brewhouse'!#REF!) -> #REF! | J5: =AVERAGEIF('FTR Brewhouse'!#REF!,'MTD - Time & OG'!$B5,'FTR Brewhouse'!#REF!) -> #REF! | K5: ='MTD Performance'!E4 -> #REF! | L5: =AVERAGEIF('FTR Brewhouse'!#REF!,'MTD - Time & OG'!$B5,'FTR Brewhouse'!#REF!) -> #REF! | M5: =AVERAGEIF('FTR Brewhouse'!#REF!,'MTD - Time & OG'!$B5,'FTR Brewhouse'!#REF!) -> #REF! | N5: ='MTD Performance'!F4 -> #REF! | O5: =AVERAGEIF('FTR Brewhouse'!#REF!,'MTD - Time & OG'!$B5,'FTR Brewhouse'!#REF!) -> #REF! | P5: =AVERAGEIF('FTR Brewhouse'!#REF!,'MTD - Time & OG'!$B5,'FTR Brewhouse'!#REF!) -> #REF! | Q5: ='MTD Performance'!G4 -> #REF! | R5: =AVERAGEIF('FTR Brewhouse'!#REF!,'MTD - Time & OG'!$B5,'FTR Brewhouse'!#REF!) -> #REF! | S5: =AVERAGEIF('FTR Brewhouse'!#REF!,'MTD - Time & OG'!$B5,'FTR Brewhouse'!#REF!) -> #REF! | T5: ='MTD Performance'!H4 -> #REF! | U5: NA | V5: NA | W5: NA | X5: =AVERAGEIF('FTR Brewhouse'!#REF!,'MTD - Time & OG'!$B5,'FTR Brewhouse'!#REF!) -> #REF! | Y5: =AVERAGEIF('FTR Brewhouse'!#REF!,'MTD - Time & OG'!$B5,'FTR Brewhouse'!#REF!) -> #REF! | Z5: ='MTD Performance'!J4 -> #REF!
B6: J.Greenidge | C6: =AVERAGEIF('FTR Brewhouse'!$J$17:$J$19,'MTD - Time & OG'!$B6,'FTR Brewhouse'!$D$17:$D$19) -> #DIV/0! | D6: =AVERAGEIF('FTR Brewhouse'!$J$17:$J$19,'MTD - Time & OG'!$B6,'FTR Brewhouse'!#REF!) -> #REF! | E6: ='MTD Performance'!C5 -> #DIV/0! | F6: =AVERAGEIF('FTR Brewhouse'!#REF!,'MTD - Time & OG'!$B6,'FTR Brewhouse'!#REF!) -> #REF! | G6: =AVERAGEIF('FTR Brewhouse'!#REF!,'MTD - Time & OG'!$B6,'FTR Brewhouse'!#REF!) -> #REF! | H6: ='MTD Performance'!D5 -> #REF! | I6: =AVERAGEIF('FTR Brewhouse'!#REF!,'MTD - Time & OG'!$B6,'FTR Brewhouse'!#REF!) -> #REF! | J6: =AVERAGEIF('FTR Brewhouse'!#REF!,'MTD - Time & OG'!$B6,'FTR Brewhouse'!#REF!) -> #REF! | K6: ='MTD Performance'!E5 -> #REF! | L6: =AVERAGEIF('FTR Brewhouse'!#REF!,'MTD - Time & OG'!$B6,'FTR Brewhouse'!#REF!) -> #REF! | M6: =AVERAGEIF('FTR Brewhouse'!#REF!,'MTD - Time & OG'!$B6,'FTR Brewhouse'!#REF!) -> #REF! | N6: ='MTD Performance'!F5 -> #REF! | O6: =AVERAGEIF('FTR Brewhouse'!#REF!,'MTD - Time & OG'!$B6,'FTR Brewhouse'!#REF!) -> #REF! | P6: =AVERAGEIF('FTR Brewhouse'!#REF!,'MTD - Time & OG'!$B6,'FTR Brewhouse'!#REF!) -> #REF! | Q6: ='MTD Performance'!G5 -> #REF! | R6: =AVERAGEIF('FTR Brewhouse'!#REF!,'MTD - Time & OG'!$B6,'FTR Brewhouse'!#REF!) -> #REF! | S6: =AVERAGEIF('FTR Brewhouse'!#REF!,'MTD - Time & OG'!$B6,'FTR Brewhouse'!#REF!) -> #REF! | T6: ='MTD Performance'!H5 -> #REF! | U6: =AVERAGEIF('FTR Brewhouse'!#REF!,'MTD - Time & OG'!$B6,'FTR Brewhouse'!#REF!) -> #REF! | V6: =AVERAGEIF('FTR Brewhouse'!#REF!,'MTD - Time & OG'!$B6,'FTR Brewhouse'!#REF!) -> #REF! | W6: ='MTD Performance'!I5 -> #REF! | X6: =AVERAGEIF('FTR Brewhouse'!#REF!,'MTD - Time & OG'!$B6,'FTR Brewhouse'!#REF!) -> #REF! | Y6: =AVERAGEIF('FTR Brewhouse'!#REF!,'MTD - Time & OG'!$B6,'FTR Brewhouse'!#REF!) -> #REF! | Z6: ='MTD Performance'!J5 -> #REF!
B7: K. Williams | C7: =AVERAGEIF('FTR Brewhouse'!$J$17:$J$19,'MTD - Time & OG'!$B7,'FTR Brewhouse'!$D$17:$D$19) -> #DIV/0! | D7: =AVERAGEIF('FTR Brewhouse'!$J$17:$J$19,'MTD - Time & OG'!$B7,'FTR Brewhouse'!#REF!) -> #REF! | E7: ='MTD Performance'!C6 -> #DIV/0! | F7: =AVERAGEIF('FTR Brewhouse'!#REF!,'MTD - Time & OG'!$B7,'FTR Brewhouse'!#REF!) -> #REF! | G7: =AVERAGEIF('FTR Brewhouse'!#REF!,'MTD - Time & OG'!$B7,'FTR Brewhouse'!#REF!) -> #REF! | H7: ='MTD Performance'!D6 -> #REF! | I7: NA | J7: NA | K7: NA | L7: NA | M7: NA | N7: NA | O7: NA | P7: NA | Q7: NA | R7: NA | S7: NA | T7: NA | U7: NA | V7: NA | W7: NA | X7: NA | Y7: NA | Z7: NA
B8: K. Benjamin | C8: NA | D8: NA | E8: NA | F8: =AVERAGEIF('FTR Brewhouse'!#REF!,'MTD - Time & OG'!$B8,'FTR Brewhouse'!#REF!) -> #REF! | G8: =AVERAGEIF('FTR Brewhouse'!#REF!,'MTD - Time & OG'!$B8,'FTR Brewhouse'!#REF!) -> #REF! | H8: ='MTD Performance'!D7 -> #REF! | I8: =AVERAGEIF('FTR Brewhouse'!#REF!,'MTD - Time & OG'!$B8,'FTR Brewhouse'!#REF!) -> #REF! | J8: =AVERAGEIF('FTR Brewhouse'!#REF!,'MTD - Time & OG'!$B8,'FTR Brewhouse'!#REF!) -> #REF! | K8: ='MTD Performance'!E7 -> #REF! | L8: =AVERAGEIF('FTR Brewhouse'!#REF!,'MTD - Time & OG'!$B8,'FTR Brewhouse'!#REF!) -> #REF! | M8: =AVERAGEIF('FTR Brewhouse'!#REF!,'MTD - Time & OG'!$B8,'FTR Brewhouse'!#REF!) -> #REF! | N8: ='MTD Performance'!F7 -> #REF! | O8: =AVERAGEIF('FTR Brewhouse'!#REF!,'MTD - Time & OG'!$B8,'FTR Brewhouse'!#REF!) -> #REF! | P8: =AVERAGEIF('FTR Brewhouse'!#REF!,'MTD - Time & OG'!$B8,'FTR Brewhouse'!#REF!) -> #REF! | Q8: ='MTD Performance'!G7 -> #REF! | R8: =AVERAGEIF('FTR Brewhouse'!#REF!,'MTD - Time & OG'!$B8,'FTR Brewhouse'!#REF!) -> #REF! | S8: =AVERAGEIF('FTR Brewhouse'!#REF!,'MTD - Time & OG'!$B8,'FTR Brewhouse'!#REF!) -> #REF! | T8: ='MTD Performance'!H7 -> #REF! | U8: =AVERAGEIF('FTR Brewhouse'!#REF!,'MTD - Time & OG'!$B8,'FTR Brewhouse'!#REF!) -> #REF! | V8: =AVERAGEIF('FTR Brewhouse'!#REF!,'MTD - Time & OG'!$B8,'FTR Brewhouse'!#REF!) -> #REF! | W8: ='MTD Performance'!I7 -> #REF! | X8: =AVERAGEIF('FTR Brewhouse'!#REF!,'MTD - Time & OG'!$B8,'FTR Brewhouse'!#REF!) -> #REF! | Y8: =AVERAGEIF('FTR Brewhouse'!#REF!,'MTD - Time & OG'!$B8,'FTR Brewhouse'!#REF!) -> #REF! | Z8: ='MTD Performance'!J7 -> #REF!
B9: J.Grant | C9: NA | D9: NA | E9: NA | F9: NA | G9: NA | H9: NA | I9: NA | J9: NA | K9: NA | L9: NA | M9: NA | N9: NA | O9: NA | P9: NA | Q9: NA | R9: NA | S9: NA | T9: NA | U9: =AVERAGEIF('FTR Brewhouse'!#REF!,'MTD - Time & OG'!$B9,'FTR Brewhouse'!#REF!) -> #REF! | V9: =AVERAGEIF('FTR Brewhouse'!#REF!,'MTD - Time & OG'!$B9,'FTR Brewhouse'!#REF!) -> #REF! | W9: ='MTD Performance'!I8 -> #REF! | X9: =AVERAGEIF('FTR Brewhouse'!#REF!,'MTD - Time & OG'!$B9,'FTR Brewhouse'!#REF!) -> #REF! | Y9: =AVERAGEIF('FTR Brewhouse'!#REF!,'MTD - Time & OG'!$B9,'FTR Brewhouse'!#REF!) -> #REF! | Z9: ='MTD Performance'!J8 -> #REF!
B10: K. Bridgeman | C10: NA | D10: NA | E10: NA | F10: NA | G10: NA | H10: NA | I10: NA | J10: NA | K10: NA | L10: NA | M10: NA | N10: NA | O10: =AVERAGEIF('FTR Brewhouse'!#REF!,'MTD - Time & OG'!$B10,'FTR Brewhouse'!#REF!) -> #REF! | P10: =AVERAGEIF('FTR Brewhouse'!#REF!,'MTD - Time & OG'!$B10,'FTR Brewhouse'!#REF!) -> #REF! | Q10: ='MTD Performance'!G9 -> #REF! | R10: NA | S10: NA | T10: NA | U10: NA | V10: NA | W10: NA | X10: NA | Y10: NA | Z10: NA

Sheet Brewer's Performance- Extract
C3: January | G3: February | K3: March | O3: April | S3: May | W3: June | AA3: July | AE3: August
C4: Original Extract (°P) | D4: Total Brewing time | E4: Extract Recovery | F4: Percentage | G4: Original Extract (°P) | H4: Total Brewing time | I4: Extract Recovery | J4: Percentage | K4: Original Extract (°P) | L4: Total Brewing time | M4: Extract Recovery | N4: Percentage | O4: Original Extract (°P) | P4: Total Brewing time | Q4: Extract Recovery | R4: Percentage | S4: Original Extract (°P) | T4: Total Brewing time | U4: Extract Recovery | V4: Percentage | W4: Original Extract (°P) | X4: Total Brewing time | Y4: Extract Recovery | Z4: Percentage | AA4: Original Extract (°P) | AB4: Total Brewing time | AC4: Extract Recovery | AD4: Percentage | AE4: Original Extract (°P) | AF4: Total Brewing time | AG4: Extract Recovery | AH4: Percentage
B5: R. Regis | C5: =AVERAGEIF('FTR Brewhouse'!$J$17:$J$19,'Brewer''s Performance- Extract'!$B5,'FTR Brewhouse'!$D$17:$D$19) -> #DIV/0! | D5: =AVERAGEIF('FTR Brewhouse'!$J$17:$J$19,'Brewer''s Performance- Extract'!$B5,'FTR Brewhouse'!#REF!) -> #REF! | E5: 0.9793 | F5: =(C5+D5+E5)/3 -> #DIV/0! | G5: =AVERAGEIF('FTR Brewhouse'!#REF!,'Brewer''s Performance- Extract'!$B5,'FTR Brewhouse'!#REF!) -> #REF! | H5: =AVERAGEIF('FTR Brewhouse'!#REF!,'Brewer''s Performance- Extract'!$B5,'FTR Brewhouse'!#REF!) -> #REF! | I5: 0.9825 | J5: =(G5+H5+I5)/3 -> #REF! | K5: =AVERAGEIF('FTR Brewhouse'!#REF!,'Brewer''s Performance- Extract'!$B5,'FTR Brewhouse'!#REF!) -> #REF! | L5: =AVERAGEIF('FTR Brewhouse'!#REF!,'Brewer''s Performance- Extract'!$B5,'FTR Brewhouse'!#REF!) -> #REF! | M5: 0.9694 | N5: =(K5+L5+M5)/3 -> #REF! | O5: =AVERAGEIF('FTR Brewhouse'!#REF!,'Brewer''s Performance- Extract'!$B5,'FTR Brewhouse'!#REF!) -> #REF! | P5: =AVERAGEIF('FTR Brewhouse'!#REF!,'Brewer''s Performance- Extract'!$B5,'FTR Brewhouse'!#REF!) -> #REF! | Q5: 0.985 | R5: =(O5+P5+Q5)/3 -> #REF! | S5: =AVERAGEIF('FTR Brewhouse'!#REF!,'Brewer''s Performance- Extract'!$B5,'FTR Brewhouse'!#REF!) -> #REF! | T5: =AVERAGEIF('FTR Brewhouse'!#REF!,'Brewer''s Performance- Extract'!$B5,'FTR Brewhouse'!#REF!) -> #REF! | U5: 0.987 | V5: =(S5+T5+U5)/3 -> #REF! | W5: =AVERAGEIF('FTR Brewhouse'!#REF!,'Brewer''s Performance- Extract'!$B5,'FTR Brewhouse'!#REF!) -> #REF! | X5: =AVERAGEIF('FTR Brewhouse'!#REF!,'Brewer''s Performance- Extract'!$B5,'FTR Brewhouse'!#REF!) -> #REF! | Y5: 0.987 | Z5: =(W5+X5+Y5)/3 -> #REF! | AA5: =AVERAGEIF('FTR Brewhouse'!#REF!,'Brewer''s Performance- Extract'!$B5,'FTR Brewhouse'!#REF!) -> #REF! | AB5: =AVERAGEIF('FTR Brewhouse'!#REF!,'Brewer''s Performance- Extract'!$B5,'FTR Brewhouse'!#REF!) -> #REF! | AC5: 0.987 | AD5: =(AA5+AB5+AC5)/3 -> #REF! | AE5: ='MTD - Time & OG'!X5 -> #REF! | AF5: ='MTD - Time & OG'!Y5 -> #REF! | AH5: =(AE5+AF5+AG5)/3 -> #REF!
B6: J.Greenidge | C6: =AVERAGEIF('FTR Brewhouse'!$J$17:$J$19,'Brewer''s Performance- Extract'!$B6,'FTR Brewhouse'!$D$17:$D$19) -> #DIV/0! | D6: =AVERAGEIF('FTR Brewhouse'!$J$17:$J$19,'Brewer''s Performance- Extract'!$B6,'FTR Brewhouse'!#REF!) -> #REF! | E6: 0.9907 | F6: =(C6+D6+E6)/3 -> #DIV/0! | G6: =AVERAGEIF('FTR Brewhouse'!#REF!,'Brewer''s Performance- Extract'!$B6,'FTR Brewhouse'!#REF!) -> #REF! | H6: =AVERAGEIF('FTR Brewhouse'!#REF!,'Brewer''s Performance- Extract'!$B6,'FTR Brewhouse'!#REF!) -> #REF! | I6: 0.9798 | J6: =(G6+H6+I6)/3 -> #REF! | K6: =AVERAGEIF('FTR Brewhouse'!#REF!,'Brewer''s Performance- Extract'!$B6,'FTR Brewhouse'!#REF!) -> #REF! | L6: =AVERAGEIF('FTR Brewhouse'!#REF!,'Brewer''s Performance- Extract'!$B6,'FTR Brewhouse'!#REF!) -> #REF! | M6: 0.9757 | N6: =(K6+L6+M6)/3 -> #REF! | O6: =AVERAGEIF('FTR Brewhouse'!#REF!,'Brewer''s Performance- Extract'!$B6,'FTR Brewhouse'!#REF!) -> #REF! | P6: =AVERAGEIF('FTR Brewhouse'!#REF!,'Brewer''s Performance- Extract'!$B6,'FTR Brewhouse'!#REF!) -> #REF! | Q6: 0.985 | R6: =(O6+P6+Q6)/3 -> #REF! | S6: =AVERAGEIF('FTR Brewhouse'!#REF!,'Brewer''s Performance- Extract'!$B6,'FTR Brewhouse'!#REF!) -> #REF! | T6: =AVERAGEIF('FTR Brewhouse'!#REF!,'Brewer''s Performance- Extract'!$B6,'FTR Brewhouse'!#REF!) -> #REF! | U6: 0.987 | V6: =(S6+T6+U6)/3 -> #REF! | W6: =AVERAGEIF('FTR Brewhouse'!#REF!,'Brewer''s Performance- Extract'!$B6,'FTR Brewhouse'!#REF!) -> #REF! | X6: =AVERAGEIF('FTR Brewhouse'!#REF!,'Brewer''s Performance- Extract'!$B6,'FTR Brewhouse'!#REF!) -> #REF! | Y6: 0.994 | Z6: =(W6+X6+Y6)/3 -> #REF! | AA6: =AVERAGEIF('FTR Brewhouse'!#REF!,'Brewer''s Performance- Extract'!$B6,'FTR Brewhouse'!#REF!) -> #REF! | AB6: =AVERAGEIF('FTR Brewhouse'!#REF!,'Brewer''s Performance- Extract'!$B6,'FTR Brewhouse'!#REF!) -> #REF! | AC6: 0.994 | AD6: =(AA6+AB6+AC6)/3 -> #REF! | AE6: ='MTD - Time & OG'!X6 -> #REF! | AF6: ='MTD - Time & OG'!Y6 -> #REF! | AH6: =(AE6+AF6+AG6)/3 -> #REF!
B7: K. Williams | C7: =AVERAGEIF('FTR Brewhouse'!$J$17:$J$19,'Brewer''s Performance- Extract'!$B7,'FTR Brewhouse'!$D$17:$D$19) -> #DIV/0! | D7: =AVERAGEIF('FTR Brewhouse'!$J$17:$J$19,'Brewer''s Performance- Extract'!$B7,'FTR Brewhouse'!#REF!) -> #REF! | E7: 0.9798 | F7: =(C7+D7+E7)/3 -> #DIV/0! | G7: =AVERAGEIF('FTR Brewhouse'!#REF!,'Brewer''s Performance- Extract'!$B7,'FTR Brewhouse'!#REF!) -> #REF! | H7: =AVERAGEIF('FTR Brewhouse'!#REF!,'Brewer''s Performance- Extract'!$B7,'FTR Brewhouse'!#REF!) -> #REF! | I7: 0.9709 | J7: =(G7+H7+I7)/3 -> #REF! | K7: NA | L7: NA | M7: NA | N7: NA | O7: NA | P7: NA | Q7: NA | R7: NA | S7: NA | T7: NA | U7: NA | V7: NA | W7: NA | X7: NA | Y7: NA | Z7: NA | AA7: NA | AB7: NA | AC7: NA | AD7: NA | AE7: ='MTD - Time & OG'!X7 -> NA | AF7: ='MTD - Time & OG'!Y7 -> NA | AH7: NA
B8: K. Benjamin | C8: NA | D8: NA | E8: NA | F8: NA | G8: =AVERAGEIF('FTR Brewhouse'!#REF!,'Brewer''s Performance- Extract'!$B8,'FTR Brewhouse'!#REF!) -> #REF! | H8: =AVERAGEIF('FTR Brewhouse'!#REF!,'Brewer''s Performance- Extract'!$B8,'FTR Brewhouse'!#REF!) -> #REF! | I8: 0.9808 | J8: =(G8+H8+I8)/3 -> #REF! | K8: =AVERAGEIF('FTR Brewhouse'!#REF!,'Brewer''s Performance- Extract'!$B8,'FTR Brewhouse'!#REF!) -> #REF! | L8: =AVERAGEIF('FTR Brewhouse'!#REF!,'Brewer''s Performance- Extract'!$B8,'FTR Brewhouse'!#REF!) -> #REF! | M8: 0.9601 | N8: =(K8+L8+M8)/3 -> #REF! | O8: =AVERAGEIF('FTR Brewhouse'!#REF!,'Brewer''s Performance- Extract'!$B8,'FTR Brewhouse'!#REF!) -> #REF! | P8: =AVERAGEIF('FTR Brewhouse'!#REF!,'Brewer''s Performance- Extract'!$B8,'FTR Brewhouse'!#REF!) -> #REF! | Q8: 0.9777 | R8: =(O8+P8+Q8)/3 -> #REF! | S8: =AVERAGEIF('FTR Brewhouse'!#REF!,'Brewer''s Performance- Extract'!$B8,'FTR Brewhouse'!#REF!) -> #REF! | T8: =AVERAGEIF('FTR Brewhouse'!#REF!,'Brewer''s Performance- Extract'!$B8,'FTR Brewhouse'!#REF!) -> #REF! | U8: 0.987 | V8: =(S8+T8+U8)/3 -> #REF! | W8: =AVERAGEIF('FTR Brewhouse'!#REF!,'Brewer''s Performance- Extract'!$B8,'FTR Brewhouse'!#REF!) -> #REF! | X8: =AVERAGEIF('FTR Brewhouse'!#REF!,'Brewer''s Performance- Extract'!$B8,'FTR Brewhouse'!#REF!) -> #REF! | Y8: 0.973 | Z8: =(W8+X8+Y8)/3 -> #REF! | AA8: =AVERAGEIF('FTR Brewhouse'!#REF!,'Brewer''s Performance- Extract'!$B8,'FTR Brewhouse'!#REF!) -> #REF! | AB8: =AVERAGEIF('FTR Brewhouse'!#REF!,'Brewer''s Performance- Extract'!$B8,'FTR Brewhouse'!#REF!) -> #REF! | AC8: 0.973 | AD8: =(AA8+AB8+AC8)/3 -> #REF! | AE8: ='MTD - Time & OG'!X8 -> #REF! | AF8: ='MTD - Time & OG'!Y8 -> #REF! | AH8: =(AE8+AF8+AG8)/3 -> #REF!
B9: J.Grant | C9: NA | D9: NA | E9: NA | F9: NA | G9: NA | H9: NA | I9: NA | J9: NA | K9: NA | L9: NA | M9: NA | N9: NA | O9: NA | P9: NA | Q9: NA | R9: NA | S9: NA | T9: NA | U9: NA | V9: NA | W9: NA | X9: NA | Y9: NA | Z9: NA | AA9: =AVERAGEIF('FTR Brewhouse'!#REF!,'Brewer''s Performance- Extract'!$B9,'FTR Brewhouse'!#REF!) -> #REF! | AB9: =AVERAGEIF('FTR Brewhouse'!#REF!,'Brewer''s Performance- Extract'!$B9,'FTR Brewhouse'!#REF!) -> #REF! | AE9: ='MTD - Time & OG'!X9 -> #REF! | AF9: ='MTD - Time & OG'!Y9 -> #REF!
B10: K. Bridgeman | C10: NA | D10: NA | E10: NA | F10: NA | G10: NA | H10: NA | I10: NA | J10: NA | K10: NA | L10: NA | M10: NA | N10: NA | O10: NA | P10: NA | Q10: NA | R10: NA | S10: =AVERAGEIF('FTR Brewhouse'!#REF!,'Brewer''s Performance- Extract'!$B10,'FTR Brewhouse'!#REF!) -> #REF! | T10: =AVERAGEIF('FTR Brewhouse'!#REF!,'Brewer''s Performance- Extract'!$B10,'FTR Brewhouse'!#REF!) -> #REF! | U10: 0.9897 | V10: =(S10+T10+U10)/3 -> #REF! | W10: NA | X10: NA | Y10: NA | Z10: NA | AB10: =AVERAGEIF('FTR Brewhouse'!#REF!,'Brewer''s Performance- Extract'!$B10,'FTR Brewhouse'!#REF!) -> #REF! | AE10: ='MTD - Time & OG'!X10 -> NA | AF10: ='MTD - Time & OG'!Y10 -> NA

Sheet FTR Brewhouse-New
O1: P.G. | Q1: Total Brewing Time | S1: Areation
O2: Lower | P2: Upper | Q2: Lower | R2: Upper | S2: Lower | T2: Upper
N3: CA | O3: 11.6 | P3: 11.9 | Q3: 250 | R3: 305 | S3: 2.5 | T3: 2.5
N4: ST | O4: 11.6 | P4: 11.9 | Q4: 250 | R4: 305 | S4: =+S3 -> 2.5 | T4: =+T3 -> 2.5
N5: GU | O5: 17 | P5: 17.5 | Q5: 280 | R5: 365 | S5: 3.5 | T5: 3.5
N6: MK | O6: 13.4 | P6: 13.6 | Q6: 320 | R6: 365 | S6: 2.5 | T6: 2.5
N7: SM | O7: 17.1 | P7: 17.5 | Q7: 300 | R7: 350
N8: MM | O8: 16.8 | P8: 17.2 | Q8: 300 | R8: 350
N9: VM | O9: 14.4 | P9: 14.6 | Q9: 275 | R9: 325
C10: PARAMETERS CHECKED | O10: P.G. | Q10: Total Brewing Time | S10: Areation
A11: 2020 | N11: =LEFT(B11,2) | O11: =VLOOKUP($N11,$N$3:$T$9,2,FALSE) -> #N/A | P11: =VLOOKUP($N11,$N$3:$T$9,3,FALSE) -> #N/A | Q11: =VLOOKUP($N11,$N$3:$T$9,4,FALSE) -> #N/A | R11: =VLOOKUP($N11,$N$3:$T$9,5,FALSE) -> #N/A | S11: =VLOOKUP($N11,$N$3:$T$9,6,FALSE) -> #N/A | T11: =VLOOKUP($N11,$N$3:$T$9,7,FALSE) -> #N/A
N12: =LEFT(B12,2) | O12: =VLOOKUP($N12,$N$3:$T$9,2,FALSE) -> #N/A | P12: =VLOOKUP($N12,$N$3:$T$9,3,FALSE) -> #N/A | Q12: =VLOOKUP($N12,$N$3:$T$9,4,FALSE) -> #N/A | R12: =VLOOKUP($N12,$N$3:$T$9,5,FALSE) -> #N/A | S12: =VLOOKUP($N12,$N$3:$T$9,6,FALSE) -> #N/A | T12: =VLOOKUP($N12,$N$3:$T$9,7,FALSE) -> #N/A
N13: =LEFT(B13,2) | O13: =VLOOKUP($N13,$N$3:$T$9,2,FALSE) -> #N/A | P13: =VLOOKUP($N13,$N$3:$T$9,3,FALSE) -> #N/A | Q13: =VLOOKUP($N13,$N$3:$T$9,4,FALSE) -> #N/A | R13: =VLOOKUP($N13,$N$3:$T$9,5,FALSE) -> #N/A | S13: =VLOOKUP($N13,$N$3:$T$9,6,FALSE) -> #N/A | T13: =VLOOKUP($N13,$N$3:$T$9,7,FALSE) -> #N/A
A14: Date | B14: ID Number | C14: Original Extract (°P) | E14: Total Brewing time | G14: Aeration level | I14: FTR | N14: =LEFT(B14,2) -> ID | O14: =VLOOKUP($N14,$N$3:$T$9,2,FALSE) -> #N/A | P14: =VLOOKUP($N14,$N$3:$T$9,3,FALSE) -> #N/A | Q14: =VLOOKUP($N14,$N$3:$T$9,4,FALSE) -> #N/A | R14: =VLOOKUP($N14,$N$3:$T$9,5,FALSE) -> #N/A | S14: =VLOOKUP($N14,$N$3:$T$9,6,FALSE) -> #N/A | T14: =VLOOKUP($N14,$N$3:$T$9,7,FALSE) -> #N/A
A15: 43832 | B15: CA001 | C15: 11.5 | D15: =IF(+(IF(C15<O15,0,IF(C15>P15,0,1)))=1,1,0) -> 0 | E15: =#REF! -> #REF! | F15: =IF(+(IF(E15<Q15,0,IF(E15>R15,0,1)))=1,1,0) -> #REF! | I15: 0 | J15: R. Regis | N15: =LEFT(B15,2) -> CA | O15: =VLOOKUP($N15,$N$3:$T$9,2,FALSE) -> 11.6 | P15: =VLOOKUP($N15,$N$3:$T$9,3,FALSE) -> 11.9 | Q15: =VLOOKUP($N15,$N$3:$T$9,4,FALSE) -> 250 | R15: =VLOOKUP($N15,$N$3:$T$9,5,FALSE) -> 305 | S15: =VLOOKUP($N15,$N$3:$T$9,6,FALSE) -> 2.5 | T15: =VLOOKUP($N15,$N$3:$T$9,7,FALSE) -> 2.5
A16: 43832 | B16: CA002 | C16: 11.8 | D16: =IF(+(IF(C16<O16,0,IF(C16>P16,0,1)))=1,1,0) -> 1 | E16: =#REF! -> #REF! | F16: =IF(+(IF(E16<Q16,0,IF(E16>R16,0,1)))=1,1,0) -> #REF! | I16: 0 | J16: K. Benjamin | N16: =LEFT(B16,2) -> CA | O16: =VLOOKUP($N16,$N$3:$T$9,2,FALSE) -> 11.6 | P16: =VLOOKUP($N16,$N$3:$T$9,3,FALSE) -> 11.9 | Q16: =VLOOKUP($N16,$N$3:$T$9,4,FALSE) -> 250 | R16: =VLOOKUP($N16,$N$3:$T$9,5,FALSE) -> 305 | S16: =VLOOKUP($N16,$N$3:$T$9,6,FALSE) -> 2.5 | T16: =VLOOKUP($N16,$N$3:$T$9,7,FALSE) -> 2.5
A17: 43832 | B17: CA003 | C17: 12.1 | D17: =IF(+(IF(C17<O17,0,IF(C17>P17,0,1)))=1,1,0) -> 0 | E17: =#REF! -> #REF! | F17: =IF(+(IF(E17<Q17,0,IF(E17>R17,0,1)))=1,1,0) -> #REF! | I17: 0 | J17: K. Benjamin | N17: =LEFT(B17,2) -> CA | O17: =VLOOKUP($N17,$N$3:$T$9,2,FALSE) -> 11.6 | P17: =VLOOKUP($N17,$N$3:$T$9,3,FALSE) -> 11.9 | Q17: =VLOOKUP($N17,$N$3:$T$9,4,FALSE) -> 250 | R17: =VLOOKUP($N17,$N$3:$T$9,5,FALSE) -> 305 | S17: =VLOOKUP($N17,$N$3:$T$9,6,FALSE) -> 2.5 | T17: =VLOOKUP($N17,$N$3:$T$9,7,FALSE) -> 2.5
A18: 43832 | B18: CA004 | C18: 11.7 | D18: =IF(+(IF(C18<O18,0,IF(C18>P18,0,1)))=1,1,0) -> 1 | E18: =#REF! -> #REF! | F18: =IF(+(IF(E18<Q18,0,IF(E18>R18,0,1)))=1,1,0) -> #REF! | I18: 0 | J18: K. Benjamin | N18: =LEFT(B18,2) -> CA | O18: =VLOOKUP($N18,$N$3:$T$9,2,FALSE) -> 11.6 | P18: =VLOOKUP($N18,$N$3:$T$9,3,FALSE) -> 11.9 | Q18: =VLOOKUP($N18,$N$3:$T$9,4,FALSE) -> 250 | R18: =VLOOKUP($N18,$N$3:$T$9,5,FALSE) -> 305 | S18: =VLOOKUP($N18,$N$3:$T$9,6,FALSE) -> 2.5 | T18: =VLOOKUP($N18,$N$3:$T$9,7,FALSE) -> 2.5
A19: 43832 | B19: CA005 | C19: 11.7 | D19: =IF(+(IF(C19<O19,0,IF(C19>P19,0,1)))=1,1,0) -> 1 | E19: =#REF! -> #REF! | F19: =IF(+(IF(E19<Q19,0,IF(E19>R19,0,1)))=1,1,0) -> #REF! | I19: 1 | J19: K. Benjamin | N19: =LEFT(B19,2) -> CA | O19: =VLOOKUP($N19,$N$3:$T$9,2,FALSE) -> 11.6 | P19: =VLOOKUP($N19,$N$3:$T$9,3,FALSE) -> 11.9 | Q19: =VLOOKUP($N19,$N$3:$T$9,4,FALSE) -> 250 | R19: =VLOOKUP($N19,$N$3:$T$9,5,FALSE) -> 305 | S19: =VLOOKUP($N19,$N$3:$T$9,6,FALSE) -> 2.5 | T19: =VLOOKUP($N19,$N$3:$T$9,7,FALSE) -> 2.5
A20: 43832 | B20: CA006 | C20: 11.6 | D20: =IF(+(IF(C20<O20,0,IF(C20>P20,0,1)))=1,1,0) -> 1 | E20: =#REF! -> #REF! | F20: =IF(+(IF(E20<Q20,0,IF(E20>R20,0,1)))=1,1,0) -> #REF! | I20: 1 | J20: J.Greenidge | N20: =LEFT(B20,2) -> CA | O20: =VLOOKUP($N20,$N$3:$T$9,2,FALSE) -> 11.6 | P20: =VLOOKUP($N20,$N$3:$T$9,3,FALSE) -> 11.9 | Q20: =VLOOKUP($N20,$N$3:$T$9,4,FALSE) -> 250 | R20: =VLOOKUP($N20,$N$3:$T$9,5,FALSE) -> 305 | S20: =VLOOKUP($N20,$N$3:$T$9,6,FALSE) -> 2.5 | T20: =VLOOKUP($N20,$N$3:$T$9,7,FALSE) -> 2.5
A21: 43832 | B21: CA007 | C21: 11.9 | D21: =IF(+(IF(C21<O21,0,IF(C21>P21,0,1)))=1,1,0) -> 1 | E21: =#REF! -> #REF! | F21: =IF(+(IF(E21<Q21,0,IF(E21>R21,0,1)))=1,1,0) -> #REF! | I21: 1 | J21: J.Greenidge | N21: =LEFT(B21,2) -> CA | O21: =VLOOKUP($N21,$N$3:$T$9,2,FALSE) -> 11.6 | P21: =VLOOKUP($N21,$N$3:$T$9,3,FALSE) -> 11.9 | Q21: =VLOOKUP($N21,$N$3:$T$9,4,FALSE) -> 250 | R21: =VLOOKUP($N21,$N$3:$T$9,5,FALSE) -> 305 | S21: =VLOOKUP($N21,$N$3:$T$9,6,FALSE) -> 2.5 | T21: =VLOOKUP($N21,$N$3:$T$9,7,FALSE) -> 2.5
A22: 43832 | B22: CA008 | C22: 11.6 | D22: =IF(+(IF(C22<O22,0,IF(C22>P22,0,1)))=1,1,0) -> 1 | E22: =#REF! -> #REF! | F22: =IF(+(IF(E22<Q22,0,IF(E22>R22,0,1)))=1,1,0) -> #REF! | I22: 1 | J22: J.Greenidge | N22: =LEFT(B22,2) -> CA | O22: =VLOOKUP($N22,$N$3:$T$9,2,FALSE) -> 11.6 | P22: =VLOOKUP($N22,$N$3:$T$9,3,FALSE) -> 11.9 | Q22: =VLOOKUP($N22,$N$3:$T$9,4,FALSE) -> 250 | R22: =VLOOKUP($N22,$N$3:$T$9,5,FALSE) -> 305 | S22: =VLOOKUP($N22,$N$3:$T$9,6,FALSE) -> 2.5 | T22: =VLOOKUP($N22,$N$3:$T$9,7,FALSE) -> 2.5
A23: 43832 | B23: CA009 | C23: 11.6 | D23: =IF(+(IF(C23<O23,0,IF(C23>P23,0,1)))=1,1,0) -> 1 | E23: =#REF! -> #REF! | F23: =IF(+(IF(E23<Q23,0,IF(E23>R23,0,1)))=1,1,0) -> #REF! | I23: 1 | J23: R. Regis | N23: =LEFT(B23,2) -> CA | O23: =VLOOKUP($N23,$N$3:$T$9,2,FALSE) -> 11.6 | P23: =VLOOKUP($N23,$N$3:$T$9,3,FALSE) -> 11.9 | Q23: =VLOOKUP($N23,$N$3:$T$9,4,FALSE) -> 250 | R23: =VLOOKUP($N23,$N$3:$T$9,5,FALSE) -> 305 | S23: =VLOOKUP($N23,$N$3:$T$9,6,FALSE) -> 2.5 | T23: =VLOOKUP($N23,$N$3:$T$9,7,FALSE) -> 2.5
A24: 43832 | B24: CA010 | C24: 11.6 | D24: =IF(+(IF(C24<O24,0,IF(C24>P24,0,1)))=1,1,0) -> 1 | E24: =#REF! -> #REF! | F24: =IF(+(IF(E24<Q24,0,IF(E24>R24,0,1)))=1,1,0) -> #REF! | I24: 1 | J24: R. Regis | N24: =LEFT(B24,2) -> CA | O24: =VLOOKUP($N24,$N$3:$T$9,2,FALSE) -> 11.6 | P24: =VLOOKUP($N24,$N$3:$T$9,3,FALSE) -> 11.9 | Q24: =VLOOKUP($N24,$N$3:$T$9,4,FALSE) -> 250 | R24: =VLOOKUP($N24,$N$3:$T$9,5,FALSE) -> 305 | S24: =VLOOKUP($N24,$N$3:$T$9,6,FALSE) -> 2.5 | T24: =VLOOKUP($N24,$N$3:$T$9,7,FALSE) -> 2.5
A25: 43833 | B25: CA011 | C25: 11.9 | D25: =IF(+(IF(C25<O25,0,IF(C25>P25,0,1)))=1,1,0) -> 1 | E25: =#REF! -> #REF! | F25: =IF(+(IF(E25<Q25,0,IF(E25>R25,0,1)))=1,1,0) -> #REF! | I25: 1 | J25: R. Regis | N25: =LEFT(B25,2) -> CA | O25: =VLOOKUP($N25,$N$3:$T$9,2,FALSE) -> 11.6 | P25: =VLOOKUP($N25,$N$3:$T$9,3,FALSE) -> 11.9 | Q25: =VLOOKUP($N25,$N$3:$T$9,4,FALSE) -> 250 | R25: =VLOOKUP($N25,$N$3:$T$9,5,FALSE) -> 305 | S25: =VLOOKUP($N25,$N$3:$T$9,6,FALSE) -> 2.5 | T25: =VLOOKUP($N25,$N$3:$T$9,7,FALSE) -> 2.5
A26: 43833 | B26: CA012 | C26: 12 | D26: =IF(+(IF(C26<O26,0,IF(C26>P26,0,1)))=1,1,0) -> 0 | E26: =#REF! -> #REF! | F26: =IF(+(IF(E26<Q26,0,IF(E26>R26,0,1)))=1,1,0) -> #REF! | I26: 0 | J26: R. Regis | N26: =LEFT(B26,2) -> CA | O26: =VLOOKUP($N26,$N$3:$T$9,2,FALSE) -> 11.6 | P26: =VLOOKUP($N26,$N$3:$T$9,3,FALSE) -> 11.9 | Q26: =VLOOKUP($N26,$N$3:$T$9,4,FALSE) -> 250 | R26: =VLOOKUP($N26,$N$3:$T$9,5,FALSE) -> 305 | S26: =VLOOKUP($N26,$N$3:$T$9,6,FALSE) -> 2.5 | T26: =VLOOKUP($N26,$N$3:$T$9,7,FALSE) -> 2.5
A27: 43834 | B27: MK001 | C27: 13 | D27: =IF(+(IF(C27<O27,0,IF(C27>P27,0,1)))=1,1,0) -> 0 | E27: ='[1]Brew Times'!$F4 -> 0.27291667 | F27: =IF(+(IF(E27<Q27,0,IF(E27>R27,0,1)))=1,1,0) -> 0 | I27: 0 | J27: K. Benjamin | N27: =LEFT(B27,2) -> MK | O27: =VLOOKUP($N27,$N$3:$T$9,2,FALSE) -> 13.4 | P27: =VLOOKUP($N27,$N$3:$T$9,3,FALSE) -> 13.6 | Q27: =VLOOKUP($N27,$N$3:$T$9,4,FALSE) -> 320 | R27: =VLOOKUP($N27,$N$3:$T$9,5,FALSE) -> 365 | S27: =VLOOKUP($N27,$N$3:$T$9,6,FALSE) -> 2.5 | T27: =VLOOKUP($N27,$N$3:$T$9,7,FALSE) -> 2.5
A28: 43834 | B28: MK002 | C28: 13.7 | D28: =IF(+(IF(C28<O28,0,IF(C28>P28,0,1)))=1,1,0) -> 0 | E28: ='[1]Brew Times'!$F5 -> 0.26319444 | F28: =IF(+(IF(E28<Q28,0,IF(E28>R28,0,1)))=1,1,0) -> 0 | I28: 0 | J28: K. Benjamin | N28: =LEFT(B28,2) -> MK | O28: =VLOOKUP($N28,$N$3:$T$9,2,FALSE) -> 13.4 | P28: =VLOOKUP($N28,$N$3:$T$9,3,FALSE) -> 13.6 | Q28: =VLOOKUP($N28,$N$3:$T$9,4,FALSE) -> 320 | R28: =VLOOKUP($N28,$N$3:$T$9,5,FALSE) -> 365 | S28: =VLOOKUP($N28,$N$3:$T$9,6,FALSE) -> 2.5 | T28: =VLOOKUP($N28,$N$3:$T$9,7,FALSE) -> 2.5
A29: 43834 | B29: MK003 | C29: 13.4 | D29: =IF(+(IF(C29<O29,0,IF(C29>P29,0,1)))=1,1,0) -> 1 | E29: ='[1]Brew Times'!$F6 -> 0.26597222 | F29: =IF(+(IF(E29<Q29,0,IF(E29>R29,0,1)))=1,1,0) -> 0 | I29: 1 | J29: K. Benjamin | N29: =LEFT(B29,2) -> MK | O29: =VLOOKUP($N29,$N$3:$T$9,2,FALSE) -> 13.4 | P29: =VLOOKUP($N29,$N$3:$T$9,3,FALSE) -> 13.6 | Q29: =VLOOKUP($N29,$N$3:$T$9,4,FALSE) -> 320 | R29: =VLOOKUP($N29,$N$3:$T$9,5,FALSE) -> 365 | S29: =VLOOKUP($N29,$N$3:$T$9,6,FALSE) -> 2.5 | T29: =VLOOKUP($N29,$N$3:$T$9,7,FALSE) -> 2.5
A30: 43834 | B30: MK004 | C30: 14.1 | D30: =IF(+(IF(C30<O30,0,IF(C30>P30,0,1)))=1,1,0) -> 0 | E30: ='[1]Brew Times'!$F7 -> 0.27638889 | F30: =IF(+(IF(E30<Q30,0,IF(E30>R30,0,1)))=1,1,0) -> 0 | I30: 0 | J30: K. Benjamin | N30: =LEFT(B30,2) -> MK | O30: =VLOOKUP($N30,$N$3:$T$9,2,FALSE) -> 13.4 | P30: =VLOOKUP($N30,$N$3:$T$9,3,FALSE) -> 13.6 | Q30: =VLOOKUP($N30,$N$3:$T$9,4,FALSE) -> 320 | R30: =VLOOKUP($N30,$N$3:$T$9,5,FALSE) -> 365 | S30: =VLOOKUP($N30,$N$3:$T$9,6,FALSE) -> 2.5 | T30: =VLOOKUP($N30,$N$3:$T$9,7,FALSE) -> 2.5
A31: 43834 | B31: MK005 | C31: 13.7 | D31: =IF(+(IF(C31<O31,0,IF(C31>P31,0,1)))=1,1,0) -> 0 | E31: ='[1]Brew Times'!$F8 -> 0.27916667 | F31: =IF(+(IF(E31<Q31,0,IF(E31>R31,0,1)))=1,1,0) -> 0 | I31: 0 | J31: K. Benjamin | N31: =LEFT(B31,2) -> MK | O31: =VLOOKUP($N31,$N$3:$T$9,2,FALSE) -> 13.4 | P31: =VLOOKUP($N31,$N$3:$T$9,3,FALSE) -> 13.6 | Q31: =VLOOKUP($N31,$N$3:$T$9,4,FALSE) -> 320 | R31: =VLOOKUP($N31,$N$3:$T$9,5,FALSE) -> 365 | S31: =VLOOKUP($N31,$N$3:$T$9,6,FALSE) -> 2.5 | T31: =VLOOKUP($N31,$N$3:$T$9,7,FALSE) -> 2.5
A32: 43834 | B32: MK006 | C32: 13.5 | D32: =IF(+(IF(C32<O32,0,IF(C32>P32,0,1)))=1,1,0) -> 1 | E32: ='[1]Brew Times'!$F9 -> 0.28888889 | F32: =IF(+(IF(E32<Q32,0,IF(E32>R32,0,1)))=1,1,0) -> 0 | I32: 1 | J32: K. Benjamin | N32: =LEFT(B32,2) -> MK | O32: =VLOOKUP($N32,$N$3:$T$9,2,FALSE) -> 13.4 | P32: =VLOOKUP($N32,$N$3:$T$9,3,FALSE) -> 13.6 | Q32: =VLOOKUP($N32,$N$3:$T$9,4,FALSE) -> 320 | R32: =VLOOKUP($N32,$N$3:$T$9,5,FALSE) -> 365 | S32: =VLOOKUP($N32,$N$3:$T$9,6,FALSE) -> 2.5 | T32: =VLOOKUP($N32,$N$3:$T$9,7,FALSE) -> 2.5
A33: 43837 | B33: ST001 | C33: 11.5 | D33: =IF(+(IF(C33<O33,0,IF(C33>P33,0,1)))=1,1,0) -> 0 | E33: =#REF! -> #REF! | F33: =IF(+(IF(E33<Q33,0,IF(E33>R33,0,1)))=1,1,0) -> #REF! | I33: 0 | J33: R. Regis | N33: =LEFT(B33,2) -> ST | O33: =VLOOKUP($N33,$N$3:$T$9,2,FALSE) -> 11.6 | P33: =VLOOKUP($N33,$N$3:$T$9,3,FALSE) -> 11.9 | Q33: =VLOOKUP($N33,$N$3:$T$9,4,FALSE) -> 250 | R33: =VLOOKUP($N33,$N$3:$T$9,5,FALSE) -> 305 | S33: =VLOOKUP($N33,$N$3:$T$9,6,FALSE) -> 2.5 | T33: =VLOOKUP($N33,$N$3:$T$9,7,FALSE) -> 2.5
A34: 43837 | B34: ST002 | C34: 12.4 | D34: =IF(+(IF(C34<O34,0,IF(C34>P34,0,1)))=1,1,0) -> 0 | E34: =#REF! -> #REF! | F34: =IF(+(IF(E34<Q34,0,IF(E34>R34,0,1)))=1,1,0) -> #REF! | I34: 0 | J34: R. Regis | N34: =LEFT(B34,2) -> ST | O34: =VLOOKUP($N34,$N$3:$T$9,2,FALSE) -> 11.6 | P34: =VLOOKUP($N34,$N$3:$T$9,3,FALSE) -> 11.9 | Q34: =VLOOKUP($N34,$N$3:$T$9,4,FALSE) -> 250 | R34: =VLOOKUP($N34,$N$3:$T$9,5,FALSE) -> 305 | S34: =VLOOKUP($N34,$N$3:$T$9,6,FALSE) -> 2.5 | T34: =VLOOKUP($N34,$N$3:$T$9,7,FALSE) -> 2.5
A35: 43837 | B35: ST003 | C35: 11.7 | D35: =IF(+(IF(C35<O35,0,IF(C35>P35,0,1)))=1,1,0) -> 1 | E35: =#REF! -> #REF! | F35: =IF(+(IF(E35<Q35,0,IF(E35>R35,0,1)))=1,1,0) -> #REF! | I35: 1 | J35: R. Regis | N35: =LEFT(B35,2) -> ST | O35: =VLOOKUP($N35,$N$3:$T$9,2,FALSE) -> 11.6 | P35: =VLOOKUP($N35,$N$3:$T$9,3,FALSE) -> 11.9 | Q35: =VLOOKUP($N35,$N$3:$T$9,4,FALSE) -> 250 | R35: =VLOOKUP($N35,$N$3:$T$9,5,FALSE) -> 305 | S35: =VLOOKUP($N35,$N$3:$T$9,6,FALSE) -> 2.5 | T35: =VLOOKUP($N35,$N$3:$T$9,7,FALSE) -> 2.5
A36: 43837 | B36: ST004 | C36: 11.8 | D36: =IF(+(IF(C36<O36,0,IF(C36>P36,0,1)))=1,1,0) -> 1 | E36: =#REF! -> #REF! | F36: =IF(+(IF(E36<Q36,0,IF(E36>R36,0,1)))=1,1,0) -> #REF! | I36: 1 | J36: R. Regis | N36: =LEFT(B36,2) -> ST | O36: =VLOOKUP($N36,$N$3:$T$9,2,FALSE) -> 11.6 | P36: =VLOOKUP($N36,$N$3:$T$9,3,FALSE) -> 11.9 | Q36: =VLOOKUP($N36,$N$3:$T$9,4,FALSE) -> 250 | R36: =VLOOKUP($N36,$N$3:$T$9,5,FALSE) -> 305 | S36: =VLOOKUP($N36,$N$3:$T$9,6,FALSE) -> 2.5 | T36: =VLOOKUP($N36,$N$3:$T$9,7,FALSE) -> 2.5
A37: 43837 | B37: ST005 | C37: 11.7 | D37: =IF(+(IF(C37<O37,0,IF(C37>P37,0,1)))=1,1,0) -> 1 | E37: =#REF! -> #REF! | F37: =IF(+(IF(E37<Q37,0,IF(E37>R37,0,1)))=1,1,0) -> #REF! | I37: 1 | J37: K. Benjamin | N37: =LEFT(B37,2) -> ST | O37: =VLOOKUP($N37,$N$3:$T$9,2,FALSE) -> 11.6 | P37: =VLOOKUP($N37,$N$3:$T$9,3,FALSE) -> 11.9 | Q37: =VLOOKUP($N37,$N$3:$T$9,4,FALSE) -> 250 | R37: =VLOOKUP($N37,$N$3:$T$9,5,FALSE) -> 305 | S37: =VLOOKUP($N37,$N$3:$T$9,6,FALSE) -> 2.5 | T37: =VLOOKUP($N37,$N$3:$T$9,7,FALSE) -> 2.5
A38: 43837 | B38: ST006 | C38: 11.9 | D38: =IF(+(IF(C38<O38,0,IF(C38>P38,0,1)))=1,1,0) -> 1 | E38: =#REF! -> #REF! | F38: =IF(+(IF(E38<Q38,0,IF(E38>R38,0,1)))=1,1,0) -> #REF! | I38: 1 | J38: K. Benjamin | N38: =LEFT(B38,2) -> ST | O38: =VLOOKUP($N38,$N$3:$T$9,2,FALSE) -> 11.6 | P38: =VLOOKUP($N38,$N$3:$T$9,3,FALSE) -> 11.9 | Q38: =VLOOKUP($N38,$N$3:$T$9,4,FALSE) -> 250 | R38: =VLOOKUP($N38,$N$3:$T$9,5,FALSE) -> 305 | S38: =VLOOKUP($N38,$N$3:$T$9,6,FALSE) -> 2.5 | T38: =VLOOKUP($N38,$N$3:$T$9,7,FALSE) -> 2.5
A39: 43837 | B39: ST007 | C39: 11.8 | D39: =IF(+(IF(C39<O39,0,IF(C39>P39,0,1)))=1,1,0) -> 1 | E39: =#REF! -> #REF! | F39: =IF(+(IF(E39<Q39,0,IF(E39>R39,0,1)))=1,1,0) -> #REF! | I39: 1 | J39: K. Benjamin | N39: =LEFT(B39,2) -> ST | O39: =VLOOKUP($N39,$N$3:$T$9,2,FALSE) -> 11.6 | P39: =VLOOKUP($N39,$N$3:$T$9,3,FALSE) -> 11.9 | Q39: =VLOOKUP($N39,$N$3:$T$9,4,FALSE) -> 250 | R39: =VLOOKUP($N39,$N$3:$T$9,5,FALSE) -> 305 | S39: =VLOOKUP($N39,$N$3:$T$9,6,FALSE) -> 2.5 | T39: =VLOOKUP($N39,$N$3:$T$9,7,FALSE) -> 2.5
A40: 43837 | B40: ST008 | C40: 11.9 | D40: =IF(+(IF(C40<O40,0,IF(C40>P40,0,1)))=1,1,0) -> 1 | E40: =#REF! -> #REF! | F40: =IF(+(IF(E40<Q40,0,IF(E40>R40,0,1)))=1,1,0) -> #REF! | I40: 1 | J40: K. Benjamin | N40: =LEFT(B40,2) -> ST | O40: =VLOOKUP($N40,$N$3:$T$9,2,FALSE) -> 11.6 | P40: =VLOOKUP($N40,$N$3:$T$9,3,FALSE) -> 11.9 | Q40: =VLOOKUP($N40,$N$3:$T$9,4,FALSE) -> 250 | R40: =VLOOKUP($N40,$N$3:$T$9,5,FALSE) -> 305 | S40: =VLOOKUP($N40,$N$3:$T$9,6,FALSE) -> 2.5 | T40: =VLOOKUP($N40,$N$3:$T$9,7,FALSE) -> 2.5
...

Sheet FTR Brewhouse
O1: P.G. | Q1: Areation | S1: Total Brewing Time
O2: Lower | P2: Upper | Q2: Lower | R2: Upper | S2: Lower | T2: Upper
N3: CA | O3: 11.6 | P3: 12.04 | Q3: 8 | R3: 14.4 | S3: =250+10+5+60 -> 325 | T3: =305+10+5+60 -> 380
N4: ST | O4: 11.6 | P4: 12.04 | Q4: 8 | R4: 14.4 | S4: =250+10+5+60 -> 325 | T4: =305+10+5+60 -> 380
N5: GU | O5: 17 | P5: 17.54 | Q5: 14 | R5: 18.4 | S5: =280+10+5+60 -> 355 | T5: =335+10+5+60 -> 410
N6: MK | O6: 13.3 | P6: 13.54 | Q6: 8 | R6: 14.4 | S6: =320+10+5+60 -> 395 | T6: =360+10+5+60 -> 435
N7: SM | O7: 17 | P7: 17.44 | S7: =300+10+5+80 -> 395 | T7: =350+10+5+80 -> 445
N8: HP | O8: 10.9 | P8: 11.24 | Q8: 14 | R8: 18.4 | S8: =320+10+5+60 -> 395 | T8: =360+10+5+60 -> 435
N9: VM | O9: 14.2 | P9: 14.64 | S9: =275+10+5+85 -> 375 | T9: =325+10+5+85 -> 425
N10: HA | O10: 13.8 | P10: 14 | Q10: 14 | R10: 18.4 | S10: 395 | T10: 435
N11: HR | O11: 16.6 | P11: 17.04 | Q11: 14 | R11: 18 | S11: =320+10+5+60 -> 395 | T11: =360+10+5+60 -> 435
C12: PARAMETERS CHECKED | O12: P.G. | Q12: Areation | S12: =S1 -> Total Brewing Time
A13: 2026 | N13: =LEFT(B13,2) | O13: =VLOOKUP($N13,$N$3:$R$11,2,FALSE) -> #N/A | P13: =VLOOKUP($N13,$N$3:$R$11,3,FALSE) -> #N/A | Q13: =VLOOKUP($N13,$N$3:$R$11,4,FALSE) -> #N/A | R13: =VLOOKUP($N13,$N$3:$R$11,5,FALSE) -> #N/A | S13: =VLOOKUP($N13,$N$3:$T$11,6,FALSE) -> #N/A | T13: =VLOOKUP($N13,$N$3:$T$11,7,FALSE) -> #N/A
N14: =LEFT(B14,2) | O14: =VLOOKUP($N14,$N$3:$R$11,2,FALSE) -> #N/A | P14: =VLOOKUP($N14,$N$3:$R$11,3,FALSE) -> #N/A | Q14: =VLOOKUP($N14,$N$3:$R$11,4,FALSE) -> #N/A | R14: =VLOOKUP($N14,$N$3:$R$11,5,FALSE) -> #N/A | S14: =VLOOKUP($N14,$N$3:$T$11,6,FALSE) -> #N/A | T14: =VLOOKUP($N14,$N$3:$T$11,7,FALSE) -> #N/A
N15: =LEFT(B15,2) | O15: =VLOOKUP($N15,$N$3:$R$11,2,FALSE) -> #N/A | P15: =VLOOKUP($N15,$N$3:$R$11,3,FALSE) -> #N/A | Q15: =VLOOKUP($N15,$N$3:$R$11,4,FALSE) -> #N/A | R15: =VLOOKUP($N15,$N$3:$R$11,5,FALSE) -> #N/A | S15: =VLOOKUP($N15,$N$3:$T$11,6,FALSE) -> #N/A | T15: =VLOOKUP($N15,$N$3:$T$11,7,FALSE) -> #N/A
A16: Date | B16: ID Number | C16: Original Extract (°P) | E16: Total Brewing time | G16: Aeration level | N16: =LEFT(B16,2) -> ID | O16: =VLOOKUP($N16,$N$3:$R$11,2,FALSE) -> #N/A | P16: =VLOOKUP($N16,$N$3:$R$11,3,FALSE) -> #N/A | Q16: =VLOOKUP($N16,$N$3:$R$11,4,FALSE) -> #N/A | R16: =VLOOKUP($N16,$N$3:$R$11,5,FALSE) -> #N/A | S16: =VLOOKUP($N16,$N$3:$T$11,6,FALSE) -> #N/A | T16: =VLOOKUP($N16,$N$3:$T$11,7,FALSE) -> #N/A
A17: 46024 | B17: CA001 | C17: 11.8 | D17: =IF(+(IF(C17<O17,0,IF(C17>P17,0,1)))=1,1,0) -> 1 | E17: 349 | F17: =IF(+(IF(E17<S17,0,IF(E17>T17,0,1)))=1,1,0) -> 1 | G17: 12.36 | H17: =IF(+(IF(G17<Q17,0,IF(G17>R17,0,1)))=1,1,0) -> 1 | I17: =IF(+(IF(C17<O17,0,IF(C17>P17,0,1)))+(IF(E17<S17,0,IF(E17>T17,0,1)))+(IF(G17<Q17,0,IF(G17>R17,0,1)))=3,1,0) -> 1 | N17: =LEFT(B17,2) -> CA | O17: =VLOOKUP($N17,$N$3:$R$11,2,FALSE) -> 11.6 | P17: =VLOOKUP($N17,$N$3:$R$11,3,FALSE) -> 12.04 | Q17: =VLOOKUP($N17,$N$3:$R$11,4,FALSE) -> 8 | R17: =VLOOKUP($N17,$N$3:$R$11,5,FALSE) -> 14.4 | S17: =VLOOKUP($N17,$N$3:$T$11,6,FALSE) -> 325 | T17: =VLOOKUP($N17,$N$3:$T$11,7,FALSE) -> 380
A18: 46024 | B18: CA002 | C18: 11.8 | D18: =IF(+(IF(C18<O18,0,IF(C18>P18,0,1)))=1,1,0) -> 1 | E18: 363 | F18: =IF(+(IF(E18<S18,0,IF(E18>T18,0,1)))=1,1,0) -> 1 | G18: 11.1 | H18: =IF(+(IF(G18<Q18,0,IF(G18>R18,0,1)))=1,1,0) -> 1 | I18: =IF(+(IF(C18<O18,0,IF(C18>P18,0,1)))+(IF(E18<S18,0,IF(E18>T18,0,1)))+(IF(G18<Q18,0,IF(G18>R18,0,1)))=3,1,0) -> 1 | N18: =LEFT(B18,2) -> CA | O18: =VLOOKUP($N18,$N$3:$R$11,2,FALSE) -> 11.6 | P18: =VLOOKUP($N18,$N$3:$R$11,3,FALSE) -> 12.04 | Q18: =VLOOKUP($N18,$N$3:$R$11,4,FALSE) -> 8 | R18: =VLOOKUP($N18,$N$3:$R$11,5,FALSE) -> 14.4 | S18: =VLOOKUP($N18,$N$3:$T$11,6,FALSE) -> 325 | T18: =VLOOKUP($N18,$N$3:$T$11,7,FALSE) -> 380
A19: 46024 | B19: CA003 | C19: 11.8 | D19: =IF(+(IF(C19<O19,0,IF(C19>P19,0,1)))=1,1,0) -> 1 | E19: 393 | F19: =IF(+(IF(E19<S19,0,IF(E19>T19,0,1)))=1,1,0) -> 0 | G19: 12.2 | H19: =IF(+(IF(G19<Q19,0,IF(G19>R19,0,1)))=1,1,0) -> 1 | I19: =IF(+(IF(C19<O19,0,IF(C19>P19,0,1)))+(IF(E19<S19,0,IF(E19>T19,0,1)))+(IF(G19<Q19,0,IF(G19>R19,0,1)))=3,1,0) -> 0 | N19: =LEFT(B19,2) -> CA | O19: =VLOOKUP($N19,$N$3:$R$11,2,FALSE) -> 11.6 | P19: =VLOOKUP($N19,$N$3:$R$11,3,FALSE) -> 12.04 | Q19: =VLOOKUP($N19,$N$3:$R$11,4,FALSE) -> 8 | R19: =VLOOKUP($N19,$N$3:$R$11,5,FALSE) -> 14.4 | S19: =VLOOKUP($N19,$N$3:$T$11,6,FALSE) -> 325 | T19: =VLOOKUP($N19,$N$3:$T$11,7,FALSE) -> 380
A20: 46024 | B20: CA004 | C20: 12 | D20: =IF(+(IF(C20<O20,0,IF(C20>P20,0,1)))=1,1,0) -> 1 | E20: 401 | F20: =IF(+(IF(E20<S20,0,IF(E20>T20,0,1)))=1,1,0) -> 0 | G20: 11.31 | H20: =IF(+(IF(G20<Q20,0,IF(G20>R20,0,1)))=1,1,0) -> 1 | I20: =IF(+(IF(C20<O20,0,IF(C20>P20,0,1)))+(IF(E20<S20,0,IF(E20>T20,0,1)))+(IF(G20<Q20,0,IF(G20>R20,0,1)))=3,1,0) -> 0 | N20: =LEFT(B20,2) -> CA | O20: =VLOOKUP($N20,$N$3:$R$11,2,FALSE) -> 11.6 | P20: =VLOOKUP($N20,$N$3:$R$11,3,FALSE) -> 12.04 | Q20: =VLOOKUP($N20,$N$3:$R$11,4,FALSE) -> 8 | R20: =VLOOKUP($N20,$N$3:$R$11,5,FALSE) -> 14.4 | S20: =VLOOKUP($N20,$N$3:$T$11,6,FALSE) -> 325 | T20: =VLOOKUP($N20,$N$3:$T$11,7,FALSE) -> 380
A21: 45662 | B21: SM001 | C21: 17.1 | D21: =IF(+(IF(C21<O21,0,IF(C21>P21,0,1)))=1,1,0) -> 1 | E21: 439 | F21: =IF(+(IF(E21<S21,0,IF(E21>T21,0,1)))=1,1,0) -> 1 | I21: =IF(+(IF(C21<O21,0,IF(C21>P21,0,1)))+(IF(E21<S21,0,IF(E21>T21,0,1)))+(IF(G21<Q21,0,IF(G21>R21,0,1)))=3,1,0) -> 1 | N21: =LEFT(B21,2) -> SM | O21: =VLOOKUP($N21,$N$3:$R$11,2,FALSE) -> 17 | P21: =VLOOKUP($N21,$N$3:$R$11,3,FALSE) -> 17.44 | Q21: =VLOOKUP($N21,$N$3:$R$11,4,FALSE) -> 0 | R21: =VLOOKUP($N21,$N$3:$R$11,5,FALSE) -> 0 | S21: =VLOOKUP($N21,$N$3:$T$11,6,FALSE) -> 395 | T21: =VLOOKUP($N21,$N$3:$T$11,7,FALSE) -> 445
A22: 45662 | B22: SM002 | C22: 17.1 | D22: =IF(+(IF(C22<O22,0,IF(C22>P22,0,1)))=1,1,0) -> 1 | E22: 473 | F22: =IF(+(IF(E22<S22,0,IF(E22>T22,0,1)))=1,1,0) -> 0 | I22: =IF(+(IF(C22<O22,0,IF(C22>P22,0,1)))+(IF(E22<S22,0,IF(E22>T22,0,1)))+(IF(G22<Q22,0,IF(G22>R22,0,1)))=3,1,0) -> 0 | N22: =LEFT(B22,2) -> SM | O22: =VLOOKUP($N22,$N$3:$R$11,2,FALSE) -> 17 | P22: =VLOOKUP($N22,$N$3:$R$11,3,FALSE) -> 17.44 | Q22: =VLOOKUP($N22,$N$3:$R$11,4,FALSE) -> 0 | R22: =VLOOKUP($N22,$N$3:$R$11,5,FALSE) -> 0 | S22: =VLOOKUP($N22,$N$3:$T$11,6,FALSE) -> 395 | T22: =VLOOKUP($N22,$N$3:$T$11,7,FALSE) -> 445
A23: 45662 | B23: SM003 | C23: 17.1 | D23: =IF(+(IF(C23<O23,0,IF(C23>P23,0,1)))=1,1,0) -> 1 | E23: 449 | F23: =IF(+(IF(E23<S23,0,IF(E23>T23,0,1)))=1,1,0) -> 0 | I23: =IF(+(IF(C23<O23,0,IF(C23>P23,0,1)))+(IF(E23<S23,0,IF(E23>T23,0,1)))+(IF(G23<Q23,0,IF(G23>R23,0,1)))=3,1,0) -> 0 | N23: =LEFT(B23,2) -> SM | O23: =VLOOKUP($N23,$N$3:$R$11,2,FALSE) -> 17 | P23: =VLOOKUP($N23,$N$3:$R$11,3,FALSE) -> 17.44 | Q23: =VLOOKUP($N23,$N$3:$R$11,4,FALSE) -> 0 | R23: =VLOOKUP($N23,$N$3:$R$11,5,FALSE) -> 0 | S23: =VLOOKUP($N23,$N$3:$T$11,6,FALSE) -> 395 | T23: =VLOOKUP($N23,$N$3:$T$11,7,FALSE) -> 445
A24: 45663 | B24: SM004 | C24: 17.2 | D24: =IF(+(IF(C24<O24,0,IF(C24>P24,0,1)))=1,1,0) -> 1 | E24: 447 | F24: =IF(+(IF(E24<S24,0,IF(E24>T24,0,1)))=1,1,0) -> 0 | I24: =IF(+(IF(C24<O24,0,IF(C24>P24,0,1)))+(IF(E24<S24,0,IF(E24>T24,0,1)))+(IF(G24<Q24,0,IF(G24>R24,0,1)))=3,1,0) -> 0 | N24: =LEFT(B24,2) -> SM | O24: =VLOOKUP($N24,$N$3:$R$11,2,FALSE) -> 17 | P24: =VLOOKUP($N24,$N$3:$R$11,3,FALSE) -> 17.44 | Q24: =VLOOKUP($N24,$N$3:$R$11,4,FALSE) -> 0 | R24: =VLOOKUP($N24,$N$3:$R$11,5,FALSE) -> 0 | S24: =VLOOKUP($N24,$N$3:$T$11,6,FALSE) -> 395 | T24: =VLOOKUP($N24,$N$3:$T$11,7,FALSE) -> 445
A25: 45663 | B25: SM005 | C25: 17.1 | D25: =IF(+(IF(C25<O25,0,IF(C25>P25,0,1)))=1,1,0) -> 1 | E25: 435 | F25: =IF(+(IF(E25<S25,0,IF(E25>T25,0,1)))=1,1,0) -> 1 | I25: =IF(+(IF(C25<O25,0,IF(C25>P25,0,1)))+(IF(E25<S25,0,IF(E25>T25,0,1)))+(IF(G25<Q25,0,IF(G25>R25,0,1)))=3,1,0) -> 1 | N25: =LEFT(B25,2) -> SM | O25: =VLOOKUP($N25,$N$3:$R$11,2,FALSE) -> 17 | P25: =VLOOKUP($N25,$N$3:$R$11,3,FALSE) -> 17.44 | Q25: =VLOOKUP($N25,$N$3:$R$11,4,FALSE) -> 0 | R25: =VLOOKUP($N25,$N$3:$R$11,5,FALSE) -> 0 | S25: =VLOOKUP($N25,$N$3:$T$11,6,FALSE) -> 395 | T25: =VLOOKUP($N25,$N$3:$T$11,7,FALSE) -> 445
A26: 45663 | B26: SM006 | C26: 17 | D26: =IF(+(IF(C26<O26,0,IF(C26>P26,0,1)))=1,1,0) -> 1 | E26: 444 | F26: =IF(+(IF(E26<S26,0,IF(E26>T26,0,1)))=1,1,0) -> 1 | I26: =IF(+(IF(C26<O26,0,IF(C26>P26,0,1)))+(IF(E26<S26,0,IF(E26>T26,0,1)))+(IF(G26<Q26,0,IF(G26>R26,0,1)))=3,1,0) -> 1 | N26: =LEFT(B26,2) -> SM | O26: =VLOOKUP($N26,$N$3:$R$11,2,FALSE) -> 17 | P26: =VLOOKUP($N26,$N$3:$R$11,3,FALSE) -> 17.44 | Q26: =VLOOKUP($N26,$N$3:$R$11,4,FALSE) -> 0 | R26: =VLOOKUP($N26,$N$3:$R$11,5,FALSE) -> 0 | S26: =VLOOKUP($N26,$N$3:$T$11,6,FALSE) -> 395 | T26: =VLOOKUP($N26,$N$3:$T$11,7,FALSE) -> 445
A27: 45663 | B27: SM007 | C27: 17 | D27: =IF(+(IF(C27<O27,0,IF(C27>P27,0,1)))=1,1,0) -> 1 | E27: 476 | F27: =IF(+(IF(E27<S27,0,IF(E27>T27,0,1)))=1,1,0) -> 0 | I27: =IF(+(IF(C27<O27,0,IF(C27>P27,0,1)))+(IF(E27<S27,0,IF(E27>T27,0,1)))+(IF(G27<Q27,0,IF(G27>R27,0,1)))=3,1,0) -> 0 | N27: =LEFT(B27,2) -> SM | O27: =VLOOKUP($N27,$N$3:$R$11,2,FALSE) -> 17 | P27: =VLOOKUP($N27,$N$3:$R$11,3,FALSE) -> 17.44 | Q27: =VLOOKUP($N27,$N$3:$R$11,4,FALSE) -> 0 | R27: =VLOOKUP($N27,$N$3:$R$11,5,FALSE) -> 0 | S27: =VLOOKUP($N27,$N$3:$T$11,6,FALSE) -> 395 | T27: =VLOOKUP($N27,$N$3:$T$11,7,FALSE) -> 445
A28: 45663 | B28: SM008 | C28: 17.1 | D28: =IF(+(IF(C28<O28,0,IF(C28>P28,0,1)))=1,1,0) -> 1 | E28: 440 | F28: =IF(+(IF(E28<S28,0,IF(E28>T28,0,1)))=1,1,0) -> 1 | I28: =IF(+(IF(C28<O28,0,IF(C28>P28,0,1)))+(IF(E28<S28,0,IF(E28>T28,0,1)))+(IF(G28<Q28,0,IF(G28>R28,0,1)))=3,1,0) -> 1 | N28: =LEFT(B28,2) -> SM | O28: =VLOOKUP($N28,$N$3:$R$11,2,FALSE) -> 17 | P28: =VLOOKUP($N28,$N$3:$R$11,3,FALSE) -> 17.44 | Q28: =VLOOKUP($N28,$N$3:$R$11,4,FALSE) -> 0 | R28: =VLOOKUP($N28,$N$3:$R$11,5,FALSE) -> 0 | S28: =VLOOKUP($N28,$N$3:$T$11,6,FALSE) -> 395 | T28: =VLOOKUP($N28,$N$3:$T$11,7,FALSE) -> 445
A29: 45663 | B29: SM009 | C29: 17.3 | D29: =IF(+(IF(C29<O29,0,IF(C29>P29,0,1)))=1,1,0) -> 1 | E29: 453 | F29: =IF(+(IF(E29<S29,0,IF(E29>T29,0,1)))=1,1,0) -> 0 | I29: =IF(+(IF(C29<O29,0,IF(C29>P29,0,1)))+(IF(E29<S29,0,IF(E29>T29,0,1)))+(IF(G29<Q29,0,IF(G29>R29,0,1)))=3,1,0) -> 0 | N29: =LEFT(B29,2) -> SM | O29: =VLOOKUP($N29,$N$3:$R$11,2,FALSE) -> 17 | P29: =VLOOKUP($N29,$N$3:$R$11,3,FALSE) -> 17.44 | Q29: =VLOOKUP($N29,$N$3:$R$11,4,FALSE) -> 0 | R29: =VLOOKUP($N29,$N$3:$R$11,5,FALSE) -> 0 | S29: =VLOOKUP($N29,$N$3:$T$11,6,FALSE) -> 395 | T29: =VLOOKUP($N29,$N$3:$T$11,7,FALSE) -> 445
A30: 45663 | B30: SM010 | C30: 17.2 | D30: =IF(+(IF(C30<O30,0,IF(C30>P30,0,1)))=1,1,0) -> 1 | E30: 456 | F30: =IF(+(IF(E30<S30,0,IF(E30>T30,0,1)))=1,1,0) -> 0 | I30: =IF(+(IF(C30<O30,0,IF(C30>P30,0,1)))+(IF(E30<S30,0,IF(E30>T30,0,1)))+(IF(G30<Q30,0,IF(G30>R30,0,1)))=3,1,0) -> 0 | N30: =LEFT(B30,2) -> SM | O30: =VLOOKUP($N30,$N$3:$R$11,2,FALSE) -> 17 | P30: =VLOOKUP($N30,$N$3:$R$11,3,FALSE) -> 17.44 | Q30: =VLOOKUP($N30,$N$3:$R$11,4,FALSE) -> 0 | R30: =VLOOKUP($N30,$N$3:$R$11,5,FALSE) -> 0 | S30: =VLOOKUP($N30,$N$3:$T$11,6,FALSE) -> 395 | T30: =VLOOKUP($N30,$N$3:$T$11,7,FALSE) -> 445
A31: 45663 | B31: ST002 | C31: 11.7 | D31: =IF(+(IF(C31<O31,0,IF(C31>P31,0,1)))=1,1,0) -> 1 | E31: 394 | F31: =IF(+(IF(E31<S31,0,IF(E31>T31,0,1)))=1,1,0) -> 0 | G31: 13.41 | H31: =IF(+(IF(G31<Q31,0,IF(G31>R31,0,1)))=1,1,0) -> 1 | I31: =IF(+(IF(C31<O31,0,IF(C31>P31,0,1)))+(IF(E31<S31,0,IF(E31>T31,0,1)))+(IF(G31<Q31,0,IF(G31>R31,0,1)))=3,1,0) -> 0 | N31: =LEFT(B31,2) -> ST | O31: =VLOOKUP($N31,$N$3:$R$11,2,FALSE) -> 11.6 | P31: =VLOOKUP($N31,$N$3:$R$11,3,FALSE) -> 12.04 | Q31: =VLOOKUP($N31,$N$3:$R$11,4,FALSE) -> 8 | R31: =VLOOKUP($N31,$N$3:$R$11,5,FALSE) -> 14.4 | S31: =VLOOKUP($N31,$N$3:$T$11,6,FALSE) -> 325 | T31: =VLOOKUP($N31,$N$3:$T$11,7,FALSE) -> 380
A32: 45664 | B32: MK001 | C32: 13.3 | D32: =IF(+(IF(C32<O32,0,IF(C32>P32,0,1)))=1,1,0) -> 1 | E32: 420 | F32: =IF(+(IF(E32<S32,0,IF(E32>T32,0,1)))=1,1,0) -> 1 | G32: 12.88 | H32: =IF(+(IF(G32<Q32,0,IF(G32>R32,0,1)))=1,1,0) -> 1 | I32: =IF(+(IF(C32<O32,0,IF(C32>P32,0,1)))+(IF(E32<S32,0,IF(E32>T32,0,1)))+(IF(G32<Q32,0,IF(G32>R32,0,1)))=3,1,0) -> 1 | N32: =LEFT(B32,2) -> MK | O32: =VLOOKUP($N32,$N$3:$R$11,2,FALSE) -> 13.3 | P32: =VLOOKUP($N32,$N$3:$R$11,3,FALSE) -> 13.54 | Q32: =VLOOKUP($N32,$N$3:$R$11,4,FALSE) -> 8 | R32: =VLOOKUP($N32,$N$3:$R$11,5,FALSE) -> 14.4 | S32: =VLOOKUP($N32,$N$3:$T$11,6,FALSE) -> 395 | T32: =VLOOKUP($N32,$N$3:$T$11,7,FALSE) -> 435
A33: 45664 | B33: MK002 | C33: 13 | D33: =IF(+(IF(C33<O33,0,IF(C33>P33,0,1)))=1,1,0) -> 0 | E33: 447 | F33: =IF(+(IF(E33<S33,0,IF(E33>T33,0,1)))=1,1,0) -> 0 | G33: 12.72 | H33: =IF(+(IF(G33<Q33,0,IF(G33>R33,0,1)))=1,1,0) -> 1 | I33: =IF(+(IF(C33<O33,0,IF(C33>P33,0,1)))+(IF(E33<S33,0,IF(E33>T33,0,1)))+(IF(G33<Q33,0,IF(G33>R33,0,1)))=3,1,0) -> 0 | N33: =LEFT(B33,2) -> MK | O33: =VLOOKUP($N33,$N$3:$R$11,2,FALSE) -> 13.3 | P33: =VLOOKUP($N33,$N$3:$R$11,3,FALSE) -> 13.54 | Q33: =VLOOKUP($N33,$N$3:$R$11,4,FALSE) -> 8 | R33: =VLOOKUP($N33,$N$3:$R$11,5,FALSE) -> 14.4 | S33: =VLOOKUP($N33,$N$3:$T$11,6,FALSE) -> 395 | T33: =VLOOKUP($N33,$N$3:$T$11,7,FALSE) -> 435
A34: 45664 | B34: MK003 | C34: 12.8 | D34: =IF(+(IF(C34<O34,0,IF(C34>P34,0,1)))=1,1,0) -> 0 | E34: 430 | F34: =IF(+(IF(E34<S34,0,IF(E34>T34,0,1)))=1,1,0) -> 1 | G34: 13.19 | H34: =IF(+(IF(G34<Q34,0,IF(G34>R34,0,1)))=1,1,0) -> 1 | I34: =IF(+(IF(C34<O34,0,IF(C34>P34,0,1)))+(IF(E34<S34,0,IF(E34>T34,0,1)))+(IF(G34<Q34,0,IF(G34>R34,0,1)))=3,1,0) -> 0 | N34: =LEFT(B34,2) -> MK | O34: =VLOOKUP($N34,$N$3:$R$11,2,FALSE) -> 13.3 | P34: =VLOOKUP($N34,$N$3:$R$11,3,FALSE) -> 13.54 | Q34: =VLOOKUP($N34,$N$3:$R$11,4,FALSE) -> 8 | R34: =VLOOKUP($N34,$N$3:$R$11,5,FALSE) -> 14.4 | S34: =VLOOKUP($N34,$N$3:$T$11,6,FALSE) -> 395 | T34: =VLOOKUP($N34,$N$3:$T$11,7,FALSE) -> 435
A35: 45664 | B35: MK004 | C35: 13.5 | D35: =IF(+(IF(C35<O35,0,IF(C35>P35,0,1)))=1,1,0) -> 1 | E35: 403 | F35: =IF(+(IF(E35<S35,0,IF(E35>T35,0,1)))=1,1,0) -> 1 | G35: 11.9 | H35: =IF(+(IF(G35<Q35,0,IF(G35>R35,0,1)))=1,1,0) -> 1 | I35: =IF(+(IF(C35<O35,0,IF(C35>P35,0,1)))+(IF(E35<S35,0,IF(E35>T35,0,1)))+(IF(G35<Q35,0,IF(G35>R35,0,1)))=3,1,0) -> 1 | N35: =LEFT(B35,2) -> MK | O35: =VLOOKUP($N35,$N$3:$R$11,2,FALSE) -> 13.3 | P35: =VLOOKUP($N35,$N$3:$R$11,3,FALSE) -> 13.54 | Q35: =VLOOKUP($N35,$N$3:$R$11,4,FALSE) -> 8 | R35: =VLOOKUP($N35,$N$3:$R$11,5,FALSE) -> 14.4 | S35: =VLOOKUP($N35,$N$3:$T$11,6,FALSE) -> 395 | T35: =VLOOKUP($N35,$N$3:$T$11,7,FALSE) -> 435
A36: 45664 | B36: MK005 | C36: 13.3 | D36: =IF(+(IF(C36<O36,0,IF(C36>P36,0,1)))=1,1,0) -> 1 | E36: 443 | F36: =IF(+(IF(E36<S36,0,IF(E36>T36,0,1)))=1,1,0) -> 0 | G36: 12.25 | H36: =IF(+(IF(G36<Q36,0,IF(G36>R36,0,1)))=1,1,0) -> 1 | I36: =IF(+(IF(C36<O36,0,IF(C36>P36,0,1)))+(IF(E36<S36,0,IF(E36>T36,0,1)))+(IF(G36<Q36,0,IF(G36>R36,0,1)))=3,1,0) -> 0 | N36: =LEFT(B36,2) -> MK | O36: =VLOOKUP($N36,$N$3:$R$11,2,FALSE) -> 13.3 | P36: =VLOOKUP($N36,$N$3:$R$11,3,FALSE) -> 13.54 | Q36: =VLOOKUP($N36,$N$3:$R$11,4,FALSE) -> 8 | R36: =VLOOKUP($N36,$N$3:$R$11,5,FALSE) -> 14.4 | S36: =VLOOKUP($N36,$N$3:$T$11,6,FALSE) -> 395 | T36: =VLOOKUP($N36,$N$3:$T$11,7,FALSE) -> 435
