Workbook

Sheet FTR Spec Change (Overall)
C3: JAN | D3: FEB | E3: MAR | F3: APR | G3: MAY | H3: JUN | I3: JUL | J3: AUG | K3: SEP | L3: OCT | M3: NOV | N3: DEC | O3: YTD
B4: FTR (Current) | C4: 0.581 | D4: 0.561 | O4: =AVERAGE(C4:N4) -> 0.571
B5: FTR (Proposed Spec change) | C5: 0.601 | D5: 0.626 | O5: =AVERAGE(C5:N5) -> 0.6135
B6: FTR (Without Color/Bitterness) | C6: 0.72 | D6: 0.73 | O6: =AVERAGE(C6:N6) -> 0.725
B7: TARGET | C7: 0.8 | D7: 0.8 | E7: 0.8 | F7: 0.8 | G7: 0.8 | H7: 0.8 | I7: 0.8 | J7: 0.8 | K7: 0.8 | L7: 0.8 | M7: 0.8 | N7: 0.8 | O7: 0.8

Sheet FTR Spec Change (By Area)
C3: JAN | D3: FEB | E3: MAR | F3: APR | G3: MAY | H3: JUN | I3: JUL | J3: AUG | K3: SEP | L3: OCT | M3: NOV | N3: DEC | O3: YTD
B4: FTR BBT (Current) | C4: 0.29 | D4: 0.35 | O4: =AVERAGE(C4:N4) -> 0.32
B5: FTR BBT (Proposed) | C5: 0.32 | D5: 0.51 | O5: =AVERAGE(C5:N5) -> 0.415
B6: FTR Finished Product (Current) | C6: 0.3 | D6: 0.17 | O6: =AVERAGE(C6:N6) -> 0.235
B7: FTR Finished Product (Proposed) | C7: 0.39 | D7: 0.4 | O7: =AVERAGE(C7:N7) -> 0.395
B8: TARGET | C8: 0.8 | D8: 0.8 | E8: 0.8 | F8: 0.8 | G8: 0.8 | H8: 0.8 | I8: 0.8 | J8: 0.8 | K8: 0.8 | L8: 0.8 | M8: 0.8 | N8: 0.8 | O8: 0.8
B26: Changing Color and Bitterness specification will improve FTR for BBT and Finished Product

Sheet January '25
A1: KPI- Jan | C1: Actual | E1: KPI- Without colour | G1: Actual
A2: FTR Brewing | B2: % | C2: ='[3]FTR Brewhouse'!$I$172 -> 0.43506494 | E2: FTR Brewing | F2: % | G2: ='January ''25'!C2 -> 0.43506494
A3: Cast Gravity | B3: % | C3: ='[3]FTR Brewhouse'!$C$172 -> 0.95394737 | E3: Cast Gravity | F3: % | G3: ='January ''25'!C3 -> 0.95394737
A4: Brewing Time | B4: % | C4: ='[3]FTR Brewhouse'!$E$172 -> 0.47402597 | E4: Brewing Time | F4: % | G4: ='January ''25'!C4 -> 0.47402597
A5: Aeration Level | B5: % | C5: ='[3]FTR Brewhouse'!$G$172 -> 0.97037037 | E5: Aeration Level | F5: % | G5: ='January ''25'!C5 -> 0.97037037
A7: FTR Fermentation | B7: % | C7: ='[3]FTR Fermentation'!$P$71 -> 0.53333333 | E7: FTR Fermentation | F7: % | G7: ='January ''25'!C7 -> 0.53333333
A8: FVSV Fill Duration | B8: % | C8: ='[3]FTR Fermentation'!$D$71 -> 0.56 | E8: FVSV Fill Duration | F8: % | G8: ='January ''25'!C8 -> 0.56
A9: Yeast Dosage | B9: % | C9: ='[3]FTR Fermentation'!$G$71 -> 1 | E9: Yeast Dosage | F9: % | G9: ='January ''25'!C9 -> 1
A10: Pitched Yeast Stain | B10: % | C10: ='[3]FTR Fermentation'!$K$71 -> 1 | E10: Pitched Yeast Stain | F10: % | G10: ='January ''25'!C10 -> 1
A11: Yeast Storage Duration | B11: % | C11: ='[3]FTR Fermentation'!$M$71 -> 1 | E11: Yeast Storage Duration | F11: % | G11: ='January ''25'!C11 -> 1
A12: Fermentation Speed | B12: % | C12: ='[3]FTR Fermentation'!$I$71 -> 1 | E12: Fermentation Speed | F12: % | G12: ='January ''25'!C12 -> 1
A14: FTR BBT | B14: % | C14: ='[3]FTR BBT'!$N$85 -> 0.78125 | E14: FTR BBT | F14: % | G14: ='[6]FTR BBT'!$O$107 -> 0.97727273
A15: PG | B15: % | C15: ='[3]FTR BBT'!$D$85 -> 1 | E15: Original Gravity | F15: % | G15: ='[7]FTR BBT'!$D$86 -> 0.95081967
A16: Colour | B16: % | C16: ='[3]FTR BBT'!$J$85 -> 0.8125 | E16: Colour | F16: %
A17: CO2 | B17: % | C17: ='[3]FTR BBT'!$H$85 -> 0.984375 | E17: CO2 | F17: % | G17: ='[6]FTR BBT'!$H$107 -> 1
A18: DO | B18: % | C18: ='[3]FTR BBT'!$F$85 -> 1 | E18: DO | F18: % | G18: ='[6]FTR BBT'!$F$107 -> 1
A19: Haze | B19: % | C19: ='[3]FTR BBT'!$L$85 -> 0.96226415 | E19: Haze | F19: % | G19: ='[6]FTR BBT'!$L$107 -> 1
A21: FTR Packaging | B21: % | C21: ='[3]FTR Packaging'!$L$62 -> 0.87804878 | E21: FTR Packaging | F21: % | G21: ='[6]FTR Packaging'!$L$72 -> 0.92307692
A22: PU | B22: % | C22: ='[3]FTR Packaging'!$F$62 -> 0.87804878 | E22: PU | F22: % | G22: ='[6]FTR Packaging'!$F$72 -> 0.92307692
A23: Fill Volume | B23: % | C23: ='[3]FTR Packaging'!$D$62 -> 1 | E23: Fill Volume | F23: % | G23: ='[6]FTR Packaging'!$D$72 -> 1
A24: TOP | B24: % | C24: ='[3]FTR Packaging'!$H$62 -> 1 | E24: TOP | F24: % | G24: ='[6]FTR Packaging'!$H$72 -> 1
A25: Packaging Index | B25: % | C25: ='[3]FTR Packaging'!$J$62 -> 1 | E25: Packaging Index | F25: % | G25: ='[6]FTR Packaging'!$J$72 -> 0.96078431
A27: FTR Micro | B27: % | C27: 0.76 | E27: FTR Micro | F27: % | G27: ='January ''25'!C27 -> 0.76
A28: MicroPack - MicroTunnel | B28: % | C28: 1 | E28: MicroPack - MicroTunnel | F28: % | G28: ='January ''25'!C28 -> 1
A29: MicroBeer - MicroFerment | B29: % | C29: 0.76 | E29: MicroBeer - MicroFerment | F29: % | G29: ='January ''25'!C29 -> 0.76
A31: FTR Finished Product | B31: % | C31: ='[3]FTR Finished Product'!$L$60 -> 0.80487805 | E31: FTR Finished Product | F31: % | G31: ='[6]FTR Finished Product'!$M$72 -> 0.94230769
A32: Colour | B32: % | C32: ='[3]FTR Finished Product'!$J$60 -> 0.85714286 | E32: Colour | F32: %
A33: ISO-H | B33: % | C33: ='[3]FTR Finished Product'!$F$60 -> 0.925 | E33: ISO-H | F33: % | G33: ='[6]FTR Finished Product'!$F$72 -> 1
A34: PG | B34: % | C34: ='[3]FTR Finished Product'!$D$60 -> 1 | E34: Original Gravity | F34: % | G34: ='[6]FTR Finished Product'!$D$72 -> 0.94230769
A35: TIPO | B35: % | C35: ='[3]FTR Finished Product'!$H$60 -> 0.97142857 | E35: TIPO | F35: % | G35: ='[6]FTR Finished Product'!$H$72 -> 1
C37: =(C2+C7+C14+C21+C27+C31)/6 -> 0.69876252 | G37: =(G2+G7+G14+G21+G27+G31)/6 -> 0.7618426

Sheet February '24
A1: KPI- Feb | C1: Actual | E1: KPI- Without colour | G1: Actual
A2: FTR Brewing | B2: % | C2: ='[8]FTR Brewhouse'!$I$325 -> 0.41538462 | E2: FTR Brewing | F2: % | G2: ='February ''24'!C2 -> 0.41538462
A3: Cast Gravity | B3: % | C3: ='[8]FTR Brewhouse'!$C$325 -> 0.92307692 | E3: Cast Gravity | F3: % | G3: ='February ''24'!C3 -> 0.92307692
A4: Brewing Time | B4: % | C4: ='[8]FTR Brewhouse'!$E$325 -> 0.43846154 | E4: Brewing Time | F4: % | G4: ='February ''24'!C4 -> 0.43846154
A5: Aeration Level | B5: % | C5: ='[8]FTR Brewhouse'!$G$325 -> 1 | E5: Aeration Level | F5: % | G5: ='February ''24'!C5 -> 1
A7: FTR Fermentation | B7: % | C7: ='[8]FTR Fermentation'!$P$109 -> 0.5625 | E7: FTR Fermentation | F7: % | G7: ='February ''24'!C7 -> 0.5625
A8: FVSV Fill Duration | B8: % | C8: ='[8]FTR Fermentation'!$D$109 -> 0.77777778 | E8: FVSV Fill Duration | F8: % | G8: ='February ''24'!C8 -> 0.77777778
A9: Yeast Dosage | B9: % | C9: ='[8]FTR Fermentation'!$G$109 -> 1 | E9: Yeast Dosage | F9: % | G9: ='February ''24'!C9 -> 1
A10: Pitched Yeast Stain | B10: % | C10: ='[8]FTR Fermentation'!$K$109 -> 1 | E10: Pitched Yeast Stain | F10: % | G10: ='February ''24'!C10 -> 1
A11: Yeast Storage Duration | B11: % | C11: ='[8]FTR Fermentation'!$M$109 -> 1 | E11: Yeast Storage Duration | F11: % | G11: ='February ''24'!C11 -> 1
A12: Fermentation Speed | B12: % | C12: ='[8]FTR Fermentation'!$I$109 -> 0.85714286 | E12: Fermentation Speed | F12: % | G12: ='February ''24'!C12 -> 0.85714286
A14: FTR BBT | B14: % | C14: ='[8]FTR BBT'!$N$175 -> 0.95238095 | E14: FTR BBT | F14: % | G14: ='[8]FTR BBT'!$O$175 -> 0.95238095
A15: PG | B15: % | C15: ='[8]GBL BBT Score '!$D$176 -> 0.95384615 | E15: Original Gravity | F15: % | G15: ='February ''24'!C15 -> 0.95384615
A16: Colour | B16: % | C16: ='[8]FTR BBT'!$J$175 -> 1 | E16: Colour | F16: %
A17: CO2 | B17: % | C17: ='[8]FTR BBT'!$H$175 -> 1 | E17: CO2 | F17: % | G17: ='February ''24'!C17 -> 1
A18: DO | B18: % | C18: ='[8]FTR BBT'!$F$175 -> 1 | E18: DO | F18: % | G18: ='February ''24'!C18 -> 1
A19: Haze | C19: ='[8]FTR BBT'!$L$175 -> 1 | G19: ='February ''24'!C19 -> 1
A21: FTR Packaging | B21: % | C21: ='[8]FTR Packaging'!$L$120 -> 1 | E21: FTR Packaging | F21: % | G21: ='[9]FTR Packaging'!$L$154 -> 0.93548387
A22: PU | B22: % | C22: ='[8]FTR Packaging'!$H$120 -> 1 | E22: PU | F22: % | G22: ='[9]FTR Packaging'!$F$154 -> 0.91666667
A23: Fill Volume | B23: % | C23: ='[8]FTR Packaging'!$D$120 -> 1 | E23: Fill Volume | F23: % | G23: ='[8]FTR Packaging'!$F$120 -> 1
A24: TOP | B24: % | C24: ='[8]FTR Packaging'!$H$120 -> 1 | E24: TOP | F24: % | G24: ='[8]FTR Packaging'!$H$120 -> 1
A25: Packaging Index | B25: % | C25: ='[8]FTR Packaging'!$J$120 -> 1 | E25: Packaging Index | F25: % | G25: ='[8]FTR Packaging'!$J$120 -> 1
A27: FTR Micro | B27: % | C27: 0.867 | E27: FTR Micro | F27: % | G27: ='February ''24'!C27 -> 0.867
A28: MicroPack - MicroTunnel | B28: % | C28: 1 | E28: MicroPack - MicroTunnel | F28: % | G28: ='February ''24'!C28 -> 1
A29: MicroBeer - MicroFerment | B29: % | C29: 0.867 | E29: MicroBeer - MicroFerment | F29: % | G29: ='February ''24'!C29 -> 0.867
A31: FTR Finished Product | B31: % | C31: ='[8]FTR Finished Product'!$L$122 -> 0.86046512 | E31: FTR Finished Product | F31: % | G31: ='[8]FTR Finished Product'!$M$122 -> 0.88372093
A32: Colour | B32: % | C32: ='[8]FTR Finished Product'!$J$122 -> 0.95238095 | E32: Colour | F32: %
A33: ISO-H | B33: % | C33: ='[8]FTR Finished Product'!$F$122 -> 0.95121951 | E33: ISO-H | F33: % | G33: ='[8]FTR Finished Product'!$H$122 -> 1
A34: PG | B34: % | C34: ='[8]FTR Finished Product'!$D$122 -> 0.93023256 | E34: Original Gravity | F34: % | G34: ='February ''24'!C34 -> 0.93023256
A35: TIPO | B35: % | C35: ='[8]FTR Finished Product'!$H$122 -> 1 | E35: TOP | F35: % | G35: ='February ''24'!C35 -> 1
C38: =(C2+C7+C14+C21+C27+C31)/6 -> 0.77628845 | G38: =(G2+G7+G14+G21+G27+G31)/6 -> 0.76941173
A39: With Colour | B39: YTD | C39: =AVERAGE('January ''25'!C37,C38) -> 0.73752548 | E39: With-out Colour | F39: YTD | G39: =AVERAGE('January ''25'!G37,'February ''24'!G38) -> 0.76562717

Sheet March '24
A1: KPI- March | C1: Actual | E1: KPI- Without colour | G1: Actual
A2: FTR Brewing | B2: % | C2: ='[8]FTR Brewhouse'!$I$482 -> 0.36 | E2: FTR Brewing | F2: % | G2: ='[8]FTR Brewhouse'!$I$482 -> 0.36
A3: Cast Gravity | B3: % | C3: ='[8]FTR Brewhouse'!$C$482 -> 0.86666667 | E3: Cast Gravity | F3: % | G3: ='[8]FTR Brewhouse'!$C$482 -> 0.86666667
A4: Brewing Time | B4: % | C4: ='[8]FTR Brewhouse'!$E$482 -> 0.44 | E4: Brewing Time | F4: % | G4: ='[8]FTR Brewhouse'!$E$482 -> 0.44
A5: Aeration Level | B5: % | C5: ='[8]FTR Brewhouse'!$G$482 -> 0.98484848 | E5: Aeration Level | F5: % | G5: ='[8]FTR Brewhouse'!$G$482 -> 0.98484848
A7: FTR Fermentation | B7: % | C7: ='[8]FTR Fermentation'!$P$149 -> 0.48571429 | E7: FTR Fermentation | F7: % | G7: ='[8]FTR Fermentation'!$P$200 -> 0.52631579
A8: FVSV Fill Duration | B8: % | C8: ='[8]FTR Fermentation'!$D$149 -> 0.76 | E8: FVSV Fill Duration | F8: % | G8: ='[8]FTR Fermentation'!$D$200 -> 0.82608696
A9: Yeast Dosage | B9: % | C9: ='[8]FTR Fermentation'!$G$149 -> 1 | E9: Yeast Dosage | F9: % | G9: ='[8]FTR Fermentation'!$G$200 -> 1
A10: Pitched Yeast Stain | B10: % | C10: ='[8]FTR Fermentation'!$K$149 -> 1 | E10: Pitched Yeast Stain | F10: % | G10: ='[8]FTR Fermentation'!$K$200 -> 1
A11: Yeast Storage Duration | B11: % | C11: ='[8]FTR Fermentation'!$M$149 -> 0.91428571 | E11: Yeast Storage Duration | F11: % | G11: ='[8]FTR Fermentation'!$M$200 -> 1
A12: Fermentation Speed | B12: % | C12: ='[8]FTR Fermentation'!$I$149 -> 0.7027027 | E12: Fermentation Speed | F12: % | G12: ='[8]FTR Fermentation'!$I$200 -> 0.58823529
A14: FTR BBT | B14: % | C14: ='[8]FTR BBT'!$N$253 -> 0.94520548 | E14: FTR BBT | F14: % | G14: ='[8]FTR BBT'!$O$253 -> 0.98630137
A15: PG | B15: % | C15: ='[8]FTR BBT'!$D$253 -> 0.98648649 | E15: Original Gravity | F15: % | G15: ='[8]FTR BBT'!$D$253 -> 0.98648649
A16: Colour | B16: % | C16: ='[8]FTR BBT'!$J$253 -> 0.95945946 | E16: Colour | F16: %
A17: CO2 | B17: % | C17: ='[8]FTR BBT'!$H$253 -> 1 | E17: CO2 | F17: % | G17: ='[8]FTR BBT'!$H$253 -> 1
A18: DO | B18: % | C18: ='[8]FTR BBT'!$F$253 -> 1 | E18: DO | F18: % | G18: ='[8]FTR BBT'!$F$253 -> 1
A19: Haze | B19: % | C19: ='[8]FTR BBT'!$L$253 -> 1 | G19: ='[8]FTR BBT'!$L$253 -> 1
A21: FTR Packaging | B21: % | C21: ='[8]FTR Packaging'!$L$169 -> 0.97727273 | E21: FTR Packaging | F21: % | G21: ='[8]FTR Packaging'!$L$169 -> 0.97727273
A22: PU | B22: % | C22: ='[8]FTR Packaging'!$F$169 -> 1 | E22: PU | F22: % | G22: ='[8]FTR Packaging'!$F$169 -> 1
A23: Fill Volume | B23: % | C23: ='[8]FTR Packaging'!$D$169 -> 1 | E23: Fill Volume | F23: % | G23: ='[8]FTR Packaging'!$D$169 -> 1
A24: Packaging Index | B24: % | C24: ='[8]FTR Packaging'!$J$169 -> 0.97674419 | E24: Packaging Index | F24: % | G24: ='[8]FTR Packaging'!$J$169 -> 0.97674419
A26: FTR Micro | B26: % | C26: 0.83 | E26: FTR Micro | F26: %
A27: MicroPack - MicroTunnel | B27: % | C27: 1 | E27: MicroPack - MicroTunnel | F27: %
A28: MicroBeer - MicroFerment | B28: % | C28: 0.83 | E28: MicroBeer - MicroFerment | F28: %
A30: FTR Finished Product | B30: % | C30: ='[8]FTR Finished Product'!$L$172 -> 1 | E30: FTR Finished Product | F30: % | G30: ='[8]FTR Finished Product'!$L$172 -> 1
A31: Colour | B31: % | C31: ='[8]FTR Finished Product'!$J$172 -> 1 | E31: Colour | F31: % | G31: ='[8]FTR Finished Product'!$J$172 -> 1
A32: ISO-H | B32: % | C32: ='[8]FTR Finished Product'!$F$172 -> 1 | E32: ISO-H | F32: % | G32: ='[8]FTR Finished Product'!$F$172 -> 1
A33: PG | B33: % | C33: ='[8]FTR Finished Product'!$D$172 -> 1 | E33: Original Gravity | F33: % | G33: ='[8]FTR Finished Product'!$D$172 -> 1
A34: TIPO | B34: % | C34: ='[8]FTR Finished Product'!$H$172 -> 1 | E34: TOP | F34: % | G34: ='[8]FTR Finished Product'!$H$172 -> 1
C36: =(C2+C7+C14+C21+C26+C30)/6 -> 0.76636542 | G36: =(G2+G7+G14+G21+G26+G30)/6 -> 0.64164831
A37: With Colour | B37: YTD | C37: =AVERAGE('January ''25'!C37,'February ''24'!C38,C36) -> 0.74713879 | E37: With-out Colour | F37: YTD | G37: =AVERAGE('January ''25'!G37,'February ''24'!G38,'March ''24'!G36) -> 0.72430088

Sheet April '24
A1: KPI- April | C1: Actual | E1: KPI- Without colour | G1: Actual
A2: FTR Brewing | B2: % | C2: ='[8]FTR Brewhouse'!$I$630 -> 0.35779817 | E2: FTR Brewing | F2: % | G2: ='[8]FTR Brewhouse'!$I$630 -> 0.35779817
A3: Cast Gravity | B3: % | C3: ='[8]FTR Brewhouse'!$C$630 -> 0.92727273 | E3: Cast Gravity | F3: % | G3: ='[8]FTR Brewhouse'!$C$630 -> 0.92727273
A4: Brewing Time | B4: % | C4: ='[8]FTR Brewhouse'!$E$630 -> 0.38181818 | E4: Brewing Time | F4: % | G4: ='[8]FTR Brewhouse'!$E$630 -> 0.38181818
A5: Aeration Level | B5: % | C5: ='[8]FTR Brewhouse'!$G$630 -> 1 | E5: Aeration Level | F5: % | G5: ='[8]FTR Brewhouse'!$G$630 -> 1
A7: FTR Fermentation | B7: % | C7: ='[8]FTR Fermentation'!$P$200 -> 0.52631579 | E7: FTR Fermentation | F7: % | G7: ='[8]FTR Fermentation'!$P$200 -> 0.52631579
A8: FVSV Fill Duration | B8: % | C8: ='[8]FTR Fermentation'!$D$200 -> 0.82608696 | E8: FVSV Fill Duration | F8: % | G8: ='[8]FTR Fermentation'!$D$200 -> 0.82608696
A9: Yeast Dosage | B9: % | C9: ='[8]FTR Fermentation'!$G$200 -> 1 | E9: Yeast Dosage | F9: % | G9: ='[8]FTR Fermentation'!$G$200 -> 1
A10: Pitched Yeast Stain | B10: % | C10: ='[8]FTR Fermentation'!$K$200 -> 1 | E10: Pitched Yeast Stain | F10: % | G10: ='[8]FTR Fermentation'!$K$200 -> 1
A11: Yeast Storage Duration | B11: % | C11: ='[8]FTR Fermentation'!$M$200 -> 1 | E11: Yeast Storage Duration | F11: % | G11: ='[8]FTR Fermentation'!$M$200 -> 1
A12: Fermentation Speed | B12: % | C12: ='[8]FTR Fermentation'!$I$200 -> 0.58823529 | E12: Fermentation Speed | F12: % | G12: ='[8]FTR Fermentation'!$I$200 -> 0.58823529
A14: FTR BBT | B14: % | C14: ='[8]FTR BBT'!$N$333 -> 0.95890411 | E14: FTR BBT | F14: % | G14: ='[8]FTR BBT'!$O$321 -> 1
A15: PG | B15: % | C15: ='[8]FTR BBT'!$D$333 -> 0.98648649 | E15: Original Gravity | F15: % | G15: ='[8]FTR BBT'!$D$321 -> 2.05
A16: Colour | B16: % | C16: ='[8]FTR BBT'!$J$333 -> 0.97297297 | E16: Colour | F16: %
A17: CO2 | B17: % | C17: ='[8]FTR BBT'!$H$333 -> 1 | E17: CO2 | F17: % | G17: ='[8]FTR BBT'!$H$321 -> 2.8
A18: DO | B18: % | C18: ='[8]FTR BBT'!$F$333 -> 1 | E18: DO | F18: % | G18: ='[8]FTR BBT'!$F$321 -> 0.03
A19: Haze | B19: % | C19: ='[8]FTR BBT'!$L$333 -> 1 | G19: ='[8]FTR BBT'!$L$321 -> 0.31
A21: FTR Packaging | B21: % | C21: ='[8]FTR Packaging'!$L$224 -> 0.98 | E21: FTR Packaging | F21: % | G21: ='[8]FTR Packaging'!$L$224 -> 0.98
A22: PU | B22: % | C22: ='[8]FTR Packaging'!$F$224 -> 0.97959184 | E22: PU | F22: % | G22: ='[8]FTR Packaging'!$F$224 -> 0.97959184
A23: Fill Volume | B23: % | C23: ='[8]FTR Packaging'!$D$224 -> 1 | E23: Fill Volume | F23: % | G23: ='[8]FTR Packaging'!$D$224 -> 1
A24: Packaging Index | B24: % | C24: ='[8]FTR Packaging'!$J$224 -> 1 | E24: Packaging Index | F24: % | G24: ='[8]FTR Packaging'!$J$224 -> 1
A26: FTR Micro | B26: % | C26: 0.783 | E26: FTR Micro | F26: %
A27: MicroPack - MicroTunnel | B27: % | C27: 1 | E27: MicroPack - MicroTunnel | F27: %
A28: MicroBeer - MicroFerment | B28: % | C28: 0.783 | E28: MicroBeer - MicroFerment | F28: %
A30: FTR Finished Product | B30: % | C30: ='[8]FTR Finished Product'!$L$228 -> 1 | E30: FTR Finished Product | F30: % | G30: ='[8]FTR Finished Product'!$M$229 -> #REF!
A31: Colour | B31: % | C31: ='[8]FTR Finished Product'!$J$228 -> 1 | E31: Colour | F31: % | G31: ='[8]FTR Finished Product'!$J$229 -> #REF!
A32: ISO-H | B32: % | C32: ='[8]FTR Finished Product'!$F$228 -> 1 | E32: ISO-H | F32: % | G32: ='[8]FTR Finished Product'!$F$229 -> #REF!
A33: PG | B33: % | C33: ='[8]FTR Finished Product'!$D$228 -> 1 | E33: Original Gravity | F33: % | G33: ='[8]FTR Finished Product'!$D$229 -> #REF!
A34: TOP | B34: % | C34: ='[8]FTR Finished Product'!$H$228 -> 1 | E34: TOP | F34: % | G34: ='[8]FTR Finished Product'!$H$229 -> #REF!
C36: =(C2+C7+C14+C21+C26+C30)/6 -> 0.76766968 | G36: =(G2+G7+G14+G21+G26+G30)/6 -> #REF!
B37: YTD | C37: =AVERAGE('January ''25'!C37,'February ''24'!C38,'March ''24'!C36,'April ''24'!C36) -> 0.75227151 | E37: With-out Colour | F37: YTD | G37: =AVERAGE('January ''25'!G37,'February ''24'!G38,'March ''24'!G36,'April ''24'!G36) -> #REF!

Sheet June '24 
A1: KPI- June | C1: Actual | E1: KPI- Without colour | G1: Actual
A2: FTR Brewing | B2: % | C2: ='[8]FTR Brewhouse'!$I$1060 -> 0.51388889 | E2: FTR Brewing | F2: % | G2: ='[8]FTR Brewhouse'!$I$1060 -> 0.51388889
A3: Cast Gravity | B3: % | C3: ='[10]FTR Brewhouse'!$C$1060 -> 0.85526316 | E3: Cast Gravity | F3: % | G3: ='[8]FTR Brewhouse'!$C$1060 -> 0.82894737
A4: Brewing Time | B4: % | C4: ='[10]FTR Brewhouse'!$E$1060 -> 0.60130719 | E4: Brewing Time | F4: % | G4: ='[8]FTR Brewhouse'!$E$1060 -> 0.60130719
A5: Aeration Level | B5: % | C5: ='[10]FTR Brewhouse'!$G$1060 -> 0.97692308 | E5: Aeration Level | F5: % | G5: ='[8]FTR Brewhouse'!$G$1060 -> 1
A7: FTR Fermentation | B7: % | C7: ='[10]FTR Fermentation'!$P$286 -> 0.42307692 | E7: FTR Fermentation | F7: % | G7: ='June ''24 '!C7 -> 0.42307692
A8: FVSV Fill Duration | B8: % | C8: ='[10]FTR Fermentation'!$D$286 -> 0.84615385 | E8: FVSV Fill Duration | F8: % | G8: ='June ''24 '!C8 -> 0.84615385
A9: Yeast Dosage | B9: % | C9: ='[10]FTR Fermentation'!$G$286 -> 1 | E9: Yeast Dosage | F9: % | G9: ='June ''24 '!C9 -> 1
A10: Pitched Yeast Stain | B10: % | C10: ='[10]FTR Fermentation'!$K$286 -> 1 | E10: Pitched Yeast Stain | F10: % | G10: ='June ''24 '!C10 -> 1
A11: Yeast Storage Duration | B11: % | C11: ='[10]FTR Fermentation'!$M$286 -> 0.73076923 | E11: Yeast Storage Duration | F11: % | G11: ='June ''24 '!C11 -> 0.73076923
A12: Fermentation Speed | B12: % | C12: ='[10]FTR Fermentation'!$I$286 -> 0.61538462 | E12: Fermentation Speed | F12: % | G12: ='June ''24 '!C12 -> 0.61538462
A14: FTR BBT | B14: % | C14: ='[10]FTR BBT'!$N$460 -> 0.84848485 | E14: FTR BBT | F14: % | G14: ='[8]FTR BBT'!$O$472 -> 1
A15: PG | B15: % | C15: ='[10]FTR BBT'!$D$460 -> 0.92424242 | E15: PG | F15: % | G15: ='[8]FTR BBT'!$D$472 -> 2.13
A16: Colour | B16: % | C16: ='[10]FTR BBT'!$J$460 -> 0.92307692 | E16: Colour | F16: %
A17: CO2 | B17: % | C17: ='[10]FTR BBT'!$H$460 -> 1 | E17: CO2 | F17: % | G17: ='[8]FTR BBT'!$H$472 -> 2.85
A18: DO | B18: % | C18: ='[10]FTR BBT'!$F$460 -> 1 | E18: DO | F18: % | G18: ='[8]FTR BBT'!$F$472 -> 0.03
A19: Haze | B19: % | C19: ='[10]FTR BBT'!$L$460 -> 0.98275862 | E19: Haze | F19: % | G19: ='[8]FTR BBT'!$L$472 -> 0.57
A21: FTR Packaging | B21: % | C21: ='[10]FTR Packaging'!$L$374 -> 0.9137931 | E21: FTR Packaging | F21: % | G21: ='June ''24 '!C21 -> 0.9137931
A22: PU | B22: % | C22: ='[10]FTR Packaging'!$F$374 -> 0.91836735 | E22: PU | F22: % | G22: ='June ''24 '!C22 -> 0.91836735
A23: Fill Volume | B23: % | C23: ='[10]FTR Packaging'!$D$374 -> 0.98214286 | E23: Fill Volume | F23: % | G23: ='June ''24 '!C23 -> 0.98214286
A24: Packaging Index | B24: % | C24: ='[10]FTR Packaging'!$J$374 -> 0.98181818 | E24: Packaging Index | F24: % | G24: ='June ''24 '!C24 -> 0.98181818
A26: FTR Micro | B26: % | C26: 0.763 | E26: FTR Micro | F26: % | G26: ='June ''24 '!C26 -> 0.763
A27: MicroPack - MicroTunnel | B27: % | C27: 1 | E27: MicroPack - MicroTunnel | F27: % | G27: ='June ''24 '!C27 -> 1
A28: MicroBeer - MicroFerment | B28: % | C28: 0.763 | E28: MicroBeer - MicroFerment | F28: % | G28: ='June ''24 '!C28 -> 0.763
A30: FTR Finished Product | B30: % | C30: ='[10]FTR Finished Product'!$L$386 -> 0 | E30: FTR Finished Product | F30: % | G30: ='[11]FTR Finished Product'!$M$364 -> 0.91111111
A31: Colour | B31: % | C31: ='[10]FTR Finished Product'!$J$386 -> 0 | E31: Colour | F31: %
A32: ISO-H | B32: % | C32: ='[10]FTR Finished Product'!$F$386 -> 0 | E32: ISO-H | F32: % | G32: ='June ''24 '!C32 -> 0
A33: PG | B33: % | C33: ='[10]FTR Finished Product'!$D$386 -> 0 | E33: PG | F33: % | G33: ='June ''24 '!C33 -> 0
A34: TOP | B34: % | C34: ='[10]FTR Finished Product'!$H$386 -> 0 | E34: TOP | F34: % | G34: ='June ''24 '!C34 -> 0
C36: =(C2+C7+C14+C21+C26+C30)/6 -> 0.57704063 | G36: =(G2+G7+G14+G21+G26+G30)/6 -> 0.754145
B37: YTD | C37: =AVERAGE('January ''25'!C37,'February ''24'!C38,'March ''24'!C36,'April ''24'!C36,#REF!,C36) -> #REF! | E37: With-out Colour | F37: YTD | G37: =AVERAGE('January ''25'!G37,'February ''24'!G38,'March ''24'!G36,'April ''24'!G36,#REF!,'June ''24 '!G36) -> #REF!

Sheet July '24
A1: KPI- JULY | C1: Actual | E1: KPI- Without colour | G1: Actual
A2: FTR Brewing | B2: % | C2: ='[10]FTR Brewhouse'!$I$1223 -> 0.51875 | E2: FTR Brewing | F2: % | G2: ='July ''24'!C2 -> 0.51875
A3: Cast Gravity | B3: % | C3: ='[10]FTR Brewhouse'!$C$1223 -> 0.9625 | E3: Cast Gravity | F3: % | G3: ='July ''24'!C3 -> 0.9625
A4: Brewing Time | B4: % | C4: ='[10]FTR Brewhouse'!$E$1223 -> 0.5375 | E4: Brewing Time | F4: % | G4: ='July ''24'!C4 -> 0.5375
A5: Aeration Level | B5: % | C5: ='[10]FTR Brewhouse'!$G$1223 -> 1 | E5: Aeration Level | F5: % | G5: ='July ''24'!C5 -> 1
A7: FTR Fermentation | B7: % | C7: ='[10]FTR Fermentation'!$P$319 -> 0.61538462 | E7: FTR Fermentation | F7: % | G7: #DIV/0!
A8: FVSV Fill Duration | B8: % | C8: ='[10]FTR Fermentation'!$D$319 -> 0.70833333 | E8: FVSV Fill Duration | F8: % | G8: #DIV/0!
A9: Yeast Dosage | B9: % | C9: ='[10]FTR Fermentation'!$G$319 -> 1 | E9: Yeast Dosage | F9: % | G9: #DIV/0!
A10: Pitched Yeast Stain | B10: % | C10: ='[10]FTR Fermentation'!$K$319 -> 1 | E10: Pitched Yeast Stain | F10: % | G10: #DIV/0!
A11: Yeast Storage Duration | B11: % | C11: ='[10]FTR Fermentation'!$M$319 -> 0.84615385 | E11: Yeast Storage Duration | F11: % | G11: #DIV/0!
A12: Fermentation Speed | B12: % | C12: ='[10]FTR Fermentation'!$I$319 -> 0.83333333 | E12: Fermentation Speed | F12: % | G12: #DIV/0!
A14: FTR BBT | B14: % | C14: ='[10]FTR BBT'!$N$533 -> 0.86956522 | E14: FTR BBT | F14: % | G14: ='[10]FTR BBT'!$O$533 -> 0.86956522
A15: Original Gravity | B15: % | C15: ='[10]FTR BBT'!$D$533 -> 0.95652174 | E15: Original Gravity | F15: % | G15: ='[10]FTR BBT'!$D$533 -> 0.95652174
A16: Colour | B16: % | C16: ='[10]FTR BBT'!$J$533 -> 1 | E16: Colour | F16: %
A17: CO2 | B17: % | C17: ='[10]FTR BBT'!$H$533 -> 1 | E17: CO2 | F17: % | G17: ='[10]FTR BBT'!$H$533 -> 1
A18: DO | B18: % | C18: ='[10]FTR BBT'!$F$533 -> 1 | E18: DO | F18: % | G18: ='[10]FTR BBT'!$F$533 -> 1
A20: FTR Packaging | B20: % | C20: ='[10]FTR Packaging'!$L$374 -> 0.9137931 | E20: FTR Packaging | F20: % | G20: ='[10]FTR Packaging'!$L$374 -> 0.9137931
A21: PU | B21: % | C21: ='[10]FTR Packaging'!$F$374 -> 0.91836735 | E21: PU | F21: % | G21: ='[10]FTR Packaging'!$F$374 -> 0.91836735
A22: Fill Volume | B22: % | C22: ='[10]FTR Packaging'!$D$374 -> 0.98214286 | E22: Fill Volume | F22: % | G22: ='[10]FTR Packaging'!$D$374 -> 0.98214286
A23: Packaging Index | B23: % | C23: ='[10]FTR Packaging'!$J$374 -> 0.98181818 | E23: Packaging Index | F23: % | G23: ='[10]FTR Packaging'!$J$374 -> 0.98181818
A25: FTR Micro | B25: % | C25: 0.84 | E25: FTR Micro | F25: % | G25: ='July ''24'!$C$25 -> 0.84
A26: MicroPack - MicroTunnel | B26: % | C26: 1 | E26: MicroPack - MicroTunnel | F26: % | G26: ='July ''24'!C26 -> 1
A27: MicroBeer - MicroFerment | B27: % | C27: 0.8435 | E27: MicroBeer - MicroFerment | F27: % | G27: ='July ''24'!C27 -> 0.8435
A29: FTR Finished Product | B29: % | C29: ='[10]FTR Finished Product'!$L$386 -> 0 | E29: FTR Finished Product | F29: % | G29: ='[10]FTR Finished Product'!$M$386 -> 0
A30: Colour | B30: % | C30: ='[10]FTR Finished Product'!$J$386 -> 0 | E30: Colour | F30: %
A31: ISO-H | B31: % | C31: ='[10]FTR Finished Product'!$F$386 -> 0 | E31: ISO-H | F31: % | G31: ='[10]FTR Finished Product'!$F$386 -> 0
A32: Original Gravity | B32: % | C32: ='[10]FTR Finished Product'!$D$386 -> 0 | E32: Original Gravity | F32: % | G32: ='[10]FTR Finished Product'!$D$386 -> 0
A33: TOP | B33: % | C33: ='[10]FTR Finished Product'!$H$386 -> 0 | E33: TOP | F33: % | G33: ='[10]FTR Finished Product'!$H$386 -> 0
C35: =(C2+C7+C14+C20+C25+C29)/6 -> 0.62624882 | G35: =(G2+G7+G14+G20+G25+G29)/6 -> #DIV/0!
B36: YTD | C36: =AVERAGE('January ''25'!C37,'February ''24'!C38,'March ''24'!C36,'April ''24'!C36,#REF!,'June ''24 '!C36,C35) -> #REF! | E36: With-out Colour | F36: YTD | G36: =AVERAGE('January ''25'!G37,'February ''24'!G38,'March ''24'!G36,'April ''24'!G36,#REF!,'June ''24 '!G36,'July ''24'!G35) -> #REF!

Sheet August '24
A1: KPI- Aug | C1: Actual | E1: KPI- Without colour | G1: Actual
A2: FTR Brewing | B2: % | C2: ='[10]FTR Brewhouse'!$I$1377 -> 0.52054795 | E2: FTR Brewing | F2: % | G2: ='August ''24'!C2 -> 0.52054795
A3: Cast Gravity | B3: % | C3: ='[10]FTR Brewhouse'!$C$1377 -> 0.94520548 | E3: Cast Gravity | F3: % | G3: ='August ''24'!C3 -> 0.94520548
A4: Brewing Time | B4: % | C4: ='[10]FTR Brewhouse'!$E$1377 -> 0.55479452 | E4: Brewing Time | F4: % | G4: ='August ''24'!C4 -> 0.55479452
A5: Aeration Level | B5: % | C5: ='[10]FTR Brewhouse'!$G$1377 -> 0.968 | E5: Aeration Level | F5: % | G5: ='August ''24'!C5 -> 0.968
A7: FTR Fermentation | B7: % | C7: ='[10]FTR Fermentation'!$P$356 -> 0.83333333 | E7: FTR Fermentation | F7: % | G7: ='August ''24'!C7 -> 0.83333333
A8: FVSV Fill Duration | B8: % | C8: ='[10]FTR Fermentation'!$D$356 -> 0.625 | E8: FVSV Fill Duration | F8: % | G8: ='August ''24'!C8 -> 0.625
A9: Yeast Dosage | B9: % | C9: ='[10]FTR Fermentation'!$G$356 -> 1 | E9: Yeast Dosage | F9: % | G9: ='August ''24'!C9 -> 1
A10: Pitched Yeast Stain | B10: % | C10: ='[10]FTR Fermentation'!$K$356 -> 1 | E10: Pitched Yeast Stain | F10: % | G10: ='August ''24'!C10 -> 1
A11: Yeast Storage Duration | B11: % | C11: ='[10]FTR Fermentation'!$M$356 -> 0.83333333 | E11: Yeast Storage Duration | F11: % | G11: ='August ''24'!C11 -> 0.83333333
A12: Fermentation Speed | B12: % | C12: ='[10]FTR Fermentation'!$I$356 -> 0.875 | E12: Fermentation Speed | F12: % | G12: ='August ''24'!C12 -> 0.875
A14: FTR BBT | B14: % | C14: ='[10]FTR BBT'!$N$615 -> 1 | E14: FTR BBT | F14: % | G14: ='[10]FTR BBT'!$O$615 -> 1
A15: Original Gravity | B15: % | C15: ='[10]FTR BBT'!$D$615 -> 0.98701299 | E15: Original Gravity | F15: % | G15: ='August ''24'!C15 -> 0.98701299
A16: Colour | B16: % | C16: ='[10]FTR BBT'!$J$615 -> 1 | E16: Colour | F16: %
A17: CO2 | B17: % | C17: ='[10]FTR BBT'!$H$615 -> 1 | E17: CO2 | F17: % | G17: ='August ''24'!C17 -> 1
A18: DO | B18: % | C18: ='[10]FTR BBT'!$F$615 -> 1 | E18: DO | F18: % | G18: ='August ''24'!C18 -> 1
A20: FTR Packaging | B20: % | C20: ='[10]FTR Packaging'!$L$430 -> 0.96078431 | E20: FTR Packaging | G20: ='August ''24'!C20 -> 0.96078431
A21: PU | B21: % | C21: ='[10]FTR Packaging'!$F$430 -> 0.96 | E21: PU | G21: ='August ''24'!C21 -> 0.96
A22: Fill Volume | B22: % | C22: ='[10]FTR Packaging'!$D$430 -> 0.98039216 | E22: Fill Volume | G22: ='August ''24'!C22 -> 0.98039216
A23: Packaging Index | B23: % | C23: ='[10]FTR Packaging'!$J$430 -> 0.91836735 | E23: Packaging Index | G23: ='August ''24'!C23 -> 0.91836735
A25: FTR Micro | B25: % | C25: 0.869 | E25: FTR Micro
A26: MicroPack - MicroTunnel | B26: % | C26: 1 | E26: MicroPack - MicroTunnel
A27: MicroBeer - MicroFerment | B27: % | C27: 0.869 | E27: MicroBeer - MicroFerment
A29: FTR Finished Product | B29: % | C29: ='[10]FTR Finished Product'!$L$444 -> 0 | E29: FTR Finished Product | F29: % | G29: ='[10]FTR Finished Product'!$M$444 -> 0
A30: Colour | B30: % | C30: ='[10]FTR Finished Product'!$J$444 -> 0 | E30: Colour | F30: %
A31: ISO-H | B31: % | C31: ='[10]FTR Finished Product'!$F$444 -> 0 | E31: ISO-H | F31: % | G31: ='August ''24'!C31 -> 0
A32: Original Gravity | B32: % | C32: ='[10]FTR Finished Product'!$D$444 -> 0 | E32: Original Gravity | F32: % | G32: ='August ''24'!C32 -> 0
A33: TOP | B33: % | C33: ='[10]FTR Finished Product'!$H$444 -> 0 | E33: TOP | F33: % | G33: ='August ''24'!C33 -> 0
C35: =(C2+C7+C14+C20+C25+C29)/6 -> 0.6972776 | G35: =(G2+G7+G14+G20+G25+G29)/6 -> 0.55244427
B36: YTD | C36: =AVERAGE('January ''25'!C37,'February ''24'!C38,'March ''24'!C36,'April ''24'!C36,#REF!,'June ''24 '!C36,'July ''24'!C35,C35) -> #REF! | E36: With-out Colour | F36: YTD | G36: =AVERAGE('January ''25'!G37,'February ''24'!G38,'March ''24'!G36,'April ''24'!G36,#REF!,'June ''24 '!G36,'July ''24'!G35,'August ''24'!G35) -> #REF!

Sheet September '24 
A1: KPI- Sept | C1: Actual | E1: KPI- Without colour | G1: Actual
A2: FTR Brewing | B2: % | C2: ='[10]FTR Brewhouse'!$I$1510 -> 0.3828125 | E2: FTR Brewing | F2: % | G2: ='September ''24 '!C2 -> 0.3828125
A3: Cast Gravity | B3: % | C3: ='[10]FTR Brewhouse'!$C$1510 -> 0.953125 | E3: Cast Gravity | F3: % | G3: ='September ''24 '!C3 -> 0.953125
A4: Brewing Time | B4: % | C4: ='[10]FTR Brewhouse'!$E$1510 -> 0.4140625 | E4: Brewing Time | F4: % | G4: ='September ''24 '!C4 -> 0.4140625
A5: Aeration Level | B5: % | C5: ='[10]FTR Brewhouse'!$G$1510 -> 1 | E5: Aeration Level | F5: % | G5: ='September ''24 '!C5 -> 1
A7: FTR Fermentation | B7: % | C7: ='[10]FTR Fermentation'!$P$385 -> 0.63636364 | E7: FTR Fermentation | F7: % | G7: ='September ''24 '!C7 -> 0.63636364
A8: FVSV Fill Duration | B8: % | C8: ='[10]FTR Fermentation'!$D$385 -> 0.72727273 | E8: FVSV Fill Duration | F8: % | G8: ='September ''24 '!C8 -> 0.72727273
A9: Yeast Dosage | B9: % | C9: ='[10]FTR Fermentation'!$G$385 -> 1 | E9: Yeast Dosage | F9: % | G9: ='September ''24 '!C9 -> 1
A10: Pitched Yeast Stain | B10: % | C10: ='[10]FTR Fermentation'!$K$385 -> 1 | E10: Pitched Yeast Stain | F10: % | G10: ='September ''24 '!C10 -> 1
A11: Yeast Storage Duration | B11: % | C11: ='[10]FTR Fermentation'!$M$385 -> 0.91304348 | E11: Yeast Storage Duration | F11: % | G11: ='September ''24 '!C11 -> 0.91304348
A12: Fermentation Speed | B12: % | C12: ='[10]FTR Fermentation'!$I$385 -> 1 | E12: Fermentation Speed | F12: % | G12: ='September ''24 '!C12 -> 1
A14: FTR BBT | B14: % | C14: ='[10]FTR BBT'!$N$690 -> 0.97101449 | E14: FTR BBT | F14: % | G14: ='[10]FTR BBT'!$O$690 -> 0.97014925
A15: Original Gravity | B15: % | C15: ='[10]FTR BBT'!$D$690 -> 0.98550725 | E15: Original Gravity | F15: % | G15: ='September ''24 '!C15 -> 0.98550725
A16: Colour | B16: % | C16: ='[10]FTR BBT'!$J$690 -> 1 | E16: Colour | F16: %
A17: CO2 | B17: % | C17: ='[10]FTR BBT'!$H$690 -> 1 | E17: CO2 | F17: % | G17: ='[10]FTR BBT'!$H$690 -> 1
A18: DO | B18: % | C18: ='[10]FTR BBT'!$F$690 -> 1 | E18: DO | F18: % | G18: ='[10]FTR BBT'!$F$690 -> 1
A20: FTR Packaging | B20: % | C20: ='[10]FTR Packaging'!$L$479 -> 0.94736842 | E20: FTR Packaging | F20: % | G20: ='September ''24 '!C20 -> 0.94736842
A21: PU | B21: % | C21: ='[10]FTR Packaging'!$F$479 -> 0.97297297 | E21: PU | F21: % | G21: ='September ''24 '!C21 -> 0.97297297
A22: Fill Volume | B22: % | C22: ='[10]FTR Packaging'!$D$479 -> 1 | E22: Fill Volume | F22: % | G22: ='September ''24 '!C22 -> 1
A23: Packaging Index | B23: % | C23: ='[10]FTR Packaging'!$J$479 -> 0.97368421 | E23: Packaging Index | F23: % | G23: ='September ''24 '!C23 -> 0.97368421
A25: FTR Micro | B25: % | C25: 0.80898 | E25: FTR Micro | F25: % | G25: ='September ''24 '!C25 -> 0.80898
A26: MicroPack - MicroTunnel | B26: % | C26: 1 | E26: MicroPack - MicroTunnel | F26: % | G26: ='September ''24 '!C26 -> 1
A27: MicroBeer - MicroFerment | B27: % | C27: 0.8089 | E27: MicroBeer - MicroFerment | F27: % | G27: ='September ''24 '!C27 -> 0.8089
A29: FTR Finished Product | B29: % | C29: ='[10]FTR Finished Product'!$L$490 -> 1 | E29: FTR Finished Product | F29: % | G29: ='[10]FTR Finished Product'!$M$488 -> 1
A30: Colour | B30: % | C30: ='[10]FTR Finished Product'!$J$490 -> 126.9 | E30: Colour | F30: % | G30: ='September ''24 '!C30 -> 126.9
A31: ISO-H | B31: % | C31: ='[10]FTR Finished Product'!$F$490 -> 14.3 | E31: ISO-H | F31: % | G31: ='September ''24 '!C31 -> 14.3
A32: Original Gravity | B32: % | C32: ='[10]FTR Finished Product'!$D$490 -> 16.4 | E32: Original Gravity | F32: % | G32: ='September ''24 '!C32 -> 16.4
A33: TOP | B33: % | C33: ='[10]FTR Finished Product'!$H$490 -> 0.25 | E33: TOP | F33: % | G33: ='September ''24 '!C33 -> 0.25
C35: =(C2+C7+C14+C20+C25+C29)/6 -> 0.79108984 | G35: =(G2+G7+G14+G20+G25+G29)/6 -> 0.79094564
B36: YTD | C36: =AVERAGE('January ''25'!C37,'February ''24'!C38,'March ''24'!C36,'April ''24'!C36,#REF!,'June ''24 '!C36,'July ''24'!C35,'August ''24'!C35,C35) -> #REF! | E36: With-out Colour | F36: YTD | G36: =AVERAGE('January ''25'!G37,'February ''24'!G38,'March ''24'!G36,'April ''24'!G36,#REF!,'June ''24 '!G36,'July ''24'!G35,'August ''24'!G35,'September ''24 '!G35) -> #REF!

Sheet October '24 
A1: KPI | C1: Actual | E1: KPI- Without colour | G1: Actual
A2: FTR Brewing | B2: % | C2: ='[10]FTR Brewhouse'!$I$1649 -> 0.42063492 | E2: FTR Brewing | F2: % | G2: ='[10]FTR Brewhouse'!#REF! -> #REF!
A3: Cast Gravity | B3: % | C3: ='[10]FTR Brewhouse'!$C$1649 -> 0.93650794 | E3: Cast Gravity | F3: % | G3: ='[10]FTR Brewhouse'!#REF! -> #REF!
A4: Brewing Time | B4: % | C4: ='[10]FTR Brewhouse'!$E$1649 -> 0.45238095 | E4: Brewing Time | F4: % | G4: ='[10]FTR Brewhouse'!#REF! -> #REF!
A5: Aeration Level | B5: % | C5: ='[10]FTR Brewhouse'!$G$1649 -> 0.99047619 | E5: Aeration Level | F5: % | G5: ='[10]FTR Brewhouse'!#REF! -> #REF!
A7: FTR Fermentation | B7: % | C7: ='[10]FTR Fermentation'!$P$410 -> 0.55555556 | E7: FTR Fermentation | F7: % | G7: ='[10]FTR Fermentation'!#REF! -> #REF!
A8: FVSV Fill Duration | B8: % | C8: ='[10]FTR Fermentation'!$D$410 -> 0.7 | E8: FVSV Fill Duration | F8: % | G8: ='[10]FTR Fermentation'!#REF! -> #REF!
A9: Yeast Dosage | B9: % | C9: ='[10]FTR Fermentation'!$G$410 -> 1 | E9: Yeast Dosage | F9: % | G9: ='[10]FTR Fermentation'!#REF! -> #REF!
A10: Pitched Yeast Stain | B10: % | C10: ='[10]FTR Fermentation'!$K$410 -> 1 | E10: Pitched Yeast Stain | F10: % | G10: ='[10]FTR Fermentation'!#REF! -> #REF!
A11: Yeast Storage Duration | B11: % | C11: ='[10]FTR Fermentation'!$M$410 -> 0.77777778 | E11: Yeast Storage Duration | F11: % | G11: ='[10]FTR Fermentation'!#REF! -> #REF!
A12: Fermentation Speed | B12: % | C12: ='[10]FTR Fermentation'!$I$410 -> 1 | E12: Fermentation Speed | F12: % | G12: ='[10]FTR Fermentation'!#REF! -> #REF!
A14: FTR BBT | B14: % | C14: ='[10]FTR BBT'!$N$777 -> 0.93333333 | E14: FTR BBT | F14: % | G14: ='[10]FTR BBT'!$N$777 -> 0.93333333
A15: Original Gravity | B15: % | C15: ='[10]FTR BBT'!$D$777 -> 0.97619048 | E15: Original Gravity | F15: % | G15: ='[10]FTR BBT'!$D$777 -> 0.97619048
A16: Colour | B16: % | C16: ='[10]FTR BBT'!$J$777 -> 0.96428571 | E16: Colour | F16: %
A17: CO2 | B17: % | C17: ='[10]FTR BBT'!$H$777 -> 0.98734177 | E17: CO2 | F17: % | G17: ='[10]FTR BBT'!$H$777 -> 0.98734177
A18: DO | B18: % | C18: ='[10]FTR BBT'!$F$777 -> 1 | E18: DO | F18: % | G18: ='[10]FTR BBT'!$F$777 -> 1
A20: FTR Packaging | B20: % | C20: ='[10]FTR Packaging'!$L$541 -> 0.92982456 | E20: FTR Packaging | F20: % | G20: ='[10]FTR Packaging'!$L$541 -> 0.92982456
A21: PU | B21: % | C21: ='[10]FTR Packaging'!$F$541 -> 0.91836735 | E21: PU | F21: % | G21: ='[10]FTR Packaging'!$F$541 -> 0.91836735
A22: Fill Volume | B22: % | C22: ='[10]FTR Packaging'!$D$541 -> 1 | E22: Fill Volume | F22: % | G22: ='[10]FTR Packaging'!$D$541 -> 1
A23: Packaging Index | B23: % | C23: ='[10]FTR Packaging'!$J$541 -> 1 | E23: Packaging Index | F23: % | G23: ='[10]FTR Packaging'!$J$541 -> 1
A25: FTR Micro | B25: % | C25: 0.869 | E25: FTR Micro | F25: % | G25: ='October ''24 '!C25 -> 0.869
A26: MicroPack - MicroTunnel | B26: % | C26: 1 | E26: MicroPack - MicroTunnel | F26: % | G26: ='October ''24 '!C26 -> 1
A27: MicroBeer - MicroFerment | B27: % | C27: 0.869 | E27: MicroBeer - MicroFerment | F27: % | G27: ='October ''24 '!C27 -> 0.869
A29: FTR Finished Product | B29: % | C29: ='[10]FTR Finished Product'!$L$552 -> 1 | E29: FTR Finished Product | F29: % | G29: ='[10]FTR Finished Product'!$L$552 -> 1
A30: Colour | B30: % | C30: ='[10]FTR Finished Product'!$J$552 -> 6.35 | E30: Colour | F30: %
A31: ISO-H | B31: % | C31: ='[10]FTR Finished Product'!$F$552 -> 13 | E31: ISO-H | F31: % | G31: ='[10]FTR Finished Product'!$F$552 -> 13
A32: Original Gravity | B32: % | C32: ='[10]FTR Finished Product'!$D$552 -> 1.95 | E32: Original Gravity | F32: % | G32: ='[10]FTR Finished Product'!$D$552 -> 1.95
A33: TOP | B33: % | C33: ='[10]FTR Finished Product'!$H$552 -> 0.02 | E33: TOP | F33: % | G33: ='[10]FTR Finished Product'!$H$552 -> 0.02
C35: =(C2+C7+C14+C20+C25+C29)/6 -> 0.78472473 | G35: =(G2+G7+G14+G20+G25+G29)/6 -> #REF!
B36: YTD | C36: =AVERAGE('January ''25'!C37,'February ''24'!C38,'March ''24'!C36,'April ''24'!C36,#REF!,'June ''24 '!C36,'July ''24'!C35,'August ''24'!C35,'September ''24 '!C35,'October ''24 '!C35) -> #REF! | E36: With-out Colour | F36: YTD | G36: =AVERAGE('January ''25'!G37,'February ''24'!G38,'March ''24'!G36,'April ''24'!G36,#REF!,'June ''24 '!G36,'July ''24'!G35,'August ''24'!G35,'September ''24 '!G35,'October ''24 '!G35) -> #REF!

Sheet November '24 
A1: KPI | C1: Actual | E1: KPI- Without colour | G1: Actual
A2: FTR Brewing | B2: % | C2: ='[10]FTR Brewhouse'!$I$1818 -> 0.48780488 | E2: FTR Brewing | F2: % | G2: ='November ''24 '!C2 -> 0.48780488
A3: Cast Gravity | B3: % | C3: ='[10]FTR Brewhouse'!$C$1818 -> 0.9695122 | E3: Cast Gravity | F3: % | G3: ='November ''24 '!C3 -> 0.9695122
A4: Brewing Time | B4: % | C4: ='[10]FTR Brewhouse'!$E$1818 -> 0.51829268 | E4: Brewing Time | F4: % | G4: ='November ''24 '!C4 -> 0.51829268
A5: Aeration Level | B5: % | C5: ='[10]FTR Brewhouse'!$G$1818 -> 1 | E5: Aeration Level | F5: % | G5: ='November ''24 '!C5 -> 1
A7: FTR Fermentation | B7: % | C7: ='[10]FTR Fermentation'!$P$446 -> 0.20833333 | E7: FTR Fermentation | F7: % | G7: ='November ''24 '!C7 -> 0.20833333
A8: FVSV Fill Duration | B8: % | C8: ='[10]FTR Fermentation'!$D$446 -> 0.61538462 | E8: FVSV Fill Duration | F8: % | G8: ='November ''24 '!C8 -> 0.61538462
A9: Yeast Dosage | B9: % | C9: ='[10]FTR Fermentation'!$G$446 -> 0.92 | E9: Yeast Dosage | F9: % | G9: ='November ''24 '!C9 -> 0.92
A10: Pitched Yeast Stain | B10: % | C10: ='[10]FTR Fermentation'!$K$446 -> 1 | E10: Pitched Yeast Stain | F10: % | G10: ='November ''24 '!C10 -> 1
A11: Yeast Storage Duration | B11: % | C11: ='[10]FTR Fermentation'!$M$446 -> 0.66666667 | E11: Yeast Storage Duration | F11: % | G11: ='November ''24 '!C11 -> 0.66666667
A12: Fermentation Speed | B12: % | C12: ='[10]FTR Fermentation'!$I$446 -> 0.5 | E12: Fermentation Speed | F12: % | G12: ='November ''24 '!C12 -> 0.5
A14: FTR BBT | B14: % | C14: ='[10]FTR BBT'!$N$855 -> 0.91176471 | E14: FTR BBT | F14: % | G14: ='[10]FTR BBT'!$O$855 -> 0.98529412
A15: Original Gravity | B15: % | C15: ='[10]FTR BBT'!$D$855 -> 1 | E15: Original Gravity | F15: % | G15: ='November ''24 '!C15 -> 1
A16: Colour | B16: % | C16: ='[10]FTR BBT'!$J$855 -> 0.92857143 | E16: Colour | F16: %
A17: CO2 | B17: % | C17: ='[10]FTR BBT'!$H$855 -> 1 | E17: CO2 | F17: % | G17: ='November ''24 '!C17 -> 1
A18: DO | B18: % | C18: ='[10]FTR BBT'!$F$855 -> 1 | E18: DO | F18: % | G18: ='November ''24 '!C18 -> 1
A20: FTR Packaging | B20: % | C20: ='[10]FTR Packaging'!$L$596 -> 0.91666667 | E20: FTR Packaging | F20: % | G20: ='November ''24 '!C20 -> 0.91666667
A21: PU | B21: % | C21: ='[10]FTR Packaging'!$F$596 -> 0.91836735 | E21: PU | F21: % | G21: ='November ''24 '!C21 -> 0.91836735
A22: Fill Volume | B22: % | C22: ='[10]FTR Packaging'!$D$596 -> 1 | E22: Fill Volume | F22: % | G22: ='November ''24 '!C22 -> 1
A23: Packaging Index | B23: % | C23: ='[10]FTR Packaging'!$J$596 -> 1 | E23: Packaging Index | F23: % | G23: ='November ''24 '!C23 -> 1
A25: FTR Micro | B25: % | C25: 0.852 | E25: FTR Micro | F25: % | G25: ='November ''24 '!C25 -> 0.852
A26: MicroPack - MicroTunnel | B26: % | C26: 1 | E26: MicroPack - MicroTunnel | F26: % | G26: ='November ''24 '!C26 -> 1
A27: MicroBeer - MicroFerment | B27: % | C27: 0.852 | E27: MicroBeer - MicroFerment | F27: % | G27: ='November ''24 '!C27 -> 0.852
A29: FTR Finished Product | B29: % | C29: ='[10]FTR Finished Product'!$L$611 -> 0 | E29: FTR Finished Product | F29: % | G29: ='[10]FTR Finished Product'!$M$611 -> 0
A30: Colour | B30: % | C30: ='[10]FTR Finished Product'!$J$611 -> 0 | E30: Colour | F30: % | G30: ='November ''24 '!C30 -> 0
A31: ISO-H | B31: % | C31: ='[10]FTR Finished Product'!$F$611 -> 0 | E31: ISO-H | F31: % | G31: ='November ''24 '!C31 -> 0
A32: Original Gravity | B32: % | C32: ='[10]FTR Finished Product'!$D$611 -> 0 | E32: Original Gravity | F32: % | G32: ='November ''24 '!C32 -> 0
A33: TOP | B33: % | C33: ='[10]FTR Finished Product'!$H$611 -> 0 | E33: TOP | F33: % | G33: ='November ''24 '!C33 -> 0
C35: =(C2+C7+C14+C20+C25+C29)/6 -> 0.5627616 | G35: =(G2+G7+G14+G20+G25+G29)/6 -> 0.5750165
B36: YTD | C36: =AVERAGE('January ''25'!C37,'February ''24'!C38,'March ''24'!C36,'April ''24'!C36,#REF!,'June ''24 '!C36,'July ''24'!C35,'August ''24'!C35,'September ''24 '!C35,'October ''24 '!C35,C35) -> #REF! | E36: With-out Colour | F36: YTD | G36: =AVERAGE('January ''25'!G37,'February ''24'!G38,'March ''24'!G36,'April ''24'!G36,#REF!,'June ''24 '!G36,'July ''24'!G35,'August ''24'!G35,'September ''24 '!G35,'October ''24 '!G35,'November ''24 '!G35) -> #REF!

Sheet December '24
A1: KPI | C1: Actual | E1: KPI- Without colour | G1: Actual
A2: FTR Brewing | B2: % | C2: ='[10]FTR Brewhouse'!$I$1993 -> 0 | E2: FTR Brewing | F2: % | G2: ='[10]FTR Brewhouse'!$I$1986 -> 0
A3: Cast Gravity | B3: % | C3: ='[10]FTR Brewhouse'!$C$1993 -> 0 | E3: Cast Gravity | F3: % | G3: ='[10]FTR Brewhouse'!$C$1986 -> 0
A4: Brewing Time | B4: % | C4: ='[10]FTR Brewhouse'!$E$1993 -> 0 | E4: Brewing Time | F4: % | G4: ='[10]FTR Brewhouse'!$E$1986 -> 0
A5: Aeration Level | B5: % | C5: ='[10]FTR Brewhouse'!$G$1993 -> 0 | E5: Aeration Level | F5: % | G5: ='[10]FTR Brewhouse'!$G$1986 -> 0
A7: FTR Fermentation | B7: % | C7: ='[10]FTR Fermentation'!$P$482 -> 0.23076923 | E7: FTR Fermentation | F7: % | G7: #N/A
A8: FVSV Fill Duration | B8: % | C8: ='[10]FTR Fermentation'!$D$482 -> 0.58333333 | E8: FVSV Fill Duration | F8: % | G8: #DIV/0!
A9: Yeast Dosage | B9: % | C9: ='[10]FTR Fermentation'!$G$482 -> 1 | E9: Yeast Dosage | F9: % | G9: #DIV/0!
A10: Pitched Yeast Stain | B10: % | C10: ='[10]FTR Fermentation'!$K$482 -> 1 | E10: Pitched Yeast Stain | F10: % | G10: #DIV/0!
A11: Yeast Storage Duration | B11: % | C11: ='[10]FTR Fermentation'!$M$482 -> 0.42307692 | E11: Yeast Storage Duration | F11: % | G11: #DIV/0!
A12: Fermentation Speed | B12: % | C12: ='[10]FTR Fermentation'!$I$482 -> 0.73076923 | E12: Fermentation Speed | F12: % | G12: #DIV/0!
A14: FTR BBT | B14: % | C14: ='[10]FTR BBT'!$N$973 -> 0 | E14: FTR BBT | F14: % | G14: 1
A15: Original Gravity | B15: % | C15: ='[10]FTR BBT'!$D$973 -> 0 | E15: Original Gravity | F15: % | G15: 1
A16: Colour | B16: % | C16: ='[10]FTR BBT'!$J$973 -> 0 | E16: Colour | F16: %
A17: CO2 | B17: % | C17: ='[10]FTR BBT'!$H$973 -> 0 | E17: CO2 | F17: % | G17: 1
A18: DO | B18: % | C18: ='[10]FTR BBT'!$F$973 -> 0 | E18: DO | F18: % | G18: 1
A20: FTR Packaging | B20: % | C20: ='[10]FTR Packaging'!$L$677 -> 0.93939394 | E20: FTR Packaging | F20: % | G20: ='[10]FTR Packaging'!$L$677 -> 0.93939394
A21: PU | B21: % | C21: ='[10]FTR Packaging'!$F$677 -> 0.96923077 | E21: PU | F21: % | G21: ='[10]FTR Packaging'!$F$677 -> 0.96923077
A22: Fill Volume | B22: % | C22: ='[10]FTR Packaging'!$D$677 -> 1 | E22: Fill Volume | F22: % | G22: ='[10]FTR Packaging'!$D$677 -> 1
A23: Packaging Index | B23: % | C23: ='[10]FTR Packaging'!$J$677 -> 1 | E23: Packaging Index | F23: % | G23: ='[10]FTR Packaging'!$J$677 -> 1
A25: FTR Micro | B25: % | E25: FTR Micro | F25: %
A26: MicroPack - MicroTunnel | B26: % | E26: MicroPack - MicroTunnel | F26: %
A27: MicroBeer - MicroFerment | B27: % | E27: MicroBeer - MicroFerment | F27: %
A29: FTR Finished Product | B29: % | C29: ='[10]FTR Finished Product'!$L$693 -> 0 | E29: FTR Finished Product | F29: % | G29: ='[10]FTR Finished Product'!$M$693 -> 0
A30: Colour | B30: % | C30: ='[10]FTR Finished Product'!$J$693 -> 0 | E30: Colour | F30: % | G30: ='[10]FTR Finished Product'!$J$693 -> 0
A31: ISO-H | B31: % | C31: ='[10]FTR Finished Product'!$F$693 -> 0 | E31: ISO-H | F31: % | G31: ='[10]FTR Finished Product'!$F$693 -> 0
A32: Original Gravity | B32: % | C32: ='[10]FTR Finished Product'!$D$693 -> 0 | E32: Original Gravity | F32: % | G32: ='[10]FTR Finished Product'!$D$693 -> 0
A33: TOP | B33: % | C33: ='[10]FTR Finished Product'!$H$693 -> 0 | E33: TOP | F33: % | G33: ='[10]FTR Finished Product'!$H$693 -> 0
C35: =(C2+C7+C14+C20+C25+C29)/5 -> 0.23403263 | G35: =(G2+G7+G14+G20+G25+G29)/6 -> #N/A
B36: YTD | C36: =AVERAGE('January ''25'!C37,'February ''24'!C38,'March ''24'!C36,'April ''24'!C36,#REF!,'June ''24 '!C36,'July ''24'!C35,'August ''24'!C35,'September ''24 '!C35,'October ''24 '!C35,'November ''24 '!C35,C35) -> #REF! | E36: With-out Colour | F36: YTD | G36: =AVERAGE('January ''25'!G37,'February ''24'!G38,'March ''24'!G36,'April ''24'!G36,#REF!,'June ''24 '!G36,'July ''24'!G35,'August ''24'!G35,'September ''24 '!G35,'October ''24 '!G35,'November ''24 '!G35,'December ''24'!G35) -> #REF!

Sheet May '20
A1: KPI | C1: Actual
A2: FTR Brewing | B2: % | C2: ='[12]FTR Brewhouse'!$I$846 -> 0.64788732
A3: Cast Gravity | B3: % | C3: ='[12]FTR Brewhouse'!$C$846 -> 0.7260274
A4: Brewing Time | B4: % | C4: ='[12]FTR Brewhouse'!$E$846 -> 0.91780822
A5: Aeration Level | B5: %
A7: FTR Fermentation | B7: % | C7: ='[12]FTR Fermentation'!$P$233 -> 0.5
A8: FVSV Fill Duration | B8: % | C8: ='[12]FTR Fermentation'!$D$233 -> 0.70588235
A9: Yeast Dosage | B9: % | C9: ='[12]FTR Fermentation'!$G$233 -> 1
A10: Pitched Yeast Stain | B10: % | C10: ='[12]FTR Fermentation'!$K$233 -> 0.75
A11: Yeast Storage Duration | B11: % | C11: ='[12]FTR Fermentation'!$M$233 -> 0.9375
A12: Fermentation Speed | B12: % | C12: ='[12]FTR Fermentation'!$I$233 -> 0.875
A14: FTR BBT | B14: % | C14: ='[12]FTR BBT'!$N$493 -> 0.40816327
A15: Original Gravity | B15: % | C15: ='[12]FTR BBT'!$D$493 -> 0.97959184
A16: Colour | B16: % | C16: ='[12]FTR BBT'!$J$493 -> 0.40816327
A17: CO2 | B17: % | C17: ='[12]FTR BBT'!$H$493 -> 1
A18: DO | B18: % | C18: ='[12]FTR BBT'!$F$493 -> #DIV/0!
A20: FTR Packaging | B20: % | C20: ='[12]FTR Packaging'!$L$458 -> 0.66666667
A21: PU | B21: % | C21: ='[12]FTR Packaging'!$F$458 -> 0.65
A22: Fill Volume | B22: % | C22: ='[12]FTR Packaging'!$D$458 -> 1
A25: FTR Micro | B25: % | C25: 0.941
A26: MicroPack - MicroTunnel | B26: % | C26: 1
A27: MicroBeer - MicroFerment | B27: % | C27: 0.941
A29: FTR Finished Product | B29: % | C29: ='[12]FTR Finished Product'!$N$378 -> 0.36585366
A30: Colour | B30: % | C30: ='[12]FTR Finished Product'!$K$378 -> 0.3902439
A31: ISO-H | B31: % | C31: ='[12]FTR Finished Product'!$F$378 -> 0.82857143
A32: Original Gravity | B32: % | C32: ='[12]FTR Finished Product'!$D$378 -> 1
A33: TOP | B33: %
C35: =AVERAGE(C2,C7,C14,C20,C25,C29) -> 0.58826182 | E35: YTD | F35: =AVERAGE('January ''25'!C37,'February ''24'!#REF!,'March ''24'!C36,'April ''24'!C36,C35) -> #REF!

Sheet June'20
A1: KPI | C1: Actual
A2: FTR Brewing | B2: % | C2: ='[12]FTR Brewhouse'!$I$1015 -> 0.71969697
A3: Cast Gravity | B3: % | C3: ='[12]FTR Brewhouse'!$C$1015 -> 0.87857143
A4: Brewing Time | B4: % | C4: ='[12]FTR Brewhouse'!$E$1015 -> 0.90714286
A5: Aeration Level | B5: %
A7: FTR Fermentation | B7: % | C7: ='[12]FTR Fermentation'!$P$270 -> 0.77272727
A8: FVSV Fill Duration | B8: % | C8: ='[12]FTR Fermentation'!$D$270 -> 0.95454545
A9: Yeast Dosage | B9: % | C9: ='[12]FTR Fermentation'!$G$270 -> 1
A10: Pitched Yeast Stain | B10: % | C10: ='[12]FTR Fermentation'!$K$270 -> 1
A11: Yeast Storage Duration | B11: % | C11: ='[12]FTR Fermentation'!$M$270 -> 0.90909091
A12: Fermentation Speed | B12: % | C12: ='[12]FTR Fermentation'!$I$270 -> 0.86363636
A14: FTR BBT | B14: % | C14: ='[12]FTR BBT'!$N$590 -> 0.64814815
A15: Original Gravity | B15: % | C15: ='[12]FTR BBT'!$D$590 -> 0.98181818
A16: Colour | B16: % | C16: ='[12]FTR BBT'!$J$590 -> 0.66666667
A17: CO2 | B17: % | C17: ='[12]FTR BBT'!$H$590 -> 1
A18: DO | B18: % | C18: ='[12]FTR BBT'!$F$590 -> #DIV/0!
A20: FTR Packaging | B20: % | C20: ='[12]FTR Packaging'!$L$553 -> 0.61904762
A21: PU | B21: % | C21: ='[12]FTR Packaging'!$F$553 -> 0.61904762
A22: Fill Volume | B22: % | C22: ='[12]FTR Packaging'!$D$553 -> 1
A25: FTR Micro | B25: % | C25: 0.855
A26: MicroPack - MicroTunnel | B26: % | C26: 1
A27: MicroBeer - MicroFerment | B27: % | C27: 0.855
A29: FTR Finished Product | B29: % | C29: ='[12]FTR Finished Product'!$N$451 -> 0.63414634
A30: Colour | B30: % | C30: ='[12]FTR Finished Product'!$K$451 -> 0.725
A31: ISO-H | B31: % | C31: ='[12]FTR Finished Product'!$F$451 -> 1
A32: Original Gravity | B32: % | C32: ='[12]FTR Finished Product'!$D$451 -> 0.9
A33: TOP | B33: %
C35: =AVERAGE(C2,C7,C14,C20,C25,C29) -> 0.70812773 | E35: YTD | F35: =AVERAGE('January ''25'!C37,'February ''24'!#REF!,'March ''24'!C36,'April ''24'!C36,'May ''20'!C35,C35) -> #REF!

Sheet September '20
A1: KPI | C1: Target
A2: FTR Brewing | B2: % | C2: ='[12]FTR Brewhouse'!$I$1569 -> 0.72897196
A3: Cast Gravity | B3: % | C3: ='[12]FTR Brewhouse'!$C$1569 -> 0.85046729
A4: Brewing Time | B4: % | C4: ='[12]FTR Brewhouse'!$E$1569 -> 0.85981308
A5: Aeration Level | B5: %
A7: FTR Fermentation | B7: % | C7: ='[12]FTR Fermentation'!$P$385 -> 0.16666667
A8: FVSV Fill Duration | B8: % | C8: ='[12]FTR Fermentation'!$D$385 -> 0.94444444
A9: Yeast Dosage | B9: % | C9: ='[12]FTR Fermentation'!$G$385 -> 0.94444444
A10: Pitched Yeast Stain | B10: % | C10: ='[12]FTR Fermentation'!$K$385 -> 0.11111111
A11: Yeast Storage Duration | B11: % | C11: ='[12]FTR Fermentation'!$M$308 -> 0.96969697
A12: Fermentation Speed | B12: % | C12: ='[12]FTR Fermentation'!$I$385 -> 0.83333333
A14: FTR BBT | B14: % | C14: ='[12]FTR BBT'!$N$911 -> 0.45205479
A15: Original Gravity | B15: % | C15: ='[12]FTR BBT'!$D$911 -> 0.97260274
A16: Colour | B16: % | C16: ='[12]FTR BBT'!$J$911 -> 0.47945205
A17: CO2 | B17: % | C17: ='[12]FTR BBT'!$H$804 -> 1
A18: DO | B18: % | C18: ='[12]FTR BBT'!$F$804 -> 1
A20: FTR Packaging | B20: % | C20: ='[12]FTR Packaging'!$L$835 -> 0.69642857
A21: PU | B21: % | C21: ='[12]FTR Packaging'!$F$835 -> 0.73214286
A22: Fill Volume | B22: % | C22: ='[12]FTR Packaging'!$D$835 -> 0.96296296
A25: FTR Micro | B25: % | C25: 0.716
A26: MicroPack - MicroTunnel | B26: % | C26: 1
A27: MicroBeer - MicroFerment | B27: % | C27: 0.716
A29: FTR Finished Product | B29: % | C29: ='[12]FTR Finished Product'!$N$665 -> 0.30357143
A30: Colour | B30: % | C30: ='[12]FTR Finished Product'!$K$665 -> 0.43636364
A31: ISO-H | B31: % | C31: ='[12]FTR Finished Product'!$F$665 -> 0.90243902
A32: Original Gravity | B32: % | C32: ='[12]FTR Finished Product'!$D$665 -> 0.94545455
A33: TOP | B33: %
C35: =AVERAGE(C2,C7,C14,C20,C25,C29) -> 0.51061557 | E35: YTD | F35: =AVERAGE('January ''25'!C37,'February ''24'!#REF!,'March ''24'!C36,'April ''24'!C36,'May ''20'!C35,'June''20'!C35,#REF!,#REF!,'September ''20'!C35) -> #REF!

Sheet November '18
A1: KPI | C1: Target
A2: FTR Brewing | B2: % | C2: ='[13]FTR Brewhouse'!$I$3240 -> 0.43708609
A3: Cast Gravity | B3: % | C3: ='[13]FTR Brewhouse'!$C$3240 -> 0.8013245
A4: Process Time | B4: % | C4: ='[13]FTR Brewhouse'!$E$3240 -> 0.50993377
A6: FTR Fermentation | B6: % | C6: ='[13]FTR Fermentation'!$P$811 -> 0.64285714
A7: FVSV Fill Duration | B7: % | C7: ='[13]FTR Fermentation'!$D$811 -> 0.78571429
A8: Yeast Dosage | B8: % | C8: ='[13]FTR Fermentation'!$G$811 -> 1
A9: Pitched Yeast Stain | B9: % | C9: ='[13]FTR Fermentation'!$K$811 -> 1
A10: Yeast Storage Duration | B10: % | C10: ='[13]FTR Fermentation'!$M$811 -> 0.92857143
A11: Harvest Moment | B11: % | C11: -
A12: Fermentation Speed | B12: % | C12: ='[13]FTR Fermentation'!$I$811 -> 0.85714286
A14: FTR BBT | B14: % | C14: ='[13]FTR BBT'!$M$1806 -> 0.5
A15: Original Gravity | B15: % | C15: ='[13]FTR BBT'!$D$1806 -> 0.89393939
A16: Colour | B16: % | C16: ='[13]FTR BBT'!$K$1806 -> 0.59090909
A17: Haze - H90 | B17: % | C17: -
A18: Haze - H25 | B18: % | C18: -
A19: CO2 | B19: % | C19: ='[13]FTR BBT'!$H$1806 -> 1
A20: DO | B20: % | C20: ='[13]FTR BBT'!$F$1806 -> #DIV/0!
A21: Turbidity | B21: % | C21: -
A23: FTR Packaging | B23: % | C23: ='[13]FTR Packaging'!$L$1344 -> 0.87719298
A24: PU | B24: % | C24: ='[13]FTR Packaging'!$F$1344 -> 0.90384615
A25: Fill Volume | B25: % | C25: ='[13]FTR Packaging'!$D$1344 -> 0.96491228
A26: TOP | B26: % | C26: ='[13]FTR Packaging'!$H$1344 -> #DIV/0!
A29: FTR Micro | B29: % | C29: 0.943
A30: MicroPack - MicroTunnel | B30: % | C30: 1
A31: MicroBeer - MicroFerment | B31: % | C31: 0.943
A33: FTR Finished Product | B33: % | C33: ='[13]FTR Finished Product'!$N$1248 -> 0.43478261
A34: Colour | C34: ='[13]FTR Finished Product'!$K$1248 -> 0.48717949
A35: ISO-H | C35: ='[13]FTR Finished Product'!$F$1248 -> 0.64864865
A36: Original Gravity | C36: ='[13]FTR Finished Product'!$D$1248 -> 0.75675676
A37: Turbidity | C37: -
C39: =(C2+C6+C14+C23+C29+C33)/6 -> 0.63915314 | E39: YTD | F39: =AVERAGE('January ''25'!C37,'February ''24'!#REF!,'March ''24'!C36,'April ''24'!C36,'May ''20'!C35,'June''20'!C35,#REF!,#REF!,'September ''20'!C35,#REF!,C39) -> #REF!

Sheet December '18
A1: KPI | C1: Target
A2: FTR Brewing | B2: % | C2: ='[13]FTR Brewhouse'!$I$3401 -> 0.82352941
A3: Cast Gravity | B3: % | C3: ='[13]FTR Brewhouse'!$C$3401 -> 0.91176471
A4: Process Time | B4: % | C4: ='[13]FTR Brewhouse'!$E$3401 -> 0.88970588
A6: FTR Fermentation | B6: % | C6: ='[13]FTR Fermentation'!$P$852 -> 0.88461538
A7: FVSV Fill Duration | B7: % | C7: ='[13]FTR Fermentation'!$D$852 -> 0.96153846
A8: Yeast Dosage | B8: % | C8: ='[13]FTR Fermentation'!$G$852 -> 0.96153846
A9: Pitched Yeast Stain | B9: % | C9: ='[13]FTR Fermentation'!$K$852 -> 1
A10: Yeast Storage Duration | B10: % | C10: ='[13]FTR Fermentation'!$M$852 -> 0.96153846
A11: Harvest Moment | B11: %
A12: Fermentation Speed | B12: % | C12: ='[13]FTR Fermentation'!$I$852 -> 1
A14: FTR BBT | B14: % | C14: ='[13]FTR BBT'!$M$1905 -> 0.88157895
A15: Original Gravity | B15: % | C15: ='[13]FTR BBT'!$D$1905 -> 0.97368421
A16: Colour | B16: % | C16: ='[13]FTR BBT'!$K$1905 -> 0.90789474
A17: Haze - H90 | B17: % | C17: -
A18: Haze - H25 | B18: % | C18: -
A19: CO2 | B19: % | C19: ='[13]FTR BBT'!$H$1905 -> 1
A20: DO | B20: % | C20: ='[13]FTR BBT'!$F$1905 -> #DIV/0!
A21: Turbidity | B21: %
A23: FTR Packaging | B23: % | C23: ='[13]FTR Packaging'!$L$1422 -> 0.85454545
A24: PU | B24: % | C24: ='[13]FTR Packaging'!$F$1422 -> 0.8490566
A25: Fill Volume | B25: % | C25: ='[13]FTR Packaging'!$D$1422 -> 1
A26: TOP | B26: % | C26: ='[13]FTR Packaging'!$H$1422 -> #DIV/0!
A29: FTR Micro | B29: % | C29: 0.943
A30: MicroPack - MicroTunnel | B30: % | C30: 100
A31: MicroBeer - MicroFerment | B31: % | C31: 94.3
A33: FTR Finished Product | B33: % | C33: ='[13]FTR Finished Product'!$N$1314 -> 0.81034483
A34: Colour | C34: ='[13]FTR Finished Product'!$K$1314 -> 0.87037037
A35: ISO-H | C35: ='[13]FTR Finished Product'!$F$1314 -> 0.98039216
A36: Original Gravity | C36: ='[13]FTR Finished Product'!$D$1314 -> 0.94444444
A37: Turbidity | C37: -
C39: =(C2+C6+C14+C23+C29+C33)/6 -> 0.866269 | E39: YTD | F39: =AVERAGE('January ''25'!C37,'February ''24'!#REF!,'March ''24'!C36,'April ''24'!C36,'May ''20'!C35,'June''20'!C35,#REF!,#REF!,'September ''20'!C35,#REF!,'November ''18'!C39,C39) -> #REF!

Sheet FTR Trend
B3: FTR | C3: Jan | D3: Feb | E3: Mar | F3: Apr | G3: May | H3: Jun | I3: Jul | J3: Aug | K3: Sep | L3: Oct | M3: Nov | N3: Dec | O3: Overall | P3: TARGET
B4: FTR Brewing | C4: ='January ''25'!$C$2 -> 0.43506494 | D4: ='February ''24'!$C$2 -> 0.41538462 | E4: ='March ''24'!C2 -> 0.36 | F4: ='April ''24'!C2 -> 0.35779817 | G4: ='May ''20'!C2 -> 0.64788732 | H4: ='June''20'!C2 -> 0.71969697 | I4: =#REF! -> #REF! | J4: =#REF! -> #REF! | O4: =AVERAGE(Table3[[#This Row],[Jan]:[Dec]]) -> #REF! | P4: 0.85
B5: FTR Fermentation | C5: ='January ''25'!$C$7 -> 0.53333333 | D5: ='February ''24'!$C$7 -> 0.5625 | E5: ='March ''24'!C7 -> 0.48571429 | F5: ='April ''24'!C7 -> 0.52631579 | G5: ='May ''20'!C7 -> 0.5 | H5: ='June''20'!C7 -> 0.77272727 | I5: =#REF! -> #REF! | J5: =#REF! -> #REF! | O5: =AVERAGE(Table3[[#This Row],[Jan]:[Dec]]) -> #REF! | P5: 0.8
B6: FTR BBT | C6: ='January ''25'!$C$14 -> 0.78125 | D6: ='February ''24'!$C$14 -> 0.95238095 | E6: ='March ''24'!C14 -> 0.94520548 | F6: ='April ''24'!C14 -> 0.95890411 | G6: ='May ''20'!C14 -> 0.40816327 | H6: ='June''20'!C14 -> 0.64814815 | I6: =#REF! -> #REF! | J6: =#REF! -> #REF! | O6: =AVERAGE(Table3[[#This Row],[Jan]:[Dec]]) -> #REF! | P6: 0.8
B7: FTR Packaging | C7: ='January ''25'!$C$21 -> 0.87804878 | D7: ='February ''24'!$C$21 -> 1 | E7: ='March ''24'!C21 -> 0.97727273 | F7: ='April ''24'!C21 -> 0.98 | G7: ='May ''20'!C20 -> 0.66666667 | H7: ='June''20'!C20 -> 0.61904762 | I7: =#REF! -> #REF! | J7: =#REF! -> #REF! | O7: =AVERAGE(Table3[[#This Row],[Jan]:[Dec]]) -> #REF! | P7: 0.7
B8: FTR Micro | C8: ='January ''25'!$C$27 -> 0.76 | D8: ='February ''24'!$C$27 -> 0.867 | G8: ='May ''20'!C25 -> 0.941 | H8: ='June''20'!C25 -> 0.855 | I8: =#REF! -> #REF! | J8: =#REF! -> #REF! | O8: =AVERAGE(Table3[[#This Row],[Jan]:[Dec]]) -> #REF! | P8: 0.7
B9: FTR Finished Product | C9: ='January ''25'!$C$31 -> 0.80487805 | D9: ='February ''24'!$C$31 -> 0.86046512 | E9: ='March ''24'!C30 -> 1 | F9: ='April ''24'!C30 -> 1 | G9: ='May ''20'!C29 -> 0.36585366 | H9: ='June''20'!C29 -> 0.63414634 | I9: =#REF! -> #REF! | J9: =#REF! -> #REF! | O9: =AVERAGE(Table3[[#This Row],[Jan]:[Dec]]) -> #REF! | P9: 0.75
B10: Overall | C10: ='January ''25'!$C$37 -> 0.69876252 | D10: ='February ''24'!#REF! -> #REF! | E10: ='March ''24'!C36 -> 0.76636542 | F10: ='April ''24'!C36 -> 0.76766968 | G10: ='May ''20'!C35 -> 0.58826182 | H10: ='June''20'!C35 -> 0.70812773 | I10: =#REF! -> #REF! | J10: =#REF! -> #REF! | O10: =AVERAGE(Table3[[#This Row],[Jan]:[Dec]]) -> #REF! | P10: 0.8

Sheet FTR Parameter Trend
B3: Parameters | C3: Jan | D3: Feb | E3: Mar | F3: Apr | G3: May | H3: Jun | I3: Jul | J3: Aug | K3: Sep | L3: Oct | M3: Nov | N3: Dec | O3: Overall | P3: TARGET
A4: Brew | B4: Cast Gravity | C4: ='January ''25'!C3 -> 0.95394737 | D4: ='February ''24'!$C$3 -> 0.92307692 | E4: ='March ''24'!C3 -> 0.86666667 | F4: ='April ''24'!C3 -> 0.92727273 | G4: ='May ''20'!C3 -> 0.7260274 | H4: ='June''20'!C3 -> 0.87857143 | I4: =#REF! -> #REF! | J4: =#REF! -> #REF! | K4: ='September ''20'!C3 -> 0.85046729 | L4: =#REF! -> #REF! | M4: ='November ''18'!C3 -> 0.8013245 | N4: ='December ''18'!C3 -> 0.91176471 | O4: =AVERAGE(Table1[[#This Row],[Jan]:[Dec]]) -> #REF! | P4: 0.949 | R4: =(Table1[[#This Row],[Overall]]-Table1[[#This Row],[TARGET]])*100 -> #REF!
