Workbook
Name Apr: [1]April!$A$1:$Q$35
Name Aug: [1]Aug!$A$1:$Q$35
Name Category: #REF!
Name Classification: #REF!
Name CO2MOR: #REF!
Name Company: #REF!
Name Date: #REF!
Name Dec: [1]Dec!$A$1:$Q$35
Name elc.beer: [2]Electricity!#REF!
Name Elec.beer: [2]Electricity!#REF!
Name elec.malt: [2]Electricity!#REF!
Name elec.oth: [2]Electricity!#REF!
Name ELECMOR: #REF!
Name Feb: [1]Feb!$A$1:$Q$35
Name FS_Area: #REF!
Name FUELMOR: #REF!
Name H20MOR: #REF!
Name IT: #REF!
Name Jan: '[1] Jan'!$A$1:$Q$35
Name July: [1]July!$A$1:$Q$35
Name June: [1]June!$A$1:$Q$35
Name Mar: [1]Mar!$A$1:$Q$35
Name May: [1]May!$A$1:$Q$35
Name MS: #REF!
Name Nov: [1]Nov!$A$1:$Q$35
Name Oct: [1]Oct!$A$1:$Q$35
Name RATIOS: #REF!
Name Reporting_body: #REF!
Name Risk: #REF!
Name Sector: #REF!
Name Sept: [1]Sept!$A$1:$Q$35
Name Status: #REF!
Name Summary: #REF!
Name TOTALMOR: #REF!

Sheet Summary 2025 CPH 
C1: Available Time | G1: Fill Mins
C2: New MTD CPH | D2: New YTD CPH | G2: Old MTD CPH | H2: Old YTD CPH | K2: New Vs Old Diff MTD | L2: New Vs Old Diff YTD
B3: Jan | C3: =January_2025!Q65 -> 329.9106 | D3: =January_2025!R65 -> 329.9106 | F3: Jan | G3: =January_2025!Q67 -> 417.25817 | H3: =January_2025!R67 -> 417.25817 | K3: =C3-G3 -> -87.347562 | L3: =D3-H3 -> -87.347562
B4: Feb | C4: =February_2025!Q63 -> 297.08261 | D4: =February_2025!R63 -> 309.49036 | F4: Feb | G4: =February_2025!Q65 -> 386.44063 | H4: =February_2025!R65 -> 398.29267 | K4: =C4-G4 -> -89.358018 | L4: =D4-H4 -> -88.802312
B5: Mar | C5: =March_2025!Q62 -> 258.18732 | D5: =March_2025!R62 -> 290.77687 | F5: Mar | G5: =March_2025!Q64 -> 341.12731 | H5: =March_2025!R64 -> 377.78806 | K5: =C5-G5 -> -82.939992 | L5: =D5-H5 -> -87.011196
B6: Apr | C6: ='April_2025 '!Q54 -> 281.7882 | D6: ='April_2025 '!R54 -> 288.36403 | F6: Apr | G6: ='April_2025 '!Q56 -> 355.54997 | H6: ='April_2025 '!R56 -> 371.69 | K6: =C6-G6 -> -73.761779 | L6: =D6-H6 -> -83.325969
B7: May | C7: =May_2025!R63 -> 197.24186 | D7: =May_2025!S63 -> 274.41256 | F7: May | G7: =May_2025!R65 -> 317.49394 | H7: =May_2025!S65 -> 360.86932 | K7: =C7-G7 -> -120.25208 | L7: =D7-H7 -> -86.456763
B8: Jun | C8: =June_2025!Q57 -> 289.34656 | D8: =June_2025!R57 -> 270.7666 | F8: Jun | G8: =June_2025!Q59 -> 369.85315 | H8: =June_2025!R59 -> 362.55261 | K8: =C8-G8 -> -80.506584 | L8: =D8-H8 -> -91.786003
B9: Jul | C9: =July_2025!Q55 -> 275.49765 | D9: =July_2025!R55 -> 271.54794 | F9: Jul | G9: =July_2025!Q57 -> 393.45557 | H9: =July_2025!R57 -> 367.3874 | K9: =C9-G9 -> -117.95791 | L9: =D9-H9 -> -95.839463
B10: Aug | C10: =August_2025!Q57 -> 293.59276 | D10: =August_2025!R57 -> 282.80052 | F10: Aug | G10: =August_2025!Q59 -> 392.66579 | H10: =August_2025!R59 -> 370.2679 | K10: =C10-G10 -> -99.073032 | L10: =D10-H10 -> -87.467384
B11: Sep | C11: =September_2025!Q54 -> 279.47043 | D11: =September_2025!R54 -> 274.62897 | F11: Sep | G11: =September_2025!Q56 -> 399.59138 | H11: =September_2025!R56 -> 373.31684 | K11: =C11-G11 -> -120.12095 | L11: =D11-H11 -> -98.687876
B12: Oct | C12: =October_2025!Q64 -> 296.95343 | D12: =October_2025!R64 -> 277.09489 | F12: Oct | G12: =October_2025!Q66 -> 402.83395 | H12: =October_2025!R66 -> 376.58322 | K12: =C12-G12 -> -105.88052 | L12: =D12-H12 -> -99.488334
B13: Nov | C13: =November_2025!Q62 -> 267.01347 | D13: =November_2025!R62 -> 276.20899 | F13: Nov | G13: =November_2025!Q64 -> 372.39112 | H13: =November_2025!R64 -> 376.22344 | K13: =C13-G13 -> -105.37764 | L13: =D13-H13 -> -100.01445
B14: Dec | C14: =December_2025!Q60 -> 257.40149 | D14: =December_2025!S60 -> 274.21192 | F14: Dec | G14: =December_2025!Q62 -> 361.78202 | H14: =December_2025!S62 -> 374.73246 | K14: =C14-G14 -> -104.38053 | L14: =D14-H14 -> -100.52054

Sheet January_2025
B1: GRENADA BREWERIES LIMITED
B3: PRODUCTION DEPARTMENT
B4: 45658
B5: DATE | C5: DAY | D5: PRODUCT | E5: AVAIL. | F5: FILL | G5: CASES | H5: Line Rated | I5: Cases on Hold | J5: BBT | K5: BOTTLED | L5: Diff BBT Hls vs Hls in Package | M5: DOWNTIME (Mins) | N5: REJECTS (Cases) | O5: KEGS | P5: BOTTLED | Q5: AVERAGE | R5: YTD
E6: TIME | F6: TIME | G6: BOTTLED | H6: Efficiency | J6: HLS | K6: HLS | P6: LOSS | Q6: CASE/HR | R6: Ave Case per hour
F7: Mins | H7: %
B8: 45659 | C8: 1 | D8: STAG LOCAL | E8: 858 | F8: =[4]Jan!$N69 -> 364 | G8: 2153 | H8: =(G8)*24/(F8/60)/17000*100 -> 50.102133 | J8: =71.3+72 -> 143.3 | K8: =(G8)*0.066 -> 142.098 | L8: =J8-K8 -> 1.202 | M8: =[4]Jan!AD8 -> 189 | N8: =3.5 -> 3.5 | P8: =(J8-K8)/J8*100 -> 0.83879972 | Q8: =(G8)/(F8/60) -> 354.89011
B9: 45659 | C9: 1 | D9: CARIB AMBER | F9: =[4]Jan!$N70 -> 405 | G9: 3344 | H9: =(G9)*24/(F9/60)/17000*100 -> 69.939869 | J9: =99.4+87.1+99.2+101.8-73.2-78 -> 236.3 | K9: =(G9)*0.066 -> 220.704 | L9: =J9-K9 -> 15.596 | M9: =[4]Jan!AD9 -> 194 | N9: =1+3 -> 4 | P9: =(J9-K9)/J9*100 -> 6.6000846 | Q9: =(G9)/(F9/60) -> 495.40741
B10: 3 | C10: 2 | D10: CARIB FLINT LOCAL | E10: 186 | F10: =[4]Jan!$N71 -> 174 | G10: 1292 | H10: =(G10)*24/(F10/60)/17000*100 -> 62.896552 | J10: =73.2+78-30.3-35.2 -> 85.7 | K10: =(G10)*0.066 -> 85.272 | L10: =J10-K10 -> 0.428 | M10: =[4]Jan!AD10 -> 47 | N10: 9 | P10: =(J10-K10)/J10*100 -> 0.49941657 | Q10: =(G10)/(F10/60) -> 445.51724
B11: 6 | C11: 3 | D11: CARIB AMBER | E11: 1440 | F11: =[4]Jan!$N72 -> 794 | G11: 5928 | H11: =(G11)*24/(F11/60)/17000*100 -> 63.241369 | J11: =94+96.7+65.5+87.5+54 -> 397.7 | K11: =(G11)*0.066 -> 391.248 | L11: =J11-K11 -> 6.452 | M11: =[4]Jan!AD11 -> 82 | N11: 25 | P11: =(J11-K11)/J11*100 -> 1.6223284 | Q11: =(G11)/(F11/60) -> 447.9597
B12: 6 | C12: 3 | D12: STAG LOCAL | F12: =[4]Jan!$N73 -> 359 | G12: 2487 | H12: =(G12)*24/(F12/60)/17000*100 -> 58.680649 | J12: =95+93-21.5 -> 166.5 | K12: =(G12)*0.066 -> 164.142 | L12: =J12-K12 -> 2.358 | M12: =[4]Jan!AD12 -> 68 | N12: 9 | P12: =(J12-K12)/J12*100 -> 1.4162162 | Q12: =(G12)/(F12/60) -> 415.6546
B13: 45664 | C13: 4 | D13: STAG LOCAL | E13: 1440 | F13: =[4]Jan!$N74 -> 400 | G13: 3057 | H13: =(G13)*24/(F13/60)/17000*100 -> 64.736471 | J13: =99.4+85+21.5 -> 205.9 | K13: =(G13)*0.066 -> 201.762 | L13: =J13-K13 -> 4.138 | M13: =[4]Jan!AD13 -> 57 | N13: 5 | P13: =(J13-K13)/J13*100 -> 2.0097135 | Q13: =(G13)/(F13/60) -> 458.55
B14: 45664 | C14: 4 | D14: CARIB AMBER | F14: =[4]Jan!$N75 -> 478 | G14: 3335 | H14: =(G14)*24/(F14/60)/17000*100 -> 59.099188 | J14: =91+42.2+90.2 -> 223.4 | K14: =(G14)*0.066 -> 220.11 | L14: =J14-K14 -> 3.29 | M14: =[4]Jan!AD14 -> 128 | N14: 15 | P14: =(J14-K14)/J14*100 -> 1.4726947 | Q14: =(G14)/(F14/60) -> 418.61925
B15: 45664 | C15: 4 | D15: VITAMALT CLASSIC | F15: =[4]Jan!$N76 -> 337 | G15: 360 | H15: =(G15)*24/(F15/60)/17000*100 -> 9.0486996 | J15: =99.2+42.3-45-70 -> 26.5 | K15: =G15*0.0708 -> 25.488 | L15: =J15-K15 -> 1.012 | M15: =[4]Jan!AD15 -> 436 | P15: =(J15-K15)/J15*100 -> 3.8188679 | Q15: =(G15)/(F15/60) -> 64.094955
B16: 45665 | C16: 5 | D16: VITAMALT CLASSIC | E16: 1440 | F16: =[4]Jan!$N77 -> 205 | G16: 1606 | H16: =(G16)*24/(F16/60)/17000*100 -> 66.359828 | J16: =45+70 -> 115 | K16: =G16*0.0708 -> 113.7048 | L16: =J16-K16 -> 1.2952 | M16: =[4]Jan!AD16 -> 125 | P16: =(J16-K16)/J16*100 -> 1.1262609 | Q16: =(G16)/(F16/60) -> 470.04878
B17: 45665 | C17: 5 | D17: VITAMALT GINGER | F17: =[4]Jan!$N78 -> 210 | G17: 686 | H17: =(G17)*24/(F17/60)/17000*100 -> 27.670588 | J17: =50.7 -> 50.7 | K17: =G17*0.0708 -> 48.5688 | L17: =J17-K17 -> 2.1312 | M17: =[4]Jan!AD17 -> 21 | P17: =(J17-K17)/J17*100 -> 4.2035503 | Q17: =(G17)/(F17/60) -> 196
B18: 45665 | C18: 5 | D18: GUINNESS | F18: =[4]Jan!$N79 -> 663 | G18: 4437 | H18: =(G18)*24/(F18/60)/17000*100 -> 56.687783 | J18: =96+97.4+102.8 -> 296.2 | K18: =G18*0.066 -> 292.842 | L18: =J18-K18 -> 3.358 | M18: =[4]Jan!AD18 -> 361 | N18: 32 | P18: =(J18-K18)/J18*100 -> 1.1336935 | Q18: =(G18)/(F18/60) -> 401.53846
B19: 45665 | C19: 5 | D19: CARIB AMBER | F19: =[4]Jan!$N80 -> 47 | G19: 356 | H19: =(G19)*24/(F19/60)/17000*100 -> 64.1602 | J19: =98-74 -> 24 | K19: =G19*0.066 -> 23.496 | L19: =J19-K19 -> 0.504 | M19: =[4]Jan!AD19 -> 83 | P19: =(J19-K19)/J19*100 -> 2.1 | Q19: =(G19)/(F19/60) -> 454.46809
B20: 45666 | C20: 6 | D20: CARIB AMBER | E20: 965 | F20: =[4]Jan!$N81 -> 916 | G20: 6459 | H20: =(G20)*24/(F20/60)/17000*100 -> 59.728744 | J20: =74+97.1+82+97+82.5 -> 432.6 | K20: =G20*0.066 -> 426.294 | L20: =J20-K20 -> 6.306 | M20: =[4]Jan!AD20 -> 226 | P20: =(J20-K20)/J20*100 -> 1.4576976 | Q20: =(G20)/(F20/60) -> 423.0786
B21: 45673 | C21: 7 | D21: CARIB AMBER | E21: 863 | F21: =[4]Jan!$N82 -> 309 | G21: 2589 | H21: =(G21)*24/(F21/60)/17000*100 -> 70.972016 | J21: =87.4+94 -> 181.4 | K21: =G21*0.066+(35*0.19) -> 177.524 | L21: =J21-K21 -> 3.876 | M21: =[4]Jan!AD21 -> 140 | N21: 35 | O21: 35 | P21: =(J21-K21)/J21*100 -> 2.1367144 | Q21: =(G21)/(F21/60) -> 502.71845
B22: 45673 | C22: 7 | D22: STAG LOCAL | F22: =[4]Jan!$N83 -> 79 | G22: 509 | H22: =(G22)*24/(F22/60)/17000*100 -> 54.576322 | J22: =93.3-58 -> 35.3 | K22: =G22*0.066+(5*0.19) -> 34.544 | L22: =J22-K22 -> 0.756 | M22: =[4]Jan!AD22 -> 336 | O22: 5 | P22: =(J22-K22)/J22*100 -> 2.1416431 | Q22: =(G22)/(F22/60) -> 386.58228
B23: 45674 | C23: 8 | D23: STAG LOCAL | E23: 717 | F23: =[4]Jan!$N84 -> 99 | G23: 846 | H23: =(G23)*24/(F23/60)/17000*100 -> 72.385027 | J23: =58 -> 58 | K23: =G23*0.066 -> 55.836 | L23: =J23-K23 -> 2.164 | M23: =[4]Jan!AD23 -> 26 | N23: 6 | P23: =(J23-K23)/J23*100 -> 3.7310345 | Q23: =(G23)/(F23/60) -> 512.72727
B24: 45674 | C24: 8 | D24: CARIB AMBER | F24: =[4]Jan!$N85 -> 512 | G24: 3943 | H24: =(G24)*24/(F24/60)/17000*100 -> 65.233456 | J24: =81.1+96.8+96-9 -> 264.9 | K24: =G24*0.066 -> 260.238 | L24: =J24-K24 -> 4.662 | M24: =[4]Jan!AD24 -> 234 | P24: =(J24-K24)/J24*100 -> 1.7599094 | Q24: =(G24)/(F24/60) -> 462.07031
B25: 45677 | C25: 9 | D25: CARIB AMBER | E25: 853 | F25: =[4]Jan!$N86 -> 155 | G25: 1575 | H25: =(G25)*24/(F25/60)/17000*100 -> 86.072106 | J25: =9+99 -> 108 | K25: =G25*0.066 -> 103.95 | L25: =J25-K25 -> 4.05 | M25: =[4]Jan!AD25 -> 196 | N25: 7 | P25: =(J25-K25)/J25*100 -> 3.75 | Q25: =(G25)/(F25/60) -> 609.67742
B26: 45677 | C26: 9 | D26: STAG LOCAL | F26: =[4]Jan!$N87 -> 506 | G26: 3354 | H26: =(G26)*24/(F26/60)/17000*100 -> 56.146943 | J26: =89.6+99.6+100.9+99.7-75-90 -> 224.8 | K26: =G26*0.066 -> 221.364 | L26: =J26-K26 -> 3.436 | M26: =[4]Jan!AD26 -> 148 | P26: =(J26-K26)/J26*100 -> 1.5284698 | Q26: =(G26)/(F26/60) -> 397.70751
B27: 45678 | C27: 10 | D27: STAG LOCAL | E27: 819 | F27: =[4]Jan!$N88 -> 422 | G27: 3600 | H27: =(G27)*24/(F27/60)/17000*100 -> 72.260942 | J27: =75+90+75 -> 240 | K27: =G27*0.066 -> 237.6 | L27: =J27-K27 -> 2.4 | M27: =[4]Jan!AD27 -> 166 | N27: =3+6 -> 9 | P27: =(J27-K27)/J27*100 -> 1 | Q27: =(G27)/(F27/60) -> 511.84834
B28: 45678 | C28: 10 | D28: MACKESON | F28: =[4]Jan!$N89 -> 150 | G28: 1585 | H28: =(G28)*24/(F28/60)/17000*100 -> 89.505882 | J28: =100.2+96-87 -> 109.2 | K28: =G28*0.066 -> 104.61 | L28: =J28-K28 -> 4.59 | M28: =[4]Jan!AD28 -> 137 | N28: 3 | P28: =(J28-K28)/J28*100 -> 4.2032967 | Q28: =(G28)/(F28/60) -> 634
B29: 45679 | C29: 11 | D29: STAR MALT | E29: 799 | F29: =[4]Jan!$N90 -> 780 | G29: 5884 | H29: =(G29)*24/(F29/60)/17000*100 -> 63.898643 | J29: =97+100.9+99.4+100.8 -> 398.1 | K29: =G29*0.066 -> 388.344 | L29: =J29-K29 -> 9.756 | M29: =[4]Jan!AD29 -> 199 | N29: 10 | P29: =(J29-K29)/J29*100 -> 2.4506405 | Q29: =(G29)/(F29/60) -> 452.61538
B30: 45680 | C30: 12 | D30: MACKESON | E30: 834 | F30: =[4]Jan!$N91 -> 634 | G30: 4090 | H30: =(G30)*24/(F30/60)/17000*100 -> 54.644647 | J30: =87+94.3+90.4 -> 271.7 | K30: =G30*0.066 -> 269.94 | L30: =J30-K30 -> 1.76 | M30: =[4]Jan!AD30 -> 213 | P30: =(J30-K30)/J30*100 -> 0.64777328 | Q30: =(G30)/(F30/60) -> 387.06625
B31: 45680 | C31: 12 | D31: CARIB AMBER | F31: =[4]Jan!$N92 -> 109 | G31: 419 | H31: =(G31)*24/(F31/60)/17000*100 -> 32.561252 | J31: =97-69 -> 28 | K31: =G31*0.066 -> 27.654 | L31: =J31-K31 -> 0.346 | M31: =[4]Jan!AD31 -> 102 | P31: =(J31-K31)/J31*100 -> 1.2357143 | Q31: =(G31)/(F31/60) -> 230.6422
B32: 45681 | C32: 13 | D32: CARIB AMBER | E32: 795 | F32: =[4]Jan!$N93 -> 465 | G32: 3350 | H32: =(G32)*24/(F32/60)/17000*100 -> 61.024668 | J32: =69+75.1+103.2-15 -> 232.3 | K32: =G32*0.066 -> 221.1 | L32: =J32-K32 -> 11.2 | M32: =[4]Jan!AD32 -> 186 | N32: 4 | P32: =(J32-K32)/J32*100 -> 4.8213517 | Q32: =(G32)/(F32/60) -> 432.25806
B33: 45681 | C33: 13 | D33: ginseng original | F33: =[4]Jan!$N94 -> 175 | G33: 1602 | H33: =(G33)*24/(F33/60)/17000*100 -> 77.542185 | J33: =107.6 -> 107.6 | K33: =G33*0.066 -> 105.732 | L33: =J33-K33 -> 1.868 | M33: =[4]Jan!AD33 -> 68 | N33: 7 | P33: =(J33-K33)/J33*100 -> 1.7360595 | Q33: =(G33)/(F33/60) -> 549.25714
B34: 45684 | C34: 14 | D34: STAG LOCAL | E34: 887 | F34: =[4]Jan!$N95 -> 319 | G34: 2594 | H34: =(G34)*24/(F34/60)/17000*100 -> 68.879956 | J34: =80.3+96.5 -> 176.8 | K34: =G34*0.066+(10*0.19) -> 173.104 | L34: =J34-K34 -> 3.696 | M34: =[4]Jan!AD34 -> 398 | N34: 5 | O34: 10 | P34: =(J34-K34)/J34*100 -> 2.0904977 | Q34: =(G34)/(F34/60) -> 487.89969
B35: 45684 | C35: 14 | D35: CARIB AMBER | F35: =[4]Jan!$N96 -> 161 | G35: 963 | H35: =(G35)*24/(F35/60)/17000*100 -> 50.665692 | J35: =92+93.3-40-72 -> 73.3 | K35: =G35*0.066+(40*0.19) -> 71.158 | L35: =J35-K35 -> 2.142 | M35: =[4]Jan!AD35 -> 41 | N35: =3+2 -> 5 | O35: 40 | P35: =(J35-K35)/J35*100 -> 2.9222374 | Q35: =(G35)/(F35/60) -> 358.88199
B36: 45685 | C36: 15 | D36: CARIB AMBER | E36: 803 | F36: =[4]Jan!$N97 -> 184 | G36: 1548 | H36: =(G36)*24/(F36/60)/17000*100 -> 71.263427 | J36: =40+72-7 -> 105 | K36: =G36*0.066 -> 102.168 | L36: =J36-K36 -> 2.832 | M36: =[4]Jan!AD36 -> 66 | P36: =(J36-K36)/J36*100 -> 2.6971429 | Q36: =(G36)/(F36/60) -> 504.78261
B37: 45319 | C37: 15 | D37: shandy lime | F37: =[4]Jan!$N98 -> 528 | G37: 1895 | H37: =(G37)*24/(F37/60)/17000*100 -> 30.40107 | J37: =98+77.3-43.5 -> 131.8 | K37: =G37*0.066 -> 125.07 | L37: =J37-K37 -> 6.73 | M37: =[4]Jan!AD37 -> 339 | P37: =(J37-K37)/J37*100 -> 5.1062215 | Q37: =(G37)/(F37/60) -> 215.34091
B38: 45686 | C38: 16 | D38: shandy lime | E38: 810 | F38: =[4]Jan!$N99 -> 156 | G38: 626 | H38: =(G38)*24/(F38/60)/17000*100 -> 33.99095 | J38: =43.5 -> 43.5 | K38: =G38*0.066 -> 41.316 | L38: =J38-K38 -> 2.184 | M38: =[4]Jan!AD38 -> 269 | P38: =(J38-K38)/J38*100 -> 5.0206897 | Q38: =(G38)/(F38/60) -> 240.76923
B39: 45686 | C39: 16 | D39: CARIBE PEARSECCO | F39: =[4]Jan!$N100 -> 356 | G39: 2006 | H39: =(G39)*24/(F39/60)/17000*100 -> 47.730337 | J39: =95+90+92-70-66 -> 141 | K39: =G39*0.066 -> 132.396 | L39: =J39-K39 -> 8.604 | M39: =[4]Jan!AD39 -> 253 | P39: =(J39-K39)/J39*100 -> 6.1021277 | Q39: =(G39)/(F39/60) -> 338.08989
B40: 45687 | C40: 17 | D40: CARIBE PEARSECCO | E40: 869 | F40: =[4]Jan!$N101 -> 274 | G40: 1979 | H40: =(G40)*24/(F40/60)/17000*100 -> 61.179906 | J40: =70+66 -> 136 | K40: =G40*0.066 -> 130.614 | L40: =J40-K40 -> 5.386 | M40: =[4]Jan!AD40 -> 63 | N40: 12 | P40: =(J40-K40)/J40*100 -> 3.9602941 | Q40: =(G40)/(F40/60) -> 433.35766
B41: 45687 | C41: 17 | D41: CARIB AMBER | F41: =[4]Jan!$N102 -> 457 | G41: 3609 | H41: =(G41)*24/(F41/60)/17000*100 -> 66.893551 | J41: =90.2+90+100.3-35.8 -> 244.7 | K41: =G41*0.066 -> 238.194 | L41: =J41-K41 -> 6.506 | M41: =[4]Jan!AD41 -> 171 | N41: 10 | P41: =(J41-K41)/J41*100 -> 2.6587658 | Q41: =(G41)/(F41/60) -> 473.82932
...

Sheet February_2025
B1: GRENADA BREWERIES LIMITED
B3: PRODUCTION DEPARTMENT
B4: 45706
B5: DATE | C5: DAY | D5: PRODUCT | E5: AVAIL. | F5: FILL | G5: CASES | H5: Line Rated | I5: Cases on Hold | J5: BBT | K5: BOTTLED | L5: Diff BBT Hls vs Hls in Package | M5: DOWNTIME (Mins) | N5: REJECTS (Cases) | O5: KEGS | P5: BOTTLED | Q5: AVERAGE | R5: YTD
E6: TIME | F6: TIME | G6: BOTTLED | H6: Efficiency | J6: HLS | K6: HLS | P6: LOSS | Q6: CASE/HR | R6: Ave Case per hour
F7: Mins | H7: %
B8: 45691 | C8: 1 | D8: VITAMALT CLASSIC | E8: 1380 | F8: =[3]Feb!N68 -> 273 | G8: 2128 | H8: =(G8)*24/(F8/60)/17000*100 -> 66.027149 | J8: =4+99.7+99-52 -> 150.7 | K8: =(G8)*0.0708 -> 150.6624 | L8: =J8-K8 -> 0.0376 | M8: =[3]Feb!AD8 -> 90 | N8: 6 | P8: =(J8-K8)/J8*100 -> 0.024950232 | Q8: =G8/(F8/60) -> 467.69231
B9: 45691 | C9: 1 | D9: VITAMALT GINGER | F9: =[3]Feb!N69 -> 172 | G9: 734 | H9: =(G9)*24/(F9/60)/17000*100 -> 36.147743 | J9: 52 | K9: =(G9)*0.0708 -> 51.9672 | L9: =J9-K9 -> 0.0328 | M9: =[3]Feb!AD9 -> 96 | N9: 8 | P9: =(J9-K9)/J9*100 -> 0.063076923 | Q9: =G9/(F9/60) -> 256.04651
B10: 45691 | C10: 1 | D10: STAG LOCAL | F10: =[3]Feb!N70 -> 682 | G10: 4848 | H10: =(G10)*24/(F10/60)/17000*100 -> 60.213214 | I10: 8 | J10: =87.6+90+102.8+99-55 -> 324.4 | K10: =(G10)*0.066 -> 319.968 | L10: =J10-K10 -> 4.432 | M10: =[3]Feb!AD10 -> 321 | P10: =(J10-K10)/J10*100 -> 1.3662145 | Q10: =G10/(F10/60) -> 426.51026
B11: 45692 | C11: 2 | D11: STAG LOCAL | E11: 1440 | F11: =[3]Feb!N71 -> 97 | G11: 792 | H11: =(G11)*24/(F11/60)/17000*100 -> 69.161916 | J11: 55 | K11: =(G11)*0.066 -> 52.272 | L11: =J11-K11 -> 2.728 | M11: =[3]Feb!AD11 -> 14 | N11: 0.5 | P11: =(J11-K11)/J11*100 -> 4.96 | Q11: =G11/(F11/60) -> 489.89691
B12: 45692 | C12: 2 | D12: CARIB AMBER | F12: =[3]Feb!N72 -> 1267 | G12: 7331 | H12: =(G12)*24/(F12/60)/17000*100 -> 49.011746 | J12: =97.5+95.5+81.8+101.2+100.6+99-82 -> 493.6 | K12: =(G12)*0.066 -> 483.846 | L12: =J12-K12 -> 9.754 | M12: =[3]Feb!AD12 -> 597 | P12: =(J12-K12)/J12*100 -> 1.976094 | Q12: =G12/(F12/60) -> 347.16654
B13: 45693 | C13: 3 | D13: CARIB AMBER | E13: 1440 | F13: =[3]Feb!N73 -> 979 | G13: 8093 | H13: =(G13)*24/(F13/60)/17000*100 -> 70.022953 | I13: 11 | J13: =82+67+94.7+92.5+107.5+100 -> 543.7 | K13: =(G13)*0.066 -> 534.138 | L13: =J13-K13 -> 9.562 | M13: =[3]Feb!AD13 -> 286 | N13: =3+16 -> 19 | P13: =(J13-K13)/J13*100 -> 1.7586905 | Q13: =G13/(F13/60) -> 495.99591
B14: 45693 | C14: 3 | D14: GUINNESS | F14: =[3]Feb!N74 -> 173 | G14: 1329 | H14: =(G14)*24/(F14/60)/17000*100 -> 65.071744 | J14: =91.5-3 -> 88.5 | K14: =(G14)*0.066 -> 87.714 | L14: =J14-K14 -> 0.786 | M14: =[3]Feb!AD14 -> 124 | N14: 6 | P14: =(J14-K14)/J14*100 -> 0.88813559 | Q14: =G14/(F14/60) -> 460.92486
B15: 45694 | C15: 4 | D15: GUINNESS | E15: 1315 | F15: =[3]Feb!N75 -> 265 | G15: 1306 | H15: =(G15)*24/(F15/60)/17000*100 -> 41.745616 | J15: =83.6+3 -> 86.6 | K15: =(G15)*0.066 -> 86.196 | L15: =J15-K15 -> 0.404 | M15: =[3]Feb!AD15 -> 144 | N15: =5+7 -> 12 | P15: =(J15-K15)/J15*100 -> 0.4665127 | Q15: =G15/(F15/60) -> 295.69811
B16: 45694 | C16: 4 | D16: HURRICANE REEF PILS | F16: =[3]Feb!N76 -> 541 | G16: 2854 | H16: =(G16)*24/(F16/60)/17000*100 -> 44.685876 | J16: =97.6+95.4 -> 193 | K16: =(G16)*0.066 -> 188.364 | L16: =J16-K16 -> 4.636 | M16: =[3]Feb!AD16 -> 297 | N16: =4+4 -> 8 | P16: =(J16-K16)/J16*100 -> 2.4020725 | Q16: =G16/(F16/60) -> 316.52495
B17: 45694 | C17: 4 | D17: STAG LOCAL | F17: =[3]Feb!N77 -> 274 | G17: 1865 | H17: =(G17)*24/(F17/60)/17000*100 -> 57.655646 | J17: =98.3+95-70 -> 123.3 | K17: =(G17)*0.066 -> 123.09 | L17: =J17-K17 -> 0.21 | M17: =[3]Feb!AD17 -> 151 | N17: =9+3 -> 12 | P17: =(J17-K17)/J17*100 -> 0.1703163 | Q17: =G17/(F17/60) -> 408.39416
B18: 45698 | C18: 5 | D18: STAG LOCAL | E18: 1380 | F18: =[3]Feb!N78 -> 586 | G18: 2330 | H18: =(G18)*24/(F18/60)/17000*100 -> 33.679984 | J18: =70+91.7 -> 161.7 | K18: =(G18)*0.066 -> 153.78 | L18: =J18-K18 -> 7.92 | M18: =[3]Feb!AD18 -> 408 | N18: 4 | P18: =(J18-K18)/J18*100 -> 4.8979592 | Q18: =G18/(F18/60) -> 238.56655 | S18: 67
B19: 45698 | C19: 5 | D19: CARIB AMBER | F19: =[3]Feb!N79 -> 601 | G19: 3919 | H19: =(G19)*24/(F19/60)/17000*100 -> 55.235 | I19: 7 | J19: =93.5+96+91.2-15 -> 265.7 | K19: =(G19)*0.066 -> 258.654 | L19: =J19-K19 -> 7.046 | M19: =[3]Feb!AD19 -> 151 | N19: =5+7 -> 12 | P19: =(J19-K19)/J19*100 -> 2.651863 | Q19: =G19/(F19/60) -> 391.24792
B20: 45699 | C20: 6 | D20: CARIB AMBER | E20: 1440 | F20: =[3]Feb!N80 -> 198 | G20: 1647 | H20: =(G20)*24/(F20/60)/17000*100 -> 70.459893 | J20: =97.3+15 -> 112.3 | K20: =(G20)*0.066 -> 108.702 | L20: =J20-K20 -> 3.598 | M20: =[3]Feb!AD20 -> 37 | N20: =2+11 -> 13 | P20: =(J20-K20)/J20*100 -> 3.2039181 | Q20: =G20/(F20/60) -> 499.09091
B21: 45699 | C21: 6 | D21: STAG LOCAL | F21: =[3]Feb!N81 -> 1046 | G21: 8192 | H21: =(G21)*24/(F21/60)/17000*100 -> 66.339444 | J21: =93.6+86.8+97.1+96.2+97.7+79.2 -> 550.6 | K21: =(G21)*0.066 -> 540.672 | L21: =J21-K21 -> 9.928 | M21: =[3]Feb!AD21 -> 236 | N21: 0 | P21: =(J21-K21)/J21*100 -> 1.8031239 | Q21: =G21/(F21/60) -> 469.9044
B22: 45699 | C22: 6 | D22: CARIB AMBER | F22: =[3]Feb!N82 -> 72 | G22: 600 | H22: =(G22)*24/(F22/60)/17000*100 -> 70.588235 | J22: =88.6+100-60-88 -> 40.6 | K22: =(G22)*0.066 -> 39.6 | L22: =J22-K22 -> 1 | M22: =[3]Feb!AD22 -> 29 | N22: 6 | P22: =(J22-K22)/J22*100 -> 2.4630542 | Q22: =G22/(F22/60) -> 500
B23: 45700 | C23: 7 | D23: CARIB AMBER | E23: 1432 | F23: =[3]Feb!N83 -> 704 | G23: 5129 | H23: =(G23)*24/(F23/60)/17000*100 -> 61.712567 | J23: =60+88+88.2+109 -> 345.2 | K23: =(G23)*0.066 -> 338.514 | L23: =J23-K23 -> 6.686 | M23: =[3]Feb!AD23 -> 245 | N23: =7 -> 7 | P23: =(J23-K23)/J23*100 -> 1.9368482 | Q23: =G23/(F23/60) -> 437.13068
B24: 45700 | C24: 7 | D24: STAG LOCAL | F24: =[3]Feb!N84 -> 571 | G24: 4259 | H24: =(G24)*24/(F24/60)/17000*100 -> 63.180797 | J24: =96.6+97.8+97.5 -> 291.9 | K24: =(G24)*0.066+(25*0.19) -> 285.844 | L24: =J24-K24 -> 6.056 | M24: =[3]Feb!AD24 -> 157 | N24: =4+24 -> 28 | O24: 25 | P24: =(J24-K24)/J24*100 -> 2.0746831 | Q24: =G24/(F24/60) -> 447.53065
B25: 45701 | C25: 8 | D25: STAR MALT | E25: 1550 | F25: =[3]Feb!N85 -> 526 | G25: 4442 | H25: =(G25)*24/(F25/60)/17000*100 -> 71.53299 | J25: =SUM(100.5,96.8,104.3) -> 301.6 | K25: =(G25)*0.066 -> 293.172 | L25: =J25-K25 -> 8.428 | M25: =[3]Feb!AD25 -> 205 | N25: 5 | P25: =(J25-K25)/J25*100 -> 2.7944297 | Q25: =G25/(F25/60) -> 506.69202
B26: 45701 | C26: 8 | D26: GUINNESS | F26: =[3]Feb!N86 -> 433 | G26: 4017 | H26: =(G26)*24/(F26/60)/17000*100 -> 78.582801 | J26: =SUM(93.8,94.5,79) -> 267.3 | K26: =(G26)*0.066 -> 265.122 | L26: =J26-K26 -> 2.178 | M26: =[3]Feb!AD26 -> 357 | N26: 10 | P26: =(J26-K26)/J26*100 -> 0.81481481 | Q26: =G26/(F26/60) -> 556.62818
B27: 45702 | C27: 9 | D27: CARIB AMBER | E27: 1213 | F27: =[3]Feb!N87 -> 428 | G27: 2401 | H27: =(G27)*24/(F27/60)/17000*100 -> 47.518417 | J27: =72.2+99.2 -> 171.4 | K27: =(G27)*0.066+(46*0.19) -> 167.206 | L27: =J27-K27 -> 4.194 | M27: =[3]Feb!AD27 -> 354 | N27: 0 | O27: 46 | P27: =(J27-K27)/J27*100 -> 2.4469078 | Q27: =G27/(F27/60) -> 336.58879
B28: 45702 | C28: 9 | D28: STAG LOCAL | F28: =[3]Feb!N88 -> 512 | G28: 2100 | H28: =(G28)*24/(F28/60)/17000*100 -> 34.742647 | J28: =93.5+90.9-43 -> 141.4 | K28: =(G28)*0.066 -> 138.6 | L28: =J28-K28 -> 2.8 | M28: =[3]Feb!AD28 -> 348 | N28: 10 | P28: =(J28-K28)/J28*100 -> 1.980198 | Q28: =G28/(F28/60) -> 246.09375
B29: 45705 | C29: 10 | D29: STAG LOCAL | E29: 1380 | F29: =[3]Feb!N89 -> 260 | G29: 631 | H29: =(G29)*24/(F29/60)/17000*100 -> 20.557466 | I29: 44 | J29: 43 | K29: =(G29)*0.066 -> 41.646 | L29: =J29-K29 -> 1.354 | M29: =[3]Feb!AD29 -> 394 | N29: 5 | P29: =(J29-K29)/J29*100 -> 3.1488372 | Q29: =G29/(F29/60) -> 145.61538
B30: 45705 | C30: 10 | D30: CARIB AMBER | F30: =[3]Feb!N90 -> 887 | G30: 4120 | H30: =(G30)*24/(F30/60)/17000*100 -> 39.344784 | I30: 25 | J30: =97.5+104+85.8+92-45-54 -> 280.3 | K30: =(G30)*0.066 -> 271.92 | L30: =J30-K30 -> 8.38 | M30: =[3]Feb!AD30 -> 424 | N30: 29 | P30: =(J30-K30)/J30*100 -> 2.9896539 | Q30: =G30/(F30/60) -> 278.69222
B31: 45706 | C31: 11 | D31: CARIB AMBER | E31: 1440 | F31: =[3]Feb!N91 -> 138 | G31: 806 | H31: =(G31)*24/(F31/60)/17000*100 -> 49.473146 | J31: 54 | K31: =(G31)*0.066 -> 53.196 | L31: =J31-K31 -> 0.804 | M31: =[3]Feb!AD31 -> 63 | N31: 5 | P31: =(J31-K31)/J31*100 -> 1.4888889 | Q31: =G31/(F31/60) -> 350.43478
B32: 45706 | C32: 11 | D32: CARIBE PEARSECO | F32: =[3]Feb!N92 -> 249 | G32: 1438 | H32: =(G32)*24/(F32/60)/17000*100 -> 48.918498 | I32: 2 | J32: 101 | K32: =(G32)*0.066 -> 94.908 | L32: =J32-K32 -> 6.092 | M32: =[3]Feb!AD32 -> 343 | N32: 10 | P32: =(J32-K32)/J32*100 -> 6.0316832 | Q32: =G32/(F32/60) -> 346.50602
B33: 45706 | C33: 11 | D33: CARIBE ROSE | F33: =[3]Feb!N93 -> 485 | G33: 2593 | H33: =(G33)*24/(F33/60)/17000*100 -> 45.287083 | J33: =88+89 -> 177 | K33: =(G33)*0.066 -> 171.138 | L33: =J33-K33 -> 5.862 | M33: =[3]Feb!AD33 -> 203 | N33: 0 | P33: =(J33-K33)/J33*100 -> 3.3118644 | Q33: =G33/(F33/60) -> 320.78351
B34: 45706 | C34: 11 | D34: SHANDY GINGER | F34: =[3]Feb!N94 -> 120 | G34: 498 | H34: =(G34)*24/(F34/60)/17000*100 -> 35.152941 | J34: =102-66 -> 36 | K34: =(G34)*0.066 -> 32.868 | L34: =J34-K34 -> 3.132 | M34: =[3]Feb!AD34 -> 179 | N34: 6 | P34: =(J34-K34)/J34*100 -> 8.7 | Q34: =G34/(F34/60) -> 249
B35: 45707 | C35: 12 | D35: SHANDY GINGER | E35: 1440 | F35: =[3]Feb!N95 -> 201 | G35: 949 | H35: =(G35)*24/(F35/60)/17000*100 -> 39.992976 | J35: 66 | K35: =(G35)*0.066 -> 62.634 | L35: =J35-K35 -> 3.366 | M35: =[3]Feb!AD35 -> 90 | N35: 16 | P35: =(J35-K35)/J35*100 -> 5.1 | Q35: =G35/(F35/60) -> 283.28358
B36: 45707 | C36: 12 | D36: TING ORIGINAL | F36: =[3]Feb!N96 -> 593 | G36: 3386 | H36: =(G36)*24/(F36/60)/17000*100 -> 48.36663 | J36: =K36*1.02 -> 227.94552 | K36: =(G36)*0.066 -> 223.476 | L36: =J36-K36 -> 4.46952 | M36: =[3]Feb!AD36 -> 427 | P36: =(J36-K36)/J36*100 -> 1.9607843 | Q36: =G36/(F36/60) -> 342.59696
B37: 45707 | C37: 12 | D37: SHANDY SORREL | F37: =[3]Feb!N97 -> 268 | G37: 1576 | H37: =(G37)*24/(F37/60)/17000*100 -> 49.812116 | J37: =93.7+84.2-70 -> 107.9 | K37: =(G37)*0.066 -> 104.016 | L37: =J37-K37 -> 3.884 | M37: =[3]Feb!AD37 -> 182 | N37: 11 | P37: =(J37-K37)/J37*100 -> 3.5996293 | Q37: =G37/(F37/60) -> 352.83582
B38: 45708 | C38: 13 | D38: SHANDY SORREL | E38: 1440 | F38: =[3]Feb!N98 -> 196 | G38: 1046 | H38: =(G38)*24/(F38/60)/17000*100 -> 45.205282 | J38: 70 | K38: =(G38)*0.066 -> 69.036 | L38: =J38-K38 -> 0.964 | M38: =[3]Feb!AD38 -> 52 | N38: 13 | P38: =(J38-K38)/J38*100 -> 1.3771429 | Q38: =G38/(F38/60) -> 320.20408
B39: 45708 | C39: 13 | D39: VITA MALT CLASSIC | F39: =[3]Feb!N99 -> 391 | G39: 2662 | H39: =(G39)*24/(F39/60)/17000*100 -> 57.669325 | J39: =96.2+95.4 -> 191.6 | K39: =(G39)*0.0708 -> 188.4696 | L39: =J39-K39 -> 3.1304 | M39: =[3]Feb!AD39 -> 177 | N39: 1 | P39: =(J39-K39)/J39*100 -> 1.6338205 | Q39: =G39/(F39/60) -> 408.49105
B40: 45708 | C40: 13 | D40: J COOL CLUB SODA | F40: =[3]Feb!N100 -> 164 | G40: 697 | H40: =(G40)*24/(F40/60)/17000*100 -> 36 | I40: 50 | J40: =K40*1.02 -> 46.92204 | K40: =(G40)*0.066 -> 46.002 | L40: =J40-K40 -> 0.92004 | M40: =[3]Feb!AD40 -> 453 | N40: 3 | P40: =(J40-K40)/J40*100 -> 1.9607843 | Q40: =G40/(F40/60) -> 255
B41: 45708 | C41: 13 | D41: J COOL KOLA CHAMPAYNE | F41: =[3]Feb!N101 -> 97 | G41: 522 | H41: =(G41)*24/(F41/60)/17000*100 -> 45.58399 | J41: =K41*1.02 -> 35.14104 | K41: =(G41)*0.066 -> 34.452 | L41: =J41-K41 -> 0.68904 | M41: =[3]Feb!AD41 -> 40 | N41: 2 | P41: =(J41-K41)/J41*100 -> 1.9607843 | Q41: =G41/(F41/60) -> 322.8866
...

Sheet March_2025
B1: GRENADA BREWERIES LIMITED
B3: PRODUCTION DEPARTMENT
B4: 45717
B5: DATE | C5: DAY | D5: PRODUCT | E5: AVAIL. | F5: FILL | G5: CASES | H5: Line Rated | I5: Cases on Hold | J5: BBT | K5: BOTTLED | L5: Diff BBT Hls vs Hls in Package | M5: DOWNTIME (Mins) | N5: REJECTS (Cases) | O5: KEGS | P5: BOTTLED | Q5: AVERAGE | R5: YTD
E6: TIME | F6: TIME | G6: BOTTLED | H6: Efficiency | J6: HLS | K6: HLS | P6: LOSS | Q6: CASE/HR | R6: Ave Case per hour
F7: Mins | H7: % | Q7: Target- 430
B8: 45354 | C8: 1 | D8: CLUB SODA | E8: 1380 | F8: =[3]Mar!N69 -> 95 | G8: 698 | H8: =(G8)*24/(F8/60)/17000*100 -> 62.236533 | J8: =K8*1.02 -> 46.98936 | K8: =(G8)*0.066 -> 46.068 | L8: =J8-K8 -> 0.92136 | M8: =[3]Mar!AD8 -> 101 | N8: 14 | P8: =(J8-K8)/J8*100 -> 1.9607843 | Q8: =(G8)/(F8/60) -> 440.84211
B9: 45354 | C9: 1 | D9: JUICY COOL BANANA | F9: =[3]Mar!N70 -> 186 | G9: 1290 | H9: =(G9)*24/(F9/60)/17000*100 -> 58.747628 | J9: =K9*1.02 -> 86.8428 | K9: =(G9)*0.066 -> 85.14 | L9: =J9-K9 -> 1.7028 | M9: =[3]Mar!AD9 -> 40 | N9: 5 | P9: =(J9-K9)/J9*100 -> 1.9607843 | Q9: =(G9)/(F9/60) -> 416.12903
B10: 45719 | C10: 1 | D10: CREAM SODA | F10: =[3]Mar!N71 -> 78 | G10: 657 | H10: =(G10)*24/(F10/60)/17000*100 -> 71.348416 | J10: =K10*1.02 -> 44.22924 | K10: =(G10)*0.066 -> 43.362 | L10: =J10-K10 -> 0.86724 | M10: =[3]Mar!AD10 -> 103 | N10: 0 | P10: =(J10-K10)/J10*100 -> 1.9607843 | Q10: =(G10)/(F10/60) -> 505.38462
B11: 45719 | C11: 1 | D11: KOLA CHAMPAGNE | F11: =[3]Mar!N72 -> 80 | G11: 661 | H11: =(G11)*24/(F11/60)/17000*100 -> 69.988235 | J11: =K11*1.02 -> 44.49852 | K11: =(G11)*0.066 -> 43.626 | L11: =J11-K11 -> 0.87252 | M11: =[3]Mar!AD11 -> 13 | N11: 0 | P11: =(J11-K11)/J11*100 -> 1.9607843 | Q11: =(G11)/(F11/60) -> 495.75
B12: 45719 | C12: 1 | D12: JUICY COOL GINGER | F12: =[3]Mar!N73 -> 161 | G12: 1393 | H12: =(G12)*24/(F12/60)/17000*100 -> 73.289003 | J12: =K12*1.02 -> 93.77676 | K12: =(G12)*0.066 -> 91.938 | L12: =J12-K12 -> 1.83876 | M12: =[3]Mar!AD12 -> 132 | N12: 14 | P12: =(J12-K12)/J12*100 -> 1.9607843 | Q12: =(G12)/(F12/60) -> 519.13043
B13: 45719 | C13: 1 | D13: JUICY COOL GRAPE | F13: =[3]Mar!N74 -> 115 | G13: 701 | H13: =(G13)*24/(F13/60)/17000*100 -> 51.63376 | J13: =K13*1.02 -> 47.19132 | K13: =(G13)*0.066 -> 46.266 | L13: =J13-K13 -> 0.92532 | M13: =[3]Mar!AD13 -> 113 | N13: 5 | P13: =(J13-K13)/J13*100 -> 1.9607843 | Q13: =(G13)/(F13/60) -> 365.73913
B14: 45720 | C14: 2 | D14: STAG LOCAL | E14: 1544 | F14: =[3]Mar!N75 -> 253 | G14: 1703 | H14: =(G14)*24/(F14/60)/17000*100 -> 57.017438 | I14: 4 | J14: =57.8+57.2 -> 115 | K14: =(G14)*0.066 -> 112.398 | L14: =J14-K14 -> 2.602 | M14: =[3]Mar!AD14 -> 332 | N14: 4 | P14: =(J14-K14)/J14*100 -> 2.2626087 | Q14: =(G14)/(F14/60) -> 403.87352
B15: 45720 | C15: 2 | D15: CARIB AMBER | F15: =[3]Mar!N76 -> 760 | G15: 5524 | H15: =(G15)*24/(F15/60)/17000*100 -> 61.567802 | J15: =95.5+90.2+92.4+97 -> 375.1 | K15: =(G15)*0.066 -> 364.584 | L15: =J15-K15 -> 10.516 | M15: =[3]Mar!AD15 -> 263 | N15: 46 | P15: =(J15-K15)/J15*100 -> 2.8035191 | Q15: =(G15)/(F15/60) -> 436.10526
B16: 45720 | C16: 2 | D16: GINSENG UP ORIGINAL | F16: =[3]Mar!N77 -> 0 | G16: 0 | J16: 0 | K16: =(G16)*0.066 -> 0 | L16: =J16-K16 -> 0 | M16: =[3]Mar!AD16 -> 138 | N16: 0
B17: 45721 | C17: 3 | D17: GINSENG UP ORIGINAL | E17: 1440 | F17: =[3]Mar!N78 -> 508 | G17: 2856 | H17: =(G17)*24/(F17/60)/17000*100 -> 47.622047 | I17: 11 | J17: =100+98.3 -> 198.3 | K17: =(G17)*0.066 -> 188.496 | L17: =J17-K17 -> 9.804 | M17: =[3]Mar!AD17 -> 142 | N17: 0 | P17: =(J17-K17)/J17*100 -> 4.9440242 | Q17: =(G17)/(F17/60) -> 337.32283
B18: 45721 | C18: 3 | D18: GINSENG UP APPLE | F18: =[3]Mar!N79 -> 339 | G18: 1789 | H18: =(G18)*24/(F18/60)/17000*100 -> 44.701718 | I18: 41 | J18: =21.7+101 -> 122.7 | K18: =(G18)*0.066 -> 118.074 | L18: =J18-K18 -> 4.626 | M18: =[3]Mar!AD18 -> 185 | N18: 11 | P18: =(J18-K18)/J18*100 -> 3.7701711 | Q18: =(G18)/(F18/60) -> 316.63717
B19: 45721 | C19: 3 | D19: JUICY COOL GRAPE | F19: =[3]Mar!N80 -> 116 | G19: 584 | H19: =(G19)*24/(F19/60)/17000*100 -> 42.64503 | J19: =K19*1.02 -> 39.31488 | K19: =(G19)*0.066 -> 38.544 | L19: =J19-K19 -> 0.77088 | M19: =[3]Mar!AD19 -> 280 | N19: 14 | P19: =(J19-K19)/J19*100 -> 1.9607843 | Q19: =(G19)/(F19/60) -> 302.06897
B20: 45721 | C20: 3 | D20: GUINNESS | F20: =[3]Mar!N81 -> 0 | G20: 0 | J20: 0 | K20: =(G20)*0.066 -> 0 | L20: =J20-K20 -> 0 | M20: =[3]Mar!AD20 -> 108
B21: 45722 | C21: 4 | D21: GUINNESS | E21: 1450 | F21: =[3]Mar!N82 -> 576 | G21: 2928 | H21: =(G21)*24/(F21/60)/17000*100 -> 43.058824 | J21: =100+97.3 -> 197.3 | K21: =(G21)*0.066 -> 193.248 | L21: =J21-K21 -> 4.052 | M21: =[3]Mar!AD21 -> 289 | N21: =8+15 -> 23 | P21: =(J21-K21)/J21*100 -> 2.0537253 | Q21: =(G21)/(F21/60) -> 305
B22: 45722 | C22: 4 | D22: STAR MALT | F22: =[3]Mar!N83 -> 727 | G22: 2887 | H22: =(G22)*24/(F22/60)/17000*100 -> 33.637673 | J22: =93.5+102.1 -> 195.6 | K22: =(G22)*0.066 -> 190.542 | L22: =J22-K22 -> 5.058 | M22: =[3]Mar!AD22 -> 505 | N22: =5+1 -> 6 | P22: =(J22-K22)/J22*100 -> 2.5858896 | Q22: =(G22)/(F22/60) -> 238.26685
B23: 45723 | C23: 5 | D23: STAG LOCAL | E23: 1168 | F23: =[3]Mar!N84 -> 675 | G23: 4977 | H23: =(G23)*24/(F23/60)/17000*100 -> 62.456471 | J23: =91.7+91+56+90.3+38.4-25 -> 342.4 | K23: =(G23)*0.066+(30*0.019) -> 329.052 | L23: =J23-K23 -> 13.348 | M23: =[3]Mar!AD23 -> 599 | N23: =1+8 -> 9 | O23: 30 | P23: =(J23-K23)/J23*100 -> 3.8983645 | Q23: =(G23)/(F23/60) -> 442.4
B24: 45726 | C24: 6 | D24: CARIB AMBER | E24: 934 | F24: =[3]Mar!N85 -> 754 | G24: 3460 | H24: =(G24)*24/(F24/60)/17000*100 -> 38.870339 | J24: =98+92.9+98.2-37 -> 252.1 | K24: =(G24)*0.066+(70*0.19) -> 241.66 | L24: =J24-K24 -> 10.44 | M24: =[3]Mar!AD24 -> 306 | N24: 85 | O24: 70 | P24: =(J24-K24)/J24*100 -> 4.1412138 | Q24: =(G24)/(F24/60) -> 275.33156
B25: 45727 | C25: 7 | D25: CARIB AMBER | E25: 850 | F25: =[3]Mar!N86 -> 312 | G25: 1640 | H25: =(G25)*24/(F25/60)/17000*100 -> 44.524887 | J25: =37+82 -> 119 | K25: =(G25)*0.066 -> 108.24 | L25: =J25-K25 -> 10.76 | M25: =[3]Mar!AD25 -> 83 | N25: 86 | P25: =(J25-K25)/J25*100 -> 9.0420168 | Q25: =(G25)/(F25/60) -> 315.38462
B26: 45727 | C26: 7 | D26: STAG LOCAL | F26: =[3]Mar!N87 -> 78 | G26: 359 | H26: =(G26)*24/(F26/60)/17000*100 -> 38.986425 | J26: 25 | K26: =(G26)*0.066 -> 23.694 | L26: =J26-K26 -> 1.306 | M26: =[3]Mar!AD26 -> 105 | N26: 3 | P26: =(J26-K26)/J26*100 -> 5.224 | Q26: =(G26)/(F26/60) -> 276.15385
B27: 45727 | C27: 7 | D27: STAR MALT | F27: =[3]Mar!N88 -> 288 | G27: 836 | H27: =(G27)*24/(F27/60)/17000*100 -> 24.588235 | J27: =100+100.1-70.9-71 -> 58.2 | K27: =(G27)*0.066 -> 55.176 | L27: =J27-K27 -> 3.024 | M27: =[3]Mar!AD27 -> 208 | N27: 11 | P27: =(J27-K27)/J27*100 -> 5.1958763 | Q27: =(G27)/(F27/60) -> 174.16667
B28: 45728 | C28: 8 | D28: STAR MALT | E28: 759 | F28: =[3]Mar!N89 -> 334 | G28: 2046 | H28: =(G28)*24/(F28/60)/17000*100 -> 51.888693 | J28: =70.9+71 -> 141.9 | K28: =(G28)*0.066 -> 135.036 | L28: =J28-K28 -> 6.864 | M28: =[3]Mar!AD28 -> 497 | N28: 30 | P28: =(J28-K28)/J28*100 -> 4.8372093 | Q28: =(G28)/(F28/60) -> 367.54491
B29: 45729 | C29: 9 | D29: CARIB AMBER | E29: 843 | F29: =[3]Mar!N90 -> 678 | G29: 5464 | H29: =(G29)*24/(F29/60)/17000*100 -> 68.264446 | J29: =94+93.6+93.4+93-2.4 -> 371.6 | K29: =(G29)*0.066 -> 360.624 | L29: =J29-K29 -> 10.976 | M29: =[3]Mar!AD29 -> 239 | N29: =10.5+16 -> 26.5 | P29: =(J29-K29)/J29*100 -> 2.9537137 | Q29: =(G29)/(F29/60) -> 483.53982
B30: 45730 | C30: 10 | D30: STAG LOCAL | E30: 717 | F30: =[3]Mar!N91 -> 150 | G30: 1410 | H30: =(G30)*24/(F30/60)/17000*100 -> 79.623529 | J30: 95.4 | K30: =(G30)*0.066 -> 93.06 | L30: =J30-K30 -> 2.34 | M30: =[3]Mar!AD30 -> 85 | N30: =6+3 -> 9 | P30: =(J30-K30)/J30*100 -> 2.4528302 | Q30: =(G30)/(F30/60) -> 564
B31: 45730 | C31: 10 | D31: CARIB AMBER | F31: =[3]Mar!N92 -> 380 | G31: 2718 | H31: =(G31)*24/(F31/60)/17000*100 -> 60.586997 | J31: =99.6+93.3+2.4-7.8 -> 187.5 | K31: =(G31)*0.066 -> 179.388 | L31: =J31-K31 -> 8.112 | M31: =[3]Mar!AD31 -> 150 | N31: 14 | P31: =(J31-K31)/J31*100 -> 4.3264 | Q31: =(G31)/(F31/60) -> 429.15789
B32: 45733 | C32: 11 | D32: CARIB AMBER | E32: 1380 | F32: =[3]Mar!N93 -> 415 | G32: 1568 | H32: =(G32)*24/(F32/60)/17000*100 -> 32.004536 | J32: 107.8 | K32: =(G32)*0.066 -> 103.488 | L32: =J32-K32 -> 4.312 | M32: =[3]Mar!AD32 -> 1075 | N32: 13 | P32: =(J32-K32)/J32*100 -> 4 | Q32: =(G32)/(F32/60) -> 226.6988
B33: 45733 | C33: 11 | D33: STAG LOCAL | F33: =[3]Mar!N94 -> 92 | G33: 731 | H33: =(G33)*24/(F33/60)/17000*100 -> 67.304348 | J33: =94+79.9-65-60 -> 48.9 | K33: =(G33)*0.066 -> 48.246 | L33: =J33-K33 -> 0.654 | M33: =[3]Mar!AD33 -> 38 | N33: 3 | P33: =(J33-K33)/J33*100 -> 1.3374233 | Q33: =(G33)/(F33/60) -> 476.73913
B34: 45734 | C34: 12 | D34: STAG LOCAL | E34: 1440 | F34: =[3]Mar!N95 -> 225 | G34: 1880 | H34: =(G34)*24/(F34/60)/17000*100 -> 70.776471 | J34: =65+60 -> 125 | K34: =(G34)*0.066 -> 124.08 | L34: =J34-K34 -> 0.92 | M34: =[3]Mar!AD34 -> 59 | N34: 5 | P34: =(J34-K34)/J34*100 -> 0.736 | Q34: =(G34)/(F34/60) -> 501.33333
B35: 45734 | C35: 12 | D35: CARIB AMBER | F35: =[3]Mar!N96 -> 627 | G35: 4631 | H35: =(G35)*24/(F35/60)/17000*100 -> 62.563467 | J35: =97+96+97+100+73-68-81 -> 314 | K35: =(G35)*0.066 -> 305.646 | L35: =J35-K35 -> 8.354 | M35: =[3]Mar!AD35 -> 659 | N35: =5+9 -> 14 | P35: =(J35-K35)/J35*100 -> 2.6605096 | Q35: =(G35)/(F35/60) -> 443.15789
B36: 45735 | C36: 13 | D36: CARIB AMBER | E36: 1540 | F36: =[3]Mar!N97 -> 103 | G36: 864 | H36: =(G36)*24/(F36/60)/17000*100 -> 71.054255 | J36: =68+81 -> 149 | K36: =(G36+G37)*0.066 -> 146.652 | L36: =J36-K36 -> 2.348 | M36: =[3]Mar!AD36 -> 25 | N36: 6 | P36: =(J36-K36)/J36*100 -> 1.5758389 | Q36: =(G36)/(F36/60) -> 503.30097
B37: 45735 | C37: 13 | D37: CARIB FLINT LOCAL | F37: =[3]Mar!N98 -> 200 | G37: 1358 | H37: =(G37)*24/(F37/60)/17000*100 -> 57.515294 | M37: =[3]Mar!AD37 -> 126 | N37: 7 | Q37: =(G37)/(F37/60) -> 407.4
B38: 45735 | C38: 13 | D38: STAG LOCAL | F38: =[3]Mar!N99 -> 1010 | G38: 5375 | H38: =(G38)*24/(F38/60)/17000*100 -> 45.078626 | J38: =83.8+92.3+85.1+97.5 -> 358.7 | K38: =(G38)*0.066 -> 354.75 | L38: =J38-K38 -> 3.95 | M38: =[3]Mar!AD38 -> 534 | N38: =5+5 -> 10 | P38: =(J38-K38)/J38*100 -> 1.1011988 | Q38: =(G38)/(F38/60) -> 319.30693
B39: 45736 | C39: 14 | D39: GUINNESS | E39: 1340 | F39: =[3]Mar!N100 -> 1270 | G39: 4053 | H39: =(G39)*24/(F39/60)/17000*100 -> 27.032515 | J39: =96+99.4+97.5-25.4 -> 267.5 | K39: =(G39)*0.066 -> 267.498 | L39: =J39-K39 -> 0.002 | M39: =[3]Mar!AD39 -> 801 | N39: 8 | P39: =(J39-K39)/J39*100 -> 0.00074766355 | Q39: =(G39)/(F39/60) -> 191.48031
B40: 45737 | C40: 15 | D40: GUINNESS | E40: 312 | F40: =[3]Mar!N101 -> 295 | G40: 1771 | H40: =(G40)*24/(F40/60)/17000*100 -> 50.852243 | J40: =91.7+25.4 -> 117.1 | K40: =(G40)*0.066 -> 116.886 | L40: =J40-K40 -> 0.214 | M40: =[3]Mar!AD40 -> 81 | N40: 9 | P40: =(J40-K40)/J40*100 -> 0.18274979 | Q40: =(G40)/(F40/60) -> 360.20339
B41: 45740 | C41: 16 | D41: CARIB AMBER | E41: 1380 | F41: =[3]Mar!N102 -> 1265 | G41: 1021 | H41: =(G41)*24/(F41/60)/17000*100 -> 6.8367356 | J41: =95+56-72 -> 79 | K41: =(G41)*0.066+((22+28)*0.19) -> 76.886 | L41: =J41-K41 -> 2.114 | M41: =[3]Mar!AD41 -> 1248 | N41: =3+9 -> 12 | O41: =22+28 -> 50 | P41: =(J41-K41)/J41*100 -> 2.6759494 | Q41: =(G41)/(F41/60) -> 48.426877
...

Sheet April_2025 
B1: GRENADA BREWERIES LIMITED
B3: PRODUCTION DEPARTMENT
B4: 45748
B5: DATE | C5: DAY | D5: PRODUCT | E5: AVAIL. | F5: FILL | G5: CASES | H5: Line Rated | I5: Cases on Hold | J5: BBT | K5: BOTTLED | L5: Diff BBT Hls vs Hls in Package | M5: DOWNTIME (Mins) | N5: REJECTS (Cases) | O5: KEGS | P5: BOTTLED | Q5: AVERAGE | R5: YTD
E6: TIME | F6: TIME | G6: BOTTLED | H6: Efficiency | J6: HLS | K6: HLS | P6: LOSS | Q6: CASE/HR | R6: Ave Case per hour
F7: Mins | H7: %
B8: 45748 | C8: 1 | D8: CARIB AMBER | E8: 1440 | F8: =[3]Apr!P62 -> 1048 | G8: 7510 | H8: =(G8)*24/(F8/60)/17000*100 -> 60.700494 | J8: =SUM(84.8,43,100,92.6,96,82.2) -> 498.6 | K8: =(G8)*0.066 -> 495.66 | L8: =J8-K8 -> 2.94 | M8: =[3]Apr!AD8 -> 179 | N8: 6 | P8: =(J8-K8)/J8*100 -> 0.58965102 | Q8: =(G8)/(F8/60) -> 429.96183
B9: 45748 | C9: 1 | D9: STAG LOCAL | F9: =[3]Apr!P63 -> 372 | G9: 2172 | H9: =(G9)*24/(F9/60)/17000*100 -> 49.457306 | I9: 26 | J9: =SUM(96,98)-33.8-12.8 -> 147.4 | K9: =(G9)*0.066 -> 143.352 | L9: =J9-K9 -> 4.048 | M9: =[3]Apr!AD9 -> 72 | N9: 4 | P9: =(J9-K9)/J9*100 -> 2.7462687 | Q9: =(G9)/(F9/60) -> 350.32258
B10: 45749 | C10: 2 | D10: STAG LOCAL | E10: 688 | F10: =[3]Apr!P64 -> 628 | G10: 3638 | H10: =(G10)*24/(F10/60)/17000*100 -> 49.070064 | J10: =SUM(97,97.2,33.8,12.8) -> 240.8 | K10: =(G10)*0.066 -> 240.108 | L10: =J10-K10 -> 0.692 | M10: =[3]Apr!AD10 -> 216 | N10: =8+3 -> 11 | P10: =(J10-K10)/J10*100 -> 0.28737542 | Q10: =(G10)/(F10/60) -> 347.57962
B11: 45750 | C11: 3 | D11: CARIBE PEARSECCO | E11: 610 | F11: =[3]Apr!P65 -> 391 | G11: 1601 | H11: =(G11)*24/(F11/60)/17000*100 -> 34.683918 | I11: 16 | J11: =SUM(91.2,91.5)-72 -> 110.7 | K11: =(G11)*0.066 -> 105.666 | L11: =J11-K11 -> 5.034 | M11: =[3]Apr!AD11 -> 295 | N11: 8 | P11: =(J11-K11)/J11*100 -> 4.5474255 | Q11: =(G11)/(F11/60) -> 245.67775
B12: 45751 | C12: 4 | D12: CARIBE PEARSECCO | E12: 1207 | F12: =[3]Apr!P66 -> 234 | G12: 1050 | H12: =(G12)*24/(F12/60)/17000*100 -> 38.00905 | J12: 72 | K12: =(G12)*0.066 -> 69.3 | L12: =J12-K12 -> 2.7 | M12: =[3]Apr!AD12 -> 106 | N12: 6 | P12: =(J12-K12)/J12*100 -> 3.75 | Q12: =(G12)/(F12/60) -> 269.23077
B13: 45751 | C13: 4 | D13: CARIBE ROSE | F13: =[3]Apr!P67 -> 273 | G13: 1254 | H13: =(G13)*24/(F13/60)/17000*100 -> 38.908856 | J13: =SUM(86) -> 86 | K13: =(G13)*0.066 -> 82.764 | L13: =J13-K13 -> 3.236 | M13: =[3]Apr!AD13 -> 136 | N13: 2 | P13: =(J13-K13)/J13*100 -> 3.7627907 | Q13: =(G13)/(F13/60) -> 275.6044
B14: 45751 | C14: 4 | D14: CARIB AMBER | F14: =[3]Apr!P68 -> 433 | G14: 3310 | H14: =(G14)*24/(F14/60)/17000*100 -> 64.752072 | J14: =SUM(94.9,84.5,97.5)-46.7 -> 230.2 | K14: =(G14)*0.066+(45*0.19) -> 227.01 | L14: =J14-K14 -> 3.19 | M14: =[3]Apr!AD14 -> 206 | N14: =4+6 -> 10 | O14: 45 | P14: =(J14-K14)/J14*100 -> 1.3857515 | Q14: =(G14)/(F14/60) -> 458.66051
B15: 45754 | C15: 5 | D15: CARIB AMBER | E15: 1380 | F15: =[3]Apr!P69 -> 1100 | G15: 8796 | H15: =(G15)*24/(F15/60)/17000*100 -> 67.733904 | J15: =SUM(97,95.3,104,46.7,92.9,78.7,94.8,100)-96.5 -> 612.9 | K15: =(G15+G16)*0.066 -> 607.2 | L15: =J15-K15 -> 5.7 | M15: =[3]Apr!AD15 -> 299 | N15: =11+4 -> 15 | P15: =(J15-K15)/J15*100 -> 0.93000489 | Q15: =(G15)/(F15/60) -> 479.78182
B16: 45754 | C16: 5 | D16: CARIB FLINT LOCAL | F16: =[3]Apr!P70 -> 97 | G16: 404 | H16: =(G16)*24/(F16/60)/17000*100 -> 35.279563 | M16: =[3]Apr!AD16 -> 56 | Q16: =(G16)/(F16/60) -> 249.89691
B17: 45755 | C17: 6 | D17: CARIB FLINT LOCAL | E17: 1422 | F17: =[3]Apr!P71 -> 487 | G17: 2951 | H17: =(G17)*24/(F17/60)/17000*100 -> 51.327938 | J17: =SUM(96.5,100) -> 196.5 | K17: =(G17)*0.066 -> 194.766 | L17: =J17-K17 -> 1.734 | M17: =[3]Apr!AD17 -> 291 | N17: 10 | P17: =(J17-K17)/J17*100 -> 0.88244275 | Q17: =(G17)/(F17/60) -> 363.5729
B18: 45755 | C18: 6 | D18: STAG LOCAL | F18: =[3]Apr!P72 -> 711 | G18: 3959 | H18: =(G18)*24/(F18/60)/17000*100 -> 47.166046 | I18: =9+70 -> 79 | J18: =SUM(98.9,97.1,103,100.6)-32.8-98 -> 268.8 | K18: =(G18)*0.066+(15*0.19) -> 264.144 | L18: =J18-K18 -> 4.656 | M18: =[3]Apr!AD18 -> 304 | N18: =14+1 -> 15 | O18: 15 | P18: =(J18-K18)/J18*100 -> 1.7321429 | Q18: =(G18)/(F18/60) -> 334.09283
B19: 45756 | C19: 7 | D19: STAG LOCAL | E19: 1423 | F19: =[3]Apr!P73 -> 226 | G19: 1975 | H19: =(G19)*24/(F19/60)/17000*100 -> 74.023946 | J19: =SUM(98,32.8) -> 130.8 | K19: =(G19)*0.066 -> 130.35 | L19: =J19-K19 -> 0.45 | M19: =[3]Apr!AD19 -> 75 | N19: 2 | P19: =(J19-K19)/J19*100 -> 0.3440367 | Q19: =(G19)/(F19/60) -> 524.33628
B20: 45756 | C20: 7 | D20: GUINNESS | F20: =[3]Apr!P74 -> 638 | G20: 3640 | H20: =(G20)*24/(F20/60)/17000*100 -> 48.327494 | J20: =SUM(96.4,47.9,96.2) -> 240.5 | K20: =(G20)*0.066 -> 240.24 | L20: =J20-K20 -> 0.26 | M20: =[3]Apr!AD20 -> 236 | N20: =4+10 -> 14 | P20: =(J20-K20)/J20*100 -> 0.10810811 | Q20: =(G20)/(F20/60) -> 342.31975
B21: 45756 | C21: 7 | D21: STAR MALT | F21: =[3]Apr!P75 -> 390 | G21: 2087 | H21: =(G21)*24/(F21/60)/17000*100 -> 45.328507 | J21: =SUM(106,98.5)-62.7 -> 141.8 | K21: =(G21)*0.066 -> 137.742 | L21: =J21-K21 -> 4.058 | M21: =[3]Apr!AD21 -> 193 | N21: 4 | P21: =(J21-K21)/J21*100 -> 2.8617772 | Q21: =(G21)/(F21/60) -> 321.07692
B22: 45757 | C22: 8 | D22: STAR MALT | E22: 1369 | F22: =[3]Apr!P76 -> 139 | G22: 940 | H22: =(G22)*24/(F22/60)/17000*100 -> 57.283115 | J22: 62.7 | K22: =(G22)*0.066 -> 62.04 | L22: =J22-K22 -> 0.66 | M22: =[3]Apr!AD22 -> 50 | N22: 2 | P22: =(J22-K22)/J22*100 -> 1.0526316 | Q22: =(G22)/(F22/60) -> 405.7554
B23: 45757 | C23: 8 | D23: CARIB AMBER | F23: =[3]Apr!P77 -> 459 | G23: 2938 | H23: =(G23)*24/(F23/60)/17000*100 -> 54.219146 | J23: =SUM(99.3,98.6) -> 197.9 | K23: =(G23)*0.066 -> 193.908 | L23: =J23-K23 -> 3.992 | M23: =[3]Apr!AD23 -> 179 | N23: 14 | P23: =(J23-K23)/J23*100 -> 2.0171804 | Q23: =(G23)/(F23/60) -> 384.05229
B24: 45757 | C24: 8 | D24: JCOOL SORREL | F24: =[3]Apr!P78 -> 174 | G24: 891 | H24: =(G24)*24/(F24/60)/17000*100 -> 43.375254 | J24: =K24*1.02 -> 59.98212 | K24: =(G24)*0.066 -> 58.806 | L24: =J24-K24 -> 1.17612 | M24: =[3]Apr!AD24 -> 358 | N24: 15 | P24: =(J24-K24)/J24*100 -> 1.9607843 | Q24: =(G24)/(F24/60) -> 307.24138
B25: 45761 | C25: 9 | D25: CARIB AMBER | E25: 1380 | F25: =[3]Apr!P79 -> 679 | G25: 4275 | H25: =(G25)*24/(F25/60)/17000*100 -> 53.331023 | I25: =100+13 -> 113 | J25: =SUM(96.5,94.8,97) -> 288.3 | K25: =(G25)*0.066 -> 282.15 | L25: =J25-K25 -> 6.15 | M25: =[3]Apr!AD25 -> 374 | N25: 10 | P25: =(J25-K25)/J25*100 -> 2.1331946 | Q25: =(G25)/(F25/60) -> 377.76141
B26: 45761 | C26: 9 | D26: STAG LOCAL | F26: =[3]Apr!P80 -> 355 | G26: 2798 | H26: =(G26)*24/(F26/60)/17000*100 -> 66.762552 | J26: =SUM(92,95) -> 187 | K26: =(G26)*0.066 -> 184.668 | L26: =J26-K26 -> 2.332 | M26: =[3]Apr!AD26 -> 130 | N26: 7 | P26: =(J26-K26)/J26*100 -> 1.2470588 | Q26: =(G26)/(F26/60) -> 472.90141
B27: 45761 | C27: 9 | D27: CARIB AMBER | F27: =[3]Apr!P81 -> 34 | G27: 213 | H27: =(G27)*24/(F27/60)/17000*100 -> 53.065744 | J27: =SUM(97.5,97)-89.7-90.5 -> 14.3 | K27: =(G27)*0.066 -> 14.058 | L27: =J27-K27 -> 0.242 | M27: =[3]Apr!AD27 -> 41 | N27: 0 | P27: =(J27-K27)/J27*100 -> 1.6923077 | Q27: =(G27)/(F27/60) -> 375.88235
B28: 45762 | C28: 10 | D28: CARIB AMBER | E28: 1425 | F28: =[3]Apr!P82 -> 636 | G28: 5276 | H28: =(G28)*24/(F28/60)/17000*100 -> 70.26859 | J28: =SUM(89.7,90.5,4.8,92.6,97.5) -> 375.1 | K28: =(G28+G29)*0.066 -> 369.6 | L28: =J28-K28 -> 5.5 | M28: =[3]Apr!AD28 -> 184 | N28: 0 | P28: =(J28-K28)/J28*100 -> 1.4662757 | Q28: =(G28)/(F28/60) -> 497.73585
B29: 45762 | C29: 10 | D29: CARIB FLINT LOCAL | F29: =[3]Apr!P83 -> 57 | G29: 324 | H29: =(G29)*24/(F29/60)/17000*100 -> 48.148607 | L29: =J29-K29 -> 0 | M29: =[3]Apr!AD29 -> 14 | N29: 0 | Q29: =(G29)/(F29/60) -> 341.05263
B30: 45762 | C30: 10 | D30: VITA MALT CLASSIC | F30: =[3]Apr!P84 -> 451 | G30: 1761 | H30: =(G30)*24/(F30/60)/17000*100 -> 33.074736 | J30: =SUM(98.8,96)-50-16.6 -> 128.2 | K30: =(G30)*0.0708 -> 124.6788 | L30: =J30-K30 -> 3.5212 | M30: =[3]Apr!AD30 -> 453 | N30: 3 | P30: =(J30-K30)/J30*100 -> 2.7466459 | Q30: =(G30)/(F30/60) -> 234.27938
B31: 45763 | C31: 11 | D31: VITA MALT CLASSIC | E31: 1442 | F31: =[3]Apr!P85 -> 449 | G31: 3062 | H31: =(G31)*24/(F31/60)/17000*100 -> 57.766016 | J31: =SUM(103.1,97.3,16.6) -> 217 | K31: =(G31)*0.0708 -> 216.7896 | L31: =J31-K31 -> 0.2104 | M31: =[3]Apr!AD31 -> 208 | N31: 7 | P31: =(J31-K31)/J31*100 -> 0.096958525 | Q31: =(G31)/(F31/60) -> 409.17595
B32: 45763 | C32: 11 | D32: VITA MALT GINGER | F32: =[3]Apr!P86 -> 97 | G32: 665 | H32: =(G32)*24/(F32/60)/17000*100 -> 58.071559 | J32: 50 | K32: =(G32)*0.0708 -> 47.082 | L32: =J32-K32 -> 2.918 | M32: =[3]Apr!AD32 -> 22 | N32: 1 | P32: =(J32-K32)/J32*100 -> 5.836 | Q32: =(G32)/(F32/60) -> 411.34021
B33: 45763 | C33: 11 | D33: TING ORIGINAL | F33: =[3]Apr!P87 -> 544 | G33: 3498 | H33: =(G33)*24/(F33/60)/17000*100 -> 54.467128 | J33: =K33*1.02 -> 235.48536 | K33: =(G33)*0.066 -> 230.868 | L33: =J33-K33 -> 4.61736 | M33: =[3]Apr!AD33 -> 395 | N33: 6 | P33: =(J33-K33)/J33*100 -> 1.9607843 | Q33: =(G33)/(F33/60) -> 385.80882
B34: 45764 | C34: 12 | D34: CARIB AMBER | E34: 1165 | F34: =[3]Apr!P88 -> 456 | G34: 4165 | H34: =(G34)*24/(F34/60)/17000*100 -> 77.368421 | J34: =SUM(72.3,102.3,103.9) -> 278.5 | K34: =(G34)*0.066 -> 274.89 | L34: =J34-K34 -> 3.61 | M34: =[3]Apr!AD34 -> 248 | N34: 9 | P34: =(J34-K34)/J34*100 -> 1.2962298 | Q34: =(G34)/(F34/60) -> 548.02632
B35: 45764 | C35: 12 | D35: STAG LOCAL | F35: =[3]Apr!P89 -> 519 | G35: 3133 | H35: =(G35)*24/(F35/60)/17000*100 -> 51.133628 | J35: =SUM(96,90,95.7)-65 -> 216.7 | K35: =(G35)*0.066+(30*0.19) -> 212.478 | L35: =J35-K35 -> 4.222 | M35: =[3]Apr!AD35 -> 242 | N35: 10 | O35: 30 | P35: =(J35-K35)/J35*100 -> 1.9483156 | Q35: =(G35)/(F35/60) -> 362.19653
B36: 45769 | C36: 13 | D36: STAG LOCAL | E36: 1440 | F36: =[3]Apr!P90 -> 945 | G36: 299 | H36: =(G36)*24/(F36/60)/17000*100 -> 2.680112 | J36: =65+92.4-66.7-70 -> 20.7 | K36: =(G36)*0.066 -> 19.734 | L36: =J36-K36 -> 0.966 | M36: =[3]Apr!AD36 -> 1401 | N36: 3 | P36: =(J36-K36)/J36*100 -> 4.6666667 | Q36: =(G36)/(F36/60) -> 18.984127
B37: 45770 | C37: 14 | D37: STAG LOCAL | E37: 1440 | F37: =[3]Apr!P91 -> 391 | G37: 2002 | H37: =(G37)*24/(F37/60)/17000*100 -> 43.371145 | J37: =66.7+70 -> 136.7 | K37: =(G37)*0.066 -> 132.132 | L37: =J37-K37 -> 4.568 | M37: =[3]Apr!AD37 -> 979 | N37: =3+31 -> 34 | P37: =(J37-K37)/J37*100 -> 3.341624 | Q37: =(G37)/(F37/60) -> 307.21228
B38: 45770 | C38: 14 | D38: CARIB AMBER | F38: =[3]Apr!P92 -> 167 | G38: 811 | H38: =(G38)*24/(F38/60)/17000*100 -> 41.135611 | J38: =77.3+86.7-9.6-96.9 -> 57.5 | K38: =(G38)*0.066 -> 53.526 | L38: =J38-K38 -> 3.974 | M38: =[3]Apr!AD38 -> 80 | N38: 0 | O38: 70 | P38: =(J38-K38)/J38*100 -> 6.9113043 | Q38: =(G38)/(F38/60) -> 291.37725
B39: 45771 | C39: 15 | D39: CARIB AMBER | E39: 1440 | F39: =[3]Apr!P93 -> 974 | G39: 1561 | H39: =(G39)*24/(F39/60)/17000*100 -> 13.575553 | J39: =9.6+96.9 -> 106.5 | K39: =(G39)*0.066 -> 103.026 | L39: =J39-K39 -> 3.474 | M39: =[3]Apr!AD39 -> 782 | N39: =3+3+2 -> 8 | P39: =(J39-K39)/J39*100 -> 3.2619718 | Q39: =(G39)/(F39/60) -> 96.160164
B40: 45771 | C40: 15 | D40: GUINNESS | F40: =[3]Apr!P94 -> 436 | G40: 2149 | H40: =(G40)*24/(F40/60)/17000*100 -> 41.750675 | J40: =98.8+96.1-15-38 -> 141.9 | K40: =(G40)*0.066 -> 141.834 | L40: =J40-K40 -> 0.066 | M40: =[3]Apr!AD40 -> 160 | N40: 8 | P40: =(J40-K40)/J40*100 -> 0.046511628 | Q40: =(G40)/(F40/60) -> 295.73394
B41: 45772 | C41: 16 | D41: GUINNESS | E41: 1204 | F41: =[3]Apr!P95 -> 127 | G41: 801 | H41: =(G41)*24/(F41/60)/17000*100 -> 53.424734 | J41: =15+38 -> 53 | K41: =(G41)*0.066 -> 52.866 | L41: =J41-K41 -> 0.134 | M41: =[3]Apr!AD41 -> 10 | N41: 9 | P41: =(J41-K41)/J41*100 -> 0.25283019 | Q41: =(G41)/(F41/60) -> 378.4252
...

Sheet May_2025
B1: GRENADA BREWERIES LIMITED
B3: PRODUCTION DEPARTMENT
B4: 45778
B5: DATE | C5: DAY | D5: PRODUCT | E5: AVAIL. | F5: FILL | G5: CASES | H5: Line Rated | I5: Cases on Hold | J5: GROSS | K5: BBT | L5: BOTTLED | M5: Diff BBT Hls vs Hls in Package | N5: DOWNTIME (Mins) | O5: REJECTS (Cases) | P5: KEGS | Q5: BOTTLED | R5: AVERAGE | S5: YTD
E6: TIME | F6: TIME | G6: BOTTLED | H6: Efficiency | J6: EFFICIENCY | K6: HLS | L6: HLS | Q6: LOSS | R6: CASE/HR | S6: Ave Case per hour
F7: Mins | H7: % | J7: %
B8: 45779 | C8: 1 | D8: CARIB AMBER | E8: 1172 | F8: =[3]May!$N71 -> 93 | G8: 502 | H8: =(G8)*24/(F8/60)/17000*100 -> 45.72296 | K8: =SUM(93.6)-60 -> 33.6 | L8: =(G8)*0.066 -> 33.132 | M8: =K8-L8 -> 0.468 | N8: =[3]May!$AD8 -> 118 | O8: 5 | Q8: =(K8-L8)/K8*100 -> 1.3928571 | R8: =(G8)/(F8/60) -> 323.87097
B9: 45779 | C9: 1 | D9: SHANDY LIME (LOCAL) | F9: =[3]May!$N72 -> 273 | G9: 798 | H9: =(G9)*24/(F9/60)/17000*100 -> 24.760181 | K9: 102 | L9: =(G9+G10)*0.066 -> 97.614 | M9: =K9-L9 -> 4.386 | N9: =[3]May!$AD9 -> 94 | O9: 6 | Q9: =(K9-L9)/K9*100 -> 4.3 | R9: =(G9)/(F9/60) -> 175.38462
B10: 45779 | C10: 1 | D10: SHANDY LIME ( EXPORT) | F10: =[3]May!$N73 -> 130 | G10: 681 | H10: =(G10)*24/(F10/60)/17000*100 -> 44.372851 | M10: =K10-L10 -> 0 | N10: =[3]May!$AD10 -> 120 | R10: =(G10)/(F10/60) -> 314.30769
B11: 45782 | C11: 2 | D11: SHANDY GINGER ( LOCAL) | E11: 1160 | F11: =[3]May!$N74 -> 242 | G11: 795 | H11: =(G11+G12)*24/(F11/60)/17000*100 -> 36.892562 | K11: =SUM(103)-27 -> 76 | L11: =(G11+G12)*0.066 -> 69.564 | M11: =K11-L11 -> 6.436 | N11: =[3]May!$AD11 -> 512 | O11: 7 | Q11: =(K11-L11)/K11*100 -> 8.4684211 | R11: =(G11+G12)/(F11/60) -> 261.32231
B12: 45782 | C12: 2 | D12: SHANDY GINGER (EXPORT) | G12: 259 | N12: =[3]May!$AD12 -> 237
B13: 45782 | C13: 2 | D13: SHANDY SORREL ( EXPORT) | F13: =[3]May!$N76 -> 573 | G13: 734 | H13: =(G13+G14)*24/(F13/60)/17000*100 -> 29.314444 | K13: =SUM(89,89)-42 -> 136 | L13: =(G13+G14)*0.066 -> 130.878 | M13: =K13-L13 -> 5.122 | N13: =[3]May!$AD13 -> 271 | O13: =2+7 -> 9 | Q13: =(K13-L13)/K13*100 -> 3.7661765 | R13: =(G13+G14)/(F13/60) -> 207.64398
B14: 45782 | C14: 2 | D14: SHANDY SORREL ( LOCAL) | G14: 1249
B15: 45783 | C15: 3 | D15: SHANDY SORREL (LOCAL) | E15: 1438 | F15: =[3]May!$N78 -> 145 | G15: 634 | H15: =(G15)*24/(F15/60)/17000*100 -> 37.036917 | K15: 42 | L15: =(G15)*0.066 -> 41.844 | M15: =K15-L15 -> 0.156 | N15: =[3]May!$AD15 -> 82 | O15: =1+16 -> 17 | Q15: =(K15-L15)/K15*100 -> 0.37142857 | R15: =(G15)/(F15/60) -> 262.34483
B16: 45783 | C16: 3 | D16: CARIB AMBER | F16: =[3]May!$N79 -> 1031 | G16: 6488 | H16: =(G16)*24/(F16/60)/17000*100 -> 53.30473 | I16: =7+210 -> 217 | K16: =60+99.6+99.3+96.8+84.1 -> 439.8 | L16: =(G16)*0.066 -> 428.208 | M16: =K16-L16 -> 11.592 | N16: =[3]May!$AD16 -> 408 | O16: 17 | Q16: =(K16-L16)/K16*100 -> 2.6357435 | R16: =(G16)/(F16/60) -> 377.57517
B17: 45783 | C17: 3 | D17: SHANDY GINGER (EXPORT) | F17: =[3]May!$N80 -> 79 | G17: 371 | H17: =(G17)*24/(F17/60)/17000*100 -> 39.779598 | K17: 27 | L17: =(G17)*0.066 -> 24.486 | M17: =K17-L17 -> 2.514 | N17: =[3]May!$AD17 -> 76 | Q17: =(K17-L17)/K17*100 -> 9.3111111 | R17: =(G17)/(F17/60) -> 281.77215
B18: 45784 | C18: 4 | D18: STAG LOCAL | E18: 1442 | F18: =[3]May!$N81 -> 1166 | G18: 7121 | H18: =(G18)*24/(F18/60)/17000*100 -> 51.731611 | K18: =99.2+101.1+102+99+75.3 -> 476.6 | L18: =(G18)*0.066 -> 469.986 | M18: =K18-L18 -> 6.614 | N18: =[3]May!$AD18 -> 467 | O18: 24 | Q18: =(K18-L18)/K18*100 -> 1.3877465 | R18: =(G18)/(F18/60) -> 366.43225
B19: 45784 | C19: 4 | D19: STAR MALT | F19: =[3]May!$N82 -> 0 | G19: 0 | H19: =(G19)*24/(F19/60)/17000*100 -> #DIV/0! | K19: 0 | L19: =(G19)*0.066 -> 0 | M19: =K19-L19 -> 0 | N19: =[3]May!$AD19 -> 130 | O19: 0 | Q19: =(K19-L19)/K19*100 -> #DIV/0! | R19: =(G19)/(F19/60) -> #DIV/0! | S19: =((K20+K19)-(L20+L19))/(K20+K19)*100 -> 2.531995
B20: 45785 | C20: 5 | D20: STAR MALT | E20: 1440 | F20: =[3]May!$N83 -> 1003 | G20: 5885 | H20: =(G20)*24/(F20/60)/17000*100 -> 49.700311 | K20: =97+100+107+94.5 -> 398.5 | L20: =(G20)*0.066 -> 388.41 | M20: =K20-L20 -> 10.09 | N20: =[3]May!$AD20 -> 504 | O20: =4+10+13 -> 27 | Q20: =(K20-L20)/K20*100 -> 2.531995 | R20: =(G20)/(F20/60) -> 352.04387
B21: 45785 | C21: 5 | D21: CARIB AMBER | F21: =[3]May!$N84 -> 99 | G21: 370 | H21: =(G21)*24/(F21/60)/17000*100 -> 31.657754 | K21: =99+101.3-88.3-86.5 -> 25.5 | L21: =(G21)*0.066 -> 24.42 | M21: =K21-L21 -> 1.08 | N21: =[3]May!$AD21 -> 134 | O21: =3+1 -> 4 | Q21: =(K21-L21)/K21*100 -> 4.2352941 | R21: =(G21)/(F21/60) -> 224.24242 | S21: =((K22+K21)-(L22+L21))/(K22+K21)*100 -> 2.3918919
B22: 45786 | C22: 6 | D22: CARIB AMBER | E22: 1197 | F22: =[3]May!$N85 -> 956 | G22: 6853 | H22: =(G22)*24/(F22/60)/17000*100 -> 60.72065 | K22: =88.3+86.5+102+92.3+93.8 -> 462.9 | L22: =(G22)*0.066 -> 452.298 | M22: =K22-L22 -> 10.602 | N22: =[3]May!$AD22 -> 142 | O22: =25+37+18 -> 80 | Q22: =(K22-L22)/K22*100 -> 2.2903435 | R22: =(G22)/(F22/60) -> 430.1046
B23: 45786 | C23: 6 | D23: STAG LOCAL | F23: =[3]May!$N86 -> 127 | G23: 1012 | H23: =(G23)*24/(F23/60)/17000*100 -> 67.497916 | K23: =97.6+102.4-60-68 -> 72 | L23: =(G23)*0.066 -> 66.792 | M23: =K23-L23 -> 5.208 | N23: =[3]May!$AD23 -> 42 | O23: 4 | Q23: =(K23-L23)/K23*100 -> 7.2333333 | R23: =(G23)/(F23/60) -> 478.11024
B24: 45789 | C24: 7 | D24: STAG LOCAL | E24: 1380 | F24: =[3]May!$N87 -> 818 | G24: 4674 | H24: =(G24)*24/(F24/60)/17000*100 -> 48.400403 | K24: =60+68+92.3+89 -> 309.3 | L24: =(G24)*0.066 -> 308.484 | M24: =K24-L24 -> 0.816 | N24: =[3]May!$AD24 -> 370 | O24: =4+10+1 -> 15 | Q24: =(K24-L24)/K24*100 -> 0.26382153 | R24: =(G24)/(F24/60) -> 342.83619
B25: 45789 | C25: 7 | D25: CARIB AMBER | F25: =[3]May!$N88 -> 425 | G25: 3131 | H25: =(G25)*24/(F25/60)/17000*100 -> 62.403322 | K25: =99.5+100+100.3+85.4-91.8-81 -> 212.4 | L25: =(G25)*0.066 -> 206.646 | M25: =K25-L25 -> 5.754 | N25: =[3]May!$AD25 -> 100 | O25: =2 -> 2 | Q25: =(K25-L25)/K25*100 -> 2.7090395 | R25: =(G25)/(F25/60) -> 442.02353 | S25: =((K26+K25)-(L26+L25))/(K26+K25)*100 -> 1.5140187
B26: 45790 | C26: 8 | D26: CARIB AMBER | E26: 1440 | F26: =[3]May!$N89 -> 348 | G26: 2617 | H26: =(G26)*24/(F26/60)/17000*100 -> 63.699797 | K26: =91.8+81 -> 172.8 | L26: =(G26)*0.066 -> 172.722 | M26: =K26-L26 -> 0.078 | N26: =[3]May!$AD26 -> 55 | O26: 16 | Q26: =(K26-L26)/K26*100 -> 0.045138889 | R26: =(G26)/(F26/60) -> 451.2069
B27: 45790 | C27: 8 | D27: VITA MALT (CLASSIC) | G27: 0 | H27: =(G27)*24/(F27/60)/17000*100 -> #DIV/0! | K27: 0 | L27: =(G27)*0.066 -> 0 | M27: =K27-L27 -> 0 | N27: =[3]May!$AD27 -> 1078 | O27: 0 | Q27: =(K27-L27)/K27*100 -> #DIV/0! | R27: =(G27)/(F27/60) -> #DIV/0! | S27: =((K28+K27+K29+K30)-(L28+L27+L29+L30))/(K28+K27+K29+K30)*100 -> 3.2112195
B28: 45791 | C28: 9 | D28: VITA MALT (CLASSIC) | E28: 1440 | F28: =[3]May!$N91 -> 550 | G28: 578 | H28: =(G28)*24/(F28/60)/17000*100 -> 8.9018182 | K28: =SUM(99.2)-51.8 -> 47.4 | L28: =(G28)*0.0708 -> 40.9224 | M28: =K28-L28 -> 6.4776 | N28: =[3]May!$AD28 -> 1422 | O28: 22 | Q28: =(K28-L28)/K28*100 -> 13.665823 | R28: =(G28)/(F28/60) -> 63.054545
B29: 45792 | C29: 10 | D29: VITA MALT (CLASSIC) | E29: 1440 | F29: =[3]May!$N92 -> 234 | G29: 1358 | H29: =(G29)*24/(F29/60)/17000*100 -> 49.158371 | K29: =100.6+98-44-58 -> 96.6 | L29: =(G29)*0.0708 -> 96.1464 | M29: =K29-L29 -> 0.4536 | N29: =[3]May!$AD29 -> 1222 | O29: 10 | Q29: =(K29-L29)/K29*100 -> 0.46956522 | R29: =(G29)/(F29/60) -> 348.20513
B30: 45793 | C30: 11 | D30: VITA MALT (CLASSIC) | E30: 1145 | F30: =[3]May!$N93 -> 192 | G30: 1427 | H30: =(G30)*24/(F30/60)/17000*100 -> 62.955882 | K30: =44+58 -> 102 | L30: =(G30)*0.0708 -> 101.0316 | M30: =K30-L30 -> 0.9684 | N30: =[3]May!$AD30 -> 49 | O30: 18 | Q30: =(K30-L30)/K30*100 -> 0.94941176 | R30: =(G30)/(F30/60) -> 445.9375
B31: 45793 | C31: 11 | D31: VITA MALT (GINGER) | F31: =[3]May!$N94 -> 102 | G31: 690 | H31: =(G31)*24/(F31/60)/17000*100 -> 57.301038 | K31: 51.8 | L31: =(G31)*0.0708 -> 48.852 | M31: =K31-L31 -> 2.948 | N31: =[3]May!$AD31 -> 14 | O31: 4 | Q31: =(K31-L31)/K31*100 -> 5.6911197 | R31: =(G31)/(F31/60) -> 405.88235
B32: 45793 | C32: 11 | D32: STAG LOCAL | F32: =[3]May!$N95 -> 725 | G32: 136 | H32: =(G32)*24/(F32/60)/17000*100 -> 1.5889655 | I32: 109 | K32: =97.3+99-94-89 -> 13.3 | L32: =(G32)*0.066 -> 8.976 | M32: =K32-L32 -> 4.324 | N32: =[3]May!$AD32 -> 816 | O32: =9+14 -> 23 | Q32: =(K32-L32)/K32*100 -> 32.511278 | R32: =(G32)/(F32/60) -> 11.255172
B33: 45796 | C33: 12 | D33: STAG LOCAL | E33: 1380 | F33: =[3]May!$N96 -> 847 | G33: 5270 | H33: =(G33)*24/(F33/60)/17000*100 -> 52.70366 | K33: =94+89+100.3+106.5-28 -> 361.8 | L33: =(G33)*0.066 -> 347.82 | M33: =K33-L33 -> 13.98 | N33: =[3]May!$AD33 -> 870 | O33: =25+46 -> 71 | P33: 15 | Q33: =(K33-L33)/K33*100 -> 3.8640133 | R33: =(G33)/(F33/60) -> 373.31759 | S33: =((K34+K33)-(L34+L33))/(K34+K33)*100 -> 3.7429451
B34: 45797 | C34: 13 | D34: STAG LOCAL | E34: 1440 | F34: =[3]May!$N97 -> 51 | G34: 415 | H34: =(G34)*24/(F34/60)/17000*100 -> 68.927336 | K34: 28 | L34: =(G34)*0.066 -> 27.39 | M34: =K34-L34 -> 0.61 | N34: =[3]May!$AD34 -> 21 | O34: 6 | Q34: =(K34-L34)/K34*100 -> 2.1785714 | R34: =(G34)/(F34/60) -> 488.23529
B35: 45797 | C35: 13 | D35: CARIB AMBER | F35: =[3]May!$N98 -> 744 | G35: 5287 | H35: =(G35)*24/(F35/60)/17000*100 -> 60.193548 | K35: =98.4+99.1+98+95+89 -> 479.5 | L35: =(G35+G36)*0.066+(60*0.066) -> 468.93 | M35: =K35-L35 -> 10.57 | N35: =[3]May!$AD35 -> 299 | O35: =3+22 -> 25 | P35: 60 | Q35: =(K35-L35)/K35*100 -> 2.2043796 | R35: =(G35)/(F35/60) -> 426.37097 | S35: =((K37+K35+K39)-(L37+L35+L39))/(K37+K35+K39)*100 -> 2.8512269
B36: 45797 | C36: 13 | D36: CARIB EXPORT | F36: =[3]May!$N99 -> 465 | G36: 1758 | H36: =(G36)*24/(F36/60)/17000*100 -> 32.024288 | N36: =[3]May!$AD36 -> 103 | O36: 28 | R36: =(G36)/(F36/60) -> 226.83871
B37: 45798 | C37: 14 | D37: CARIB EXPORT | E37: 1440 | F37: =[3]May!$N100 -> 481 | G37: 2617 | H37: =(G37)*24/(F37/60)/17000*100 -> 46.08634 | K37: =102.2+95.5+96.4+98+89-25 -> 456.1 | L37: =(G37+G38)*0.066 -> 438.306 | M37: =K37-L37 -> 17.794 | N37: =[3]May!$AD37 -> 97 | O37: 43 | Q37: =(K37-L37)/K37*100 -> 3.9013374 | R37: =(G37)/(F37/60) -> 326.44491
