Workbook
Name ProductList: [1]November15!$R$3:$R$9
Name ProductList: [2]November15!$R$3:$R$9

Sheet Dec 18th
T1: P.G. | V1: Hot Time | X1: Process Time | Z1: Cooling Time
B2: Brewing Department Daily Process Loss Report | T2: Lower | U2: Upper | V2: Lower | W2: Upper | X2: Lower | Y2: Upper | Z2: Lower | AA2: Upper
S3: CARIB | T3: 11.6 | U3: 12 | V3: 0 | W3: 0.11805556 | X3: 0.17361111 | Y3: 0.21180556 | Z3: 0 | AA3: 60 | AC3: HR- PISNER
B4: Date: | C4: 45278 | J4: LOT WORT COLOUR: 3.4 | M4: Filter Sheets (Target 20 days) | S4: STAG | T4: 11.6 | U4: 12 | V4: 0 | W4: 0.11805556 | X4: 0.17361111 | Y4: 0.21180556 | Z4: 0 | AA4: 60
M5: Double | N5: Single | S5: GUINNESS | T5: 17 | U5: 17.5 | V5: 0 | W5: 0.10763889 | X5: 0.19444444 | Y5: 0.23263889 | Z5: 0 | AA5: 60
J6: MALT LOT: Lot 8 | L6: Sheet Day | S6: MACKESON | T6: 13.3 | U6: 13.5 | V6: 0 | W6: 0.12905093 | X6: 0.22222222 | Y6: 0.25347222 | Z6: 0
S7: STARMALT | T7: 17.1 | U7: 17.5 | V7: 0 | W7: 0.13605324 | X7: 0.20833333 | Y7: 0.24305556 | Z7: 0 | AA7: 60
B8: Brand | C8: Brew no. | D8: Kett. Hls | E8: Wort | F8: Cool Time(Mins) | G8: Cast. P.G. (Lab Result) | H8: Cast P.G. (Cellar Operator)-gravity | I8: Extr. Rec (79.1%) | J8: Theor. Extr. (77.5%) | K8: Boil Off /Vol. (4-6%) | L8: Boil Time | M8: Total Hot | N8: Brewing | P8: Comments | Q8: Actual Pilsen Malt | S8: Hurricane Reef | T8: 16.6 | U8: 17 | V8: 0 | W8: 0.12905093 | X8: 0.22222222 | Y8: 0.25347222 | Z8: 0
E9: Meter (Hls) | F9: Target(< 60Mins) | M9: Time | S9: VITAMALT | T9: 14.4 | U9: 14.6 | V9: 0 | W9: 0.13905093 | X9: 0.19097222 | Y9: 0.22569444 | Z9: 0 | AA9: 75
S10: =B10 -> 0 | T10: =VLOOKUP($B10,$S$3:$Y$9,2,FALSE) -> #N/A | U10: =VLOOKUP($B10,$S$3:$Y$9,3,FALSE) -> #N/A | V10: =VLOOKUP($B10,$S$3:$Y$9,4,FALSE) -> #N/A | W10: =VLOOKUP($B10,$S$3:$Y$9,5,FALSE) -> #N/A | X10: =VLOOKUP($B10,$S$3:$Y$9,6,FALSE) -> #N/A | Y10: =VLOOKUP($B10,$S$3:$Y$9,7,FALSE) -> #N/A | Z10: =VLOOKUP($B10,$S$3:$AA$9,8,FALSE) -> #N/A | AA10: =VLOOKUP($B10,$S$3:$AA$9,9,FALSE) -> #N/A
S11: =B11 -> 0 | T11: =VLOOKUP($B11,$S$3:$Y$9,2,FALSE) -> #N/A | U11: =VLOOKUP($B11,$S$3:$Y$9,3,FALSE) -> #N/A | V11: =VLOOKUP($B11,$S$3:$Y$9,4,FALSE) -> #N/A | W11: =VLOOKUP($B11,$S$3:$Y$9,5,FALSE) -> #N/A | X11: =VLOOKUP($B11,$S$3:$Y$9,6,FALSE) -> #N/A | Y11: =VLOOKUP($B11,$S$3:$Y$9,7,FALSE) -> #N/A | Z11: =VLOOKUP($B11,$S$3:$AA$9,8,FALSE) -> #N/A | AA11: =VLOOKUP($B11,$S$3:$AA$9,9,FALSE) -> #N/A
S12: =B12 -> 0 | T12: =VLOOKUP($B12,$S$3:$Y$9,2,FALSE) -> #N/A | U12: =VLOOKUP($B12,$S$3:$Y$9,3,FALSE) -> #N/A | V12: =VLOOKUP($B12,$S$3:$Y$9,4,FALSE) -> #N/A | W12: =VLOOKUP($B12,$S$3:$Y$9,5,FALSE) -> #N/A | X12: =VLOOKUP($B12,$S$3:$Y$9,6,FALSE) -> #N/A | Y12: =VLOOKUP($B12,$S$3:$Y$9,7,FALSE) -> #N/A | Z12: =VLOOKUP($B12,$S$3:$AA$9,8,FALSE) -> #N/A | AA12: =VLOOKUP($B12,$S$3:$AA$9,9,FALSE) -> #N/A
S13: =B13 -> 0 | T13: =VLOOKUP($B13,$S$3:$Y$9,2,FALSE) -> #N/A | U13: =VLOOKUP($B13,$S$3:$Y$9,3,FALSE) -> #N/A | V13: =VLOOKUP($B13,$S$3:$Y$9,4,FALSE) -> #N/A | W13: =VLOOKUP($B13,$S$3:$Y$9,5,FALSE) -> #N/A | X13: =VLOOKUP($B13,$S$3:$Y$9,6,FALSE) -> #N/A | Y13: =VLOOKUP($B13,$S$3:$Y$9,7,FALSE) -> #N/A | Z13: =VLOOKUP($B13,$S$3:$AA$9,8,FALSE) -> #N/A | AA13: =VLOOKUP($B13,$S$3:$AA$9,9,FALSE) -> #N/A
S14: =B14 -> 0 | T14: =VLOOKUP($B14,$S$3:$Y$9,2,FALSE) -> #N/A | U14: =VLOOKUP($B14,$S$3:$Y$9,3,FALSE) -> #N/A | V14: =VLOOKUP($B14,$S$3:$Y$9,4,FALSE) -> #N/A | W14: =VLOOKUP($B14,$S$3:$Y$9,5,FALSE) -> #N/A | X14: =VLOOKUP($B14,$S$3:$Y$9,6,FALSE) -> #N/A | Y14: =VLOOKUP($B14,$S$3:$Y$9,7,FALSE) -> #N/A | Z14: =VLOOKUP($B14,$S$3:$AA$9,8,FALSE) -> #N/A | AA14: =VLOOKUP($B14,$S$3:$AA$9,9,FALSE) -> #N/A
S15: =B15 -> 0 | T15: =VLOOKUP($B15,$S$3:$Y$9,2,FALSE) -> #N/A | U15: =VLOOKUP($B15,$S$3:$Y$9,3,FALSE) -> #N/A | V15: =VLOOKUP($B15,$S$3:$Y$9,4,FALSE) -> #N/A | W15: =VLOOKUP($B15,$S$3:$Y$9,5,FALSE) -> #N/A | X15: =VLOOKUP($B15,$S$3:$Y$9,6,FALSE) -> #N/A | Y15: =VLOOKUP($B15,$S$3:$Y$9,7,FALSE) -> #N/A | Z15: =VLOOKUP($B15,$S$3:$AA$9,8,FALSE) -> #N/A | AA15: =VLOOKUP($B15,$S$3:$AA$9,9,FALSE) -> #N/A
S16: =B16 -> 0 | T16: =VLOOKUP($B16,$S$3:$Y$9,2,FALSE) -> #N/A | U16: =VLOOKUP($B16,$S$3:$Y$9,3,FALSE) -> #N/A | V16: =VLOOKUP($B16,$S$3:$Y$9,4,FALSE) -> #N/A | W16: =VLOOKUP($B16,$S$3:$Y$9,5,FALSE) -> #N/A | X16: =VLOOKUP($B16,$S$3:$Y$9,6,FALSE) -> #N/A | Y16: =VLOOKUP($B16,$S$3:$Y$9,7,FALSE) -> #N/A | Z16: =VLOOKUP($B16,$S$3:$AA$9,8,FALSE) -> #N/A | AA16: =VLOOKUP($B16,$S$3:$AA$9,9,FALSE) -> #N/A
S17: =B17 -> 0 | T17: =VLOOKUP($B17,$S$3:$Y$9,2,FALSE) -> #N/A | U17: =VLOOKUP($B17,$S$3:$Y$9,3,FALSE) -> #N/A | V17: =VLOOKUP($B17,$S$3:$Y$9,4,FALSE) -> #N/A | W17: =VLOOKUP($B17,$S$3:$Y$9,5,FALSE) -> #N/A | X17: =VLOOKUP($B17,$S$3:$Y$9,6,FALSE) -> #N/A | Y17: =VLOOKUP($B17,$S$3:$Y$9,7,FALSE) -> #N/A | Z17: =VLOOKUP($B17,$S$3:$AA$9,8,FALSE) -> #N/A | AA17: =VLOOKUP($B17,$S$3:$AA$9,9,FALSE) -> #N/A
S18: =B18 -> 0 | T18: =VLOOKUP($B18,$S$3:$Y$9,2,FALSE) -> #N/A | U18: =VLOOKUP($B18,$S$3:$Y$9,3,FALSE) -> #N/A | V18: =VLOOKUP($B18,$S$3:$Y$9,4,FALSE) -> #N/A | W18: =VLOOKUP($B18,$S$3:$Y$9,5,FALSE) -> #N/A | X18: =VLOOKUP($B18,$S$3:$Y$9,6,FALSE) -> #N/A | Y18: =VLOOKUP($B18,$S$3:$Y$9,7,FALSE) -> #N/A | Z18: =VLOOKUP($B18,$S$3:$AA$9,8,FALSE) -> #N/A | AA18: =VLOOKUP($B18,$S$3:$AA$9,9,FALSE) -> #N/A
S19: =B19 -> 0 | T19: =VLOOKUP($B19,$S$3:$Y$9,2,FALSE) -> #N/A | U19: =VLOOKUP($B19,$S$3:$Y$9,3,FALSE) -> #N/A | V19: =VLOOKUP($B19,$S$3:$Y$9,4,FALSE) -> #N/A | W19: =VLOOKUP($B19,$S$3:$Y$9,5,FALSE) -> #N/A | X19: =VLOOKUP($B19,$S$3:$Y$9,6,FALSE) -> #N/A | Y19: =VLOOKUP($B19,$S$3:$Y$9,7,FALSE) -> #N/A | Z19: =VLOOKUP($B19,$S$3:$AA$9,8,FALSE) -> #N/A | AA19: =VLOOKUP($B19,$S$3:$AA$9,9,FALSE) -> #N/A
S20: =B20 -> 0 | T20: =VLOOKUP($B20,$S$3:$Y$9,2,FALSE) -> #N/A | U20: =VLOOKUP($B20,$S$3:$Y$9,3,FALSE) -> #N/A | V20: =VLOOKUP($B20,$S$3:$Y$9,4,FALSE) -> #N/A | W20: =VLOOKUP($B20,$S$3:$Y$9,5,FALSE) -> #N/A | X20: =VLOOKUP($B20,$S$3:$Y$9,6,FALSE) -> #N/A | Y20: =VLOOKUP($B20,$S$3:$Y$9,7,FALSE) -> #N/A | Z20: =VLOOKUP($B20,$S$3:$AA$9,8,FALSE) -> #N/A | AA20: =VLOOKUP($B20,$S$3:$AA$9,9,FALSE) -> #N/A
S21: =B21 -> 0 | T21: =VLOOKUP($B21,$S$3:$Y$9,2,FALSE) -> #N/A | U21: =VLOOKUP($B21,$S$3:$Y$9,3,FALSE) -> #N/A | V21: =VLOOKUP($B21,$S$3:$Y$9,4,FALSE) -> #N/A | W21: =VLOOKUP($B21,$S$3:$Y$9,5,FALSE) -> #N/A | X21: =VLOOKUP($B21,$S$3:$Y$9,6,FALSE) -> #N/A | Y21: =VLOOKUP($B21,$S$3:$Y$9,7,FALSE) -> #N/A | Z21: =VLOOKUP($B21,$S$3:$AA$9,8,FALSE) -> #N/A | AA21: =VLOOKUP($B21,$S$3:$AA$9,9,FALSE) -> #N/A
... S47: =B47 -> 0 | T47: =VLOOKUP($B47,$S$3:$Y$9,2,FALSE) -> #N/A | U47: =VLOOKUP($B47,$S$3:$Y$9,3,FALSE) -> #N/A | V47: =VLOOKUP($B47,$S$3:$Y$9,4,FALSE) -> #N/A | W47: =VLOOKUP($B47,$S$3:$Y$9,5,FALSE) -> #N/A | X47: =VLOOKUP($B47,$S$3:$Y$9,6,FALSE) -> #N/A | Y47: =VLOOKUP($B47,$S$3:$Y$9,7,FALSE) -> #N/A | Z47: =VLOOKUP($B47,$S$3:$AA$9,8,FALSE) -> #N/A | AA47: =VLOOKUP($B47,$S$3:$AA$9,9,FALSE) -> #N/A
I48: EXTRACT RECOVERY
B49: BRAND | D49: BBT P.G./ O.G | I49: Brand | J49: Actual | K49: MTD No. of Brews | L49: MTD | M49: YTD | N49: Target
B50: STAG | C50: 11.8 | D50: 11.73 | I50: CARIB | K50: =COUNTA([3]Brewhouse!$A$1596:$A$1619) -> 24 | L50: =AVERAGE([3]Brewhouse!$AU$1529,[3]Brewhouse!$AU$1531:$AU$1594,[3]Brewhouse!$AU$1596:$AU$1619) -> 98.205761 | M50: =AVERAGE([3]Brewhouse!$AU$849:$AU$924,[3]Brewhouse!$AU$926:$AU$971,[3]Brewhouse!$AU$973:$AU$1066,[3]Brewhouse!$AU$1068:$AU$1111,[3]Brewhouse!$AU$1113:$AU$1132,[3]Brewhouse!$AU$1134:$AU$1167,[3]Brewhouse!$AU$1169:$AU$1230,[3]Brewhouse!$AU$1232:$AU$1299,[3]Brewhouse!$AU$1301:$AU$1363,[3]Brewhouse!$AU$1365:$AU$1444,[3]Brewhouse!$AU$1446:$AU$1527,[3]Brewhouse!$AU$1529,[3]Brewhouse!$AU$1531:$AU$1594,[3]Brewhouse!$AU$1596:$AU$1619) -> 98.381806 | N50: 98
C51: 11.9 | I51: STAG | K51: =COUNTA([4]Brewhouse!$A$976:$A$1007) -> 32 | L51: =AVERAGE([4]Brewhouse!$AS$976:$AS$979,[4]Brewhouse!$AS$981:$AS$1007) -> 98.538567 | M51: =AVERAGE([4]Brewhouse!$AS$577:$AS$618,[4]Brewhouse!$AS$620:$AS$651,[4]Brewhouse!$AS$653:$AS$696,[4]Brewhouse!$AS$698:$AS$708,[4]Brewhouse!$AS$710:$AS$733,[4]Brewhouse!$AS$735:$AS$777,[4]Brewhouse!$AS$779:$AS$822,[4]Brewhouse!$AS$824:$AS$863,[4]Brewhouse!$AS$865:$AS$974,[4]Brewhouse!$AS$976:$AS$979,[4]Brewhouse!$AS$981:$AS$1007) -> 98.489671 | N51: 98
I52: GUINNESS | K52: =COUNTA([5]Brewhouse!$A$282:$A$289) -> 8 | L52: =AVERAGE([5]Brewhouse!$AU$269:$AU$279,[5]Brewhouse!$AU$282:$AU$289) -> 96.186177 | M52: =AVERAGE([5]Brewhouse!$AU$161:$AU$176,[5]Brewhouse!$AU$178:$AU$195,[5]Brewhouse!$AU$197:$AU$208,[5]Brewhouse!$AU$210:$AU$221,[5]Brewhouse!$AU$223:$AU$232,[5]Brewhouse!$AU$234:$AU$279,[5]Brewhouse!$AU$282:$AU$289) -> 96.64916 | N52: 98
I53: VITAMALT | K53: =COUNTA([6]Brewhouse!$A$158:$A$163) -> 6 | L53: =AVERAGE([6]Brewhouse!$AU$158:$AU$163) -> 94.60305 | M53: =AVERAGE([6]Brewhouse!$AU$91:$AU$101,[6]Brewhouse!$AU$103:$AU$112,[6]Brewhouse!$AU$114:$AU$123,[6]Brewhouse!$AU$125:$AU$134,[6]Brewhouse!$AU$136:$AU$145,[6]Brewhouse!$AU$147:$AU$156,[6]Brewhouse!$AU$158:$AU$163) -> 96.240014 | N53: 98
I54: MAXIMALT | N54: 98
I55: MACKESON | M55: =AVERAGE([7]Brewhouse!$AT$74:$AT$79) -> 93.959836 | N55: 98
I56: STARMALT | K56: =COUNTA([8]Brewhouse!$A$249:$A$254) -> 6 | L56: =AVERAGE([8]Brewhouse!$AY$249:$AY$254) -> 99.681996 | M56: =AVERAGE([8]Brewhouse!$AY$138:$AY$143,[8]Brewhouse!$AY$145:$AY$153,[8]Brewhouse!$AY$155,[8]Brewhouse!$AY$156:$AY$174,[8]Brewhouse!$AY$176:$AY$185,[8]Brewhouse!$AY$187:$AY$198,[8]Brewhouse!$AY$200:$AY$247,[8]Brewhouse!$AY$249:$AY$254) -> 98.774703 | N56: 98
I57: HR- P | M57: =AVERAGE([9]Brewhouse!$AW$13:$AW$14,[9]Brewhouse!$AW$16:$AW$17) -> 92.042628 | N57: 98
I58: Hurricane Reef | M58: =AVERAGE([9]Brewhouse!$AW$13:$AW$14) -> 88.376943 | N58: 98
K59: =SUM(K50:K58) -> 76 | L59: =((L50*K50)+(L51*K51)+(L52*K52)+(L53*K53)+(L54*K54)+(K57*L57)+(L55*K55)+(L56*K56)+(L58*K58))/(K59) -> 97.965422 | M59: =AVERAGE('[10]Closing- January 2023'!$L$42,'[11]Feb. 28th'!$L$42,'[12]March 31st'!$L$75,'[13]Apri 28th'!$L$51,L59) -> 98.06926 | N59: 98
J62: Daily Brewing Plan
J63: Brand | K63: Brews Achieved | L63: Average Brews per day
J64: CARIB | L64: MTD | M64: YTD | N64: TARGET
J65: STAG | K65: 5 | L65: =AVERAGE(#REF!,#REF!,K74,#REF!,#REF!,#REF!,#REF!,#REF!,#REF!,#REF!,#REF!) -> #REF! | M65: =AVERAGE(6,6,'[12]March 31st'!$L$80,'[14]June 30th '!$L$71,6,L65,'[15]July 31st'!$L$108,'[16]Aug 30th'!$L$124,7,[17]Oct.31st!$L$51) -> #REF! | N65: 9
J66: GUINN
J67: VITAMALT
...

Sheet Jan 2nd
S1: P.G. | U1: Hot Time | W1: Process Time | Y1: Cooling Time
B2: Brewing Department Daily Process Loss Report | S2: Lower | T2: Upper | U2: Lower | V2: Upper | W2: Lower | X2: Upper | Y2: Lower | Z2: Upper
R3: CARIB | S3: 11.6 | T3: 12 | U3: 0 | V3: 0.11805556 | W3: 0.22569444 | X3: 0.26388889 | Y3: 0 | Z3: 60
B4: Date: | C4: 45660 | J4: LOT WORT COLOUR: 3.4 | M4: Filter Sheets (Target 20 days) | R4: STAG | S4: 11.6 | T4: 12 | U4: 0 | V4: 0.11805556 | W4: 0.22569444 | X4: 0.26388889 | Y4: 0 | Z4: 60
M5: Double | N5: Single | R5: GUINNESS | S5: 17 | T5: 17.5 | U5: 0 | V5: 0.10763889 | W5: 0.24652778 | X5: 0.28472222 | Y5: 0 | Z5: 60
J6: MALT LOT: Lot 25 | L6: Sheet Day | R6: MACKESON | S6: 13.3 | T6: 13.5 | U6: 0 | V6: 0.12905093 | W6: 0.27430556 | X6: 0.30208333 | Y6: 0
R7: STARMALT | S7: 17.1 | T7: 17.5 | U7: 0 | V7: 0.13605324 | W7: 0.27430556 | X7: 0.30902778 | Y7: 0 | Z7: 60
B8: Brand | C8: Brew no. | D8: Kett. Hls | E8: Wort | F8: Cool Time(Mins) | G8: Cast. P.G. (Lab Result) | H8: Cast P.G. (Cellar Operator)-gravity | I8: Extr. Rec (80.9%) | J8: Theor. Extr. (77.5%) | K8: Boil Off /Vol. (4-6%) | L8: Boil Time | M8: Total Hot | N8: Brewing | O8: Operator | P8: Comments | R8: Hurricane Reef | S8: 16.6 | T8: 17 | U8: 0 | V8: 0.12905093 | W8: 0.27430556 | X8: 0.30208333 | Y8: 0
E9: Meter (Hls) | F9: Target(< 60Mins) | M9: Time | R9: VITAMALT | S9: 14.4 | T9: 14.6 | U9: 0 | V9: 0.13905093 | W9: 0.26041667 | X9: 0.29513889 | Y9: 0 | Z9: 75
B10: STAG | C10: =[22]Brewhouse!$A15 -> ST001 | D10: =[22]Brewhouse!$AD15 -> 53.3 | E10: =[22]Brewhouse!$AG15 -> 49.8 | F10: =[22]Brewhouse!$V15 -> 71 | G10: =[22]Brewhouse!$AE15 -> 11.6 | H10: 11.7 | I10: =[22]Brewhouse!$AS15 -> 93.952909 | J10: =[22]Brewhouse!$AT15 -> 97.220197 | K10: =[22]Brewhouse!$Q15 -> 5.4945055 | L10: =[22]Brewhouse!$P15 -> 63 | M10: =[22]Brewhouse!$U15-[22]Brewhouse!$T15 -> 0.12013889 | N10: =[22]Brewhouse!$AW15 -> 0.28611111 | O10: =[22]Brewhouse!$AV15 -> k.Benjamin | R10: =B10 -> STAG | S10: =VLOOKUP($B10,$R$3:$X$9,2,FALSE) -> 11.6 | T10: =VLOOKUP($B10,$R$3:$X$9,3,FALSE) -> 12 | U10: =VLOOKUP($B10,$R$3:$X$9,4,FALSE) -> 0 | V10: =VLOOKUP($B10,$R$3:$X$9,5,FALSE) -> 0.11805556 | W10: =VLOOKUP($B10,$R$3:$X$9,6,FALSE) -> 0.22569444 | X10: =VLOOKUP($B10,$R$3:$X$9,7,FALSE) -> 0.26388889 | Y10: =VLOOKUP($B10,$R$3:$Z$9,8,FALSE) -> 0 | Z10: =VLOOKUP($B10,$R$3:$Z$9,9,FALSE) -> 60
B11: STAG | C11: =[22]Brewhouse!$A16 -> ST002 | D11: =[22]Brewhouse!$AD16 -> 53.4 | E11: =[22]Brewhouse!$AG16 -> 50.2 | F11: =[22]Brewhouse!$V16 -> 60 | G11: =[22]Brewhouse!$AE16 -> 11.8 | H11: 11.9 | I11: =[22]Brewhouse!$AS16 -> 96.305388 | J11: =[22]Brewhouse!$AT16 -> 99.655578 | K11: =[22]Brewhouse!$Q16 -> 6.6176471 | L11: =[22]Brewhouse!$P16 -> 60 | M11: =[22]Brewhouse!$U16-[22]Brewhouse!$T16 -> 0.071527778 | N11: =[22]Brewhouse!$AW16 -> 0.21875 | O11: =[22]Brewhouse!$AV16 -> k.Benjamin | R11: =B11 -> STAG | S11: =VLOOKUP($B11,$R$3:$X$9,2,FALSE) -> 11.6 | T11: =VLOOKUP($B11,$R$3:$X$9,3,FALSE) -> 12 | U11: =VLOOKUP($B11,$R$3:$X$9,4,FALSE) -> 0 | V11: =VLOOKUP($B11,$R$3:$X$9,5,FALSE) -> 0.11805556 | W11: =VLOOKUP($B11,$R$3:$X$9,6,FALSE) -> 0.22569444 | X11: =VLOOKUP($B11,$R$3:$X$9,7,FALSE) -> 0.26388889 | Y11: =VLOOKUP($B11,$R$3:$Z$9,8,FALSE) -> 0 | Z11: =VLOOKUP($B11,$R$3:$Z$9,9,FALSE) -> 60
B12: STAG | C12: =[22]Brewhouse!$A17 -> ST003 | D12: =[22]Brewhouse!$AD17 -> 53.8 | E12: =[22]Brewhouse!$AG17 -> 50.6 | F12: =[22]Brewhouse!$V17 -> 56 | G12: =[22]Brewhouse!$AE17 -> 11.8 | H12: 11.8 | I12: =[22]Brewhouse!$AS17 -> 97.317556 | J12: =[22]Brewhouse!$AT17 -> 100.70075 | K12: =[22]Brewhouse!$Q17 -> 5.3604436 | L12: =[22]Brewhouse!$P17 -> 61 | M12: =[22]Brewhouse!$U17-[22]Brewhouse!$T17 -> 0.10972222 | N12: =[22]Brewhouse!$AW17 -> 0.25138889 | O12: =[22]Brewhouse!$AV17 -> R.Regis | R12: =B12 -> STAG | S12: =VLOOKUP($B12,$R$3:$X$9,2,FALSE) -> 11.6 | T12: =VLOOKUP($B12,$R$3:$X$9,3,FALSE) -> 12 | U12: =VLOOKUP($B12,$R$3:$X$9,4,FALSE) -> 0 | V12: =VLOOKUP($B12,$R$3:$X$9,5,FALSE) -> 0.11805556 | W12: =VLOOKUP($B12,$R$3:$X$9,6,FALSE) -> 0.22569444 | X12: =VLOOKUP($B12,$R$3:$X$9,7,FALSE) -> 0.26388889 | Y12: =VLOOKUP($B12,$R$3:$Z$9,8,FALSE) -> 0 | Z12: =VLOOKUP($B12,$R$3:$Z$9,9,FALSE) -> 60
B13: STAG | C13: =[22]Brewhouse!$A18 -> ST004 | D13: =[22]Brewhouse!$AD18 -> 53.5 | E13: =[22]Brewhouse!$AG18 -> 50.3 | F13: =[22]Brewhouse!$V18 -> 63 | G13: =[22]Brewhouse!$AE18 -> 11.8 | H13: 11.8 | I13: =[22]Brewhouse!$AS18 -> 96.740575 | J13: =[22]Brewhouse!$AT18 -> 100.10371 | K13: =[22]Brewhouse!$Q18 -> 6.2615101 | L13: =[22]Brewhouse!$P18 -> 60 | M13: =[22]Brewhouse!$U18-[22]Brewhouse!$T18 -> 0.11597222 | N13: =[22]Brewhouse!$AW18 -> 0.27777778 | O13: =[22]Brewhouse!$AV18 -> R.Regis | R13: =B13 -> STAG | S13: =VLOOKUP($B13,$R$3:$X$9,2,FALSE) -> 11.6 | T13: =VLOOKUP($B13,$R$3:$X$9,3,FALSE) -> 12 | U13: =VLOOKUP($B13,$R$3:$X$9,4,FALSE) -> 0 | V13: =VLOOKUP($B13,$R$3:$X$9,5,FALSE) -> 0.11805556 | W13: =VLOOKUP($B13,$R$3:$X$9,6,FALSE) -> 0.22569444 | X13: =VLOOKUP($B13,$R$3:$X$9,7,FALSE) -> 0.26388889 | Y13: =VLOOKUP($B13,$R$3:$Z$9,8,FALSE) -> 0 | Z13: =VLOOKUP($B13,$R$3:$Z$9,9,FALSE) -> 60
B14: STAG | C14: =[22]Brewhouse!$A19 -> ST005 | D14: =[22]Brewhouse!$AD19 -> 52.5 | E14: =[22]Brewhouse!$AG19 -> 49.3 | F14: =[22]Brewhouse!$V19 -> 59 | G14: =[22]Brewhouse!$AE19 -> 11.9 | I14: =[22]Brewhouse!$AS19 -> 95.662514 | J14: =[22]Brewhouse!$AT19 -> 98.988167 | K14: =[22]Brewhouse!$Q19 -> 5.9369202 | L14: =[22]Brewhouse!$P19 -> 59 | M14: =[22]Brewhouse!$U19-[22]Brewhouse!$T19 -> 0.11111111 | N14: =[22]Brewhouse!$AW19 -> 0.30555556 | O14: =[22]Brewhouse!$AV19 -> R.Sookram | R14: =B14 -> STAG | S14: =VLOOKUP($B14,$R$3:$X$9,2,FALSE) -> 11.6 | T14: =VLOOKUP($B14,$R$3:$X$9,3,FALSE) -> 12 | U14: =VLOOKUP($B14,$R$3:$X$9,4,FALSE) -> 0 | V14: =VLOOKUP($B14,$R$3:$X$9,5,FALSE) -> 0.11805556 | W14: =VLOOKUP($B14,$R$3:$X$9,6,FALSE) -> 0.22569444 | X14: =VLOOKUP($B14,$R$3:$X$9,7,FALSE) -> 0.26388889 | Y14: =VLOOKUP($B14,$R$3:$Z$9,8,FALSE) -> 0 | Z14: =VLOOKUP($B14,$R$3:$Z$9,9,FALSE) -> 60
R15: =B15 -> 0 | S15: =VLOOKUP($B15,$R$3:$X$9,2,FALSE) -> #N/A | T15: =VLOOKUP($B15,$R$3:$X$9,3,FALSE) -> #N/A | U15: =VLOOKUP($B15,$R$3:$X$9,4,FALSE) -> #N/A | V15: =VLOOKUP($B15,$R$3:$X$9,5,FALSE) -> #N/A | W15: =VLOOKUP($B15,$R$3:$X$9,6,FALSE) -> #N/A | X15: =VLOOKUP($B15,$R$3:$X$9,7,FALSE) -> #N/A | Y15: =VLOOKUP($B15,$R$3:$Z$9,8,FALSE) -> #N/A | Z15: =VLOOKUP($B15,$R$3:$Z$9,9,FALSE) -> #N/A
R16: =B16 -> 0 | S16: =VLOOKUP($B16,$R$3:$X$9,2,FALSE) -> #N/A | T16: =VLOOKUP($B16,$R$3:$X$9,3,FALSE) -> #N/A | U16: =VLOOKUP($B16,$R$3:$X$9,4,FALSE) -> #N/A | V16: =VLOOKUP($B16,$R$3:$X$9,5,FALSE) -> #N/A | W16: =VLOOKUP($B16,$R$3:$X$9,6,FALSE) -> #N/A | X16: =VLOOKUP($B16,$R$3:$X$9,7,FALSE) -> #N/A | Y16: =VLOOKUP($B16,$R$3:$Z$9,8,FALSE) -> #N/A | Z16: =VLOOKUP($B16,$R$3:$Z$9,9,FALSE) -> #N/A
R17: =B17 -> 0 | S17: =VLOOKUP($B17,$R$3:$X$9,2,FALSE) -> #N/A | T17: =VLOOKUP($B17,$R$3:$X$9,3,FALSE) -> #N/A | U17: =VLOOKUP($B17,$R$3:$X$9,4,FALSE) -> #N/A | V17: =VLOOKUP($B17,$R$3:$X$9,5,FALSE) -> #N/A | W17: =VLOOKUP($B17,$R$3:$X$9,6,FALSE) -> #N/A | X17: =VLOOKUP($B17,$R$3:$X$9,7,FALSE) -> #N/A | Y17: =VLOOKUP($B17,$R$3:$Z$9,8,FALSE) -> #N/A | Z17: =VLOOKUP($B17,$R$3:$Z$9,9,FALSE) -> #N/A
R18: =B18 -> 0 | S18: =VLOOKUP($B18,$R$3:$X$9,2,FALSE) -> #N/A | T18: =VLOOKUP($B18,$R$3:$X$9,3,FALSE) -> #N/A | U18: =VLOOKUP($B18,$R$3:$X$9,4,FALSE) -> #N/A | V18: =VLOOKUP($B18,$R$3:$X$9,5,FALSE) -> #N/A | W18: =VLOOKUP($B18,$R$3:$X$9,6,FALSE) -> #N/A | X18: =VLOOKUP($B18,$R$3:$X$9,7,FALSE) -> #N/A | Y18: =VLOOKUP($B18,$R$3:$Z$9,8,FALSE) -> #N/A | Z18: =VLOOKUP($B18,$R$3:$Z$9,9,FALSE) -> #N/A
R19: =B19 -> 0 | S19: =VLOOKUP($B19,$R$3:$X$9,2,FALSE) -> #N/A | T19: =VLOOKUP($B19,$R$3:$X$9,3,FALSE) -> #N/A | U19: =VLOOKUP($B19,$R$3:$X$9,4,FALSE) -> #N/A | V19: =VLOOKUP($B19,$R$3:$X$9,5,FALSE) -> #N/A | W19: =VLOOKUP($B19,$R$3:$X$9,6,FALSE) -> #N/A | X19: =VLOOKUP($B19,$R$3:$X$9,7,FALSE) -> #N/A | Y19: =VLOOKUP($B19,$R$3:$Z$9,8,FALSE) -> #N/A | Z19: =VLOOKUP($B19,$R$3:$Z$9,9,FALSE) -> #N/A
R20: =B20 -> 0 | S20: =VLOOKUP($B20,$R$3:$X$9,2,FALSE) -> #N/A | T20: =VLOOKUP($B20,$R$3:$X$9,3,FALSE) -> #N/A | U20: =VLOOKUP($B20,$R$3:$X$9,4,FALSE) -> #N/A | V20: =VLOOKUP($B20,$R$3:$X$9,5,FALSE) -> #N/A | W20: =VLOOKUP($B20,$R$3:$X$9,6,FALSE) -> #N/A | X20: =VLOOKUP($B20,$R$3:$X$9,7,FALSE) -> #N/A | Y20: =VLOOKUP($B20,$R$3:$Z$9,8,FALSE) -> #N/A | Z20: =VLOOKUP($B20,$R$3:$Z$9,9,FALSE) -> #N/A
R21: =B21 -> 0 | S21: =VLOOKUP($B21,$R$3:$X$9,2,FALSE) -> #N/A | T21: =VLOOKUP($B21,$R$3:$X$9,3,FALSE) -> #N/A | U21: =VLOOKUP($B21,$R$3:$X$9,4,FALSE) -> #N/A | V21: =VLOOKUP($B21,$R$3:$X$9,5,FALSE) -> #N/A | W21: =VLOOKUP($B21,$R$3:$X$9,6,FALSE) -> #N/A | X21: =VLOOKUP($B21,$R$3:$X$9,7,FALSE) -> #N/A | Y21: =VLOOKUP($B21,$R$3:$Z$9,8,FALSE) -> #N/A | Z21: =VLOOKUP($B21,$R$3:$Z$9,9,FALSE) -> #N/A
R22: =B22 -> 0 | S22: =VLOOKUP($B22,$R$3:$X$9,2,FALSE) -> #N/A | T22: =VLOOKUP($B22,$R$3:$X$9,3,FALSE) -> #N/A | U22: =VLOOKUP($B22,$R$3:$X$9,4,FALSE) -> #N/A | V22: =VLOOKUP($B22,$R$3:$X$9,5,FALSE) -> #N/A | W22: =VLOOKUP($B22,$R$3:$X$9,6,FALSE) -> #N/A | X22: =VLOOKUP($B22,$R$3:$X$9,7,FALSE) -> #N/A | Y22: =VLOOKUP($B22,$R$3:$Z$9,8,FALSE) -> #N/A | Z22: =VLOOKUP($B22,$R$3:$Z$9,9,FALSE) -> #N/A
R23: =B23 -> 0 | S23: =VLOOKUP($B23,$R$3:$X$9,2,FALSE) -> #N/A | T23: =VLOOKUP($B23,$R$3:$X$9,3,FALSE) -> #N/A | U23: =VLOOKUP($B23,$R$3:$X$9,4,FALSE) -> #N/A | V23: =VLOOKUP($B23,$R$3:$X$9,5,FALSE) -> #N/A | W23: =VLOOKUP($B23,$R$3:$X$9,6,FALSE) -> #N/A | X23: =VLOOKUP($B23,$R$3:$X$9,7,FALSE) -> #N/A | Y23: =VLOOKUP($B23,$R$3:$Z$9,8,FALSE) -> #N/A | Z23: =VLOOKUP($B23,$R$3:$Z$9,9,FALSE) -> #N/A
R24: =B24 -> 0 | S24: =VLOOKUP($B24,$R$3:$X$9,2,FALSE) -> #N/A | T24: =VLOOKUP($B24,$R$3:$X$9,3,FALSE) -> #N/A | U24: =VLOOKUP($B24,$R$3:$X$9,4,FALSE) -> #N/A | V24: =VLOOKUP($B24,$R$3:$X$9,5,FALSE) -> #N/A | W24: =VLOOKUP($B24,$R$3:$X$9,6,FALSE) -> #N/A | X24: =VLOOKUP($B24,$R$3:$X$9,7,FALSE) -> #N/A | Y24: =VLOOKUP($B24,$R$3:$Z$9,8,FALSE) -> #N/A | Z24: =VLOOKUP($B24,$R$3:$Z$9,9,FALSE) -> #N/A
R25: =B25 -> 0 | S25: =VLOOKUP($B25,$R$3:$X$9,2,FALSE) -> #N/A | T25: =VLOOKUP($B25,$R$3:$X$9,3,FALSE) -> #N/A | U25: =VLOOKUP($B25,$R$3:$X$9,4,FALSE) -> #N/A | V25: =VLOOKUP($B25,$R$3:$X$9,5,FALSE) -> #N/A | W25: =VLOOKUP($B25,$R$3:$X$9,6,FALSE) -> #N/A | X25: =VLOOKUP($B25,$R$3:$X$9,7,FALSE) -> #N/A | Y25: =VLOOKUP($B25,$R$3:$Z$9,8,FALSE) -> #N/A | Z25: =VLOOKUP($B25,$R$3:$Z$9,9,FALSE) -> #N/A
R26: =B26 -> 0 | S26: =VLOOKUP($B26,$R$3:$X$9,2,FALSE) -> #N/A | T26: =VLOOKUP($B26,$R$3:$X$9,3,FALSE) -> #N/A | U26: =VLOOKUP($B26,$R$3:$X$9,4,FALSE) -> #N/A | V26: =VLOOKUP($B26,$R$3:$X$9,5,FALSE) -> #N/A | W26: =VLOOKUP($B26,$R$3:$X$9,6,FALSE) -> #N/A | X26: =VLOOKUP($B26,$R$3:$X$9,7,FALSE) -> #N/A | Y26: =VLOOKUP($B26,$R$3:$Z$9,8,FALSE) -> #N/A | Z26: =VLOOKUP($B26,$R$3:$Z$9,9,FALSE) -> #N/A
... R41: =B41 -> 0 | S41: =VLOOKUP($B41,$R$3:$X$9,2,FALSE) -> #N/A | T41: =VLOOKUP($B41,$R$3:$X$9,3,FALSE) -> #N/A | U41: =VLOOKUP($B41,$R$3:$X$9,4,FALSE) -> #N/A | V41: =VLOOKUP($B41,$R$3:$X$9,5,FALSE) -> #N/A | W41: =VLOOKUP($B41,$R$3:$X$9,6,FALSE) -> #N/A | X41: =VLOOKUP($B41,$R$3:$X$9,7,FALSE) -> #N/A | Y41: =VLOOKUP($B41,$R$3:$Z$9,8,FALSE) -> #N/A | Z41: =VLOOKUP($B41,$R$3:$Z$9,9,FALSE) -> #N/A
I42: EXTRACT RECOVERY | R42: =B42 -> 0 | S42: =VLOOKUP($B42,$R$3:$X$9,2,FALSE) -> #N/A | T42: =VLOOKUP($B42,$R$3:$X$9,3,FALSE) -> #N/A | U42: =VLOOKUP($B42,$R$3:$X$9,4,FALSE) -> #N/A | V42: =VLOOKUP($B42,$R$3:$X$9,5,FALSE) -> #N/A | W42: =VLOOKUP($B42,$R$3:$X$9,6,FALSE) -> #N/A | X42: =VLOOKUP($B42,$R$3:$X$9,7,FALSE) -> #N/A | Y42: =VLOOKUP($B42,$R$3:$Z$9,8,FALSE) -> #N/A | Z42: =VLOOKUP($B42,$R$3:$Z$9,9,FALSE) -> #N/A
B43: BRAND | D43: BBT P.G./ O.G | I43: Brand | J43: Actual | K43: MTD No. of Brews | L43: MTD | M43: YTD | N43: Target | R43: =B43 -> BRAND | S43: =VLOOKUP($B43,$R$3:$X$9,2,FALSE) -> #N/A | T43: =VLOOKUP($B43,$R$3:$X$9,3,FALSE) -> #N/A | U43: =VLOOKUP($B43,$R$3:$X$9,4,FALSE) -> #N/A | V43: =VLOOKUP($B43,$R$3:$X$9,5,FALSE) -> #N/A | W43: =VLOOKUP($B43,$R$3:$X$9,6,FALSE) -> #N/A | X43: =VLOOKUP($B43,$R$3:$X$9,7,FALSE) -> #N/A | Y43: =VLOOKUP($B43,$R$3:$Z$9,8,FALSE) -> #N/A | Z43: =VLOOKUP($B43,$R$3:$Z$9,9,FALSE) -> #N/A
B44: =I44 -> CARIB | C44: 12 | D44: 11.79 | I44: CARIB | N44: 98
C45: 11.9 | I45: STAG | J45: =AVERAGE(I10:I14) -> 95.995788 | K45: =COUNTA(C10:C14) -> 5 | L45: =J45 -> 95.995788 | M45: =L45 -> 95.995788 | N45: 98
C46: 11.8 | D46: 11.81 | I46: GUINNESS | N46: 98
C47: 11.9 | I47: VITAMALT | N47: 98
C48: 11.7 | D48: 11.74 | I48: MAXIMALT | N48: 98
C49: 11.8 | I49: MACKESON | N49: 98
C50: 11.8 | D50: 12.03 | I50: STARMALT | N50: 98
C51: 11.8 | I51: HR- P | N51: 98
I52: HR-IPA | N52: 98
I53: HR-APA | N53: 98
K54: =SUM(K44:K53) -> 5 | L54: =((L44*K44)+(L45*K45)+(L46*K46)+(L47*K47)+(L48*K48)+(K51*L51)+(L49*K49)+(L50*K50)+(L53*K53))/(K54) -> 95.995788 | N54: 98
...

Sheet Jan 3rd
S1: P.G. | U1: Hot Time | W1: Process Time | Y1: Cooling Time
B2: Brewing Department Daily Process Loss Report | S2: Lower | T2: Upper | U2: Lower | V2: Upper | W2: Lower | X2: Upper | Y2: Lower | Z2: Upper
R3: CARIB | S3: 11.6 | T3: 12 | U3: 0 | V3: 0.11805556 | W3: 0.22569444 | X3: 0.26388889 | Y3: 0 | Z3: 60
B4: Date: | C4: 45661 | J4: LOT WORT COLOUR: 3.4 | M4: Filter Sheets (Target 20 days) | R4: STAG | S4: 11.6 | T4: 12 | U4: 0 | V4: 0.11805556 | W4: 0.22569444 | X4: 0.26388889 | Y4: 0 | Z4: 60
M5: Double | N5: Single | R5: GUINNESS | S5: 17 | T5: 17.5 | U5: 0 | V5: 0.10763889 | W5: 0.24652778 | X5: 0.28472222 | Y5: 0 | Z5: 60
J6: MALT LOT: Lot 25 | L6: Sheet Day | R6: MACKESON | S6: 13.3 | T6: 13.5 | U6: 0 | V6: 0.12905093 | W6: 0.27430556 | X6: 0.30208333 | Y6: 0
R7: STARMALT | S7: 17.1 | T7: 17.5 | U7: 0 | V7: 0.13605324 | W7: 0.27430556 | X7: 0.30902778 | Y7: 0 | Z7: 60
B8: Brand | C8: Brew no. | D8: Kett. Hls | E8: Wort | F8: Cool Time(Mins) | G8: Cast. P.G. (Lab Result) | H8: Cast P.G. (Cellar Operator)-gravity | I8: Extr. Rec (80.9%) | J8: Theor. Extr. (77.5%) | K8: Boil Off /Vol. (4-6%) | L8: Boil Time | M8: Total Hot | N8: Brewing | O8: Operator | P8: Comments | R8: Hurricane Reef | S8: 16.6 | T8: 17 | U8: 0 | V8: 0.12905093 | W8: 0.27430556 | X8: 0.30208333 | Y8: 0
E9: Meter (Hls) | F9: Target(< 60Mins) | M9: Time | R9: VITAMALT | S9: 14.4 | T9: 14.6 | U9: 0 | V9: 0.13905093 | W9: 0.26041667 | X9: 0.29513889 | Y9: 0 | Z9: 75
R10: =B10 -> 0 | S10: =VLOOKUP($B10,$R$3:$X$9,2,FALSE) -> #N/A | T10: =VLOOKUP($B10,$R$3:$X$9,3,FALSE) -> #N/A | U10: =VLOOKUP($B10,$R$3:$X$9,4,FALSE) -> #N/A | V10: =VLOOKUP($B10,$R$3:$X$9,5,FALSE) -> #N/A | W10: =VLOOKUP($B10,$R$3:$X$9,6,FALSE) -> #N/A | X10: =VLOOKUP($B10,$R$3:$X$9,7,FALSE) -> #N/A | Y10: =VLOOKUP($B10,$R$3:$Z$9,8,FALSE) -> #N/A | Z10: =VLOOKUP($B10,$R$3:$Z$9,9,FALSE) -> #N/A
R11: =B11 -> 0 | S11: =VLOOKUP($B11,$R$3:$X$9,2,FALSE) -> #N/A | T11: =VLOOKUP($B11,$R$3:$X$9,3,FALSE) -> #N/A | U11: =VLOOKUP($B11,$R$3:$X$9,4,FALSE) -> #N/A | V11: =VLOOKUP($B11,$R$3:$X$9,5,FALSE) -> #N/A | W11: =VLOOKUP($B11,$R$3:$X$9,6,FALSE) -> #N/A | X11: =VLOOKUP($B11,$R$3:$X$9,7,FALSE) -> #N/A | Y11: =VLOOKUP($B11,$R$3:$Z$9,8,FALSE) -> #N/A | Z11: =VLOOKUP($B11,$R$3:$Z$9,9,FALSE) -> #N/A
R12: =B12 -> 0 | S12: =VLOOKUP($B12,$R$3:$X$9,2,FALSE) -> #N/A | T12: =VLOOKUP($B12,$R$3:$X$9,3,FALSE) -> #N/A | U12: =VLOOKUP($B12,$R$3:$X$9,4,FALSE) -> #N/A | V12: =VLOOKUP($B12,$R$3:$X$9,5,FALSE) -> #N/A | W12: =VLOOKUP($B12,$R$3:$X$9,6,FALSE) -> #N/A | X12: =VLOOKUP($B12,$R$3:$X$9,7,FALSE) -> #N/A | Y12: =VLOOKUP($B12,$R$3:$Z$9,8,FALSE) -> #N/A | Z12: =VLOOKUP($B12,$R$3:$Z$9,9,FALSE) -> #N/A
R13: =B13 -> 0 | S13: =VLOOKUP($B13,$R$3:$X$9,2,FALSE) -> #N/A | T13: =VLOOKUP($B13,$R$3:$X$9,3,FALSE) -> #N/A | U13: =VLOOKUP($B13,$R$3:$X$9,4,FALSE) -> #N/A | V13: =VLOOKUP($B13,$R$3:$X$9,5,FALSE) -> #N/A | W13: =VLOOKUP($B13,$R$3:$X$9,6,FALSE) -> #N/A | X13: =VLOOKUP($B13,$R$3:$X$9,7,FALSE) -> #N/A | Y13: =VLOOKUP($B13,$R$3:$Z$9,8,FALSE) -> #N/A | Z13: =VLOOKUP($B13,$R$3:$Z$9,9,FALSE) -> #N/A
R14: =B14 -> 0 | S14: =VLOOKUP($B14,$R$3:$X$9,2,FALSE) -> #N/A | T14: =VLOOKUP($B14,$R$3:$X$9,3,FALSE) -> #N/A | U14: =VLOOKUP($B14,$R$3:$X$9,4,FALSE) -> #N/A | V14: =VLOOKUP($B14,$R$3:$X$9,5,FALSE) -> #N/A | W14: =VLOOKUP($B14,$R$3:$X$9,6,FALSE) -> #N/A | X14: =VLOOKUP($B14,$R$3:$X$9,7,FALSE) -> #N/A | Y14: =VLOOKUP($B14,$R$3:$Z$9,8,FALSE) -> #N/A | Z14: =VLOOKUP($B14,$R$3:$Z$9,9,FALSE) -> #N/A
B15: STAG | C15: =[22]Brewhouse!$A20 -> ST006 | D15: =[22]Brewhouse!$AD20 -> 53.4 | E15: =[22]Brewhouse!$AG20 -> 50.7 | F15: =[22]Brewhouse!$V20 -> 63 | G15: =[22]Brewhouse!$AE20 -> 11.7 | I15: =[22]Brewhouse!$AS20 -> 96.762677 | J15: =[22]Brewhouse!$AT20 -> 100.12547 | K15: =[22]Brewhouse!$Q20 -> 4.6915405 | L15: =[22]Brewhouse!$P20 -> 57 | M15: =[22]Brewhouse!$U20-[22]Brewhouse!$T20 -> 0.11041667 | N15: =[22]Brewhouse!$AW20 -> 0.26805556 | O15: =[22]Brewhouse!$AV20 -> R.Sookram | R15: =B15 -> STAG | S15: =VLOOKUP($B15,$R$3:$X$9,2,FALSE) -> 11.6 | T15: =VLOOKUP($B15,$R$3:$X$9,3,FALSE) -> 12 | U15: =VLOOKUP($B15,$R$3:$X$9,4,FALSE) -> 0 | V15: =VLOOKUP($B15,$R$3:$X$9,5,FALSE) -> 0.11805556 | W15: =VLOOKUP($B15,$R$3:$X$9,6,FALSE) -> 0.22569444 | X15: =VLOOKUP($B15,$R$3:$X$9,7,FALSE) -> 0.26388889 | Y15: =VLOOKUP($B15,$R$3:$Z$9,8,FALSE) -> 0 | Z15: =VLOOKUP($B15,$R$3:$Z$9,9,FALSE) -> 60
B16: STAG | C16: =[22]Brewhouse!$A21 -> ST007 | D16: =[22]Brewhouse!$AD21 -> 52.9 | E16: =[22]Brewhouse!$AG21 -> 49 | F16: =[22]Brewhouse!$V21 -> 75 | G16: =[22]Brewhouse!$AE21 -> 11.8 | I16: =[22]Brewhouse!$AS21 -> 94.359297 | J16: =[22]Brewhouse!$AT21 -> 97.63857 | K16: =[22]Brewhouse!$Q21 -> 2.6666667 | L16: =[22]Brewhouse!$P21 -> 62 | M16: =[22]Brewhouse!$U21-[22]Brewhouse!$T21 -> 0.11388889 | N16: =[22]Brewhouse!$AW21 -> 0.30277778 | O16: =[22]Brewhouse!$AV21 -> R.Sookram | R16: =B16 -> STAG | S16: =VLOOKUP($B16,$R$3:$X$9,2,FALSE) -> 11.6 | T16: =VLOOKUP($B16,$R$3:$X$9,3,FALSE) -> 12 | U16: =VLOOKUP($B16,$R$3:$X$9,4,FALSE) -> 0 | V16: =VLOOKUP($B16,$R$3:$X$9,5,FALSE) -> 0.11805556 | W16: =VLOOKUP($B16,$R$3:$X$9,6,FALSE) -> 0.22569444 | X16: =VLOOKUP($B16,$R$3:$X$9,7,FALSE) -> 0.26388889 | Y16: =VLOOKUP($B16,$R$3:$Z$9,8,FALSE) -> 0 | Z16: =VLOOKUP($B16,$R$3:$Z$9,9,FALSE) -> 60
B17: STAG | C17: =[22]Brewhouse!$A22 -> ST008 | D17: =[22]Brewhouse!$AD22 -> 52.1 | E17: =[22]Brewhouse!$AG22 -> 49.8 | F17: =[22]Brewhouse!$V22 -> 72 | G17: =[22]Brewhouse!$AE22 -> 11.8 | I17: =[22]Brewhouse!$AS22 -> 95.899857 | J17: =[22]Brewhouse!$AT22 -> 99.232669 | K17: =[22]Brewhouse!$Q22 -> 5.893186 | L17: =[22]Brewhouse!$P22 -> 63 | M17: =[22]Brewhouse!$U22-[22]Brewhouse!$T22 -> 0.12361111 | N17: =[22]Brewhouse!$AW22 -> 0.28194444 | O17: =[22]Brewhouse!$AV22 -> k.Benjamin | R17: =B17 -> STAG | S17: =VLOOKUP($B17,$R$3:$X$9,2,FALSE) -> 11.6 | T17: =VLOOKUP($B17,$R$3:$X$9,3,FALSE) -> 12 | U17: =VLOOKUP($B17,$R$3:$X$9,4,FALSE) -> 0 | V17: =VLOOKUP($B17,$R$3:$X$9,5,FALSE) -> 0.11805556 | W17: =VLOOKUP($B17,$R$3:$X$9,6,FALSE) -> 0.22569444 | X17: =VLOOKUP($B17,$R$3:$X$9,7,FALSE) -> 0.26388889 | Y17: =VLOOKUP($B17,$R$3:$Z$9,8,FALSE) -> 0 | Z17: =VLOOKUP($B17,$R$3:$Z$9,9,FALSE) -> 60
B18: STAG | C18: =[22]Brewhouse!$A23 -> ST009 | D18: =[22]Brewhouse!$AD23 -> 52.9 | E18: =[22]Brewhouse!$AG23 -> 49.5 | F18: =[22]Brewhouse!$V23 -> 90 | G18: =[22]Brewhouse!$AE23 -> 11.9 | I18: =[22]Brewhouse!$AS23 -> 96.050597 | J18: =[22]Brewhouse!$AT23 -> 99.389742 | K18: =[22]Brewhouse!$Q23 -> 11.460259 | L18: =[22]Brewhouse!$P23 -> 60 | M18: =[22]Brewhouse!$U23-[22]Brewhouse!$T23 -> 0.11944444 | N18: =[22]Brewhouse!$AW23 -> 0.26180556 | O18: =[22]Brewhouse!$AV23 -> k.Benjamin | R18: =B18 -> STAG | S18: =VLOOKUP($B18,$R$3:$X$9,2,FALSE) -> 11.6 | T18: =VLOOKUP($B18,$R$3:$X$9,3,FALSE) -> 12 | U18: =VLOOKUP($B18,$R$3:$X$9,4,FALSE) -> 0 | V18: =VLOOKUP($B18,$R$3:$X$9,5,FALSE) -> 0.11805556 | W18: =VLOOKUP($B18,$R$3:$X$9,6,FALSE) -> 0.22569444 | X18: =VLOOKUP($B18,$R$3:$X$9,7,FALSE) -> 0.26388889 | Y18: =VLOOKUP($B18,$R$3:$Z$9,8,FALSE) -> 0 | Z18: =VLOOKUP($B18,$R$3:$Z$9,9,FALSE) -> 60
B19: STAG | C19: =[22]Brewhouse!$A24 -> ST010 | D19: =[22]Brewhouse!$AD24 -> 52.9 | E19: =[22]Brewhouse!$AG24 -> 49.5 | F19: =[22]Brewhouse!$V24 -> 90 | G19: =[22]Brewhouse!$AE24 -> 11.9 | I19: =[22]Brewhouse!$AS24 -> 96.050597 | J19: =[22]Brewhouse!$AT24 -> 99.389742 | K19: =[22]Brewhouse!$Q24 -> 6.2622309 | L19: =[22]Brewhouse!$P24 -> 60 | M19: =[22]Brewhouse!$U24-[22]Brewhouse!$T24 -> 0.13611111 | N19: =[22]Brewhouse!$AW24 -> 0.30972222 | O19: =[22]Brewhouse!$AV24 -> Regis | R19: =B19 -> STAG | S19: =VLOOKUP($B19,$R$3:$X$9,2,FALSE) -> 11.6 | T19: =VLOOKUP($B19,$R$3:$X$9,3,FALSE) -> 12 | U19: =VLOOKUP($B19,$R$3:$X$9,4,FALSE) -> 0 | V19: =VLOOKUP($B19,$R$3:$X$9,5,FALSE) -> 0.11805556 | W19: =VLOOKUP($B19,$R$3:$X$9,6,FALSE) -> 0.22569444 | X19: =VLOOKUP($B19,$R$3:$X$9,7,FALSE) -> 0.26388889 | Y19: =VLOOKUP($B19,$R$3:$Z$9,8,FALSE) -> 0 | Z19: =VLOOKUP($B19,$R$3:$Z$9,9,FALSE) -> 60
R20: =B20 -> 0 | S20: =VLOOKUP($B20,$R$3:$X$9,2,FALSE) -> #N/A | T20: =VLOOKUP($B20,$R$3:$X$9,3,FALSE) -> #N/A | U20: =VLOOKUP($B20,$R$3:$X$9,4,FALSE) -> #N/A | V20: =VLOOKUP($B20,$R$3:$X$9,5,FALSE) -> #N/A | W20: =VLOOKUP($B20,$R$3:$X$9,6,FALSE) -> #N/A | X20: =VLOOKUP($B20,$R$3:$X$9,7,FALSE) -> #N/A | Y20: =VLOOKUP($B20,$R$3:$Z$9,8,FALSE) -> #N/A | Z20: =VLOOKUP($B20,$R$3:$Z$9,9,FALSE) -> #N/A
R21: =B21 -> 0 | S21: =VLOOKUP($B21,$R$3:$X$9,2,FALSE) -> #N/A | T21: =VLOOKUP($B21,$R$3:$X$9,3,FALSE) -> #N/A | U21: =VLOOKUP($B21,$R$3:$X$9,4,FALSE) -> #N/A | V21: =VLOOKUP($B21,$R$3:$X$9,5,FALSE) -> #N/A | W21: =VLOOKUP($B21,$R$3:$X$9,6,FALSE) -> #N/A | X21: =VLOOKUP($B21,$R$3:$X$9,7,FALSE) -> #N/A | Y21: =VLOOKUP($B21,$R$3:$Z$9,8,FALSE) -> #N/A | Z21: =VLOOKUP($B21,$R$3:$Z$9,9,FALSE) -> #N/A
R22: =B22 -> 0 | S22: =VLOOKUP($B22,$R$3:$X$9,2,FALSE) -> #N/A | T22: =VLOOKUP($B22,$R$3:$X$9,3,FALSE) -> #N/A | U22: =VLOOKUP($B22,$R$3:$X$9,4,FALSE) -> #N/A | V22: =VLOOKUP($B22,$R$3:$X$9,5,FALSE) -> #N/A | W22: =VLOOKUP($B22,$R$3:$X$9,6,FALSE) -> #N/A | X22: =VLOOKUP($B22,$R$3:$X$9,7,FALSE) -> #N/A | Y22: =VLOOKUP($B22,$R$3:$Z$9,8,FALSE) -> #N/A | Z22: =VLOOKUP($B22,$R$3:$Z$9,9,FALSE) -> #N/A
R23: =B23 -> 0 | S23: =VLOOKUP($B23,$R$3:$X$9,2,FALSE) -> #N/A | T23: =VLOOKUP($B23,$R$3:$X$9,3,FALSE) -> #N/A | U23: =VLOOKUP($B23,$R$3:$X$9,4,FALSE) -> #N/A | V23: =VLOOKUP($B23,$R$3:$X$9,5,FALSE) -> #N/A | W23: =VLOOKUP($B23,$R$3:$X$9,6,FALSE) -> #N/A | X23: =VLOOKUP($B23,$R$3:$X$9,7,FALSE) -> #N/A | Y23: =VLOOKUP($B23,$R$3:$Z$9,8,FALSE) -> #N/A | Z23: =VLOOKUP($B23,$R$3:$Z$9,9,FALSE) -> #N/A
R24: =B24 -> 0 | S24: =VLOOKUP($B24,$R$3:$X$9,2,FALSE) -> #N/A | T24: =VLOOKUP($B24,$R$3:$X$9,3,FALSE) -> #N/A | U24: =VLOOKUP($B24,$R$3:$X$9,4,FALSE) -> #N/A | V24: =VLOOKUP($B24,$R$3:$X$9,5,FALSE) -> #N/A | W24: =VLOOKUP($B24,$R$3:$X$9,6,FALSE) -> #N/A | X24: =VLOOKUP($B24,$R$3:$X$9,7,FALSE) -> #N/A | Y24: =VLOOKUP($B24,$R$3:$Z$9,8,FALSE) -> #N/A | Z24: =VLOOKUP($B24,$R$3:$Z$9,9,FALSE) -> #N/A
R25: =B25 -> 0 | S25: =VLOOKUP($B25,$R$3:$X$9,2,FALSE) -> #N/A | T25: =VLOOKUP($B25,$R$3:$X$9,3,FALSE) -> #N/A | U25: =VLOOKUP($B25,$R$3:$X$9,4,FALSE) -> #N/A | V25: =VLOOKUP($B25,$R$3:$X$9,5,FALSE) -> #N/A | W25: =VLOOKUP($B25,$R$3:$X$9,6,FALSE) -> #N/A | X25: =VLOOKUP($B25,$R$3:$X$9,7,FALSE) -> #N/A | Y25: =VLOOKUP($B25,$R$3:$Z$9,8,FALSE) -> #N/A | Z25: =VLOOKUP($B25,$R$3:$Z$9,9,FALSE) -> #N/A
R26: =B26 -> 0 | S26: =VLOOKUP($B26,$R$3:$X$9,2,FALSE) -> #N/A | T26: =VLOOKUP($B26,$R$3:$X$9,3,FALSE) -> #N/A | U26: =VLOOKUP($B26,$R$3:$X$9,4,FALSE) -> #N/A | V26: =VLOOKUP($B26,$R$3:$X$9,5,FALSE) -> #N/A | W26: =VLOOKUP($B26,$R$3:$X$9,6,FALSE) -> #N/A | X26: =VLOOKUP($B26,$R$3:$X$9,7,FALSE) -> #N/A | Y26: =VLOOKUP($B26,$R$3:$Z$9,8,FALSE) -> #N/A | Z26: =VLOOKUP($B26,$R$3:$Z$9,9,FALSE) -> #N/A
R27: =B27 -> 0 | S27: =VLOOKUP($B27,$R$3:$X$9,2,FALSE) -> #N/A | T27: =VLOOKUP($B27,$R$3:$X$9,3,FALSE) -> #N/A | U27: =VLOOKUP($B27,$R$3:$X$9,4,FALSE) -> #N/A | V27: =VLOOKUP($B27,$R$3:$X$9,5,FALSE) -> #N/A | W27: =VLOOKUP($B27,$R$3:$X$9,6,FALSE) -> #N/A | X27: =VLOOKUP($B27,$R$3:$X$9,7,FALSE) -> #N/A | Y27: =VLOOKUP($B27,$R$3:$Z$9,8,FALSE) -> #N/A | Z27: =VLOOKUP($B27,$R$3:$Z$9,9,FALSE) -> #N/A
R28: =B28 -> 0 | S28: =VLOOKUP($B28,$R$3:$X$9,2,FALSE) -> #N/A | T28: =VLOOKUP($B28,$R$3:$X$9,3,FALSE) -> #N/A | U28: =VLOOKUP($B28,$R$3:$X$9,4,FALSE) -> #N/A | V28: =VLOOKUP($B28,$R$3:$X$9,5,FALSE) -> #N/A | W28: =VLOOKUP($B28,$R$3:$X$9,6,FALSE) -> #N/A | X28: =VLOOKUP($B28,$R$3:$X$9,7,FALSE) -> #N/A | Y28: =VLOOKUP($B28,$R$3:$Z$9,8,FALSE) -> #N/A | Z28: =VLOOKUP($B28,$R$3:$Z$9,9,FALSE) -> #N/A
R29: =B29 -> 0 | S29: =VLOOKUP($B29,$R$3:$X$9,2,FALSE) -> #N/A | T29: =VLOOKUP($B29,$R$3:$X$9,3,FALSE) -> #N/A | U29: =VLOOKUP($B29,$R$3:$X$9,4,FALSE) -> #N/A | V29: =VLOOKUP($B29,$R$3:$X$9,5,FALSE) -> #N/A | W29: =VLOOKUP($B29,$R$3:$X$9,6,FALSE) -> #N/A | X29: =VLOOKUP($B29,$R$3:$X$9,7,FALSE) -> #N/A | Y29: =VLOOKUP($B29,$R$3:$Z$9,8,FALSE) -> #N/A | Z29: =VLOOKUP($B29,$R$3:$Z$9,9,FALSE) -> #N/A
R30: =B30 -> 0 | S30: =VLOOKUP($B30,$R$3:$X$9,2,FALSE) -> #N/A | T30: =VLOOKUP($B30,$R$3:$X$9,3,FALSE) -> #N/A | U30: =VLOOKUP($B30,$R$3:$X$9,4,FALSE) -> #N/A | V30: =VLOOKUP($B30,$R$3:$X$9,5,FALSE) -> #N/A | W30: =VLOOKUP($B30,$R$3:$X$9,6,FALSE) -> #N/A | X30: =VLOOKUP($B30,$R$3:$X$9,7,FALSE) -> #N/A | Y30: =VLOOKUP($B30,$R$3:$Z$9,8,FALSE) -> #N/A | Z30: =VLOOKUP($B30,$R$3:$Z$9,9,FALSE) -> #N/A
R31: =B31 -> 0 | S31: =VLOOKUP($B31,$R$3:$X$9,2,FALSE) -> #N/A | T31: =VLOOKUP($B31,$R$3:$X$9,3,FALSE) -> #N/A | U31: =VLOOKUP($B31,$R$3:$X$9,4,FALSE) -> #N/A | V31: =VLOOKUP($B31,$R$3:$X$9,5,FALSE) -> #N/A | W31: =VLOOKUP($B31,$R$3:$X$9,6,FALSE) -> #N/A | X31: =VLOOKUP($B31,$R$3:$X$9,7,FALSE) -> #N/A | Y31: =VLOOKUP($B31,$R$3:$Z$9,8,FALSE) -> #N/A | Z31: =VLOOKUP($B31,$R$3:$Z$9,9,FALSE) -> #N/A
... R41: =B41 -> 0 | S41: =VLOOKUP($B41,$R$3:$X$9,2,FALSE) -> #N/A | T41: =VLOOKUP($B41,$R$3:$X$9,3,FALSE) -> #N/A | U41: =VLOOKUP($B41,$R$3:$X$9,4,FALSE) -> #N/A | V41: =VLOOKUP($B41,$R$3:$X$9,5,FALSE) -> #N/A | W41: =VLOOKUP($B41,$R$3:$X$9,6,FALSE) -> #N/A | X41: =VLOOKUP($B41,$R$3:$X$9,7,FALSE) -> #N/A | Y41: =VLOOKUP($B41,$R$3:$Z$9,8,FALSE) -> #N/A | Z41: =VLOOKUP($B41,$R$3:$Z$9,9,FALSE) -> #N/A
I42: EXTRACT RECOVERY | R42: =B42 -> 0 | S42: =VLOOKUP($B42,$R$3:$X$9,2,FALSE) -> #N/A | T42: =VLOOKUP($B42,$R$3:$X$9,3,FALSE) -> #N/A | U42: =VLOOKUP($B42,$R$3:$X$9,4,FALSE) -> #N/A | V42: =VLOOKUP($B42,$R$3:$X$9,5,FALSE) -> #N/A | W42: =VLOOKUP($B42,$R$3:$X$9,6,FALSE) -> #N/A | X42: =VLOOKUP($B42,$R$3:$X$9,7,FALSE) -> #N/A | Y42: =VLOOKUP($B42,$R$3:$Z$9,8,FALSE) -> #N/A | Z42: =VLOOKUP($B42,$R$3:$Z$9,9,FALSE) -> #N/A
B43: BRAND | D43: BBT P.G./ O.G | I43: Brand | J43: Actual | K43: MTD No. of Brews | L43: MTD | M43: YTD | N43: Target | R43: =B43 -> BRAND | S43: =VLOOKUP($B43,$R$3:$X$9,2,FALSE) -> #N/A | T43: =VLOOKUP($B43,$R$3:$X$9,3,FALSE) -> #N/A | U43: =VLOOKUP($B43,$R$3:$X$9,4,FALSE) -> #N/A | V43: =VLOOKUP($B43,$R$3:$X$9,5,FALSE) -> #N/A | W43: =VLOOKUP($B43,$R$3:$X$9,6,FALSE) -> #N/A | X43: =VLOOKUP($B43,$R$3:$X$9,7,FALSE) -> #N/A | Y43: =VLOOKUP($B43,$R$3:$Z$9,8,FALSE) -> #N/A | Z43: =VLOOKUP($B43,$R$3:$Z$9,9,FALSE) -> #N/A
B44: =I44 -> CARIB | C44: 11.8 | D44: 11.8 | I44: CARIB | N44: 98
C45: 11.8 | I45: STAG | J45: =AVERAGE(I15:I19) -> 95.824605 | K45: 10 | L45: =AVERAGE(I15:I19) -> 95.824605 | M45: =L45 -> 95.824605 | N45: 98
C46: 11.8 | D46: 11.82 | I46: GUINNESS | N46: 98
C47: 11.8 | I47: VITAMALT | N47: 98
I48: MAXIMALT | N48: 98
I49: MACKESON | N49: 98
...

Sheet Jan 6th
S1: P.G. | U1: Hot Time | W1: Process Time | Y1: Cooling Time
B2: Brewing Department Daily Process Loss Report | S2: Lower | T2: Upper | U2: Lower | V2: Upper | W2: Lower | X2: Upper | Y2: Lower | Z2: Upper
R3: CARIB | S3: 11.6 | T3: 12 | U3: 0 | V3: 0.11805556 | W3: 0.22569444 | X3: 0.26388889 | Y3: 0 | Z3: 60
B4: Date: | C4: 45664 | J4: LOT WORT COLOUR: 3.4 | M4: Filter Sheets (Target 20 days) | R4: STAG | S4: 11.6 | T4: 12 | U4: 0 | V4: 0.11805556 | W4: 0.22569444 | X4: 0.26388889 | Y4: 0 | Z4: 60
M5: Double | N5: Single | R5: GUINNESS | S5: 17 | T5: 17.5 | U5: 0 | V5: 0.10763889 | W5: 0.24652778 | X5: 0.28472222 | Y5: 0 | Z5: 60
J6: MALT LOT: Lot 25 | L6: Sheet Day | R6: MACKESON | S6: 13.3 | T6: 13.5 | U6: 0 | V6: 0.12905093 | W6: 0.27430556 | X6: 0.30208333 | Y6: 0
R7: STARMALT | S7: 17.1 | T7: 17.5 | U7: 0 | V7: 0.13605324 | W7: 0.27430556 | X7: 0.30902778 | Y7: 0 | Z7: 60
B8: Brand | C8: Brew no. | D8: Kett. Hls | E8: Wort | F8: Cool Time(Mins) | G8: Cast. P.G. (Lab Result) | H8: Cast P.G. (Cellar Operator)-gravity | I8: Extr. Rec (80.9%) | J8: Theor. Extr. (77.5%) | K8: Boil Off /Vol. (4-6%) | L8: Boil Time | M8: Total Hot | N8: Brewing | O8: Operator | P8: Comments | R8: Hurricane Reef | S8: 16.6 | T8: 17 | U8: 0 | V8: 0.12905093 | W8: 0.27430556 | X8: 0.30208333 | Y8: 0
E9: Meter (Hls) | F9: Target(< 60Mins) | M9: Time | R9: VITAMALT | S9: 14.4 | T9: 14.6 | U9: 0 | V9: 0.13905093 | W9: 0.26041667 | X9: 0.29513889 | Y9: 0 | Z9: 75
B10: VITAMALT | C10: =[25]Brewhouse!A5 -> VM001 | D10: =[25]Brewhouse!AE5 -> 52.6 | E10: =[25]Brewhouse!AJ5 -> 46.9 | F10: =[25]Brewhouse!X5 -> 84 | G10: =[25]Brewhouse!AH5 -> 14.5 | H10: 14.3 | I10: =[25]Brewhouse!AV5 -> 96.276959 | J10: =[25]Brewhouse!AW5 -> 97.112608 | K10: =[25]Brewhouse!S5 -> 6.9581749 | L10: =[25]Brewhouse!R5 -> 57 | M10: =[25]Brewhouse!$W5-[25]Brewhouse!$V5 -> 0.15694444 | N10: =[25]Brewhouse!AB5 -> 0.29652778 | O10: =[25]Brewhouse!$AZ5 -> R.Sookram | R10: =B10 -> VITAMALT | S10: =VLOOKUP($B10,$R$3:$X$9,2,FALSE) -> 14.4 | T10: =VLOOKUP($B10,$R$3:$X$9,3,FALSE) -> 14.6 | U10: =VLOOKUP($B10,$R$3:$X$9,4,FALSE) -> 0 | V10: =VLOOKUP($B10,$R$3:$X$9,5,FALSE) -> 0.13905093 | W10: =VLOOKUP($B10,$R$3:$X$9,6,FALSE) -> 0.26041667 | X10: =VLOOKUP($B10,$R$3:$X$9,7,FALSE) -> 0.29513889 | Y10: =VLOOKUP($B10,$R$3:$Z$9,8,FALSE) -> 0 | Z10: =VLOOKUP($B10,$R$3:$Z$9,9,FALSE) -> 75
B11: VITAMALT | C11: =[25]Brewhouse!A6 -> VM002 | D11: =[25]Brewhouse!AE6 -> 52.2 | E11: =[25]Brewhouse!AJ6 -> 46.4 | F11: =[25]Brewhouse!X6 -> 79 | G11: =[25]Brewhouse!AH6 -> 14.5 | H11: 14.4 | I11: =[25]Brewhouse!AV6 -> 95.250552 | J11: =[25]Brewhouse!AW6 -> 96.077292 | K11: =[25]Brewhouse!S6 -> 6.2452107 | L11: =[25]Brewhouse!R6 -> 60 | M11: =[25]Brewhouse!$W6-[25]Brewhouse!$V6 -> 0.13541667 | N11: =[25]Brewhouse!AB6 -> 0.28611111 | O11: =[25]Brewhouse!$AZ6 -> K. Benjamin | R11: =B11 -> VITAMALT | S11: =VLOOKUP($B11,$R$3:$X$9,2,FALSE) -> 14.4 | T11: =VLOOKUP($B11,$R$3:$X$9,3,FALSE) -> 14.6 | U11: =VLOOKUP($B11,$R$3:$X$9,4,FALSE) -> 0 | V11: =VLOOKUP($B11,$R$3:$X$9,5,FALSE) -> 0.13905093 | W11: =VLOOKUP($B11,$R$3:$X$9,6,FALSE) -> 0.26041667 | X11: =VLOOKUP($B11,$R$3:$X$9,7,FALSE) -> 0.29513889 | Y11: =VLOOKUP($B11,$R$3:$Z$9,8,FALSE) -> 0 | Z11: =VLOOKUP($B11,$R$3:$Z$9,9,FALSE) -> 75
B12: VITAMALT | C12: =[25]Brewhouse!A7 -> VM003 | D12: =[25]Brewhouse!AE7 -> 52.9 | E12: =[25]Brewhouse!AJ7 -> 48 | F12: =[25]Brewhouse!X7 -> 84 | G12: =[25]Brewhouse!AH7 -> 14.5 | H12: 14.5 | I12: =[25]Brewhouse!AV7 -> 98.215857 | J12: =[25]Brewhouse!AW7 -> 99.079155 | K12: =[25]Brewhouse!S7 -> 7.8638941 | L12: =[25]Brewhouse!R7 -> 61 | M12: =[25]Brewhouse!$W7-[25]Brewhouse!$V7 -> 0.13888889 | N12: =[25]Brewhouse!AB7 -> 0.27361111 | O12: =[25]Brewhouse!$AZ7 -> K. Benjamin | R12: =B12 -> VITAMALT | S12: =VLOOKUP($B12,$R$3:$X$9,2,FALSE) -> 14.4 | T12: =VLOOKUP($B12,$R$3:$X$9,3,FALSE) -> 14.6 | U12: =VLOOKUP($B12,$R$3:$X$9,4,FALSE) -> 0 | V12: =VLOOKUP($B12,$R$3:$X$9,5,FALSE) -> 0.13905093 | W12: =VLOOKUP($B12,$R$3:$X$9,6,FALSE) -> 0.26041667 | X12: =VLOOKUP($B12,$R$3:$X$9,7,FALSE) -> 0.29513889 | Y12: =VLOOKUP($B12,$R$3:$Z$9,8,FALSE) -> 0 | Z12: =VLOOKUP($B12,$R$3:$Z$9,9,FALSE) -> 75
B13: VITAMALT | C13: =[25]Brewhouse!A8 -> VM004 | D13: =[25]Brewhouse!AE8 -> 52.3 | E13: =[25]Brewhouse!AJ8 -> 47.1 | F13: =[25]Brewhouse!X8 -> 83 | G13: =[25]Brewhouse!AH8 -> 14.6 | H13: 14.5 | I13: =[25]Brewhouse!AV8 -> 97.065841 | J13: =[25]Brewhouse!AW8 -> 97.91903 | K13: =[25]Brewhouse!S8 -> 6.6156788 | L13: =[25]Brewhouse!R8 -> 62 | M13: =[25]Brewhouse!$W8-[25]Brewhouse!$V8 -> 0.13680556 | N13: =[25]Brewhouse!AB8 -> 0.27430556 | O13: =[25]Brewhouse!$AZ8 -> R. Regis | R13: =B13 -> VITAMALT | S13: =VLOOKUP($B13,$R$3:$X$9,2,FALSE) -> 14.4 | T13: =VLOOKUP($B13,$R$3:$X$9,3,FALSE) -> 14.6 | U13: =VLOOKUP($B13,$R$3:$X$9,4,FALSE) -> 0 | V13: =VLOOKUP($B13,$R$3:$X$9,5,FALSE) -> 0.13905093 | W13: =VLOOKUP($B13,$R$3:$X$9,6,FALSE) -> 0.26041667 | X13: =VLOOKUP($B13,$R$3:$X$9,7,FALSE) -> 0.29513889 | Y13: =VLOOKUP($B13,$R$3:$Z$9,8,FALSE) -> 0 | Z13: =VLOOKUP($B13,$R$3:$Z$9,9,FALSE) -> 75
R14: =B14 -> 0 | S14: =VLOOKUP($B14,$R$3:$X$9,2,FALSE) -> #N/A | T14: =VLOOKUP($B14,$R$3:$X$9,3,FALSE) -> #N/A | U14: =VLOOKUP($B14,$R$3:$X$9,4,FALSE) -> #N/A | V14: =VLOOKUP($B14,$R$3:$X$9,5,FALSE) -> #N/A | W14: =VLOOKUP($B14,$R$3:$X$9,6,FALSE) -> #N/A | X14: =VLOOKUP($B14,$R$3:$X$9,7,FALSE) -> #N/A | Y14: =VLOOKUP($B14,$R$3:$Z$9,8,FALSE) -> #N/A | Z14: =VLOOKUP($B14,$R$3:$Z$9,9,FALSE) -> #N/A
R15: =B15 -> 0 | S15: =VLOOKUP($B15,$R$3:$X$9,2,FALSE) -> #N/A | T15: =VLOOKUP($B15,$R$3:$X$9,3,FALSE) -> #N/A | U15: =VLOOKUP($B15,$R$3:$X$9,4,FALSE) -> #N/A | V15: =VLOOKUP($B15,$R$3:$X$9,5,FALSE) -> #N/A | W15: =VLOOKUP($B15,$R$3:$X$9,6,FALSE) -> #N/A | X15: =VLOOKUP($B15,$R$3:$X$9,7,FALSE) -> #N/A | Y15: =VLOOKUP($B15,$R$3:$Z$9,8,FALSE) -> #N/A | Z15: =VLOOKUP($B15,$R$3:$Z$9,9,FALSE) -> #N/A
R16: =B16 -> 0 | S16: =VLOOKUP($B16,$R$3:$X$9,2,FALSE) -> #N/A | T16: =VLOOKUP($B16,$R$3:$X$9,3,FALSE) -> #N/A | U16: =VLOOKUP($B16,$R$3:$X$9,4,FALSE) -> #N/A | V16: =VLOOKUP($B16,$R$3:$X$9,5,FALSE) -> #N/A | W16: =VLOOKUP($B16,$R$3:$X$9,6,FALSE) -> #N/A | X16: =VLOOKUP($B16,$R$3:$X$9,7,FALSE) -> #N/A | Y16: =VLOOKUP($B16,$R$3:$Z$9,8,FALSE) -> #N/A | Z16: =VLOOKUP($B16,$R$3:$Z$9,9,FALSE) -> #N/A
R17: =B17 -> 0 | S17: =VLOOKUP($B17,$R$3:$X$9,2,FALSE) -> #N/A | T17: =VLOOKUP($B17,$R$3:$X$9,3,FALSE) -> #N/A | U17: =VLOOKUP($B17,$R$3:$X$9,4,FALSE) -> #N/A | V17: =VLOOKUP($B17,$R$3:$X$9,5,FALSE) -> #N/A | W17: =VLOOKUP($B17,$R$3:$X$9,6,FALSE) -> #N/A | X17: =VLOOKUP($B17,$R$3:$X$9,7,FALSE) -> #N/A | Y17: =VLOOKUP($B17,$R$3:$Z$9,8,FALSE) -> #N/A | Z17: =VLOOKUP($B17,$R$3:$Z$9,9,FALSE) -> #N/A
R18: =B18 -> 0 | S18: =VLOOKUP($B18,$R$3:$X$9,2,FALSE) -> #N/A | T18: =VLOOKUP($B18,$R$3:$X$9,3,FALSE) -> #N/A | U18: =VLOOKUP($B18,$R$3:$X$9,4,FALSE) -> #N/A | V18: =VLOOKUP($B18,$R$3:$X$9,5,FALSE) -> #N/A | W18: =VLOOKUP($B18,$R$3:$X$9,6,FALSE) -> #N/A | X18: =VLOOKUP($B18,$R$3:$X$9,7,FALSE) -> #N/A | Y18: =VLOOKUP($B18,$R$3:$Z$9,8,FALSE) -> #N/A | Z18: =VLOOKUP($B18,$R$3:$Z$9,9,FALSE) -> #N/A
R19: =B19 -> 0 | S19: =VLOOKUP($B19,$R$3:$X$9,2,FALSE) -> #N/A | T19: =VLOOKUP($B19,$R$3:$X$9,3,FALSE) -> #N/A | U19: =VLOOKUP($B19,$R$3:$X$9,4,FALSE) -> #N/A | V19: =VLOOKUP($B19,$R$3:$X$9,5,FALSE) -> #N/A | W19: =VLOOKUP($B19,$R$3:$X$9,6,FALSE) -> #N/A | X19: =VLOOKUP($B19,$R$3:$X$9,7,FALSE) -> #N/A | Y19: =VLOOKUP($B19,$R$3:$Z$9,8,FALSE) -> #N/A | Z19: =VLOOKUP($B19,$R$3:$Z$9,9,FALSE) -> #N/A
R20: =B20 -> 0 | S20: =VLOOKUP($B20,$R$3:$X$9,2,FALSE) -> #N/A | T20: =VLOOKUP($B20,$R$3:$X$9,3,FALSE) -> #N/A | U20: =VLOOKUP($B20,$R$3:$X$9,4,FALSE) -> #N/A | V20: =VLOOKUP($B20,$R$3:$X$9,5,FALSE) -> #N/A | W20: =VLOOKUP($B20,$R$3:$X$9,6,FALSE) -> #N/A | X20: =VLOOKUP($B20,$R$3:$X$9,7,FALSE) -> #N/A | Y20: =VLOOKUP($B20,$R$3:$Z$9,8,FALSE) -> #N/A | Z20: =VLOOKUP($B20,$R$3:$Z$9,9,FALSE) -> #N/A
R21: =B21 -> 0 | S21: =VLOOKUP($B21,$R$3:$X$9,2,FALSE) -> #N/A | T21: =VLOOKUP($B21,$R$3:$X$9,3,FALSE) -> #N/A | U21: =VLOOKUP($B21,$R$3:$X$9,4,FALSE) -> #N/A | V21: =VLOOKUP($B21,$R$3:$X$9,5,FALSE) -> #N/A | W21: =VLOOKUP($B21,$R$3:$X$9,6,FALSE) -> #N/A | X21: =VLOOKUP($B21,$R$3:$X$9,7,FALSE) -> #N/A | Y21: =VLOOKUP($B21,$R$3:$Z$9,8,FALSE) -> #N/A | Z21: =VLOOKUP($B21,$R$3:$Z$9,9,FALSE) -> #N/A
R22: =B22 -> 0 | S22: =VLOOKUP($B22,$R$3:$X$9,2,FALSE) -> #N/A | T22: =VLOOKUP($B22,$R$3:$X$9,3,FALSE) -> #N/A | U22: =VLOOKUP($B22,$R$3:$X$9,4,FALSE) -> #N/A | V22: =VLOOKUP($B22,$R$3:$X$9,5,FALSE) -> #N/A | W22: =VLOOKUP($B22,$R$3:$X$9,6,FALSE) -> #N/A | X22: =VLOOKUP($B22,$R$3:$X$9,7,FALSE) -> #N/A | Y22: =VLOOKUP($B22,$R$3:$Z$9,8,FALSE) -> #N/A | Z22: =VLOOKUP($B22,$R$3:$Z$9,9,FALSE) -> #N/A
R23: =B23 -> 0 | S23: =VLOOKUP($B23,$R$3:$X$9,2,FALSE) -> #N/A | T23: =VLOOKUP($B23,$R$3:$X$9,3,FALSE) -> #N/A | U23: =VLOOKUP($B23,$R$3:$X$9,4,FALSE) -> #N/A | V23: =VLOOKUP($B23,$R$3:$X$9,5,FALSE) -> #N/A | W23: =VLOOKUP($B23,$R$3:$X$9,6,FALSE) -> #N/A | X23: =VLOOKUP($B23,$R$3:$X$9,7,FALSE) -> #N/A | Y23: =VLOOKUP($B23,$R$3:$Z$9,8,FALSE) -> #N/A | Z23: =VLOOKUP($B23,$R$3:$Z$9,9,FALSE) -> #N/A
R24: =B24 -> 0 | S24: =VLOOKUP($B24,$R$3:$X$9,2,FALSE) -> #N/A | T24: =VLOOKUP($B24,$R$3:$X$9,3,FALSE) -> #N/A | U24: =VLOOKUP($B24,$R$3:$X$9,4,FALSE) -> #N/A | V24: =VLOOKUP($B24,$R$3:$X$9,5,FALSE) -> #N/A | W24: =VLOOKUP($B24,$R$3:$X$9,6,FALSE) -> #N/A | X24: =VLOOKUP($B24,$R$3:$X$9,7,FALSE) -> #N/A | Y24: =VLOOKUP($B24,$R$3:$Z$9,8,FALSE) -> #N/A | Z24: =VLOOKUP($B24,$R$3:$Z$9,9,FALSE) -> #N/A
R25: =B25 -> 0 | S25: =VLOOKUP($B25,$R$3:$X$9,2,FALSE) -> #N/A | T25: =VLOOKUP($B25,$R$3:$X$9,3,FALSE) -> #N/A | U25: =VLOOKUP($B25,$R$3:$X$9,4,FALSE) -> #N/A | V25: =VLOOKUP($B25,$R$3:$X$9,5,FALSE) -> #N/A | W25: =VLOOKUP($B25,$R$3:$X$9,6,FALSE) -> #N/A | X25: =VLOOKUP($B25,$R$3:$X$9,7,FALSE) -> #N/A | Y25: =VLOOKUP($B25,$R$3:$Z$9,8,FALSE) -> #N/A | Z25: =VLOOKUP($B25,$R$3:$Z$9,9,FALSE) -> #N/A
R26: =B26 -> 0 | S26: =VLOOKUP($B26,$R$3:$X$9,2,FALSE) -> #N/A | T26: =VLOOKUP($B26,$R$3:$X$9,3,FALSE) -> #N/A | U26: =VLOOKUP($B26,$R$3:$X$9,4,FALSE) -> #N/A | V26: =VLOOKUP($B26,$R$3:$X$9,5,FALSE) -> #N/A | W26: =VLOOKUP($B26,$R$3:$X$9,6,FALSE) -> #N/A | X26: =VLOOKUP($B26,$R$3:$X$9,7,FALSE) -> #N/A | Y26: =VLOOKUP($B26,$R$3:$Z$9,8,FALSE) -> #N/A | Z26: =VLOOKUP($B26,$R$3:$Z$9,9,FALSE) -> #N/A
I27: EXTRACT RECOVERY | R27: =B27 -> 0 | S27: =VLOOKUP($B27,$R$3:$X$9,2,FALSE) -> #N/A | T27: =VLOOKUP($B27,$R$3:$X$9,3,FALSE) -> #N/A | U27: =VLOOKUP($B27,$R$3:$X$9,4,FALSE) -> #N/A | V27: =VLOOKUP($B27,$R$3:$X$9,5,FALSE) -> #N/A | W27: =VLOOKUP($B27,$R$3:$X$9,6,FALSE) -> #N/A | X27: =VLOOKUP($B27,$R$3:$X$9,7,FALSE) -> #N/A | Y27: =VLOOKUP($B27,$R$3:$Z$9,8,FALSE) -> #N/A | Z27: =VLOOKUP($B27,$R$3:$Z$9,9,FALSE) -> #N/A
B28: BRAND | D28: BBT P.G./ O.G | I28: Brand | J28: Actual | K28: MTD No. of Brews | L28: MTD | M28: YTD | N28: Target | R28: =B28 -> BRAND | S28: =VLOOKUP($B28,$R$3:$X$9,2,FALSE) -> #N/A | T28: =VLOOKUP($B28,$R$3:$X$9,3,FALSE) -> #N/A | U28: =VLOOKUP($B28,$R$3:$X$9,4,FALSE) -> #N/A | V28: =VLOOKUP($B28,$R$3:$X$9,5,FALSE) -> #N/A | W28: =VLOOKUP($B28,$R$3:$X$9,6,FALSE) -> #N/A | X28: =VLOOKUP($B28,$R$3:$X$9,7,FALSE) -> #N/A | Y28: =VLOOKUP($B28,$R$3:$Z$9,8,FALSE) -> #N/A | Z28: =VLOOKUP($B28,$R$3:$Z$9,9,FALSE) -> #N/A
B29: =I30 -> STAG | C29: 12.04 | D29: 11.87 | I29: CARIB | N29: 98
C30: 11.87 | I30: STAG | K30: 10 | L30: 95.824605 | M30: 95.824605 | N30: 98
C31: 11.71 | D31: 11.9 | I31: GUINNESS | N31: 98
C32: 11.79 | I32: VITAMALT | J32: =AVERAGE(I10:I13) -> 96.702302 | K32: 4 | L32: =J32 -> 96.702302 | M32: =L32 -> 96.702302 | N32: 98
C33: 11.9 | D33: 11.81 | I33: MAXIMALT | N33: 98
C34: 11.6 | I34: MACKESON | N34: 98
C35: 11.87 | D35: 11.88 | I35: STARMALT | N35: 98
C36: 11.82 | I36: HR- P | N36: 98
I37: HR-IPA | N37: 98
I38: HR-APA | N38: 98
K39: =SUM(K29:K38) -> 14 | L39: =((L29*K29)+(L30*K30)+(L31*K31)+(L32*K32)+(L33*K33)+(K36*L36)+(L34*K34)+(L35*K35)+(L38*K38))/(K39) -> 96.075376 | M39: =L39 -> 96.075376 | N39: 98
B42: =I29 -> CARIB | C42: 11.6 | D42: 11.8 | J42: Daily Brewing Plan
...

Sheet Jan 7th
S1: P.G. | U1: Hot Time | W1: Process Time | Y1: Cooling Time
B2: Brewing Department Daily Process Loss Report | S2: Lower | T2: Upper | U2: Lower | V2: Upper | W2: Lower | X2: Upper | Y2: Lower | Z2: Upper
R3: CARIB | S3: 11.6 | T3: 12 | U3: 0 | V3: 0.11805556 | W3: 0.22569444 | X3: 0.26388889 | Y3: 0 | Z3: 60
B4: Date: | C4: 45665 | J4: LOT WORT COLOUR: 3.4 | M4: Filter Sheets (Target 20 days) | R4: STAG | S4: 11.6 | T4: 12 | U4: 0 | V4: 0.11805556 | W4: 0.22569444 | X4: 0.26388889 | Y4: 0 | Z4: 60
M5: Double | N5: Single | R5: GUINNESS | S5: 17 | T5: 17.5 | U5: 0 | V5: 0.10763889 | W5: 0.24652778 | X5: 0.28472222 | Y5: 0 | Z5: 60
J6: MALT LOT: Lot 25 | L6: Sheet Day | R6: MACKESON | S6: 13.3 | T6: 13.5 | U6: 0 | V6: 0.12905093 | W6: 0.27430556 | X6: 0.30208333 | Y6: 0
R7: STARMALT | S7: 17.1 | T7: 17.5 | U7: 0 | V7: 0.13605324 | W7: 0.27430556 | X7: 0.30902778 | Y7: 0 | Z7: 60
R8: HR-PILSNER | S8: 10.9 | T8: 11.3 | U8: 0 | V8: 0.12905093 | W8: 0.22569444 | X8: 0.26388889 | Y8: 0 | Z8: 60
R9: HR- IPA
B10: Brand | C10: Brew no. | D10: Kett. Hls | E10: Wort | F10: Cool Time(Mins) | G10: Cast. P.G. (Lab Result) | H10: Cast P.G. (Cellar Operator)-gravity | I10: Extr. Rec (80.9%) | J10: Theor. Extr. (77.5%) | K10: Boil Off /Vol. (4-6%) | L10: Boil Time | M10: Total Hot | N10: Brewing | O10: Operator | P10: Comments | R10: HR- APA | S10: 16.6 | T10: 17 | U10: 0 | V10: 0.12905093 | W10: 0.27430556 | X10: 0.30208333 | Y10: 0
E11: Meter (Hls) | F11: Target(< 60Mins) | M11: Time | R11: VITAMALT | S11: 14.4 | T11: 14.6 | U11: 0 | V11: 0.13905093 | W11: 0.26041667 | X11: 0.29513889 | Y11: 0 | Z11: 75
B12: STAG | C12: ST011 | D12: 53 | E12: 49 | F12: 54 | G12: 11.72 | H12: 11.6 | I12: 93.400254 | J12: 96.647261 | K12: 4.9056604 | L12: 62 | M12: 0.11041667 | N12: 0.24791667 | O12: Regis | R12: =B12 -> STAG | S12: =VLOOKUP($B12,$R$3:$X$11,2,FALSE) -> 11.6 | T12: =VLOOKUP($B12,$R$3:$X$11,3,FALSE) -> 12 | U12: =VLOOKUP($B12,$R$3:$X$11,4,FALSE) -> 0 | V12: =VLOOKUP($B12,$R$3:$X$11,5,FALSE) -> 0.11805556 | W12: =VLOOKUP($B12,$R$3:$X$11,6,FALSE) -> 0.22569444 | X12: =VLOOKUP($B12,$R$3:$X$11,7,FALSE) -> 0.26388889 | Y12: =VLOOKUP($B12,$R$3:$Z$11,8,FALSE) -> 0 | Z12: =VLOOKUP($B12,$R$3:$Z$11,9,FALSE) -> 60
B13: STAG | C13: ST012 | D13: 53.7 | E13: 50.2 | F13: 65 | G13: 11.8 | H13: 11.8 | I13: 96.426665 | J13: 99.77998 | K13: 6.8014706 | L13: 60 | M13: 0.11527778 | N13: 0.26111111 | O13: Regis | R13: =B13 -> STAG | S13: =VLOOKUP($B13,$R$3:$X$11,2,FALSE) -> 11.6 | T13: =VLOOKUP($B13,$R$3:$X$11,3,FALSE) -> 12 | U13: =VLOOKUP($B13,$R$3:$X$11,4,FALSE) -> 0 | V13: =VLOOKUP($B13,$R$3:$X$11,5,FALSE) -> 0.11805556 | W13: =VLOOKUP($B13,$R$3:$X$11,6,FALSE) -> 0.22569444 | X13: =VLOOKUP($B13,$R$3:$X$11,7,FALSE) -> 0.26388889 | Y13: =VLOOKUP($B13,$R$3:$Z$11,8,FALSE) -> 0 | Z13: =VLOOKUP($B13,$R$3:$Z$11,9,FALSE) -> 60
B14: STAG | C14: ST013 | D14: 53.9 | E14: 50.6 | F14: 61 | G14: 11.7 | H14: 11.7 | I14: 96.328599 | J14: 99.678503 | K14: 5.9149723 | L14: 58 | M14: 0.11111111 | N14: 0.27013889 | O14: R.Sookram | R14: =B14 -> STAG | S14: =VLOOKUP($B14,$R$3:$X$11,2,FALSE) -> 11.6 | T14: =VLOOKUP($B14,$R$3:$X$11,3,FALSE) -> 12 | U14: =VLOOKUP($B14,$R$3:$X$11,4,FALSE) -> 0 | V14: =VLOOKUP($B14,$R$3:$X$11,5,FALSE) -> 0.11805556 | W14: =VLOOKUP($B14,$R$3:$X$11,6,FALSE) -> 0.22569444 | X14: =VLOOKUP($B14,$R$3:$X$11,7,FALSE) -> 0.26388889 | Y14: =VLOOKUP($B14,$R$3:$Z$11,8,FALSE) -> 0 | Z14: =VLOOKUP($B14,$R$3:$Z$11,9,FALSE) -> 60
B15: STAG | C15: ST014 | D15: 53.4 | E15: 50.3 | F15: 68 | G15: 11.9 | H15: 11.9 | I15: 97.60293 | J15: 100.99604 | K15: 3.9399625 | L15: 58 | M15: 0.1125 | N15: 0.27222222 | O15: R.Sookram | R15: =B15 -> STAG | S15: =VLOOKUP($B15,$R$3:$X$11,2,FALSE) -> 11.6 | T15: =VLOOKUP($B15,$R$3:$X$11,3,FALSE) -> 12 | U15: =VLOOKUP($B15,$R$3:$X$11,4,FALSE) -> 0 | V15: =VLOOKUP($B15,$R$3:$X$11,5,FALSE) -> 0.11805556 | W15: =VLOOKUP($B15,$R$3:$X$11,6,FALSE) -> 0.22569444 | X15: =VLOOKUP($B15,$R$3:$X$11,7,FALSE) -> 0.26388889 | Y15: =VLOOKUP($B15,$R$3:$Z$11,8,FALSE) -> 0 | Z15: =VLOOKUP($B15,$R$3:$Z$11,9,FALSE) -> 60
R16: =B16 -> 0 | S16: =VLOOKUP($B16,$R$3:$X$11,2,FALSE) -> #N/A | T16: =VLOOKUP($B16,$R$3:$X$11,3,FALSE) -> #N/A | U16: =VLOOKUP($B16,$R$3:$X$11,4,FALSE) -> #N/A | V16: =VLOOKUP($B16,$R$3:$X$11,5,FALSE) -> #N/A | W16: =VLOOKUP($B16,$R$3:$X$11,6,FALSE) -> #N/A | X16: =VLOOKUP($B16,$R$3:$X$11,7,FALSE) -> #N/A | Y16: =VLOOKUP($B16,$R$3:$Z$11,8,FALSE) -> #N/A | Z16: =VLOOKUP($B16,$R$3:$Z$11,9,FALSE) -> #N/A
B17: HR-PILSNER | C17: =[26]Brewhouse!$A5 -> HP001 | D17: =[26]Brewhouse!$AF5 -> 55.5 | E17: =[26]Brewhouse!$AI5 -> 50.1 | F17: =[26]Brewhouse!$V5 -> 59 | G17: =[26]Brewhouse!$AG5 -> 11.7 | H17: 11.3 | I17: =[26]Brewhouse!$AU5 -> 92.965702 | J17: =[26]Brewhouse!$AV5 -> 96.837223 | K17: =[26]Brewhouse!$Q5 -> 6.0805861 | L17: =[26]Brewhouse!$P5 -> 60 | M17: =[26]Brewhouse!$U5-[26]Brewhouse!$T5 -> 0.10833333 | N17: =[26]Brewhouse!$Y5 -> 0.20694444 | O17: =[26]Brewhouse!$AW5 -> R.Sookram | R17: =B17 -> HR-PILSNER | S17: =VLOOKUP($B17,$R$3:$X$11,2,FALSE) -> 10.9 | T17: =VLOOKUP($B17,$R$3:$X$11,3,FALSE) -> 11.3 | U17: =VLOOKUP($B17,$R$3:$X$11,4,FALSE) -> 0 | V17: =VLOOKUP($B17,$R$3:$X$11,5,FALSE) -> 0.12905093 | W17: =VLOOKUP($B17,$R$3:$X$11,6,FALSE) -> 0.22569444 | X17: =VLOOKUP($B17,$R$3:$X$11,7,FALSE) -> 0.26388889 | Y17: =VLOOKUP($B17,$R$3:$Z$11,8,FALSE) -> 0 | Z17: =VLOOKUP($B17,$R$3:$Z$11,9,FALSE) -> 60
B18: HR-PILSNER | C18: =[26]Brewhouse!$A6 -> HP002 | D18: =[26]Brewhouse!$AF6 -> 54.8 | E18: =[26]Brewhouse!$AI6 -> 50.6 | F18: =[26]Brewhouse!$V6 -> 61 | G18: =[26]Brewhouse!$AG6 -> 11.6 | H18: 11.4 | I18: =[26]Brewhouse!$AU6 -> 93.049 | J18: =[26]Brewhouse!$AV6 -> 96.923989 | K18: =[26]Brewhouse!$Q6 -> 7.0899471 | L18: =[26]Brewhouse!$P6 -> 60 | M18: =[26]Brewhouse!$U6-[26]Brewhouse!$T6 -> 0.11180556 | N18: =[26]Brewhouse!$Y6 -> 0.20694444 | O18: =[26]Brewhouse!$AW6 -> K.Benjamin | R18: =B18 -> HR-PILSNER | S18: =VLOOKUP($B18,$R$3:$X$11,2,FALSE) -> 10.9 | T18: =VLOOKUP($B18,$R$3:$X$11,3,FALSE) -> 11.3 | U18: =VLOOKUP($B18,$R$3:$X$11,4,FALSE) -> 0 | V18: =VLOOKUP($B18,$R$3:$X$11,5,FALSE) -> 0.12905093 | W18: =VLOOKUP($B18,$R$3:$X$11,6,FALSE) -> 0.22569444 | X18: =VLOOKUP($B18,$R$3:$X$11,7,FALSE) -> 0.26388889 | Y18: =VLOOKUP($B18,$R$3:$Z$11,8,FALSE) -> 0 | Z18: =VLOOKUP($B18,$R$3:$Z$11,9,FALSE) -> 60
B19: HR-PILSNER | C19: =[26]Brewhouse!$A7 -> HP003 | D19: =[26]Brewhouse!$AF7 -> 58.1 | E19: =[26]Brewhouse!$AI7 -> 48.5 | F19: =[26]Brewhouse!$V7 -> 65 | G19: =[26]Brewhouse!$AG7 -> 11.12 | H19: 11.1 | I19: =[26]Brewhouse!$AU7 -> 84.477723 | J19: =[26]Brewhouse!$AV7 -> 87.995764 | K19: =[26]Brewhouse!$Q7 -> 6.3844797 | L19: =[26]Brewhouse!$P7 -> 60 | M19: =[26]Brewhouse!$U7-[26]Brewhouse!$T7 -> 0.11458333 | N19: =[26]Brewhouse!$Y7 -> 0.20277778 | O19: =[26]Brewhouse!$AW7 -> K.Benjamin | R19: =B19 -> HR-PILSNER | S19: =VLOOKUP($B19,$R$3:$X$11,2,FALSE) -> 10.9 | T19: =VLOOKUP($B19,$R$3:$X$11,3,FALSE) -> 11.3 | U19: =VLOOKUP($B19,$R$3:$X$11,4,FALSE) -> 0 | V19: =VLOOKUP($B19,$R$3:$X$11,5,FALSE) -> 0.12905093 | W19: =VLOOKUP($B19,$R$3:$X$11,6,FALSE) -> 0.22569444 | X19: =VLOOKUP($B19,$R$3:$X$11,7,FALSE) -> 0.26388889 | Y19: =VLOOKUP($B19,$R$3:$Z$11,8,FALSE) -> 0 | Z19: =VLOOKUP($B19,$R$3:$Z$11,9,FALSE) -> 60
B20: HR-PILSNER | C20: =[26]Brewhouse!$A8 -> HP004 | D20: =[26]Brewhouse!$AF8 -> 58.1 | E20: =[26]Brewhouse!$AI8 -> 53.7 | F20: =[26]Brewhouse!$V8 -> 65 | G20: =[26]Brewhouse!$AG8 -> 11.1 | H20: 11.2 | I20: =[26]Brewhouse!$AU8 -> 93.535128 | J20: =[26]Brewhouse!$AV8 -> 97.430362 | K20: =[26]Brewhouse!$Q8 -> 6.8214286 | L20: =[26]Brewhouse!$P8 -> 60 | M20: =[26]Brewhouse!$U8-[26]Brewhouse!$T8 -> 0.070138889 | N20: =[26]Brewhouse!$Y8 -> 0.21875 | O20: =[26]Brewhouse!$AW8 -> K.Benjamin | R20: =B20 -> HR-PILSNER | S20: =VLOOKUP($B20,$R$3:$X$11,2,FALSE) -> 10.9 | T20: =VLOOKUP($B20,$R$3:$X$11,3,FALSE) -> 11.3 | U20: =VLOOKUP($B20,$R$3:$X$11,4,FALSE) -> 0 | V20: =VLOOKUP($B20,$R$3:$X$11,5,FALSE) -> 0.12905093 | W20: =VLOOKUP($B20,$R$3:$X$11,6,FALSE) -> 0.22569444 | X20: =VLOOKUP($B20,$R$3:$X$11,7,FALSE) -> 0.26388889 | Y20: =VLOOKUP($B20,$R$3:$Z$11,8,FALSE) -> 0 | Z20: =VLOOKUP($B20,$R$3:$Z$11,9,FALSE) -> 60
R21: =B21 -> 0 | S21: =VLOOKUP($B21,$R$3:$X$11,2,FALSE) -> #N/A | T21: =VLOOKUP($B21,$R$3:$X$11,3,FALSE) -> #N/A | U21: =VLOOKUP($B21,$R$3:$X$11,4,FALSE) -> #N/A | V21: =VLOOKUP($B21,$R$3:$X$11,5,FALSE) -> #N/A | W21: =VLOOKUP($B21,$R$3:$X$11,6,FALSE) -> #N/A | X21: =VLOOKUP($B21,$R$3:$X$11,7,FALSE) -> #N/A | Y21: =VLOOKUP($B21,$R$3:$Z$11,8,FALSE) -> #N/A | Z21: =VLOOKUP($B21,$R$3:$Z$11,9,FALSE) -> #N/A
R22: =B22 -> 0 | S22: =VLOOKUP($B22,$R$3:$X$11,2,FALSE) -> #N/A | T22: =VLOOKUP($B22,$R$3:$X$11,3,FALSE) -> #N/A | U22: =VLOOKUP($B22,$R$3:$X$11,4,FALSE) -> #N/A | V22: =VLOOKUP($B22,$R$3:$X$11,5,FALSE) -> #N/A | W22: =VLOOKUP($B22,$R$3:$X$11,6,FALSE) -> #N/A | X22: =VLOOKUP($B22,$R$3:$X$11,7,FALSE) -> #N/A | Y22: =VLOOKUP($B22,$R$3:$Z$11,8,FALSE) -> #N/A | Z22: =VLOOKUP($B22,$R$3:$Z$11,9,FALSE) -> #N/A
R23: =B23 -> 0 | S23: =VLOOKUP($B23,$R$3:$X$11,2,FALSE) -> #N/A | T23: =VLOOKUP($B23,$R$3:$X$11,3,FALSE) -> #N/A | U23: =VLOOKUP($B23,$R$3:$X$11,4,FALSE) -> #N/A | V23: =VLOOKUP($B23,$R$3:$X$11,5,FALSE) -> #N/A | W23: =VLOOKUP($B23,$R$3:$X$11,6,FALSE) -> #N/A | X23: =VLOOKUP($B23,$R$3:$X$11,7,FALSE) -> #N/A | Y23: =VLOOKUP($B23,$R$3:$Z$11,8,FALSE) -> #N/A | Z23: =VLOOKUP($B23,$R$3:$Z$11,9,FALSE) -> #N/A
R24: =B24 -> 0 | S24: =VLOOKUP($B24,$R$3:$X$11,2,FALSE) -> #N/A | T24: =VLOOKUP($B24,$R$3:$X$11,3,FALSE) -> #N/A | U24: =VLOOKUP($B24,$R$3:$X$11,4,FALSE) -> #N/A | V24: =VLOOKUP($B24,$R$3:$X$11,5,FALSE) -> #N/A | W24: =VLOOKUP($B24,$R$3:$X$11,6,FALSE) -> #N/A | X24: =VLOOKUP($B24,$R$3:$X$11,7,FALSE) -> #N/A | Y24: =VLOOKUP($B24,$R$3:$Z$11,8,FALSE) -> #N/A | Z24: =VLOOKUP($B24,$R$3:$Z$11,9,FALSE) -> #N/A
R25: =B25 -> 0 | S25: =VLOOKUP($B25,$R$3:$X$11,2,FALSE) -> #N/A | T25: =VLOOKUP($B25,$R$3:$X$11,3,FALSE) -> #N/A | U25: =VLOOKUP($B25,$R$3:$X$11,4,FALSE) -> #N/A | V25: =VLOOKUP($B25,$R$3:$X$11,5,FALSE) -> #N/A | W25: =VLOOKUP($B25,$R$3:$X$11,6,FALSE) -> #N/A | X25: =VLOOKUP($B25,$R$3:$X$11,7,FALSE) -> #N/A | Y25: =VLOOKUP($B25,$R$3:$Z$11,8,FALSE) -> #N/A | Z25: =VLOOKUP($B25,$R$3:$Z$11,9,FALSE) -> #N/A
