Workbook
Name ProductList: [1]November15!$R$3:$R$9
Name ProductList: [2]November15!$R$3:$R$9

Sheet Dec 18th
T1: P.G. | V1: Hot Time | X1: Process Time | Z1: Cooling Time
B2: Brewing Department Daily Process Loss Report | T2: Lower | U2: Upper | V2: Lower | W2: Upper | X2: Lower | Y2: Upper | Z2: Lower | AA2: Upper
S3: CARIB | T3: 11.6 | U3: 12 | V3: 0 | W3: 0.11805556 | X3: 0.17361111 | Y3: 0.21180556 | Z3: 0 | AA3: 60 | AC3: HR- PISNER
B4: Date: | C4: 45278 | J4: LOT WORT COLOUR: 3.4 | M4: Filter Sheets (Target 20 days) | S4: STAG | T4: 11.6 | U4: 12 | V4: 0 | W4: 0.11805556 | X4: 0.17361111 | Y4: 0.21180556 | Z4: 0 | AA4: 60
M5: Double | N5: Single | S5: GUINNESS | T5: 17 | U5: 17.5 | V5: 0 | W5: 0.10763889 | X5: 0.19444444 | Y5: 0.23263889 | Z5: 0 | AA5: 60
J6: MALT LOT: Lot 8 | L6: Sheet Day | S6: MACKESON | T6: 13.3 | U6: 13.5 | V6: 0 | W6: 0.12905093 | X6: 0.22222222 | Y6: 0.25347222 | Z6: 0
S7: STARMALT | T7: 17.1 | U7: 17.5 | V7: 0 | W7: 0.13605324 | X7: 0.20833333 | Y7: 0.24305556 | Z7: 0 | AA7: 60
B8: Brand | C8: Brew no. | D8: Kett. Hls | E8: Wort | F8: Cool Time(Mins) | G8: Cast. P.G. (Lab Result) | H8: Cast P.G. (Cellar Operator)-gravity | I8: Extr. Rec (79.1%) | J8: Theor. Extr. (77.5%) | K8: Boil Off /Vol. (4-6%) | L8: Boil Time | M8: Total Hot | N8: Brewing | P8: Comments | Q8: Actual Pilsen Malt | S8: Hurricane Reef | T8: 16.6 | U8: 17 | V8: 0 | W8: 0.12905093 | X8: 0.22222222 | Y8: 0.25347222 | Z8: 0
E9: Meter (Hls) | F9: Target(< 60Mins) | M9: Time | S9: VITAMALT | T9: 14.4 | U9: 14.6 | V9: 0 | W9: 0.13905093 | X9: 0.19097222 | Y9: 0.22569444 | Z9: 0 | AA9: 75
S10: =B10 -> 0 | T10: =VLOOKUP($B10,$S$3:$Y$9,2,FALSE) -> #N/A | U10: =VLOOKUP($B10,$S$3:$Y$9,3,FALSE) -> #N/A | V10: =VLOOKUP($B10,$S$3:$Y$9,4,FALSE) -> #N/A | W10: =VLOOKUP($B10,$S$3:$Y$9,5,FALSE) -> #N/A | X10: =VLOOKUP($B10,$S$3:$Y$9,6,FALSE) -> #N/A | Y10: =VLOOKUP($B10,$S$3:$Y$9,7,FALSE) -> #N/A | Z10: =VLOOKUP($B10,$S$3:$AA$9,8,FALSE) -> #N/A | AA10: =VLOOKUP($B10,$S$3:$AA$9,9,FALSE) -> #N/A
S11: =B11 -> 0 | T11: =VLOOKUP($B11,$S$3:$Y$9,2,FALSE) -> #N/A | U11: =VLOOKUP($B11,$S$3:$Y$9,3,FALSE) -> #N/A | V11: =VLOOKUP($B11,$S$3:$Y$9,4,FALSE) -> #N/A | W11: =VLOOKUP($B11,$S$3:$Y$9,5,FALSE) -> #N/A | X11: =VLOOKUP($B11,$S$3:$Y$9,6,FALSE) -> #N/A | Y11: =VLOOKUP($B11,$S$3:$Y$9,7,FALSE) -> #N/A | Z11: =VLOOKUP($B11,$S$3:$AA$9,8,FALSE) -> #N/A | AA11: =VLOOKUP($B11,$S$3:$AA$9,9,FALSE) -> #N/A
S12: =B12 -> 0 | T12: =VLOOKUP($B12,$S$3:$Y$9,2,FALSE) -> #N/A | U12: =VLOOKUP($B12,$S$3:$Y$9,3,FALSE) -> #N/A | V12: =VLOOKUP($B12,$S$3:$Y$9,4,FALSE) -> #N/A | W12: =VLOOKUP($B12,$S$3:$Y$9,5,FALSE) -> #N/A | X12: =VLOOKUP($B12,$S$3:$Y$9,6,FALSE) -> #N/A | Y12: =VLOOKUP($B12,$S$3:$Y$9,7,FALSE) -> #N/A | Z12: =VLOOKUP($B12,$S$3:$AA$9,8,FALSE) -> #N/A | AA12: =VLOOKUP($B12,$S$3:$AA$9,9,FALSE) -> #N/A
S13: =B13 -> 0 | T13: =VLOOKUP($B13,$S$3:$Y$9,2,FALSE) -> #N/A | U13: =VLOOKUP($B13,$S$3:$Y$9,3,FALSE) -> #N/A | V13: =VLOOKUP($B13,$S$3:$Y$9,4,FALSE) -> #N/A | W13: =VLOOKUP($B13,$S$3:$Y$9,5,FALSE) -> #N/A | X13: =VLOOKUP($B13,$S$3:$Y$9,6,FALSE) -> #N/A | Y13: =VLOOKUP($B13,$S$3:$Y$9,7,FALSE) -> #N/A | Z13: =VLOOKUP($B13,$S$3:$AA$9,8,FALSE) -> #N/A | AA13: =VLOOKUP($B13,$S$3:$AA$9,9,FALSE) -> #N/A
S14: =B14 -> 0 | T14: =VLOOKUP($B14,$S$3:$Y$9,2,FALSE) -> #N/A | U14: =VLOOKUP($B14,$S$3:$Y$9,3,FALSE) -> #N/A | V14: =VLOOKUP($B14,$S$3:$Y$9,4,FALSE) -> #N/A | W14: =VLOOKUP($B14,$S$3:$Y$9,5,FALSE) -> #N/A | X14: =VLOOKUP($B14,$S$3:$Y$9,6,FALSE) -> #N/A | Y14: =VLOOKUP($B14,$S$3:$Y$9,7,FALSE) -> #N/A | Z14: =VLOOKUP($B14,$S$3:$AA$9,8,FALSE) -> #N/A | AA14: =VLOOKUP($B14,$S$3:$AA$9,9,FALSE) -> #N/A
S15: =B15 -> 0 | T15: =VLOOKUP($B15,$S$3:$Y$9,2,FALSE) -> #N/A | U15: =VLOOKUP($B15,$S$3:$Y$9,3,FALSE) -> #N/A | V15: =VLOOKUP($B15,$S$3:$Y$9,4,FALSE) -> #N/A | W15: =VLOOKUP($B15,$S$3:$Y$9,5,FALSE) -> #N/A | X15: =VLOOKUP($B15,$S$3:$Y$9,6,FALSE) -> #N/A | Y15: =VLOOKUP($B15,$S$3:$Y$9,7,FALSE) -> #N/A | Z15: =VLOOKUP($B15,$S$3:$AA$9,8,FALSE) -> #N/A | AA15: =VLOOKUP($B15,$S$3:$AA$9,9,FALSE) -> #N/A
S16: =B16 -> 0 | T16: =VLOOKUP($B16,$S$3:$Y$9,2,FALSE) -> #N/A | U16: =VLOOKUP($B16,$S$3:$Y$9,3,FALSE) -> #N/A | V16: =VLOOKUP($B16,$S$3:$Y$9,4,FALSE) -> #N/A | W16: =VLOOKUP($B16,$S$3:$Y$9,5,FALSE) -> #N/A | X16: =VLOOKUP($B16,$S$3:$Y$9,6,FALSE) -> #N/A | Y16: =VLOOKUP($B16,$S$3:$Y$9,7,FALSE) -> #N/A | Z16: =VLOOKUP($B16,$S$3:$AA$9,8,FALSE) -> #N/A | AA16: =VLOOKUP($B16,$S$3:$AA$9,9,FALSE) -> #N/A
S17: =B17 -> 0 | T17: =VLOOKUP($B17,$S$3:$Y$9,2,FALSE) -> #N/A | U17: =VLOOKUP($B17,$S$3:$Y$9,3,FALSE) -> #N/A | V17: =VLOOKUP($B17,$S$3:$Y$9,4,FALSE) -> #N/A | W17: =VLOOKUP($B17,$S$3:$Y$9,5,FALSE) -> #N/A | X17: =VLOOKUP($B17,$S$3:$Y$9,6,FALSE) -> #N/A | Y17: =VLOOKUP($B17,$S$3:$Y$9,7,FALSE) -> #N/A | Z17: =VLOOKUP($B17,$S$3:$AA$9,8,FALSE) -> #N/A | AA17: =VLOOKUP($B17,$S$3:$AA$9,9,FALSE) -> #N/A
S18: =B18 -> 0 | T18: =VLOOKUP($B18,$S$3:$Y$9,2,FALSE) -> #N/A | U18: =VLOOKUP($B18,$S$3:$Y$9,3,FALSE) -> #N/A | V18: =VLOOKUP($B18,$S$3:$Y$9,4,FALSE) -> #N/A | W18: =VLOOKUP($B18,$S$3:$Y$9,5,FALSE) -> #N/A | X18: =VLOOKUP($B18,$S$3:$Y$9,6,FALSE) -> #N/A | Y18: =VLOOKUP($B18,$S$3:$Y$9,7,FALSE) -> #N/A | Z18: =VLOOKUP($B18,$S$3:$AA$9,8,FALSE) -> #N/A | AA18: =VLOOKUP($B18,$S$3:$AA$9,9,FALSE) -> #N/A
S19: =B19 -> 0 | T19: =VLOOKUP($B19,$S$3:$Y$9,2,FALSE) -> #N/A | U19: =VLOOKUP($B19,$S$3:$Y$9,3,FALSE) -> #N/A | V19: =VLOOKUP($B19,$S$3:$Y$9,4,FALSE) -> #N/A | W19: =VLOOKUP($B19,$S$3:$Y$9,5,FALSE) -> #N/A | X19: =VLOOKUP($B19,$S$3:$Y$9,6,FALSE) -> #N/A | Y19: =VLOOKUP($B19,$S$3:$Y$9,7,FALSE) -> #N/A | Z19: =VLOOKUP($B19,$S$3:$AA$9,8,FALSE) -> #N/A | AA19: =VLOOKUP($B19,$S$3:$AA$9,9,FALSE) -> #N/A
S20: =B20 -> 0 | T20: =VLOOKUP($B20,$S$3:$Y$9,2,FALSE) -> #N/A | U20: =VLOOKUP($B20,$S$3:$Y$9,3,FALSE) -> #N/A | V20: =VLOOKUP($B20,$S$3:$Y$9,4,FALSE) -> #N/A | W20: =VLOOKUP($B20,$S$3:$Y$9,5,FALSE) -> #N/A | X20: =VLOOKUP($B20,$S$3:$Y$9,6,FALSE) -> #N/A | Y20: =VLOOKUP($B20,$S$3:$Y$9,7,FALSE) -> #N/A | Z20: =VLOOKUP($B20,$S$3:$AA$9,8,FALSE) -> #N/A | AA20: =VLOOKUP($B20,$S$3:$AA$9,9,FALSE) -> #N/A
S21: =B21 -> 0 | T21: =VLOOKUP($B21,$S$3:$Y$9,2,FALSE) -> #N/A | U21: =VLOOKUP($B21,$S$3:$Y$9,3,FALSE) -> #N/A | V21: =VLOOKUP($B21,$S$3:$Y$9,4,FALSE) -> #N/A | W21: =VLOOKUP($B21,$S$3:$Y$9,5,FALSE) -> #N/A | X21: =VLOOKUP($B21,$S$3:$Y$9,6,FALSE) -> #N/A | Y21: =VLOOKUP($B21,$S$3:$Y$9,7,FALSE) -> #N/A | Z21: =VLOOKUP($B21,$S$3:$AA$9,8,FALSE) -> #N/A | AA21: =VLOOKUP($B21,$S$3:$AA$9,9,FALSE) -> #N/A
... S47: =B47 -> 0 | T47: =VLOOKUP($B47,$S$3:$Y$9,2,FALSE) -> #N/A | U47: =VLOOKUP($B47,$S$3:$Y$9,3,FALSE) -> #N/A | V47: =VLOOKUP($B47,$S$3:$Y$9,4,FALSE) -> #N/A | W47: =VLOOKUP($B47,$S$3:$Y$9,5,FALSE) -> #N/A | X47: =VLOOKUP($B47,$S$3:$Y$9,6,FALSE) -> #N/A | Y47: =VLOOKUP($B47,$S$3:$Y$9,7,FALSE) -> #N/A | Z47: =VLOOKUP($B47,$S$3:$AA$9,8,FALSE) -> #N/A | AA47: =VLOOKUP($B47,$S$3:$AA$9,9,FALSE) -> #N/A
I48: EXTRACT RECOVERY
B49: BRAND | D49: BBT P.G./ O.G | I49: Brand | J49: Actual | K49: MTD No. of Brews | L49: MTD | M49: YTD | N49: Target
B50: STAG | C50: 11.8 | D50: 11.73 | I50: CARIB | K50: =COUNTA([11]Brewhouse!$A$1596:$A$1619) -> 24 | L50: =AVERAGE([11]Brewhouse!$AU$1529,[11]Brewhouse!$AU$1531:$AU$1594,[11]Brewhouse!$AU$1596:$AU$1619) -> 98.205761 | M50: =AVERAGE([11]Brewhouse!$AU$849:$AU$924,[11]Brewhouse!$AU$926:$AU$971,[11]Brewhouse!$AU$973:$AU$1066,[11]Brewhouse!$AU$1068:$AU$1111,[11]Brewhouse!$AU$1113:$AU$1132,[11]Brewhouse!$AU$1134:$AU$1167,[11]Brewhouse!$AU$1169:$AU$1230,[11]Brewhouse!$AU$1232:$AU$1299,[11]Brewhouse!$AU$1301:$AU$1363,[11]Brewhouse!$AU$1365:$AU$1444,[11]Brewhouse!$AU$1446:$AU$1527,[11]Brewhouse!$AU$1529,[11]Brewhouse!$AU$1531:$AU$1594,[11]Brewhouse!$AU$1596:$AU$1619) -> 98.381806 | N50: 98
C51: 11.9 | I51: STAG | K51: =COUNTA([12]Brewhouse!$A$976:$A$1007) -> 32 | L51: =AVERAGE([12]Brewhouse!$AS$976:$AS$979,[12]Brewhouse!$AS$981:$AS$1007) -> 98.538567 | M51: =AVERAGE([12]Brewhouse!$AS$577:$AS$618,[12]Brewhouse!$AS$620:$AS$651,[12]Brewhouse!$AS$653:$AS$696,[12]Brewhouse!$AS$698:$AS$708,[12]Brewhouse!$AS$710:$AS$733,[12]Brewhouse!$AS$735:$AS$777,[12]Brewhouse!$AS$779:$AS$822,[12]Brewhouse!$AS$824:$AS$863,[12]Brewhouse!$AS$865:$AS$974,[12]Brewhouse!$AS$976:$AS$979,[12]Brewhouse!$AS$981:$AS$1007) -> 98.489671 | N51: 98
I52: GUINNESS | K52: =COUNTA([13]Brewhouse!$A$282:$A$289) -> 8 | L52: =AVERAGE([13]Brewhouse!$AU$269:$AU$279,[13]Brewhouse!$AU$282:$AU$289) -> 96.186177 | M52: =AVERAGE([13]Brewhouse!$AU$161:$AU$176,[13]Brewhouse!$AU$178:$AU$195,[13]Brewhouse!$AU$197:$AU$208,[13]Brewhouse!$AU$210:$AU$221,[13]Brewhouse!$AU$223:$AU$232,[13]Brewhouse!$AU$234:$AU$279,[13]Brewhouse!$AU$282:$AU$289) -> 96.64916 | N52: 98
I53: VITAMALT | K53: =COUNTA([14]Brewhouse!$A$158:$A$163) -> 6 | L53: =AVERAGE([14]Brewhouse!$AU$158:$AU$163) -> 94.60305 | M53: =AVERAGE([14]Brewhouse!$AU$91:$AU$101,[14]Brewhouse!$AU$103:$AU$112,[14]Brewhouse!$AU$114:$AU$123,[14]Brewhouse!$AU$125:$AU$134,[14]Brewhouse!$AU$136:$AU$145,[14]Brewhouse!$AU$147:$AU$156,[14]Brewhouse!$AU$158:$AU$163) -> 96.240014 | N53: 98
I54: MAXIMALT | N54: 98
I55: MACKESON | M55: =AVERAGE([15]Brewhouse!$AT$74:$AT$79) -> 93.959836 | N55: 98
I56: STARMALT | K56: =COUNTA([16]Brewhouse!$A$249:$A$254) -> 6 | L56: =AVERAGE([16]Brewhouse!$AY$249:$AY$254) -> 99.681996 | M56: =AVERAGE([16]Brewhouse!$AY$138:$AY$143,[16]Brewhouse!$AY$145:$AY$153,[16]Brewhouse!$AY$155,[16]Brewhouse!$AY$156:$AY$174,[16]Brewhouse!$AY$176:$AY$185,[16]Brewhouse!$AY$187:$AY$198,[16]Brewhouse!$AY$200:$AY$247,[16]Brewhouse!$AY$249:$AY$254) -> 98.774703 | N56: 98
I57: HR- P | M57: =AVERAGE([17]Brewhouse!$AW$13:$AW$14,[17]Brewhouse!$AW$16:$AW$17) -> 92.042628 | N57: 98
I58: Hurricane Reef | M58: =AVERAGE([17]Brewhouse!$AW$13:$AW$14) -> 88.376943 | N58: 98
K59: =SUM(K50:K58) -> 76 | L59: =((L50*K50)+(L51*K51)+(L52*K52)+(L53*K53)+(L54*K54)+(K57*L57)+(L55*K55)+(L56*K56)+(L58*K58))/(K59) -> 97.965422 | M59: =AVERAGE('[18]Closing- January 2023'!$L$42,'[19]Feb. 28th'!$L$42,'[20]March 31st'!$L$75,'[21]Apri 28th'!$L$51,L59) -> 98.06926 | N59: 98
J62: Daily Brewing Plan
J63: Brand | K63: Brews Achieved | L63: Average Brews per day
J64: CARIB | L64: MTD | M64: YTD | N64: TARGET
J65: STAG | K65: 5 | L65: =AVERAGE(#REF!,#REF!,K74,#REF!,#REF!,#REF!,#REF!,#REF!,#REF!,#REF!,#REF!) -> #REF! | M65: =AVERAGE(6,6,'[20]March 31st'!$L$80,'[22]June 30th '!$L$71,6,L65,'[23]July 31st'!$L$108,'[24]Aug 30th'!$L$124,7,[25]Oct.31st!$L$51) -> #REF! | N65: 9
J66: GUINN
J67: VITAMALT
...

Sheet Jan 2nd
S1: P.G. | U1: Hot Time | W1: Process Time | Y1: Cooling Time
B2: Brewing Department Daily Process Loss Report | S2: Lower | T2: Upper | U2: Lower | V2: Upper | W2: Lower | X2: Upper | Y2: Lower | Z2: Upper
R3: CARIB | S3: 11.6 | T3: 12 | U3: 0 | V3: 0.11805556 | W3: 0.22569444 | X3: 0.26388889 | Y3: 0 | Z3: 60 | AB3: HR- PISNER
B4: Date: | C4: 46024 | J4: LOT WORT COLOUR: | M4: Filter Sheets (Target 20 days) | R4: STAG | S4: 11.6 | T4: 12 | U4: 0 | V4: 0.11805556 | W4: 0.22569444 | X4: 0.26388889 | Y4: 0 | Z4: 60
M5: Double | N5: Single | R5: GUINNESS | S5: 17 | T5: 17.5 | U5: 0 | V5: 0.10763889 | W5: 0.24652778 | X5: 0.28472222 | Y5: 0 | Z5: 60
J6: MALT LOT: Lot #8 | L6: Sheet Day | R6: MACKESON | S6: 13.3 | T6: 13.5 | U6: 0 | V6: 0.12905093 | W6: 0.27430556 | X6: 0.30208333 | Y6: 0
R7: STARMALT | S7: 17 | T7: 17.4 | U7: 0 | V7: 0.13605324 | W7: 0.27430556 | X7: 0.30902778 | Y7: 0 | Z7: 85
B8: Brand | C8: Brew no. | D8: Kett. Hls | E8: Wort | F8: Cool Time(Mins) | G8: Cast. P.G. (Lab Result) | H8: Cast P.G. (Cellar Operator)-gravity | I8: Extr. Rec (77.9%) | J8: Theor. Extr. (77.5%) | K8: Boil Off /Vol. (4-6%) | L8: Boil Time | M8: Total Hot | N8: Brewing | O8: Operator | R8: Hurricane Reef | S8: 16.6 | T8: 17 | U8: 0 | V8: 0.12905093 | W8: 0.27430556 | X8: 0.30208333 | Y8: 0
E9: Meter (Hls) | F9: Target(< 60Mins) | M9: Time | R9: VITAMALT | S9: 14.2 | T9: 14.6 | U9: 0 | V9: 0.13905093 | W9: 0.26041667 | X9: 0.29513889 | Y9: 0 | Z9: 75
B10: CARIB | C10: =[4]Brewhouse!$A42 -> CA001 | D10: =[4]Brewhouse!$AF42 -> 50.9 | E10: =[4]Brewhouse!$AI42 -> 50.8 | F10: =[4]Brewhouse!$V42 -> 60 | G10: =[4]Brewhouse!AG42 -> 11.8 | H10: 11.8 | I10: =[4]Brewhouse!$AU42 -> 98.774704 | J10: =[4]Brewhouse!$AV42 -> 99.531679 | K10: =[4]Brewhouse!$Q42 -> 5.4990584 | L10: =[4]Brewhouse!$P42 -> 57 | M10: =[4]Brewhouse!$U42-[4]Brewhouse!$T42 -> 0.1125 | N10: =[4]Brewhouse!$Z42 -> 0.24236111 | O10: =[4]Brewhouse!$AX42 -> R.Sookram | R10: =B10 -> CARIB | S10: =VLOOKUP($B10,$R$3:$X$9,2,FALSE) -> 11.6 | T10: =VLOOKUP($B10,$R$3:$X$9,3,FALSE) -> 12 | U10: =VLOOKUP($B10,$R$3:$X$9,4,FALSE) -> 0 | V10: =VLOOKUP($B10,$R$3:$X$9,5,FALSE) -> 0.11805556 | W10: =VLOOKUP($B10,$R$3:$X$9,6,FALSE) -> 0.22569444 | X10: =VLOOKUP($B10,$R$3:$X$9,7,FALSE) -> 0.26388889 | Y10: =VLOOKUP($B10,$R$3:$Z$9,8,FALSE) -> 0 | Z10: =VLOOKUP($B10,$R$3:$Z$9,9,FALSE) -> 60
B11: CARIB | C11: =[4]Brewhouse!$A43 -> CA002 | D11: =[4]Brewhouse!$AF43 -> 52.6 | E11: =[4]Brewhouse!$AI43 -> 51.3 | F11: =[4]Brewhouse!$V43 -> 57 | G11: =[4]Brewhouse!AG43 -> 11.8 | H11: 11.8 | I11: =[4]Brewhouse!$AU43 -> 99.746896 | J11: =[4]Brewhouse!$AV43 -> 100.51132 | K11: =[4]Brewhouse!$Q43 -> 3.8041431 | L11: =[4]Brewhouse!$P43 -> 57 | M11: =[4]Brewhouse!$U43-[4]Brewhouse!$T43 -> 0.11319444 | N11: =[4]Brewhouse!$Z43 -> 0.25208333 | O11: =[4]Brewhouse!$AX43 -> R.Sookram | R11: =B11 -> CARIB | S11: =VLOOKUP($B11,$R$3:$X$9,2,FALSE) -> 11.6 | T11: =VLOOKUP($B11,$R$3:$X$9,3,FALSE) -> 12 | U11: =VLOOKUP($B11,$R$3:$X$9,4,FALSE) -> 0 | V11: =VLOOKUP($B11,$R$3:$X$9,5,FALSE) -> 0.11805556 | W11: =VLOOKUP($B11,$R$3:$X$9,6,FALSE) -> 0.22569444 | X11: =VLOOKUP($B11,$R$3:$X$9,7,FALSE) -> 0.26388889 | Y11: =VLOOKUP($B11,$R$3:$Z$9,8,FALSE) -> 0 | Z11: =VLOOKUP($B11,$R$3:$Z$9,9,FALSE) -> 60
B12: CARIB | C12: =[4]Brewhouse!$A44 -> CA003 | D12: =[4]Brewhouse!$AF44 -> 52.6 | E12: =[4]Brewhouse!$AI44 -> 51.1 | F12: =[4]Brewhouse!$V44 -> 59 | G12: =[4]Brewhouse!AG44 -> 11.8 | H12: 11.9 | I12: =[4]Brewhouse!$AU44 -> 99.480491 | J12: =[4]Brewhouse!$AV44 -> 100.24281 | K12: =[4]Brewhouse!$Q44 -> 4.5660377 | L12: =[4]Brewhouse!$P44 -> 59 | M12: =[4]Brewhouse!$U44-[4]Brewhouse!$T44 -> 0.11666667 | N12: =[4]Brewhouse!$Z44 -> 0.27291667 | O12: =[4]Brewhouse!$AX44 -> R.Sookram | R12: =B12 -> CARIB | S12: =VLOOKUP($B12,$R$3:$X$9,2,FALSE) -> 11.6 | T12: =VLOOKUP($B12,$R$3:$X$9,3,FALSE) -> 12 | U12: =VLOOKUP($B12,$R$3:$X$9,4,FALSE) -> 0 | V12: =VLOOKUP($B12,$R$3:$X$9,5,FALSE) -> 0.11805556 | W12: =VLOOKUP($B12,$R$3:$X$9,6,FALSE) -> 0.22569444 | X12: =VLOOKUP($B12,$R$3:$X$9,7,FALSE) -> 0.26388889 | Y12: =VLOOKUP($B12,$R$3:$Z$9,8,FALSE) -> 0 | Z12: =VLOOKUP($B12,$R$3:$Z$9,9,FALSE) -> 60
B13: CARIB | C13: =[4]Brewhouse!$A45 -> CA004 | D13: =[4]Brewhouse!$AF45 -> 0 | E13: =[4]Brewhouse!$AI45 -> 50.7 | F13: =[4]Brewhouse!$V45 -> 46 | G13: =[4]Brewhouse!AG45 -> 12 | H13: 12 | I13: =[4]Brewhouse!$AU45 -> 99.359192 | J13: =[4]Brewhouse!$AV45 -> 100.12113 | L13: =[4]Brewhouse!$P45 -> 60 | M13: =[4]Brewhouse!$U45-[4]Brewhouse!$T45 -> 0.11875 | N13: =[4]Brewhouse!$Z45 -> 0.27847222 | O13: =[4]Brewhouse!$AX45 -> K. Benjamin | R13: =B13 -> CARIB | S13: =VLOOKUP($B13,$R$3:$X$9,2,FALSE) -> 11.6 | T13: =VLOOKUP($B13,$R$3:$X$9,3,FALSE) -> 12 | U13: =VLOOKUP($B13,$R$3:$X$9,4,FALSE) -> 0 | V13: =VLOOKUP($B13,$R$3:$X$9,5,FALSE) -> 0.11805556 | W13: =VLOOKUP($B13,$R$3:$X$9,6,FALSE) -> 0.22569444 | X13: =VLOOKUP($B13,$R$3:$X$9,7,FALSE) -> 0.26388889 | Y13: =VLOOKUP($B13,$R$3:$Z$9,8,FALSE) -> 0 | Z13: =VLOOKUP($B13,$R$3:$Z$9,9,FALSE) -> 60
R14: =B14 -> 0 | S14: =VLOOKUP($B14,$R$3:$X$9,2,FALSE) -> #N/A | T14: =VLOOKUP($B14,$R$3:$X$9,3,FALSE) -> #N/A | U14: =VLOOKUP($B14,$R$3:$X$9,4,FALSE) -> #N/A | V14: =VLOOKUP($B14,$R$3:$X$9,5,FALSE) -> #N/A | W14: =VLOOKUP($B14,$R$3:$X$9,6,FALSE) -> #N/A | X14: =VLOOKUP($B14,$R$3:$X$9,7,FALSE) -> #N/A | Y14: =VLOOKUP($B14,$R$3:$Z$9,8,FALSE) -> #N/A | Z14: =VLOOKUP($B14,$R$3:$Z$9,9,FALSE) -> #N/A
R15: =B15 -> 0 | S15: =VLOOKUP($B15,$R$3:$X$9,2,FALSE) -> #N/A | T15: =VLOOKUP($B15,$R$3:$X$9,3,FALSE) -> #N/A | U15: =VLOOKUP($B15,$R$3:$X$9,4,FALSE) -> #N/A | V15: =VLOOKUP($B15,$R$3:$X$9,5,FALSE) -> #N/A | W15: =VLOOKUP($B15,$R$3:$X$9,6,FALSE) -> #N/A | X15: =VLOOKUP($B15,$R$3:$X$9,7,FALSE) -> #N/A | Y15: =VLOOKUP($B15,$R$3:$Z$9,8,FALSE) -> #N/A | Z15: =VLOOKUP($B15,$R$3:$Z$9,9,FALSE) -> #N/A
R16: =B16 -> 0 | S16: =VLOOKUP($B16,$R$3:$X$9,2,FALSE) -> #N/A | T16: =VLOOKUP($B16,$R$3:$X$9,3,FALSE) -> #N/A | U16: =VLOOKUP($B16,$R$3:$X$9,4,FALSE) -> #N/A | V16: =VLOOKUP($B16,$R$3:$X$9,5,FALSE) -> #N/A | W16: =VLOOKUP($B16,$R$3:$X$9,6,FALSE) -> #N/A | X16: =VLOOKUP($B16,$R$3:$X$9,7,FALSE) -> #N/A | Y16: =VLOOKUP($B16,$R$3:$Z$9,8,FALSE) -> #N/A | Z16: =VLOOKUP($B16,$R$3:$Z$9,9,FALSE) -> #N/A
R17: =B17 -> 0 | S17: =VLOOKUP($B17,$R$3:$X$9,2,FALSE) -> #N/A | T17: =VLOOKUP($B17,$R$3:$X$9,3,FALSE) -> #N/A | U17: =VLOOKUP($B17,$R$3:$X$9,4,FALSE) -> #N/A | V17: =VLOOKUP($B17,$R$3:$X$9,5,FALSE) -> #N/A | W17: =VLOOKUP($B17,$R$3:$X$9,6,FALSE) -> #N/A | X17: =VLOOKUP($B17,$R$3:$X$9,7,FALSE) -> #N/A | Y17: =VLOOKUP($B17,$R$3:$Z$9,8,FALSE) -> #N/A | Z17: =VLOOKUP($B17,$R$3:$Z$9,9,FALSE) -> #N/A
R18: =B18 -> 0 | S18: =VLOOKUP($B18,$R$3:$X$9,2,FALSE) -> #N/A | T18: =VLOOKUP($B18,$R$3:$X$9,3,FALSE) -> #N/A | U18: =VLOOKUP($B18,$R$3:$X$9,4,FALSE) -> #N/A | V18: =VLOOKUP($B18,$R$3:$X$9,5,FALSE) -> #N/A | W18: =VLOOKUP($B18,$R$3:$X$9,6,FALSE) -> #N/A | X18: =VLOOKUP($B18,$R$3:$X$9,7,FALSE) -> #N/A | Y18: =VLOOKUP($B18,$R$3:$Z$9,8,FALSE) -> #N/A | Z18: =VLOOKUP($B18,$R$3:$Z$9,9,FALSE) -> #N/A
R19: =B19 -> 0 | S19: =VLOOKUP($B19,$R$3:$X$9,2,FALSE) -> #N/A | T19: =VLOOKUP($B19,$R$3:$X$9,3,FALSE) -> #N/A | U19: =VLOOKUP($B19,$R$3:$X$9,4,FALSE) -> #N/A | V19: =VLOOKUP($B19,$R$3:$X$9,5,FALSE) -> #N/A | W19: =VLOOKUP($B19,$R$3:$X$9,6,FALSE) -> #N/A | X19: =VLOOKUP($B19,$R$3:$X$9,7,FALSE) -> #N/A | Y19: =VLOOKUP($B19,$R$3:$Z$9,8,FALSE) -> #N/A | Z19: =VLOOKUP($B19,$R$3:$Z$9,9,FALSE) -> #N/A
B20: BRAND | D20: BBT P.G./ O.G | I20: Brand | K20: MTD No. of Brews | L20: MTD | M20: YTD | N20: Target | R20: =B20 -> BRAND | S20: =VLOOKUP($B20,$R$3:$X$9,2,FALSE) -> #N/A | T20: =VLOOKUP($B20,$R$3:$X$9,3,FALSE) -> #N/A | U20: =VLOOKUP($B20,$R$3:$X$9,4,FALSE) -> #N/A | V20: =VLOOKUP($B20,$R$3:$X$9,5,FALSE) -> #N/A | W20: =VLOOKUP($B20,$R$3:$X$9,6,FALSE) -> #N/A | X20: =VLOOKUP($B20,$R$3:$X$9,7,FALSE) -> #N/A | Y20: =VLOOKUP($B20,$R$3:$Z$9,8,FALSE) -> #N/A | Z20: =VLOOKUP($B20,$R$3:$Z$9,9,FALSE) -> #N/A
B21: =I21 -> CARIB | I21: CARIB | J21: =AVERAGE(I10:I13) -> 99.340321 | K21: =COUNTA([4]Brewhouse!$A$42:$A$45) -> 4 | L21: =AVERAGE([4]Brewhouse!$AU$42:$AU$45) -> 99.340321 | M21: =AVERAGE([4]Brewhouse!$AU$42:$AU$45) -> 99.340321 | N21: 98 | R21: =B21 -> CARIB | S21: =VLOOKUP($B21,$R$3:$X$9,2,FALSE) -> 11.6 | T21: =VLOOKUP($B21,$R$3:$X$9,3,FALSE) -> 12 | U21: =VLOOKUP($B21,$R$3:$X$9,4,FALSE) -> 0 | V21: =VLOOKUP($B21,$R$3:$X$9,5,FALSE) -> 0.11805556 | W21: =VLOOKUP($B21,$R$3:$X$9,6,FALSE) -> 0.22569444 | X21: =VLOOKUP($B21,$R$3:$X$9,7,FALSE) -> 0.26388889 | Y21: =VLOOKUP($B21,$R$3:$Z$9,8,FALSE) -> 0 | Z21: =VLOOKUP($B21,$R$3:$Z$9,9,FALSE) -> 60
I22: STAG | N22: 98 | R22: =B22 -> 0 | S22: =VLOOKUP($B22,$R$3:$X$9,2,FALSE) -> #N/A | T22: =VLOOKUP($B22,$R$3:$X$9,3,FALSE) -> #N/A | U22: =VLOOKUP($B22,$R$3:$X$9,4,FALSE) -> #N/A | V22: =VLOOKUP($B22,$R$3:$X$9,5,FALSE) -> #N/A | W22: =VLOOKUP($B22,$R$3:$X$9,6,FALSE) -> #N/A | X22: =VLOOKUP($B22,$R$3:$X$9,7,FALSE) -> #N/A | Y22: =VLOOKUP($B22,$R$3:$Z$9,8,FALSE) -> #N/A | Z22: =VLOOKUP($B22,$R$3:$Z$9,9,FALSE) -> #N/A
I23: GUINNESS | N23: 98 | R23: =B23 -> 0 | S23: =VLOOKUP($B23,$R$3:$X$9,2,FALSE) -> #N/A | T23: =VLOOKUP($B23,$R$3:$X$9,3,FALSE) -> #N/A | U23: =VLOOKUP($B23,$R$3:$X$9,4,FALSE) -> #N/A | V23: =VLOOKUP($B23,$R$3:$X$9,5,FALSE) -> #N/A | W23: =VLOOKUP($B23,$R$3:$X$9,6,FALSE) -> #N/A | X23: =VLOOKUP($B23,$R$3:$X$9,7,FALSE) -> #N/A | Y23: =VLOOKUP($B23,$R$3:$Z$9,8,FALSE) -> #N/A | Z23: =VLOOKUP($B23,$R$3:$Z$9,9,FALSE) -> #N/A
I24: VITAMALT | N24: 98 | R24: =B24 -> 0 | S24: =VLOOKUP($B24,$R$3:$X$9,2,FALSE) -> #N/A | T24: =VLOOKUP($B24,$R$3:$X$9,3,FALSE) -> #N/A | U24: =VLOOKUP($B24,$R$3:$X$9,4,FALSE) -> #N/A | V24: =VLOOKUP($B24,$R$3:$X$9,5,FALSE) -> #N/A | W24: =VLOOKUP($B24,$R$3:$X$9,6,FALSE) -> #N/A | X24: =VLOOKUP($B24,$R$3:$X$9,7,FALSE) -> #N/A | Y24: =VLOOKUP($B24,$R$3:$Z$9,8,FALSE) -> #N/A | Z24: =VLOOKUP($B24,$R$3:$Z$9,9,FALSE) -> #N/A
I25: MAXIMALT | N25: 98 | R25: =B25 -> 0 | S25: =VLOOKUP($B25,$R$3:$X$9,2,FALSE) -> #N/A | T25: =VLOOKUP($B25,$R$3:$X$9,3,FALSE) -> #N/A | U25: =VLOOKUP($B25,$R$3:$X$9,4,FALSE) -> #N/A | V25: =VLOOKUP($B25,$R$3:$X$9,5,FALSE) -> #N/A | W25: =VLOOKUP($B25,$R$3:$X$9,6,FALSE) -> #N/A | X25: =VLOOKUP($B25,$R$3:$X$9,7,FALSE) -> #N/A | Y25: =VLOOKUP($B25,$R$3:$Z$9,8,FALSE) -> #N/A | Z25: =VLOOKUP($B25,$R$3:$Z$9,9,FALSE) -> #N/A
I26: MACKESON | N26: 98 | R26: =B26 -> 0 | S26: =VLOOKUP($B26,$R$3:$X$9,2,FALSE) -> #N/A | T26: =VLOOKUP($B26,$R$3:$X$9,3,FALSE) -> #N/A | U26: =VLOOKUP($B26,$R$3:$X$9,4,FALSE) -> #N/A | V26: =VLOOKUP($B26,$R$3:$X$9,5,FALSE) -> #N/A | W26: =VLOOKUP($B26,$R$3:$X$9,6,FALSE) -> #N/A | X26: =VLOOKUP($B26,$R$3:$X$9,7,FALSE) -> #N/A | Y26: =VLOOKUP($B26,$R$3:$Z$9,8,FALSE) -> #N/A | Z26: =VLOOKUP($B26,$R$3:$Z$9,9,FALSE) -> #N/A
I27: STARMALT | N27: 98 | R27: =B27 -> 0 | S27: =VLOOKUP($B27,$R$3:$X$9,2,FALSE) -> #N/A | T27: =VLOOKUP($B27,$R$3:$X$9,3,FALSE) -> #N/A | U27: =VLOOKUP($B27,$R$3:$X$9,4,FALSE) -> #N/A | V27: =VLOOKUP($B27,$R$3:$X$9,5,FALSE) -> #N/A | W27: =VLOOKUP($B27,$R$3:$X$9,6,FALSE) -> #N/A | X27: =VLOOKUP($B27,$R$3:$X$9,7,FALSE) -> #N/A | Y27: =VLOOKUP($B27,$R$3:$Z$9,8,FALSE) -> #N/A | Z27: =VLOOKUP($B27,$R$3:$Z$9,9,FALSE) -> #N/A
I28: HR- Pils | N28: 98 | R28: =B28 -> 0 | S28: =VLOOKUP($B28,$R$3:$X$9,2,FALSE) -> #N/A | T28: =VLOOKUP($B28,$R$3:$X$9,3,FALSE) -> #N/A | U28: =VLOOKUP($B28,$R$3:$X$9,4,FALSE) -> #N/A | V28: =VLOOKUP($B28,$R$3:$X$9,5,FALSE) -> #N/A | W28: =VLOOKUP($B28,$R$3:$X$9,6,FALSE) -> #N/A | X28: =VLOOKUP($B28,$R$3:$X$9,7,FALSE) -> #N/A | Y28: =VLOOKUP($B28,$R$3:$Z$9,8,FALSE) -> #N/A | Z28: =VLOOKUP($B28,$R$3:$Z$9,9,FALSE) -> #N/A
I29: HR- IPA | N29: 98 | R29: =B29 -> 0 | S29: =VLOOKUP($B29,$R$3:$X$9,2,FALSE) -> #N/A | T29: =VLOOKUP($B29,$R$3:$X$9,3,FALSE) -> #N/A | U29: =VLOOKUP($B29,$R$3:$X$9,4,FALSE) -> #N/A | V29: =VLOOKUP($B29,$R$3:$X$9,5,FALSE) -> #N/A | W29: =VLOOKUP($B29,$R$3:$X$9,6,FALSE) -> #N/A | X29: =VLOOKUP($B29,$R$3:$X$9,7,FALSE) -> #N/A | Y29: =VLOOKUP($B29,$R$3:$Z$9,8,FALSE) -> #N/A | Z29: =VLOOKUP($B29,$R$3:$Z$9,9,FALSE) -> #N/A
I30: HR- APA | N30: 98 | R30: =B30 -> 0 | S30: =VLOOKUP($B30,$R$3:$X$9,2,FALSE) -> #N/A | T30: =VLOOKUP($B30,$R$3:$X$9,3,FALSE) -> #N/A | U30: =VLOOKUP($B30,$R$3:$X$9,4,FALSE) -> #N/A | V30: =VLOOKUP($B30,$R$3:$X$9,5,FALSE) -> #N/A | W30: =VLOOKUP($B30,$R$3:$X$9,6,FALSE) -> #N/A | X30: =VLOOKUP($B30,$R$3:$X$9,7,FALSE) -> #N/A | Y30: =VLOOKUP($B30,$R$3:$Z$9,8,FALSE) -> #N/A | Z30: =VLOOKUP($B30,$R$3:$Z$9,9,FALSE) -> #N/A
K31: =SUM(K21:K30) -> 4 | L31: =((L21*K21)+(L22*K22)+(L23*K23)+(L24*K24)+(L25*K25)+(K28*L28)+(L26*K26)+(L27*K27)+(L30*K30))/(K31) -> 99.340321 | M31: =L31 -> 99.340321 | N31: 98 | R31: =B31 -> 0 | S31: =VLOOKUP($B31,$R$3:$X$9,2,FALSE) -> #N/A | T31: =VLOOKUP($B31,$R$3:$X$9,3,FALSE) -> #N/A | U31: =VLOOKUP($B31,$R$3:$X$9,4,FALSE) -> #N/A | V31: =VLOOKUP($B31,$R$3:$X$9,5,FALSE) -> #N/A | W31: =VLOOKUP($B31,$R$3:$X$9,6,FALSE) -> #N/A | X31: =VLOOKUP($B31,$R$3:$X$9,7,FALSE) -> #N/A | Y31: =VLOOKUP($B31,$R$3:$Z$9,8,FALSE) -> #N/A | Z31: =VLOOKUP($B31,$R$3:$Z$9,9,FALSE) -> #N/A
R32: =B32 -> 0 | S32: =VLOOKUP($B32,$R$3:$X$9,2,FALSE) -> #N/A | T32: =VLOOKUP($B32,$R$3:$X$9,3,FALSE) -> #N/A | U32: =VLOOKUP($B32,$R$3:$X$9,4,FALSE) -> #N/A | V32: =VLOOKUP($B32,$R$3:$X$9,5,FALSE) -> #N/A | W32: =VLOOKUP($B32,$R$3:$X$9,6,FALSE) -> #N/A | X32: =VLOOKUP($B32,$R$3:$X$9,7,FALSE) -> #N/A | Y32: =VLOOKUP($B32,$R$3:$Z$9,8,FALSE) -> #N/A | Z32: =VLOOKUP($B32,$R$3:$Z$9,9,FALSE) -> #N/A
J33: Daily Brewing Plan
J34: Brand | K34: Brews Achieved | L34: Average Brews per day
J35: CARIB | K35: 4 | L35: MTD | M35: YTD | N35: TARGET
J36: STAG | L36: =AVERAGE('Jan 2nd'!K45) -> 4 | M36: =AVERAGE(L36) -> 4 | N36: 9.2
J37: GUINN
J38: VITAMALT
J39: STARMALT
J40: MACKESON
...

Sheet Jan 5th
S1: P.G. | U1: Hot Time | W1: Process Time | Y1: Cooling Time
B2: Brewing Department Daily Process Loss Report | S2: Lower | T2: Upper | U2: Lower | V2: Upper | W2: Lower | X2: Upper | Y2: Lower | Z2: Upper
R3: CARIB | S3: 11.6 | T3: 12 | U3: 0 | V3: 0.11805556 | W3: 0.22569444 | X3: 0.26388889 | Y3: 0 | Z3: 60 | AB3: HR- PISNER
B4: Date: | C4: 46028 | J4: LOT WORT COLOUR: | M4: Filter Sheets (Target 20 days) | R4: STAG | S4: 11.6 | T4: 12 | U4: 0 | V4: 0.11805556 | W4: 0.22569444 | X4: 0.26388889 | Y4: 0 | Z4: 60
M5: Double | N5: Single | R5: GUINNESS | S5: 17 | T5: 17.5 | U5: 0 | V5: 0.10763889 | W5: 0.24652778 | X5: 0.28472222 | Y5: 0 | Z5: 60
J6: MALT LOT: Lot #8 | L6: Sheet Day | R6: MACKESON | S6: 13.3 | T6: 13.5 | U6: 0 | V6: 0.12905093 | W6: 0.27430556 | X6: 0.30208333 | Y6: 0
R7: STARMALT | S7: 17 | T7: 17.4 | U7: 0 | V7: 0.13605324 | W7: 0.27430556 | X7: 0.30902778 | Y7: 0 | Z7: 85
B8: Brand | C8: Brew no. | D8: Kett. Hls | E8: Wort | F8: Cool Time(Mins) | G8: Cast. P.G. (Lab Result) | H8: Cast P.G. (Cellar Operator)-gravity | I8: Extr. Rec (77.9%) | J8: Theor. Extr. (77.5%) | K8: Boil Off /Vol. (4-6%) | L8: Boil Time | M8: Total Hot | N8: Brewing | O8: Operator | R8: Hurricane Reef | S8: 16.6 | T8: 17 | U8: 0 | V8: 0.12905093 | W8: 0.27430556 | X8: 0.30208333 | Y8: 0
E9: Meter (Hls) | F9: Target(< 60Mins) | M9: Time | R9: VITAMALT | S9: 14.2 | T9: 14.6 | U9: 0 | V9: 0.13905093 | W9: 0.26041667 | X9: 0.29513889 | Y9: 0 | Z9: 75
B10: STAG | C10: =[5]Brewhouse!$A51 -> ST001 | D10: DUMPED | R10: =B10 -> STAG | S10: =VLOOKUP($B10,$R$3:$X$9,2,FALSE) -> 11.6 | T10: =VLOOKUP($B10,$R$3:$X$9,3,FALSE) -> 12 | U10: =VLOOKUP($B10,$R$3:$X$9,4,FALSE) -> 0 | V10: =VLOOKUP($B10,$R$3:$X$9,5,FALSE) -> 0.11805556 | W10: =VLOOKUP($B10,$R$3:$X$9,6,FALSE) -> 0.22569444 | X10: =VLOOKUP($B10,$R$3:$X$9,7,FALSE) -> 0.26388889 | Y10: =VLOOKUP($B10,$R$3:$Z$9,8,FALSE) -> 0 | Z10: =VLOOKUP($B10,$R$3:$Z$9,9,FALSE) -> 60
R11: =B11 -> 0 | S11: =VLOOKUP($B11,$R$3:$X$9,2,FALSE) -> #N/A | T11: =VLOOKUP($B11,$R$3:$X$9,3,FALSE) -> #N/A | U11: =VLOOKUP($B11,$R$3:$X$9,4,FALSE) -> #N/A | V11: =VLOOKUP($B11,$R$3:$X$9,5,FALSE) -> #N/A | W11: =VLOOKUP($B11,$R$3:$X$9,6,FALSE) -> #N/A | X11: =VLOOKUP($B11,$R$3:$X$9,7,FALSE) -> #N/A | Y11: =VLOOKUP($B11,$R$3:$Z$9,8,FALSE) -> #N/A | Z11: =VLOOKUP($B11,$R$3:$Z$9,9,FALSE) -> #N/A
B12: STARMALT | C12: =[8]Brewhouse!$A5 -> SM001 | D12: =[8]Brewhouse!$AH5 -> 53.1 | E12: =[8]Brewhouse!$AM5 -> 52 | F12: =[8]Brewhouse!$Z5 -> 66 | G12: =[8]Brewhouse!$AK5 -> 17.1 | H12: 17 | I12: =[8]Brewhouse!$AY5 -> 97.569472 | J12: =[8]Brewhouse!$AZ5 -> 97.939158 | K12: =[8]Brewhouse!$U5 -> 4.8587571 | L12: =[8]Brewhouse!$T5 -> 59 | M12: =[8]Brewhouse!$Y5-[8]Brewhouse!$X5 -> 0.14097222 | N12: =[8]Brewhouse!$AD5 -> 0.30486111 | O12: =[8]Brewhouse!$BC5 -> R. Regis | R12: =B12 -> STARMALT | S12: =VLOOKUP($B12,$R$3:$X$9,2,FALSE) -> 17 | T12: =VLOOKUP($B12,$R$3:$X$9,3,FALSE) -> 17.4 | U12: =VLOOKUP($B12,$R$3:$X$9,4,FALSE) -> 0 | V12: =VLOOKUP($B12,$R$3:$X$9,5,FALSE) -> 0.13605324 | W12: =VLOOKUP($B12,$R$3:$X$9,6,FALSE) -> 0.27430556 | X12: =VLOOKUP($B12,$R$3:$X$9,7,FALSE) -> 0.30902778 | Y12: =VLOOKUP($B12,$R$3:$Z$9,8,FALSE) -> 0 | Z12: =VLOOKUP($B12,$R$3:$Z$9,9,FALSE) -> 85
B13: STARMALT | C13: =[8]Brewhouse!$A6 -> SM002 | D13: =[8]Brewhouse!$AH6 -> 53 | E13: =[8]Brewhouse!$AM6 -> 52.6 | F13: =[8]Brewhouse!$Z6 -> 73 | G13: =[8]Brewhouse!$AK6 -> 17.1 | H13: 17.1 | I13: =[8]Brewhouse!$AY6 -> 98.853919 | J13: =[8]Brewhouse!$AZ6 -> 99.22778 | K13: =[8]Brewhouse!$U6 -> 2.4150943 | L13: =[8]Brewhouse!$T6 -> 60 | M13: =[8]Brewhouse!$Y6-[8]Brewhouse!$X6 -> 0.15138889 | N13: =[8]Brewhouse!$AD6 -> 0.32847222 | O13: =[8]Brewhouse!$BC6 -> K. Benjamin | R13: =B13 -> STARMALT | S13: =VLOOKUP($B13,$R$3:$X$9,2,FALSE) -> 17 | T13: =VLOOKUP($B13,$R$3:$X$9,3,FALSE) -> 17.4 | U13: =VLOOKUP($B13,$R$3:$X$9,4,FALSE) -> 0 | V13: =VLOOKUP($B13,$R$3:$X$9,5,FALSE) -> 0.13605324 | W13: =VLOOKUP($B13,$R$3:$X$9,6,FALSE) -> 0.27430556 | X13: =VLOOKUP($B13,$R$3:$X$9,7,FALSE) -> 0.30902778 | Y13: =VLOOKUP($B13,$R$3:$Z$9,8,FALSE) -> 0 | Z13: =VLOOKUP($B13,$R$3:$Z$9,9,FALSE) -> 85
B14: STARMALT | C14: =[8]Brewhouse!$A7 -> SM003 | D14: =[8]Brewhouse!$AH7 -> 53 | E14: =[8]Brewhouse!$AM7 -> 52 | F14: =[8]Brewhouse!$Z7 -> 70 | G14: =[8]Brewhouse!$AK7 -> 17.1 | H14: 17.2 | I14: =[8]Brewhouse!$AY7 -> 97.962509 | J14: =[8]Brewhouse!$AZ7 -> 98.331967 | K14: =[8]Brewhouse!$U7 -> 1.2830189 | L14: =[8]Brewhouse!$T7 -> 60 | M14: =[8]Brewhouse!$Y7-[8]Brewhouse!$X7 -> 0.13819444 | N14: =[8]Brewhouse!$AD7 -> 0.31180556 | O14: =[8]Brewhouse!$BC7 -> K. Benjamin | R14: =B14 -> STARMALT | S14: =VLOOKUP($B14,$R$3:$X$9,2,FALSE) -> 17 | T14: =VLOOKUP($B14,$R$3:$X$9,3,FALSE) -> 17.4 | U14: =VLOOKUP($B14,$R$3:$X$9,4,FALSE) -> 0 | V14: =VLOOKUP($B14,$R$3:$X$9,5,FALSE) -> 0.13605324 | W14: =VLOOKUP($B14,$R$3:$X$9,6,FALSE) -> 0.27430556 | X14: =VLOOKUP($B14,$R$3:$X$9,7,FALSE) -> 0.30902778 | Y14: =VLOOKUP($B14,$R$3:$Z$9,8,FALSE) -> 0 | Z14: =VLOOKUP($B14,$R$3:$Z$9,9,FALSE) -> 85
R15: =B15 -> 0 | S15: =VLOOKUP($B15,$R$3:$X$9,2,FALSE) -> #N/A | T15: =VLOOKUP($B15,$R$3:$X$9,3,FALSE) -> #N/A | U15: =VLOOKUP($B15,$R$3:$X$9,4,FALSE) -> #N/A | V15: =VLOOKUP($B15,$R$3:$X$9,5,FALSE) -> #N/A | W15: =VLOOKUP($B15,$R$3:$X$9,6,FALSE) -> #N/A | X15: =VLOOKUP($B15,$R$3:$X$9,7,FALSE) -> #N/A | Y15: =VLOOKUP($B15,$R$3:$Z$9,8,FALSE) -> #N/A | Z15: =VLOOKUP($B15,$R$3:$Z$9,9,FALSE) -> #N/A
R16: =B16 -> 0 | S16: =VLOOKUP($B16,$R$3:$X$9,2,FALSE) -> #N/A | T16: =VLOOKUP($B16,$R$3:$X$9,3,FALSE) -> #N/A | U16: =VLOOKUP($B16,$R$3:$X$9,4,FALSE) -> #N/A | V16: =VLOOKUP($B16,$R$3:$X$9,5,FALSE) -> #N/A | W16: =VLOOKUP($B16,$R$3:$X$9,6,FALSE) -> #N/A | X16: =VLOOKUP($B16,$R$3:$X$9,7,FALSE) -> #N/A | Y16: =VLOOKUP($B16,$R$3:$Z$9,8,FALSE) -> #N/A | Z16: =VLOOKUP($B16,$R$3:$Z$9,9,FALSE) -> #N/A
R17: =B17 -> 0 | S17: =VLOOKUP($B17,$R$3:$X$9,2,FALSE) -> #N/A | T17: =VLOOKUP($B17,$R$3:$X$9,3,FALSE) -> #N/A | U17: =VLOOKUP($B17,$R$3:$X$9,4,FALSE) -> #N/A | V17: =VLOOKUP($B17,$R$3:$X$9,5,FALSE) -> #N/A | W17: =VLOOKUP($B17,$R$3:$X$9,6,FALSE) -> #N/A | X17: =VLOOKUP($B17,$R$3:$X$9,7,FALSE) -> #N/A | Y17: =VLOOKUP($B17,$R$3:$Z$9,8,FALSE) -> #N/A | Z17: =VLOOKUP($B17,$R$3:$Z$9,9,FALSE) -> #N/A
R18: =B18 -> 0 | S18: =VLOOKUP($B18,$R$3:$X$9,2,FALSE) -> #N/A | T18: =VLOOKUP($B18,$R$3:$X$9,3,FALSE) -> #N/A | U18: =VLOOKUP($B18,$R$3:$X$9,4,FALSE) -> #N/A | V18: =VLOOKUP($B18,$R$3:$X$9,5,FALSE) -> #N/A | W18: =VLOOKUP($B18,$R$3:$X$9,6,FALSE) -> #N/A | X18: =VLOOKUP($B18,$R$3:$X$9,7,FALSE) -> #N/A | Y18: =VLOOKUP($B18,$R$3:$Z$9,8,FALSE) -> #N/A | Z18: =VLOOKUP($B18,$R$3:$Z$9,9,FALSE) -> #N/A
R19: =B19 -> 0 | S19: =VLOOKUP($B19,$R$3:$X$9,2,FALSE) -> #N/A | T19: =VLOOKUP($B19,$R$3:$X$9,3,FALSE) -> #N/A | U19: =VLOOKUP($B19,$R$3:$X$9,4,FALSE) -> #N/A | V19: =VLOOKUP($B19,$R$3:$X$9,5,FALSE) -> #N/A | W19: =VLOOKUP($B19,$R$3:$X$9,6,FALSE) -> #N/A | X19: =VLOOKUP($B19,$R$3:$X$9,7,FALSE) -> #N/A | Y19: =VLOOKUP($B19,$R$3:$Z$9,8,FALSE) -> #N/A | Z19: =VLOOKUP($B19,$R$3:$Z$9,9,FALSE) -> #N/A
B20: BRAND | D20: BBT P.G./ O.G | I20: Brand | K20: MTD No. of Brews | L20: MTD | M20: YTD | N20: Target | R20: =B20 -> BRAND | S20: =VLOOKUP($B20,$R$3:$X$9,2,FALSE) -> #N/A | T20: =VLOOKUP($B20,$R$3:$X$9,3,FALSE) -> #N/A | U20: =VLOOKUP($B20,$R$3:$X$9,4,FALSE) -> #N/A | V20: =VLOOKUP($B20,$R$3:$X$9,5,FALSE) -> #N/A | W20: =VLOOKUP($B20,$R$3:$X$9,6,FALSE) -> #N/A | X20: =VLOOKUP($B20,$R$3:$X$9,7,FALSE) -> #N/A | Y20: =VLOOKUP($B20,$R$3:$Z$9,8,FALSE) -> #N/A | Z20: =VLOOKUP($B20,$R$3:$Z$9,9,FALSE) -> #N/A
B21: =I21 -> CARIB | I21: CARIB | K21: =COUNTA([4]Brewhouse!$A$42:$A$45) -> 4 | L21: =AVERAGE([4]Brewhouse!$AU$42:$AU$45) -> 99.340321 | M21: =AVERAGE([4]Brewhouse!$AU$42:$AU$45) -> 99.340321 | N21: 98 | R21: =B21 -> CARIB | S21: =VLOOKUP($B21,$R$3:$X$9,2,FALSE) -> 11.6 | T21: =VLOOKUP($B21,$R$3:$X$9,3,FALSE) -> 12 | U21: =VLOOKUP($B21,$R$3:$X$9,4,FALSE) -> 0 | V21: =VLOOKUP($B21,$R$3:$X$9,5,FALSE) -> 0.11805556 | W21: =VLOOKUP($B21,$R$3:$X$9,6,FALSE) -> 0.22569444 | X21: =VLOOKUP($B21,$R$3:$X$9,7,FALSE) -> 0.26388889 | Y21: =VLOOKUP($B21,$R$3:$Z$9,8,FALSE) -> 0 | Z21: =VLOOKUP($B21,$R$3:$Z$9,9,FALSE) -> 60
I22: STAG | N22: 98 | R22: =B22 -> 0 | S22: =VLOOKUP($B22,$R$3:$X$9,2,FALSE) -> #N/A | T22: =VLOOKUP($B22,$R$3:$X$9,3,FALSE) -> #N/A | U22: =VLOOKUP($B22,$R$3:$X$9,4,FALSE) -> #N/A | V22: =VLOOKUP($B22,$R$3:$X$9,5,FALSE) -> #N/A | W22: =VLOOKUP($B22,$R$3:$X$9,6,FALSE) -> #N/A | X22: =VLOOKUP($B22,$R$3:$X$9,7,FALSE) -> #N/A | Y22: =VLOOKUP($B22,$R$3:$Z$9,8,FALSE) -> #N/A | Z22: =VLOOKUP($B22,$R$3:$Z$9,9,FALSE) -> #N/A
I23: GUINNESS | N23: 98 | R23: =B23 -> 0 | S23: =VLOOKUP($B23,$R$3:$X$9,2,FALSE) -> #N/A | T23: =VLOOKUP($B23,$R$3:$X$9,3,FALSE) -> #N/A | U23: =VLOOKUP($B23,$R$3:$X$9,4,FALSE) -> #N/A | V23: =VLOOKUP($B23,$R$3:$X$9,5,FALSE) -> #N/A | W23: =VLOOKUP($B23,$R$3:$X$9,6,FALSE) -> #N/A | X23: =VLOOKUP($B23,$R$3:$X$9,7,FALSE) -> #N/A | Y23: =VLOOKUP($B23,$R$3:$Z$9,8,FALSE) -> #N/A | Z23: =VLOOKUP($B23,$R$3:$Z$9,9,FALSE) -> #N/A
I24: VITAMALT | N24: 98 | R24: =B24 -> 0 | S24: =VLOOKUP($B24,$R$3:$X$9,2,FALSE) -> #N/A | T24: =VLOOKUP($B24,$R$3:$X$9,3,FALSE) -> #N/A | U24: =VLOOKUP($B24,$R$3:$X$9,4,FALSE) -> #N/A | V24: =VLOOKUP($B24,$R$3:$X$9,5,FALSE) -> #N/A | W24: =VLOOKUP($B24,$R$3:$X$9,6,FALSE) -> #N/A | X24: =VLOOKUP($B24,$R$3:$X$9,7,FALSE) -> #N/A | Y24: =VLOOKUP($B24,$R$3:$Z$9,8,FALSE) -> #N/A | Z24: =VLOOKUP($B24,$R$3:$Z$9,9,FALSE) -> #N/A
I25: MAXIMALT | N25: 98 | R25: =B25 -> 0 | S25: =VLOOKUP($B25,$R$3:$X$9,2,FALSE) -> #N/A | T25: =VLOOKUP($B25,$R$3:$X$9,3,FALSE) -> #N/A | U25: =VLOOKUP($B25,$R$3:$X$9,4,FALSE) -> #N/A | V25: =VLOOKUP($B25,$R$3:$X$9,5,FALSE) -> #N/A | W25: =VLOOKUP($B25,$R$3:$X$9,6,FALSE) -> #N/A | X25: =VLOOKUP($B25,$R$3:$X$9,7,FALSE) -> #N/A | Y25: =VLOOKUP($B25,$R$3:$Z$9,8,FALSE) -> #N/A | Z25: =VLOOKUP($B25,$R$3:$Z$9,9,FALSE) -> #N/A
I26: MACKESON | N26: 98 | R26: =B26 -> 0 | S26: =VLOOKUP($B26,$R$3:$X$9,2,FALSE) -> #N/A | T26: =VLOOKUP($B26,$R$3:$X$9,3,FALSE) -> #N/A | U26: =VLOOKUP($B26,$R$3:$X$9,4,FALSE) -> #N/A | V26: =VLOOKUP($B26,$R$3:$X$9,5,FALSE) -> #N/A | W26: =VLOOKUP($B26,$R$3:$X$9,6,FALSE) -> #N/A | X26: =VLOOKUP($B26,$R$3:$X$9,7,FALSE) -> #N/A | Y26: =VLOOKUP($B26,$R$3:$Z$9,8,FALSE) -> #N/A | Z26: =VLOOKUP($B26,$R$3:$Z$9,9,FALSE) -> #N/A
I27: STARMALT | J27: =AVERAGE(I12:I14) -> 98.128633 | K27: =COUNTA([8]Brewhouse!$A$5:$A$7) -> 3 | L27: =AVERAGE([8]Brewhouse!$AY$5:$AY$7) -> 98.128633 | M27: =AVERAGE([8]Brewhouse!$AY$5:$AY$7) -> 98.128633 | N27: 98 | R27: =B27 -> 0 | S27: =VLOOKUP($B27,$R$3:$X$9,2,FALSE) -> #N/A | T27: =VLOOKUP($B27,$R$3:$X$9,3,FALSE) -> #N/A | U27: =VLOOKUP($B27,$R$3:$X$9,4,FALSE) -> #N/A | V27: =VLOOKUP($B27,$R$3:$X$9,5,FALSE) -> #N/A | W27: =VLOOKUP($B27,$R$3:$X$9,6,FALSE) -> #N/A | X27: =VLOOKUP($B27,$R$3:$X$9,7,FALSE) -> #N/A | Y27: =VLOOKUP($B27,$R$3:$Z$9,8,FALSE) -> #N/A | Z27: =VLOOKUP($B27,$R$3:$Z$9,9,FALSE) -> #N/A
I28: HR- Pils | N28: 98 | R28: =B28 -> 0 | S28: =VLOOKUP($B28,$R$3:$X$9,2,FALSE) -> #N/A | T28: =VLOOKUP($B28,$R$3:$X$9,3,FALSE) -> #N/A | U28: =VLOOKUP($B28,$R$3:$X$9,4,FALSE) -> #N/A | V28: =VLOOKUP($B28,$R$3:$X$9,5,FALSE) -> #N/A | W28: =VLOOKUP($B28,$R$3:$X$9,6,FALSE) -> #N/A | X28: =VLOOKUP($B28,$R$3:$X$9,7,FALSE) -> #N/A | Y28: =VLOOKUP($B28,$R$3:$Z$9,8,FALSE) -> #N/A | Z28: =VLOOKUP($B28,$R$3:$Z$9,9,FALSE) -> #N/A
I29: HR- IPA | N29: 98 | R29: =B29 -> 0 | S29: =VLOOKUP($B29,$R$3:$X$9,2,FALSE) -> #N/A | T29: =VLOOKUP($B29,$R$3:$X$9,3,FALSE) -> #N/A | U29: =VLOOKUP($B29,$R$3:$X$9,4,FALSE) -> #N/A | V29: =VLOOKUP($B29,$R$3:$X$9,5,FALSE) -> #N/A | W29: =VLOOKUP($B29,$R$3:$X$9,6,FALSE) -> #N/A | X29: =VLOOKUP($B29,$R$3:$X$9,7,FALSE) -> #N/A | Y29: =VLOOKUP($B29,$R$3:$Z$9,8,FALSE) -> #N/A | Z29: =VLOOKUP($B29,$R$3:$Z$9,9,FALSE) -> #N/A
I30: HR- APA | N30: 98 | R30: =B30 -> 0 | S30: =VLOOKUP($B30,$R$3:$X$9,2,FALSE) -> #N/A | T30: =VLOOKUP($B30,$R$3:$X$9,3,FALSE) -> #N/A | U30: =VLOOKUP($B30,$R$3:$X$9,4,FALSE) -> #N/A | V30: =VLOOKUP($B30,$R$3:$X$9,5,FALSE) -> #N/A | W30: =VLOOKUP($B30,$R$3:$X$9,6,FALSE) -> #N/A | X30: =VLOOKUP($B30,$R$3:$X$9,7,FALSE) -> #N/A | Y30: =VLOOKUP($B30,$R$3:$Z$9,8,FALSE) -> #N/A | Z30: =VLOOKUP($B30,$R$3:$Z$9,9,FALSE) -> #N/A
K31: =SUM(K21:K30) -> 7 | L31: =((L21*K21)+(L22*K22)+(L23*K23)+(L24*K24)+(L25*K25)+(K28*L28)+(L26*K26)+(L27*K27)+(L30*K30))/(K31) -> 98.821026 | M31: =L31 -> 98.821026 | N31: 98 | R31: =B31 -> 0 | S31: =VLOOKUP($B31,$R$3:$X$9,2,FALSE) -> #N/A | T31: =VLOOKUP($B31,$R$3:$X$9,3,FALSE) -> #N/A | U31: =VLOOKUP($B31,$R$3:$X$9,4,FALSE) -> #N/A | V31: =VLOOKUP($B31,$R$3:$X$9,5,FALSE) -> #N/A | W31: =VLOOKUP($B31,$R$3:$X$9,6,FALSE) -> #N/A | X31: =VLOOKUP($B31,$R$3:$X$9,7,FALSE) -> #N/A | Y31: =VLOOKUP($B31,$R$3:$Z$9,8,FALSE) -> #N/A | Z31: =VLOOKUP($B31,$R$3:$Z$9,9,FALSE) -> #N/A
R32: =B32 -> 0 | S32: =VLOOKUP($B32,$R$3:$X$9,2,FALSE) -> #N/A | T32: =VLOOKUP($B32,$R$3:$X$9,3,FALSE) -> #N/A | U32: =VLOOKUP($B32,$R$3:$X$9,4,FALSE) -> #N/A | V32: =VLOOKUP($B32,$R$3:$X$9,5,FALSE) -> #N/A | W32: =VLOOKUP($B32,$R$3:$X$9,6,FALSE) -> #N/A | X32: =VLOOKUP($B32,$R$3:$X$9,7,FALSE) -> #N/A | Y32: =VLOOKUP($B32,$R$3:$Z$9,8,FALSE) -> #N/A | Z32: =VLOOKUP($B32,$R$3:$Z$9,9,FALSE) -> #N/A
J33: Daily Brewing Plan
J34: Brand | K34: Brews Achieved | L34: Average Brews per day
J35: CARIB | L35: MTD | M35: YTD | N35: TARGET
J36: STAG | L36: =AVERAGE('Jan 2nd'!K45,'Jan 5th'!K45) -> 3.5 | M36: =AVERAGE(L36) -> 3.5 | N36: 9.2
J37: GUINN
J38: VITAMALT
J39: STARMALT | K39: 3
J40: MACKESON
...

Sheet Jan 6th
S1: P.G. | U1: Hot Time | W1: Process Time | Y1: Cooling Time
B2: Brewing Department Daily Process Loss Report | S2: Lower | T2: Upper | U2: Lower | V2: Upper | W2: Lower | X2: Upper | Y2: Lower | Z2: Upper
R3: CARIB | S3: 11.6 | T3: 12 | U3: 0 | V3: 0.11805556 | W3: 0.22569444 | X3: 0.26388889 | Y3: 0 | Z3: 60 | AB3: HR- PISNER
B4: Date: | C4: 46029 | J4: LOT WORT COLOUR: | M4: Filter Sheets (Target 20 days) | R4: STAG | S4: 11.6 | T4: 12 | U4: 0 | V4: 0.11805556 | W4: 0.22569444 | X4: 0.26388889 | Y4: 0 | Z4: 60
M5: Double | N5: Single | R5: GUINNESS | S5: 17 | T5: 17.5 | U5: 0 | V5: 0.10763889 | W5: 0.24652778 | X5: 0.28472222 | Y5: 0 | Z5: 60
J6: MALT LOT: Lot #8 | L6: Sheet Day | R6: MACKESON | S6: 13.3 | T6: 13.5 | U6: 0 | V6: 0.12905093 | W6: 0.27430556 | X6: 0.30208333 | Y6: 0
R7: STARMALT | S7: 17 | T7: 17.4 | U7: 0 | V7: 0.13605324 | W7: 0.27430556 | X7: 0.30902778 | Y7: 0 | Z7: 85
B8: Brand | C8: Brew no. | D8: Kett. Hls | E8: Wort | F8: Cool Time(Mins) | G8: Cast. P.G. (Lab Result) | H8: Cast P.G. (Cellar Operator)-gravity | I8: Extr. Rec (77.9%) | J8: Theor. Extr. (77.5%) | K8: Boil Off /Vol. (4-6%) | L8: Boil Time | M8: Total Hot | N8: Brewing | O8: Operator | R8: Hurricane Reef | S8: 16.6 | T8: 17 | U8: 0 | V8: 0.12905093 | W8: 0.27430556 | X8: 0.30208333 | Y8: 0
E9: Meter (Hls) | F9: Target(< 60Mins) | M9: Time | R9: VITAMALT | S9: 14.2 | T9: 14.6 | U9: 0 | V9: 0.13905093 | W9: 0.26041667 | X9: 0.29513889 | Y9: 0 | Z9: 75
B10: STARMALT | C10: =[8]Brewhouse!$A8 -> SM004 | D10: =[8]Brewhouse!$AH8 -> 53 | E10: =[8]Brewhouse!$AM8 -> 52.2 | F10: =[8]Brewhouse!$Z8 -> 70 | G10: =[8]Brewhouse!$AK8 -> 17.2 | H10: 17.2 | I10: =[8]Brewhouse!$AY8 -> 98.851729 | J10: =[8]Brewhouse!$AZ8 -> 99.224888 | K10: =[8]Brewhouse!$U8 -> 0.90566038 | L10: =[8]Brewhouse!$T8 -> 61 | M10: =[8]Brewhouse!$Y8-[8]Brewhouse!$X8 -> 0.14375 | N10: =[8]Brewhouse!$AD8 -> 0.31041667 | O10: =[8]Brewhouse!$BC8 -> K. Benjamin | R10: =B10 -> STARMALT | S10: =VLOOKUP($B10,$R$3:$X$9,2,FALSE) -> 17 | T10: =VLOOKUP($B10,$R$3:$X$9,3,FALSE) -> 17.4 | U10: =VLOOKUP($B10,$R$3:$X$9,4,FALSE) -> 0 | V10: =VLOOKUP($B10,$R$3:$X$9,5,FALSE) -> 0.13605324 | W10: =VLOOKUP($B10,$R$3:$X$9,6,FALSE) -> 0.27430556 | X10: =VLOOKUP($B10,$R$3:$X$9,7,FALSE) -> 0.30902778 | Y10: =VLOOKUP($B10,$R$3:$Z$9,8,FALSE) -> 0 | Z10: =VLOOKUP($B10,$R$3:$Z$9,9,FALSE) -> 85
B11: STARMALT | C11: =[8]Brewhouse!$A9 -> SM005 | D11: =[8]Brewhouse!$AH9 -> 53.1 | E11: =[8]Brewhouse!$AM9 -> 51.3 | F11: =[8]Brewhouse!$Z9 -> 60 | G11: =[8]Brewhouse!$AK9 -> 17.1 | H11: 17.2 | I11: =[8]Brewhouse!$AY9 -> 96.643783 | J11: =[8]Brewhouse!$AZ9 -> 97.008267 | K11: =[8]Brewhouse!$U9 -> 2.4105461 | L11: =[8]Brewhouse!$T9 -> 61 | M11: =[8]Brewhouse!$Y9-[8]Brewhouse!$X9 -> 0.13194444 | N11: =[8]Brewhouse!$AD9 -> 0.30208333 | O11: =[8]Brewhouse!$BC9 -> R.Sookram | R11: =B11 -> STARMALT | S11: =VLOOKUP($B11,$R$3:$X$9,2,FALSE) -> 17 | T11: =VLOOKUP($B11,$R$3:$X$9,3,FALSE) -> 17.4 | U11: =VLOOKUP($B11,$R$3:$X$9,4,FALSE) -> 0 | V11: =VLOOKUP($B11,$R$3:$X$9,5,FALSE) -> 0.13605324 | W11: =VLOOKUP($B11,$R$3:$X$9,6,FALSE) -> 0.27430556 | X11: =VLOOKUP($B11,$R$3:$X$9,7,FALSE) -> 0.30902778 | Y11: =VLOOKUP($B11,$R$3:$Z$9,8,FALSE) -> 0 | Z11: =VLOOKUP($B11,$R$3:$Z$9,9,FALSE) -> 85
B12: STARMALT | C12: =[8]Brewhouse!$A10 -> SM006 | D12: =[8]Brewhouse!$AH10 -> 53.1 | E12: =[8]Brewhouse!$AM10 -> 50.4 | F12: =[8]Brewhouse!$Z10 -> 78 | G12: =[8]Brewhouse!$AK10 -> 17 | H12: 17 | I12: =[8]Brewhouse!$AY10 -> 94.324644 | J12: =[8]Brewhouse!$AZ10 -> 94.680382 | K12: =[8]Brewhouse!$U10 -> 3.1638418 | L12: =[8]Brewhouse!$T10 -> 60 | M12: =[8]Brewhouse!$Y10-[8]Brewhouse!$X10 -> 0.14583333 | N12: =[8]Brewhouse!$AD10 -> 0.30833333 | O12: =[8]Brewhouse!$BC10 -> R.Sookram | R12: =B12 -> STARMALT | S12: =VLOOKUP($B12,$R$3:$X$9,2,FALSE) -> 17 | T12: =VLOOKUP($B12,$R$3:$X$9,3,FALSE) -> 17.4 | U12: =VLOOKUP($B12,$R$3:$X$9,4,FALSE) -> 0 | V12: =VLOOKUP($B12,$R$3:$X$9,5,FALSE) -> 0.13605324 | W12: =VLOOKUP($B12,$R$3:$X$9,6,FALSE) -> 0.27430556 | X12: =VLOOKUP($B12,$R$3:$X$9,7,FALSE) -> 0.30902778 | Y12: =VLOOKUP($B12,$R$3:$Z$9,8,FALSE) -> 0 | Z12: =VLOOKUP($B12,$R$3:$Z$9,9,FALSE) -> 85
B13: STARMALT | C13: =[8]Brewhouse!$A11 -> SM007 | D13: =[8]Brewhouse!$AH11 -> 53.1 | E13: =[8]Brewhouse!$AM11 -> 49.3 | F13: =[8]Brewhouse!$Z11 -> 91 | G13: =[8]Brewhouse!$AK11 -> 17 | H13: 17 | I13: =[8]Brewhouse!$AY11 -> 92.117541 | J13: =[8]Brewhouse!$AZ11 -> 92.465603 | K13: =[8]Brewhouse!$U11 -> 5.2354049 | L13: =[8]Brewhouse!$T11 -> 59 | M13: =[8]Brewhouse!$Y11-[8]Brewhouse!$X11 -> 0.15694444 | N13: =[8]Brewhouse!$AD11 -> 0.33055556 | O13: =[8]Brewhouse!$BC11 -> R.Sookram | R13: =B13 -> STARMALT | S13: =VLOOKUP($B13,$R$3:$X$9,2,FALSE) -> 17 | T13: =VLOOKUP($B13,$R$3:$X$9,3,FALSE) -> 17.4 | U13: =VLOOKUP($B13,$R$3:$X$9,4,FALSE) -> 0 | V13: =VLOOKUP($B13,$R$3:$X$9,5,FALSE) -> 0.13605324 | W13: =VLOOKUP($B13,$R$3:$X$9,6,FALSE) -> 0.27430556 | X13: =VLOOKUP($B13,$R$3:$X$9,7,FALSE) -> 0.30902778 | Y13: =VLOOKUP($B13,$R$3:$Z$9,8,FALSE) -> 0 | Z13: =VLOOKUP($B13,$R$3:$Z$9,9,FALSE) -> 85
B14: STARMALT | C14: =[8]Brewhouse!$A12 -> SM008 | D14: =[8]Brewhouse!$AH12 -> 53.1 | E14: =[8]Brewhouse!$AM12 -> 51.6 | F14: =[8]Brewhouse!$Z12 -> 66 | G14: =[8]Brewhouse!$AK12 -> 17.1 | H14: 17.1 | I14: =[8]Brewhouse!$AY12 -> 97.208952 | J14: =[8]Brewhouse!$AZ12 -> 97.575567 | K14: =[8]Brewhouse!$U12 -> 1.4689266 | L14: =[8]Brewhouse!$T12 -> 60 | M14: =[8]Brewhouse!$Y12-[8]Brewhouse!$X12 -> 0.12569444 | N14: =[8]Brewhouse!$AD12 -> 0.30555556 | O14: =[8]Brewhouse!$BC12 -> R.Sookram | R14: =B14 -> STARMALT | S14: =VLOOKUP($B14,$R$3:$X$9,2,FALSE) -> 17 | T14: =VLOOKUP($B14,$R$3:$X$9,3,FALSE) -> 17.4 | U14: =VLOOKUP($B14,$R$3:$X$9,4,FALSE) -> 0 | V14: =VLOOKUP($B14,$R$3:$X$9,5,FALSE) -> 0.13605324 | W14: =VLOOKUP($B14,$R$3:$X$9,6,FALSE) -> 0.27430556 | X14: =VLOOKUP($B14,$R$3:$X$9,7,FALSE) -> 0.30902778 | Y14: =VLOOKUP($B14,$R$3:$Z$9,8,FALSE) -> 0 | Z14: =VLOOKUP($B14,$R$3:$Z$9,9,FALSE) -> 85
B15: STARMALT | C15: =[8]Brewhouse!$A13 -> SM009 | D15: =[8]Brewhouse!$AH13 -> 53.1 | E15: =[8]Brewhouse!$AM13 -> 51.6 | F15: =[8]Brewhouse!$Z13 -> 81 | G15: =[8]Brewhouse!$AK13 -> 17.3 | I15: =[8]Brewhouse!$AY13 -> 98.512077 | J15: =[8]Brewhouse!$AZ13 -> 98.883259 | K15: =[8]Brewhouse!$U13 -> 1.6572505 | L15: =[8]Brewhouse!$T13 -> 59 | M15: =[8]Brewhouse!$Y13-[8]Brewhouse!$X13 -> 0.15069444 | N15: =[8]Brewhouse!$AD13 -> 0.31458333 | O15: =[8]Brewhouse!$BC13 -> R.Sookram | R15: =B15 -> STARMALT | S15: =VLOOKUP($B15,$R$3:$X$9,2,FALSE) -> 17 | T15: =VLOOKUP($B15,$R$3:$X$9,3,FALSE) -> 17.4 | U15: =VLOOKUP($B15,$R$3:$X$9,4,FALSE) -> 0 | V15: =VLOOKUP($B15,$R$3:$X$9,5,FALSE) -> 0.13605324 | W15: =VLOOKUP($B15,$R$3:$X$9,6,FALSE) -> 0.27430556 | X15: =VLOOKUP($B15,$R$3:$X$9,7,FALSE) -> 0.30902778 | Y15: =VLOOKUP($B15,$R$3:$Z$9,8,FALSE) -> 0 | Z15: =VLOOKUP($B15,$R$3:$Z$9,9,FALSE) -> 85
B16: STARMALT | C16: =[8]Brewhouse!$A14 -> SM010 | D16: =[8]Brewhouse!$AH14 -> 53.1 | E16: =[8]Brewhouse!$AM14 -> 50.3 | F16: =[8]Brewhouse!$Z14 -> 77 | G16: =[8]Brewhouse!$AK14 -> 17.2 | H16: 17.2 | I16: =[8]Brewhouse!$AY14 -> 95.253677 | J16: =[8]Brewhouse!$AZ14 -> 95.613254 | K16: =[8]Brewhouse!$U14 -> 2.9755179 | L16: =[8]Brewhouse!$T14 -> 60 | M16: =[8]Brewhouse!$Y14-[8]Brewhouse!$X14 -> 0.15138889 | N16: =[8]Brewhouse!$AD14 -> 0.31666667 | O16: =[8]Brewhouse!$BC14 -> R.Sookram | R16: =B16 -> STARMALT | S16: =VLOOKUP($B16,$R$3:$X$9,2,FALSE) -> 17 | T16: =VLOOKUP($B16,$R$3:$X$9,3,FALSE) -> 17.4 | U16: =VLOOKUP($B16,$R$3:$X$9,4,FALSE) -> 0 | V16: =VLOOKUP($B16,$R$3:$X$9,5,FALSE) -> 0.13605324 | W16: =VLOOKUP($B16,$R$3:$X$9,6,FALSE) -> 0.27430556 | X16: =VLOOKUP($B16,$R$3:$X$9,7,FALSE) -> 0.30902778 | Y16: =VLOOKUP($B16,$R$3:$Z$9,8,FALSE) -> 0 | Z16: =VLOOKUP($B16,$R$3:$Z$9,9,FALSE) -> 85
R17: =B17 -> 0 | S17: =VLOOKUP($B17,$R$3:$X$9,2,FALSE) -> #N/A | T17: =VLOOKUP($B17,$R$3:$X$9,3,FALSE) -> #N/A | U17: =VLOOKUP($B17,$R$3:$X$9,4,FALSE) -> #N/A | V17: =VLOOKUP($B17,$R$3:$X$9,5,FALSE) -> #N/A | W17: =VLOOKUP($B17,$R$3:$X$9,6,FALSE) -> #N/A | X17: =VLOOKUP($B17,$R$3:$X$9,7,FALSE) -> #N/A | Y17: =VLOOKUP($B17,$R$3:$Z$9,8,FALSE) -> #N/A | Z17: =VLOOKUP($B17,$R$3:$Z$9,9,FALSE) -> #N/A
B18: STAG | C18: =[5]Brewhouse!$A52 -> ST002 | D18: =[5]Brewhouse!$AB52 -> 52 | E18: =[5]Brewhouse!$AG52 -> 49.83 | F18: =[5]Brewhouse!$V52 -> 59 | G18: =[5]Brewhouse!$AE52 -> 11.7 | H18: 11.7 | I18: =[5]Brewhouse!$AS52 -> 104.87426 | J18: =[5]Brewhouse!$AT52 -> 105.5395 | K18: =[5]Brewhouse!$Q52 -> 3.7980769 | L18: =[5]Brewhouse!$P52 -> 60 | M18: =[5]Brewhouse!$U52-[5]Brewhouse!$T52 -> 0.15416667 | N18: =[5]Brewhouse!$AW52 -> 0.27361111 | O18: =[5]Brewhouse!$AV52 -> K. Benjamin | R18: =B18 -> STAG | S18: =VLOOKUP($B18,$R$3:$X$9,2,FALSE) -> 11.6 | T18: =VLOOKUP($B18,$R$3:$X$9,3,FALSE) -> 12 | U18: =VLOOKUP($B18,$R$3:$X$9,4,FALSE) -> 0 | V18: =VLOOKUP($B18,$R$3:$X$9,5,FALSE) -> 0.11805556 | W18: =VLOOKUP($B18,$R$3:$X$9,6,FALSE) -> 0.22569444 | X18: =VLOOKUP($B18,$R$3:$X$9,7,FALSE) -> 0.26388889 | Y18: =VLOOKUP($B18,$R$3:$Z$9,8,FALSE) -> 0 | Z18: =VLOOKUP($B18,$R$3:$Z$9,9,FALSE) -> 60
R19: =B19 -> 0 | S19: =VLOOKUP($B19,$R$3:$X$9,2,FALSE) -> #N/A | T19: =VLOOKUP($B19,$R$3:$X$9,3,FALSE) -> #N/A | U19: =VLOOKUP($B19,$R$3:$X$9,4,FALSE) -> #N/A | V19: =VLOOKUP($B19,$R$3:$X$9,5,FALSE) -> #N/A | W19: =VLOOKUP($B19,$R$3:$X$9,6,FALSE) -> #N/A | X19: =VLOOKUP($B19,$R$3:$X$9,7,FALSE) -> #N/A | Y19: =VLOOKUP($B19,$R$3:$Z$9,8,FALSE) -> #N/A | Z19: =VLOOKUP($B19,$R$3:$Z$9,9,FALSE) -> #N/A
R20: =B20 -> 0 | S20: =VLOOKUP($B20,$R$3:$X$9,2,FALSE) -> #N/A | T20: =VLOOKUP($B20,$R$3:$X$9,3,FALSE) -> #N/A | U20: =VLOOKUP($B20,$R$3:$X$9,4,FALSE) -> #N/A | V20: =VLOOKUP($B20,$R$3:$X$9,5,FALSE) -> #N/A | W20: =VLOOKUP($B20,$R$3:$X$9,6,FALSE) -> #N/A | X20: =VLOOKUP($B20,$R$3:$X$9,7,FALSE) -> #N/A | Y20: =VLOOKUP($B20,$R$3:$Z$9,8,FALSE) -> #N/A | Z20: =VLOOKUP($B20,$R$3:$Z$9,9,FALSE) -> #N/A
R21: =B21 -> 0 | S21: =VLOOKUP($B21,$R$3:$X$9,2,FALSE) -> #N/A | T21: =VLOOKUP($B21,$R$3:$X$9,3,FALSE) -> #N/A | U21: =VLOOKUP($B21,$R$3:$X$9,4,FALSE) -> #N/A | V21: =VLOOKUP($B21,$R$3:$X$9,5,FALSE) -> #N/A | W21: =VLOOKUP($B21,$R$3:$X$9,6,FALSE) -> #N/A | X21: =VLOOKUP($B21,$R$3:$X$9,7,FALSE) -> #N/A | Y21: =VLOOKUP($B21,$R$3:$Z$9,8,FALSE) -> #N/A | Z21: =VLOOKUP($B21,$R$3:$Z$9,9,FALSE) -> #N/A
R22: =B22 -> 0 | S22: =VLOOKUP($B22,$R$3:$X$9,2,FALSE) -> #N/A | T22: =VLOOKUP($B22,$R$3:$X$9,3,FALSE) -> #N/A | U22: =VLOOKUP($B22,$R$3:$X$9,4,FALSE) -> #N/A | V22: =VLOOKUP($B22,$R$3:$X$9,5,FALSE) -> #N/A | W22: =VLOOKUP($B22,$R$3:$X$9,6,FALSE) -> #N/A | X22: =VLOOKUP($B22,$R$3:$X$9,7,FALSE) -> #N/A | Y22: =VLOOKUP($B22,$R$3:$Z$9,8,FALSE) -> #N/A | Z22: =VLOOKUP($B22,$R$3:$Z$9,9,FALSE) -> #N/A
R23: =B23 -> 0 | S23: =VLOOKUP($B23,$R$3:$X$9,2,FALSE) -> #N/A | T23: =VLOOKUP($B23,$R$3:$X$9,3,FALSE) -> #N/A | U23: =VLOOKUP($B23,$R$3:$X$9,4,FALSE) -> #N/A | V23: =VLOOKUP($B23,$R$3:$X$9,5,FALSE) -> #N/A | W23: =VLOOKUP($B23,$R$3:$X$9,6,FALSE) -> #N/A | X23: =VLOOKUP($B23,$R$3:$X$9,7,FALSE) -> #N/A | Y23: =VLOOKUP($B23,$R$3:$Z$9,8,FALSE) -> #N/A | Z23: =VLOOKUP($B23,$R$3:$Z$9,9,FALSE) -> #N/A
B24: BRAND | D24: BBT P.G./ O.G | I24: Brand | K24: MTD No. of Brews | L24: MTD | M24: YTD | N24: Target | R24: =B24 -> BRAND | S24: =VLOOKUP($B24,$R$3:$X$9,2,FALSE) -> #N/A | T24: =VLOOKUP($B24,$R$3:$X$9,3,FALSE) -> #N/A | U24: =VLOOKUP($B24,$R$3:$X$9,4,FALSE) -> #N/A | V24: =VLOOKUP($B24,$R$3:$X$9,5,FALSE) -> #N/A | W24: =VLOOKUP($B24,$R$3:$X$9,6,FALSE) -> #N/A | X24: =VLOOKUP($B24,$R$3:$X$9,7,FALSE) -> #N/A | Y24: =VLOOKUP($B24,$R$3:$Z$9,8,FALSE) -> #N/A | Z24: =VLOOKUP($B24,$R$3:$Z$9,9,FALSE) -> #N/A
I25: CARIB | K25: =COUNTA([4]Brewhouse!$A$42:$A$45) -> 4 | L25: =AVERAGE([4]Brewhouse!$AU$42:$AU$45) -> 99.340321 | M25: =AVERAGE([4]Brewhouse!$AU$42:$AU$45) -> 99.340321 | N25: 98 | R25: =B25 -> 0 | S25: =VLOOKUP($B25,$R$3:$X$9,2,FALSE) -> #N/A | T25: =VLOOKUP($B25,$R$3:$X$9,3,FALSE) -> #N/A | U25: =VLOOKUP($B25,$R$3:$X$9,4,FALSE) -> #N/A | V25: =VLOOKUP($B25,$R$3:$X$9,5,FALSE) -> #N/A | W25: =VLOOKUP($B25,$R$3:$X$9,6,FALSE) -> #N/A | X25: =VLOOKUP($B25,$R$3:$X$9,7,FALSE) -> #N/A | Y25: =VLOOKUP($B25,$R$3:$Z$9,8,FALSE) -> #N/A | Z25: =VLOOKUP($B25,$R$3:$Z$9,9,FALSE) -> #N/A
I26: STAG | J26: =I18 -> 104.87426 | K26: =COUNTA([5]Brewhouse!$A$52) -> 1 | L26: =[5]Brewhouse!$AS$52 -> 104.87426 | M26: =[5]Brewhouse!$AS$52 -> 104.87426 | N26: 98 | R26: =B26 -> 0 | S26: =VLOOKUP($B26,$R$3:$X$9,2,FALSE) -> #N/A | T26: =VLOOKUP($B26,$R$3:$X$9,3,FALSE) -> #N/A | U26: =VLOOKUP($B26,$R$3:$X$9,4,FALSE) -> #N/A | V26: =VLOOKUP($B26,$R$3:$X$9,5,FALSE) -> #N/A | W26: =VLOOKUP($B26,$R$3:$X$9,6,FALSE) -> #N/A | X26: =VLOOKUP($B26,$R$3:$X$9,7,FALSE) -> #N/A | Y26: =VLOOKUP($B26,$R$3:$Z$9,8,FALSE) -> #N/A | Z26: =VLOOKUP($B26,$R$3:$Z$9,9,FALSE) -> #N/A
I27: GUINNESS | N27: 98 | R27: =B27 -> 0 | S27: =VLOOKUP($B27,$R$3:$X$9,2,FALSE) -> #N/A | T27: =VLOOKUP($B27,$R$3:$X$9,3,FALSE) -> #N/A | U27: =VLOOKUP($B27,$R$3:$X$9,4,FALSE) -> #N/A | V27: =VLOOKUP($B27,$R$3:$X$9,5,FALSE) -> #N/A | W27: =VLOOKUP($B27,$R$3:$X$9,6,FALSE) -> #N/A | X27: =VLOOKUP($B27,$R$3:$X$9,7,FALSE) -> #N/A | Y27: =VLOOKUP($B27,$R$3:$Z$9,8,FALSE) -> #N/A | Z27: =VLOOKUP($B27,$R$3:$Z$9,9,FALSE) -> #N/A
I28: VITAMALT | N28: 98 | R28: =B28 -> 0 | S28: =VLOOKUP($B28,$R$3:$X$9,2,FALSE) -> #N/A | T28: =VLOOKUP($B28,$R$3:$X$9,3,FALSE) -> #N/A | U28: =VLOOKUP($B28,$R$3:$X$9,4,FALSE) -> #N/A | V28: =VLOOKUP($B28,$R$3:$X$9,5,FALSE) -> #N/A | W28: =VLOOKUP($B28,$R$3:$X$9,6,FALSE) -> #N/A | X28: =VLOOKUP($B28,$R$3:$X$9,7,FALSE) -> #N/A | Y28: =VLOOKUP($B28,$R$3:$Z$9,8,FALSE) -> #N/A | Z28: =VLOOKUP($B28,$R$3:$Z$9,9,FALSE) -> #N/A
I29: MAXIMALT | N29: 98 | R29: =B29 -> 0 | S29: =VLOOKUP($B29,$R$3:$X$9,2,FALSE) -> #N/A | T29: =VLOOKUP($B29,$R$3:$X$9,3,FALSE) -> #N/A | U29: =VLOOKUP($B29,$R$3:$X$9,4,FALSE) -> #N/A | V29: =VLOOKUP($B29,$R$3:$X$9,5,FALSE) -> #N/A | W29: =VLOOKUP($B29,$R$3:$X$9,6,FALSE) -> #N/A | X29: =VLOOKUP($B29,$R$3:$X$9,7,FALSE) -> #N/A | Y29: =VLOOKUP($B29,$R$3:$Z$9,8,FALSE) -> #N/A | Z29: =VLOOKUP($B29,$R$3:$Z$9,9,FALSE) -> #N/A
I30: MACKESON | N30: 98 | R30: =B30 -> 0 | S30: =VLOOKUP($B30,$R$3:$X$9,2,FALSE) -> #N/A | T30: =VLOOKUP($B30,$R$3:$X$9,3,FALSE) -> #N/A | U30: =VLOOKUP($B30,$R$3:$X$9,4,FALSE) -> #N/A | V30: =VLOOKUP($B30,$R$3:$X$9,5,FALSE) -> #N/A | W30: =VLOOKUP($B30,$R$3:$X$9,6,FALSE) -> #N/A | X30: =VLOOKUP($B30,$R$3:$X$9,7,FALSE) -> #N/A | Y30: =VLOOKUP($B30,$R$3:$Z$9,8,FALSE) -> #N/A | Z30: =VLOOKUP($B30,$R$3:$Z$9,9,FALSE) -> #N/A
I31: STARMALT | J31: =AVERAGE(I10:I16) -> 96.130343 | K31: =COUNTA([8]Brewhouse!$A$5:$A$7) -> 3 | L31: =AVERAGE([8]Brewhouse!$AY$5:$AY$7) -> 98.128633 | M31: =AVERAGE([8]Brewhouse!$AY$5:$AY$7) -> 98.128633 | N31: 98 | R31: =B31 -> 0 | S31: =VLOOKUP($B31,$R$3:$X$9,2,FALSE) -> #N/A | T31: =VLOOKUP($B31,$R$3:$X$9,3,FALSE) -> #N/A | U31: =VLOOKUP($B31,$R$3:$X$9,4,FALSE) -> #N/A | V31: =VLOOKUP($B31,$R$3:$X$9,5,FALSE) -> #N/A | W31: =VLOOKUP($B31,$R$3:$X$9,6,FALSE) -> #N/A | X31: =VLOOKUP($B31,$R$3:$X$9,7,FALSE) -> #N/A | Y31: =VLOOKUP($B31,$R$3:$Z$9,8,FALSE) -> #N/A | Z31: =VLOOKUP($B31,$R$3:$Z$9,9,FALSE) -> #N/A
I32: HR- Pils | N32: 98 | R32: =B32 -> 0 | S32: =VLOOKUP($B32,$R$3:$X$9,2,FALSE) -> #N/A | T32: =VLOOKUP($B32,$R$3:$X$9,3,FALSE) -> #N/A | U32: =VLOOKUP($B32,$R$3:$X$9,4,FALSE) -> #N/A | V32: =VLOOKUP($B32,$R$3:$X$9,5,FALSE) -> #N/A | W32: =VLOOKUP($B32,$R$3:$X$9,6,FALSE) -> #N/A | X32: =VLOOKUP($B32,$R$3:$X$9,7,FALSE) -> #N/A | Y32: =VLOOKUP($B32,$R$3:$Z$9,8,FALSE) -> #N/A | Z32: =VLOOKUP($B32,$R$3:$Z$9,9,FALSE) -> #N/A
I33: HR- IPA | N33: 98 | R33: =B33 -> 0 | S33: =VLOOKUP($B33,$R$3:$X$9,2,FALSE) -> #N/A | T33: =VLOOKUP($B33,$R$3:$X$9,3,FALSE) -> #N/A | U33: =VLOOKUP($B33,$R$3:$X$9,4,FALSE) -> #N/A | V33: =VLOOKUP($B33,$R$3:$X$9,5,FALSE) -> #N/A | W33: =VLOOKUP($B33,$R$3:$X$9,6,FALSE) -> #N/A | X33: =VLOOKUP($B33,$R$3:$X$9,7,FALSE) -> #N/A | Y33: =VLOOKUP($B33,$R$3:$Z$9,8,FALSE) -> #N/A | Z33: =VLOOKUP($B33,$R$3:$Z$9,9,FALSE) -> #N/A
I34: HR- APA | N34: 98 | R34: =B34 -> 0 | S34: =VLOOKUP($B34,$R$3:$X$9,2,FALSE) -> #N/A | T34: =VLOOKUP($B34,$R$3:$X$9,3,FALSE) -> #N/A | U34: =VLOOKUP($B34,$R$3:$X$9,4,FALSE) -> #N/A | V34: =VLOOKUP($B34,$R$3:$X$9,5,FALSE) -> #N/A | W34: =VLOOKUP($B34,$R$3:$X$9,6,FALSE) -> #N/A | X34: =VLOOKUP($B34,$R$3:$X$9,7,FALSE) -> #N/A | Y34: =VLOOKUP($B34,$R$3:$Z$9,8,FALSE) -> #N/A | Z34: =VLOOKUP($B34,$R$3:$Z$9,9,FALSE) -> #N/A
K35: =SUM(K25:K34) -> 8 | L35: =((L25*K25)+(L26*K26)+(L27*K27)+(L28*K28)+(L29*K29)+(K32*L32)+(L30*K30)+(L31*K31)+(L34*K34))/(K35) -> 99.577681 | M35: =L35 -> 99.577681 | N35: 98 | R35: =B35 -> 0 | S35: =VLOOKUP($B35,$R$3:$X$9,2,FALSE) -> #N/A | T35: =VLOOKUP($B35,$R$3:$X$9,3,FALSE) -> #N/A | U35: =VLOOKUP($B35,$R$3:$X$9,4,FALSE) -> #N/A | V35: =VLOOKUP($B35,$R$3:$X$9,5,FALSE) -> #N/A | W35: =VLOOKUP($B35,$R$3:$X$9,6,FALSE) -> #N/A | X35: =VLOOKUP($B35,$R$3:$X$9,7,FALSE) -> #N/A | Y35: =VLOOKUP($B35,$R$3:$Z$9,8,FALSE) -> #N/A | Z35: =VLOOKUP($B35,$R$3:$Z$9,9,FALSE) -> #N/A
R36: =B36 -> 0 | S36: =VLOOKUP($B36,$R$3:$X$9,2,FALSE) -> #N/A | T36: =VLOOKUP($B36,$R$3:$X$9,3,FALSE) -> #N/A | U36: =VLOOKUP($B36,$R$3:$X$9,4,FALSE) -> #N/A | V36: =VLOOKUP($B36,$R$3:$X$9,5,FALSE) -> #N/A | W36: =VLOOKUP($B36,$R$3:$X$9,6,FALSE) -> #N/A | X36: =VLOOKUP($B36,$R$3:$X$9,7,FALSE) -> #N/A | Y36: =VLOOKUP($B36,$R$3:$Z$9,8,FALSE) -> #N/A | Z36: =VLOOKUP($B36,$R$3:$Z$9,9,FALSE) -> #N/A
J37: Daily Brewing Plan
J38: Brand | K38: Brews Achieved | L38: Average Brews per day
J39: CARIB | L39: MTD | M39: YTD | N39: TARGET
J40: STAG | K40: 1 | L40: =AVERAGE('Jan 2nd'!K45,'Jan 5th'!K45,'Jan 6th'!K49) -> 5 | M40: =AVERAGE(L40) -> 5 | N40: 9.2
...

Sheet Jan 7th
S1: P.G. | U1: Hot Time | W1: Process Time | Y1: Cooling Time
B2: Brewing Department Daily Process Loss Report | S2: Lower | T2: Upper | U2: Lower | V2: Upper | W2: Lower | X2: Upper | Y2: Lower | Z2: Upper
R3: CARIB | S3: 11.6 | T3: 12 | U3: 0 | V3: 0.11805556 | W3: 0.22569444 | X3: 0.26388889 | Y3: 0 | Z3: 60 | AB3: HR- PISNER
B4: Date: | C4: 46030 | J4: LOT WORT COLOUR: | M4: Filter Sheets (Target 20 days) | R4: STAG | S4: 11.6 | T4: 12 | U4: 0 | V4: 0.11805556 | W4: 0.22569444 | X4: 0.26388889 | Y4: 0 | Z4: 60
M5: Double | N5: Single | R5: GUINNESS | S5: 17 | T5: 17.5 | U5: 0 | V5: 0.10763889 | W5: 0.24652778 | X5: 0.28472222 | Y5: 0 | Z5: 60
J6: MALT LOT: Lot #8 | L6: Sheet Day | R6: MACKESON | S6: 13.3 | T6: 13.5 | U6: 0 | V6: 0.12905093 | W6: 0.27430556 | X6: 0.30208333 | Y6: 0
R7: STARMALT | S7: 17 | T7: 17.4 | U7: 0 | V7: 0.13605324 | W7: 0.27430556 | X7: 0.30902778 | Y7: 0 | Z7: 85
B8: Brand | C8: Brew no. | D8: Kett. Hls | E8: Wort | F8: Cool Time(Mins) | G8: Cast. P.G. (Lab Result) | H8: Cast P.G. (Cellar Operator)-gravity | I8: Extr. Rec (77.9%) | J8: Theor. Extr. (77.5%) | K8: Boil Off /Vol. (4-6%) | L8: Boil Time | M8: Total Hot | N8: Brewing | O8: Operator | R8: Hurricane Reef | S8: 16.6 | T8: 17 | U8: 0 | V8: 0.12905093 | W8: 0.27430556 | X8: 0.30208333 | Y8: 0
E9: Meter (Hls) | F9: Target(< 60Mins) | M9: Time | R9: VITAMALT | S9: 14.2 | T9: 14.6 | U9: 0 | V9: 0.13905093 | W9: 0.26041667 | X9: 0.29513889 | Y9: 0 | Z9: 75
B10: MACKESON | C10: =[7]Brewhouse!$A4 -> MK001 | D10: =[7]Brewhouse!$AF4 -> 53.2 | E10: =[7]Brewhouse!$AI4 -> 51 | F10: =[7]Brewhouse!$X4 -> 59 | G10: =[7]Brewhouse!$AG4 -> 13.3 | H10: 13.3 | I10: =[7]Brewhouse!$AT4 -> 95.757584 | J10: =[7]Brewhouse!$AU4 -> 96.414076 | K10: =[7]Brewhouse!$S4 -> 5.5657143 | L10: =[7]Brewhouse!$R4 -> 75 | M10: =[7]Brewhouse!$W4-[7]Brewhouse!$V4 -> 0.13541667 | N10: =[7]Brewhouse!$AA4 -> 0.29166667 | O10: =[7]Brewhouse!$AX4 -> K.Benjamin | R10: =B10 -> MACKESON | S10: =VLOOKUP($B10,$R$3:$X$9,2,FALSE) -> 13.3 | T10: =VLOOKUP($B10,$R$3:$X$9,3,FALSE) -> 13.5 | U10: =VLOOKUP($B10,$R$3:$X$9,4,FALSE) -> 0 | V10: =VLOOKUP($B10,$R$3:$X$9,5,FALSE) -> 0.12905093 | W10: =VLOOKUP($B10,$R$3:$X$9,6,FALSE) -> 0.27430556 | X10: =VLOOKUP($B10,$R$3:$X$9,7,FALSE) -> 0.30208333 | Y10: =VLOOKUP($B10,$R$3:$Z$9,8,FALSE) -> 0 | Z10: =VLOOKUP($B10,$R$3:$Z$9,9,FALSE) -> 0
B11: MACKESON | C11: =[7]Brewhouse!$A5 -> MK002 | D11: =[7]Brewhouse!$AF5 -> 53.5 | E11: =[7]Brewhouse!$AI5 -> 51 | F11: =[7]Brewhouse!$X5 -> 60 | G11: =[7]Brewhouse!$AG5 -> 13 | H11: 13 | I11: =[7]Brewhouse!$AT5 -> 95.858103 | J11: =[7]Brewhouse!$AU5 -> 96.515152 | L11: =[7]Brewhouse!$R5 -> 75 | M11: =[7]Brewhouse!$W5-[7]Brewhouse!$V5 -> 0.15277778 | N11: =[7]Brewhouse!$AA5 -> 0.31041667 | O11: =[7]Brewhouse!$AX5 -> R.Regis | R11: =B11 -> MACKESON | S11: =VLOOKUP($B11,$R$3:$X$9,2,FALSE) -> 13.3 | T11: =VLOOKUP($B11,$R$3:$X$9,3,FALSE) -> 13.5 | U11: =VLOOKUP($B11,$R$3:$X$9,4,FALSE) -> 0 | V11: =VLOOKUP($B11,$R$3:$X$9,5,FALSE) -> 0.12905093 | W11: =VLOOKUP($B11,$R$3:$X$9,6,FALSE) -> 0.27430556 | X11: =VLOOKUP($B11,$R$3:$X$9,7,FALSE) -> 0.30208333 | Y11: =VLOOKUP($B11,$R$3:$Z$9,8,FALSE) -> 0 | Z11: =VLOOKUP($B11,$R$3:$Z$9,9,FALSE) -> 0
B12: MACKESON | C12: =[7]Brewhouse!$A6 -> MK003 | D12: =[7]Brewhouse!$AF6 -> 53.1 | E12: =[7]Brewhouse!$AI6 -> 50.4 | F12: =[7]Brewhouse!$X6 -> 59 | G12: =[7]Brewhouse!$AG6 -> 12.8 | H12: 12.8 | I12: =[7]Brewhouse!$AT6 -> 91.101782 | J12: =[7]Brewhouse!$AU6 -> 91.726104 | K12: =[7]Brewhouse!$S6 -> 0.4090566 | L12: =[7]Brewhouse!$R6 -> 77 | M12: =[7]Brewhouse!$W6-[7]Brewhouse!$V6 -> 0.12361111 | N12: =[7]Brewhouse!$AA6 -> 0.29861111 | O12: =[7]Brewhouse!$AX6 -> R.Regis | R12: =B12 -> MACKESON | S12: =VLOOKUP($B12,$R$3:$X$9,2,FALSE) -> 13.3 | T12: =VLOOKUP($B12,$R$3:$X$9,3,FALSE) -> 13.5 | U12: =VLOOKUP($B12,$R$3:$X$9,4,FALSE) -> 0 | V12: =VLOOKUP($B12,$R$3:$X$9,5,FALSE) -> 0.12905093 | W12: =VLOOKUP($B12,$R$3:$X$9,6,FALSE) -> 0.27430556 | X12: =VLOOKUP($B12,$R$3:$X$9,7,FALSE) -> 0.30208333 | Y12: =VLOOKUP($B12,$R$3:$Z$9,8,FALSE) -> 0 | Z12: =VLOOKUP($B12,$R$3:$Z$9,9,FALSE) -> 0
B13: MACKESON | C13: =[7]Brewhouse!$A7 -> MK004 | D13: =[7]Brewhouse!$AF7 -> 51.2 | E13: =[7]Brewhouse!$AI7 -> 50.4 | F13: =[7]Brewhouse!$X7 -> 60 | G13: =[7]Brewhouse!$AG7 -> 13.5 | H13: 13.4 | I13: =[7]Brewhouse!$AT7 -> 96.220044 | J13: =[7]Brewhouse!$AU7 -> 96.879575 | K13: =[7]Brewhouse!$S7 -> 1.6015686 | L13: =[7]Brewhouse!$R7 -> 72 | M13: =[7]Brewhouse!$W7-[7]Brewhouse!$V7 -> 0.12291667 | N13: =[7]Brewhouse!$AA7 -> 0.27986111 | O13: =[7]Brewhouse!$AX7 -> R.Sookram | R13: =B13 -> MACKESON | S13: =VLOOKUP($B13,$R$3:$X$9,2,FALSE) -> 13.3 | T13: =VLOOKUP($B13,$R$3:$X$9,3,FALSE) -> 13.5 | U13: =VLOOKUP($B13,$R$3:$X$9,4,FALSE) -> 0 | V13: =VLOOKUP($B13,$R$3:$X$9,5,FALSE) -> 0.12905093 | W13: =VLOOKUP($B13,$R$3:$X$9,6,FALSE) -> 0.27430556 | X13: =VLOOKUP($B13,$R$3:$X$9,7,FALSE) -> 0.30208333 | Y13: =VLOOKUP($B13,$R$3:$Z$9,8,FALSE) -> 0 | Z13: =VLOOKUP($B13,$R$3:$Z$9,9,FALSE) -> 0
