Workbook

Sheet Entries July 2026
B1: ENTRIES FOR DAILY CONS. MONITOR | O1: =B1 -> ENTRIES FOR DAILY CONS. MONITOR
O2: Service 227.3 cubic meters (2273 Hls)Filtered 189.3 cubic meters(1893 Hls)
D3: FUEL | J3: ELECT. | L3: CO2 | O3: WATER | AG3: CO2 Scrubber (m3) | AH3: Supply to Washdown Area (m3) | AI3: Supply to RUs (m3) | AJ3: Steam Mass Flow Meter | AL3: CO2 TANKS' READING
B4: Boilers tot. | C4: Boiler 1 | D4: Gen. meter | E4: Tank level | F4: Boiler 1 | G4: Boiler 2 | H4: Gen | I4: Meter1 | J4: Meter 2 | K4: Gen Meter | L4: Consumption (BBT SECTION) (kg) | M4: Consumption (Totalizer Flowmeter) | N4: Consumption (Filler) (kg) | O4: Nawasa Meter (m3) | P4: Annandale Supply (m3) | Q4: Service Supply to Plant (m3) | R4: Cellars/Filtration (m3) | S4: Brewhouse Meter (m3) | T4: Cellars/Process Areas (m3) | U4: Pasteuriser (m3) | V4: Water Plant-Nawasa Annadale (m3) | W4: Water Plant-Well # 1 (m3) | X4: CIP Process | Y4: Bottle Washer | Z4: Boiler | AA4: Permeate #1 | AB4: Permeate #2 | AC4: Bottle Filler (m3) | AD4: RO # 1 Totaliser (m3) | AE4: RO # 2 Totaliser (m3) | AF4: Recovered Water (m3) | AL4: Tank "C" | AM4: Tank "A" | AN4: Tank "B" | AO4: Mobile Tanker
A5: DATE | B5: (liters) | C5: (liters) | D5: (Imp. gals) | E5: (inches) | F5: Hrs | G5: Hrs | H5: Hrs. | I5: (Kwhr) | J5: (Kwhr) | K5: (Kwhr) | M5: (kg) | X5: (m3) | Y5: (m3) | Z5: (m3) | AL5: inH2O | AM5: (Kg.) | AN5: (Kg.) | AO5: (pounds)
A6: 1 | B6: 8296880 | E6: 64 | F6: 9818.3 | G6: 68225 | I6: 1275845 | K6: 468000 | L6: 48242.18 | M6: 502510.38 | N6: 70845.18 | O6: 239094 | P6: 71771 | Q6: 973280 | S6: 86793 | U6: 252 | V6: 1351661 | X6: 46205 | Y6: 64265 | Z6: 14156 | AA6: 97122 | AC6: 5518 | AD6: 263573 | AJ6: 7369202.9
A7: 2 | B7: 8299720 | E7: 64 | F7: 9839.4 | G7: 68225 | I7: 1282285 | K7: 468000 | L7: 49225.89 | M7: 505237.47 | N7: 71138.77 | O7: 239360 | P7: 71948 | Q7: 973498 | S7: 86947 | U7: 255 | V7: 1351849 | X7: 46247 | Y7: 64329 | Z7: 14171 | AA7: 97122 | AC7: 5537 | AD7: 263573 | AJ7: 7369202.9
A8: 3 | B8: 8303170 | E8: 64 | F8: 9860.8 | G8: 68225 | I8: 1290886 | K8: 468000 | L8: 49786.92 | M8: 507678.46 | N8: 71585.36 | O8: 239629 | P8: 72161 | Q8: 973745 | S8: 87167 | U8: 262 | V8: 1352069 | X8: 46297 | Y8: 64412 | Z8: 14189 | AA8: 97122 | AC8: 5567 | AD8: 263573 | AJ8: 7369202.9
A9: 4 | B9: 8306160 | E9: 64 | F9: 9880.7 | G9: 68225 | I9: 1299598 | K9: 468000 | L9: 50298.22 | M9: 509591.38 | N9: 71795.41 | O9: 239636 | P9: 72304 | Q9: 973931 | S9: 87307 | U9: 264 | V9: 1352218 | X9: 46316 | Y9: 64498 | Z9: 14206 | AA9: 97122 | AC9: 5590 | AD9: 263568 | AJ9: 7369284.8
A10: 5 | B10: 8307100 | E10: 64 | F10: 9887.4 | G10: 68225 | I10: 1303250 | K10: 468000 | L10: 50298.22 | M10: 509591.38 | N10: 71795.41 | O10: 239657 | P10: 72488 | Q10: 974012 | S10: 87371 | U10: 300 | V10: 1352412 | X10: 46316 | Y10: 64503 | Z10: 14212 | AA10: 97122 | AC10: 5590 | AD10: 263568 | AJ10: 7369294.4
A11: 6 | B11: 8308580 | E11: 64 | F11: 9896.4 | G11: 68225 | I11: 1308613 | K11: 468000 | L11: 50340.57 | M11: 509699.38 | N11: 71811.71 | O11: 239658 | P11: 72529 | Q11: 974101 | S11: 87378 | U11: 303 | V11: 1352454 | X11: 46317 | Y11: 64537 | Z11: 14226 | AA11: 97122 | AC11: 5591 | AD11: 263555 | AJ11: 7369729.8
A12: 7 | B12: 8310990 | E12: 64 | F12: 9911.8 | G12: 68225 | I12: 1315792 | K12: 468000 | L12: 51246.97 | M12: 511528.81 | N12: 72023.41 | O12: 239783 | P12: 72717 | Q12: 974327 | S12: 87483 | U12: 309 | V12: 1352651 | X12: 46382 | Y12: 64613 | Z12: 14253 | AA12: 97122 | AC12: 5620 | AD12: 263558 | AJ12: 7369729.8
A13: 8 | B13: 8313800 | E13: 64 | F13: 9931 | G13: 68225 | I13: 1323958 | K13: 468000 | L13: 51888.07 | M13: 512905.5 | N13: 72141.08 | O13: 240050 | P13: 72841 | Q13: 974472 | S13: 87619 | U13: 316 | V13: 1352781 | X13: 46398 | Y13: 64662 | Z13: 14282 | AA13: 97122 | AC13: 5636 | AD13: 263613 | AJ13: 7369758.9
A14: 9 | B14: 8317310 | E14: 64 | F14: 9951.2 | G14: 68225 | I14: 1334042 | K14: 468000 | L14: 52910.04 | M14: 516105.19 | N14: 72421.32 | O14: 240051 | P14: 72958 | Q14: 974696 | S14: 87813 | U14: 321 | V14: 1352904 | X14: 46433 | Y14: 64743 | Z14: 14314 | AA14: 97122 | AC14: 5668 | AD14: 263673 | AJ14: 7369758.9
A15: 10 | B15: 8319820 | E15: 64 | F15: 9970.7 | G15: 68225 | I15: 1340634 | K15: 468000 | L15: 53307 | M15: 517705.91 | N15: 72579.13 | O15: 240264 | P15: 73153 | Q15: 974908 | S15: 87878 | U15: 321 | V15: 1353108 | X15: 46485 | Y15: 64816 | Z15: 14342 | AA15: 97122 | AC15: 5689 | AD15: 263676 | AJ15: 7369758.9
A16: 11 | B16: 8322770 | E16: 64 | F16: 9989.6 | G16: 68225 | I16: 1348237 | K16: 468000 | L16: 54036.04 | M16: 519534.59 | N16: 72780.29 | O16: 240498 | P16: 73332 | Q16: 975095 | S16: 88042 | U16: 323 | V16: 1353296 | X16: 46515 | Y16: 64886 | Z16: 14375 | AA16: 97122 | AC16: 5712 | AD16: 263676 | AJ16: 7369758.9
A17: 12 | B17: 8324770 | E17: 64 | F17: 10004 | G17: 68225 | I17: 1352074 | K17: 468000 | L17: 54036.04 | M17: 519676.67 | N17: 72780.29 | O17: 240498 | P17: 73429 | Q17: 975195 | S17: 88138 | U17: 323 | V17: 1353396 | X17: 46515 | Y17: 64927 | Z17: 14388 | AA17: 97122 | AC17: 5717 | AD17: 263676 | AJ17: 7369758.9
... A37: 1 | B37: 8379250 | E37: 64 | F37: 10357.7 | G37: 68225 | I37: 1496310 | K37: 468000 | L37: 63876.51 | M37: 550471 | N37: 75948.14 | O37: 243905 | P37: 76483 | Q37: 979132 | S37: 90627 | U37: 367 | V37: 1356580 | X37: 47169 | Y37: 66288 | Z37: 14750 | AA37: 97122 | AC37: 6043 | AD37: 263788 | AJ37: 7369792.7

Sheet Utility Analysis July 2026
J2: GRENADA BREWERIES LIMITED
J3: UTILITY ANALYSIS
A5: MONTH: | I5: 39295
A7: DATE | D7: ELECTRICITY GRENLEC | E7: Solar System CARIB | F7: % (Solar/Total Usage) | G7: CARIB GENSET | H7: ELECTRICITY TOTAL | I7: WATER | J7: FUEL | K7: CO2 | L7: PRODUCTION - HL | Q7: UTILITY RATIOS
B8: METER 1 | C8: METER 2 | Q8: Elect | R8: Water | S8: Fuel | T8: CO2
G9: USAGE (kwh) | H9: USAGE (kwh) | I9: USAGE (Hl) | J9: USAGE (l) | K9: USAGE (Kg.) | L9: BREWED | M9: BOTTLED | N9: KEGS | O9: OTHER | P9: TOTAL | Q9: KWH/Hl | R9: Hl/hl | S9: Litres/hl | T9: kg./Hl
A10: 1 | B10: =IF('Entries July 2026'!I7<'Entries July 2026'!I6,"0",(IF('Entries July 2026'!I7>='Entries July 2026'!I6,'Entries July 2026'!I7-'Entries July 2026'!I6,(999999-'Entries July 2026'!I6)+'Entries July 2026'!I7+1))) -> 6440 | C10: =IF('Entries July 2026'!J7<='Entries July 2026'!J6,"0",IF('Entries July 2026'!J7>='Entries July 2026'!J6,'Entries July 2026'!J7-'Entries July 2026'!J6,(999999-'Entries July 2026'!J6)+'Entries July 2026'!J7+1)) -> 0 | D10: =B10+C10 -> 6440 | E10: 1524 | F10: =IF((E10+D10)=0,"0",E10/(D10+E10)) -> 0.19136113 | G10: =IF('Entries July 2026'!K7<'Entries July 2026'!K6,"0",IF('Entries July 2026'!K7>='Entries July 2026'!K6,'Entries July 2026'!K7-'Entries July 2026'!K6,(999999-'Entries July 2026'!K6)+'Entries July 2026'!K7+1)) -> 0 | H10: =D10+G10+E10 -> 7964 | I10: ='Water '!Z7*10 -> 4430 | J10: =IF('Entries July 2026'!B7-'Entries July 2026'!B6<1,"0",'Entries July 2026'!B7-'Entries July 2026'!B6) -> 2840 | K10: ='CO2'!E7 -> 2800 | L10: =+'PROD.FIG. '!F5 -> 0 | M10: =+'PROD.FIG. '!C5 -> 0 | N10: =+'PROD.FIG. '!D5 -> 0 | O10: =+'PROD.FIG. '!E5 -> 0 | P10: {=TRANSPOSE('Daily KPIs'!B9:AF9)} -> 471.8652 | Q10: =IF(P10=0,0,H10/P10) -> 16.877702 | R10: =IF(Q10=0,0,I10/P10) -> 9.3882744 | S10: =IF(R10=0,0,J10/P10) -> 6.018668 | T10: =IF(S10=0,0,K10/P10) -> 5.9338981
A11: 2 | B11: =IF('Entries July 2026'!I8<'Entries July 2026'!I7,"0",(IF('Entries July 2026'!I8>='Entries July 2026'!I7,'Entries July 2026'!I8-'Entries July 2026'!I7,(999999-'Entries July 2026'!I7)+'Entries July 2026'!I8+1))) -> 8601 | C11: =IF('Entries July 2026'!J8<='Entries July 2026'!J7,"0",IF('Entries July 2026'!J8>='Entries July 2026'!J7,'Entries July 2026'!J8-'Entries July 2026'!J7,(999999-'Entries July 2026'!J7)+'Entries July 2026'!J8+1)) -> 0 | D11: =B11+C11 -> 8601 | E11: 1499 | F11: =IF((E11+D11)=0,"0",E11/(D11+E11)) -> 0.14841584 | G11: =IF('Entries July 2026'!K8<'Entries July 2026'!K7,"0",IF('Entries July 2026'!K8>='Entries July 2026'!K7,'Entries July 2026'!K8-'Entries July 2026'!K7,(999999-'Entries July 2026'!K7)+'Entries July 2026'!K8+1)) -> 0 | H11: =D11+G11+E11 -> 10100 | I11: ='Water '!Z8*10 -> 4820 | J11: =IF('Entries July 2026'!B8-'Entries July 2026'!B7<1,"0",'Entries July 2026'!B8-'Entries July 2026'!B7) -> 3450 | K11: ='CO2'!E8 -> 2500 | L11: =+'PROD.FIG. '!F6 -> 0 | M11: =+'PROD.FIG. '!C6 -> 0 | N11: =+'PROD.FIG. '!D6 -> 0 | O11: =+'PROD.FIG. '!E6 -> 0 | P11: 507.3684 | Q11: =IF(P11=0,0,H11/P11) -> 19.90664 | R11: =IF(Q11=0,0,I11/P11) -> 9.5000004 | S11: =IF(R11=0,0,J11/P11) -> 6.7997928 | T11: =IF(S11=0,0,K11/P11) -> 4.9273861
A12: 3 | B12: =IF('Entries July 2026'!I9<'Entries July 2026'!I8,"0",(IF('Entries July 2026'!I9>='Entries July 2026'!I8,'Entries July 2026'!I9-'Entries July 2026'!I8,(999999-'Entries July 2026'!I8)+'Entries July 2026'!I9+1))) -> 8712 | C12: =IF('Entries July 2026'!J9<='Entries July 2026'!J8,"0",IF('Entries July 2026'!J9>='Entries July 2026'!J8,'Entries July 2026'!J9-'Entries July 2026'!J8,(999999-'Entries July 2026'!J8)+'Entries July 2026'!J9+1)) -> 0 | D12: =B12+C12 -> 8712 | E12: 534.4 | F12: =IF((E12+D12)=0,"0",E12/(D12+E12)) -> 0.057795466 | G12: =IF('Entries July 2026'!K9<'Entries July 2026'!K8,"0",IF('Entries July 2026'!K9>='Entries July 2026'!K8,'Entries July 2026'!K9-'Entries July 2026'!K8,(999999-'Entries July 2026'!K8)+'Entries July 2026'!K9+1)) -> 0 | H12: =D12+G12+E12 -> 9246.4 | I12: ='Water '!Z9*10 -> 1500 | J12: =IF('Entries July 2026'!B9-'Entries July 2026'!B8<1,"0",'Entries July 2026'!B9-'Entries July 2026'!B8) -> 2990 | K12: ='CO2'!E9 -> 3100 | L12: =+'PROD.FIG. '!F7 -> 0 | M12: =+'PROD.FIG. '!C7 -> 0 | N12: =+'PROD.FIG. '!D7 -> 0 | O12: =+'PROD.FIG. '!E7 -> 0 | P12: 492.096 | Q12: =IF(P12=0,0,H12/P12) -> 18.78983 | R12: =IF(Q12=0,0,I12/P12) -> 3.0481857 | S12: =IF(R12=0,0,J12/P12) -> 6.0760502 | T12: =IF(S12=0,0,K12/P12) -> 6.2995838
A13: 4 | B13: =IF('Entries July 2026'!I10<'Entries July 2026'!I9,"0",(IF('Entries July 2026'!I10>='Entries July 2026'!I9,'Entries July 2026'!I10-'Entries July 2026'!I9,(999999-'Entries July 2026'!I9)+'Entries July 2026'!I10+1))) -> 3652 | C13: =IF('Entries July 2026'!J10<='Entries July 2026'!J9,"0",IF('Entries July 2026'!J10>='Entries July 2026'!J9,'Entries July 2026'!J10-'Entries July 2026'!J9,(999999-'Entries July 2026'!J9)+'Entries July 2026'!J10+1)) -> 0 | D13: =B13+C13 -> 3652 | E13: 1458 | F13: =IF((E13+D13)=0,"0",E13/(D13+E13)) -> 0.2853229 | G13: =IF('Entries July 2026'!K10<'Entries July 2026'!K9,"0",IF('Entries July 2026'!K10>='Entries July 2026'!K9,'Entries July 2026'!K10-'Entries July 2026'!K9,(999999-'Entries July 2026'!K9)+'Entries July 2026'!K10+1)) -> 0 | H13: =D13+G13+E13 -> 5110 | I13: ='Water '!Z10*10 -> 2050 | J13: =IF('Entries July 2026'!B10-'Entries July 2026'!B9<1,"0",'Entries July 2026'!B10-'Entries July 2026'!B9) -> 940 | K13: ='CO2'!E10 -> 0 | L13: =+'PROD.FIG. '!F8 -> 0 | M13: =+'PROD.FIG. '!C8 -> 0 | N13: =+'PROD.FIG. '!D8 -> 0 | O13: =+'PROD.FIG. '!E8 -> 0 | P13: 0 | Q13: =IF(P13=0,0,H13/P13) -> 0 | R13: =IF(Q13=0,0,I13/P13) -> 0 | S13: =IF(R13=0,0,J13/P13) -> 0 | T13: =IF(S13=0,0,K13/P13) -> 0
A14: 5 | B14: =IF('Entries July 2026'!I11<'Entries July 2026'!I10,"0",(IF('Entries July 2026'!I11>='Entries July 2026'!I10,'Entries July 2026'!I11-'Entries July 2026'!I10,(999999-'Entries July 2026'!I10)+'Entries July 2026'!I11+1))) -> 5363 | C14: =IF('Entries July 2026'!J11<='Entries July 2026'!J10,"0",IF('Entries July 2026'!J11>='Entries July 2026'!J10,'Entries July 2026'!J11-'Entries July 2026'!J10,(999999-'Entries July 2026'!J10)+'Entries July 2026'!J11+1)) -> 0 | D14: =B14+C14 -> 5363 | E14: 1074.4 | F14: =IF((E14+D14)=0,"0",E14/(D14+E14)) -> 0.16689968 | G14: =IF('Entries July 2026'!K11<'Entries July 2026'!K10,"0",IF('Entries July 2026'!K11>='Entries July 2026'!K10,'Entries July 2026'!K11-'Entries July 2026'!K10,(999999-'Entries July 2026'!K10)+'Entries July 2026'!K11+1)) -> 0 | H14: =D14+G14+E14 -> 6437.4 | I14: ='Water '!Z11*10 -> 420 | J14: =IF('Entries July 2026'!B11-'Entries July 2026'!B10<1,"0",'Entries July 2026'!B11-'Entries July 2026'!B10) -> 1480 | K14: ='CO2'!E11 -> 0 | L14: =+'PROD.FIG. '!F9 -> 0 | M14: =+'PROD.FIG. '!C9 -> 0 | N14: =+'PROD.FIG. '!D9 -> 0 | O14: =+'PROD.FIG. '!E9 -> 0 | P14: 0 | Q14: =IF(P14=0,0,H14/P14) -> 0 | R14: =IF(Q14=0,0,I14/P14) -> 0 | S14: =IF(R14=0,0,J14/P14) -> 0 | T14: =IF(S14=0,0,K14/P14) -> 0
A15: 6 | B15: =IF('Entries July 2026'!I12<'Entries July 2026'!I11,"0",(IF('Entries July 2026'!I12>='Entries July 2026'!I11,'Entries July 2026'!I12-'Entries July 2026'!I11,(999999-'Entries July 2026'!I11)+'Entries July 2026'!I12+1))) -> 7179 | C15: =IF('Entries July 2026'!J12<='Entries July 2026'!J11,"0",IF('Entries July 2026'!J12>='Entries July 2026'!J11,'Entries July 2026'!J12-'Entries July 2026'!J11,(999999-'Entries July 2026'!J11)+'Entries July 2026'!J12+1)) -> 0 | D15: =B15+C15 -> 7179 | E15: 1149.1 | F15: =IF((E15+D15)=0,"0",E15/(D15+E15)) -> 0.13797865 | G15: =IF('Entries July 2026'!K12<'Entries July 2026'!K11,"0",IF('Entries July 2026'!K12>='Entries July 2026'!K11,'Entries July 2026'!K12-'Entries July 2026'!K11,(999999-'Entries July 2026'!K11)+'Entries July 2026'!K12+1)) -> 0 | H15: =D15+G15+E15 -> 8328.1 | I15: ='Water '!Z12*10 -> 3130 | J15: =IF('Entries July 2026'!B12-'Entries July 2026'!B11<1,"0",'Entries July 2026'!B12-'Entries July 2026'!B11) -> 2410 | K15: ='CO2'!E12 -> 1600 | L15: =+'PROD.FIG. '!F10 -> 0 | M15: =+'PROD.FIG. '!C10 -> 0 | N15: =+'PROD.FIG. '!D10 -> 0 | O15: =+'PROD.FIG. '!E10 -> 0 | P15: 410.784 | Q15: =IF(P15=0,0,H15/P15) -> 20.273672 | R15: =IF(Q15=0,0,I15/P15) -> 7.6195762 | S15: =IF(R15=0,0,J15/P15) -> 5.8668303 | T15: =IF(S15=0,0,K15/P15) -> 3.894991
A16: 7 | B16: =IF('Entries July 2026'!I13<'Entries July 2026'!I12,"0",(IF('Entries July 2026'!I13>='Entries July 2026'!I12,'Entries July 2026'!I13-'Entries July 2026'!I12,(999999-'Entries July 2026'!I12)+'Entries July 2026'!I13+1))) -> 8166 | C16: =IF('Entries July 2026'!J13<='Entries July 2026'!J12,"0",IF('Entries July 2026'!J13>='Entries July 2026'!J12,'Entries July 2026'!J13-'Entries July 2026'!J12,(999999-'Entries July 2026'!J12)+'Entries July 2026'!J13+1)) -> 0 | D16: =B16+C16 -> 8166 | E16: 1453.3 | F16: =IF((E16+D16)=0,"0",E16/(D16+E16)) -> 0.15108168 | G16: =IF('Entries July 2026'!K13<'Entries July 2026'!K12,"0",IF('Entries July 2026'!K13>='Entries July 2026'!K12,'Entries July 2026'!K13-'Entries July 2026'!K12,(999999-'Entries July 2026'!K12)+'Entries July 2026'!K13+1)) -> 0 | H16: =D16+G16+E16 -> 9619.3 | I16: ='Water '!Z13*10 -> 3910 | J16: =IF('Entries July 2026'!B13-'Entries July 2026'!B12<1,"0",'Entries July 2026'!B13-'Entries July 2026'!B12) -> 2810 | K16: ='CO2'!E13 -> 1600 | L16: =+'PROD.FIG. '!F11 -> 0 | M16: =+'PROD.FIG. '!C11 -> 0 | N16: =+'PROD.FIG. '!D11 -> 0 | O16: =+'PROD.FIG. '!E11 -> 0 | P16: 209.88 | Q16: =IF(P16=0,0,H16/P16) -> 45.83238 | R16: =IF(Q16=0,0,I16/P16) -> 18.629693 | S16: =IF(R16=0,0,J16/P16) -> 13.388603 | T16: =IF(S16=0,0,K16/P16) -> 7.6234038
A17: 8 | B17: =IF('Entries July 2026'!I14<'Entries July 2026'!I13,"0",(IF('Entries July 2026'!I14>='Entries July 2026'!I13,'Entries July 2026'!I14-'Entries July 2026'!I13,(999999-'Entries July 2026'!I13)+'Entries July 2026'!I14+1))) -> 10084 | C17: =IF('Entries July 2026'!J14<='Entries July 2026'!J13,"0",IF('Entries July 2026'!J14>='Entries July 2026'!J13,'Entries July 2026'!J14-'Entries July 2026'!J13,(999999-'Entries July 2026'!J13)+'Entries July 2026'!J14+1)) -> 0 | D17: =B17+C17 -> 10084 | E17: 1338.1 | F17: =IF((E17+D17)=0,"0",E17/(D17+E17)) -> 0.11715009 | G17: =IF('Entries July 2026'!K14<'Entries July 2026'!K13,"0",IF('Entries July 2026'!K14>='Entries July 2026'!K13,'Entries July 2026'!K14-'Entries July 2026'!K13,(999999-'Entries July 2026'!K13)+'Entries July 2026'!K14+1)) -> 0 | H17: =D17+G17+E17 -> 11422.1 | I17: ='Water '!Z14*10 -> 1180 | J17: =IF('Entries July 2026'!B14-'Entries July 2026'!B13<1,"0",'Entries July 2026'!B14-'Entries July 2026'!B13) -> 3510 | K17: ='CO2'!E14 -> 3200 | L17: =+'PROD.FIG. '!F12 -> 0 | M17: =+'PROD.FIG. '!C12 -> 0 | N17: =+'PROD.FIG. '!D12 -> 0 | O17: =+'PROD.FIG. '!E12 -> 0 | P17: 376.728 | Q17: =IF(P17=0,0,H17/P17) -> 30.319222 | R17: =IF(Q17=0,0,I17/P17) -> 3.1322333 | S17: =IF(R17=0,0,J17/P17) -> 9.317067 | T17: =IF(S17=0,0,K17/P17) -> 8.4941921
A18: 9 | B18: =IF('Entries July 2026'!I15<'Entries July 2026'!I14,"0",(IF('Entries July 2026'!I15>='Entries July 2026'!I14,'Entries July 2026'!I15-'Entries July 2026'!I14,(999999-'Entries July 2026'!I14)+'Entries July 2026'!I15+1))) -> 6592 | C18: =IF('Entries July 2026'!J15<='Entries July 2026'!J14,"0",IF('Entries July 2026'!J15>='Entries July 2026'!J14,'Entries July 2026'!J15-'Entries July 2026'!J14,(999999-'Entries July 2026'!J14)+'Entries July 2026'!J15+1)) -> 0 | D18: =B18+C18 -> 6592 | E18: 1304 | F18: =IF((E18+D18)=0,"0",E18/(D18+E18)) -> 0.16514691 | G18: =IF('Entries July 2026'!K15<'Entries July 2026'!K14,"0",IF('Entries July 2026'!K15>='Entries July 2026'!K14,'Entries July 2026'!K15-'Entries July 2026'!K14,(999999-'Entries July 2026'!K14)+'Entries July 2026'!K15+1)) -> 0 | H18: =D18+G18+E18 -> 7896 | I18: ='Water '!Z15*10 -> 4080 | J18: =IF('Entries July 2026'!B15-'Entries July 2026'!B14<1,"0",'Entries July 2026'!B15-'Entries July 2026'!B14) -> 2510 | K18: ='CO2'!E15 -> 1600 | L18: =+'PROD.FIG. '!F13 -> 0 | M18: =+'PROD.FIG. '!C13 -> 0 | N18: =+'PROD.FIG. '!D13 -> 0 | O18: =+'PROD.FIG. '!E13 -> 0 | P18: 322.806 | Q18: =IF(P18=0,0,H18/P18) -> 24.460512 | R18: =IF(Q18=0,0,I18/P18) -> 12.63917 | S18: =IF(R18=0,0,J18/P18) -> 7.775568 | T18: =IF(S18=0,0,K18/P18) -> 4.9565374
A19: 10 | B19: =IF('Entries July 2026'!I16<'Entries July 2026'!I15,"0",(IF('Entries July 2026'!I16>='Entries July 2026'!I15,'Entries July 2026'!I16-'Entries July 2026'!I15,(999999-'Entries July 2026'!I15)+'Entries July 2026'!I16+1))) -> 7603 | C19: =IF('Entries July 2026'!J16<='Entries July 2026'!J15,"0",IF('Entries July 2026'!J16>='Entries July 2026'!J15,'Entries July 2026'!J16-'Entries July 2026'!J15,(999999-'Entries July 2026'!J15)+'Entries July 2026'!J16+1)) -> 0 | D19: =B19+C19 -> 7603 | E19: 1399.9 | F19: =IF((E19+D19)=0,"0",E19/(D19+E19)) -> 0.15549434 | G19: =IF('Entries July 2026'!K16<'Entries July 2026'!K15,"0",IF('Entries July 2026'!K16>='Entries July 2026'!K15,'Entries July 2026'!K16-'Entries July 2026'!K15,(999999-'Entries July 2026'!K15)+'Entries July 2026'!K16+1)) -> 0 | H19: =D19+G19+E19 -> 9002.9 | I19: ='Water '!Z16*10 -> 4130 | J19: =IF('Entries July 2026'!B16-'Entries July 2026'!B15<1,"0",'Entries July 2026'!B16-'Entries July 2026'!B15) -> 2950 | K19: ='CO2'!E16 -> 1900 | L19: =+'PROD.FIG. '!F14 -> 0 | M19: =+'PROD.FIG. '!C14 -> 0 | N19: =+'PROD.FIG. '!D14 -> 0 | O19: =+'PROD.FIG. '!E14 -> 0 | P19: 349.932 | Q19: =IF(P19=0,0,H19/P19) -> 25.72757 | R19: =IF(Q19=0,0,I19/P19) -> 11.802293 | S19: =IF(R19=0,0,J19/P19) -> 8.4302093 | T19: =IF(S19=0,0,K19/P19) -> 5.4296263
A20: 11 | B20: =IF('Entries July 2026'!I17<'Entries July 2026'!I16,"0",(IF('Entries July 2026'!I17>='Entries July 2026'!I16,'Entries July 2026'!I17-'Entries July 2026'!I16,(999999-'Entries July 2026'!I16)+'Entries July 2026'!I17+1))) -> 3837 | C20: =IF('Entries July 2026'!J17<='Entries July 2026'!J16,"0",IF('Entries July 2026'!J17>='Entries July 2026'!J16,'Entries July 2026'!J17-'Entries July 2026'!J16,(999999-'Entries July 2026'!J16)+'Entries July 2026'!J17+1)) -> 0 | D20: =B20+C20 -> 3837 | E20: 511.9 | F20: =IF((E20+D20)=0,"0",E20/(D20+E20)) -> 0.11770793 | G20: =IF('Entries July 2026'!K17<'Entries July 2026'!K16,"0",IF('Entries July 2026'!K17>='Entries July 2026'!K16,'Entries July 2026'!K17-'Entries July 2026'!K16,(999999-'Entries July 2026'!K16)+'Entries July 2026'!K17+1)) -> 0 | H20: =D20+G20+E20 -> 4348.9 | I20: ='Water '!Z17*10 -> 970 | J20: =IF('Entries July 2026'!B17-'Entries July 2026'!B16<1,"0",'Entries July 2026'!B17-'Entries July 2026'!B16) -> 2000 | K20: ='CO2'!E17 -> 300 | L20: =+'PROD.FIG. '!F15 -> 0 | M20: =+'PROD.FIG. '!C15 -> 0 | N20: =+'PROD.FIG. '!D15 -> 0 | O20: =+'PROD.FIG. '!E15 -> 0 | P20: 0 | Q20: =IF(P20=0,0,H20/P20) -> 0 | R20: =IF(Q20=0,0,I20/P20) -> 0 | S20: =IF(R20=0,0,J20/P20) -> 0 | T20: =IF(S20=0,0,K20/P20) -> 0
A21: 12 | B21: =IF('Entries July 2026'!I18<'Entries July 2026'!I17,"0",(IF('Entries July 2026'!I18>='Entries July 2026'!I17,'Entries July 2026'!I18-'Entries July 2026'!I17,(999999-'Entries July 2026'!I17)+'Entries July 2026'!I18+1))) -> 4845 | C21: =IF('Entries July 2026'!J18<='Entries July 2026'!J17,"0",IF('Entries July 2026'!J18>='Entries July 2026'!J17,'Entries July 2026'!J18-'Entries July 2026'!J17,(999999-'Entries July 2026'!J17)+'Entries July 2026'!J18+1)) -> 0 | D21: =B21+C21 -> 4845 | E21: 335.7 | F21: =IF((E21+D21)=0,"0",E21/(D21+E21)) -> 0.064798193 | G21: =IF('Entries July 2026'!K18<'Entries July 2026'!K17,"0",IF('Entries July 2026'!K18>='Entries July 2026'!K17,'Entries July 2026'!K18-'Entries July 2026'!K17,(999999-'Entries July 2026'!K17)+'Entries July 2026'!K18+1)) -> 0 | H21: =D21+G21+E21 -> 5180.7 | I21: ='Water '!Z18*10 -> 4650 | J21: =IF('Entries July 2026'!B18-'Entries July 2026'!B17<1,"0",'Entries July 2026'!B18-'Entries July 2026'!B17) -> 2480 | K21: ='CO2'!E18 -> 500 | L21: =+'PROD.FIG. '!F16 -> 0 | M21: =+'PROD.FIG. '!C16 -> 0 | N21: =+'PROD.FIG. '!D16 -> 0 | O21: =+'PROD.FIG. '!E16 -> 0 | P21: 0 | Q21: =IF(P21=0,0,H21/P21) -> 0 | R21: =IF(Q21=0,0,I21/P21) -> 0 | S21: =IF(R21=0,0,J21/P21) -> 0 | T21: =IF(S21=0,0,K21/P21) -> 0
A22: 13 | B22: =IF('Entries July 2026'!I19<'Entries July 2026'!I18,"0",(IF('Entries July 2026'!I19>='Entries July 2026'!I18,'Entries July 2026'!I19-'Entries July 2026'!I18,(999999-'Entries July 2026'!I18)+'Entries July 2026'!I19+1))) -> 8262 | C22: =IF('Entries July 2026'!J19<='Entries July 2026'!J18,"0",IF('Entries July 2026'!J19>='Entries July 2026'!J18,'Entries July 2026'!J19-'Entries July 2026'!J18,(999999-'Entries July 2026'!J18)+'Entries July 2026'!J19+1)) -> 0 | D22: =B22+C22 -> 8262 | E22: 740.4 | F22: =IF((E22+D22)=0,"0",E22/(D22+E22)) -> 0.082244735 | G22: =IF('Entries July 2026'!K19<'Entries July 2026'!K18,"0",IF('Entries July 2026'!K19>='Entries July 2026'!K18,'Entries July 2026'!K19-'Entries July 2026'!K18,(999999-'Entries July 2026'!K18)+'Entries July 2026'!K19+1)) -> 0 | H22: =D22+G22+E22 -> 9002.4 | I22: ='Water '!Z19*10 -> 2800 | J22: =IF('Entries July 2026'!B19-'Entries July 2026'!B18<1,"0",'Entries July 2026'!B19-'Entries July 2026'!B18) -> 2280 | K22: ='CO2'!E19 -> 1800 | L22: =+'PROD.FIG. '!F17 -> 0 | M22: =+'PROD.FIG. '!C17 -> 0 | N22: =+'PROD.FIG. '!D17 -> 0 | O22: =+'PROD.FIG. '!E17 -> 0 | P22: 407.22 | Q22: =IF(P22=0,0,H22/P22) -> 22.106969 | R22: =IF(Q22=0,0,I22/P22) -> 6.8758902 | S22: =IF(R22=0,0,J22/P22) -> 5.5989391 | T22: =IF(S22=0,0,K22/P22) -> 4.4202151
... A39: 30 | B39: =IF('Entries July 2026'!I36<'Entries July 2026'!I35,"0",(IF('Entries July 2026'!I36>='Entries July 2026'!I35,'Entries July 2026'!I36-'Entries July 2026'!I35,(999999-'Entries July 2026'!I35)+'Entries July 2026'!I36+1))) -> 9708 | C39: =IF('Entries July 2026'!J36<='Entries July 2026'!J35,"0",IF('Entries July 2026'!J36>='Entries July 2026'!J35,'Entries July 2026'!J36-'Entries July 2026'!J35,(999999-'Entries July 2026'!J35)+'Entries July 2026'!J36+1)) -> 0 | D39: =B39+C39 -> 9708 | E39: 1507.1 | F39: =IF((E39+D39)=0,"0",E39/(D39+E39)) -> 0.13438133 | G39: =IF('Entries July 2026'!K36<'Entries July 2026'!K35,"0",IF('Entries July 2026'!K36>='Entries July 2026'!K35,'Entries July 2026'!K36-'Entries July 2026'!K35,(999999-'Entries July 2026'!K35)+'Entries July 2026'!K36+1)) -> 0 | H39: =D39+G39+E39 -> 11215.1 | I39: ='Water '!Z36*10 -> 3470 | J39: =IF('Entries July 2026'!B36-'Entries July 2026'!B35<1,"0",'Entries July 2026'!B36-'Entries July 2026'!B35) -> 3920 | K39: ='CO2'!E36 -> 2500 | L39: =+'PROD.FIG. '!F34 -> 0 | M39: =+'PROD.FIG. '!C34 -> 0 | N39: =+'PROD.FIG. '!D34 -> 0 | O39: =+'PROD.FIG. '!E34 -> 0 | P39: 606.8688 | Q39: =IF(P39=0,0,H39/P39) -> 18.480271 | R39: =IF(Q39=0,0,I39/P39) -> 5.7178751 | S39: =IF(R39=0,0,J39/P39) -> 6.4593863 | T39: =IF(S39=0,0,K39/P39) -> 4.1195066
A40: 31 | B40: =IF('Entries July 2026'!I37<'Entries July 2026'!I36,"0",(IF('Entries July 2026'!I37>='Entries July 2026'!I36,'Entries July 2026'!I37-'Entries July 2026'!I36,(999999-'Entries July 2026'!I36)+'Entries July 2026'!I37+1))) -> 8223 | C40: =IF('Entries July 2026'!J37<='Entries July 2026'!J36,"0",IF('Entries July 2026'!J37>='Entries July 2026'!J36,'Entries July 2026'!J37-'Entries July 2026'!J36,(999999-'Entries July 2026'!J36)+'Entries July 2026'!J37+1)) -> 0 | D40: =B40+C40 -> 8223 | E40: 1320.9 | F40: =IF((E40+D40)=0,"0",E40/(D40+E40)) -> 0.13840254 | G40: =IF('Entries July 2026'!K37<'Entries July 2026'!K36,"0",IF('Entries July 2026'!K37>='Entries July 2026'!K36,'Entries July 2026'!K37-'Entries July 2026'!K36,(999999-'Entries July 2026'!K36)+'Entries July 2026'!K37+1)) -> 0 | H40: =D40+G40+E40 -> 9543.9 | I40: ='Water '!Z37*10 -> 3370 | J40: =IF('Entries July 2026'!B37-'Entries July 2026'!B36<1,"0",'Entries July 2026'!B37-'Entries July 2026'!B36) -> 3050 | K40: ='CO2'!E37 -> 1900 | P40: 498.498 | Q40: =IF(P40=0,0,H40/P40) -> 19.145313 | R40: =IF(Q40=0,0,I40/P40) -> 6.760308 | S40: =IF(R40=0,0,J40/P40) -> 6.1183796 | T40: =IF(S40=0,0,K40/P40) -> 3.8114496
Q41: MTD
D42: Kwhr | G42: Kwhr | H42: Kwhr | I42: Hl | J42: L | K42: kg. | L42: hl | M42: hl | N42: hl | O42: hl | P42: hl | Q42: Elect | R42: Water | S42: Fuel | T42: CO2
A43: Total | D43: =SUM(D10:D40) -> 220465 | E43: =SUM(E10:E40) -> 39202 | F43: =IF((E43+D43)=0,"0",E43/(D43+E43)) -> 0.15097028 | G43: =SUM(G10:G40) -> 0 | H43: =SUM(H10:H40) -> 259667 | I43: =SUM(I10:I40) -> 95230 | J43: =SUM(J10:J40) -> 82370 | K43: =SUM(K10:K40) -> 53100 | L43: =SUM(L10:L40) -> 0 | M43: =SUM(M10:M40) -> 0 | N43: =SUM(N10:N40) -> 0 | ... P43: =SUM(P10:P40) -> 8998.2516 | Q43: KWH/Hl | R43: Hl/hl | S43: Litres/hl | T43: kg./Hl
D44: TOTAL | E44: =D43+E43 -> 259667 | Q44: =IF(P43=0,0,H43/P43) -> 28.857495 | R44: =IF(Q44=0,0,I43/P43) -> 10.583167 | S44: =IF(R44=0,0,J43/P43) -> 9.1540005 | T44: =IF(S44=0,0,K43/P43) -> 5.9011464

Sheet Steam Mass Flow 
A3: DATE | B3: Steam Mass Flow Reading
A5: 1 | B5: =IF('Entries July 2026'!AJ7-'Entries July 2026'!AJ6<1,"0",'Entries July 2026'!AJ7-'Entries July 2026'!AJ6) -> 0
A6: 2 | B6: =IF('Entries July 2026'!AJ8-'Entries July 2026'!AJ7<1,"0",'Entries July 2026'!AJ8-'Entries July 2026'!AJ7) -> 0
A7: 3 | B7: =IF('Entries July 2026'!AJ9-'Entries July 2026'!AJ8<1,"0",'Entries July 2026'!AJ9-'Entries July 2026'!AJ8) -> 81.965
A8: 4 | B8: =IF('Entries July 2026'!AJ10-'Entries July 2026'!AJ9<1,"0",'Entries July 2026'!AJ10-'Entries July 2026'!AJ9) -> 9.577
A9: 5 | B9: =IF('Entries July 2026'!AJ11-'Entries July 2026'!AJ10<1,"0",'Entries July 2026'!AJ11-'Entries July 2026'!AJ10) -> 435.436
A10: 6 | B10: =IF('Entries July 2026'!AJ12-'Entries July 2026'!AJ11<1,"0",'Entries July 2026'!AJ12-'Entries July 2026'!AJ11) -> 0
A11: 7 | B11: =IF('Entries July 2026'!AJ13-'Entries July 2026'!AJ12<1,"0",'Entries July 2026'!AJ13-'Entries July 2026'!AJ12) -> 29.026
A12: 8 | B12: =IF('Entries July 2026'!AJ14-'Entries July 2026'!AJ13<1,"0",'Entries July 2026'!AJ14-'Entries July 2026'!AJ13) -> 0
A13: 9 | B13: =IF('Entries July 2026'!AJ15-'Entries July 2026'!AJ14<1,"0",'Entries July 2026'!AJ15-'Entries July 2026'!AJ14) -> 0
A14: 10 | B14: =IF('Entries July 2026'!AJ16-'Entries July 2026'!AJ15<1,"0",'Entries July 2026'!AJ16-'Entries July 2026'!AJ15) -> 0
A15: 11 | B15: =IF('Entries July 2026'!AJ17-'Entries July 2026'!AJ16<1,"0",'Entries July 2026'!AJ17-'Entries July 2026'!AJ16) -> 0
A16: 12 | B16: =IF('Entries July 2026'!AJ18-'Entries July 2026'!AJ17<1,"0",'Entries July 2026'!AJ18-'Entries July 2026'!AJ17) -> 0
... A35: 31 | B35: =IF('Entries July 2026'!AJ37-'Entries July 2026'!AJ36<1,"0",'Entries July 2026'!AJ37-'Entries July 2026'!AJ36) -> 0
B36: =SUM(B5:B35) -> 589.823

Sheet Fuel 
A1: DAILY FUEL CONSUMPTION FOR JULY 2026
A4: DATE | B4: Boiler 1 | C4: Boiler 1 | D4: Boiler 2 | E4: Boiler 2 | F4: Gen. | G4: Gen | H4: Boiler 1 sp. | I4: Boiler 2 sp. | J4: Gen. sp | K4: Daily cons. | L4: Total Prod.(HL) | M4: Fuel(Litres/HL)
B5: Cons ( l ) | C5: Hrs | D5: Cons ( l ) | E5: Hrs | F5: Cons ( l ) | G5: Hrs | H5: cons (l/hr) | I5: cons (l/hr) | J5: Cons.(l/hr) | K5: (litres)
A7: 1 | B7: =IF('Entries July 2026'!B7-'Entries July 2026'!B6<1,"0",'Entries July 2026'!B7-'Entries July 2026'!B6) -> 2840 | C7: =IF('Entries July 2026'!F7-'Entries July 2026'!F6<1,"0",'Entries July 2026'!F7-'Entries July 2026'!F6) -> 21.1 | D7: =IF('Entries July 2026'!C6=0,0,+'Entries July 2026'!C6-'Entries July 2026'!#REF!) -> 0 | E7: =IF('Entries July 2026'!G7-'Entries July 2026'!G6<1,"0",'Entries July 2026'!G7-'Entries July 2026'!G6) -> 0 | H7: =IF(C7+E7=0,"0", B7/(C7+E7)) -> 134.59716 | I7: =IF(E7=0,"0", D7/E7) -> 0 | J7: =IF(G7=0,"0", F7/G7) -> 0 | K7: =B7+D7+F7 -> 2840 | L7: {=IF(TRANSPOSE('Daily KPIs'!B9:AF9)=0,"0",TRANSPOSE('Daily KPIs'!B9:AF9))} -> 471.8652 | M7: =IF(L7=0,"0",(K7/L7)) -> 6.018668
A8: 2 | B8: =IF('Entries July 2026'!B8-'Entries July 2026'!B7<1,"0",'Entries July 2026'!B8-'Entries July 2026'!B7) -> 3450 | C8: =IF('Entries July 2026'!F8-'Entries July 2026'!F7<1,"0",'Entries July 2026'!F8-'Entries July 2026'!F7) -> 21.4 | D8: =IF('Entries July 2026'!C7=0,0,+'Entries July 2026'!C7-'Entries July 2026'!C6) -> 0 | E8: =IF('Entries July 2026'!G8-'Entries July 2026'!G7<1,"0",'Entries July 2026'!G8-'Entries July 2026'!G7) -> 0 | H8: =IF(C8+E8=0,"0", B8/(C8+E8)) -> 161.21495 | I8: =IF(E8=0,"0", D8/E8) -> 0 | J8: =IF(G8=0,"0", F8/G8) -> 0 | K8: =B8+D8+F8 -> 3450 | L8: 507.3684 | M8: =IF(L8=0,"0",(K8/L8)) -> 6.7997928
A9: 3 | B9: =IF('Entries July 2026'!B9-'Entries July 2026'!B8<1,"0",'Entries July 2026'!B9-'Entries July 2026'!B8) -> 2990 | C9: =IF('Entries July 2026'!F9-'Entries July 2026'!F8<1,"0",'Entries July 2026'!F9-'Entries July 2026'!F8) -> 19.9 | D9: =IF('Entries July 2026'!C8=0,0,+'Entries July 2026'!C8-'Entries July 2026'!C7) -> 0 | E9: =IF('Entries July 2026'!G9-'Entries July 2026'!G8<1,"0",'Entries July 2026'!G9-'Entries July 2026'!G8) -> 0 | H9: =IF(C9+E9=0,"0", B9/(C9+E9)) -> 150.25126 | I9: =IF(E9=0,"0", D9/E9) -> 0 | J9: =IF(G9=0,"0", F9/G9) -> 0 | K9: =B9+D9+F9 -> 2990 | L9: 492.096 | M9: =IF(L9=0,"0",(K9/L9)) -> 6.0760502
A10: 4 | B10: =IF('Entries July 2026'!B10-'Entries July 2026'!B9<1,"0",'Entries July 2026'!B10-'Entries July 2026'!B9) -> 940 | C10: =IF('Entries July 2026'!F10-'Entries July 2026'!F9<1,"0",'Entries July 2026'!F10-'Entries July 2026'!F9) -> 6.7 | D10: =IF('Entries July 2026'!C11=0,0,+'Entries July 2026'!C11-'Entries July 2026'!C8) -> 0 | E10: =IF('Entries July 2026'!G10-'Entries July 2026'!G9<1,"0",'Entries July 2026'!G10-'Entries July 2026'!G9) -> 0 | H10: =IF(C10+E10=0,"0", B10/(C10+E10)) -> 140.29851 | I10: =IF(E10=0,"0", D10/E10) -> 0 | J10: =IF(G10=0,"0", F10/G10) -> 0 | K10: =B10+D10+F10 -> 940 | L10: 0 | M10: =IF(L10=0,"0",(K10/L10)) -> 0
A11: 5 | B11: =IF('Entries July 2026'!B11-'Entries July 2026'!B10<1,"0",'Entries July 2026'!B11-'Entries July 2026'!B10) -> 1480 | C11: =IF('Entries July 2026'!F11-'Entries July 2026'!F10<1,"0",'Entries July 2026'!F11-'Entries July 2026'!F10) -> 9 | D11: =IF('Entries July 2026'!C10=0,0,+'Entries July 2026'!C10-'Entries July 2026'!C11) -> 0 | E11: =IF('Entries July 2026'!G11-'Entries July 2026'!G10<1,"0",'Entries July 2026'!G11-'Entries July 2026'!G10) -> 0 | H11: =IF(C11+E11=0,"0", B11/(C11+E11)) -> 164.44444 | I11: =IF(E11=0,"0", D11/E11) -> 0 | J11: =IF(G11=0,"0", F11/G11) -> 0 | K11: =B11+D11+F11 -> 1480 | L11: 0 | M11: =IF(L11=0,"0",(K11/L11)) -> 0
A12: 6 | B12: =IF('Entries July 2026'!B12-'Entries July 2026'!B11<1,"0",'Entries July 2026'!B12-'Entries July 2026'!B11) -> 2410 | C12: =IF('Entries July 2026'!F12-'Entries July 2026'!F11<1,"0",'Entries July 2026'!F12-'Entries July 2026'!F11) -> 15.4 | D12: =IF('Entries July 2026'!C12=0,0,+'Entries July 2026'!C12-'Entries July 2026'!C10) -> 0 | E12: =IF('Entries July 2026'!G12-'Entries July 2026'!G11<1,"0",'Entries July 2026'!G12-'Entries July 2026'!G11) -> 0 | H12: =IF(C12+E12=0,"0", B12/(C12+E12)) -> 156.49351 | I12: =IF(E12=0,"0", D12/E12) -> 0 | J12: =IF(G12=0,"0", F12/G12) -> 0 | K12: =B12+D12+F12 -> 2410 | L12: 410.784 | M12: =IF(L12=0,"0",(K12/L12)) -> 5.8668303
A13: 7 | B13: =IF('Entries July 2026'!B13-'Entries July 2026'!B12<1,"0",'Entries July 2026'!B13-'Entries July 2026'!B12) -> 2810 | C13: =IF('Entries July 2026'!F13-'Entries July 2026'!F12<1,"0",'Entries July 2026'!F13-'Entries July 2026'!F12) -> 19.2 | D13: =IF('Entries July 2026'!C13=0,0,+'Entries July 2026'!C13-'Entries July 2026'!C11) -> 0 | E13: =IF('Entries July 2026'!G13-'Entries July 2026'!G12<1,"0",'Entries July 2026'!G13-'Entries July 2026'!G12) -> 0 | H13: =IF(C13+E13=0,"0", B13/(C13+E13)) -> 146.35417 | I13: =IF(E13=0,"0", D13/E13) -> 0 | J13: =IF(G13=0,"0", F13/G13) -> 0 | K13: =B13+D13+F13 -> 2810 | L13: 209.88 | M13: =IF(L13=0,"0",(K13/L13)) -> 13.388603
A14: 8 | B14: =IF('Entries July 2026'!B14-'Entries July 2026'!B13<1,"0",'Entries July 2026'!B14-'Entries July 2026'!B13) -> 3510 | C14: =IF('Entries July 2026'!F14-'Entries July 2026'!F13<1,"0",'Entries July 2026'!F14-'Entries July 2026'!F13) -> 20.2 | D14: =IF('Entries July 2026'!C13=0,0,+'Entries July 2026'!C13-'Entries July 2026'!#REF!) -> 0 | E14: =IF('Entries July 2026'!G14-'Entries July 2026'!G13<1,"0",'Entries July 2026'!G14-'Entries July 2026'!G13) -> 0 | H14: =IF(C14+E14=0,"0", B14/(C14+E14)) -> 173.76238 | I14: =IF(E14=0,"0", D14/E14) -> 0 | J14: =IF(G14=0,"0", F14/G14) -> 0 | K14: =B14+D14+F14 -> 3510 | L14: 376.728 | M14: =IF(L14=0,"0",(K14/L14)) -> 9.317067
A15: 9 | B15: =IF('Entries July 2026'!B15-'Entries July 2026'!B14<1,"0",'Entries July 2026'!B15-'Entries July 2026'!B14) -> 2510 | C15: =IF('Entries July 2026'!F15-'Entries July 2026'!F14<1,"0",'Entries July 2026'!F15-'Entries July 2026'!F14) -> 19.5 | D15: =IF('Entries July 2026'!C14=0,0,+'Entries July 2026'!C14-'Entries July 2026'!C13) -> 0 | E15: =IF('Entries July 2026'!G15-'Entries July 2026'!G14<1,"0",'Entries July 2026'!G15-'Entries July 2026'!G14) -> 0 | H15: =IF(C15+E15=0,"0", B15/(C15+E15)) -> 128.71795 | I15: =IF(E15=0,"0", D15/E15) -> 0 | J15: =IF(G15=0,"0", F15/G15) -> 0 | K15: =B15+D15+F15 -> 2510 | L15: 322.806 | M15: =IF(L15=0,"0",(K15/L15)) -> 7.775568
A16: 10 | B16: =IF('Entries July 2026'!B16-'Entries July 2026'!B15<1,"0",'Entries July 2026'!B16-'Entries July 2026'!B15) -> 2950 | C16: =IF('Entries July 2026'!F16-'Entries July 2026'!F15<1,"0",'Entries July 2026'!F16-'Entries July 2026'!F15) -> 18.9 | D16: =IF('Entries July 2026'!C15=0,0,+'Entries July 2026'!C15-'Entries July 2026'!C14) -> 0 | E16: =IF('Entries July 2026'!G16-'Entries July 2026'!G15<1,"0",'Entries July 2026'!G16-'Entries July 2026'!G15) -> 0 | H16: =IF(C16+E16=0,"0", B16/(C16+E16)) -> 156.08466 | I16: =IF(E16=0,"0", D16/E16) -> 0 | J16: =IF(G16=0,"0", F16/G16) -> 0 | K16: =B16+D16+F16 -> 2950 | L16: 349.932 | M16: =IF(L16=0,"0",(K16/L16)) -> 8.4302093
A17: 11 | B17: =IF('Entries July 2026'!B17-'Entries July 2026'!B16<1,"0",'Entries July 2026'!B17-'Entries July 2026'!B16) -> 2000 | C17: =IF('Entries July 2026'!F17-'Entries July 2026'!F16<1,"0",'Entries July 2026'!F17-'Entries July 2026'!F16) -> 14.4 | D17: =IF('Entries July 2026'!C16=0,0,+'Entries July 2026'!C16-'Entries July 2026'!C15) -> 0 | E17: =IF('Entries July 2026'!G17-'Entries July 2026'!G16<1,"0",'Entries July 2026'!G17-'Entries July 2026'!G16) -> 0 | H17: =IF(C17+E17=0,"0", B17/(C17+E17)) -> 138.88889 | I17: =IF(E17=0,"0", D17/E17) -> 0 | J17: =IF(G17=0,"0", F17/G17) -> 0 | K17: =B17+D17+F17 -> 2000 | L17: 0 | M17: =IF(L17=0,"0",(K17/L17)) -> 0
A18: 12 | B18: =IF('Entries July 2026'!B18-'Entries July 2026'!B17<1,"0",'Entries July 2026'!B18-'Entries July 2026'!B17) -> 2480 | C18: =IF('Entries July 2026'!F18-'Entries July 2026'!F17<1,"0",'Entries July 2026'!F18-'Entries July 2026'!F17) -> 19.48 | D18: =IF('Entries July 2026'!C17=0,0,+'Entries July 2026'!C17-'Entries July 2026'!C16) -> 0 | E18: =IF('Entries July 2026'!G18-'Entries July 2026'!G17<1,"0",'Entries July 2026'!G18-'Entries July 2026'!G17) -> 0 | H18: =IF(C18+E18=0,"0", B18/(C18+E18)) -> 127.31006 | I18: =IF(E18=0,"0", D18/E18) -> 0 | J18: =IF(G18=0,"0", F18/G18) -> 0 | K18: =B18+D18+F18 -> 2480 | L18: 0 | M18: =IF(L18=0,"0",(K18/L18)) -> 0
A19: 13 | B19: =IF('Entries July 2026'!B19-'Entries July 2026'!B18<1,"0",'Entries July 2026'!B19-'Entries July 2026'!B18) -> 2280 | C19: =IF('Entries July 2026'!F19-'Entries July 2026'!F18<1,"0",'Entries July 2026'!F19-'Entries July 2026'!F18) -> 16.52 | D19: =IF('Entries July 2026'!C18=0,0,+'Entries July 2026'!C18-'Entries July 2026'!C17) -> 0 | E19: =IF('Entries July 2026'!G19-'Entries July 2026'!G18<1,"0",'Entries July 2026'!G19-'Entries July 2026'!G18) -> 0 | H19: =IF(C19+E19=0,"0", B19/(C19+E19)) -> 138.01453 | I19: =IF(E19=0,"0", D19/E19) -> 0 | J19: =IF(G19=0,"0", F19/G19) -> 0 | K19: =B19+D19+F19 -> 2280 | L19: 407.22 | M19: =IF(L19=0,"0",(K19/L19)) -> 5.5989391
A20: 14 | B20: =IF('Entries July 2026'!B20-'Entries July 2026'!B19<1,"0",'Entries July 2026'!B20-'Entries July 2026'!B19) -> 3620 | C20: =IF('Entries July 2026'!F20-'Entries July 2026'!F19<1,"0",'Entries July 2026'!F20-'Entries July 2026'!F19) -> 22.1 | D20: =IF('Entries July 2026'!C19=0,0,+'Entries July 2026'!C19-'Entries July 2026'!C18) -> 0 | E20: =IF('Entries July 2026'!G20-'Entries July 2026'!G19<1,"0",'Entries July 2026'!G20-'Entries July 2026'!G19) -> 0 | H20: =IF(C20+E20=0,"0", B20/(C20+E20)) -> 163.8009 | I20: =IF(E20=0,"0", D20/E20) -> 0 | J20: =IF(G20=0,"0", F20/G20) -> 0 | K20: =B20+D20+F20 -> 3620 | L20: 603.57 | M20: =IF(L20=0,"0",(K20/L20)) -> 5.9976473
A21: 15 | B21: =IF('Entries July 2026'!B21-'Entries July 2026'!B20<1,"0",'Entries July 2026'!B21-'Entries July 2026'!B20) -> 2990 | C21: =IF('Entries July 2026'!F21-'Entries July 2026'!F20<1,"0",'Entries July 2026'!F21-'Entries July 2026'!F20) -> 20.8 | D21: =IF('Entries July 2026'!C20=0,0,+'Entries July 2026'!C20-'Entries July 2026'!C19) -> 0 | E21: =IF('Entries July 2026'!G21-'Entries July 2026'!G20<1,"0",'Entries July 2026'!G21-'Entries July 2026'!G20) -> 0 | H21: =IF(C21+E21=0,"0", B21/(C21+E21)) -> 143.75 | I21: =IF(E21=0,"0", D21/E21) -> 0 | J21: =IF(G21=0,"0", F21/G21) -> 0 | K21: =B21+D21+F21 -> 2990 | L21: 387.684 | M21: =IF(L21=0,"0",(K21/L21)) -> 7.7124669
A22: 16 | B22: =IF('Entries July 2026'!B22-'Entries July 2026'!B21<1,"0",'Entries July 2026'!B22-'Entries July 2026'!B21) -> 2910 | C22: =IF('Entries July 2026'!F22-'Entries July 2026'!F21<1,"0",'Entries July 2026'!F22-'Entries July 2026'!F21) -> 18.8 | D22: =IF('Entries July 2026'!C21=0,0,+'Entries July 2026'!C21-'Entries July 2026'!C20) -> 0 | E22: =IF('Entries July 2026'!G22-'Entries July 2026'!G21<1,"0",'Entries July 2026'!G22-'Entries July 2026'!G21) -> 0 | H22: =IF(C22+E22=0,"0", B22/(C22+E22)) -> 154.78723 | I22: =IF(E22=0,"0", D22/E22) -> 0 | J22: =IF(G22=0,"0", F22/G22) -> 0 | K22: =B22+D22+F22 -> 2910 | L22: 425.106 | M22: =IF(L22=0,"0",(K22/L22)) -> 6.8453515
A23: 17 | B23: =IF('Entries July 2026'!B23-'Entries July 2026'!B22<1,"0",'Entries July 2026'!B23-'Entries July 2026'!B22) -> 2830 | C23: =IF('Entries July 2026'!F23-'Entries July 2026'!F22<1,"0",'Entries July 2026'!F23-'Entries July 2026'!F22) -> 19.4 | D23: =IF('Entries July 2026'!C22=0,0,+'Entries July 2026'!C22-'Entries July 2026'!C21) -> 0 | E23: =IF('Entries July 2026'!G23-'Entries July 2026'!G22<1,"0",'Entries July 2026'!G23-'Entries July 2026'!G22) -> 0 | H23: =IF(C23+E23=0,"0", B23/(C23+E23)) -> 145.87629 | I23: =IF(E23=0,"0", D23/E23) -> 0 | J23: =IF(G23=0,"0", F23/G23) -> 0 | K23: =B23+D23+F23 -> 2830 | L23: 71.94 | M23: =IF(L23=0,"0",(K23/L23)) -> 39.338338
A24: 18 | B24: =IF('Entries July 2026'!B24-'Entries July 2026'!B23<1,"0",'Entries July 2026'!B24-'Entries July 2026'!B23) -> 840 | C24: =IF('Entries July 2026'!F24-'Entries July 2026'!F23<1,"0",'Entries July 2026'!F24-'Entries July 2026'!F23) -> 5.8 | D24: =IF('Entries July 2026'!C23=0,0,+'Entries July 2026'!C23-'Entries July 2026'!C22) -> 0 | E24: =IF('Entries July 2026'!G24-'Entries July 2026'!G23<1,"0",'Entries July 2026'!G24-'Entries July 2026'!G23) -> 0 | H24: =IF(C24+E24=0,"0", B24/(C24+E24)) -> 144.82759 | I24: =IF(E24=0,"0", D24/E24) -> 0 | J24: =IF(G24=0,"0", F24/G24) -> 0 | K24: =B24+D24+F24 -> 840 | L24: 0 | M24: =IF(L24=0,"0",(K24/L24)) -> 0
A25: 19 | B25: =IF('Entries July 2026'!B25-'Entries July 2026'!B24<1,"0",'Entries July 2026'!B25-'Entries July 2026'!B24) -> 2010 | C25: =IF('Entries July 2026'!F25-'Entries July 2026'!F24<1,"0",'Entries July 2026'!F25-'Entries July 2026'!F24) -> 14.3 | D25: =IF('Entries July 2026'!C24=0,0,+'Entries July 2026'!C24-'Entries July 2026'!C23) -> 0 | E25: =IF('Entries July 2026'!G25-'Entries July 2026'!G24<1,"0",'Entries July 2026'!G25-'Entries July 2026'!G24) -> 0 | H25: =IF(C25+E25=0,"0", B25/(C25+E25)) -> 140.55944 | I25: =IF(E25=0,"0", D25/E25) -> 0 | J25: =IF(G25=0,"0", F25/G25) -> 0 | K25: =B25+D25+F25 -> 2010 | L25: 0 | M25: =IF(L25=0,"0",(K25/L25)) -> 0
A26: 20 | B26: =IF('Entries July 2026'!B26-'Entries July 2026'!B25<1,"0",'Entries July 2026'!B26-'Entries July 2026'!B25) -> 3320 | C26: =IF('Entries July 2026'!F26-'Entries July 2026'!F25<1,"0",'Entries July 2026'!F26-'Entries July 2026'!F25) -> 21 | D26: =IF('Entries July 2026'!C25=0,0,+'Entries July 2026'!C25-'Entries July 2026'!C24) -> 0 | E26: =IF('Entries July 2026'!G26-'Entries July 2026'!G25<1,"0",'Entries July 2026'!G26-'Entries July 2026'!G25) -> 0 | H26: =IF(C26+E26=0,"0", B26/(C26+E26)) -> 158.09524 | I26: =IF(E26=0,"0", D26/E26) -> 0 | J26: =IF(G26=0,"0", F26/G26) -> 0 | K26: =B26+D26+F26 -> 3320 | L26: 406.89 | M26: =IF(L26=0,"0",(K26/L26)) -> 8.1594534
A27: 21 | B27: =IF('Entries July 2026'!B27-'Entries July 2026'!B26<1,"0",'Entries July 2026'!B27-'Entries July 2026'!B26) -> 3960 | C27: =IF('Entries July 2026'!F27-'Entries July 2026'!F26<1,"0",'Entries July 2026'!F27-'Entries July 2026'!F26) -> 23.7 | D27: =IF('Entries July 2026'!C26=0,0,+'Entries July 2026'!C26-'Entries July 2026'!C25) -> 0 | E27: =IF('Entries July 2026'!G27-'Entries July 2026'!G26<1,"0",'Entries July 2026'!G27-'Entries July 2026'!G26) -> 0 | H27: =IF(C27+E27=0,"0", B27/(C27+E27)) -> 167.08861 | I27: =IF(E27=0,"0", D27/E27) -> 0 | J27: =IF(G27=0,"0", F27/G27) -> 0 | K27: =B27+D27+F27 -> 3960 | L27: 500.148 | M27: =IF(L27=0,"0",(K27/L27)) -> 7.9176564
A28: 22 | B28: =IF('Entries July 2026'!B28-'Entries July 2026'!B27<1,"0",'Entries July 2026'!B28-'Entries July 2026'!B27) -> 2980 | C28: =IF('Entries July 2026'!F28-'Entries July 2026'!F27<1,"0",'Entries July 2026'!F28-'Entries July 2026'!F27) -> 19.1 | D28: =IF('Entries July 2026'!C27=0,0,+'Entries July 2026'!C27-'Entries July 2026'!C26) -> 0 | E28: =IF('Entries July 2026'!G28-'Entries July 2026'!G27<1,"0",'Entries July 2026'!G28-'Entries July 2026'!G27) -> 0 | H28: =IF(C28+E28=0,"0", B28/(C28+E28)) -> 156.02094 | I28: =IF(E28=0,"0", D28/E28) -> 0 | J28: =IF(G28=0,"0", F28/G28) -> 0 | K28: =B28+D28+F28 -> 2980 | L28: 202.554 | M28: =IF(L28=0,"0",(K28/L28)) -> 14.712126
A29: 23 | B29: =IF('Entries July 2026'!B29-'Entries July 2026'!B28<1,"0",'Entries July 2026'!B29-'Entries July 2026'!B28) -> 3230 | C29: =IF('Entries July 2026'!F29-'Entries July 2026'!F28<1,"0",'Entries July 2026'!F29-'Entries July 2026'!F28) -> 20.4 | D29: =IF('Entries July 2026'!C28=0,0,+'Entries July 2026'!C28-'Entries July 2026'!C27) -> 0 | E29: =IF('Entries July 2026'!G29-'Entries July 2026'!G28<1,"0",'Entries July 2026'!G29-'Entries July 2026'!G28) -> 0 | H29: =IF(C29+E29=0,"0", B29/(C29+E29)) -> 158.33333 | I29: =IF(E29=0,"0", D29/E29) -> 0 | J29: =IF(G29=0,"0", F29/G29) -> 0 | K29: =B29+D29+F29 -> 3230 | L29: 258.786 | M29: =IF(L29=0,"0",(K29/L29)) -> 12.481355
A30: 24 | B30: =IF('Entries July 2026'!B30-'Entries July 2026'!B29<1,"0",'Entries July 2026'!B30-'Entries July 2026'!B29) -> 2840 | C30: =IF('Entries July 2026'!F30-'Entries July 2026'!F29<1,"0",'Entries July 2026'!F30-'Entries July 2026'!F29) -> 14.8 | D30: =IF('Entries July 2026'!C29=0,0,+'Entries July 2026'!C29-'Entries July 2026'!C28) -> 0 | E30: =IF('Entries July 2026'!G30-'Entries July 2026'!G29<1,"0",'Entries July 2026'!G30-'Entries July 2026'!G29) -> 0 | H30: =IF(C30+E30=0,"0", B30/(C30+E30)) -> 191.89189 | I30: =IF(E30=0,"0", D30/E30) -> 0 | J30: =IF(G30=0,"0", F30/G30) -> 0 | K30: =B30+D30+F30 -> 2840 | L30: 91.872 | M30: =IF(L30=0,"0",(K30/L30)) -> 30.912574
A31: 25 | B31: =IF('Entries July 2026'!B31-'Entries July 2026'!B30<1,"0",'Entries July 2026'!B31-'Entries July 2026'!B30) -> 450 | C31: =IF('Entries July 2026'!F31-'Entries July 2026'!F30<1,"0",'Entries July 2026'!F31-'Entries July 2026'!F30) -> 7.8 | D31: =IF('Entries July 2026'!C30=0,0,+'Entries July 2026'!C30-'Entries July 2026'!C29) -> 0 | E31: =IF('Entries July 2026'!G31-'Entries July 2026'!G30<1,"0",'Entries July 2026'!G31-'Entries July 2026'!G30) -> 0 | H31: =IF(C31+E31=0,"0", B31/(C31+E31)) -> 57.692308 | I31: =IF(E31=0,"0", D31/E31) -> 0 | J31: =IF(G31=0,"0", F31/G31) -> 0 | K31: =B31+D31+F31 -> 450 | L31: 0 | M31: =IF(L31=0,"0",(K31/L31)) -> 0
A32: 26 | B32: =IF('Entries July 2026'!B32-'Entries July 2026'!B31<1,"0",'Entries July 2026'!B32-'Entries July 2026'!B31) -> 940 | C32: =IF('Entries July 2026'!F32-'Entries July 2026'!F31<1,"0",'Entries July 2026'!F32-'Entries July 2026'!F31) -> 6.6 | D32: =IF('Entries July 2026'!C31=0,0,+'Entries July 2026'!C31-'Entries July 2026'!C30) -> 0 | E32: =IF('Entries July 2026'!G32-'Entries July 2026'!G31<1,"0",'Entries July 2026'!G32-'Entries July 2026'!G31) -> 0 | H32: =IF(C32+E32=0,"0", B32/(C32+E32)) -> 142.42424 | I32: =IF(E32=0,"0", D32/E32) -> 0 | J32: =IF(G32=0,"0", F32/G32) -> 0 | K32: =B32+D32+F32 -> 940 | L32: 0 | M32: =IF(L32=0,"0",(K32/L32)) -> 0
A33: 27 | B33: =IF('Entries July 2026'!B33-'Entries July 2026'!B32<1,"0",'Entries July 2026'!B33-'Entries July 2026'!B32) -> 2870 | C33: =IF('Entries July 2026'!F33-'Entries July 2026'!F32<1,"0",'Entries July 2026'!F33-'Entries July 2026'!F32) -> 19.8 | D33: =IF('Entries July 2026'!C32=0,0,+'Entries July 2026'!C32-'Entries July 2026'!C31) -> 0 | E33: =IF('Entries July 2026'!G33-'Entries July 2026'!G32<1,"0",'Entries July 2026'!G33-'Entries July 2026'!G32) -> 0 | H33: =IF(C33+E33=0,"0", B33/(C33+E33)) -> 144.94949 | I33: =IF(E33=0,"0", D33/E33) -> 0 | J33: =IF(G33=0,"0", F33/G33) -> 0 | K33: =B33+D33+F33 -> 2870 | L33: 365.97 | M33: =IF(L33=0,"0",(K33/L33)) -> 7.8421729
A34: 28 | B34: =IF('Entries July 2026'!B34-'Entries July 2026'!B33<1,"0",'Entries July 2026'!B34-'Entries July 2026'!B33) -> 3650 | C34: =IF('Entries July 2026'!F34-'Entries July 2026'!F33<1,"0",'Entries July 2026'!F34-'Entries July 2026'!F33) -> 21.5 | D34: =IF('Entries July 2026'!C33=0,0,+'Entries July 2026'!C33-'Entries July 2026'!C32) -> 0 | E34: =IF('Entries July 2026'!G34-'Entries July 2026'!G33<1,"0",'Entries July 2026'!G34-'Entries July 2026'!G33) -> 0 | H34: =IF(C34+E34=0,"0", B34/(C34+E34)) -> 169.76744 | I34: =IF(E34=0,"0", D34/E34) -> 0 | J34: =IF(G34=0,"0", F34/G34) -> 0 | K34: =B34+D34+F34 -> 3650 | L34: 642.048 | M34: =IF(L34=0,"0",(K34/L34)) -> 5.6849332
A35: 29 | B35: =IF('Entries July 2026'!B35-'Entries July 2026'!B34<1,"0",'Entries July 2026'!B35-'Entries July 2026'!B34) -> 3310 | C35: =IF('Entries July 2026'!F35-'Entries July 2026'!F34<1,"0",'Entries July 2026'!F35-'Entries July 2026'!F34) -> 21.2 | E35: =IF('Entries July 2026'!G35-'Entries July 2026'!G34<1,"0",'Entries July 2026'!G35-'Entries July 2026'!G34) -> 0 | H35: =IF(C35+E35=0,"0", B35/(C35+E35)) -> 156.13208 | I35: =IF(E35=0,"0", D35/E35) -> 0 | J35: =IF(G35=0,"0", F35/G35) -> 0 | K35: =B35+D35+F35 -> 3310 | L35: 387.6372 | M35: =IF(L35=0,"0",(K35/L35)) -> 8.5389122
A36: 30 | B36: =IF('Entries July 2026'!B36-'Entries July 2026'!B35<1,"0",'Entries July 2026'!B36-'Entries July 2026'!B35) -> 3920 | C36: =IF('Entries July 2026'!F36-'Entries July 2026'!F35<1,"0",'Entries July 2026'!F36-'Entries July 2026'!F35) -> 22.8 | E36: =IF('Entries July 2026'!G36-'Entries July 2026'!G35<1,"0",'Entries July 2026'!G36-'Entries July 2026'!G35) -> 0 | H36: =IF(C36+E36=0,"0", B36/(C36+E36)) -> 171.92982 | I36: =IF(E36=0,"0", D36/E36) -> 0 | J36: =IF(G36=0,"0", F36/G36) -> 0 | K36: =B36+D36+F36 -> 3920 | L36: 606.8688 | M36: =IF(L36=0,"0",(K36/L36)) -> 6.4593863
A37: 31 | B37: =IF('Entries July 2026'!B37-'Entries July 2026'!B36<1,"0",'Entries July 2026'!B37-'Entries July 2026'!B36) -> 3050 | C37: =IF('Entries July 2026'!F37-'Entries July 2026'!F36<1,"0",'Entries July 2026'!F37-'Entries July 2026'!F36) -> 17.8 | E37: =IF('Entries July 2026'!G37-'Entries July 2026'!G36<1,"0",'Entries July 2026'!G37-'Entries July 2026'!G36) -> 0 | H37: =IF(C37+E37=0,"0", B37/(C37+E37)) -> 171.34831 | I37: =IF(E37=0,"0", D37/E37) -> 0 | J37: =IF(G37=0,"0", F37/G37) -> 0 | K37: =B37+D37+F37 -> 3050 | L37: 498.498
B38: =SUM(B7:B37) -> 82370 | C38: =SUM(C7:C37) -> 539.4 | D38: =SUM(D7:D37) -> 0 | E38: =SUM(E7:E37) -> 0 | F38: =SUM(F7:F37) -> 0 | G38: =SUM(G7:G37) -> 0 | H38: =SUM(H7:H37) -> 4655.7076 | M38: =IF(L38=0,"0",(K38/L38)) -> 0 | N38: 7.2 | O38: =M38/N38*100 -> 0
A39: AVE. | B39: =AVERAGE(B7:B37) -> 2657.0968 | C39: =AVERAGE(C7:C37) -> 17.4 | H39: cons (l/hr)

Sheet Water 
B4: DATE | C4: Well Supply (m3) | D4: Nawasa Supply (m3) | E4: Annanale Supply (m3) | F4: RO Water Plant Nawasa (m3) | G4: Service Water Received (m3) | H4: Service Water Supply to Plant (m3) | I4: CO2 Scrubber (m3) | J4: Brewhouse / Old Pepsi Area (m3) | K4: Filtration/Cellars (m3) | L4: Cellars/Process Area (m3) | M4: Pasteuriser (m3) | R4: Permeate Produced (m3) | S4: Plant Cons. USAGE (Hl.) | U4: Bottle Filler (m3) | X4: Rus (m3) | Y4: Washdown Area (m3) | Z4: TOTAL SUPPLY (M3) | AA4: Total Prod.(HL) | AB4: Water KPI (Hl/Hl)
N5: CIP Process (m3) | O5: Bottles Washer (m3) | P5: Bottles Filler (m3) | Q5: Boiler Supply (m3) | T5: ∑ Service Water to Processes | V5: Water into RO #1 (m3) | W5: Water into RO #2 (m3)
B6: -
B7: 1 | C7: =IF('Entries July 2026'!W7-'Entries July 2026'!W6<1,"0",'Entries July 2026'!W7-'Entries July 2026'!W6) -> 0 | D7: =IF('Entries July 2026'!O7-'Entries July 2026'!O6<1,"0",'Entries July 2026'!O7-'Entries July 2026'!O6) -> 266 | E7: =IF('Entries July 2026'!P7-'Entries July 2026'!P6<1,"0",'Entries July 2026'!P7-'Entries July 2026'!P6) -> 177 | F7: =IF('Entries July 2026'!V7-'Entries July 2026'!V6<1,"0",'Entries July 2026'!V7-'Entries July 2026'!V6) -> 188 | G7: =(D7+E7)-F7 -> 255 | H7: =IF('Entries July 2026'!Q7-'Entries July 2026'!Q6<1,0,'Entries July 2026'!Q7-'Entries July 2026'!Q6) -> 218 | I7: =IF('Entries July 2026'!AG7-'Entries July 2026'!AG6<1,0,'Entries July 2026'!AG7-'Entries July 2026'!AG6) -> 0 | J7: =IF('Entries July 2026'!S7-'Entries July 2026'!S6<1,"0",'Entries July 2026'!S7-'Entries July 2026'!S6) -> 154 | K7: =IF('Entries July 2026'!R7-'Entries July 2026'!R6<1,"0",'Entries July 2026'!R7-'Entries July 2026'!R6) -> 0 | L7: =IF('Entries July 2026'!T7-'Entries July 2026'!T6<1,"0",'Entries July 2026'!T7-'Entries July 2026'!T6) -> 0 | M7: =IF('Entries July 2026'!U7-'Entries July 2026'!U6<1,"0",'Entries July 2026'!U7-'Entries July 2026'!U6) -> 3 | N7: =IF('Entries July 2026'!X7-'Entries July 2026'!X6<1,"0",'Entries July 2026'!X7-'Entries July 2026'!X6) -> 42 | O7: =IF('Entries July 2026'!Y7-'Entries July 2026'!Y6<1,"0",'Entries July 2026'!Y7-'Entries July 2026'!Y6) -> 64 | P7: =IF('Entries July 2026'!AC7-'Entries July 2026'!AC6<1,"0",'Entries July 2026'!AC7-'Entries July 2026'!AC6) -> 19 | Q7: =IF('Entries July 2026'!Z7-'Entries July 2026'!Z6<1,"0",'Entries July 2026'!Z7-'Entries July 2026'!Z6) -> 15 | R7: =IF(('Entries July 2026'!AA7-'Entries July 2026'!AA6)+('Entries July 2026'!AB7-'Entries July 2026'!AB6)<1,"0",('Entries July 2026'!AA7-'Entries July 2026'!AA6)+('Entries July 2026'!AB7-'Entries July 2026'!AB6)) -> 0 | S7: =(R7+G7)*10 -> 2550 | T7: =O7+N7+M7+L7 -> 109 | U7: =IF('Entries July 2026'!AC7-'Entries July 2026'!AC6<1,"0",'Entries July 2026'!AC7-'Entries July 2026'!AC6) -> 19 | V7: =IF('Entries July 2026'!AD7-'Entries July 2026'!AD6<1,"0",'Entries July 2026'!AD7-'Entries July 2026'!AD6) -> 0 | W7: =IF('Entries July 2026'!AE7-'Entries July 2026'!AE6<1,"0",'Entries July 2026'!AE7-'Entries July 2026'!AE6) -> 0 | X7: =IF('Entries July 2026'!AI7-'Entries July 2026'!AI6<1,"0",'Entries July 2026'!AI7-'Entries July 2026'!AI6) -> 0 | Y7: =IF('Entries July 2026'!AH7-'Entries July 2026'!AH6<1,"0",'Entries July 2026'!AH7-'Entries July 2026'!AH6) -> 0 | Z7: =C7+D7+E7 -> 443 | AA7: {=IF(TRANSPOSE('Daily KPIs'!B9:AF9)=0,"0",TRANSPOSE('Daily KPIs'!B9:AF9))} -> 471.8652 | AB7: =IF(AA7=0,"0",(Z7*10/AA7)) -> 9.3882744
B8: 2 | C8: =IF('Entries July 2026'!W8-'Entries July 2026'!W7<1,"0",'Entries July 2026'!W8-'Entries July 2026'!W7) -> 0 | D8: =IF('Entries July 2026'!O8-'Entries July 2026'!O7<1,"0",'Entries July 2026'!O8-'Entries July 2026'!O7) -> 269 | E8: =IF('Entries July 2026'!P8-'Entries July 2026'!P7<1,"0",'Entries July 2026'!P8-'Entries July 2026'!P7) -> 213 | F8: =IF('Entries July 2026'!V8-'Entries July 2026'!V7<1,"0",'Entries July 2026'!V8-'Entries July 2026'!V7) -> 220 | G8: =(D8+E8)-F8 -> 262 | H8: =IF('Entries July 2026'!Q8-'Entries July 2026'!Q7<1,0,'Entries July 2026'!Q8-'Entries July 2026'!Q7) -> 247 | I8: =IF('Entries July 2026'!AG8-'Entries July 2026'!AG7<1,0,'Entries July 2026'!AG8-'Entries July 2026'!AG7) -> 0 | J8: =IF('Entries July 2026'!S8-'Entries July 2026'!S7<1,"0",'Entries July 2026'!S8-'Entries July 2026'!S7) -> 220 | K8: =IF('Entries July 2026'!R8-'Entries July 2026'!R7<1,"0",'Entries July 2026'!R8-'Entries July 2026'!R7) -> 0 | L8: =IF('Entries July 2026'!T8-'Entries July 2026'!T7<1,"0",'Entries July 2026'!T8-'Entries July 2026'!T7) -> 0 | M8: =IF('Entries July 2026'!U8-'Entries July 2026'!U7<1,"0",'Entries July 2026'!U8-'Entries July 2026'!U7) -> 7 | N8: =IF('Entries July 2026'!X8-'Entries July 2026'!X7<1,"0",'Entries July 2026'!X8-'Entries July 2026'!X7) -> 50 | O8: =IF('Entries July 2026'!Y8-'Entries July 2026'!Y7<1,"0",'Entries July 2026'!Y8-'Entries July 2026'!Y7) -> 83 | P8: =IF('Entries July 2026'!AC8-'Entries July 2026'!AC7<1,"0",'Entries July 2026'!AC8-'Entries July 2026'!AC7) -> 30 | Q8: =IF('Entries July 2026'!Z8-'Entries July 2026'!Z7<1,"0",'Entries July 2026'!Z8-'Entries July 2026'!Z7) -> 18 | R8: =IF(('Entries July 2026'!AA8-'Entries July 2026'!AA7)+('Entries July 2026'!AB8-'Entries July 2026'!AB7)<1,"0",('Entries July 2026'!AA8-'Entries July 2026'!AA7)+('Entries July 2026'!AB8-'Entries July 2026'!AB7)) -> 0 | S8: =(R8+G8)*10 -> 2620 | T8: =O8+N8+M8+L8 -> 140 | U8: =IF('Entries July 2026'!AC8-'Entries July 2026'!AC7<1,"0",'Entries July 2026'!AC8-'Entries July 2026'!AC7) -> 30 | V8: =IF('Entries July 2026'!AD8-'Entries July 2026'!AD7<1,"0",'Entries July 2026'!AD8-'Entries July 2026'!AD7) -> 0 | W8: =IF('Entries July 2026'!AE8-'Entries July 2026'!AE7<1,"0",'Entries July 2026'!AE8-'Entries July 2026'!AE7) -> 0 | X8: =IF('Entries July 2026'!AI8-'Entries July 2026'!AI7<1,"0",'Entries July 2026'!AI8-'Entries July 2026'!AI7) -> 0 | Y8: =IF('Entries July 2026'!AH8-'Entries July 2026'!AH7<1,"0",'Entries July 2026'!AH8-'Entries July 2026'!AH7) -> 0 | Z8: =C8+D8+E8 -> 482 | AA8: 507.3684 | AB8: =IF(AA8=0,"0",(Z8*10/AA8)) -> 9.5000004
B9: 3 | C9: =IF('Entries July 2026'!W9-'Entries July 2026'!W8<1,"0",'Entries July 2026'!W9-'Entries July 2026'!W8) -> 0 | D9: =IF('Entries July 2026'!O9-'Entries July 2026'!O8<1,"0",'Entries July 2026'!O9-'Entries July 2026'!O8) -> 7 | E9: =IF('Entries July 2026'!P9-'Entries July 2026'!P8<1,"0",'Entries July 2026'!P9-'Entries July 2026'!P8) -> 143 | F9: =IF('Entries July 2026'!V9-'Entries July 2026'!V8<1,"0",'Entries July 2026'!V9-'Entries July 2026'!V8) -> 149 | G9: =(D9+E9)-F9 -> 1 | H9: =IF('Entries July 2026'!Q9-'Entries July 2026'!Q8<1,0,'Entries July 2026'!Q9-'Entries July 2026'!Q8) -> 186 | I9: =IF('Entries July 2026'!AG9-'Entries July 2026'!AG8<1,0,'Entries July 2026'!AG9-'Entries July 2026'!AG8) -> 0 | J9: =IF('Entries July 2026'!S9-'Entries July 2026'!S8<1,"0",'Entries July 2026'!S9-'Entries July 2026'!S8) -> 140 | K9: =IF('Entries July 2026'!R9-'Entries July 2026'!R8<1,"0",'Entries July 2026'!R9-'Entries July 2026'!R8) -> 0 | L9: =IF('Entries July 2026'!T9-'Entries July 2026'!T8<1,"0",'Entries July 2026'!T9-'Entries July 2026'!T8) -> 0 | M9: =IF('Entries July 2026'!U9-'Entries July 2026'!U8<1,"0",'Entries July 2026'!U9-'Entries July 2026'!U8) -> 2 | N9: =IF('Entries July 2026'!X9-'Entries July 2026'!X8<1,"0",'Entries July 2026'!X9-'Entries July 2026'!X8) -> 19 | O9: =IF('Entries July 2026'!Y9-'Entries July 2026'!Y8<1,"0",'Entries July 2026'!Y9-'Entries July 2026'!Y8) -> 86 | P9: =IF('Entries July 2026'!AC9-'Entries July 2026'!AC8<1,"0",'Entries July 2026'!AC9-'Entries July 2026'!AC8) -> 23 | Q9: =IF('Entries July 2026'!Z9-'Entries July 2026'!Z8<1,"0",'Entries July 2026'!Z9-'Entries July 2026'!Z8) -> 17 | R9: =IF(('Entries July 2026'!AA9-'Entries July 2026'!AA8)+('Entries July 2026'!AB9-'Entries July 2026'!AB8)<1,"0",('Entries July 2026'!AA9-'Entries July 2026'!AA8)+('Entries July 2026'!AB9-'Entries July 2026'!AB8)) -> 0 | S9: =(R9+G9)*10 -> 10 | T9: =O9+N9+M9+L9 -> 107 | U9: =IF('Entries July 2026'!AC9-'Entries July 2026'!AC8<1,"0",'Entries July 2026'!AC9-'Entries July 2026'!AC8) -> 23 | V9: =IF('Entries July 2026'!AD9-'Entries July 2026'!AD8<1,"0",'Entries July 2026'!AD9-'Entries July 2026'!AD8) -> 0 | W9: =IF('Entries July 2026'!AE9-'Entries July 2026'!AE8<1,"0",'Entries July 2026'!AE9-'Entries July 2026'!AE8) -> 0 | X9: =IF('Entries July 2026'!AI9-'Entries July 2026'!AI8<1,"0",'Entries July 2026'!AI9-'Entries July 2026'!AI8) -> 0 | Y9: =IF('Entries July 2026'!AH9-'Entries July 2026'!AH8<1,"0",'Entries July 2026'!AH9-'Entries July 2026'!AH8) -> 0 | Z9: =C9+D9+E9 -> 150 | AA9: 492.096 | AB9: =IF(AA9=0,"0",(Z9*10/AA9)) -> 3.0481857
