Workbook
Name ProductList: [1]November15!$R$3:$R$9
Name ProductList: [2]November15!$R$3:$R$9

Sheet Dec 18th
T1: P.G. | V1: Hot Time | X1: Process Time | Z1: Cooling Time
B2: Brewing Department Daily Process Loss Report | T2: Lower | U2: Upper | V2: Lower | W2: Upper | X2: Lower | Y2: Upper | Z2: Lower | AA2: Upper
S3: CARIB | T3: 11.6 | U3: 12 | V3: 0 | W3: 0.11805556 | X3: 0.17361111 | Y3: 0.21180556 | Z3: 0 | AA3: 60 | AC3: HR- PISNER
B4: Date: | C4: 45278 | J4: LOT WORT COLOUR: 3.4 | M4: Filter Sheets (Target 20 days) | S4: STAG | T4: 11.6 | U4: 12 | V4: 0 | W4: 0.11805556 | X4: 0.17361111 | Y4: 0.21180556 | Z4: 0 | AA4: 60
M5: Double | N5: Single | S5: GUINNESS | T5: 17 | U5: 17.5 | V5: 0 | W5: 0.10763889 | X5: 0.19444444 | Y5: 0.23263889 | Z5: 0 | AA5: 60
J6: MALT LOT: Lot 8 | L6: Sheet Day | S6: MACKESON | T6: 13.3 | U6: 13.5 | V6: 0 | W6: 0.12905093 | X6: 0.22222222 | Y6: 0.25347222 | Z6: 0
S7: STARMALT | T7: 17.1 | U7: 17.5 | V7: 0 | W7: 0.13605324 | X7: 0.20833333 | Y7: 0.24305556 | Z7: 0 | AA7: 60
B8: Brand | C8: Brew no. | D8: Kett. Hls | E8: Wort | F8: Cool Time(Mins) | G8: Cast. P.G. (Lab Result) | H8: Cast P.G. (Cellar Operator)-gravity | I8: Extr. Rec (79.1%) | J8: Theor. Extr. (77.5%) | K8: Boil Off /Vol. (4-6%) | L8: Boil Time | M8: Total Hot | N8: Brewing | P8: Comments | Q8: Actual Pilsen Malt | S8: Hurricane Reef | T8: 16.6 | U8: 17 | V8: 0 | W8: 0.12905093 | X8: 0.22222222 | Y8: 0.25347222 | Z8: 0
E9: Meter (Hls) | F9: Target(< 60Mins) | M9: Time | S9: VITAMALT | T9: 14.4 | U9: 14.6 | V9: 0 | W9: 0.13905093 | X9: 0.19097222 | Y9: 0.22569444 | Z9: 0 | AA9: 75
S10: =B10 -> 0 | T10: =VLOOKUP($B10,$S$3:$Y$9,2,FALSE) -> #N/A | U10: =VLOOKUP($B10,$S$3:$Y$9,3,FALSE) -> #N/A | V10: =VLOOKUP($B10,$S$3:$Y$9,4,FALSE) -> #N/A | W10: =VLOOKUP($B10,$S$3:$Y$9,5,FALSE) -> #N/A | X10: =VLOOKUP($B10,$S$3:$Y$9,6,FALSE) -> #N/A | Y10: =VLOOKUP($B10,$S$3:$Y$9,7,FALSE) -> #N/A | Z10: =VLOOKUP($B10,$S$3:$AA$9,8,FALSE) -> #N/A | AA10: =VLOOKUP($B10,$S$3:$AA$9,9,FALSE) -> #N/A
S11: =B11 -> 0 | T11: =VLOOKUP($B11,$S$3:$Y$9,2,FALSE) -> #N/A | U11: =VLOOKUP($B11,$S$3:$Y$9,3,FALSE) -> #N/A | V11: =VLOOKUP($B11,$S$3:$Y$9,4,FALSE) -> #N/A | W11: =VLOOKUP($B11,$S$3:$Y$9,5,FALSE) -> #N/A | X11: =VLOOKUP($B11,$S$3:$Y$9,6,FALSE) -> #N/A | Y11: =VLOOKUP($B11,$S$3:$Y$9,7,FALSE) -> #N/A | Z11: =VLOOKUP($B11,$S$3:$AA$9,8,FALSE) -> #N/A | AA11: =VLOOKUP($B11,$S$3:$AA$9,9,FALSE) -> #N/A
S12: =B12 -> 0 | T12: =VLOOKUP($B12,$S$3:$Y$9,2,FALSE) -> #N/A | U12: =VLOOKUP($B12,$S$3:$Y$9,3,FALSE) -> #N/A | V12: =VLOOKUP($B12,$S$3:$Y$9,4,FALSE) -> #N/A | W12: =VLOOKUP($B12,$S$3:$Y$9,5,FALSE) -> #N/A | X12: =VLOOKUP($B12,$S$3:$Y$9,6,FALSE) -> #N/A | Y12: =VLOOKUP($B12,$S$3:$Y$9,7,FALSE) -> #N/A | Z12: =VLOOKUP($B12,$S$3:$AA$9,8,FALSE) -> #N/A | AA12: =VLOOKUP($B12,$S$3:$AA$9,9,FALSE) -> #N/A
S13: =B13 -> 0 | T13: =VLOOKUP($B13,$S$3:$Y$9,2,FALSE) -> #N/A | U13: =VLOOKUP($B13,$S$3:$Y$9,3,FALSE) -> #N/A | V13: =VLOOKUP($B13,$S$3:$Y$9,4,FALSE) -> #N/A | W13: =VLOOKUP($B13,$S$3:$Y$9,5,FALSE) -> #N/A | X13: =VLOOKUP($B13,$S$3:$Y$9,6,FALSE) -> #N/A | Y13: =VLOOKUP($B13,$S$3:$Y$9,7,FALSE) -> #N/A | Z13: =VLOOKUP($B13,$S$3:$AA$9,8,FALSE) -> #N/A | AA13: =VLOOKUP($B13,$S$3:$AA$9,9,FALSE) -> #N/A
S14: =B14 -> 0 | T14: =VLOOKUP($B14,$S$3:$Y$9,2,FALSE) -> #N/A | U14: =VLOOKUP($B14,$S$3:$Y$9,3,FALSE) -> #N/A | V14: =VLOOKUP($B14,$S$3:$Y$9,4,FALSE) -> #N/A | W14: =VLOOKUP($B14,$S$3:$Y$9,5,FALSE) -> #N/A | X14: =VLOOKUP($B14,$S$3:$Y$9,6,FALSE) -> #N/A | Y14: =VLOOKUP($B14,$S$3:$Y$9,7,FALSE) -> #N/A | Z14: =VLOOKUP($B14,$S$3:$AA$9,8,FALSE) -> #N/A | AA14: =VLOOKUP($B14,$S$3:$AA$9,9,FALSE) -> #N/A
S15: =B15 -> 0 | T15: =VLOOKUP($B15,$S$3:$Y$9,2,FALSE) -> #N/A | U15: =VLOOKUP($B15,$S$3:$Y$9,3,FALSE) -> #N/A | V15: =VLOOKUP($B15,$S$3:$Y$9,4,FALSE) -> #N/A | W15: =VLOOKUP($B15,$S$3:$Y$9,5,FALSE) -> #N/A | X15: =VLOOKUP($B15,$S$3:$Y$9,6,FALSE) -> #N/A | Y15: =VLOOKUP($B15,$S$3:$Y$9,7,FALSE) -> #N/A | Z15: =VLOOKUP($B15,$S$3:$AA$9,8,FALSE) -> #N/A | AA15: =VLOOKUP($B15,$S$3:$AA$9,9,FALSE) -> #N/A
S16: =B16 -> 0 | T16: =VLOOKUP($B16,$S$3:$Y$9,2,FALSE) -> #N/A | U16: =VLOOKUP($B16,$S$3:$Y$9,3,FALSE) -> #N/A | V16: =VLOOKUP($B16,$S$3:$Y$9,4,FALSE) -> #N/A | W16: =VLOOKUP($B16,$S$3:$Y$9,5,FALSE) -> #N/A | X16: =VLOOKUP($B16,$S$3:$Y$9,6,FALSE) -> #N/A | Y16: =VLOOKUP($B16,$S$3:$Y$9,7,FALSE) -> #N/A | Z16: =VLOOKUP($B16,$S$3:$AA$9,8,FALSE) -> #N/A | AA16: =VLOOKUP($B16,$S$3:$AA$9,9,FALSE) -> #N/A
S17: =B17 -> 0 | T17: =VLOOKUP($B17,$S$3:$Y$9,2,FALSE) -> #N/A | U17: =VLOOKUP($B17,$S$3:$Y$9,3,FALSE) -> #N/A | V17: =VLOOKUP($B17,$S$3:$Y$9,4,FALSE) -> #N/A | W17: =VLOOKUP($B17,$S$3:$Y$9,5,FALSE) -> #N/A | X17: =VLOOKUP($B17,$S$3:$Y$9,6,FALSE) -> #N/A | Y17: =VLOOKUP($B17,$S$3:$Y$9,7,FALSE) -> #N/A | Z17: =VLOOKUP($B17,$S$3:$AA$9,8,FALSE) -> #N/A | AA17: =VLOOKUP($B17,$S$3:$AA$9,9,FALSE) -> #N/A
S18: =B18 -> 0 | T18: =VLOOKUP($B18,$S$3:$Y$9,2,FALSE) -> #N/A | U18: =VLOOKUP($B18,$S$3:$Y$9,3,FALSE) -> #N/A | V18: =VLOOKUP($B18,$S$3:$Y$9,4,FALSE) -> #N/A | W18: =VLOOKUP($B18,$S$3:$Y$9,5,FALSE) -> #N/A | X18: =VLOOKUP($B18,$S$3:$Y$9,6,FALSE) -> #N/A | Y18: =VLOOKUP($B18,$S$3:$Y$9,7,FALSE) -> #N/A | Z18: =VLOOKUP($B18,$S$3:$AA$9,8,FALSE) -> #N/A | AA18: =VLOOKUP($B18,$S$3:$AA$9,9,FALSE) -> #N/A
S19: =B19 -> 0 | T19: =VLOOKUP($B19,$S$3:$Y$9,2,FALSE) -> #N/A | U19: =VLOOKUP($B19,$S$3:$Y$9,3,FALSE) -> #N/A | V19: =VLOOKUP($B19,$S$3:$Y$9,4,FALSE) -> #N/A | W19: =VLOOKUP($B19,$S$3:$Y$9,5,FALSE) -> #N/A | X19: =VLOOKUP($B19,$S$3:$Y$9,6,FALSE) -> #N/A | Y19: =VLOOKUP($B19,$S$3:$Y$9,7,FALSE) -> #N/A | Z19: =VLOOKUP($B19,$S$3:$AA$9,8,FALSE) -> #N/A | AA19: =VLOOKUP($B19,$S$3:$AA$9,9,FALSE) -> #N/A
S20: =B20 -> 0 | T20: =VLOOKUP($B20,$S$3:$Y$9,2,FALSE) -> #N/A | U20: =VLOOKUP($B20,$S$3:$Y$9,3,FALSE) -> #N/A | V20: =VLOOKUP($B20,$S$3:$Y$9,4,FALSE) -> #N/A | W20: =VLOOKUP($B20,$S$3:$Y$9,5,FALSE) -> #N/A | X20: =VLOOKUP($B20,$S$3:$Y$9,6,FALSE) -> #N/A | Y20: =VLOOKUP($B20,$S$3:$Y$9,7,FALSE) -> #N/A | Z20: =VLOOKUP($B20,$S$3:$AA$9,8,FALSE) -> #N/A | AA20: =VLOOKUP($B20,$S$3:$AA$9,9,FALSE) -> #N/A
S21: =B21 -> 0 | T21: =VLOOKUP($B21,$S$3:$Y$9,2,FALSE) -> #N/A | U21: =VLOOKUP($B21,$S$3:$Y$9,3,FALSE) -> #N/A | V21: =VLOOKUP($B21,$S$3:$Y$9,4,FALSE) -> #N/A | W21: =VLOOKUP($B21,$S$3:$Y$9,5,FALSE) -> #N/A | X21: =VLOOKUP($B21,$S$3:$Y$9,6,FALSE) -> #N/A | Y21: =VLOOKUP($B21,$S$3:$Y$9,7,FALSE) -> #N/A | Z21: =VLOOKUP($B21,$S$3:$AA$9,8,FALSE) -> #N/A | AA21: =VLOOKUP($B21,$S$3:$AA$9,9,FALSE) -> #N/A
... S47: =B47 -> 0 | T47: =VLOOKUP($B47,$S$3:$Y$9,2,FALSE) -> #N/A | U47: =VLOOKUP($B47,$S$3:$Y$9,3,FALSE) -> #N/A | V47: =VLOOKUP($B47,$S$3:$Y$9,4,FALSE) -> #N/A | W47: =VLOOKUP($B47,$S$3:$Y$9,5,FALSE) -> #N/A | X47: =VLOOKUP($B47,$S$3:$Y$9,6,FALSE) -> #N/A | Y47: =VLOOKUP($B47,$S$3:$Y$9,7,FALSE) -> #N/A | Z47: =VLOOKUP($B47,$S$3:$AA$9,8,FALSE) -> #N/A | AA47: =VLOOKUP($B47,$S$3:$AA$9,9,FALSE) -> #N/A
I48: EXTRACT RECOVERY
B49: BRAND | D49: BBT P.G./ O.G | I49: Brand | J49: Actual | K49: MTD No. of Brews | L49: MTD | M49: YTD | N49: Target
B50: STAG | C50: 11.8 | D50: 11.73 | I50: CARIB | K50: =COUNTA([3]Brewhouse!$A$1596:$A$1619) -> 24 | L50: =AVERAGE([3]Brewhouse!$AU$1529,[3]Brewhouse!$AU$1531:$AU$1594,[3]Brewhouse!$AU$1596:$AU$1619) -> 98.205761 | M50: =AVERAGE([3]Brewhouse!$AU$849:$AU$924,[3]Brewhouse!$AU$926:$AU$971,[3]Brewhouse!$AU$973:$AU$1066,[3]Brewhouse!$AU$1068:$AU$1111,[3]Brewhouse!$AU$1113:$AU$1132,[3]Brewhouse!$AU$1134:$AU$1167,[3]Brewhouse!$AU$1169:$AU$1230,[3]Brewhouse!$AU$1232:$AU$1299,[3]Brewhouse!$AU$1301:$AU$1363,[3]Brewhouse!$AU$1365:$AU$1444,[3]Brewhouse!$AU$1446:$AU$1527,[3]Brewhouse!$AU$1529,[3]Brewhouse!$AU$1531:$AU$1594,[3]Brewhouse!$AU$1596:$AU$1619) -> 98.381806 | N50: 98
C51: 11.9 | I51: STAG | K51: =COUNTA([4]Brewhouse!$A$976:$A$1007) -> 32 | L51: =AVERAGE([4]Brewhouse!$AS$976:$AS$979,[4]Brewhouse!$AS$981:$AS$1007) -> 98.538567 | M51: =AVERAGE([4]Brewhouse!$AS$577:$AS$618,[4]Brewhouse!$AS$620:$AS$651,[4]Brewhouse!$AS$653:$AS$696,[4]Brewhouse!$AS$698:$AS$708,[4]Brewhouse!$AS$710:$AS$733,[4]Brewhouse!$AS$735:$AS$777,[4]Brewhouse!$AS$779:$AS$822,[4]Brewhouse!$AS$824:$AS$863,[4]Brewhouse!$AS$865:$AS$974,[4]Brewhouse!$AS$976:$AS$979,[4]Brewhouse!$AS$981:$AS$1007) -> 98.489671 | N51: 98
I52: GUINNESS | K52: =COUNTA([5]Brewhouse!$A$282:$A$289) -> 8 | L52: =AVERAGE([5]Brewhouse!$AU$269:$AU$279,[5]Brewhouse!$AU$282:$AU$289) -> 96.186177 | M52: =AVERAGE([5]Brewhouse!$AU$161:$AU$176,[5]Brewhouse!$AU$178:$AU$195,[5]Brewhouse!$AU$197:$AU$208,[5]Brewhouse!$AU$210:$AU$221,[5]Brewhouse!$AU$223:$AU$232,[5]Brewhouse!$AU$234:$AU$279,[5]Brewhouse!$AU$282:$AU$289) -> 96.64916 | N52: 98
I53: VITAMALT | K53: =COUNTA([6]Brewhouse!$A$158:$A$163) -> 6 | L53: =AVERAGE([6]Brewhouse!$AU$158:$AU$163) -> 94.60305 | M53: =AVERAGE([6]Brewhouse!$AU$91:$AU$101,[6]Brewhouse!$AU$103:$AU$112,[6]Brewhouse!$AU$114:$AU$123,[6]Brewhouse!$AU$125:$AU$134,[6]Brewhouse!$AU$136:$AU$145,[6]Brewhouse!$AU$147:$AU$156,[6]Brewhouse!$AU$158:$AU$163) -> 96.240014 | N53: 98
I54: MAXIMALT | N54: 98
I55: MACKESON | M55: =AVERAGE([7]Brewhouse!$AT$74:$AT$79) -> 93.959836 | N55: 98
I56: STARMALT | K56: =COUNTA([8]Brewhouse!$A$249:$A$254) -> 6 | L56: =AVERAGE([8]Brewhouse!$AY$249:$AY$254) -> 99.681996 | M56: =AVERAGE([8]Brewhouse!$AY$138:$AY$143,[8]Brewhouse!$AY$145:$AY$153,[8]Brewhouse!$AY$155,[8]Brewhouse!$AY$156:$AY$174,[8]Brewhouse!$AY$176:$AY$185,[8]Brewhouse!$AY$187:$AY$198,[8]Brewhouse!$AY$200:$AY$247,[8]Brewhouse!$AY$249:$AY$254) -> 98.774703 | N56: 98
I57: HR- P | M57: =AVERAGE([9]Brewhouse!$AW$13:$AW$14,[9]Brewhouse!$AW$16:$AW$17) -> 92.042628 | N57: 98
I58: Hurricane Reef | M58: =AVERAGE([9]Brewhouse!$AW$13:$AW$14) -> 88.376943 | N58: 98
K59: =SUM(K50:K58) -> 76 | L59: =((L50*K50)+(L51*K51)+(L52*K52)+(L53*K53)+(L54*K54)+(K57*L57)+(L55*K55)+(L56*K56)+(L58*K58))/(K59) -> 97.965422 | M59: =AVERAGE('[10]Closing- January 2023'!$L$42,'[11]Feb. 28th'!$L$42,'[12]March 31st'!$L$75,'[13]Apri 28th'!$L$51,L59) -> 98.06926 | N59: 98
J62: Daily Brewing Plan
J63: Brand | K63: Brews Achieved | L63: Average Brews per day
J64: CARIB | L64: MTD | M64: YTD | N64: TARGET
J65: STAG | K65: 5 | L65: =AVERAGE(#REF!,#REF!,K74,#REF!,#REF!,#REF!,#REF!,#REF!,#REF!,#REF!,#REF!) -> #REF! | M65: =AVERAGE(6,6,'[12]March 31st'!$L$80,'[14]June 30th '!$L$71,6,L65,'[15]July 31st'!$L$108,'[16]Aug 30th'!$L$124,7,[17]Oct.31st!$L$51) -> #REF! | N65: 9
J66: GUINN
J67: VITAMALT
...

Sheet July 1st
S1: P.G. | U1: Hot Time | W1: Process Time | Y1: Cooling Time
B2: Brewing Department Daily Process Loss Report | S2: Lower | T2: Upper | U2: Lower | V2: Upper | W2: Lower | X2: Upper | Y2: Lower | Z2: Upper
R3: CARIB | S3: 11.6 | T3: 12 | U3: 0 | V3: 0.11805556 | W3: 0.22569444 | X3: 0.26388889 | Y3: 0 | Z3: 60 | AB3: HR- PISNER
B4: Date: | C4: 45840 | J4: LOT WORT COLOUR: 3.3 | M4: Filter Sheets (Target 20 days) | R4: STAG | S4: 11.6 | T4: 12 | U4: 0 | V4: 0.11805556 | W4: 0.22569444 | X4: 0.26388889 | Y4: 0 | Z4: 60
M5: Double | N5: Single | R5: GUINNESS | S5: 17 | T5: 17.5 | U5: 0 | V5: 0.10763889 | W5: 0.24652778 | X5: 0.28472222 | Y5: 0 | Z5: 60
J6: MALT LOT: Lot #40 | L6: Sheet Day | M6: 10 | N6: 10 | R6: MACKESON | S6: 13.3 | T6: 13.5 | U6: 0 | V6: 0.12905093 | W6: 0.27430556 | X6: 0.30208333 | Y6: 0
R7: STARMALT | S7: 17.1 | T7: 17.5 | U7: 0 | V7: 0.13605324 | W7: 0.27430556 | X7: 0.30902778 | Y7: 0 | Z7: 85
B8: Brand | C8: Brew no. | D8: Kett. Hls | E8: Wort | F8: Cool Time(Mins) | G8: Cast. P.G. (Lab Result) | H8: Cast P.G. (Cellar Operator)-gravity | I8: Extr. Rec (79.4%) | J8: Theor. Extr. (77.5%) | K8: Boil Off /Vol. (4-6%) | L8: Boil Time | M8: Total Hot | N8: Brewing | O8: Operator | R8: Hurricane Reef | S8: 16.6 | T8: 17 | U8: 0 | V8: 0.12905093 | W8: 0.27430556 | X8: 0.30208333 | Y8: 0
E9: Meter (Hls) | F9: Target(< 60Mins) | M9: Time | R9: VITAMALT | S9: 14.4 | T9: 14.6 | U9: 0 | V9: 0.13905093 | W9: 0.26041667 | X9: 0.29513889 | Y9: 0 | Z9: 75
B10: STARMALT | C10: =[22]Brewhouse!$A56 -> SM045 | D10: =[22]Brewhouse!$AH56 -> 56.7 | E10: =[22]Brewhouse!$AM56 -> 51.6 | F10: =[22]Brewhouse!$Z56 -> 81 | G10: =[22]Brewhouse!$AK56 -> 17.26 | H10: 17.4 | I10: =[22]Brewhouse!$AY56 -> 98.181054 | J10: =[22]Brewhouse!$AZ56 -> 98.962706 | K10: =[22]Brewhouse!$U56 -> 17.07231 | L10: =[22]Brewhouse!$T56 -> 61 | M10: =[22]Brewhouse!$Y56-[22]Brewhouse!$X56 -> 0.13958333 | N10: =[22]Brewhouse!$AD56 -> 0.29583333 | O10: =[22]Brewhouse!$BC56 -> D. Gomaz | R10: =B10 -> STARMALT | S10: =VLOOKUP($B10,$R$3:$X$9,2,FALSE) -> 17.1 | T10: =VLOOKUP($B10,$R$3:$X$9,3,FALSE) -> 17.5 | U10: =VLOOKUP($B10,$R$3:$X$9,4,FALSE) -> 0 | V10: =VLOOKUP($B10,$R$3:$X$9,5,FALSE) -> 0.13605324 | W10: =VLOOKUP($B10,$R$3:$X$9,6,FALSE) -> 0.27430556 | X10: =VLOOKUP($B10,$R$3:$X$9,7,FALSE) -> 0.30902778 | Y10: =VLOOKUP($B10,$R$3:$Z$9,8,FALSE) -> 0 | Z10: =VLOOKUP($B10,$R$3:$Z$9,9,FALSE) -> 85
B11: STARMALT | C11: =[22]Brewhouse!$A57 -> SM046 | D11: =[22]Brewhouse!$AH57 -> 53.1 | E11: =[22]Brewhouse!$AM57 -> 49.8 | F11: =[22]Brewhouse!$Z57 -> 77 | G11: =[22]Brewhouse!$AK57 -> 16.31 | I11: =[22]Brewhouse!$AY57 -> 87.428387 | J11: =[22]Brewhouse!$AZ57 -> 88.137927 | K11: =[22]Brewhouse!$U57 -> 9.9435028 | L11: =[22]Brewhouse!$T57 -> 60 | M11: =[22]Brewhouse!$Y57-[22]Brewhouse!$X57 -> 0.12638889 | N11: =[22]Brewhouse!$AD57 -> 0.27569444 | O11: =[22]Brewhouse!$BC57 -> D. Gomaz | P11: Brew was under grind | R11: =B11 -> STARMALT | S11: =VLOOKUP($B11,$R$3:$X$9,2,FALSE) -> 17.1 | T11: =VLOOKUP($B11,$R$3:$X$9,3,FALSE) -> 17.5 | U11: =VLOOKUP($B11,$R$3:$X$9,4,FALSE) -> 0 | V11: =VLOOKUP($B11,$R$3:$X$9,5,FALSE) -> 0.13605324 | W11: =VLOOKUP($B11,$R$3:$X$9,6,FALSE) -> 0.27430556 | X11: =VLOOKUP($B11,$R$3:$X$9,7,FALSE) -> 0.30902778 | Y11: =VLOOKUP($B11,$R$3:$Z$9,8,FALSE) -> 0 | Z11: =VLOOKUP($B11,$R$3:$Z$9,9,FALSE) -> 85
B12: STARMALT | C12: =[22]Brewhouse!$A58 -> SM047 | D12: =[22]Brewhouse!$AH58 -> 53.5 | E12: =[22]Brewhouse!$AM58 -> 53.9 | F12: =[22]Brewhouse!$Z58 -> 64 | G12: =[22]Brewhouse!$AK58 -> 18.47 | I12: =[22]Brewhouse!$AY58 -> 110.11827 | J12: =[22]Brewhouse!$AZ58 -> 110.99579 | K12: =[22]Brewhouse!$U58 -> 9.8691589 | L12: =[22]Brewhouse!$T58 -> 61 | M12: =[22]Brewhouse!$Y58-[22]Brewhouse!$X58 -> 0.12986111 | N12: =[22]Brewhouse!$AD58 -> 0.27847222 | O12: =[22]Brewhouse!$BC58 -> D. Gomaz | P12: Compensation brew | R12: =B12 -> STARMALT | S12: =VLOOKUP($B12,$R$3:$X$9,2,FALSE) -> 17.1 | T12: =VLOOKUP($B12,$R$3:$X$9,3,FALSE) -> 17.5 | U12: =VLOOKUP($B12,$R$3:$X$9,4,FALSE) -> 0 | V12: =VLOOKUP($B12,$R$3:$X$9,5,FALSE) -> 0.13605324 | W12: =VLOOKUP($B12,$R$3:$X$9,6,FALSE) -> 0.27430556 | X12: =VLOOKUP($B12,$R$3:$X$9,7,FALSE) -> 0.30902778 | Y12: =VLOOKUP($B12,$R$3:$Z$9,8,FALSE) -> 0 | Z12: =VLOOKUP($B12,$R$3:$Z$9,9,FALSE) -> 85
B13: STARMALT | C13: =[22]Brewhouse!$A59 -> SM048 | D13: =[22]Brewhouse!$AH59 -> 54.3 | E13: =[22]Brewhouse!$AM59 -> 52.3 | F13: =[22]Brewhouse!$Z59 -> 64 | G13: =[22]Brewhouse!$AK59 -> 17.24 | H13: 18.5 | I13: =[22]Brewhouse!$AY59 -> 98.787376 | J13: =[22]Brewhouse!$AZ59 -> 99.574593 | K13: =[22]Brewhouse!$U59 -> 12.302026 | L13: =[22]Brewhouse!$T59 -> 58 | M13: =[22]Brewhouse!$Y59-[22]Brewhouse!$X59 -> 0.12152778 | N13: =[22]Brewhouse!$AD59 -> 0.28125 | O13: =[22]Brewhouse!$BC59 -> R.Sookram | R13: =B13 -> STARMALT | S13: =VLOOKUP($B13,$R$3:$X$9,2,FALSE) -> 17.1 | T13: =VLOOKUP($B13,$R$3:$X$9,3,FALSE) -> 17.5 | U13: =VLOOKUP($B13,$R$3:$X$9,4,FALSE) -> 0 | V13: =VLOOKUP($B13,$R$3:$X$9,5,FALSE) -> 0.13605324 | W13: =VLOOKUP($B13,$R$3:$X$9,6,FALSE) -> 0.27430556 | X13: =VLOOKUP($B13,$R$3:$X$9,7,FALSE) -> 0.30902778 | Y13: =VLOOKUP($B13,$R$3:$Z$9,8,FALSE) -> 0 | Z13: =VLOOKUP($B13,$R$3:$Z$9,9,FALSE) -> 85
B14: 45840
B15: STARMALT | C15: =[22]Brewhouse!$A60 -> SM049 | D15: =[22]Brewhouse!$AH60 -> 55 | E15: =[22]Brewhouse!$AM60 -> 52.3 | F15: =[22]Brewhouse!$Z60 -> 71 | G15: =[22]Brewhouse!$AK60 -> 17.28 | I15: =[22]Brewhouse!$AY60 -> 99.593723 | J15: =[22]Brewhouse!$AZ60 -> 100.38588 | K15: =[22]Brewhouse!$U60 -> 12.872727 | L15: =[22]Brewhouse!$T60 -> 58 | M15: =[22]Brewhouse!$Y60-[22]Brewhouse!$X60 -> 0.1375 | N15: =[22]Brewhouse!$AD60 -> 0.28402778 | O15: =[22]Brewhouse!$BC60 -> R.Sookram | R15: =B15 -> STARMALT | S15: =VLOOKUP($B15,$R$3:$X$9,2,FALSE) -> 17.1 | T15: =VLOOKUP($B15,$R$3:$X$9,3,FALSE) -> 17.5 | U15: =VLOOKUP($B15,$R$3:$X$9,4,FALSE) -> 0 | V15: =VLOOKUP($B15,$R$3:$X$9,5,FALSE) -> 0.13605324 | W15: =VLOOKUP($B15,$R$3:$X$9,6,FALSE) -> 0.27430556 | X15: =VLOOKUP($B15,$R$3:$X$9,7,FALSE) -> 0.30902778 | Y15: =VLOOKUP($B15,$R$3:$Z$9,8,FALSE) -> 0 | Z15: =VLOOKUP($B15,$R$3:$Z$9,9,FALSE) -> 85
R16: =B16 -> 0 | S16: =VLOOKUP($B16,$R$3:$X$9,2,FALSE) -> #N/A | T16: =VLOOKUP($B16,$R$3:$X$9,3,FALSE) -> #N/A | U16: =VLOOKUP($B16,$R$3:$X$9,4,FALSE) -> #N/A | V16: =VLOOKUP($B16,$R$3:$X$9,5,FALSE) -> #N/A | W16: =VLOOKUP($B16,$R$3:$X$9,6,FALSE) -> #N/A | X16: =VLOOKUP($B16,$R$3:$X$9,7,FALSE) -> #N/A | Y16: =VLOOKUP($B16,$R$3:$Z$9,8,FALSE) -> #N/A | Z16: =VLOOKUP($B16,$R$3:$Z$9,9,FALSE) -> #N/A
B17: CARIB | C17: =[23]Brewhouse!$A580 -> CA473 | D17: =[23]Brewhouse!$AF580 -> 53.3 | E17: =[23]Brewhouse!$AI580 -> 51.22 | F17: =[23]Brewhouse!$V580 -> 59 | G17: =[23]Brewhouse!$AG580 -> 11.85 | H17: 11.8 | I17: =[23]Brewhouse!$AU580 -> 102.69776 | J17: =[23]Brewhouse!$AV580 -> 105.32766 | K17: =[23]Brewhouse!$Q580 -> 4.5735027 | L17: =[23]Brewhouse!$P580 -> 56 | M17: =[23]Brewhouse!$U580-[23]Brewhouse!$T580 -> 0.11111111 | N17: =[23]Brewhouse!$Z580 -> 0.25625 | O17: =[23]Brewhouse!$AX580 -> R. Sookram | R17: =B17 -> CARIB | S17: =VLOOKUP($B17,$R$3:$X$9,2,FALSE) -> 11.6 | T17: =VLOOKUP($B17,$R$3:$X$9,3,FALSE) -> 12 | U17: =VLOOKUP($B17,$R$3:$X$9,4,FALSE) -> 0 | V17: =VLOOKUP($B17,$R$3:$X$9,5,FALSE) -> 0.11805556 | W17: =VLOOKUP($B17,$R$3:$X$9,6,FALSE) -> 0.22569444 | X17: =VLOOKUP($B17,$R$3:$X$9,7,FALSE) -> 0.26388889 | Y17: =VLOOKUP($B17,$R$3:$Z$9,8,FALSE) -> 0 | Z17: =VLOOKUP($B17,$R$3:$Z$9,9,FALSE) -> 60
B18: CARIB | C18: =[23]Brewhouse!$A581 -> CA474 | D18: =[23]Brewhouse!$AF581 -> 53.1 | E18: =[23]Brewhouse!$AI581 -> 51.1 | F18: =[23]Brewhouse!$V581 -> 64 | G18: =[23]Brewhouse!$AG581 -> 11.66 | H18: 11.7 | I18: =[23]Brewhouse!$AU581 -> 97.886866 | J18: =[23]Brewhouse!$AV581 -> 100.3967 | K18: =[23]Brewhouse!$Q581 -> 5.4512635 | L18: =[23]Brewhouse!$P581 -> 60 | M18: =[23]Brewhouse!$U581-[23]Brewhouse!$T581 -> 0.10902778 | N18: =[23]Brewhouse!$Z581 -> 0.26388889 | O18: =[23]Brewhouse!$AX581 -> R. Sookram | R18: =B18 -> CARIB | S18: =VLOOKUP($B18,$R$3:$X$9,2,FALSE) -> 11.6 | T18: =VLOOKUP($B18,$R$3:$X$9,3,FALSE) -> 12 | U18: =VLOOKUP($B18,$R$3:$X$9,4,FALSE) -> 0 | V18: =VLOOKUP($B18,$R$3:$X$9,5,FALSE) -> 0.11805556 | W18: =VLOOKUP($B18,$R$3:$X$9,6,FALSE) -> 0.22569444 | X18: =VLOOKUP($B18,$R$3:$X$9,7,FALSE) -> 0.26388889 | Y18: =VLOOKUP($B18,$R$3:$Z$9,8,FALSE) -> 0 | Z18: =VLOOKUP($B18,$R$3:$Z$9,9,FALSE) -> 60
B19: CARIB | C19: =[23]Brewhouse!$A582 -> CA475 | D19: =[23]Brewhouse!$AF582 -> 52 | E19: =[23]Brewhouse!$AI582 -> 50.8 | F19: =[23]Brewhouse!$V582 -> 64 | G19: =[23]Brewhouse!$AG582 -> 11.86 | H19: 11.8 | I19: =[23]Brewhouse!$AU582 -> 98.571258 | J19: =[23]Brewhouse!$AV582 -> 101.0992 | K19: =[23]Brewhouse!$Q582 -> 7.6036036 | L19: =[23]Brewhouse!$P582 -> 60 | M19: =[23]Brewhouse!$U582-[23]Brewhouse!$T582 -> 0.11458333 | N19: =[23]Brewhouse!$Z582 -> 0.28333333 | O19: =[23]Brewhouse!$AX582 -> R. Regis | R19: =B19 -> CARIB | S19: =VLOOKUP($B19,$R$3:$X$9,2,FALSE) -> 11.6 | T19: =VLOOKUP($B19,$R$3:$X$9,3,FALSE) -> 12 | U19: =VLOOKUP($B19,$R$3:$X$9,4,FALSE) -> 0 | V19: =VLOOKUP($B19,$R$3:$X$9,5,FALSE) -> 0.11805556 | W19: =VLOOKUP($B19,$R$3:$X$9,6,FALSE) -> 0.22569444 | X19: =VLOOKUP($B19,$R$3:$X$9,7,FALSE) -> 0.26388889 | Y19: =VLOOKUP($B19,$R$3:$Z$9,8,FALSE) -> 0 | Z19: =VLOOKUP($B19,$R$3:$Z$9,9,FALSE) -> 60
B20: CARIB | C20: =[23]Brewhouse!$A583 -> CA476 | D20: =[23]Brewhouse!$AF583 -> 53.2 | E20: =[23]Brewhouse!$AI583 -> 51 | F20: =[23]Brewhouse!$V583 -> 66 | G20: =[23]Brewhouse!$AG583 -> 11.67 | H20: 11.7 | I20: =[23]Brewhouse!$AU583 -> 98.571044 | J20: =[23]Brewhouse!$AV583 -> 100.20023 | K20: =[23]Brewhouse!$Q583 -> 5.4414414 | L20: =[23]Brewhouse!$P583 -> 63 | M20: =[23]Brewhouse!$U583-[23]Brewhouse!$T583 -> 0.1125 | N20: =[23]Brewhouse!$Z583 -> 0.25347222 | O20: =[23]Brewhouse!$AX583 -> R. Regis | R20: =B20 -> CARIB | S20: =VLOOKUP($B20,$R$3:$X$9,2,FALSE) -> 11.6 | T20: =VLOOKUP($B20,$R$3:$X$9,3,FALSE) -> 12 | U20: =VLOOKUP($B20,$R$3:$X$9,4,FALSE) -> 0 | V20: =VLOOKUP($B20,$R$3:$X$9,5,FALSE) -> 0.11805556 | W20: =VLOOKUP($B20,$R$3:$X$9,6,FALSE) -> 0.22569444 | X20: =VLOOKUP($B20,$R$3:$X$9,7,FALSE) -> 0.26388889 | Y20: =VLOOKUP($B20,$R$3:$Z$9,8,FALSE) -> 0 | Z20: =VLOOKUP($B20,$R$3:$Z$9,9,FALSE) -> 60
R21: =B21 -> 0 | S21: =VLOOKUP($B21,$R$3:$X$9,2,FALSE) -> #N/A | T21: =VLOOKUP($B21,$R$3:$X$9,3,FALSE) -> #N/A | U21: =VLOOKUP($B21,$R$3:$X$9,4,FALSE) -> #N/A | V21: =VLOOKUP($B21,$R$3:$X$9,5,FALSE) -> #N/A | W21: =VLOOKUP($B21,$R$3:$X$9,6,FALSE) -> #N/A | X21: =VLOOKUP($B21,$R$3:$X$9,7,FALSE) -> #N/A | Y21: =VLOOKUP($B21,$R$3:$Z$9,8,FALSE) -> #N/A | Z21: =VLOOKUP($B21,$R$3:$Z$9,9,FALSE) -> #N/A
R22: =B22 -> 0 | S22: =VLOOKUP($B22,$R$3:$X$9,2,FALSE) -> #N/A | T22: =VLOOKUP($B22,$R$3:$X$9,3,FALSE) -> #N/A | U22: =VLOOKUP($B22,$R$3:$X$9,4,FALSE) -> #N/A | V22: =VLOOKUP($B22,$R$3:$X$9,5,FALSE) -> #N/A | W22: =VLOOKUP($B22,$R$3:$X$9,6,FALSE) -> #N/A | X22: =VLOOKUP($B22,$R$3:$X$9,7,FALSE) -> #N/A | Y22: =VLOOKUP($B22,$R$3:$Z$9,8,FALSE) -> #N/A | Z22: =VLOOKUP($B22,$R$3:$Z$9,9,FALSE) -> #N/A
R23: =B23 -> 0 | S23: =VLOOKUP($B23,$R$3:$X$9,2,FALSE) -> #N/A | T23: =VLOOKUP($B23,$R$3:$X$9,3,FALSE) -> #N/A | U23: =VLOOKUP($B23,$R$3:$X$9,4,FALSE) -> #N/A | V23: =VLOOKUP($B23,$R$3:$X$9,5,FALSE) -> #N/A | W23: =VLOOKUP($B23,$R$3:$X$9,6,FALSE) -> #N/A | X23: =VLOOKUP($B23,$R$3:$X$9,7,FALSE) -> #N/A | Y23: =VLOOKUP($B23,$R$3:$Z$9,8,FALSE) -> #N/A | Z23: =VLOOKUP($B23,$R$3:$Z$9,9,FALSE) -> #N/A
R24: =B24 -> 0 | S24: =VLOOKUP($B24,$R$3:$X$9,2,FALSE) -> #N/A | T24: =VLOOKUP($B24,$R$3:$X$9,3,FALSE) -> #N/A | U24: =VLOOKUP($B24,$R$3:$X$9,4,FALSE) -> #N/A | V24: =VLOOKUP($B24,$R$3:$X$9,5,FALSE) -> #N/A | W24: =VLOOKUP($B24,$R$3:$X$9,6,FALSE) -> #N/A | X24: =VLOOKUP($B24,$R$3:$X$9,7,FALSE) -> #N/A | Y24: =VLOOKUP($B24,$R$3:$Z$9,8,FALSE) -> #N/A | Z24: =VLOOKUP($B24,$R$3:$Z$9,9,FALSE) -> #N/A
R25: =B25 -> 0 | S25: =VLOOKUP($B25,$R$3:$X$9,2,FALSE) -> #N/A | T25: =VLOOKUP($B25,$R$3:$X$9,3,FALSE) -> #N/A | U25: =VLOOKUP($B25,$R$3:$X$9,4,FALSE) -> #N/A | V25: =VLOOKUP($B25,$R$3:$X$9,5,FALSE) -> #N/A | W25: =VLOOKUP($B25,$R$3:$X$9,6,FALSE) -> #N/A | X25: =VLOOKUP($B25,$R$3:$X$9,7,FALSE) -> #N/A | Y25: =VLOOKUP($B25,$R$3:$Z$9,8,FALSE) -> #N/A | Z25: =VLOOKUP($B25,$R$3:$Z$9,9,FALSE) -> #N/A
R26: =B26 -> 0 | S26: =VLOOKUP($B26,$R$3:$X$9,2,FALSE) -> #N/A | T26: =VLOOKUP($B26,$R$3:$X$9,3,FALSE) -> #N/A | U26: =VLOOKUP($B26,$R$3:$X$9,4,FALSE) -> #N/A | V26: =VLOOKUP($B26,$R$3:$X$9,5,FALSE) -> #N/A | W26: =VLOOKUP($B26,$R$3:$X$9,6,FALSE) -> #N/A | X26: =VLOOKUP($B26,$R$3:$X$9,7,FALSE) -> #N/A | Y26: =VLOOKUP($B26,$R$3:$Z$9,8,FALSE) -> #N/A | Z26: =VLOOKUP($B26,$R$3:$Z$9,9,FALSE) -> #N/A
R28: =B28 -> 0 | S28: =VLOOKUP($B28,$R$3:$X$9,2,FALSE) -> #N/A | T28: =VLOOKUP($B28,$R$3:$X$9,3,FALSE) -> #N/A | U28: =VLOOKUP($B28,$R$3:$X$9,4,FALSE) -> #N/A | V28: =VLOOKUP($B28,$R$3:$X$9,5,FALSE) -> #N/A | W28: =VLOOKUP($B28,$R$3:$X$9,6,FALSE) -> #N/A | X28: =VLOOKUP($B28,$R$3:$X$9,7,FALSE) -> #N/A | Y28: =VLOOKUP($B28,$R$3:$Z$9,8,FALSE) -> #N/A | Z28: =VLOOKUP($B28,$R$3:$Z$9,9,FALSE) -> #N/A
R29: =B29 -> 0 | S29: =VLOOKUP($B29,$R$3:$X$9,2,FALSE) -> #N/A | T29: =VLOOKUP($B29,$R$3:$X$9,3,FALSE) -> #N/A | U29: =VLOOKUP($B29,$R$3:$X$9,4,FALSE) -> #N/A | V29: =VLOOKUP($B29,$R$3:$X$9,5,FALSE) -> #N/A | W29: =VLOOKUP($B29,$R$3:$X$9,6,FALSE) -> #N/A | X29: =VLOOKUP($B29,$R$3:$X$9,7,FALSE) -> #N/A | Y29: =VLOOKUP($B29,$R$3:$Z$9,8,FALSE) -> #N/A | Z29: =VLOOKUP($B29,$R$3:$Z$9,9,FALSE) -> #N/A
R30: =B30 -> 0 | S30: =VLOOKUP($B30,$R$3:$X$9,2,FALSE) -> #N/A | T30: =VLOOKUP($B30,$R$3:$X$9,3,FALSE) -> #N/A | U30: =VLOOKUP($B30,$R$3:$X$9,4,FALSE) -> #N/A | V30: =VLOOKUP($B30,$R$3:$X$9,5,FALSE) -> #N/A | W30: =VLOOKUP($B30,$R$3:$X$9,6,FALSE) -> #N/A | X30: =VLOOKUP($B30,$R$3:$X$9,7,FALSE) -> #N/A | Y30: =VLOOKUP($B30,$R$3:$Z$9,8,FALSE) -> #N/A | Z30: =VLOOKUP($B30,$R$3:$Z$9,9,FALSE) -> #N/A
R31: =B31 -> 0 | S31: =VLOOKUP($B31,$R$3:$X$9,2,FALSE) -> #N/A | T31: =VLOOKUP($B31,$R$3:$X$9,3,FALSE) -> #N/A | U31: =VLOOKUP($B31,$R$3:$X$9,4,FALSE) -> #N/A | V31: =VLOOKUP($B31,$R$3:$X$9,5,FALSE) -> #N/A | W31: =VLOOKUP($B31,$R$3:$X$9,6,FALSE) -> #N/A | X31: =VLOOKUP($B31,$R$3:$X$9,7,FALSE) -> #N/A | Y31: =VLOOKUP($B31,$R$3:$Z$9,8,FALSE) -> #N/A | Z31: =VLOOKUP($B31,$R$3:$Z$9,9,FALSE) -> #N/A
R32: =B32 -> 0 | S32: =VLOOKUP($B32,$R$3:$X$9,2,FALSE) -> #N/A | T32: =VLOOKUP($B32,$R$3:$X$9,3,FALSE) -> #N/A | U32: =VLOOKUP($B32,$R$3:$X$9,4,FALSE) -> #N/A | V32: =VLOOKUP($B32,$R$3:$X$9,5,FALSE) -> #N/A | W32: =VLOOKUP($B32,$R$3:$X$9,6,FALSE) -> #N/A | X32: =VLOOKUP($B32,$R$3:$X$9,7,FALSE) -> #N/A | Y32: =VLOOKUP($B32,$R$3:$Z$9,8,FALSE) -> #N/A | Z32: =VLOOKUP($B32,$R$3:$Z$9,9,FALSE) -> #N/A
R33: =B33 -> 0 | S33: =VLOOKUP($B33,$R$3:$X$9,2,FALSE) -> #N/A | T33: =VLOOKUP($B33,$R$3:$X$9,3,FALSE) -> #N/A | U33: =VLOOKUP($B33,$R$3:$X$9,4,FALSE) -> #N/A | V33: =VLOOKUP($B33,$R$3:$X$9,5,FALSE) -> #N/A | W33: =VLOOKUP($B33,$R$3:$X$9,6,FALSE) -> #N/A | X33: =VLOOKUP($B33,$R$3:$X$9,7,FALSE) -> #N/A | Y33: =VLOOKUP($B33,$R$3:$Z$9,8,FALSE) -> #N/A | Z33: =VLOOKUP($B33,$R$3:$Z$9,9,FALSE) -> #N/A
... R41: =B41 -> 0 | S41: =VLOOKUP($B41,$R$3:$X$9,2,FALSE) -> #N/A | T41: =VLOOKUP($B41,$R$3:$X$9,3,FALSE) -> #N/A | U41: =VLOOKUP($B41,$R$3:$X$9,4,FALSE) -> #N/A | V41: =VLOOKUP($B41,$R$3:$X$9,5,FALSE) -> #N/A | W41: =VLOOKUP($B41,$R$3:$X$9,6,FALSE) -> #N/A | X41: =VLOOKUP($B41,$R$3:$X$9,7,FALSE) -> #N/A | Y41: =VLOOKUP($B41,$R$3:$Z$9,8,FALSE) -> #N/A | Z41: =VLOOKUP($B41,$R$3:$Z$9,9,FALSE) -> #N/A
B42: BRAND | D42: BBT P.G./ O.G | I42: Brand | J42: Actual | K42: MTD No. of Brews | L42: MTD | M42: YTD | N42: Target | R42: =B42 -> BRAND | S42: =VLOOKUP($B42,$R$3:$X$9,2,FALSE) -> #N/A | T42: =VLOOKUP($B42,$R$3:$X$9,3,FALSE) -> #N/A | U42: =VLOOKUP($B42,$R$3:$X$9,4,FALSE) -> #N/A | V42: =VLOOKUP($B42,$R$3:$X$9,5,FALSE) -> #N/A | W42: =VLOOKUP($B42,$R$3:$X$9,6,FALSE) -> #N/A | X42: =VLOOKUP($B42,$R$3:$X$9,7,FALSE) -> #N/A | Y42: =VLOOKUP($B42,$R$3:$Z$9,8,FALSE) -> #N/A | Z42: =VLOOKUP($B42,$R$3:$Z$9,9,FALSE) -> #N/A
B43: CARIB | C43: {=[23]Process!$D$504:$D$508} -> 11.9 | D43: 11.85 | I43: CARIB | J43: =AVERAGE(I17:I20) -> 99.431733 | K43: =COUNTA([23]Brewhouse!$A$580:$A$583) -> 4 | L43: =AVERAGE([23]Brewhouse!$AU$580:$AU$583) -> 99.431733 | M43: =AVERAGE([23]Brewhouse!$AU$102:$AU$171,[23]Brewhouse!$AU$173:$AU$253,[23]Brewhouse!$AU$255:$AU$339,[23]Brewhouse!$AU$341:$AU$346,[23]Brewhouse!$AU$348,[23]Brewhouse!$AU$349:$AU$406,[23]Brewhouse!$AU$408:$AU$491,[23]Brewhouse!$AU$493:$AU$578,[23]Brewhouse!$AU$580:$AU$583) -> 97.764024 | N43: 98
C44: 11.7 | I44: STAG | M44: =AVERAGE([24]Brewhouse!$AS$15:$AS$64,[24]Brewhouse!$AS$66:$AS$103,[24]Brewhouse!$AS$105:$AS$140,[24]Brewhouse!$AS$142:$AS$193,[24]Brewhouse!$AS$195:$AS$240,[24]Brewhouse!$AS$242:$AS$273) -> 97.87626 | N44: 98
C45: 11.8 | D45: 12 | I45: GUINNESS | M45: =AVERAGE([25]Brewhouse!$AU$4:$AU$7,[25]Brewhouse!$AU$9:$AU$22,[25]Brewhouse!$AU$24:$AU$35,[25]Brewhouse!$AU$37:$AU$45,[25]Brewhouse!$AU$47:$AU$62) -> 97.179377 | N45: 98
C46: 11.8 | I46: VITAMALT | M46: =AVERAGE([26]Brewhouse!$AV$5:$AV$14,[26]Brewhouse!$AV$16:$AV$19,[26]Brewhouse!$AV$21:$AV$24,[26]Brewhouse!$AV$26:$AV$33,[26]Brewhouse!$AV$35:$AV$46,[26]Brewhouse!$AV$48:$AV$53) -> 98.620084 | N46: 98
C47: 11.9 | D47: 11.95 | I47: MAXIMALT | N47: 98
I48: MACKESON | M48: =AVERAGE([27]Brewhouse!$AT$4:$AT$11,[27]Brewhouse!$AT$13:$AT$16,[27]Brewhouse!$AT$18:$AT$21) -> 94.77317 | N48: 98
...

Sheet July 2nd
S1: P.G. | U1: Hot Time | W1: Process Time | Y1: Cooling Time
B2: Brewing Department Daily Process Loss Report | S2: Lower | T2: Upper | U2: Lower | V2: Upper | W2: Lower | X2: Upper | Y2: Lower | Z2: Upper
R3: CARIB | S3: 11.6 | T3: 12 | U3: 0 | V3: 0.11805556 | W3: 0.22569444 | X3: 0.26388889 | Y3: 0 | Z3: 60 | AB3: HR- PISNER
B4: Date: | C4: 45841 | J4: LOT WORT COLOUR: 3.3 | M4: Filter Sheets (Target 20 days) | R4: STAG | S4: 11.6 | T4: 12 | U4: 0 | V4: 0.11805556 | W4: 0.22569444 | X4: 0.26388889 | Y4: 0 | Z4: 60
M5: Double | N5: Single | R5: GUINNESS | S5: 17 | T5: 17.5 | U5: 0 | V5: 0.10763889 | W5: 0.24652778 | X5: 0.28472222 | Y5: 0 | Z5: 60
J6: MALT LOT: Lot #40 | L6: Sheet Day | M6: 10 | N6: 10 | R6: MACKESON | S6: 13.3 | T6: 13.5 | U6: 0 | V6: 0.12905093 | W6: 0.27430556 | X6: 0.30208333 | Y6: 0
R7: STARMALT | S7: 17.1 | T7: 17.5 | U7: 0 | V7: 0.13605324 | W7: 0.27430556 | X7: 0.30902778 | Y7: 0 | Z7: 85
B8: Brand | C8: Brew no. | D8: Kett. Hls | E8: Wort | F8: Cool Time(Mins) | G8: Cast. P.G. (Lab Result) | H8: Cast P.G. (Cellar Operator)-gravity | I8: Extr. Rec (79.4%) | J8: Theor. Extr. (77.5%) | K8: Boil Off /Vol. (4-6%) | L8: Boil Time | M8: Total Hot | N8: Brewing | O8: Operator | R8: Hurricane Reef | S8: 16.6 | T8: 17 | U8: 0 | V8: 0.12905093 | W8: 0.27430556 | X8: 0.30208333 | Y8: 0
E9: Meter (Hls) | F9: Target(< 60Mins) | M9: Time | R9: VITAMALT | S9: 14.4 | T9: 14.6 | U9: 0 | V9: 0.13905093 | W9: 0.26041667 | X9: 0.29513889 | Y9: 0 | Z9: 75
R10: =B10 -> 0 | S10: =VLOOKUP($B10,$R$3:$X$9,2,FALSE) -> #N/A | T10: =VLOOKUP($B10,$R$3:$X$9,3,FALSE) -> #N/A | U10: =VLOOKUP($B10,$R$3:$X$9,4,FALSE) -> #N/A | V10: =VLOOKUP($B10,$R$3:$X$9,5,FALSE) -> #N/A | W10: =VLOOKUP($B10,$R$3:$X$9,6,FALSE) -> #N/A | X10: =VLOOKUP($B10,$R$3:$X$9,7,FALSE) -> #N/A | Y10: =VLOOKUP($B10,$R$3:$Z$9,8,FALSE) -> #N/A | Z10: =VLOOKUP($B10,$R$3:$Z$9,9,FALSE) -> #N/A
R11: =B11 -> 0 | S11: =VLOOKUP($B11,$R$3:$X$9,2,FALSE) -> #N/A | T11: =VLOOKUP($B11,$R$3:$X$9,3,FALSE) -> #N/A | U11: =VLOOKUP($B11,$R$3:$X$9,4,FALSE) -> #N/A | V11: =VLOOKUP($B11,$R$3:$X$9,5,FALSE) -> #N/A | W11: =VLOOKUP($B11,$R$3:$X$9,6,FALSE) -> #N/A | X11: =VLOOKUP($B11,$R$3:$X$9,7,FALSE) -> #N/A | Y11: =VLOOKUP($B11,$R$3:$Z$9,8,FALSE) -> #N/A | Z11: =VLOOKUP($B11,$R$3:$Z$9,9,FALSE) -> #N/A
R12: =B12 -> 0 | S12: =VLOOKUP($B12,$R$3:$X$9,2,FALSE) -> #N/A | T12: =VLOOKUP($B12,$R$3:$X$9,3,FALSE) -> #N/A | U12: =VLOOKUP($B12,$R$3:$X$9,4,FALSE) -> #N/A | V12: =VLOOKUP($B12,$R$3:$X$9,5,FALSE) -> #N/A | W12: =VLOOKUP($B12,$R$3:$X$9,6,FALSE) -> #N/A | X12: =VLOOKUP($B12,$R$3:$X$9,7,FALSE) -> #N/A | Y12: =VLOOKUP($B12,$R$3:$Z$9,8,FALSE) -> #N/A | Z12: =VLOOKUP($B12,$R$3:$Z$9,9,FALSE) -> #N/A
R13: =B13 -> 0 | S13: =VLOOKUP($B13,$R$3:$X$9,2,FALSE) -> #N/A | T13: =VLOOKUP($B13,$R$3:$X$9,3,FALSE) -> #N/A | U13: =VLOOKUP($B13,$R$3:$X$9,4,FALSE) -> #N/A | V13: =VLOOKUP($B13,$R$3:$X$9,5,FALSE) -> #N/A | W13: =VLOOKUP($B13,$R$3:$X$9,6,FALSE) -> #N/A | X13: =VLOOKUP($B13,$R$3:$X$9,7,FALSE) -> #N/A | Y13: =VLOOKUP($B13,$R$3:$Z$9,8,FALSE) -> #N/A | Z13: =VLOOKUP($B13,$R$3:$Z$9,9,FALSE) -> #N/A
B15: STARMALT | C15: =[22]Brewhouse!$A60 -> SM049 | D15: =[22]Brewhouse!$AH60 -> 55 | E15: =[22]Brewhouse!$AM60 -> 52.3 | F15: =[22]Brewhouse!$Z60 -> 71 | G15: =[22]Brewhouse!$AK60 -> 17.28 | I15: =[22]Brewhouse!$AY60 -> 99.593723 | J15: =[22]Brewhouse!$AZ60 -> 100.38588 | K15: =[22]Brewhouse!$U60 -> 12.872727 | L15: =[22]Brewhouse!$T60 -> 58 | M15: =[22]Brewhouse!$Y60-[22]Brewhouse!$X60 -> 0.1375 | N15: =[22]Brewhouse!$AD60 -> 0.28402778 | O15: =[22]Brewhouse!$BC60 -> R.Sookram | R15: =B15 -> STARMALT | S15: 17 | T15: 17.2 | U15: =VLOOKUP($B15,$R$3:$X$9,4,FALSE) -> 0 | V15: =VLOOKUP($B15,$R$3:$X$9,5,FALSE) -> 0.13605324 | W15: =VLOOKUP($B15,$R$3:$X$9,6,FALSE) -> 0.27430556 | X15: =VLOOKUP($B15,$R$3:$X$9,7,FALSE) -> 0.30902778 | Y15: =VLOOKUP($B15,$R$3:$Z$9,8,FALSE) -> 0 | Z15: =VLOOKUP($B15,$R$3:$Z$9,9,FALSE) -> 85
B16: STARMALT | C16: =[22]Brewhouse!$A61 -> SM050 | D16: =[22]Brewhouse!$AH61 -> 55.1 | E16: =[22]Brewhouse!$AM61 -> 51.7 | F16: =[22]Brewhouse!$Z61 -> 65 | G16: =[22]Brewhouse!$AK61 -> 17.5 | I16: =[22]Brewhouse!$AY61 -> 99.702837 | J16: =[22]Brewhouse!$AZ61 -> 100.49511 | K16: =[22]Brewhouse!$U61 -> 10.671506 | L16: =[22]Brewhouse!$T61 -> 61 | M16: =[22]Brewhouse!$Y61-[22]Brewhouse!$X61 -> 0.13194444 | N16: =[22]Brewhouse!$AD61 -> 0.27430556 | O16: =[22]Brewhouse!$BC61 -> R.Sookram | R16: =B16 -> STARMALT | S16: 17 | T16: 17.2 | U16: =VLOOKUP($B16,$R$3:$X$9,4,FALSE) -> 0 | V16: =VLOOKUP($B16,$R$3:$X$9,5,FALSE) -> 0.13605324 | W16: =VLOOKUP($B16,$R$3:$X$9,6,FALSE) -> 0.27430556 | X16: =VLOOKUP($B16,$R$3:$X$9,7,FALSE) -> 0.30902778 | Y16: =VLOOKUP($B16,$R$3:$Z$9,8,FALSE) -> 0 | Z16: =VLOOKUP($B16,$R$3:$Z$9,9,FALSE) -> 85
B17: STARMALT | C17: =[22]Brewhouse!$A62 -> SM051 | D17: =[22]Brewhouse!$AH62 -> 56.2 | E17: =[22]Brewhouse!$AM62 -> 53.9 | F17: =[22]Brewhouse!$Z62 -> 94 | G17: =[22]Brewhouse!$AK62 -> 16.8 | I17: =[22]Brewhouse!$AY62 -> 99.503395 | J17: =[22]Brewhouse!$AZ62 -> 100.29408 | K17: =[22]Brewhouse!$U62 -> 12.597865 | L17: =[22]Brewhouse!$T62 -> 61 | M17: =[22]Brewhouse!$Y62-[22]Brewhouse!$X62 -> 0.14513889 | N17: =[22]Brewhouse!$AD62 -> 0.30833333 | O17: =[22]Brewhouse!$BC62 -> R. Regis | R17: =B17 -> STARMALT | S17: 17 | T17: 17.2 | U17: =VLOOKUP($B17,$R$3:$X$9,4,FALSE) -> 0 | V17: =VLOOKUP($B17,$R$3:$X$9,5,FALSE) -> 0.13605324 | W17: =VLOOKUP($B17,$R$3:$X$9,6,FALSE) -> 0.27430556 | X17: =VLOOKUP($B17,$R$3:$X$9,7,FALSE) -> 0.30902778 | Y17: =VLOOKUP($B17,$R$3:$Z$9,8,FALSE) -> 0 | Z17: =VLOOKUP($B17,$R$3:$Z$9,9,FALSE) -> 85
B18: STARMALT | C18: =[22]Brewhouse!$A63 -> SM052 | D18: =[22]Brewhouse!$AH63 -> 56.6 | E18: =[22]Brewhouse!$AM63 -> 51.6 | F18: =[22]Brewhouse!$Z63 -> 91 | G18: =[22]Brewhouse!$AK63 -> 17.6 | I18: =[22]Brewhouse!$AY63 -> 100.14787 | J18: =[22]Brewhouse!$AZ63 -> 100.94368 | K18: =[22]Brewhouse!$U63 -> 5.795053 | L18: =[22]Brewhouse!$T63 -> 61 | M18: =[22]Brewhouse!$Y63-[22]Brewhouse!$X63 -> 0.18611111 | N18: =[22]Brewhouse!$AD63 -> 0.33611111 | O18: =[22]Brewhouse!$BC63 -> R. Regis | R18: =B18 -> STARMALT | S18: 17 | T18: 17.2 | U18: =VLOOKUP($B18,$R$3:$X$9,4,FALSE) -> 0 | V18: =VLOOKUP($B18,$R$3:$X$9,5,FALSE) -> 0.13605324 | W18: =VLOOKUP($B18,$R$3:$X$9,6,FALSE) -> 0.27430556 | X18: =VLOOKUP($B18,$R$3:$X$9,7,FALSE) -> 0.30902778 | Y18: =VLOOKUP($B18,$R$3:$Z$9,8,FALSE) -> 0 | Z18: =VLOOKUP($B18,$R$3:$Z$9,9,FALSE) -> 85
B19: STARMALT | C19: =[22]Brewhouse!$A64 -> SM053 | D19: =[22]Brewhouse!$AH64 -> 55.8 | E19: =[22]Brewhouse!$AM64 -> 48.3 | F19: =[22]Brewhouse!$Z64 -> 74 | G19: =[22]Brewhouse!$AK64 -> 16.8 | I19: =[22]Brewhouse!$AY64 -> 98.857519 | J19: =[22]Brewhouse!$AZ64 -> 99.738444 | K19: =[22]Brewhouse!$U64 -> 17.168459 | L19: =[22]Brewhouse!$T64 -> 61 | M19: =[22]Brewhouse!$Y64-[22]Brewhouse!$X64 -> 0.14722222 | N19: =[22]Brewhouse!$AD64 -> 0.31944444 | O19: =[22]Brewhouse!$BC64 -> R. Regis | R19: =B19 -> STARMALT | S19: 17 | T19: 17.2 | U19: =VLOOKUP($B19,$R$3:$X$9,4,FALSE) -> 0 | V19: =VLOOKUP($B19,$R$3:$X$9,5,FALSE) -> 0.13605324 | W19: =VLOOKUP($B19,$R$3:$X$9,6,FALSE) -> 0.27430556 | X19: =VLOOKUP($B19,$R$3:$X$9,7,FALSE) -> 0.30902778 | Y19: =VLOOKUP($B19,$R$3:$Z$9,8,FALSE) -> 0 | Z19: =VLOOKUP($B19,$R$3:$Z$9,9,FALSE) -> 85
B20: STARMALT | C20: =[22]Brewhouse!$A65 -> SM054 | D20: =[22]Brewhouse!$AH65 -> 54.3 | E20: =[22]Brewhouse!$AM65 -> 52.6 | F20: =[22]Brewhouse!$Z65 -> 78 | G20: =[22]Brewhouse!$AK65 -> 17.4 | I20: =[22]Brewhouse!$AY65 -> 100.43457 | J20: =[22]Brewhouse!$AZ65 -> 101.23641 | K20: =[22]Brewhouse!$U65 -> 12.117864 | L20: =[22]Brewhouse!$T65 -> 60 | M20: =[22]Brewhouse!$Y65-[22]Brewhouse!$X65 -> 0.13263889 | N20: =[22]Brewhouse!$AD65 -> 0.36041667 | O20: =[22]Brewhouse!$BC65 -> D. Gomaz | R20: =B20 -> STARMALT | S20: 17 | T20: 17.2 | U20: =VLOOKUP($B20,$R$3:$X$9,4,FALSE) -> 0 | V20: =VLOOKUP($B20,$R$3:$X$9,5,FALSE) -> 0.13605324 | W20: =VLOOKUP($B20,$R$3:$X$9,6,FALSE) -> 0.27430556 | X20: =VLOOKUP($B20,$R$3:$X$9,7,FALSE) -> 0.30902778 | Y20: =VLOOKUP($B20,$R$3:$Z$9,8,FALSE) -> 0 | Z20: =VLOOKUP($B20,$R$3:$Z$9,9,FALSE) -> 85
R21: =B21 -> 0 | S21: =VLOOKUP($B21,$R$3:$X$9,2,FALSE) -> #N/A | T21: =VLOOKUP($B21,$R$3:$X$9,3,FALSE) -> #N/A | U21: =VLOOKUP($B21,$R$3:$X$9,4,FALSE) -> #N/A | V21: =VLOOKUP($B21,$R$3:$X$9,5,FALSE) -> #N/A | W21: =VLOOKUP($B21,$R$3:$X$9,6,FALSE) -> #N/A | X21: =VLOOKUP($B21,$R$3:$X$9,7,FALSE) -> #N/A | Y21: =VLOOKUP($B21,$R$3:$Z$9,8,FALSE) -> #N/A | Z21: =VLOOKUP($B21,$R$3:$Z$9,9,FALSE) -> #N/A
R22: =B22 -> 0 | S22: =VLOOKUP($B22,$R$3:$X$9,2,FALSE) -> #N/A | T22: =VLOOKUP($B22,$R$3:$X$9,3,FALSE) -> #N/A | U22: =VLOOKUP($B22,$R$3:$X$9,4,FALSE) -> #N/A | V22: =VLOOKUP($B22,$R$3:$X$9,5,FALSE) -> #N/A | W22: =VLOOKUP($B22,$R$3:$X$9,6,FALSE) -> #N/A | X22: =VLOOKUP($B22,$R$3:$X$9,7,FALSE) -> #N/A | Y22: =VLOOKUP($B22,$R$3:$Z$9,8,FALSE) -> #N/A | Z22: =VLOOKUP($B22,$R$3:$Z$9,9,FALSE) -> #N/A
R23: =B23 -> 0 | S23: =VLOOKUP($B23,$R$3:$X$9,2,FALSE) -> #N/A | T23: =VLOOKUP($B23,$R$3:$X$9,3,FALSE) -> #N/A | U23: =VLOOKUP($B23,$R$3:$X$9,4,FALSE) -> #N/A | V23: =VLOOKUP($B23,$R$3:$X$9,5,FALSE) -> #N/A | W23: =VLOOKUP($B23,$R$3:$X$9,6,FALSE) -> #N/A | X23: =VLOOKUP($B23,$R$3:$X$9,7,FALSE) -> #N/A | Y23: =VLOOKUP($B23,$R$3:$Z$9,8,FALSE) -> #N/A | Z23: =VLOOKUP($B23,$R$3:$Z$9,9,FALSE) -> #N/A
R24: =B24 -> 0 | S24: =VLOOKUP($B24,$R$3:$X$9,2,FALSE) -> #N/A | T24: =VLOOKUP($B24,$R$3:$X$9,3,FALSE) -> #N/A | U24: =VLOOKUP($B24,$R$3:$X$9,4,FALSE) -> #N/A | V24: =VLOOKUP($B24,$R$3:$X$9,5,FALSE) -> #N/A | W24: =VLOOKUP($B24,$R$3:$X$9,6,FALSE) -> #N/A | X24: =VLOOKUP($B24,$R$3:$X$9,7,FALSE) -> #N/A | Y24: =VLOOKUP($B24,$R$3:$Z$9,8,FALSE) -> #N/A | Z24: =VLOOKUP($B24,$R$3:$Z$9,9,FALSE) -> #N/A
R25: =B25 -> 0 | S25: =VLOOKUP($B25,$R$3:$X$9,2,FALSE) -> #N/A | T25: =VLOOKUP($B25,$R$3:$X$9,3,FALSE) -> #N/A | U25: =VLOOKUP($B25,$R$3:$X$9,4,FALSE) -> #N/A | V25: =VLOOKUP($B25,$R$3:$X$9,5,FALSE) -> #N/A | W25: =VLOOKUP($B25,$R$3:$X$9,6,FALSE) -> #N/A | X25: =VLOOKUP($B25,$R$3:$X$9,7,FALSE) -> #N/A | Y25: =VLOOKUP($B25,$R$3:$Z$9,8,FALSE) -> #N/A | Z25: =VLOOKUP($B25,$R$3:$Z$9,9,FALSE) -> #N/A
B26: STAG | C26: =[24]Brewhouse!$A275 -> ST255 | D26: =[24]Brewhouse!$AD275 -> 48.6 | E26: =[24]Brewhouse!$AG275 -> 50.4 | F26: =[24]Brewhouse!$V275 -> 57 | G26: =[24]Brewhouse!$AE275 -> 12 | H26: 11.8 | I26: =[24]Brewhouse!$AS275 -> 100.83968 | J26: =[24]Brewhouse!$AT275 -> 102.2187 | K26: =[24]Brewhouse!$Q275 -> 14.694656 | L26: =[24]Brewhouse!$P275 -> 58 | M26: =[24]Brewhouse!$U275-[24]Brewhouse!$T275 -> 0.10694444 | N26: =[24]Brewhouse!$AW275 -> 0.23958333 | O26: =[24]Brewhouse!$AV275 -> R.Sookram | R26: =B26 -> STAG | S26: =VLOOKUP($B26,$R$3:$X$9,2,FALSE) -> 11.6 | T26: =VLOOKUP($B26,$R$3:$X$9,3,FALSE) -> 12 | U26: =VLOOKUP($B26,$R$3:$X$9,4,FALSE) -> 0 | V26: =VLOOKUP($B26,$R$3:$X$9,5,FALSE) -> 0.11805556 | W26: =VLOOKUP($B26,$R$3:$X$9,6,FALSE) -> 0.22569444 | X26: =VLOOKUP($B26,$R$3:$X$9,7,FALSE) -> 0.26388889 | Y26: =VLOOKUP($B26,$R$3:$Z$9,8,FALSE) -> 0 | Z26: =VLOOKUP($B26,$R$3:$Z$9,9,FALSE) -> 60
B27: July 3rd 2025
B28: STAG | C28: =[24]Brewhouse!$A276 -> ST256 | D28: =[24]Brewhouse!$AD276 -> 50.5 | E28: =[24]Brewhouse!$AG276 -> 49.6 | F28: =[24]Brewhouse!$V276 -> 61 | G28: =[24]Brewhouse!$AE276 -> 11.9 | H28: 11.8 | I28: =[24]Brewhouse!$AS276 -> 98.000691 | J28: =[24]Brewhouse!$AT276 -> 99.342197 | K28: =[24]Brewhouse!$Q276 -> 9.8076923 | L28: =[24]Brewhouse!$P276 -> 59 | M28: =[24]Brewhouse!$U276-[24]Brewhouse!$T276 -> 0.11388889 | N28: =[24]Brewhouse!$AW276 -> 0.24861111 | O28: =[24]Brewhouse!$AV276 -> R.Sookram
R29: =B29 -> 0 | S29: =VLOOKUP($B29,$R$3:$X$9,2,FALSE) -> #N/A | T29: =VLOOKUP($B29,$R$3:$X$9,3,FALSE) -> #N/A | U29: =VLOOKUP($B29,$R$3:$X$9,4,FALSE) -> #N/A | V29: =VLOOKUP($B29,$R$3:$X$9,5,FALSE) -> #N/A | W29: =VLOOKUP($B29,$R$3:$X$9,6,FALSE) -> #N/A | X29: =VLOOKUP($B29,$R$3:$X$9,7,FALSE) -> #N/A | Y29: =VLOOKUP($B29,$R$3:$Z$9,8,FALSE) -> #N/A | Z29: =VLOOKUP($B29,$R$3:$Z$9,9,FALSE) -> #N/A
R30: =B30 -> 0 | S30: =VLOOKUP($B30,$R$3:$X$9,2,FALSE) -> #N/A | T30: =VLOOKUP($B30,$R$3:$X$9,3,FALSE) -> #N/A | U30: =VLOOKUP($B30,$R$3:$X$9,4,FALSE) -> #N/A | V30: =VLOOKUP($B30,$R$3:$X$9,5,FALSE) -> #N/A | W30: =VLOOKUP($B30,$R$3:$X$9,6,FALSE) -> #N/A | X30: =VLOOKUP($B30,$R$3:$X$9,7,FALSE) -> #N/A | Y30: =VLOOKUP($B30,$R$3:$Z$9,8,FALSE) -> #N/A | Z30: =VLOOKUP($B30,$R$3:$Z$9,9,FALSE) -> #N/A
R31: =B31 -> 0 | S31: =VLOOKUP($B31,$R$3:$X$9,2,FALSE) -> #N/A | T31: =VLOOKUP($B31,$R$3:$X$9,3,FALSE) -> #N/A | U31: =VLOOKUP($B31,$R$3:$X$9,4,FALSE) -> #N/A | V31: =VLOOKUP($B31,$R$3:$X$9,5,FALSE) -> #N/A | W31: =VLOOKUP($B31,$R$3:$X$9,6,FALSE) -> #N/A | X31: =VLOOKUP($B31,$R$3:$X$9,7,FALSE) -> #N/A | Y31: =VLOOKUP($B31,$R$3:$Z$9,8,FALSE) -> #N/A | Z31: =VLOOKUP($B31,$R$3:$Z$9,9,FALSE) -> #N/A
R32: =B32 -> 0 | S32: =VLOOKUP($B32,$R$3:$X$9,2,FALSE) -> #N/A | T32: =VLOOKUP($B32,$R$3:$X$9,3,FALSE) -> #N/A | U32: =VLOOKUP($B32,$R$3:$X$9,4,FALSE) -> #N/A | V32: =VLOOKUP($B32,$R$3:$X$9,5,FALSE) -> #N/A | W32: =VLOOKUP($B32,$R$3:$X$9,6,FALSE) -> #N/A | X32: =VLOOKUP($B32,$R$3:$X$9,7,FALSE) -> #N/A | Y32: =VLOOKUP($B32,$R$3:$Z$9,8,FALSE) -> #N/A | Z32: =VLOOKUP($B32,$R$3:$Z$9,9,FALSE) -> #N/A
R33: =B33 -> 0 | S33: =VLOOKUP($B33,$R$3:$X$9,2,FALSE) -> #N/A | T33: =VLOOKUP($B33,$R$3:$X$9,3,FALSE) -> #N/A | U33: =VLOOKUP($B33,$R$3:$X$9,4,FALSE) -> #N/A | V33: =VLOOKUP($B33,$R$3:$X$9,5,FALSE) -> #N/A | W33: =VLOOKUP($B33,$R$3:$X$9,6,FALSE) -> #N/A | X33: =VLOOKUP($B33,$R$3:$X$9,7,FALSE) -> #N/A | Y33: =VLOOKUP($B33,$R$3:$Z$9,8,FALSE) -> #N/A | Z33: =VLOOKUP($B33,$R$3:$Z$9,9,FALSE) -> #N/A
R34: =B34 -> 0 | S34: =VLOOKUP($B34,$R$3:$X$9,2,FALSE) -> #N/A | T34: =VLOOKUP($B34,$R$3:$X$9,3,FALSE) -> #N/A | U34: =VLOOKUP($B34,$R$3:$X$9,4,FALSE) -> #N/A | V34: =VLOOKUP($B34,$R$3:$X$9,5,FALSE) -> #N/A | W34: =VLOOKUP($B34,$R$3:$X$9,6,FALSE) -> #N/A | X34: =VLOOKUP($B34,$R$3:$X$9,7,FALSE) -> #N/A | Y34: =VLOOKUP($B34,$R$3:$Z$9,8,FALSE) -> #N/A | Z34: =VLOOKUP($B34,$R$3:$Z$9,9,FALSE) -> #N/A
R35: =B35 -> 0 | S35: =VLOOKUP($B35,$R$3:$X$9,2,FALSE) -> #N/A | T35: =VLOOKUP($B35,$R$3:$X$9,3,FALSE) -> #N/A | U35: =VLOOKUP($B35,$R$3:$X$9,4,FALSE) -> #N/A | V35: =VLOOKUP($B35,$R$3:$X$9,5,FALSE) -> #N/A | W35: =VLOOKUP($B35,$R$3:$X$9,6,FALSE) -> #N/A | X35: =VLOOKUP($B35,$R$3:$X$9,7,FALSE) -> #N/A | Y35: =VLOOKUP($B35,$R$3:$Z$9,8,FALSE) -> #N/A | Z35: =VLOOKUP($B35,$R$3:$Z$9,9,FALSE) -> #N/A
R36: =B36 -> 0 | S36: =VLOOKUP($B36,$R$3:$X$9,2,FALSE) -> #N/A | T36: =VLOOKUP($B36,$R$3:$X$9,3,FALSE) -> #N/A | U36: =VLOOKUP($B36,$R$3:$X$9,4,FALSE) -> #N/A | V36: =VLOOKUP($B36,$R$3:$X$9,5,FALSE) -> #N/A | W36: =VLOOKUP($B36,$R$3:$X$9,6,FALSE) -> #N/A | X36: =VLOOKUP($B36,$R$3:$X$9,7,FALSE) -> #N/A | Y36: =VLOOKUP($B36,$R$3:$Z$9,8,FALSE) -> #N/A | Z36: =VLOOKUP($B36,$R$3:$Z$9,9,FALSE) -> #N/A
R37: =B37 -> 0 | S37: =VLOOKUP($B37,$R$3:$X$9,2,FALSE) -> #N/A | T37: =VLOOKUP($B37,$R$3:$X$9,3,FALSE) -> #N/A | U37: =VLOOKUP($B37,$R$3:$X$9,4,FALSE) -> #N/A | V37: =VLOOKUP($B37,$R$3:$X$9,5,FALSE) -> #N/A | W37: =VLOOKUP($B37,$R$3:$X$9,6,FALSE) -> #N/A | X37: =VLOOKUP($B37,$R$3:$X$9,7,FALSE) -> #N/A | Y37: =VLOOKUP($B37,$R$3:$Z$9,8,FALSE) -> #N/A | Z37: =VLOOKUP($B37,$R$3:$Z$9,9,FALSE) -> #N/A
R38: =B38 -> 0 | S38: =VLOOKUP($B38,$R$3:$X$9,2,FALSE) -> #N/A | T38: =VLOOKUP($B38,$R$3:$X$9,3,FALSE) -> #N/A | U38: =VLOOKUP($B38,$R$3:$X$9,4,FALSE) -> #N/A | V38: =VLOOKUP($B38,$R$3:$X$9,5,FALSE) -> #N/A | W38: =VLOOKUP($B38,$R$3:$X$9,6,FALSE) -> #N/A | X38: =VLOOKUP($B38,$R$3:$X$9,7,FALSE) -> #N/A | Y38: =VLOOKUP($B38,$R$3:$Z$9,8,FALSE) -> #N/A | Z38: =VLOOKUP($B38,$R$3:$Z$9,9,FALSE) -> #N/A
R39: =B39 -> 0 | S39: =VLOOKUP($B39,$R$3:$X$9,2,FALSE) -> #N/A | T39: =VLOOKUP($B39,$R$3:$X$9,3,FALSE) -> #N/A | U39: =VLOOKUP($B39,$R$3:$X$9,4,FALSE) -> #N/A | V39: =VLOOKUP($B39,$R$3:$X$9,5,FALSE) -> #N/A | W39: =VLOOKUP($B39,$R$3:$X$9,6,FALSE) -> #N/A | X39: =VLOOKUP($B39,$R$3:$X$9,7,FALSE) -> #N/A | Y39: =VLOOKUP($B39,$R$3:$Z$9,8,FALSE) -> #N/A | Z39: =VLOOKUP($B39,$R$3:$Z$9,9,FALSE) -> #N/A
R40: =B40 -> 0 | S40: =VLOOKUP($B40,$R$3:$X$9,2,FALSE) -> #N/A | T40: =VLOOKUP($B40,$R$3:$X$9,3,FALSE) -> #N/A | U40: =VLOOKUP($B40,$R$3:$X$9,4,FALSE) -> #N/A | V40: =VLOOKUP($B40,$R$3:$X$9,5,FALSE) -> #N/A | W40: =VLOOKUP($B40,$R$3:$X$9,6,FALSE) -> #N/A | X40: =VLOOKUP($B40,$R$3:$X$9,7,FALSE) -> #N/A | Y40: =VLOOKUP($B40,$R$3:$Z$9,8,FALSE) -> #N/A | Z40: =VLOOKUP($B40,$R$3:$Z$9,9,FALSE) -> #N/A
... R42: =B42 -> 0 | S42: =VLOOKUP($B42,$R$3:$X$9,2,FALSE) -> #N/A | T42: =VLOOKUP($B42,$R$3:$X$9,3,FALSE) -> #N/A | U42: =VLOOKUP($B42,$R$3:$X$9,4,FALSE) -> #N/A | V42: =VLOOKUP($B42,$R$3:$X$9,5,FALSE) -> #N/A | W42: =VLOOKUP($B42,$R$3:$X$9,6,FALSE) -> #N/A | X42: =VLOOKUP($B42,$R$3:$X$9,7,FALSE) -> #N/A | Y42: =VLOOKUP($B42,$R$3:$Z$9,8,FALSE) -> #N/A | Z42: =VLOOKUP($B42,$R$3:$Z$9,9,FALSE) -> #N/A
...

Sheet July 3rd
S1: P.G. | U1: Hot Time | W1: Process Time | Y1: Cooling Time
B2: Brewing Department Daily Process Loss Report | S2: Lower | T2: Upper | U2: Lower | V2: Upper | W2: Lower | X2: Upper | Y2: Lower | Z2: Upper
R3: CARIB | S3: 11.6 | T3: 12 | U3: 0 | V3: 0.11805556 | W3: 0.22569444 | X3: 0.26388889 | Y3: 0 | Z3: 60 | AB3: HR- PISNER
B4: Date: | C4: 45842 | J4: LOT WORT COLOUR: 3.3 | M4: Filter Sheets (Target 20 days) | R4: STAG | S4: 11.6 | T4: 12 | U4: 0 | V4: 0.11805556 | W4: 0.22569444 | X4: 0.26388889 | Y4: 0 | Z4: 60
M5: Double | N5: Single | R5: GUINNESS | S5: 17 | T5: 17.5 | U5: 0 | V5: 0.10763889 | W5: 0.24652778 | X5: 0.28472222 | Y5: 0 | Z5: 60
J6: MALT LOT: Lot #40 | L6: Sheet Day | M6: 10 | N6: 10 | R6: MACKESON | S6: 13.3 | T6: 13.5 | U6: 0 | V6: 0.12905093 | W6: 0.27430556 | X6: 0.30208333 | Y6: 0
R7: STARMALT | S7: 17.1 | T7: 17.5 | U7: 0 | V7: 0.13605324 | W7: 0.27430556 | X7: 0.30902778 | Y7: 0 | Z7: 85
B8: Brand | C8: Brew no. | D8: Kett. Hls | E8: Wort | F8: Cool Time(Mins) | G8: Cast. P.G. (Lab Result) | H8: Cast P.G. (Cellar Operator)-gravity | I8: Extr. Rec (79.4%) | J8: Theor. Extr. (77.5%) | K8: Boil Off /Vol. (4-6%) | L8: Boil Time | M8: Total Hot | N8: Brewing | O8: Operator | R8: Hurricane Reef | S8: 16.6 | T8: 17 | U8: 0 | V8: 0.12905093 | W8: 0.27430556 | X8: 0.30208333 | Y8: 0
E9: Meter (Hls) | F9: Target(< 60Mins) | M9: Time | R9: VITAMALT | S9: 14.4 | T9: 14.6 | U9: 0 | V9: 0.13905093 | W9: 0.26041667 | X9: 0.29513889 | Y9: 0 | Z9: 75
B10: STAG | C10: =[24]Brewhouse!$A276 -> ST256 | D10: =[24]Brewhouse!$AD276 -> 50.5 | E10: =[24]Brewhouse!$AG276 -> 49.6 | F10: =[24]Brewhouse!$V276 -> 61 | G10: =[24]Brewhouse!$AE276 -> 11.9 | H10: 11.8 | I10: =[24]Brewhouse!$AS276 -> 98.000691 | J10: =[24]Brewhouse!$AT276 -> 99.342197 | K10: =[24]Brewhouse!$Q276 -> 9.8076923 | L10: =[24]Brewhouse!$P276 -> 59 | M10: =[24]Brewhouse!$U276-[24]Brewhouse!$T276 -> 0.11388889 | N10: =[24]Brewhouse!$AW276 -> 0.24861111 | O10: =[24]Brewhouse!$AV276 -> R.Sookram | R10: =B10 -> STAG | S10: =VLOOKUP($B10,$R$3:$X$9,2,FALSE) -> 11.6 | T10: =VLOOKUP($B10,$R$3:$X$9,3,FALSE) -> 12 | U10: =VLOOKUP($B10,$R$3:$X$9,4,FALSE) -> 0 | V10: =VLOOKUP($B10,$R$3:$X$9,5,FALSE) -> 0.11805556 | W10: =VLOOKUP($B10,$R$3:$X$9,6,FALSE) -> 0.22569444 | X10: =VLOOKUP($B10,$R$3:$X$9,7,FALSE) -> 0.26388889 | Y10: =VLOOKUP($B10,$R$3:$Z$9,8,FALSE) -> 0 | Z10: =VLOOKUP($B10,$R$3:$Z$9,9,FALSE) -> 60
B11: STAG | C11: =[24]Brewhouse!$A277 -> ST257 | D11: =[24]Brewhouse!$AD277 -> 47.9 | E11: =[24]Brewhouse!$AG277 -> 48.1 | F11: =[24]Brewhouse!$V277 -> 59 | G11: =[24]Brewhouse!$AE277 -> 11.9 | H11: 11.9 | I11: =[24]Brewhouse!$AS277 -> 95.27537 | J11: =[24]Brewhouse!$AT277 -> 96.578719 | K11: =[24]Brewhouse!$Q277 -> 18.019802 | L11: =[24]Brewhouse!$P277 -> 61 | M11: =[24]Brewhouse!$U277-[24]Brewhouse!$T277 -> 0.14305556 | N11: =[24]Brewhouse!$AW277 -> 0.30138889 | O11: =[24]Brewhouse!$AV277 -> R. Regis | R11: =B11 -> STAG | S11: =VLOOKUP($B11,$R$3:$X$9,2,FALSE) -> 11.6 | T11: =VLOOKUP($B11,$R$3:$X$9,3,FALSE) -> 12 | U11: =VLOOKUP($B11,$R$3:$X$9,4,FALSE) -> 0 | V11: =VLOOKUP($B11,$R$3:$X$9,5,FALSE) -> 0.11805556 | W11: =VLOOKUP($B11,$R$3:$X$9,6,FALSE) -> 0.22569444 | X11: =VLOOKUP($B11,$R$3:$X$9,7,FALSE) -> 0.26388889 | Y11: =VLOOKUP($B11,$R$3:$Z$9,8,FALSE) -> 0 | Z11: =VLOOKUP($B11,$R$3:$Z$9,9,FALSE) -> 60
B12: STAG | C12: =[24]Brewhouse!$A278 -> ST258 | D12: =[24]Brewhouse!$AD278 -> 50.2 | E12: =[24]Brewhouse!$AG278 -> 50.2 | F12: =[24]Brewhouse!$V278 -> 58 | G12: =[24]Brewhouse!$AE278 -> 11.9 | H12: 11.8 | I12: =[24]Brewhouse!$AS278 -> 99.435002 | J12: =[24]Brewhouse!$AT278 -> 100.79525 | K12: =[24]Brewhouse!$Q278 -> 14.259598 | L12: =[24]Brewhouse!$P278 -> 61 | M12: =[24]Brewhouse!$U278-[24]Brewhouse!$T278 -> 0.11805556 | N12: =[24]Brewhouse!$AW278 -> 0.28680556 | O12: =[24]Brewhouse!$AV278 -> R. Regis | R12: =B12 -> STAG | S12: =VLOOKUP($B12,$R$3:$X$9,2,FALSE) -> 11.6 | T12: =VLOOKUP($B12,$R$3:$X$9,3,FALSE) -> 12 | U12: =VLOOKUP($B12,$R$3:$X$9,4,FALSE) -> 0 | V12: =VLOOKUP($B12,$R$3:$X$9,5,FALSE) -> 0.11805556 | W12: =VLOOKUP($B12,$R$3:$X$9,6,FALSE) -> 0.22569444 | X12: =VLOOKUP($B12,$R$3:$X$9,7,FALSE) -> 0.26388889 | Y12: =VLOOKUP($B12,$R$3:$Z$9,8,FALSE) -> 0 | Z12: =VLOOKUP($B12,$R$3:$Z$9,9,FALSE) -> 60
B13: STAG | C13: =[24]Brewhouse!$A279 -> ST259 | D13: =[24]Brewhouse!$AD279 -> 48.7 | E13: =[24]Brewhouse!$AG279 -> 47.7 | F13: =[24]Brewhouse!$V279 -> 59 | G13: =[24]Brewhouse!$AE279 -> 12.3 | H13: 12 | I13: =[24]Brewhouse!$AS279 -> 97.945072 | J13: =[24]Brewhouse!$AT279 -> 99.284503 | K13: =[24]Brewhouse!$Q279 -> 14.150943 | L13: =[24]Brewhouse!$P279 -> 70 | M13: =[24]Brewhouse!$U279-[24]Brewhouse!$T279 -> 0.12222222 | N13: =[24]Brewhouse!$AW279 -> 0.25833333 | O13: =[24]Brewhouse!$AV279 -> R. Regis | R13: =B13 -> STAG | S13: =VLOOKUP($B13,$R$3:$X$9,2,FALSE) -> 11.6 | T13: =VLOOKUP($B13,$R$3:$X$9,3,FALSE) -> 12 | U13: =VLOOKUP($B13,$R$3:$X$9,4,FALSE) -> 0 | V13: =VLOOKUP($B13,$R$3:$X$9,5,FALSE) -> 0.11805556 | W13: =VLOOKUP($B13,$R$3:$X$9,6,FALSE) -> 0.22569444 | X13: =VLOOKUP($B13,$R$3:$X$9,7,FALSE) -> 0.26388889 | Y13: =VLOOKUP($B13,$R$3:$Z$9,8,FALSE) -> 0 | Z13: =VLOOKUP($B13,$R$3:$Z$9,9,FALSE) -> 60
B14: STAG | C14: =[24]Brewhouse!$A280 -> ST260 | D14: =[24]Brewhouse!$AD280 -> 50.9 | E14: =[24]Brewhouse!$AG280 -> 51 | F14: =[24]Brewhouse!$V280 -> 61 | G14: =[24]Brewhouse!$AE280 -> 11.7 | H14: 11.7 | I14: =[24]Brewhouse!$AS280 -> 99.110224 | J14: =[24]Brewhouse!$AT280 -> 100.46648 | K14: =[24]Brewhouse!$Q280 -> 11.797753 | L14: =[24]Brewhouse!$P280 -> 60 | M14: =[24]Brewhouse!$U280-[24]Brewhouse!$T280 -> 0.1125 | N14: =[24]Brewhouse!$AW280 -> 0.24930556 | O14: =[24]Brewhouse!$AV280 -> R. Regis
B15: STAG | C15: =[24]Brewhouse!$A281 -> ST261 | D15: =[24]Brewhouse!$AD281 -> 52.4 | E15: =[24]Brewhouse!$AG281 -> 52.2 | F15: =[24]Brewhouse!$V281 -> 66 | G15: =[24]Brewhouse!$AE281 -> 11.6 | H15: 11.6 | I15: =[24]Brewhouse!$AS281 -> 100.65592 | J15: =[24]Brewhouse!$AT281 -> 102.03288 | K15: =[24]Brewhouse!$Q281 -> 12.081784 | L15: =[24]Brewhouse!$P281 -> 61 | M15: =[24]Brewhouse!$U281-[24]Brewhouse!$T281 -> 0.11805556 | N15: =[24]Brewhouse!$AW281 -> 0.25833333 | O15: =[24]Brewhouse!$AV281 -> D. Gomaz | R15: =B15 -> STAG | S15: 17 | T15: 17.2 | U15: =VLOOKUP($B15,$R$3:$X$9,4,FALSE) -> 0 | V15: =VLOOKUP($B15,$R$3:$X$9,5,FALSE) -> 0.11805556 | W15: =VLOOKUP($B15,$R$3:$X$9,6,FALSE) -> 0.22569444 | X15: =VLOOKUP($B15,$R$3:$X$9,7,FALSE) -> 0.26388889 | Y15: =VLOOKUP($B15,$R$3:$Z$9,8,FALSE) -> 0 | Z15: =VLOOKUP($B15,$R$3:$Z$9,9,FALSE) -> 60
B16: STAG | C16: =[24]Brewhouse!$A282 -> ST262 | D16: =[24]Brewhouse!$AD282 -> 51.7 | E16: =[24]Brewhouse!$AG282 -> 51.8 | F16: =[24]Brewhouse!$V282 -> 65 | G16: =[24]Brewhouse!$AE282 -> 11.7 | H16: 11.6 | I16: =[24]Brewhouse!$AS282 -> 100.79116 | J16: =[24]Brewhouse!$AT282 -> 102.16996 | K16: =[24]Brewhouse!$Q282 -> 13.259669 | L16: =[24]Brewhouse!$P282 -> 58 | M16: =[24]Brewhouse!$U282-[24]Brewhouse!$T282 -> 0.11180556 | N16: =[24]Brewhouse!$AW282 -> 0.24861111 | O16: =[24]Brewhouse!$AV282 -> D. Gomaz | R16: =B16 -> STAG | S16: 17 | T16: 17.2 | U16: =VLOOKUP($B16,$R$3:$X$9,4,FALSE) -> 0 | V16: =VLOOKUP($B16,$R$3:$X$9,5,FALSE) -> 0.11805556 | W16: =VLOOKUP($B16,$R$3:$X$9,6,FALSE) -> 0.22569444 | X16: =VLOOKUP($B16,$R$3:$X$9,7,FALSE) -> 0.26388889 | Y16: =VLOOKUP($B16,$R$3:$Z$9,8,FALSE) -> 0 | Z16: =VLOOKUP($B16,$R$3:$Z$9,9,FALSE) -> 60
R17: =B17 -> 0 | S17: 17 | T17: 17.2 | U17: =VLOOKUP($B17,$R$3:$X$9,4,FALSE) -> #N/A | V17: =VLOOKUP($B17,$R$3:$X$9,5,FALSE) -> #N/A | W17: =VLOOKUP($B17,$R$3:$X$9,6,FALSE) -> #N/A | X17: =VLOOKUP($B17,$R$3:$X$9,7,FALSE) -> #N/A | Y17: =VLOOKUP($B17,$R$3:$Z$9,8,FALSE) -> #N/A | Z17: =VLOOKUP($B17,$R$3:$Z$9,9,FALSE) -> #N/A
R18: =B18 -> 0 | S18: 17 | T18: 17.2 | U18: =VLOOKUP($B18,$R$3:$X$9,4,FALSE) -> #N/A | V18: =VLOOKUP($B18,$R$3:$X$9,5,FALSE) -> #N/A | W18: =VLOOKUP($B18,$R$3:$X$9,6,FALSE) -> #N/A | X18: =VLOOKUP($B18,$R$3:$X$9,7,FALSE) -> #N/A | Y18: =VLOOKUP($B18,$R$3:$Z$9,8,FALSE) -> #N/A | Z18: =VLOOKUP($B18,$R$3:$Z$9,9,FALSE) -> #N/A
R19: =B19 -> 0 | S19: 17 | T19: 17.2 | U19: =VLOOKUP($B19,$R$3:$X$9,4,FALSE) -> #N/A | V19: =VLOOKUP($B19,$R$3:$X$9,5,FALSE) -> #N/A | W19: =VLOOKUP($B19,$R$3:$X$9,6,FALSE) -> #N/A | X19: =VLOOKUP($B19,$R$3:$X$9,7,FALSE) -> #N/A | Y19: =VLOOKUP($B19,$R$3:$Z$9,8,FALSE) -> #N/A | Z19: =VLOOKUP($B19,$R$3:$Z$9,9,FALSE) -> #N/A
R20: =B20 -> 0 | S20: 17 | T20: 17.2 | U20: =VLOOKUP($B20,$R$3:$X$9,4,FALSE) -> #N/A | V20: =VLOOKUP($B20,$R$3:$X$9,5,FALSE) -> #N/A | W20: =VLOOKUP($B20,$R$3:$X$9,6,FALSE) -> #N/A | X20: =VLOOKUP($B20,$R$3:$X$9,7,FALSE) -> #N/A | Y20: =VLOOKUP($B20,$R$3:$Z$9,8,FALSE) -> #N/A | Z20: =VLOOKUP($B20,$R$3:$Z$9,9,FALSE) -> #N/A
B21: CARIB | C21: =[23]Brewhouse!$A584 -> CA477 | D21: =[23]Brewhouse!$AF584 -> 50.9 | E21: =[23]Brewhouse!$AI584 -> 48.8 | F21: =[23]Brewhouse!$V584 -> 56 | G21: =[23]Brewhouse!$AG584 -> 11.9 | H21: 11.8 | I21: =[23]Brewhouse!$AU584 -> 95.185471 | J21: =[23]Brewhouse!$AV584 -> 96.759308 | K21: =[23]Brewhouse!$Q584 -> 10.948122 | L21: =[23]Brewhouse!$P584 -> 60 | M21: =[23]Brewhouse!$U584-[23]Brewhouse!$T584 -> 0.10763889 | N21: =[23]Brewhouse!$Z584 -> 0.23958333 | O21: =[23]Brewhouse!$AX584 -> D. Gomez | R21: =B21 -> CARIB | S21: =VLOOKUP($B21,$R$3:$X$9,2,FALSE) -> 11.6 | T21: =VLOOKUP($B21,$R$3:$X$9,3,FALSE) -> 12 | U21: =VLOOKUP($B21,$R$3:$X$9,4,FALSE) -> 0 | V21: =VLOOKUP($B21,$R$3:$X$9,5,FALSE) -> 0.11805556 | W21: =VLOOKUP($B21,$R$3:$X$9,6,FALSE) -> 0.22569444 | X21: =VLOOKUP($B21,$R$3:$X$9,7,FALSE) -> 0.26388889 | Y21: =VLOOKUP($B21,$R$3:$Z$9,8,FALSE) -> 0 | Z21: =VLOOKUP($B21,$R$3:$Z$9,9,FALSE) -> 60
B22: CARIB | C22: =[23]Brewhouse!$A585 -> CA478 | D22: =[23]Brewhouse!$AF585 -> 53 | E22: =[23]Brewhouse!$AI585 -> 49.4 | F22: =[23]Brewhouse!$V585 -> 58 | G22: =[23]Brewhouse!$AG585 -> 11.8 | H22: 11.7 | I22: =[23]Brewhouse!$AU585 -> 99.179467 | J22: =[23]Brewhouse!$AV585 -> 100.81656 | K22: =[23]Brewhouse!$Q585 -> 9.8395722 | L22: =[23]Brewhouse!$P585 -> 62 | M22: =[23]Brewhouse!$U585-[23]Brewhouse!$T585 -> 0.10902778 | N22: =[23]Brewhouse!$Z585 -> 0.24375 | O22: =[23]Brewhouse!$AX585 -> R. Sookram | R22: =B22 -> CARIB | S22: =VLOOKUP($B22,$R$3:$X$9,2,FALSE) -> 11.6 | T22: =VLOOKUP($B22,$R$3:$X$9,3,FALSE) -> 12 | U22: =VLOOKUP($B22,$R$3:$X$9,4,FALSE) -> 0 | V22: =VLOOKUP($B22,$R$3:$X$9,5,FALSE) -> 0.11805556 | W22: =VLOOKUP($B22,$R$3:$X$9,6,FALSE) -> 0.22569444 | X22: =VLOOKUP($B22,$R$3:$X$9,7,FALSE) -> 0.26388889 | Y22: =VLOOKUP($B22,$R$3:$Z$9,8,FALSE) -> 0 | Z22: =VLOOKUP($B22,$R$3:$Z$9,9,FALSE) -> 60
B23: CARIB | C23: =[23]Brewhouse!$A586 -> CA479 | D23: =[23]Brewhouse!$AF586 -> 52.4 | E23: =[23]Brewhouse!$AI586 -> 50.4 | F23: =[23]Brewhouse!$V586 -> 59 | G23: =[23]Brewhouse!$AG586 -> 12 | H23: 12 | I23: =[23]Brewhouse!$AU586 -> 99.543728 | J23: =[23]Brewhouse!$AV586 -> 101.18936 | K23: =[23]Brewhouse!$Q586 -> 8.3687943 | L23: =[23]Brewhouse!$P586 -> 66 | M23: =[23]Brewhouse!$U586-[23]Brewhouse!$T586 -> 0.10763889 | N23: =[23]Brewhouse!$Z586 -> 0.24861111 | O23: =[23]Brewhouse!$AX586 -> R. Sookram | R23: =B23 -> CARIB | S23: =VLOOKUP($B23,$R$3:$X$9,2,FALSE) -> 11.6 | T23: =VLOOKUP($B23,$R$3:$X$9,3,FALSE) -> 12 | U23: =VLOOKUP($B23,$R$3:$X$9,4,FALSE) -> 0 | V23: =VLOOKUP($B23,$R$3:$X$9,5,FALSE) -> 0.11805556 | W23: =VLOOKUP($B23,$R$3:$X$9,6,FALSE) -> 0.22569444 | X23: =VLOOKUP($B23,$R$3:$X$9,7,FALSE) -> 0.26388889 | Y23: =VLOOKUP($B23,$R$3:$Z$9,8,FALSE) -> 0 | Z23: =VLOOKUP($B23,$R$3:$Z$9,9,FALSE) -> 60
R24: =B24 -> 0 | S24: =VLOOKUP($B24,$R$3:$X$9,2,FALSE) -> #N/A | T24: =VLOOKUP($B24,$R$3:$X$9,3,FALSE) -> #N/A | U24: =VLOOKUP($B24,$R$3:$X$9,4,FALSE) -> #N/A | V24: =VLOOKUP($B24,$R$3:$X$9,5,FALSE) -> #N/A | W24: =VLOOKUP($B24,$R$3:$X$9,6,FALSE) -> #N/A | X24: =VLOOKUP($B24,$R$3:$X$9,7,FALSE) -> #N/A | Y24: =VLOOKUP($B24,$R$3:$Z$9,8,FALSE) -> #N/A | Z24: =VLOOKUP($B24,$R$3:$Z$9,9,FALSE) -> #N/A
R25: =B25 -> 0 | S25: =VLOOKUP($B25,$R$3:$X$9,2,FALSE) -> #N/A | T25: =VLOOKUP($B25,$R$3:$X$9,3,FALSE) -> #N/A | U25: =VLOOKUP($B25,$R$3:$X$9,4,FALSE) -> #N/A | V25: =VLOOKUP($B25,$R$3:$X$9,5,FALSE) -> #N/A | W25: =VLOOKUP($B25,$R$3:$X$9,6,FALSE) -> #N/A | X25: =VLOOKUP($B25,$R$3:$X$9,7,FALSE) -> #N/A | Y25: =VLOOKUP($B25,$R$3:$Z$9,8,FALSE) -> #N/A | Z25: =VLOOKUP($B25,$R$3:$Z$9,9,FALSE) -> #N/A
R26: =B26 -> 0 | S26: =VLOOKUP($B26,$R$3:$X$9,2,FALSE) -> #N/A | T26: =VLOOKUP($B26,$R$3:$X$9,3,FALSE) -> #N/A | U26: =VLOOKUP($B26,$R$3:$X$9,4,FALSE) -> #N/A | V26: =VLOOKUP($B26,$R$3:$X$9,5,FALSE) -> #N/A | W26: =VLOOKUP($B26,$R$3:$X$9,6,FALSE) -> #N/A | X26: =VLOOKUP($B26,$R$3:$X$9,7,FALSE) -> #N/A | Y26: =VLOOKUP($B26,$R$3:$Z$9,8,FALSE) -> #N/A | Z26: =VLOOKUP($B26,$R$3:$Z$9,9,FALSE) -> #N/A
R29: =B29 -> 0 | S29: =VLOOKUP($B29,$R$3:$X$9,2,FALSE) -> #N/A | T29: =VLOOKUP($B29,$R$3:$X$9,3,FALSE) -> #N/A | U29: =VLOOKUP($B29,$R$3:$X$9,4,FALSE) -> #N/A | V29: =VLOOKUP($B29,$R$3:$X$9,5,FALSE) -> #N/A | W29: =VLOOKUP($B29,$R$3:$X$9,6,FALSE) -> #N/A | X29: =VLOOKUP($B29,$R$3:$X$9,7,FALSE) -> #N/A | Y29: =VLOOKUP($B29,$R$3:$Z$9,8,FALSE) -> #N/A | Z29: =VLOOKUP($B29,$R$3:$Z$9,9,FALSE) -> #N/A
R30: =B30 -> 0 | S30: =VLOOKUP($B30,$R$3:$X$9,2,FALSE) -> #N/A | T30: =VLOOKUP($B30,$R$3:$X$9,3,FALSE) -> #N/A | U30: =VLOOKUP($B30,$R$3:$X$9,4,FALSE) -> #N/A | V30: =VLOOKUP($B30,$R$3:$X$9,5,FALSE) -> #N/A | W30: =VLOOKUP($B30,$R$3:$X$9,6,FALSE) -> #N/A | X30: =VLOOKUP($B30,$R$3:$X$9,7,FALSE) -> #N/A | Y30: =VLOOKUP($B30,$R$3:$Z$9,8,FALSE) -> #N/A | Z30: =VLOOKUP($B30,$R$3:$Z$9,9,FALSE) -> #N/A
R31: =B31 -> 0 | S31: =VLOOKUP($B31,$R$3:$X$9,2,FALSE) -> #N/A | T31: =VLOOKUP($B31,$R$3:$X$9,3,FALSE) -> #N/A | U31: =VLOOKUP($B31,$R$3:$X$9,4,FALSE) -> #N/A | V31: =VLOOKUP($B31,$R$3:$X$9,5,FALSE) -> #N/A | W31: =VLOOKUP($B31,$R$3:$X$9,6,FALSE) -> #N/A | X31: =VLOOKUP($B31,$R$3:$X$9,7,FALSE) -> #N/A | Y31: =VLOOKUP($B31,$R$3:$Z$9,8,FALSE) -> #N/A | Z31: =VLOOKUP($B31,$R$3:$Z$9,9,FALSE) -> #N/A
R32: =B32 -> 0 | S32: =VLOOKUP($B32,$R$3:$X$9,2,FALSE) -> #N/A | T32: =VLOOKUP($B32,$R$3:$X$9,3,FALSE) -> #N/A | U32: =VLOOKUP($B32,$R$3:$X$9,4,FALSE) -> #N/A | V32: =VLOOKUP($B32,$R$3:$X$9,5,FALSE) -> #N/A | W32: =VLOOKUP($B32,$R$3:$X$9,6,FALSE) -> #N/A | X32: =VLOOKUP($B32,$R$3:$X$9,7,FALSE) -> #N/A | Y32: =VLOOKUP($B32,$R$3:$Z$9,8,FALSE) -> #N/A | Z32: =VLOOKUP($B32,$R$3:$Z$9,9,FALSE) -> #N/A
R33: =B33 -> 0 | S33: =VLOOKUP($B33,$R$3:$X$9,2,FALSE) -> #N/A | T33: =VLOOKUP($B33,$R$3:$X$9,3,FALSE) -> #N/A | U33: =VLOOKUP($B33,$R$3:$X$9,4,FALSE) -> #N/A | V33: =VLOOKUP($B33,$R$3:$X$9,5,FALSE) -> #N/A | W33: =VLOOKUP($B33,$R$3:$X$9,6,FALSE) -> #N/A | X33: =VLOOKUP($B33,$R$3:$X$9,7,FALSE) -> #N/A | Y33: =VLOOKUP($B33,$R$3:$Z$9,8,FALSE) -> #N/A | Z33: =VLOOKUP($B33,$R$3:$Z$9,9,FALSE) -> #N/A
R34: =B34 -> 0 | S34: =VLOOKUP($B34,$R$3:$X$9,2,FALSE) -> #N/A | T34: =VLOOKUP($B34,$R$3:$X$9,3,FALSE) -> #N/A | U34: =VLOOKUP($B34,$R$3:$X$9,4,FALSE) -> #N/A | V34: =VLOOKUP($B34,$R$3:$X$9,5,FALSE) -> #N/A | W34: =VLOOKUP($B34,$R$3:$X$9,6,FALSE) -> #N/A | X34: =VLOOKUP($B34,$R$3:$X$9,7,FALSE) -> #N/A | Y34: =VLOOKUP($B34,$R$3:$Z$9,8,FALSE) -> #N/A | Z34: =VLOOKUP($B34,$R$3:$Z$9,9,FALSE) -> #N/A
R35: =B35 -> 0 | S35: =VLOOKUP($B35,$R$3:$X$9,2,FALSE) -> #N/A | T35: =VLOOKUP($B35,$R$3:$X$9,3,FALSE) -> #N/A | U35: =VLOOKUP($B35,$R$3:$X$9,4,FALSE) -> #N/A | V35: =VLOOKUP($B35,$R$3:$X$9,5,FALSE) -> #N/A | W35: =VLOOKUP($B35,$R$3:$X$9,6,FALSE) -> #N/A | X35: =VLOOKUP($B35,$R$3:$X$9,7,FALSE) -> #N/A | Y35: =VLOOKUP($B35,$R$3:$Z$9,8,FALSE) -> #N/A | Z35: =VLOOKUP($B35,$R$3:$Z$9,9,FALSE) -> #N/A
