Workbook

Sheet Entries June'25
B1: ENTRIES FOR DAILY CONS. MONITOR | O1: =B1 -> ENTRIES FOR DAILY CONS. MONITOR
C2: old | F2: old | O2: Service 227.3 cubic meters (2273 Hls)Filtered 189.3 cubic meters(1893 Hls)
D3: FUEL | J3: ELECT. | L3: CO2 | O3: WATER | AG3: CO2 Scrubber (m3) | AH3: Supply to Washdown Area (m3) | AI3: Supply to RUs (m3) | AJ3: Steam Mass Flow Meter | AK3: CO2 TANKS' READING
B4: Boilers tot. | C4: Boiler 1 | D4: Gen. meter | E4: Tank level | F4: Boiler 1 | G4: Boiler 2 | H4: Gen | I4: Meter1 | J4: Meter 2 | K4: Gen Meter | L4: Collection | M4: Consumption | N4: Consumption (Filler) (kg) | O4: Nawasa Meter (m3) | P4: Annandale Supply (m3) | Q4: Service Supply to Plant (m3) | R4: Cellars/Filtration (m3) | S4: Brewhouse Meter (m3) | T4: Cellars/Process Areas (m3) | U4: Pasteuriser (m3) | V4: Water Plant-Nawasa Annadale (m3) | W4: Water Plant-Well # 1 (m3) | X4: CIP Process | Y4: Bottle Washer | Z4: Boiler | AA4: Permeate #1 | AB4: Permeate #2 | AC4: Bottle Filler (m3) | AD4: RO # 1 Totaliser (m3) | AE4: RO # 2 Totaliser (m3) | AF4: Recovered Water (m3) | AK4: (Kg.) | AL4: ` | AM4: (Lbs.) | AN4: (Kg.)
A5: DATE | B5: (liters) | C5: (liters) | D5: (Imp. gals) | E5: (inches) | F5: Hrs | G5: Hrs | H5: Hrs. | I5: (Kwhr) | J5: (Kwhr) | K5: (Kwhr) | L5: Meter (kg) | M5: Meter (kg) | X5: (m3) | Y5: (m3) | Z5: (m3) | AK5: Tank "A" | AL5: Tank "B" | AM5: Mobile Tanker | AN5: Inside Tank
A6: -
A7: 1 | B7: 7416560 | E7: 64 | F7: 4131.1 | G7: 68225 | I7: 651300 | J7: 204968 | K7: 468000 | N7: 3052.19 | O7: 180743 | P7: 21238 | Q7: 903351 | S7: 45913 | U7: 20888 | V7: 1298636 | X7: 34117 | Y7: 33760 | Z7: 7492 | AA7: 97122 | AC7: 40368 | AD7: 259432 | AJ7: 7288160.8
A8: 2 | B8: 7417290 | E8: 64 | F8: 4135.5 | G8: 68225 | I8: 654282 | J8: 207771 | K8: 468000 | N8: 3052.19 | O8: 180743 | P8: 21309 | Q8: 903363 | S8: 45913 | U8: 20888 | V8: 1298708 | X8: 34117 | Y8: 33787 | Z8: 7493 | AA8: 97122 | AC8: 40368 | AD8: 259432 | AJ8: 7288189.3
A9: 3 | B9: 7420570 | E9: 64 | F9: 4156.6 | G9: 68225 | I9: 658919 | J9: 212138 | K9: 468000 | N9: 3112.78 | O9: 181010 | P9: 21497 | Q9: 903698 | S9: 46026 | U9: 20907 | V9: 1298908 | X9: 34202 | Y9: 33900 | Z9: 7518 | AA9: 97122 | AC9: 40368 | AD9: 259432 | AJ9: 7288189.3
A10: 4 | B10: 7423950 | E10: 64 | F10: 4177.7 | G10: 68225 | I10: 663548 | J10: 216496 | K10: 468000 | N10: 3165.58 | O10: 181298 | P10: 21629 | Q10: 903992 | S10: 46156 | U10: 20907 | V10: 1299047 | X10: 34253 | Y10: 34058 | Z10: 7538 | AA10: 97122 | AC10: 40410 | AD10: 259432 | AJ10: 7288297.3
A11: 5 | B11: 7427080 | E11: 64 | F11: 4197.9 | G11: 68225 | I11: 668191 | J11: 220866 | K11: 468000 | N11: 3215.28 | O11: 181496 | P11: 21800 | Q11: 904220 | S11: 46329 | U11: 20907 | V11: 1299228 | X11: 34284 | Y11: 34171 | Z11: 7554 | AA11: 97122 | AC11: 40432 | AD11: 259432 | AJ11: 7288301.2
A12: 6 | B12: 7430590 | E12: 64 | F12: 4219.8 | G12: 68225 | I12: 673137 | J12: 225529 | K12: 468000 | N12: 3276.42 | O12: 181637 | P12: 22062 | Q12: 904525 | S12: 46551 | U12: 20915 | V12: 1299504 | X12: 34340 | Y12: 34321 | Z12: 7574 | AA12: 97122 | AC12: 40455 | AD12: 259448 | AJ12: 7288301.2
A13: 7 | B13: 7433250 | E13: 64 | F13: 4238.1 | G13: 68225 | I13: 677816 | J13: 229936 | K13: 468000 | N13: 3324.64 | O13: 181860 | P13: 22349 | Q13: 904750 | S13: 46673 | U13: 20915 | V13: 1299806 | X13: 34400 | Y13: 34415 | Z13: 7589 | AA13: 97122 | AC13: 40472 | AD13: 259448 | AJ13: 7288301.2
A14: 8 | B14: 7433550 | E14: 64 | F14: 4240.2 | G14: 68225 | I14: 679982 | J14: 231968 | K14: 468000 | N14: 3324.97 | O14: 181860 | P14: 22349 | Q14: 904797 | S14: 46674 | U14: 20915 | V14: 1299806 | X14: 34405 | Y14: 34420 | Z14: 7589 | AA14: 97122 | AC14: 40474 | AD14: 259448 | AJ14: 7288301.2
A15: 9 | B15: 7433550 | E15: 64 | F15: 4240.2 | G15: 68225 | I15: 682776 | J15: 234539 | K15: 468000 | N15: 3324.97 | O15: 181860 | P15: 22437 | Q15: 904868 | S15: 46674 | U15: 20915 | V15: 1299899 | X15: 34405 | Y15: 34479 | Z15: 7590 | AA15: 97122 | AC15: 40474 | AD15: 259448 | AJ15: 7288301.2
A16: 10 | B16: 7434380 | E16: 64 | F16: 4245.2 | G16: 68225 | I16: 685080 | J16: 236740 | K16: 468000 | N16: 3324.97 | O16: 181860 | P16: 22437 | Q16: 904874 | S16: 46674 | U16: 20915 | V16: 1299899 | X16: 34405 | Y16: 34479 | Z16: 7593 | AA16: 97122 | AC16: 40474 | AD16: 259448 | AJ16: 7288301.2
A17: 11 | B17: 7437280 | E17: 64 | F17: 4264.3 | G17: 68225 | I17: 689299 | J17: 240709 | K17: 468000 | N17: 3384.18 | O17: 182031 | P17: 22573 | Q17: 905144 | S17: 46774 | U17: 20921 | V17: 1300042 | X17: 34452 | Y17: 34619 | Z17: 7610 | AA17: 97122 | AC17: 40474 | AD17: 259448 | AJ17: 7288304.1
A18: 12 | B18: 7440680 | E18: 64 | F18: 4285.8 | G18: 68225 | I18: 693826 | J18: 244973 | K18: 468000 | N18: 3458.97 | O18: 182335 | P18: 22745 | Q18: 905431 | S18: 46954 | U18: 20921 | V18: 1300216 | X18: 34495 | Y18: 34777 | Z18: 7628 | AA18: 97122 | AC18: 40474 | AD18: 259448 | AJ18: 7288304.1
... A37: 1 | B37: 7486040 | E37: 64 | F37: 4583 | G37: 68225 | I37: 765750 | J37: 312573 | K37: 468000 | N37: 4185.99 | O37: 184851 | P37: 25619 | Q37: 908959 | S37: 48949 | U37: 21043 | V37: 1303314 | X37: 35100 | Y37: 36417 | Z37: 8088 | AA37: 97122 | AC37: 40783 | AD37: 259968 | AJ37: 7289001.9

Sheet Utility Analysis June 2025
H2: GRENADA BREWERIES LIMITED
H3: UTILITY ANALYSIS
A5: MONTH: | G5: 39295
A7: DATE | D7: ELECTRICITY GRENLEC | E7: CARIB GENSET | F7: ELECTRICITY TOTAL | G7: WATER | H7: FUEL | I7: CO2 | J7: PRODUCTION - HL | O7: UTILITY RATIOS
B8: METER 1 | C8: METER 2 | O8: Elect | P8: Water | Q8: Fuel | R8: CO2
D9: USAGE (kwh) | E9: USAGE (kwh) | F9: USAGE (kwh) | G9: USAGE (Hl) | H9: USAGE (l) | I9: USAGE (Kg.) | J9: BREWED | K9: BOTTLED | L9: KEGS | M9: OTHER | N9: TOTAL | O9: KWH/Hl | P9: Hl/hl | Q9: Litres/hl | R9: kg./Hl
A10: 1 | B10: =IF('Entries June''25'!I8>='Entries June''25'!I7,'Entries June''25'!I8-'Entries June''25'!I7,(999999-'Entries June''25'!I7)+'Entries June''25'!I8+1) -> 2982 | C10: =IF('Entries June''25'!J8>='Entries June''25'!J7,'Entries June''25'!J8-'Entries June''25'!J7,(999999-'Entries June''25'!J7)+'Entries June''25'!J8+1) -> 2803 | D10: =B10+C10 -> 5785 | E10: =IF('Entries June''25'!K8>='Entries June''25'!K7,'Entries June''25'!K8-'Entries June''25'!K7,(999999-'Entries June''25'!K7)+'Entries June''25'!K8+1) -> 0 | F10: =D10+E10 -> 5785 | G10: ='Water '!Z7*10 -> 710 | H10: =IF('Entries June''25'!B8-'Entries June''25'!B7<1,"0",'Entries June''25'!B8-'Entries June''25'!B7) -> 730 | I10: ='CO2'!C7 -> 0 | J10: =+'PROD.FIG. '!F5 -> 0 | K10: =+'PROD.FIG. '!C5 -> 0 | L10: =+'PROD.FIG. '!D5 -> 0 | M10: =+'PROD.FIG. '!E5 -> 0 | N10: {=TRANSPOSE('Daily KPIs'!B9:AF9)} -> 0 | O10: =IF(N10=0,0,F10/N10) -> 0 | P10: =IF(O10=0,0,G10/N10) -> 0 | Q10: =IF(P10=0,0,H10/N10) -> 0 | R10: =IF(Q10=0,0,I10/N10) -> 0
A11: 2 | B11: =IF('Entries June''25'!I9>='Entries June''25'!I8,'Entries June''25'!I9-'Entries June''25'!I8,(999999-'Entries June''25'!I8)+'Entries June''25'!I9+1) -> 4637 | C11: =IF('Entries June''25'!J9>='Entries June''25'!J8,'Entries June''25'!J9-'Entries June''25'!J8,(999999-'Entries June''25'!J8)+'Entries June''25'!J9+1) -> 4367 | D11: =B11+C11 -> 9004 | E11: =IF('Entries June''25'!K9>='Entries June''25'!K8,'Entries June''25'!K9-'Entries June''25'!K8,(999999-'Entries June''25'!K8)+'Entries June''25'!K9+1) -> 0 | F11: =D11+E11 -> 9004 | G11: ='Water '!Z8*10 -> 4550 | H11: =IF('Entries June''25'!B9-'Entries June''25'!B8<1,"0",'Entries June''25'!B9-'Entries June''25'!B8) -> 3280 | I11: ='CO2'!C8 -> 2700 | J11: =+'PROD.FIG. '!F6 -> 0 | K11: =+'PROD.FIG. '!C6 -> 0 | L11: =+'PROD.FIG. '!D6 -> 0 | M11: =+'PROD.FIG. '!E6 -> 0 | N11: 455.6052 | O11: =IF(N11=0,0,F11/N11) -> 19.762724 | P11: =IF(O11=0,0,G11/N11) -> 9.9867166 | Q11: =IF(P11=0,0,H11/N11) -> 7.1992155 | R11: =IF(Q11=0,0,I11/N11) -> 5.9261835
A12: 3 | B12: =IF('Entries June''25'!I10>='Entries June''25'!I9,'Entries June''25'!I10-'Entries June''25'!I9,(999999-'Entries June''25'!I9)+'Entries June''25'!I10+1) -> 4629 | C12: =IF('Entries June''25'!J10>='Entries June''25'!J9,'Entries June''25'!J10-'Entries June''25'!J9,(999999-'Entries June''25'!J9)+'Entries June''25'!J10+1) -> 4358 | D12: =B12+C12 -> 8987 | E12: =IF('Entries June''25'!K10>='Entries June''25'!K9,'Entries June''25'!K10-'Entries June''25'!K9,(999999-'Entries June''25'!K9)+'Entries June''25'!K10+1) -> 0 | F12: =D12+E12 -> 8987 | G12: ='Water '!Z9*10 -> 4200 | H12: =IF('Entries June''25'!B10-'Entries June''25'!B9<1,"0",'Entries June''25'!B10-'Entries June''25'!B9) -> 3380 | I12: ='CO2'!C9 -> 3100 | J12: =+'PROD.FIG. '!F7 -> 0 | K12: =+'PROD.FIG. '!C7 -> 0 | L12: =+'PROD.FIG. '!D7 -> 0 | M12: =+'PROD.FIG. '!E7 -> 0 | N12: 644.754 | O12: =IF(N12=0,0,F12/N12) -> 13.938649 | P12: =IF(O12=0,0,G12/N12) -> 6.5141124 | Q12: =IF(P12=0,0,H12/N12) -> 5.2423095 | R12: =IF(Q12=0,0,I12/N12) -> 4.8080353
A13: 4 | B13: =IF('Entries June''25'!I11>='Entries June''25'!I10,'Entries June''25'!I11-'Entries June''25'!I10,(999999-'Entries June''25'!I10)+'Entries June''25'!I11+1) -> 4643 | C13: =IF('Entries June''25'!J11>='Entries June''25'!J10,'Entries June''25'!J11-'Entries June''25'!J10,(999999-'Entries June''25'!J10)+'Entries June''25'!J11+1) -> 4370 | D13: =B13+C13 -> 9013 | E13: =IF('Entries June''25'!K11>='Entries June''25'!K10,'Entries June''25'!K11-'Entries June''25'!K10,(999999-'Entries June''25'!K10)+'Entries June''25'!K11+1) -> 0 | F13: =D13+E13 -> 9013 | G13: ='Water '!Z10*10 -> 3690 | H13: =IF('Entries June''25'!B11-'Entries June''25'!B10<1,"0",'Entries June''25'!B11-'Entries June''25'!B10) -> 3130 | I13: ='CO2'!C10 -> 2500 | J13: =+'PROD.FIG. '!F8 -> 0 | K13: =+'PROD.FIG. '!C8 -> 0 | L13: =+'PROD.FIG. '!D8 -> 0 | M13: =+'PROD.FIG. '!E8 -> 0 | N13: 398.442 | O13: =IF(N13=0,0,F13/N13) -> 22.620607 | P13: =IF(O13=0,0,G13/N13) -> 9.2610719 | Q13: =IF(P13=0,0,H13/N13) -> 7.8555976 | R13: =IF(Q13=0,0,I13/N13) -> 6.2744389
A14: 5 | B14: =IF('Entries June''25'!I12>='Entries June''25'!I11,'Entries June''25'!I12-'Entries June''25'!I11,(999999-'Entries June''25'!I11)+'Entries June''25'!I12+1) -> 4946 | C14: =IF('Entries June''25'!J12>='Entries June''25'!J11,'Entries June''25'!J12-'Entries June''25'!J11,(999999-'Entries June''25'!J11)+'Entries June''25'!J12+1) -> 4663 | D14: =B14+C14 -> 9609 | E14: =IF('Entries June''25'!K12>='Entries June''25'!K11,'Entries June''25'!K12-'Entries June''25'!K11,(999999-'Entries June''25'!K11)+'Entries June''25'!K12+1) -> 0 | F14: =D14+E14 -> 9609 | G14: ='Water '!Z11*10 -> 4030 | H14: =IF('Entries June''25'!B12-'Entries June''25'!B11<1,"0",'Entries June''25'!B12-'Entries June''25'!B11) -> 3510 | I14: ='CO2'!C11 -> 3900 | J14: =+'PROD.FIG. '!F9 -> 0 | K14: =+'PROD.FIG. '!C9 -> 0 | L14: =+'PROD.FIG. '!D9 -> 0 | M14: =+'PROD.FIG. '!E9 -> 0 | N14: 496.584 | O14: =IF(N14=0,0,F14/N14) -> 19.350201 | P14: =IF(O14=0,0,G14/N14) -> 8.1154447 | Q14: =IF(P14=0,0,H14/N14) -> 7.0682906 | R14: =IF(Q14=0,0,I14/N14) -> 7.8536562
A15: 6 | B15: =IF('Entries June''25'!I13>='Entries June''25'!I12,'Entries June''25'!I13-'Entries June''25'!I12,(999999-'Entries June''25'!I12)+'Entries June''25'!I13+1) -> 4679 | C15: =IF('Entries June''25'!J13>='Entries June''25'!J12,'Entries June''25'!J13-'Entries June''25'!J12,(999999-'Entries June''25'!J12)+'Entries June''25'!J13+1) -> 4407 | D15: =B15+C15 -> 9086 | E15: =IF('Entries June''25'!K13>='Entries June''25'!K12,'Entries June''25'!K13-'Entries June''25'!K12,(999999-'Entries June''25'!K12)+'Entries June''25'!K13+1) -> 0 | F15: =D15+E15 -> 9086 | G15: ='Water '!Z12*10 -> 5100 | H15: =IF('Entries June''25'!B13-'Entries June''25'!B12<1,"0",'Entries June''25'!B13-'Entries June''25'!B12) -> 2660 | I15: ='CO2'!C12 -> 3200 | J15: =+'PROD.FIG. '!F10 -> 0 | K15: =+'PROD.FIG. '!C10 -> 0 | L15: =+'PROD.FIG. '!D10 -> 0 | M15: =+'PROD.FIG. '!E10 -> 0 | N15: 263.934 | O15: =IF(N15=0,0,F15/N15) -> 34.425273 | P15: =IF(O15=0,0,G15/N15) -> 19.323013 | Q15: =IF(P15=0,0,H15/N15) -> 10.078277 | R15: =IF(Q15=0,0,I15/N15) -> 12.124243
A16: 7 | B16: =IF('Entries June''25'!I14>='Entries June''25'!I13,'Entries June''25'!I14-'Entries June''25'!I13,(999999-'Entries June''25'!I13)+'Entries June''25'!I14+1) -> 2166 | C16: =IF('Entries June''25'!J14>='Entries June''25'!J13,'Entries June''25'!J14-'Entries June''25'!J13,(999999-'Entries June''25'!J13)+'Entries June''25'!J14+1) -> 2032 | D16: =B16+C16 -> 4198 | E16: =IF('Entries June''25'!K14>='Entries June''25'!K13,'Entries June''25'!K14-'Entries June''25'!K13,(999999-'Entries June''25'!K13)+'Entries June''25'!K14+1) -> 0 | F16: =D16+E16 -> 4198 | G16: ='Water '!Z13*10 -> 0 | H16: =IF('Entries June''25'!B14-'Entries June''25'!B13<1,"0",'Entries June''25'!B14-'Entries June''25'!B13) -> 300 | I16: ='CO2'!C13 -> 0 | J16: =+'PROD.FIG. '!F11 -> 0 | K16: =+'PROD.FIG. '!C11 -> 0 | L16: =+'PROD.FIG. '!D11 -> 0 | M16: =+'PROD.FIG. '!E11 -> 0 | N16: 0 | O16: =IF(N16=0,0,F16/N16) -> 0 | P16: =IF(O16=0,0,G16/N16) -> 0 | Q16: =IF(P16=0,0,H16/N16) -> 0 | R16: =IF(Q16=0,0,I16/N16) -> 0
A17: 8 | B17: =IF('Entries June''25'!I15>='Entries June''25'!I14,'Entries June''25'!I15-'Entries June''25'!I14,(999999-'Entries June''25'!I14)+'Entries June''25'!I15+1) -> 2794 | C17: =IF('Entries June''25'!J15>='Entries June''25'!J14,'Entries June''25'!J15-'Entries June''25'!J14,(999999-'Entries June''25'!J14)+'Entries June''25'!J15+1) -> 2571 | D17: =B17+C17 -> 5365 | E17: =IF('Entries June''25'!K15>='Entries June''25'!K14,'Entries June''25'!K15-'Entries June''25'!K14,(999999-'Entries June''25'!K14)+'Entries June''25'!K15+1) -> 0 | F17: =D17+E17 -> 5365 | G17: ='Water '!Z14*10 -> 880 | H17: =IF('Entries June''25'!B15-'Entries June''25'!B14<1,"0",'Entries June''25'!B15-'Entries June''25'!B14) -> 0 | I17: ='CO2'!C14 -> 0 | J17: =+'PROD.FIG. '!F12 -> 0 | K17: =+'PROD.FIG. '!C12 -> 0 | L17: =+'PROD.FIG. '!D12 -> 0 | M17: =+'PROD.FIG. '!E12 -> 0 | N17: 0 | O17: =IF(N17=0,0,F17/N17) -> 0 | P17: =IF(O17=0,0,G17/N17) -> 0 | Q17: =IF(P17=0,0,H17/N17) -> 0 | R17: =IF(Q17=0,0,I17/N17) -> 0
A18: 9 | B18: =IF('Entries June''25'!I16>='Entries June''25'!I15,'Entries June''25'!I16-'Entries June''25'!I15,(999999-'Entries June''25'!I15)+'Entries June''25'!I16+1) -> 2304 | C18: =IF('Entries June''25'!J16>='Entries June''25'!J15,'Entries June''25'!J16-'Entries June''25'!J15,(999999-'Entries June''25'!J15)+'Entries June''25'!J16+1) -> 2201 | D18: =B18+C18 -> 4505 | E18: =IF('Entries June''25'!K16>='Entries June''25'!K15,'Entries June''25'!K16-'Entries June''25'!K15,(999999-'Entries June''25'!K15)+'Entries June''25'!K16+1) -> 0 | F18: =D18+E18 -> 4505 | G18: ='Water '!Z15*10 -> 0 | H18: =IF('Entries June''25'!B16-'Entries June''25'!B15<1,"0",'Entries June''25'!B16-'Entries June''25'!B15) -> 830 | I18: ='CO2'!C15 -> 400 | J18: =+'PROD.FIG. '!F13 -> 0 | K18: =+'PROD.FIG. '!C13 -> 0 | L18: =+'PROD.FIG. '!D13 -> 0 | M18: =+'PROD.FIG. '!E13 -> 0 | N18: 0 | O18: =IF(N18=0,0,F18/N18) -> 0 | P18: =IF(O18=0,0,G18/N18) -> 0 | Q18: =IF(P18=0,0,H18/N18) -> 0 | R18: =IF(Q18=0,0,I18/N18) -> 0
A19: 10 | B19: =IF('Entries June''25'!I17>='Entries June''25'!I16,'Entries June''25'!I17-'Entries June''25'!I16,(999999-'Entries June''25'!I16)+'Entries June''25'!I17+1) -> 4219 | C19: =IF('Entries June''25'!J17>='Entries June''25'!J16,'Entries June''25'!J17-'Entries June''25'!J16,(999999-'Entries June''25'!J16)+'Entries June''25'!J17+1) -> 3969 | D19: =B19+C19 -> 8188 | E19: =IF('Entries June''25'!K17>='Entries June''25'!K16,'Entries June''25'!K17-'Entries June''25'!K16,(999999-'Entries June''25'!K16)+'Entries June''25'!K17+1) -> 0 | F19: =D19+E19 -> 8188 | G19: ='Water '!Z16*10 -> 3070 | H19: =IF('Entries June''25'!B17-'Entries June''25'!B16<1,"0",'Entries June''25'!B17-'Entries June''25'!B16) -> 2900 | I19: ='CO2'!C16 -> 1700 | J19: =+'PROD.FIG. '!F14 -> 0 | K19: =+'PROD.FIG. '!C14 -> 0 | L19: =+'PROD.FIG. '!D14 -> 0 | M19: =+'PROD.FIG. '!E14 -> 0 | N19: 418.11 | O19: =IF(N19=0,0,F19/N19) -> 19.583363 | P19: =IF(O19=0,0,G19/N19) -> 7.3425654 | Q19: =IF(P19=0,0,H19/N19) -> 6.9359738 | R19: =IF(Q19=0,0,I19/N19) -> 4.0659157
A20: 11 | B20: =IF('Entries June''25'!I18>='Entries June''25'!I17,'Entries June''25'!I18-'Entries June''25'!I17,(999999-'Entries June''25'!I17)+'Entries June''25'!I18+1) -> 4527 | C20: =IF('Entries June''25'!J18>='Entries June''25'!J17,'Entries June''25'!J18-'Entries June''25'!J17,(999999-'Entries June''25'!J17)+'Entries June''25'!J18+1) -> 4264 | D20: =B20+C20 -> 8791 | E20: =IF('Entries June''25'!K18>='Entries June''25'!K17,'Entries June''25'!K18-'Entries June''25'!K17,(999999-'Entries June''25'!K17)+'Entries June''25'!K18+1) -> 0 | F20: =D20+E20 -> 8791 | G20: ='Water '!Z17*10 -> 4760 | H20: =IF('Entries June''25'!B18-'Entries June''25'!B17<1,"0",'Entries June''25'!B18-'Entries June''25'!B17) -> 3400 | I20: ='CO2'!C17 -> 2300 | J20: =+'PROD.FIG. '!F15 -> 0 | K20: =+'PROD.FIG. '!C15 -> 0 | L20: =+'PROD.FIG. '!D15 -> 0 | M20: =+'PROD.FIG. '!E15 -> 0 | N20: 475.992 | O20: =IF(N20=0,0,F20/N20) -> 18.468798 | P20: =IF(O20=0,0,G20/N20) -> 10.000168 | Q20: =IF(P20=0,0,H20/N20) -> 7.1429772 | R20: =IF(Q20=0,0,I20/N20) -> 4.832014
A21: 12 | B21: =IF('Entries June''25'!I19>='Entries June''25'!I18,'Entries June''25'!I19-'Entries June''25'!I18,(999999-'Entries June''25'!I18)+'Entries June''25'!I19+1) -> 4360 | C21: =IF('Entries June''25'!J19>='Entries June''25'!J18,'Entries June''25'!J19-'Entries June''25'!J18,(999999-'Entries June''25'!J18)+'Entries June''25'!J19+1) -> 4103 | D21: =B21+C21 -> 8463 | E21: =IF('Entries June''25'!K19>='Entries June''25'!K18,'Entries June''25'!K19-'Entries June''25'!K18,(999999-'Entries June''25'!K18)+'Entries June''25'!K19+1) -> 0 | F21: =D21+E21 -> 8463 | G21: ='Water '!Z18*10 -> 2930 | H21: =IF('Entries June''25'!B19-'Entries June''25'!B18<1,"0",'Entries June''25'!B19-'Entries June''25'!B18) -> 2940 | I21: ='CO2'!C18 -> 2500 | J21: =+'PROD.FIG. '!F16 -> 0 | K21: =+'PROD.FIG. '!C16 -> 0 | L21: =+'PROD.FIG. '!D16 -> 0 | M21: =+'PROD.FIG. '!E16 -> 0 | N21: 339.834 | O21: =IF(N21=0,0,F21/N21) -> 24.903335 | P21: =IF(O21=0,0,G21/N21) -> 8.6218566 | Q21: =IF(P21=0,0,H21/N21) -> 8.6512827 | R21: =IF(Q21=0,0,I21/N21) -> 7.3565329
A22: 13 | B22: =IF('Entries June''25'!I20>='Entries June''25'!I19,'Entries June''25'!I20-'Entries June''25'!I19,(999999-'Entries June''25'!I19)+'Entries June''25'!I20+1) -> 4330 | C22: =IF('Entries June''25'!J20>='Entries June''25'!J19,'Entries June''25'!J20-'Entries June''25'!J19,(999999-'Entries June''25'!J19)+'Entries June''25'!J20+1) -> 4076 | D22: =B22+C22 -> 8406 | E22: =IF('Entries June''25'!K20>='Entries June''25'!K19,'Entries June''25'!K20-'Entries June''25'!K19,(999999-'Entries June''25'!K19)+'Entries June''25'!K20+1) -> 0 | F22: =D22+E22 -> 8406 | G22: ='Water '!Z19*10 -> 3460 | H22: =IF('Entries June''25'!B20-'Entries June''25'!B19<1,"0",'Entries June''25'!B20-'Entries June''25'!B19) -> 3020 | I22: ='CO2'!C19 -> 2500 | J22: =+'PROD.FIG. '!F17 -> 0 | K22: =+'PROD.FIG. '!C17 -> 0 | L22: =+'PROD.FIG. '!D17 -> 0 | M22: =+'PROD.FIG. '!E17 -> 0 | N22: 411.576 | O22: =IF(N22=0,0,F22/N22) -> 20.423931 | P22: =IF(O22=0,0,G22/N22) -> 8.4067098 | Q22: =IF(P22=0,0,H22/N22) -> 7.3376485 | R22: =IF(Q22=0,0,I22/N22) -> 6.0742123
... A39: 30 | B39: =IF('Entries June''25'!I37>='Entries June''25'!I36,'Entries June''25'!I37-'Entries June''25'!I36,(999999-'Entries June''25'!I36)+'Entries June''25'!I37+1) -> 4480 | C39: =IF('Entries June''25'!J37>='Entries June''25'!J36,'Entries June''25'!J37-'Entries June''25'!J36,(999999-'Entries June''25'!J36)+'Entries June''25'!J37+1) -> 4214 | D39: =B39+C39 -> 8694 | E39: =IF('Entries June''25'!K37>='Entries June''25'!K36,'Entries June''25'!K37-'Entries June''25'!K36,(999999-'Entries June''25'!K36)+'Entries June''25'!K37+1) -> 0 | F39: =D39+E39 -> 8694 | G39: ='Water '!Z36*10 -> 3240 | H39: =IF('Entries June''25'!B37-'Entries June''25'!B36<1,"0",'Entries June''25'!B37-'Entries June''25'!B36) -> 3330 | I39: ='CO2'!C36 -> 2000 | J39: =+'PROD.FIG. '!F34 -> 0 | K39: =+'PROD.FIG. '!C34 -> 0 | L39: =+'PROD.FIG. '!D34 -> 0 | M39: =+'PROD.FIG. '!E34 -> 0 | N39: 272.844 | O39: =IF(N39=0,0,F39/N39) -> 31.864362 | P39: =IF(O39=0,0,G39/N39) -> 11.874918 | Q39: =IF(P39=0,0,H39/N39) -> 12.204776 | R39: =IF(Q39=0,0,I39/N39) -> 7.330196
D40: =B40+C40 -> 0 | F40: =D40+E40 -> 0 | G40: ='Water '!Z37*10 -> 0 | H40: =IF('Entries June''25'!B38-'Entries June''25'!B37<1,"0",'Entries June''25'!B38-'Entries June''25'!B37) -> 0 | I40: ='CO2'!C37 -> 0 | N40: 0 | O40: =IF(N40=0,0,F40/N40) -> 0 | P40: =IF(O40=0,0,G40/N40) -> 0 | Q40: =IF(P40=0,0,H40/N40) -> 0 | R40: =IF(Q40=0,0,I40/N40) -> 0
O41: MTD
D42: Kwhr | E42: Kwhr | F42: Kwhr | G42: Hl | H42: L | I42: kg. | J42: hl | K42: hl | L42: hl | M42: hl | N42: hl | O42: Elect | P42: Water | Q42: Fuel | R42: CO2
A43: Total | D43: =SUM(D10:D40) -> 222055 | E43: =SUM(E10:E40) -> 0 | F43: =SUM(F10:F40) -> 222055 | G43: =SUM(G10:G40) -> 84890 | H43: =SUM(H10:H40) -> 69480 | I43: =SUM(I10:I40) -> 50700 | J43: =SUM(J10:J40) -> 0 | K43: =SUM(K10:K40) -> 0 | ... N43: =SUM(N10:N40) -> 8404.5408 | O43: KWH/Hl | P43: Hl/hl | Q43: Litres/hl | R43: kg./Hl
O44: =IF(N43=0,0,F43/N43) -> 26.420837 | P44: =IF(O44=0,0,G43/N43) -> 10.100492 | Q44: =IF(P44=0,0,H43/N43) -> 8.2669597 | R44: =IF(Q44=0,0,I43/N43) -> 6.0324533

Sheet Steam Mass Flow 
A3: DATE | B3: Steam Mass Flow Reading
A5: 1 | B5: =IF('Entries June''25'!AJ8-'Entries June''25'!AJ7<1,"0",'Entries June''25'!AJ8-'Entries June''25'!AJ7) -> 28.524
A6: 2 | B6: =IF('Entries June''25'!AJ9-'Entries June''25'!AJ8<1,"0",'Entries June''25'!AJ9-'Entries June''25'!AJ8) -> 0
A7: 3 | B7: =IF('Entries June''25'!AJ10-'Entries June''25'!AJ9<1,"0",'Entries June''25'!AJ10-'Entries June''25'!AJ9) -> 108.055
A8: 4 | B8: =IF('Entries June''25'!AJ11-'Entries June''25'!AJ10<1,"0",'Entries June''25'!AJ11-'Entries June''25'!AJ10) -> 3.818
A9: 5 | B9: =IF('Entries June''25'!AJ12-'Entries June''25'!AJ11<1,"0",'Entries June''25'!AJ12-'Entries June''25'!AJ11) -> 0
A10: 6 | B10: =IF('Entries June''25'!AJ13-'Entries June''25'!AJ12<1,"0",'Entries June''25'!AJ13-'Entries June''25'!AJ12) -> 0
A11: 7 | B11: =IF('Entries June''25'!AJ14-'Entries June''25'!AJ13<1,"0",'Entries June''25'!AJ14-'Entries June''25'!AJ13) -> 0
A12: 8 | B12: =IF('Entries June''25'!AJ15-'Entries June''25'!AJ14<1,"0",'Entries June''25'!AJ15-'Entries June''25'!AJ14) -> 0
A13: 9 | B13: =IF('Entries June''25'!AJ16-'Entries June''25'!AJ15<1,"0",'Entries June''25'!AJ16-'Entries June''25'!AJ15) -> 0
A14: 10 | B14: =IF('Entries June''25'!AJ17-'Entries June''25'!AJ16<1,"0",'Entries June''25'!AJ17-'Entries June''25'!AJ16) -> 2.894
A15: 11 | B15: =IF('Entries June''25'!AJ18-'Entries June''25'!AJ17<1,"0",'Entries June''25'!AJ18-'Entries June''25'!AJ17) -> 0
A16: 12 | B16: =IF('Entries June''25'!AJ19-'Entries June''25'!AJ18<1,"0",'Entries June''25'!AJ19-'Entries June''25'!AJ18) -> 0
... A34: 30 | B34: =IF('Entries June''25'!AJ37-'Entries June''25'!AJ36<1,"0",'Entries June''25'!AJ37-'Entries June''25'!AJ36) -> 1.232
B36: =SUM(B5:B35) -> 841.179

Sheet Fuel 
A1: DAILY FUEL CONSUMPTION FOR JUNE 2025
A4: DATE | B4: Boiler 1 | C4: Boiler 1 | D4: Boiler 2 | E4: Boiler 2 | F4: Gen. | G4: Gen | H4: Boiler 1 sp. | I4: Boiler 2 sp. | J4: Gen. sp | K4: Daily cons. | L4: Total Prod.(HL) | M4: Fuel(Litres/HL)
B5: Cons ( l ) | C5: Hrs | D5: Cons ( l ) | E5: Hrs | F5: Cons ( l ) | G5: Hrs | H5: cons (l/hr) | I5: cons (l/hr) | J5: Cons.(l/hr) | K5: (litres)
B6: =IF('Entries June''25'!B6=0,0,+'Entries June''25'!B6-'Entries June''25'!B5) -> 0
A7: 1 | B7: =IF('Entries June''25'!B8-'Entries June''25'!B7<1,"0",'Entries June''25'!B8-'Entries June''25'!B7) -> 730 | C7: =IF('Entries June''25'!F8-'Entries June''25'!F7<1,"0",'Entries June''25'!F8-'Entries June''25'!F7) -> 4.4 | D7: =IF('Entries June''25'!C7=0,0,+'Entries June''25'!C7-'Entries June''25'!C6) -> 0 | E7: =IF('Entries June''25'!G8-'Entries June''25'!G7<1,"0",'Entries June''25'!G8-'Entries June''25'!G7) -> 0 | H7: =IF(C7+E7=0,"0", B7/(C7+E7)) -> 165.90909 | I7: =IF(E7=0,"0", D7/E7) -> 0 | J7: =IF(G7=0,"0", F7/G7) -> 0 | K7: =B7+D7+F7 -> 730 | L7: {=IF(TRANSPOSE('Daily KPIs'!B9:AF9)=0,"0",TRANSPOSE('Daily KPIs'!B9:AF9))} -> 0 | M7: =IF(L7=0,"0",(K7/L7)) -> 0
A8: 2 | B8: =IF('Entries June''25'!B9-'Entries June''25'!B8<1,"0",'Entries June''25'!B9-'Entries June''25'!B8) -> 3280 | C8: =IF('Entries June''25'!F9-'Entries June''25'!F8<1,"0",'Entries June''25'!F9-'Entries June''25'!F8) -> 21.1 | D8: =IF('Entries June''25'!C8=0,0,+'Entries June''25'!C8-'Entries June''25'!C7) -> 0 | E8: =IF('Entries June''25'!G9-'Entries June''25'!G8<1,"0",'Entries June''25'!G9-'Entries June''25'!G8) -> 0 | H8: =IF(C8+E8=0,"0", B8/(C8+E8)) -> 155.45024 | I8: =IF(E8=0,"0", D8/E8) -> 0 | J8: =IF(G8=0,"0", F8/G8) -> 0 | K8: =B8+D8+F8 -> 3280 | L8: 455.6052 | M8: =IF(L8=0,"0",(K8/L8)) -> 7.1992155
A9: 3 | B9: =IF('Entries June''25'!B10-'Entries June''25'!B9<1,"0",'Entries June''25'!B10-'Entries June''25'!B9) -> 3380 | C9: =IF('Entries June''25'!F10-'Entries June''25'!F9<1,"0",'Entries June''25'!F10-'Entries June''25'!F9) -> 21.1 | D9: =IF('Entries June''25'!C9=0,0,+'Entries June''25'!C9-'Entries June''25'!C8) -> 0 | E9: =IF('Entries June''25'!G10-'Entries June''25'!G9<1,"0",'Entries June''25'!G10-'Entries June''25'!G9) -> 0 | H9: =IF(C9+E9=0,"0", B9/(C9+E9)) -> 160.18957 | I9: =IF(E9=0,"0", D9/E9) -> 0 | J9: =IF(G9=0,"0", F9/G9) -> 0 | K9: =B9+D9+F9 -> 3380 | L9: 644.754 | M9: =IF(L9=0,"0",(K9/L9)) -> 5.2423095
A10: 4 | B10: =IF('Entries June''25'!B11-'Entries June''25'!B10<1,"0",'Entries June''25'!B11-'Entries June''25'!B10) -> 3130 | C10: =IF('Entries June''25'!F11-'Entries June''25'!F10<1,"0",'Entries June''25'!F11-'Entries June''25'!F10) -> 20.2 | D10: =IF('Entries June''25'!C12=0,0,+'Entries June''25'!C12-'Entries June''25'!C9) -> 0 | E10: =IF('Entries June''25'!G11-'Entries June''25'!G10<1,"0",'Entries June''25'!G11-'Entries June''25'!G10) -> 0 | H10: =IF(C10+E10=0,"0", B10/(C10+E10)) -> 154.9505 | I10: =IF(E10=0,"0", D10/E10) -> 0 | J10: =IF(G10=0,"0", F10/G10) -> 0 | K10: =B10+D10+F10 -> 3130 | L10: 398.442 | M10: =IF(L10=0,"0",(K10/L10)) -> 7.8555976
A11: 5 | B11: =IF('Entries June''25'!B12-'Entries June''25'!B11<1,"0",'Entries June''25'!B12-'Entries June''25'!B11) -> 3510 | C11: =IF('Entries June''25'!F12-'Entries June''25'!F11<1,"0",'Entries June''25'!F12-'Entries June''25'!F11) -> 21.9 | D11: =IF('Entries June''25'!C11=0,0,+'Entries June''25'!C11-'Entries June''25'!C12) -> 0 | E11: =IF('Entries June''25'!G12-'Entries June''25'!G11<1,"0",'Entries June''25'!G12-'Entries June''25'!G11) -> 0 | H11: =IF(C11+E11=0,"0", B11/(C11+E11)) -> 160.27397 | I11: =IF(E11=0,"0", D11/E11) -> 0 | J11: =IF(G11=0,"0", F11/G11) -> 0 | K11: =B11+D11+F11 -> 3510 | L11: 496.584 | M11: =IF(L11=0,"0",(K11/L11)) -> 7.0682906
A12: 6 | B12: =IF('Entries June''25'!B13-'Entries June''25'!B12<1,"0",'Entries June''25'!B13-'Entries June''25'!B12) -> 2660 | C12: =IF('Entries June''25'!F13-'Entries June''25'!F12<1,"0",'Entries June''25'!F13-'Entries June''25'!F12) -> 18.3 | D12: =IF('Entries June''25'!C13=0,0,+'Entries June''25'!C13-'Entries June''25'!C11) -> 0 | E12: =IF('Entries June''25'!G13-'Entries June''25'!G12<1,"0",'Entries June''25'!G13-'Entries June''25'!G12) -> 0 | H12: =IF(C12+E12=0,"0", B12/(C12+E12)) -> 145.35519 | I12: =IF(E12=0,"0", D12/E12) -> 0 | J12: =IF(G12=0,"0", F12/G12) -> 0 | K12: =B12+D12+F12 -> 2660 | L12: 263.934 | M12: =IF(L12=0,"0",(K12/L12)) -> 10.078277
A13: 7 | B13: =IF('Entries June''25'!B14-'Entries June''25'!B13<1,"0",'Entries June''25'!B14-'Entries June''25'!B13) -> 300 | C13: =IF('Entries June''25'!F14-'Entries June''25'!F13<1,"0",'Entries June''25'!F14-'Entries June''25'!F13) -> 2.1 | D13: =IF('Entries June''25'!C14=0,0,+'Entries June''25'!C14-'Entries June''25'!C12) -> 0 | E13: =IF('Entries June''25'!G14-'Entries June''25'!G13<1,"0",'Entries June''25'!G14-'Entries June''25'!G13) -> 0 | H13: =IF(C13+E13=0,"0", B13/(C13+E13)) -> 142.85714 | I13: =IF(E13=0,"0", D13/E13) -> 0 | J13: =IF(G13=0,"0", F13/G13) -> 0 | K13: =B13+D13+F13 -> 300 | L13: 0 | M13: =IF(L13=0,"0",(K13/L13)) -> 0
A14: 8 | B14: =IF('Entries June''25'!B15-'Entries June''25'!B14<1,"0",'Entries June''25'!B15-'Entries June''25'!B14) -> 0 | C14: =IF('Entries June''25'!F15-'Entries June''25'!F14<1,"0",'Entries June''25'!F15-'Entries June''25'!F14) -> 0 | D14: =IF('Entries June''25'!C14=0,0,+'Entries June''25'!C14-'Entries June''25'!#REF!) -> 0 | E14: =IF('Entries June''25'!G15-'Entries June''25'!G14<1,"0",'Entries June''25'!G15-'Entries June''25'!G14) -> 0 | H14: =IF(C14+E14=0,"0", B14/(C14+E14)) -> 0 | I14: =IF(E14=0,"0", D14/E14) -> 0 | J14: =IF(G14=0,"0", F14/G14) -> 0 | K14: =B14+D14+F14 -> 0 | L14: 0 | M14: =IF(L14=0,"0",(K14/L14)) -> 0
A15: 9 | B15: =IF('Entries June''25'!B16-'Entries June''25'!B15<1,"0",'Entries June''25'!B16-'Entries June''25'!B15) -> 830 | C15: =IF('Entries June''25'!F16-'Entries June''25'!F15<1,"0",'Entries June''25'!F16-'Entries June''25'!F15) -> 5 | D15: =IF('Entries June''25'!C15=0,0,+'Entries June''25'!C15-'Entries June''25'!C14) -> 0 | E15: =IF('Entries June''25'!G16-'Entries June''25'!G15<1,"0",'Entries June''25'!G16-'Entries June''25'!G15) -> 0 | H15: =IF(C15+E15=0,"0", B15/(C15+E15)) -> 166 | I15: =IF(E15=0,"0", D15/E15) -> 0 | J15: =IF(G15=0,"0", F15/G15) -> 0 | K15: =B15+D15+F15 -> 830 | L15: 0 | M15: =IF(L15=0,"0",(K15/L15)) -> 0
A16: 10 | B16: =IF('Entries June''25'!B17-'Entries June''25'!B16<1,"0",'Entries June''25'!B17-'Entries June''25'!B16) -> 2900 | C16: =IF('Entries June''25'!F17-'Entries June''25'!F16<1,"0",'Entries June''25'!F17-'Entries June''25'!F16) -> 19.1 | D16: =IF('Entries June''25'!C16=0,0,+'Entries June''25'!C16-'Entries June''25'!C15) -> 0 | E16: =IF('Entries June''25'!G17-'Entries June''25'!G16<1,"0",'Entries June''25'!G17-'Entries June''25'!G16) -> 0 | H16: =IF(C16+E16=0,"0", B16/(C16+E16)) -> 151.83246 | I16: =IF(E16=0,"0", D16/E16) -> 0 | J16: =IF(G16=0,"0", F16/G16) -> 0 | K16: =B16+D16+F16 -> 2900 | L16: 418.11 | M16: =IF(L16=0,"0",(K16/L16)) -> 6.9359738
A17: 11 | B17: =IF('Entries June''25'!B18-'Entries June''25'!B17<1,"0",'Entries June''25'!B18-'Entries June''25'!B17) -> 3400 | C17: =IF('Entries June''25'!F18-'Entries June''25'!F17<1,"0",'Entries June''25'!F18-'Entries June''25'!F17) -> 21.5 | D17: =IF('Entries June''25'!C17=0,0,+'Entries June''25'!C17-'Entries June''25'!C16) -> 0 | E17: =IF('Entries June''25'!G18-'Entries June''25'!G17<1,"0",'Entries June''25'!G18-'Entries June''25'!G17) -> 0 | H17: =IF(C17+E17=0,"0", B17/(C17+E17)) -> 158.13953 | I17: =IF(E17=0,"0", D17/E17) -> 0 | J17: =IF(G17=0,"0", F17/G17) -> 0 | K17: =B17+D17+F17 -> 3400 | L17: 475.992 | M17: =IF(L17=0,"0",(K17/L17)) -> 7.1429772
A18: 12 | B18: =IF('Entries June''25'!B19-'Entries June''25'!B18<1,"0",'Entries June''25'!B19-'Entries June''25'!B18) -> 2940 | C18: =IF('Entries June''25'!F19-'Entries June''25'!F18<1,"0",'Entries June''25'!F19-'Entries June''25'!F18) -> 19.4 | D18: =IF('Entries June''25'!C18=0,0,+'Entries June''25'!C18-'Entries June''25'!C17) -> 0 | E18: =IF('Entries June''25'!G19-'Entries June''25'!G18<1,"0",'Entries June''25'!G19-'Entries June''25'!G18) -> 0 | H18: =IF(C18+E18=0,"0", B18/(C18+E18)) -> 151.54639 | I18: =IF(E18=0,"0", D18/E18) -> 0 | J18: =IF(G18=0,"0", F18/G18) -> 0 | K18: =B18+D18+F18 -> 2940 | L18: 339.834 | M18: =IF(L18=0,"0",(K18/L18)) -> 8.6512827
A19: 13 | B19: =IF('Entries June''25'!B20-'Entries June''25'!B19<1,"0",'Entries June''25'!B20-'Entries June''25'!B19) -> 3020 | C19: =IF('Entries June''25'!F20-'Entries June''25'!F19<1,"0",'Entries June''25'!F20-'Entries June''25'!F19) -> 19 | D19: =IF('Entries June''25'!C19=0,0,+'Entries June''25'!C19-'Entries June''25'!C18) -> 0 | E19: =IF('Entries June''25'!G20-'Entries June''25'!G19<1,"0",'Entries June''25'!G20-'Entries June''25'!G19) -> 0 | H19: =IF(C19+E19=0,"0", B19/(C19+E19)) -> 158.94737 | I19: =IF(E19=0,"0", D19/E19) -> 0 | J19: =IF(G19=0,"0", F19/G19) -> 0 | K19: =B19+D19+F19 -> 3020 | L19: 411.576 | M19: =IF(L19=0,"0",(K19/L19)) -> 7.3376485
A20: 14 | B20: =IF('Entries June''25'!B21-'Entries June''25'!B20<1,"0",'Entries June''25'!B21-'Entries June''25'!B20) -> 1020 | C20: =IF('Entries June''25'!F21-'Entries June''25'!F20<1,"0",'Entries June''25'!F21-'Entries June''25'!F20) -> 9.7 | D20: =IF('Entries June''25'!C20=0,0,+'Entries June''25'!C20-'Entries June''25'!C19) -> 0 | E20: =IF('Entries June''25'!G21-'Entries June''25'!G20<1,"0",'Entries June''25'!G21-'Entries June''25'!G20) -> 0 | H20: =IF(C20+E20=0,"0", B20/(C20+E20)) -> 105.15464 | I20: =IF(E20=0,"0", D20/E20) -> 0 | J20: =IF(G20=0,"0", F20/G20) -> 0 | K20: =B20+D20+F20 -> 1020 | L20: 0 | M20: =IF(L20=0,"0",(K20/L20)) -> 0
A21: 15 | B21: =IF('Entries June''25'!B22-'Entries June''25'!B21<1,"0",'Entries June''25'!B22-'Entries June''25'!B21) -> 690 | C21: =IF('Entries June''25'!F22-'Entries June''25'!F21<1,"0",'Entries June''25'!F22-'Entries June''25'!F21) -> 3.8 | D21: =IF('Entries June''25'!C21=0,0,+'Entries June''25'!C21-'Entries June''25'!C20) -> 0 | E21: =IF('Entries June''25'!G22-'Entries June''25'!G21<1,"0",'Entries June''25'!G22-'Entries June''25'!G21) -> 0 | H21: =IF(C21+E21=0,"0", B21/(C21+E21)) -> 181.57895 | I21: =IF(E21=0,"0", D21/E21) -> 0 | J21: =IF(G21=0,"0", F21/G21) -> 0 | K21: =B21+D21+F21 -> 690 | L21: 0 | M21: =IF(L21=0,"0",(K21/L21)) -> 0
A22: 16 | B22: =IF('Entries June''25'!B23-'Entries June''25'!B22<1,"0",'Entries June''25'!B23-'Entries June''25'!B22) -> 3680 | C22: =IF('Entries June''25'!F23-'Entries June''25'!F22<1,"0",'Entries June''25'!F23-'Entries June''25'!F22) -> 22.3 | D22: =IF('Entries June''25'!C22=0,0,+'Entries June''25'!C22-'Entries June''25'!C21) -> 0 | E22: =IF('Entries June''25'!G23-'Entries June''25'!G22<1,"0",'Entries June''25'!G23-'Entries June''25'!G22) -> 0 | H22: =IF(C22+E22=0,"0", B22/(C22+E22)) -> 165.02242 | I22: =IF(E22=0,"0", D22/E22) -> 0 | J22: =IF(G22=0,"0", F22/G22) -> 0 | K22: =B22+D22+F22 -> 3680 | L22: 400.62 | M22: =IF(L22=0,"0",(K22/L22)) -> 9.1857621
A23: 17 | B23: =IF('Entries June''25'!B24-'Entries June''25'!B23<1,"0",'Entries June''25'!B24-'Entries June''25'!B23) -> 3620 | C23: =IF('Entries June''25'!F24-'Entries June''25'!F23<1,"0",'Entries June''25'!F24-'Entries June''25'!F23) -> 21.7 | D23: =IF('Entries June''25'!C23=0,0,+'Entries June''25'!C23-'Entries June''25'!C22) -> 0 | E23: =IF('Entries June''25'!G24-'Entries June''25'!G23<1,"0",'Entries June''25'!G24-'Entries June''25'!G23) -> 0 | H23: =IF(C23+E23=0,"0", B23/(C23+E23)) -> 166.82028 | I23: =IF(E23=0,"0", D23/E23) -> 0 | J23: =IF(G23=0,"0", F23/G23) -> 0 | K23: =B23+D23+F23 -> 3620 | L23: 550.242 | M23: =IF(L23=0,"0",(K23/L23)) -> 6.5789235
A24: 18 | B24: =IF('Entries June''25'!B25-'Entries June''25'!B24<1,"0",'Entries June''25'!B25-'Entries June''25'!B24) -> 3050 | C24: =IF('Entries June''25'!F25-'Entries June''25'!F24<1,"0",'Entries June''25'!F25-'Entries June''25'!F24) -> 19.7 | D24: =IF('Entries June''25'!C24=0,0,+'Entries June''25'!C24-'Entries June''25'!C23) -> 0 | E24: =IF('Entries June''25'!G25-'Entries June''25'!G24<1,"0",'Entries June''25'!G25-'Entries June''25'!G24) -> 0 | H24: =IF(C24+E24=0,"0", B24/(C24+E24)) -> 154.82234 | I24: =IF(E24=0,"0", D24/E24) -> 0 | J24: =IF(G24=0,"0", F24/G24) -> 0 | K24: =B24+D24+F24 -> 3050 | L24: 446.5428 | M24: =IF(L24=0,"0",(K24/L24)) -> 6.8302523
A25: 19 | B25: =IF('Entries June''25'!B26-'Entries June''25'!B25<1,"0",'Entries June''25'!B26-'Entries June''25'!B25) -> 700 | C25: =IF('Entries June''25'!F26-'Entries June''25'!F25<1,"0",'Entries June''25'!F26-'Entries June''25'!F25) -> 4.6 | D25: =IF('Entries June''25'!C25=0,0,+'Entries June''25'!C25-'Entries June''25'!C24) -> 0 | E25: =IF('Entries June''25'!G26-'Entries June''25'!G25<1,"0",'Entries June''25'!G26-'Entries June''25'!G25) -> 0 | H25: =IF(C25+E25=0,"0", B25/(C25+E25)) -> 152.17391 | I25: =IF(E25=0,"0", D25/E25) -> 0 | J25: =IF(G25=0,"0", F25/G25) -> 0 | K25: =B25+D25+F25 -> 700 | L25: 0 | M25: =IF(L25=0,"0",(K25/L25)) -> 0
A26: 20 | B26: =IF('Entries June''25'!B27-'Entries June''25'!B26<1,"0",'Entries June''25'!B27-'Entries June''25'!B26) -> 2320 | C26: =IF('Entries June''25'!F27-'Entries June''25'!F26<1,"0",'Entries June''25'!F27-'Entries June''25'!F26) -> 16.4 | D26: =IF('Entries June''25'!C26=0,0,+'Entries June''25'!C26-'Entries June''25'!C25) -> 0 | E26: =IF('Entries June''25'!G27-'Entries June''25'!G26<1,"0",'Entries June''25'!G27-'Entries June''25'!G26) -> 0 | H26: =IF(C26+E26=0,"0", B26/(C26+E26)) -> 141.46341 | I26: =IF(E26=0,"0", D26/E26) -> 0 | J26: =IF(G26=0,"0", F26/G26) -> 0 | K26: =B26+D26+F26 -> 2320 | L26: 365.0208 | M26: =IF(L26=0,"0",(K26/L26)) -> 6.3558022
A27: 21 | B27: =IF('Entries June''25'!B28-'Entries June''25'!B27<1,"0",'Entries June''25'!B28-'Entries June''25'!B27) -> 270 | C27: =IF('Entries June''25'!F28-'Entries June''25'!F27<1,"0",'Entries June''25'!F28-'Entries June''25'!F27) -> 2.1 | D27: =IF('Entries June''25'!C27=0,0,+'Entries June''25'!C27-'Entries June''25'!C26) -> 0 | E27: =IF('Entries June''25'!G28-'Entries June''25'!G27<1,"0",'Entries June''25'!G28-'Entries June''25'!G27) -> 0 | H27: =IF(C27+E27=0,"0", B27/(C27+E27)) -> 128.57143 | I27: =IF(E27=0,"0", D27/E27) -> 0 | J27: =IF(G27=0,"0", F27/G27) -> 0 | K27: =B27+D27+F27 -> 270 | L27: 0 | M27: =IF(L27=0,"0",(K27/L27)) -> 0
A28: 22 | B28: =IF('Entries June''25'!B29-'Entries June''25'!B28<1,"0",'Entries June''25'!B29-'Entries June''25'!B28) -> 0 | C28: =IF('Entries June''25'!F29-'Entries June''25'!F28<1,"0",'Entries June''25'!F29-'Entries June''25'!F28) -> 0 | D28: =IF('Entries June''25'!C28=0,0,+'Entries June''25'!C28-'Entries June''25'!C27) -> 0 | E28: =IF('Entries June''25'!G29-'Entries June''25'!G28<1,"0",'Entries June''25'!G29-'Entries June''25'!G28) -> 0 | H28: =IF(C28+E28=0,"0", B28/(C28+E28)) -> 0 | I28: =IF(E28=0,"0", D28/E28) -> 0 | J28: =IF(G28=0,"0", F28/G28) -> 0 | K28: =B28+D28+F28 -> 0 | L28: 0 | M28: =IF(L28=0,"0",(K28/L28)) -> 0
A29: 23 | B29: =IF('Entries June''25'!B30-'Entries June''25'!B29<1,"0",'Entries June''25'!B30-'Entries June''25'!B29) -> 3250 | C29: =IF('Entries June''25'!F30-'Entries June''25'!F29<1,"0",'Entries June''25'!F30-'Entries June''25'!F29) -> 22.7 | D29: =IF('Entries June''25'!C29=0,0,+'Entries June''25'!C29-'Entries June''25'!C28) -> 0 | E29: =IF('Entries June''25'!G30-'Entries June''25'!G29<1,"0",'Entries June''25'!G30-'Entries June''25'!G29) -> 0 | H29: =IF(C29+E29=0,"0", B29/(C29+E29)) -> 143.17181 | I29: =IF(E29=0,"0", D29/E29) -> 0 | J29: =IF(G29=0,"0", F29/G29) -> 0 | K29: =B29+D29+F29 -> 3250 | L29: 475.86 | M29: =IF(L29=0,"0",(K29/L29)) -> 6.8297398
A30: 24 | B30: =IF('Entries June''25'!B31-'Entries June''25'!B30<1,"0",'Entries June''25'!B31-'Entries June''25'!B30) -> 3520 | C30: =IF('Entries June''25'!F31-'Entries June''25'!F30<1,"0",'Entries June''25'!F31-'Entries June''25'!F30) -> 21.4 | D30: =IF('Entries June''25'!C30=0,0,+'Entries June''25'!C30-'Entries June''25'!C29) -> 0 | E30: =IF('Entries June''25'!G31-'Entries June''25'!G30<1,"0",'Entries June''25'!G31-'Entries June''25'!G30) -> 0 | H30: =IF(C30+E30=0,"0", B30/(C30+E30)) -> 164.48598 | I30: =IF(E30=0,"0", D30/E30) -> 0 | J30: =IF(G30=0,"0", F30/G30) -> 0 | K30: =B30+D30+F30 -> 3520 | L30: 367.752 | M30: =IF(L30=0,"0",(K30/L30)) -> 9.5716679
A31: 25 | B31: =IF('Entries June''25'!B32-'Entries June''25'!B31<1,"0",'Entries June''25'!B32-'Entries June''25'!B31) -> 3930 | C31: =IF('Entries June''25'!F32-'Entries June''25'!F31<1,"0",'Entries June''25'!F32-'Entries June''25'!F31) -> 22 | D31: =IF('Entries June''25'!C31=0,0,+'Entries June''25'!C31-'Entries June''25'!C30) -> 0 | E31: =IF('Entries June''25'!G32-'Entries June''25'!G31<1,"0",'Entries June''25'!G32-'Entries June''25'!G31) -> 0 | H31: =IF(C31+E31=0,"0", B31/(C31+E31)) -> 178.63636 | I31: =IF(E31=0,"0", D31/E31) -> 0 | J31: =IF(G31=0,"0", F31/G31) -> 0 | K31: =B31+D31+F31 -> 3930 | L31: 663.3 | M31: =IF(L31=0,"0",(K31/L31)) -> 5.9249209
A32: 26 | B32: =IF('Entries June''25'!B33-'Entries June''25'!B32<1,"0",'Entries June''25'!B33-'Entries June''25'!B32) -> 3420 | C32: =IF('Entries June''25'!F33-'Entries June''25'!F32<1,"0",'Entries June''25'!F33-'Entries June''25'!F32) -> 21.4 | D32: =IF('Entries June''25'!C32=0,0,+'Entries June''25'!C32-'Entries June''25'!C31) -> 0 | E32: =IF('Entries June''25'!G33-'Entries June''25'!G32<1,"0",'Entries June''25'!G33-'Entries June''25'!G32) -> 0 | H32: =IF(C32+E32=0,"0", B32/(C32+E32)) -> 159.81308 | I32: =IF(E32=0,"0", D32/E32) -> 0 | J32: =IF(G32=0,"0", F32/G32) -> 0 | K32: =B32+D32+F32 -> 3420 | L32: 526.284 | M32: =IF(L32=0,"0",(K32/L32)) -> 6.4983925
A33: 27 | B33: =IF('Entries June''25'!B34-'Entries June''25'!B33<1,"0",'Entries June''25'!B34-'Entries June''25'!B33) -> 3240 | C33: =IF('Entries June''25'!F34-'Entries June''25'!F33<1,"0",'Entries June''25'!F34-'Entries June''25'!F33) -> 21 | D33: =IF('Entries June''25'!C33=0,0,+'Entries June''25'!C33-'Entries June''25'!C32) -> 0 | E33: =IF('Entries June''25'!G34-'Entries June''25'!G33<1,"0",'Entries June''25'!G34-'Entries June''25'!G33) -> 0 | H33: =IF(C33+E33=0,"0", B33/(C33+E33)) -> 154.28571 | I33: =IF(E33=0,"0", D33/E33) -> 0 | J33: =IF(G33=0,"0", F33/G33) -> 0 | K33: =B33+D33+F33 -> 3240 | L33: 402.204 | M33: =IF(L33=0,"0",(K33/L33)) -> 8.0556136
A34: 28 | B34: =IF('Entries June''25'!B35-'Entries June''25'!B34<1,"0",'Entries June''25'!B35-'Entries June''25'!B34) -> 1880 | C34: =IF('Entries June''25'!F35-'Entries June''25'!F34<1,"0",'Entries June''25'!F35-'Entries June''25'!F34) -> 17.8 | D34: =IF('Entries June''25'!C34=0,0,+'Entries June''25'!C34-'Entries June''25'!C33) -> 0 | E34: =IF('Entries June''25'!G35-'Entries June''25'!G34<1,"0",'Entries June''25'!G35-'Entries June''25'!G34) -> 0 | H34: =IF(C34+E34=0,"0", B34/(C34+E34)) -> 105.61798 | I34: =IF(E34=0,"0", D34/E34) -> 0 | J34: =IF(G34=0,"0", F34/G34) -> 0 | K34: =B34+D34+F34 -> 1880 | L34: 0 | M34: =IF(L34=0,"0",(K34/L34)) -> 0
A35: 29 | B35: =IF('Entries June''25'!B36-'Entries June''25'!B35<1,"0",'Entries June''25'!B36-'Entries June''25'!B35) -> 1480 | C35: =IF('Entries June''25'!F36-'Entries June''25'!F35<1,"0",'Entries June''25'!F36-'Entries June''25'!F35) -> 10.2 | E35: =IF('Entries June''25'!G36-'Entries June''25'!G35<1,"0",'Entries June''25'!G36-'Entries June''25'!G35) -> 0 | H35: =IF(C35+E35=0,"0", B35/(C35+E35)) -> 145.09804 | I35: =IF(E35=0,"0", D35/E35) -> 0 | J35: =IF(G35=0,"0", F35/G35) -> 0 | K35: =B35+D35+F35 -> 1480 | L35: 29.04 | M35: =IF(L35=0,"0",(K35/L35)) -> 50.964187
A36: 30 | B36: =IF('Entries June''25'!B37-'Entries June''25'!B36<1,"0",'Entries June''25'!B37-'Entries June''25'!B36) -> 3330 | C36: =IF('Entries June''25'!F37-'Entries June''25'!F36<1,"0",'Entries June''25'!F37-'Entries June''25'!F36) -> 22 | E36: =IF('Entries June''25'!G37-'Entries June''25'!G36<1,"0",'Entries June''25'!G37-'Entries June''25'!G36) -> 0 | H36: =IF(C36+E36=0,"0", B36/(C36+E36)) -> 151.36364 | I36: =IF(E36=0,"0", D36/E36) -> 0 | J36: =IF(G36=0,"0", F36/G36) -> 0 | K36: =B36+D36+F36 -> 3330 | L36: 272.844 | M36: =IF(L36=0,"0",(K36/L36)) -> 12.204776
B37: =IF('Entries June''25'!B38-'Entries June''25'!B37<1,"0",'Entries June''25'!B38-'Entries June''25'!B37) -> 0 | C37: =IF('Entries June''25'!F38-'Entries June''25'!F37<1,"0",'Entries June''25'!F38-'Entries June''25'!F37) -> 0 | E37: =IF('Entries June''25'!G38-'Entries June''25'!G37<1,"0",'Entries June''25'!G38-'Entries June''25'!G37) -> 0 | H37: =IF(C37+E37=0,"0", B37/(C37+E37)) -> 0 | I37: =IF(E37=0,"0", D37/E37) -> 0 | J37: =IF(G37=0,"0", F37/G37) -> 0 | K37: =B37+D37+F37 -> 0 | L37: 0
A38: MTD | B38: =SUM(B7:B37) -> 69480 | C38: =SUM(C7:C37) -> 451.9 | D38: =SUM(D7:D34) -> 0 | E38: =SUM(E7:E34) -> 0 | H38: =IF(C38+E38=0,"0", B38/(C38+E38)) -> 153.75083 | K38: =SUM(K7:K37) -> 69480 | L38: =SUM(L7:L37) -> 8404.5408 | M38: =IF(L38=0,"0",(K38/L38)) -> 8.2669597 | N38: 7.2 | O38: =M38/N38*100 -> 114.81888
A39: AVE. | B39: =AVERAGE(B7:B37) -> 2481.4286 | C39: =AVERAGE(C7:C37) -> 16.139286 | H39: cons (l/hr)

Sheet Water 
B4: DATE | C4: Well Supply (m3) | D4: Nawasa Supply (m3) | E4: Annanale Supply (m3) | F4: RO Water Plant Nawasa (m3) | G4: Service Water Received (m3) | H4: Service Water Supply to Plant (m3) | I4: CO2 Scrubber (m3) | J4: Brewhouse / Old Pepsi Area (m3) | K4: Filtration/Cellars (m3) | L4: Cellars/Process Area (m3) | M4: Pasteuriser (m3) | R4: Permeate Produced (m3) | S4: Plant Cons. USAGE (Hl.) | U4: Bottle Filler (m3) | X4: Rus (m3) | Y4: Washdown Area (m3) | Z4: TOTAL SUPPLY (M3) | AA4: Total Prod.(HL) | AB4: Water KPI (Hl/Hl)
N5: CIP Process (m3) | O5: Bottles Washer (m3) | P5: Bottles Filler (m3) | Q5: Boiler Supply (m3) | T5: ∑ Service Water to Processes | V5: Water into RO #1 (m3) | W5: Water into RO #2 (m3)
B6: -
B7: 1 | C7: =IF('Entries June''25'!W8-'Entries June''25'!W7<1,"0",'Entries June''25'!W8-'Entries June''25'!W7) -> 0 | D7: =IF('Entries June''25'!O8-'Entries June''25'!O7<1,"0",'Entries June''25'!O8-'Entries June''25'!O7) -> 0 | E7: =IF('Entries June''25'!P8-'Entries June''25'!P7<1,"0",'Entries June''25'!P8-'Entries June''25'!P7) -> 71 | F7: =IF('Entries June''25'!V8-'Entries June''25'!V7<1,"0",'Entries June''25'!V8-'Entries June''25'!V7) -> 72 | G7: =(D7+E7)-F7 -> -1 | H7: =IF('Entries June''25'!Q8-'Entries June''25'!Q7<1,0,'Entries June''25'!Q8-'Entries June''25'!Q7) -> 12 | I7: =IF('Entries June''25'!AG8-'Entries June''25'!AG7<1,0,'Entries June''25'!AG8-'Entries June''25'!AG7) -> 0 | J7: =IF('Entries June''25'!S8-'Entries June''25'!S7<1,"0",'Entries June''25'!S8-'Entries June''25'!S7) -> 0 | K7: =IF('Entries June''25'!R8-'Entries June''25'!R7<1,"0",'Entries June''25'!R8-'Entries June''25'!R7) -> 0 | L7: =IF('Entries June''25'!T8-'Entries June''25'!T7<1,"0",'Entries June''25'!T8-'Entries June''25'!T7) -> 0 | M7: =IF('Entries June''25'!U8-'Entries June''25'!U7<1,"0",'Entries June''25'!U8-'Entries June''25'!U7) -> 0 | N7: =IF('Entries June''25'!X8-'Entries June''25'!X7<1,"0",'Entries June''25'!X8-'Entries June''25'!X7) -> 0 | O7: =IF('Entries June''25'!Y8-'Entries June''25'!Y7<1,"0",'Entries June''25'!Y8-'Entries June''25'!Y7) -> 27 | P7: =IF('Entries June''25'!AC8-'Entries June''25'!AC7<1,"0",'Entries June''25'!AC8-'Entries June''25'!AC7) -> 0 | Q7: =IF('Entries June''25'!Z8-'Entries June''25'!Z7<1,"0",'Entries June''25'!Z8-'Entries June''25'!Z7) -> 1 | R7: =IF(('Entries June''25'!AA8-'Entries June''25'!AA7)+('Entries June''25'!AB8-'Entries June''25'!AB7)<1,"0",('Entries June''25'!AA8-'Entries June''25'!AA7)+('Entries June''25'!AB8-'Entries June''25'!AB7)) -> 0 | S7: =(R7+G7)*10 -> -10 | T7: =O7+N7+M7+L7 -> 27 | U7: =IF('Entries June''25'!AC8-'Entries June''25'!AC7<1,"0",'Entries June''25'!AC8-'Entries June''25'!AC7) -> 0 | V7: =IF('Entries June''25'!AD8-'Entries June''25'!AD7<1,"0",'Entries June''25'!AD8-'Entries June''25'!AD7) -> 0 | W7: =IF('Entries June''25'!AE8-'Entries June''25'!AE7<1,"0",'Entries June''25'!AE8-'Entries June''25'!AE7) -> 0 | X7: =IF('Entries June''25'!AI8-'Entries June''25'!AI7<1,"0",'Entries June''25'!AI8-'Entries June''25'!AI7) -> 0 | Y7: =IF('Entries June''25'!AH8-'Entries June''25'!AH7<1,"0",'Entries June''25'!AH8-'Entries June''25'!AH7) -> 0 | Z7: =C7+D7+E7 -> 71 | AA7: {=IF(TRANSPOSE('Daily KPIs'!B9:AF9)=0,"0",TRANSPOSE('Daily KPIs'!B9:AF9))} -> 0 | AB7: =IF(AA7=0,"0",(Z7*10/AA7)) -> 0
B8: 2 | C8: =IF('Entries June''25'!W9-'Entries June''25'!W8<1,"0",'Entries June''25'!W9-'Entries June''25'!W8) -> 0 | D8: =IF('Entries June''25'!O9-'Entries June''25'!O8<1,"0",'Entries June''25'!O9-'Entries June''25'!O8) -> 267 | E8: =IF('Entries June''25'!P9-'Entries June''25'!P8<1,"0",'Entries June''25'!P9-'Entries June''25'!P8) -> 188 | F8: =IF('Entries June''25'!V9-'Entries June''25'!V8<1,"0",'Entries June''25'!V9-'Entries June''25'!V8) -> 200 | G8: =(D8+E8)-F8 -> 255 | H8: =IF('Entries June''25'!Q9-'Entries June''25'!Q8<1,0,'Entries June''25'!Q9-'Entries June''25'!Q8) -> 335 | I8: =IF('Entries June''25'!AG9-'Entries June''25'!AG8<1,0,'Entries June''25'!AG9-'Entries June''25'!AG8) -> 0 | J8: =IF('Entries June''25'!S9-'Entries June''25'!S8<1,"0",'Entries June''25'!S9-'Entries June''25'!S8) -> 113 | K8: =IF('Entries June''25'!R9-'Entries June''25'!R8<1,"0",'Entries June''25'!R9-'Entries June''25'!R8) -> 0 | L8: =IF('Entries June''25'!T9-'Entries June''25'!T8<1,"0",'Entries June''25'!T9-'Entries June''25'!T8) -> 0 | M8: =IF('Entries June''25'!U9-'Entries June''25'!U8<1,"0",'Entries June''25'!U9-'Entries June''25'!U8) -> 19 | N8: =IF('Entries June''25'!X9-'Entries June''25'!X8<1,"0",'Entries June''25'!X9-'Entries June''25'!X8) -> 85 | O8: =IF('Entries June''25'!Y9-'Entries June''25'!Y8<1,"0",'Entries June''25'!Y9-'Entries June''25'!Y8) -> 113 | P8: =IF('Entries June''25'!AC9-'Entries June''25'!AC8<1,"0",'Entries June''25'!AC9-'Entries June''25'!AC8) -> 0 | Q8: =IF('Entries June''25'!Z9-'Entries June''25'!Z8<1,"0",'Entries June''25'!Z9-'Entries June''25'!Z8) -> 25 | R8: =IF(('Entries June''25'!AA9-'Entries June''25'!AA8)+('Entries June''25'!AB9-'Entries June''25'!AB8)<1,"0",('Entries June''25'!AA9-'Entries June''25'!AA8)+('Entries June''25'!AB9-'Entries June''25'!AB8)) -> 0 | S8: =(R8+G8)*10 -> 2550 | T8: =O8+N8+M8+L8 -> 217 | U8: =IF('Entries June''25'!AC9-'Entries June''25'!AC8<1,"0",'Entries June''25'!AC9-'Entries June''25'!AC8) -> 0 | V8: =IF('Entries June''25'!AD9-'Entries June''25'!AD8<1,"0",'Entries June''25'!AD9-'Entries June''25'!AD8) -> 0 | W8: =IF('Entries June''25'!AE9-'Entries June''25'!AE8<1,"0",'Entries June''25'!AE9-'Entries June''25'!AE8) -> 0 | X8: =IF('Entries June''25'!AI9-'Entries June''25'!AI8<1,"0",'Entries June''25'!AI9-'Entries June''25'!AI8) -> 0 | Y8: =IF('Entries June''25'!AH9-'Entries June''25'!AH8<1,"0",'Entries June''25'!AH9-'Entries June''25'!AH8) -> 0 | Z8: =C8+D8+E8 -> 455 | AA8: 455.6052 | AB8: =IF(AA8=0,"0",(Z8*10/AA8)) -> 9.9867166
B9: 3 | C9: =IF('Entries June''25'!W10-'Entries June''25'!W9<1,"0",'Entries June''25'!W10-'Entries June''25'!W9) -> 0 | D9: =IF('Entries June''25'!O10-'Entries June''25'!O9<1,"0",'Entries June''25'!O10-'Entries June''25'!O9) -> 288 | E9: =IF('Entries June''25'!P10-'Entries June''25'!P9<1,"0",'Entries June''25'!P10-'Entries June''25'!P9) -> 132 | F9: =IF('Entries June''25'!V10-'Entries June''25'!V9<1,"0",'Entries June''25'!V10-'Entries June''25'!V9) -> 139 | G9: =(D9+E9)-F9 -> 281 | H9: =IF('Entries June''25'!Q10-'Entries June''25'!Q9<1,0,'Entries June''25'!Q10-'Entries June''25'!Q9) -> 294 | I9: =IF('Entries June''25'!AG10-'Entries June''25'!AG9<1,0,'Entries June''25'!AG10-'Entries June''25'!AG9) -> 0 | J9: =IF('Entries June''25'!S10-'Entries June''25'!S9<1,"0",'Entries June''25'!S10-'Entries June''25'!S9) -> 130 | K9: =IF('Entries June''25'!R10-'Entries June''25'!R9<1,"0",'Entries June''25'!R10-'Entries June''25'!R9) -> 0 | L9: =IF('Entries June''25'!T10-'Entries June''25'!T9<1,"0",'Entries June''25'!T10-'Entries June''25'!T9) -> 0 | M9: =IF('Entries June''25'!U10-'Entries June''25'!U9<1,"0",'Entries June''25'!U10-'Entries June''25'!U9) -> 0 | N9: =IF('Entries June''25'!X10-'Entries June''25'!X9<1,"0",'Entries June''25'!X10-'Entries June''25'!X9) -> 51 | O9: =IF('Entries June''25'!Y10-'Entries June''25'!Y9<1,"0",'Entries June''25'!Y10-'Entries June''25'!Y9) -> 158 | P9: =IF('Entries June''25'!AC10-'Entries June''25'!AC9<1,"0",'Entries June''25'!AC10-'Entries June''25'!AC9) -> 42 | Q9: =IF('Entries June''25'!Z10-'Entries June''25'!Z9<1,"0",'Entries June''25'!Z10-'Entries June''25'!Z9) -> 20 | R9: =IF(('Entries June''25'!AA10-'Entries June''25'!AA9)+('Entries June''25'!AB10-'Entries June''25'!AB9)<1,"0",('Entries June''25'!AA10-'Entries June''25'!AA9)+('Entries June''25'!AB10-'Entries June''25'!AB9)) -> 0 | S9: =(R9+G9)*10 -> 2810 | T9: =O9+N9+M9+L9 -> 209 | U9: =IF('Entries June''25'!AC10-'Entries June''25'!AC9<1,"0",'Entries June''25'!AC10-'Entries June''25'!AC9) -> 42 | V9: =IF('Entries June''25'!AD10-'Entries June''25'!AD9<1,"0",'Entries June''25'!AD10-'Entries June''25'!AD9) -> 0 | W9: =IF('Entries June''25'!AE10-'Entries June''25'!AE9<1,"0",'Entries June''25'!AE10-'Entries June''25'!AE9) -> 0 | X9: =IF('Entries June''25'!AI10-'Entries June''25'!AI9<1,"0",'Entries June''25'!AI10-'Entries June''25'!AI9) -> 0 | Y9: =IF('Entries June''25'!AH10-'Entries June''25'!AH9<1,"0",'Entries June''25'!AH10-'Entries June''25'!AH9) -> 0 | Z9: =C9+D9+E9 -> 420 | AA9: 644.754 | AB9: =IF(AA9=0,"0",(Z9*10/AA9)) -> 6.5141124
B10: 4 | C10: =IF('Entries June''25'!W11-'Entries June''25'!W10<1,"0",'Entries June''25'!W11-'Entries June''25'!W10) -> 0 | D10: =IF('Entries June''25'!O11-'Entries June''25'!O10<1,"0",'Entries June''25'!O11-'Entries June''25'!O10) -> 198 | E10: =IF('Entries June''25'!P11-'Entries June''25'!P10<1,"0",'Entries June''25'!P11-'Entries June''25'!P10) -> 171 | F10: =IF('Entries June''25'!V11-'Entries June''25'!V10<1,"0",'Entries June''25'!V11-'Entries June''25'!V10) -> 181 | G10: =(D10+E10)-F10 -> 188 | H10: =IF('Entries June''25'!Q11-'Entries June''25'!Q10<1,0,'Entries June''25'!Q11-'Entries June''25'!Q10) -> 228 | I10: =IF('Entries June''25'!AG11-'Entries June''25'!AG10<1,0,'Entries June''25'!AG11-'Entries June''25'!AG10) -> 0 | J10: =IF('Entries June''25'!S11-'Entries June''25'!S10<1,"0",'Entries June''25'!S11-'Entries June''25'!S10) -> 173 | K10: =IF('Entries June''25'!R11-'Entries June''25'!R10<1,"0",'Entries June''25'!R11-'Entries June''25'!R10) -> 0 | L10: =IF('Entries June''25'!T11-'Entries June''25'!T10<1,"0",'Entries June''25'!T11-'Entries June''25'!T10) -> 0 | M10: =IF('Entries June''25'!U11-'Entries June''25'!U10<1,"0",'Entries June''25'!U11-'Entries June''25'!U10) -> 0 | N10: =IF('Entries June''25'!X11-'Entries June''25'!X10<1,"0",'Entries June''25'!X11-'Entries June''25'!X10) -> 31 | O10: =IF('Entries June''25'!Y11-'Entries June''25'!Y10<1,"0",'Entries June''25'!Y11-'Entries June''25'!Y10) -> 113 | P10: =IF('Entries June''25'!AC11-'Entries June''25'!AC10<1,"0",'Entries June''25'!AC11-'Entries June''25'!AC10) -> 22 | Q10: =IF('Entries June''25'!Z11-'Entries June''25'!Z10<1,"0",'Entries June''25'!Z11-'Entries June''25'!Z10) -> 16 | R10: =IF(('Entries June''25'!AA11-'Entries June''25'!AA10)+('Entries June''25'!AB11-'Entries June''25'!AB10)<1,"0",('Entries June''25'!AA11-'Entries June''25'!AA10)+('Entries June''25'!AB11-'Entries June''25'!AB10)) -> 0 | S10: =(R10+G10)*10 -> 1880 | T10: =O10+N10+M10+L10 -> 144 | U10: =IF('Entries June''25'!AC11-'Entries June''25'!AC10<1,"0",'Entries June''25'!AC11-'Entries June''25'!AC10) -> 22 | V10: =IF('Entries June''25'!AD11-'Entries June''25'!AD10<1,"0",'Entries June''25'!AD11-'Entries June''25'!AD10) -> 0 | W10: =IF('Entries June''25'!AE11-'Entries June''25'!AE10<1,"0",'Entries June''25'!AE11-'Entries June''25'!AE10) -> 0 | X10: =IF('Entries June''25'!AI11-'Entries June''25'!AI10<1,"0",'Entries June''25'!AI11-'Entries June''25'!AI10) -> 0 | Y10: =IF('Entries June''25'!AH11-'Entries June''25'!AH10<1,"0",'Entries June''25'!AH11-'Entries June''25'!AH10) -> 0 | Z10: =C10+D10+E10 -> 369 | AA10: 398.442 | AB10: =IF(AA10=0,"0",(Z10*10/AA10)) -> 9.2610719
B11: 5 | C11: =IF('Entries June''25'!W12-'Entries June''25'!W11<1,"0",'Entries June''25'!W12-'Entries June''25'!W11) -> 0 | D11: =IF('Entries June''25'!O12-'Entries June''25'!O11<1,"0",'Entries June''25'!O12-'Entries June''25'!O11) -> 141 | E11: =IF('Entries June''25'!P12-'Entries June''25'!P11<1,"0",'Entries June''25'!P12-'Entries June''25'!P11) -> 262 | F11: =IF('Entries June''25'!V12-'Entries June''25'!V11<1,"0",'Entries June''25'!V12-'Entries June''25'!V11) -> 276 | G11: =(D11+E11)-F11 -> 127 | H11: =IF('Entries June''25'!Q12-'Entries June''25'!Q11<1,0,'Entries June''25'!Q12-'Entries June''25'!Q11) -> 305 | I11: =IF('Entries June''25'!AG12-'Entries June''25'!AG11<1,0,'Entries June''25'!AG12-'Entries June''25'!AG11) -> 0 | J11: =IF('Entries June''25'!S12-'Entries June''25'!S11<1,"0",'Entries June''25'!S12-'Entries June''25'!S11) -> 222 | K11: =IF('Entries June''25'!R12-'Entries June''25'!R11<1,"0",'Entries June''25'!R12-'Entries June''25'!R11) -> 0 | L11: =IF('Entries June''25'!T12-'Entries June''25'!T11<1,"0",'Entries June''25'!T12-'Entries June''25'!T11) -> 0 | M11: =IF('Entries June''25'!U12-'Entries June''25'!U11<1,"0",'Entries June''25'!U12-'Entries June''25'!U11) -> 8 | N11: =IF('Entries June''25'!X12-'Entries June''25'!X11<1,"0",'Entries June''25'!X12-'Entries June''25'!X11) -> 56 | O11: =IF('Entries June''25'!Y12-'Entries June''25'!Y11<1,"0",'Entries June''25'!Y12-'Entries June''25'!Y11) -> 150 | P11: =IF('Entries June''25'!AC12-'Entries June''25'!AC11<1,"0",'Entries June''25'!AC12-'Entries June''25'!AC11) -> 23 | Q11: =IF('Entries June''25'!Z12-'Entries June''25'!Z11<1,"0",'Entries June''25'!Z12-'Entries June''25'!Z11) -> 20 | R11: =IF(('Entries June''25'!AA12-'Entries June''25'!AA11)+('Entries June''25'!AB12-'Entries June''25'!AB11)<1,"0",('Entries June''25'!AA12-'Entries June''25'!AA11)+('Entries June''25'!AB12-'Entries June''25'!AB11)) -> 0 | S11: =(R11+G11)*10 -> 1270 | T11: =O11+N11+M11+L11 -> 214 | U11: =IF('Entries June''25'!AC12-'Entries June''25'!AC11<1,"0",'Entries June''25'!AC12-'Entries June''25'!AC11) -> 23 | V11: =IF('Entries June''25'!AD12-'Entries June''25'!AD11<1,"0",'Entries June''25'!AD12-'Entries June''25'!AD11) -> 16 | W11: =IF('Entries June''25'!AE12-'Entries June''25'!AE11<1,"0",'Entries June''25'!AE12-'Entries June''25'!AE11) -> 0 | X11: =IF('Entries June''25'!AI12-'Entries June''25'!AI11<1,"0",'Entries June''25'!AI12-'Entries June''25'!AI11) -> 0 | Y11: =IF('Entries June''25'!AH12-'Entries June''25'!AH11<1,"0",'Entries June''25'!AH12-'Entries June''25'!AH11) -> 0 | Z11: =C11+D11+E11 -> 403 | AA11: 496.584 | AB11: =IF(AA11=0,"0",(Z11*10/AA11)) -> 8.1154447
