Workbook
Name ProductList: [1]November15!$R$3:$R$9
Name ProductList: [2]November15!$R$3:$R$9

Sheet Dec 18th
T1: P.G. | V1: Hot Time | X1: Process Time | Z1: Cooling Time
B2: Brewing Department Daily Process Loss Report | T2: Lower | U2: Upper | V2: Lower | W2: Upper | X2: Lower | Y2: Upper | Z2: Lower | AA2: Upper
S3: CARIB | T3: 11.6 | U3: 12 | V3: 0 | W3: 0.11805556 | X3: 0.17361111 | Y3: 0.21180556 | Z3: 0 | AA3: 60 | AC3: HR- PISNER
B4: Date: | C4: 45278 | J4: LOT WORT COLOUR: 3.4 | M4: Filter Sheets (Target 20 days) | S4: STAG | T4: 11.6 | U4: 12 | V4: 0 | W4: 0.11805556 | X4: 0.17361111 | Y4: 0.21180556 | Z4: 0 | AA4: 60
M5: Double | N5: Single | S5: GUINNESS | T5: 17 | U5: 17.5 | V5: 0 | W5: 0.10763889 | X5: 0.19444444 | Y5: 0.23263889 | Z5: 0 | AA5: 60
J6: MALT LOT: Lot 8 | L6: Sheet Day | S6: MACKESON | T6: 13.3 | U6: 13.5 | V6: 0 | W6: 0.12905093 | X6: 0.22222222 | Y6: 0.25347222 | Z6: 0
S7: STARMALT | T7: 17.1 | U7: 17.5 | V7: 0 | W7: 0.13605324 | X7: 0.20833333 | Y7: 0.24305556 | Z7: 0 | AA7: 60
B8: Brand | C8: Brew no. | D8: Kett. Hls | E8: Wort | F8: Cool Time(Mins) | G8: Cast. P.G. (Lab Result) | H8: Cast P.G. (Cellar Operator)-gravity | I8: Extr. Rec (79.1%) | J8: Theor. Extr. (77.5%) | K8: Boil Off /Vol. (4-6%) | L8: Boil Time | M8: Total Hot | N8: Brewing | P8: Comments | Q8: Actual Pilsen Malt | S8: Hurricane Reef | T8: 16.6 | U8: 17 | V8: 0 | W8: 0.12905093 | X8: 0.22222222 | Y8: 0.25347222 | Z8: 0
E9: Meter (Hls) | F9: Target(< 60Mins) | M9: Time | S9: VITAMALT | T9: 14.4 | U9: 14.6 | V9: 0 | W9: 0.13905093 | X9: 0.19097222 | Y9: 0.22569444 | Z9: 0 | AA9: 75
S10: =B10 -> 0 | T10: =VLOOKUP($B10,$S$3:$Y$9,2,FALSE) -> #N/A | U10: =VLOOKUP($B10,$S$3:$Y$9,3,FALSE) -> #N/A | V10: =VLOOKUP($B10,$S$3:$Y$9,4,FALSE) -> #N/A | W10: =VLOOKUP($B10,$S$3:$Y$9,5,FALSE) -> #N/A | X10: =VLOOKUP($B10,$S$3:$Y$9,6,FALSE) -> #N/A | Y10: =VLOOKUP($B10,$S$3:$Y$9,7,FALSE) -> #N/A | Z10: =VLOOKUP($B10,$S$3:$AA$9,8,FALSE) -> #N/A | AA10: =VLOOKUP($B10,$S$3:$AA$9,9,FALSE) -> #N/A
S11: =B11 -> 0 | T11: =VLOOKUP($B11,$S$3:$Y$9,2,FALSE) -> #N/A | U11: =VLOOKUP($B11,$S$3:$Y$9,3,FALSE) -> #N/A | V11: =VLOOKUP($B11,$S$3:$Y$9,4,FALSE) -> #N/A | W11: =VLOOKUP($B11,$S$3:$Y$9,5,FALSE) -> #N/A | X11: =VLOOKUP($B11,$S$3:$Y$9,6,FALSE) -> #N/A | Y11: =VLOOKUP($B11,$S$3:$Y$9,7,FALSE) -> #N/A | Z11: =VLOOKUP($B11,$S$3:$AA$9,8,FALSE) -> #N/A | AA11: =VLOOKUP($B11,$S$3:$AA$9,9,FALSE) -> #N/A
S12: =B12 -> 0 | T12: =VLOOKUP($B12,$S$3:$Y$9,2,FALSE) -> #N/A | U12: =VLOOKUP($B12,$S$3:$Y$9,3,FALSE) -> #N/A | V12: =VLOOKUP($B12,$S$3:$Y$9,4,FALSE) -> #N/A | W12: =VLOOKUP($B12,$S$3:$Y$9,5,FALSE) -> #N/A | X12: =VLOOKUP($B12,$S$3:$Y$9,6,FALSE) -> #N/A | Y12: =VLOOKUP($B12,$S$3:$Y$9,7,FALSE) -> #N/A | Z12: =VLOOKUP($B12,$S$3:$AA$9,8,FALSE) -> #N/A | AA12: =VLOOKUP($B12,$S$3:$AA$9,9,FALSE) -> #N/A
S13: =B13 -> 0 | T13: =VLOOKUP($B13,$S$3:$Y$9,2,FALSE) -> #N/A | U13: =VLOOKUP($B13,$S$3:$Y$9,3,FALSE) -> #N/A | V13: =VLOOKUP($B13,$S$3:$Y$9,4,FALSE) -> #N/A | W13: =VLOOKUP($B13,$S$3:$Y$9,5,FALSE) -> #N/A | X13: =VLOOKUP($B13,$S$3:$Y$9,6,FALSE) -> #N/A | Y13: =VLOOKUP($B13,$S$3:$Y$9,7,FALSE) -> #N/A | Z13: =VLOOKUP($B13,$S$3:$AA$9,8,FALSE) -> #N/A | AA13: =VLOOKUP($B13,$S$3:$AA$9,9,FALSE) -> #N/A
S14: =B14 -> 0 | T14: =VLOOKUP($B14,$S$3:$Y$9,2,FALSE) -> #N/A | U14: =VLOOKUP($B14,$S$3:$Y$9,3,FALSE) -> #N/A | V14: =VLOOKUP($B14,$S$3:$Y$9,4,FALSE) -> #N/A | W14: =VLOOKUP($B14,$S$3:$Y$9,5,FALSE) -> #N/A | X14: =VLOOKUP($B14,$S$3:$Y$9,6,FALSE) -> #N/A | Y14: =VLOOKUP($B14,$S$3:$Y$9,7,FALSE) -> #N/A | Z14: =VLOOKUP($B14,$S$3:$AA$9,8,FALSE) -> #N/A | AA14: =VLOOKUP($B14,$S$3:$AA$9,9,FALSE) -> #N/A
S15: =B15 -> 0 | T15: =VLOOKUP($B15,$S$3:$Y$9,2,FALSE) -> #N/A | U15: =VLOOKUP($B15,$S$3:$Y$9,3,FALSE) -> #N/A | V15: =VLOOKUP($B15,$S$3:$Y$9,4,FALSE) -> #N/A | W15: =VLOOKUP($B15,$S$3:$Y$9,5,FALSE) -> #N/A | X15: =VLOOKUP($B15,$S$3:$Y$9,6,FALSE) -> #N/A | Y15: =VLOOKUP($B15,$S$3:$Y$9,7,FALSE) -> #N/A | Z15: =VLOOKUP($B15,$S$3:$AA$9,8,FALSE) -> #N/A | AA15: =VLOOKUP($B15,$S$3:$AA$9,9,FALSE) -> #N/A
S16: =B16 -> 0 | T16: =VLOOKUP($B16,$S$3:$Y$9,2,FALSE) -> #N/A | U16: =VLOOKUP($B16,$S$3:$Y$9,3,FALSE) -> #N/A | V16: =VLOOKUP($B16,$S$3:$Y$9,4,FALSE) -> #N/A | W16: =VLOOKUP($B16,$S$3:$Y$9,5,FALSE) -> #N/A | X16: =VLOOKUP($B16,$S$3:$Y$9,6,FALSE) -> #N/A | Y16: =VLOOKUP($B16,$S$3:$Y$9,7,FALSE) -> #N/A | Z16: =VLOOKUP($B16,$S$3:$AA$9,8,FALSE) -> #N/A | AA16: =VLOOKUP($B16,$S$3:$AA$9,9,FALSE) -> #N/A
S17: =B17 -> 0 | T17: =VLOOKUP($B17,$S$3:$Y$9,2,FALSE) -> #N/A | U17: =VLOOKUP($B17,$S$3:$Y$9,3,FALSE) -> #N/A | V17: =VLOOKUP($B17,$S$3:$Y$9,4,FALSE) -> #N/A | W17: =VLOOKUP($B17,$S$3:$Y$9,5,FALSE) -> #N/A | X17: =VLOOKUP($B17,$S$3:$Y$9,6,FALSE) -> #N/A | Y17: =VLOOKUP($B17,$S$3:$Y$9,7,FALSE) -> #N/A | Z17: =VLOOKUP($B17,$S$3:$AA$9,8,FALSE) -> #N/A | AA17: =VLOOKUP($B17,$S$3:$AA$9,9,FALSE) -> #N/A
S18: =B18 -> 0 | T18: =VLOOKUP($B18,$S$3:$Y$9,2,FALSE) -> #N/A | U18: =VLOOKUP($B18,$S$3:$Y$9,3,FALSE) -> #N/A | V18: =VLOOKUP($B18,$S$3:$Y$9,4,FALSE) -> #N/A | W18: =VLOOKUP($B18,$S$3:$Y$9,5,FALSE) -> #N/A | X18: =VLOOKUP($B18,$S$3:$Y$9,6,FALSE) -> #N/A | Y18: =VLOOKUP($B18,$S$3:$Y$9,7,FALSE) -> #N/A | Z18: =VLOOKUP($B18,$S$3:$AA$9,8,FALSE) -> #N/A | AA18: =VLOOKUP($B18,$S$3:$AA$9,9,FALSE) -> #N/A
S19: =B19 -> 0 | T19: =VLOOKUP($B19,$S$3:$Y$9,2,FALSE) -> #N/A | U19: =VLOOKUP($B19,$S$3:$Y$9,3,FALSE) -> #N/A | V19: =VLOOKUP($B19,$S$3:$Y$9,4,FALSE) -> #N/A | W19: =VLOOKUP($B19,$S$3:$Y$9,5,FALSE) -> #N/A | X19: =VLOOKUP($B19,$S$3:$Y$9,6,FALSE) -> #N/A | Y19: =VLOOKUP($B19,$S$3:$Y$9,7,FALSE) -> #N/A | Z19: =VLOOKUP($B19,$S$3:$AA$9,8,FALSE) -> #N/A | AA19: =VLOOKUP($B19,$S$3:$AA$9,9,FALSE) -> #N/A
S20: =B20 -> 0 | T20: =VLOOKUP($B20,$S$3:$Y$9,2,FALSE) -> #N/A | U20: =VLOOKUP($B20,$S$3:$Y$9,3,FALSE) -> #N/A | V20: =VLOOKUP($B20,$S$3:$Y$9,4,FALSE) -> #N/A | W20: =VLOOKUP($B20,$S$3:$Y$9,5,FALSE) -> #N/A | X20: =VLOOKUP($B20,$S$3:$Y$9,6,FALSE) -> #N/A | Y20: =VLOOKUP($B20,$S$3:$Y$9,7,FALSE) -> #N/A | Z20: =VLOOKUP($B20,$S$3:$AA$9,8,FALSE) -> #N/A | AA20: =VLOOKUP($B20,$S$3:$AA$9,9,FALSE) -> #N/A
S21: =B21 -> 0 | T21: =VLOOKUP($B21,$S$3:$Y$9,2,FALSE) -> #N/A | U21: =VLOOKUP($B21,$S$3:$Y$9,3,FALSE) -> #N/A | V21: =VLOOKUP($B21,$S$3:$Y$9,4,FALSE) -> #N/A | W21: =VLOOKUP($B21,$S$3:$Y$9,5,FALSE) -> #N/A | X21: =VLOOKUP($B21,$S$3:$Y$9,6,FALSE) -> #N/A | Y21: =VLOOKUP($B21,$S$3:$Y$9,7,FALSE) -> #N/A | Z21: =VLOOKUP($B21,$S$3:$AA$9,8,FALSE) -> #N/A | AA21: =VLOOKUP($B21,$S$3:$AA$9,9,FALSE) -> #N/A
... S47: =B47 -> 0 | T47: =VLOOKUP($B47,$S$3:$Y$9,2,FALSE) -> #N/A | U47: =VLOOKUP($B47,$S$3:$Y$9,3,FALSE) -> #N/A | V47: =VLOOKUP($B47,$S$3:$Y$9,4,FALSE) -> #N/A | W47: =VLOOKUP($B47,$S$3:$Y$9,5,FALSE) -> #N/A | X47: =VLOOKUP($B47,$S$3:$Y$9,6,FALSE) -> #N/A | Y47: =VLOOKUP($B47,$S$3:$Y$9,7,FALSE) -> #N/A | Z47: =VLOOKUP($B47,$S$3:$AA$9,8,FALSE) -> #N/A | AA47: =VLOOKUP($B47,$S$3:$AA$9,9,FALSE) -> #N/A
I48: EXTRACT RECOVERY
B49: BRAND | D49: BBT P.G./ O.G | I49: Brand | J49: Actual | K49: MTD No. of Brews | L49: MTD | M49: YTD | N49: Target
B50: STAG | C50: 11.8 | D50: 11.73 | I50: CARIB | K50: =COUNTA([3]Brewhouse!$A$1596:$A$1619) -> 24 | L50: =AVERAGE([3]Brewhouse!$AU$1529,[3]Brewhouse!$AU$1531:$AU$1594,[3]Brewhouse!$AU$1596:$AU$1619) -> 98.205761 | M50: =AVERAGE([3]Brewhouse!$AU$849:$AU$924,[3]Brewhouse!$AU$926:$AU$971,[3]Brewhouse!$AU$973:$AU$1066,[3]Brewhouse!$AU$1068:$AU$1111,[3]Brewhouse!$AU$1113:$AU$1132,[3]Brewhouse!$AU$1134:$AU$1167,[3]Brewhouse!$AU$1169:$AU$1230,[3]Brewhouse!$AU$1232:$AU$1299,[3]Brewhouse!$AU$1301:$AU$1363,[3]Brewhouse!$AU$1365:$AU$1444,[3]Brewhouse!$AU$1446:$AU$1527,[3]Brewhouse!$AU$1529,[3]Brewhouse!$AU$1531:$AU$1594,[3]Brewhouse!$AU$1596:$AU$1619) -> 98.381806 | N50: 98
C51: 11.9 | I51: STAG | K51: =COUNTA([4]Brewhouse!$A$976:$A$1007) -> 32 | L51: =AVERAGE([4]Brewhouse!$AS$976:$AS$979,[4]Brewhouse!$AS$981:$AS$1007) -> 98.538567 | M51: =AVERAGE([4]Brewhouse!$AS$577:$AS$618,[4]Brewhouse!$AS$620:$AS$651,[4]Brewhouse!$AS$653:$AS$696,[4]Brewhouse!$AS$698:$AS$708,[4]Brewhouse!$AS$710:$AS$733,[4]Brewhouse!$AS$735:$AS$777,[4]Brewhouse!$AS$779:$AS$822,[4]Brewhouse!$AS$824:$AS$863,[4]Brewhouse!$AS$865:$AS$974,[4]Brewhouse!$AS$976:$AS$979,[4]Brewhouse!$AS$981:$AS$1007) -> 98.489671 | N51: 98
I52: GUINNESS | K52: =COUNTA([5]Brewhouse!$A$282:$A$289) -> 8 | L52: =AVERAGE([5]Brewhouse!$AU$269:$AU$279,[5]Brewhouse!$AU$282:$AU$289) -> 96.186177 | M52: =AVERAGE([5]Brewhouse!$AU$161:$AU$176,[5]Brewhouse!$AU$178:$AU$195,[5]Brewhouse!$AU$197:$AU$208,[5]Brewhouse!$AU$210:$AU$221,[5]Brewhouse!$AU$223:$AU$232,[5]Brewhouse!$AU$234:$AU$279,[5]Brewhouse!$AU$282:$AU$289) -> 96.64916 | N52: 98
I53: VITAMALT | K53: =COUNTA([6]Brewhouse!$A$158:$A$163) -> 6 | L53: =AVERAGE([6]Brewhouse!$AU$158:$AU$163) -> 94.60305 | M53: =AVERAGE([6]Brewhouse!$AU$91:$AU$101,[6]Brewhouse!$AU$103:$AU$112,[6]Brewhouse!$AU$114:$AU$123,[6]Brewhouse!$AU$125:$AU$134,[6]Brewhouse!$AU$136:$AU$145,[6]Brewhouse!$AU$147:$AU$156,[6]Brewhouse!$AU$158:$AU$163) -> 96.240014 | N53: 98
I54: MAXIMALT | N54: 98
I55: MACKESON | M55: =AVERAGE([7]Brewhouse!$AT$74:$AT$79) -> 93.959836 | N55: 98
I56: STARMALT | K56: =COUNTA([8]Brewhouse!$A$249:$A$254) -> 6 | L56: =AVERAGE([8]Brewhouse!$AY$249:$AY$254) -> 99.681996 | M56: =AVERAGE([8]Brewhouse!$AY$138:$AY$143,[8]Brewhouse!$AY$145:$AY$153,[8]Brewhouse!$AY$155,[8]Brewhouse!$AY$156:$AY$174,[8]Brewhouse!$AY$176:$AY$185,[8]Brewhouse!$AY$187:$AY$198,[8]Brewhouse!$AY$200:$AY$247,[8]Brewhouse!$AY$249:$AY$254) -> 98.774703 | N56: 98
I57: HR- P | M57: =AVERAGE([9]Brewhouse!$AW$13:$AW$14,[9]Brewhouse!$AW$16:$AW$17) -> 92.042628 | N57: 98
I58: Hurricane Reef | M58: =AVERAGE([9]Brewhouse!$AW$13:$AW$14) -> 88.376943 | N58: 98
K59: =SUM(K50:K58) -> 76 | L59: =((L50*K50)+(L51*K51)+(L52*K52)+(L53*K53)+(L54*K54)+(K57*L57)+(L55*K55)+(L56*K56)+(L58*K58))/(K59) -> 97.965422 | M59: =AVERAGE('[10]Closing- January 2023'!$L$42,'[11]Feb. 28th'!$L$42,'[12]March 31st'!$L$75,'[13]Apri 28th'!$L$51,L59) -> 98.06926 | N59: 98
J62: Daily Brewing Plan
J63: Brand | K63: Brews Achieved | L63: Average Brews per day
J64: CARIB | L64: MTD | M64: YTD | N64: TARGET
J65: STAG | K65: 5 | L65: =AVERAGE(#REF!,#REF!,K74,#REF!,#REF!,#REF!,#REF!,#REF!,#REF!,#REF!,#REF!) -> #REF! | M65: =AVERAGE(6,6,'[12]March 31st'!$L$80,'[14]June 30th '!$L$71,6,L65,'[15]July 31st'!$L$108,'[16]Aug 30th'!$L$124,7,[17]Oct.31st!$L$51) -> #REF! | N65: 9
J66: GUINN
J67: VITAMALT
...

Sheet June 2nd
S1: P.G. | U1: Hot Time | W1: Process Time | Y1: Cooling Time
B2: Brewing Department Daily Process Loss Report | S2: Lower | T2: Upper | U2: Lower | V2: Upper | W2: Lower | X2: Upper | Y2: Lower | Z2: Upper
R3: CARIB | S3: 11.6 | T3: 12 | U3: 0 | V3: 0.11805556 | W3: 0.22569444 | X3: 0.26388889 | Y3: 0 | Z3: 60 | AB3: HR- PISNER
B4: Date: | C4: 45811 | J4: LOT WORT COLOUR: 3.6 | M4: Filter Sheets (Target 20 days) | R4: STAG | S4: 11.6 | T4: 12 | U4: 0 | V4: 0.11805556 | W4: 0.22569444 | X4: 0.26388889 | Y4: 0 | Z4: 60
M5: Double | N5: Single | R5: GUINNESS | S5: 17 | T5: 17.5 | U5: 0 | V5: 0.10763889 | W5: 0.24652778 | X5: 0.28472222 | Y5: 0 | Z5: 60
J6: MALT LOT: Lot 37 | L6: Sheet Day | R6: MACKESON | S6: 13.3 | T6: 13.5 | U6: 0 | V6: 0.12905093 | W6: 0.27430556 | X6: 0.30208333 | Y6: 0
R7: STARMALT | S7: 17.1 | T7: 17.5 | U7: 0 | V7: 0.13605324 | W7: 0.27430556 | X7: 0.30902778 | Y7: 0 | Z7: 60
B8: Brand | C8: Brew no. | D8: Kett. Hls | E8: Wort | F8: Cool Time(Mins) | G8: Cast. P.G. (Lab Result) | H8: Cast P.G. (Cellar Operator)-gravity | I8: Extr. Rec (78.95%) | J8: Theor. Extr. (77.5%) | K8: Boil Off /Vol. (4-6%) | L8: Boil Time | M8: Total Hot | N8: Brewing | O8: Operator | R8: Hurricane Reef | S8: 16.6 | T8: 17 | U8: 0 | V8: 0.12905093 | W8: 0.27430556 | X8: 0.30208333 | Y8: 0
E9: Meter (Hls) | F9: Target(< 60Mins) | M9: Time | R9: VITAMALT | S9: 14.4 | T9: 14.6 | U9: 0 | V9: 0.13905093 | W9: 0.26041667 | X9: 0.29513889 | Y9: 0 | Z9: 75
R10: =B10 -> 0 | S10: =VLOOKUP($B10,$R$3:$X$9,2,FALSE) -> #N/A | T10: =VLOOKUP($B10,$R$3:$X$9,3,FALSE) -> #N/A | U10: =VLOOKUP($B10,$R$3:$X$9,4,FALSE) -> #N/A | V10: =VLOOKUP($B10,$R$3:$X$9,5,FALSE) -> #N/A | W10: =VLOOKUP($B10,$R$3:$X$9,6,FALSE) -> #N/A | X10: =VLOOKUP($B10,$R$3:$X$9,7,FALSE) -> #N/A | Y10: =VLOOKUP($B10,$R$3:$Z$9,8,FALSE) -> #N/A | Z10: =VLOOKUP($B10,$R$3:$Z$9,9,FALSE) -> #N/A
R11: =B11 -> 0 | S11: =VLOOKUP($B11,$R$3:$X$9,2,FALSE) -> #N/A | T11: =VLOOKUP($B11,$R$3:$X$9,3,FALSE) -> #N/A | U11: =VLOOKUP($B11,$R$3:$X$9,4,FALSE) -> #N/A | V11: =VLOOKUP($B11,$R$3:$X$9,5,FALSE) -> #N/A | W11: =VLOOKUP($B11,$R$3:$X$9,6,FALSE) -> #N/A | X11: =VLOOKUP($B11,$R$3:$X$9,7,FALSE) -> #N/A | Y11: =VLOOKUP($B11,$R$3:$Z$9,8,FALSE) -> #N/A | Z11: =VLOOKUP($B11,$R$3:$Z$9,9,FALSE) -> #N/A
R12: =B12 -> 0 | S12: =VLOOKUP($B12,$R$3:$X$9,2,FALSE) -> #N/A | T12: =VLOOKUP($B12,$R$3:$X$9,3,FALSE) -> #N/A | U12: =VLOOKUP($B12,$R$3:$X$9,4,FALSE) -> #N/A | V12: =VLOOKUP($B12,$R$3:$X$9,5,FALSE) -> #N/A | W12: =VLOOKUP($B12,$R$3:$X$9,6,FALSE) -> #N/A | X12: =VLOOKUP($B12,$R$3:$X$9,7,FALSE) -> #N/A | Y12: =VLOOKUP($B12,$R$3:$Z$9,8,FALSE) -> #N/A | Z12: =VLOOKUP($B12,$R$3:$Z$9,9,FALSE) -> #N/A
R13: =B13 -> 0 | S13: =VLOOKUP($B13,$R$3:$X$9,2,FALSE) -> #N/A | T13: =VLOOKUP($B13,$R$3:$X$9,3,FALSE) -> #N/A | U13: =VLOOKUP($B13,$R$3:$X$9,4,FALSE) -> #N/A | V13: =VLOOKUP($B13,$R$3:$X$9,5,FALSE) -> #N/A | W13: =VLOOKUP($B13,$R$3:$X$9,6,FALSE) -> #N/A | X13: =VLOOKUP($B13,$R$3:$X$9,7,FALSE) -> #N/A | Y13: =VLOOKUP($B13,$R$3:$Z$9,8,FALSE) -> #N/A | Z13: =VLOOKUP($B13,$R$3:$Z$9,9,FALSE) -> #N/A
R14: =B14 -> 0 | S14: =VLOOKUP($B14,$R$3:$X$9,2,FALSE) -> #N/A | T14: =VLOOKUP($B14,$R$3:$X$9,3,FALSE) -> #N/A | U14: =VLOOKUP($B14,$R$3:$X$9,4,FALSE) -> #N/A | V14: =VLOOKUP($B14,$R$3:$X$9,5,FALSE) -> #N/A | W14: =VLOOKUP($B14,$R$3:$X$9,6,FALSE) -> #N/A | X14: =VLOOKUP($B14,$R$3:$X$9,7,FALSE) -> #N/A | Y14: =VLOOKUP($B14,$R$3:$Z$9,8,FALSE) -> #N/A | Z14: =VLOOKUP($B14,$R$3:$Z$9,9,FALSE) -> #N/A
R15: =B15 -> 0 | S15: =VLOOKUP($B15,$R$3:$X$9,2,FALSE) -> #N/A | T15: =VLOOKUP($B15,$R$3:$X$9,3,FALSE) -> #N/A | U15: =VLOOKUP($B15,$R$3:$X$9,4,FALSE) -> #N/A | V15: =VLOOKUP($B15,$R$3:$X$9,5,FALSE) -> #N/A | W15: =VLOOKUP($B15,$R$3:$X$9,6,FALSE) -> #N/A | X15: =VLOOKUP($B15,$R$3:$X$9,7,FALSE) -> #N/A | Y15: =VLOOKUP($B15,$R$3:$Z$9,8,FALSE) -> #N/A | Z15: =VLOOKUP($B15,$R$3:$Z$9,9,FALSE) -> #N/A
R16: =B16 -> 0 | S16: =VLOOKUP($B16,$R$3:$X$9,2,FALSE) -> #N/A | T16: =VLOOKUP($B16,$R$3:$X$9,3,FALSE) -> #N/A | U16: =VLOOKUP($B16,$R$3:$X$9,4,FALSE) -> #N/A | V16: =VLOOKUP($B16,$R$3:$X$9,5,FALSE) -> #N/A | W16: =VLOOKUP($B16,$R$3:$X$9,6,FALSE) -> #N/A | X16: =VLOOKUP($B16,$R$3:$X$9,7,FALSE) -> #N/A | Y16: =VLOOKUP($B16,$R$3:$Z$9,8,FALSE) -> #N/A | Z16: =VLOOKUP($B16,$R$3:$Z$9,9,FALSE) -> #N/A
R17: =B17 -> 0 | S17: =VLOOKUP($B17,$R$3:$X$9,2,FALSE) -> #N/A | T17: =VLOOKUP($B17,$R$3:$X$9,3,FALSE) -> #N/A | U17: =VLOOKUP($B17,$R$3:$X$9,4,FALSE) -> #N/A | V17: =VLOOKUP($B17,$R$3:$X$9,5,FALSE) -> #N/A | W17: =VLOOKUP($B17,$R$3:$X$9,6,FALSE) -> #N/A | X17: =VLOOKUP($B17,$R$3:$X$9,7,FALSE) -> #N/A | Y17: =VLOOKUP($B17,$R$3:$Z$9,8,FALSE) -> #N/A | Z17: =VLOOKUP($B17,$R$3:$Z$9,9,FALSE) -> #N/A
B18: STARMALT | C18: =[22]Brewhouse!$A45 -> SM035 | D18: =[22]Brewhouse!$AH45 -> 52.1 | E18: =[22]Brewhouse!$AM45 -> 52 | F18: =[22]Brewhouse!$Z45 -> 93 | G18: =[22]Brewhouse!$AK45 -> 17.2 | H18: 17.3 | I18: =[22]Brewhouse!$AY45 -> 97.680079 | J18: =[22]Brewhouse!$AZ45 -> 98.765555 | K18: =[22]Brewhouse!$U45 -> 10.134357 | L18: =[22]Brewhouse!$T45 -> 60 | M18: =[22]Brewhouse!$Y45-[22]Brewhouse!$X45 -> 0.15416667 | N18: =[22]Brewhouse!$AD45 -> 0.29305556 | O18: =[22]Brewhouse!$BC45 -> R. Regis | R18: =B18 -> STARMALT | S18: =VLOOKUP($B18,$R$3:$X$9,2,FALSE) -> 17.1 | T18: =VLOOKUP($B18,$R$3:$X$9,3,FALSE) -> 17.5 | U18: =VLOOKUP($B18,$R$3:$X$9,4,FALSE) -> 0 | V18: =VLOOKUP($B18,$R$3:$X$9,5,FALSE) -> 0.13605324 | W18: =VLOOKUP($B18,$R$3:$X$9,6,FALSE) -> 0.27430556 | X18: =VLOOKUP($B18,$R$3:$X$9,7,FALSE) -> 0.30902778 | Y18: =VLOOKUP($B18,$R$3:$Z$9,8,FALSE) -> 0 | Z18: =VLOOKUP($B18,$R$3:$Z$9,9,FALSE) -> 60
B19: STARMALT | C19: =[22]Brewhouse!$A46 -> SM036 | D19: =[22]Brewhouse!$AH46 -> 0 | E19: =[22]Brewhouse!$AM46 -> 51.04 | F19: =[22]Brewhouse!$Z46 -> 90 | G19: =[22]Brewhouse!$AK46 -> 17.2 | H19: 17.2 | I19: =[22]Brewhouse!$AY46 -> 96.032534 | J19: =[22]Brewhouse!$AZ46 -> 97.097714 | K19: =[22]Brewhouse!$U46 -> #DIV/0! | L19: =[22]Brewhouse!$T46 -> 58 | M19: =[22]Brewhouse!$Y46-[22]Brewhouse!$X46 -> 0.14583333 | N19: =[22]Brewhouse!$AD46 -> 0.3 | O19: =[22]Brewhouse!$BC46 -> D. Gomaz | R19: =B19 -> STARMALT | S19: =VLOOKUP($B19,$R$3:$X$9,2,FALSE) -> 17.1 | T19: =VLOOKUP($B19,$R$3:$X$9,3,FALSE) -> 17.5 | U19: =VLOOKUP($B19,$R$3:$X$9,4,FALSE) -> 0 | V19: =VLOOKUP($B19,$R$3:$X$9,5,FALSE) -> 0.13605324 | W19: =VLOOKUP($B19,$R$3:$X$9,6,FALSE) -> 0.27430556 | X19: =VLOOKUP($B19,$R$3:$X$9,7,FALSE) -> 0.30902778 | Y19: =VLOOKUP($B19,$R$3:$Z$9,8,FALSE) -> 0 | Z19: =VLOOKUP($B19,$R$3:$Z$9,9,FALSE) -> 60
B20: STARMALT | C20: =[22]Brewhouse!$A47 -> SM037 | D20: =[22]Brewhouse!$AH47 -> 0 | E20: =[22]Brewhouse!$AM47 -> 51.26 | F20: =[22]Brewhouse!$Z47 -> 86 | G20: =[22]Brewhouse!$AK47 -> 17.2 | H20: 17.4 | I20: =[22]Brewhouse!$AY47 -> 96.368178 | J20: =[22]Brewhouse!$AZ47 -> 97.438079 | K20: =[22]Brewhouse!$U47 -> #DIV/0! | L20: =[22]Brewhouse!$T47 -> 60 | M20: =[22]Brewhouse!$Y47-[22]Brewhouse!$X47 -> 0.15208333 | N20: =[22]Brewhouse!$AD47 -> 0.3125 | O20: =[22]Brewhouse!$BC47 -> D. Gomaz | R20: =B20 -> STARMALT | S20: =VLOOKUP($B20,$R$3:$X$9,2,FALSE) -> 17.1 | T20: =VLOOKUP($B20,$R$3:$X$9,3,FALSE) -> 17.5 | U20: =VLOOKUP($B20,$R$3:$X$9,4,FALSE) -> 0 | V20: =VLOOKUP($B20,$R$3:$X$9,5,FALSE) -> 0.13605324 | W20: =VLOOKUP($B20,$R$3:$X$9,6,FALSE) -> 0.27430556 | X20: =VLOOKUP($B20,$R$3:$X$9,7,FALSE) -> 0.30902778 | Y20: =VLOOKUP($B20,$R$3:$Z$9,8,FALSE) -> 0 | Z20: =VLOOKUP($B20,$R$3:$Z$9,9,FALSE) -> 60
B21: STARMALT | C21: =[22]Brewhouse!$A48 -> SM038 | D21: =[22]Brewhouse!$AH48 -> 50.4 | E21: =[22]Brewhouse!$AM48 -> 50.5 | F21: =[22]Brewhouse!$Z48 -> 65 | G21: =[22]Brewhouse!$AK48 -> 17.4 | H21: 17.4 | I21: =[22]Brewhouse!$AY48 -> 96.127421 | J21: =[22]Brewhouse!$AZ48 -> 97.194649 | K21: =[22]Brewhouse!$U48 -> 6.9047619 | L21: =[22]Brewhouse!$T48 -> 62 | M21: =[22]Brewhouse!$Y48-[22]Brewhouse!$X48 -> 0.13819444 | N21: =[22]Brewhouse!$AD48 -> 0.67777778 | O21: =[22]Brewhouse!$BC48 -> R. Regis | R21: =B21 -> STARMALT | S21: =VLOOKUP($B21,$R$3:$X$9,2,FALSE) -> 17.1 | T21: =VLOOKUP($B21,$R$3:$X$9,3,FALSE) -> 17.5 | U21: =VLOOKUP($B21,$R$3:$X$9,4,FALSE) -> 0 | V21: =VLOOKUP($B21,$R$3:$X$9,5,FALSE) -> 0.13605324 | W21: =VLOOKUP($B21,$R$3:$X$9,6,FALSE) -> 0.27430556 | X21: =VLOOKUP($B21,$R$3:$X$9,7,FALSE) -> 0.30902778 | Y21: =VLOOKUP($B21,$R$3:$Z$9,8,FALSE) -> 0 | Z21: =VLOOKUP($B21,$R$3:$Z$9,9,FALSE) -> 60
R22: =B22 -> 0 | S22: =VLOOKUP($B22,$R$3:$X$9,2,FALSE) -> #N/A | T22: =VLOOKUP($B22,$R$3:$X$9,3,FALSE) -> #N/A | U22: =VLOOKUP($B22,$R$3:$X$9,4,FALSE) -> #N/A | V22: =VLOOKUP($B22,$R$3:$X$9,5,FALSE) -> #N/A | W22: =VLOOKUP($B22,$R$3:$X$9,6,FALSE) -> #N/A | X22: =VLOOKUP($B22,$R$3:$X$9,7,FALSE) -> #N/A | Y22: =VLOOKUP($B22,$R$3:$Z$9,8,FALSE) -> #N/A | Z22: =VLOOKUP($B22,$R$3:$Z$9,9,FALSE) -> #N/A
R23: =B23 -> 0 | S23: =VLOOKUP($B23,$R$3:$X$9,2,FALSE) -> #N/A | T23: =VLOOKUP($B23,$R$3:$X$9,3,FALSE) -> #N/A | U23: =VLOOKUP($B23,$R$3:$X$9,4,FALSE) -> #N/A | V23: =VLOOKUP($B23,$R$3:$X$9,5,FALSE) -> #N/A | W23: =VLOOKUP($B23,$R$3:$X$9,6,FALSE) -> #N/A | X23: =VLOOKUP($B23,$R$3:$X$9,7,FALSE) -> #N/A | Y23: =VLOOKUP($B23,$R$3:$Z$9,8,FALSE) -> #N/A | Z23: =VLOOKUP($B23,$R$3:$Z$9,9,FALSE) -> #N/A
R24: =B24 -> 0 | S24: =VLOOKUP($B24,$R$3:$X$9,2,FALSE) -> #N/A | T24: =VLOOKUP($B24,$R$3:$X$9,3,FALSE) -> #N/A | U24: =VLOOKUP($B24,$R$3:$X$9,4,FALSE) -> #N/A | V24: =VLOOKUP($B24,$R$3:$X$9,5,FALSE) -> #N/A | W24: =VLOOKUP($B24,$R$3:$X$9,6,FALSE) -> #N/A | X24: =VLOOKUP($B24,$R$3:$X$9,7,FALSE) -> #N/A | Y24: =VLOOKUP($B24,$R$3:$Z$9,8,FALSE) -> #N/A | Z24: =VLOOKUP($B24,$R$3:$Z$9,9,FALSE) -> #N/A
R25: =B25 -> 0 | S25: =VLOOKUP($B25,$R$3:$X$9,2,FALSE) -> #N/A | T25: =VLOOKUP($B25,$R$3:$X$9,3,FALSE) -> #N/A | U25: =VLOOKUP($B25,$R$3:$X$9,4,FALSE) -> #N/A | V25: =VLOOKUP($B25,$R$3:$X$9,5,FALSE) -> #N/A | W25: =VLOOKUP($B25,$R$3:$X$9,6,FALSE) -> #N/A | X25: =VLOOKUP($B25,$R$3:$X$9,7,FALSE) -> #N/A | Y25: =VLOOKUP($B25,$R$3:$Z$9,8,FALSE) -> #N/A | Z25: =VLOOKUP($B25,$R$3:$Z$9,9,FALSE) -> #N/A
R26: =B26 -> 0 | S26: =VLOOKUP($B26,$R$3:$X$9,2,FALSE) -> #N/A | T26: =VLOOKUP($B26,$R$3:$X$9,3,FALSE) -> #N/A | U26: =VLOOKUP($B26,$R$3:$X$9,4,FALSE) -> #N/A | V26: =VLOOKUP($B26,$R$3:$X$9,5,FALSE) -> #N/A | W26: =VLOOKUP($B26,$R$3:$X$9,6,FALSE) -> #N/A | X26: =VLOOKUP($B26,$R$3:$X$9,7,FALSE) -> #N/A | Y26: =VLOOKUP($B26,$R$3:$Z$9,8,FALSE) -> #N/A | Z26: =VLOOKUP($B26,$R$3:$Z$9,9,FALSE) -> #N/A
R27: =B27 -> 0 | S27: =VLOOKUP($B27,$R$3:$X$9,2,FALSE) -> #N/A | T27: =VLOOKUP($B27,$R$3:$X$9,3,FALSE) -> #N/A | U27: =VLOOKUP($B27,$R$3:$X$9,4,FALSE) -> #N/A | V27: =VLOOKUP($B27,$R$3:$X$9,5,FALSE) -> #N/A | W27: =VLOOKUP($B27,$R$3:$X$9,6,FALSE) -> #N/A | X27: =VLOOKUP($B27,$R$3:$X$9,7,FALSE) -> #N/A | Y27: =VLOOKUP($B27,$R$3:$Z$9,8,FALSE) -> #N/A | Z27: =VLOOKUP($B27,$R$3:$Z$9,9,FALSE) -> #N/A
R28: =B28 -> 0 | S28: =VLOOKUP($B28,$R$3:$X$9,2,FALSE) -> #N/A | T28: =VLOOKUP($B28,$R$3:$X$9,3,FALSE) -> #N/A | U28: =VLOOKUP($B28,$R$3:$X$9,4,FALSE) -> #N/A | V28: =VLOOKUP($B28,$R$3:$X$9,5,FALSE) -> #N/A | W28: =VLOOKUP($B28,$R$3:$X$9,6,FALSE) -> #N/A | X28: =VLOOKUP($B28,$R$3:$X$9,7,FALSE) -> #N/A | Y28: =VLOOKUP($B28,$R$3:$Z$9,8,FALSE) -> #N/A | Z28: =VLOOKUP($B28,$R$3:$Z$9,9,FALSE) -> #N/A
R29: =B29 -> 0 | S29: =VLOOKUP($B29,$R$3:$X$9,2,FALSE) -> #N/A | T29: =VLOOKUP($B29,$R$3:$X$9,3,FALSE) -> #N/A | U29: =VLOOKUP($B29,$R$3:$X$9,4,FALSE) -> #N/A | V29: =VLOOKUP($B29,$R$3:$X$9,5,FALSE) -> #N/A | W29: =VLOOKUP($B29,$R$3:$X$9,6,FALSE) -> #N/A | X29: =VLOOKUP($B29,$R$3:$X$9,7,FALSE) -> #N/A | Y29: =VLOOKUP($B29,$R$3:$Z$9,8,FALSE) -> #N/A | Z29: =VLOOKUP($B29,$R$3:$Z$9,9,FALSE) -> #N/A
R30: =B30 -> 0 | S30: =VLOOKUP($B30,$R$3:$X$9,2,FALSE) -> #N/A | T30: =VLOOKUP($B30,$R$3:$X$9,3,FALSE) -> #N/A | U30: =VLOOKUP($B30,$R$3:$X$9,4,FALSE) -> #N/A | V30: =VLOOKUP($B30,$R$3:$X$9,5,FALSE) -> #N/A | W30: =VLOOKUP($B30,$R$3:$X$9,6,FALSE) -> #N/A | X30: =VLOOKUP($B30,$R$3:$X$9,7,FALSE) -> #N/A | Y30: =VLOOKUP($B30,$R$3:$Z$9,8,FALSE) -> #N/A | Z30: =VLOOKUP($B30,$R$3:$Z$9,9,FALSE) -> #N/A
I31: EXTRACT RECOVERY | R31: =B31 -> 0 | S31: =VLOOKUP($B31,$R$3:$X$9,2,FALSE) -> #N/A | T31: =VLOOKUP($B31,$R$3:$X$9,3,FALSE) -> #N/A | U31: =VLOOKUP($B31,$R$3:$X$9,4,FALSE) -> #N/A | V31: =VLOOKUP($B31,$R$3:$X$9,5,FALSE) -> #N/A | W31: =VLOOKUP($B31,$R$3:$X$9,6,FALSE) -> #N/A | X31: =VLOOKUP($B31,$R$3:$X$9,7,FALSE) -> #N/A | Y31: =VLOOKUP($B31,$R$3:$Z$9,8,FALSE) -> #N/A | Z31: =VLOOKUP($B31,$R$3:$Z$9,9,FALSE) -> #N/A
B32: BRAND | D32: BBT P.G./ O.G | I32: Brand | J32: Actual | K32: MTD No. of Brews | L32: MTD | M32: YTD | N32: Target | R32: =B32 -> BRAND | S32: =VLOOKUP($B32,$R$3:$X$9,2,FALSE) -> #N/A | T32: =VLOOKUP($B32,$R$3:$X$9,3,FALSE) -> #N/A | U32: =VLOOKUP($B32,$R$3:$X$9,4,FALSE) -> #N/A | V32: =VLOOKUP($B32,$R$3:$X$9,5,FALSE) -> #N/A | W32: =VLOOKUP($B32,$R$3:$X$9,6,FALSE) -> #N/A | X32: =VLOOKUP($B32,$R$3:$X$9,7,FALSE) -> #N/A | Y32: =VLOOKUP($B32,$R$3:$Z$9,8,FALSE) -> #N/A | Z32: =VLOOKUP($B32,$R$3:$Z$9,9,FALSE) -> #N/A
B33: =I36 -> VITAMALT | C33: =[23]Process!D41 -> 14.3 | D33: 16.54 | I33: CARIB | M33: =AVERAGE([24]Brewhouse!$AU$102:$AU$171,[24]Brewhouse!$AU$173:$AU$253,[24]Brewhouse!$AU$255:$AU$339,[24]Brewhouse!$AU$341:$AU$346,[24]Brewhouse!$AU$348,[24]Brewhouse!$AU$349:$AU$406,[24]Brewhouse!$AU$408:$AU$491) -> 97.660574 | N33: 98
C34: =[23]Process!D42 -> 14.4 | I34: STAG | M34: =AVERAGE([25]Brewhouse!$AS$15:$AS$64,[25]Brewhouse!$AS$66:$AS$103,[25]Brewhouse!$AS$105:$AS$140,[25]Brewhouse!$AS$142:$AS$193,[25]Brewhouse!$AS$195:$AS$240) -> 97.875553 | N34: 98
I35: GUINNESS | M35: =AVERAGE([26]Brewhouse!$AU$4:$AU$7,[26]Brewhouse!$AU$9:$AU$22,[26]Brewhouse!$AU$24:$AU$35,[26]Brewhouse!$AU$37:$AU$45,[26]Brewhouse!$AU$47:$AU$62) -> 97.179377 | N35: 98
I36: VITAMALT | M36: =AVERAGE([23]Brewhouse!$AV$5:$AV$14,[23]Brewhouse!$AV$16:$AV$19,[23]Brewhouse!$AV$21:$AV$24,[23]Brewhouse!$AV$26:$AV$33,[23]Brewhouse!$AV$35:$AV$46) -> 99.005314 | N36: 98
I37: MAXIMALT | N37: 98
I38: MACKESON | M38: =AVERAGE([27]Brewhouse!$AT$4:$AT$11,[27]Brewhouse!$AT$13:$AT$16) -> 94.677026 | N38: 98
I39: STARMALT | J39: =AVERAGE(I18:I21) -> 96.552053 | K39: =COUNTA([22]Brewhouse!$A$45:$A$48) -> 4 | L39: =AVERAGE([22]Brewhouse!$AY$45:$AY$48) -> 96.552053 | M39: =AVERAGE([22]Brewhouse!$AY$6:$AY$13,[22]Brewhouse!$AY$15:$AY$20,[22]Brewhouse!$AY$22:$AY$29,[22]Brewhouse!$AY$31:$AY$34,[22]Brewhouse!$AY$36:$AY$43,[22]Brewhouse!$AY$45:$AY$48) -> 96.657363 | N39: 98
I40: HR- Pils | M40: =AVERAGE([28]Brewhouse!$AU$5:$AU$8) -> 91.006888 | N40: 98
...

Sheet June 3rd
S1: P.G. | U1: Hot Time | W1: Process Time | Y1: Cooling Time
B2: Brewing Department Daily Process Loss Report | S2: Lower | T2: Upper | U2: Lower | V2: Upper | W2: Lower | X2: Upper | Y2: Lower | Z2: Upper
R3: CARIB | S3: 11.6 | T3: 12 | U3: 0 | V3: 0.11805556 | W3: 0.22569444 | X3: 0.26388889 | Y3: 0 | Z3: 60 | AB3: HR- PISNER
B4: Date: | C4: 45812 | J4: LOT WORT COLOUR: 3.6 | M4: Filter Sheets (Target 20 days) | R4: STAG | S4: 11.6 | T4: 12 | U4: 0 | V4: 0.11805556 | W4: 0.22569444 | X4: 0.26388889 | Y4: 0 | Z4: 60
M5: Double | N5: Single | R5: GUINNESS | S5: 17 | T5: 17.5 | U5: 0 | V5: 0.10763889 | W5: 0.24652778 | X5: 0.28472222 | Y5: 0 | Z5: 60
J6: MALT LOT: Lot 37 | L6: Sheet Day | R6: MACKESON | S6: 13.3 | T6: 13.5 | U6: 0 | V6: 0.12905093 | W6: 0.27430556 | X6: 0.30208333 | Y6: 0
R7: STARMALT | S7: 17.1 | T7: 17.5 | U7: 0 | V7: 0.13605324 | W7: 0.27430556 | X7: 0.30902778 | Y7: 0 | Z7: 60
B8: Brand | C8: Brew no. | D8: Kett. Hls | E8: Wort | F8: Cool Time(Mins) | G8: Cast. P.G. (Lab Result) | H8: Cast P.G. (Cellar Operator)-gravity | I8: Extr. Rec (78.95%) | J8: Theor. Extr. (77.5%) | K8: Boil Off /Vol. (4-6%) | L8: Boil Time | M8: Total Hot | N8: Brewing | O8: Operator | R8: Hurricane Reef | S8: 16.6 | T8: 17 | U8: 0 | V8: 0.12905093 | W8: 0.27430556 | X8: 0.30208333 | Y8: 0
E9: Meter (Hls) | F9: Target(< 60Mins) | M9: Time | R9: VITAMALT | S9: 14.4 | T9: 14.6 | U9: 0 | V9: 0.13905093 | W9: 0.26041667 | X9: 0.29513889 | Y9: 0 | Z9: 75
R10: =B10 -> 0 | S10: =VLOOKUP($B10,$R$3:$X$9,2,FALSE) -> #N/A | T10: =VLOOKUP($B10,$R$3:$X$9,3,FALSE) -> #N/A | U10: =VLOOKUP($B10,$R$3:$X$9,4,FALSE) -> #N/A | V10: =VLOOKUP($B10,$R$3:$X$9,5,FALSE) -> #N/A | W10: =VLOOKUP($B10,$R$3:$X$9,6,FALSE) -> #N/A | X10: =VLOOKUP($B10,$R$3:$X$9,7,FALSE) -> #N/A | Y10: =VLOOKUP($B10,$R$3:$Z$9,8,FALSE) -> #N/A | Z10: =VLOOKUP($B10,$R$3:$Z$9,9,FALSE) -> #N/A
R11: =B11 -> 0 | S11: =VLOOKUP($B11,$R$3:$X$9,2,FALSE) -> #N/A | T11: =VLOOKUP($B11,$R$3:$X$9,3,FALSE) -> #N/A | U11: =VLOOKUP($B11,$R$3:$X$9,4,FALSE) -> #N/A | V11: =VLOOKUP($B11,$R$3:$X$9,5,FALSE) -> #N/A | W11: =VLOOKUP($B11,$R$3:$X$9,6,FALSE) -> #N/A | X11: =VLOOKUP($B11,$R$3:$X$9,7,FALSE) -> #N/A | Y11: =VLOOKUP($B11,$R$3:$Z$9,8,FALSE) -> #N/A | Z11: =VLOOKUP($B11,$R$3:$Z$9,9,FALSE) -> #N/A
R12: =B12 -> 0 | S12: =VLOOKUP($B12,$R$3:$X$9,2,FALSE) -> #N/A | T12: =VLOOKUP($B12,$R$3:$X$9,3,FALSE) -> #N/A | U12: =VLOOKUP($B12,$R$3:$X$9,4,FALSE) -> #N/A | V12: =VLOOKUP($B12,$R$3:$X$9,5,FALSE) -> #N/A | W12: =VLOOKUP($B12,$R$3:$X$9,6,FALSE) -> #N/A | X12: =VLOOKUP($B12,$R$3:$X$9,7,FALSE) -> #N/A | Y12: =VLOOKUP($B12,$R$3:$Z$9,8,FALSE) -> #N/A | Z12: =VLOOKUP($B12,$R$3:$Z$9,9,FALSE) -> #N/A
R13: =B13 -> 0 | S13: =VLOOKUP($B13,$R$3:$X$9,2,FALSE) -> #N/A | T13: =VLOOKUP($B13,$R$3:$X$9,3,FALSE) -> #N/A | U13: =VLOOKUP($B13,$R$3:$X$9,4,FALSE) -> #N/A | V13: =VLOOKUP($B13,$R$3:$X$9,5,FALSE) -> #N/A | W13: =VLOOKUP($B13,$R$3:$X$9,6,FALSE) -> #N/A | X13: =VLOOKUP($B13,$R$3:$X$9,7,FALSE) -> #N/A | Y13: =VLOOKUP($B13,$R$3:$Z$9,8,FALSE) -> #N/A | Z13: =VLOOKUP($B13,$R$3:$Z$9,9,FALSE) -> #N/A
R14: =B14 -> 0 | S14: =VLOOKUP($B14,$R$3:$X$9,2,FALSE) -> #N/A | T14: =VLOOKUP($B14,$R$3:$X$9,3,FALSE) -> #N/A | U14: =VLOOKUP($B14,$R$3:$X$9,4,FALSE) -> #N/A | V14: =VLOOKUP($B14,$R$3:$X$9,5,FALSE) -> #N/A | W14: =VLOOKUP($B14,$R$3:$X$9,6,FALSE) -> #N/A | X14: =VLOOKUP($B14,$R$3:$X$9,7,FALSE) -> #N/A | Y14: =VLOOKUP($B14,$R$3:$Z$9,8,FALSE) -> #N/A | Z14: =VLOOKUP($B14,$R$3:$Z$9,9,FALSE) -> #N/A
R15: =B15 -> 0 | S15: =VLOOKUP($B15,$R$3:$X$9,2,FALSE) -> #N/A | T15: =VLOOKUP($B15,$R$3:$X$9,3,FALSE) -> #N/A | U15: =VLOOKUP($B15,$R$3:$X$9,4,FALSE) -> #N/A | V15: =VLOOKUP($B15,$R$3:$X$9,5,FALSE) -> #N/A | W15: =VLOOKUP($B15,$R$3:$X$9,6,FALSE) -> #N/A | X15: =VLOOKUP($B15,$R$3:$X$9,7,FALSE) -> #N/A | Y15: =VLOOKUP($B15,$R$3:$Z$9,8,FALSE) -> #N/A | Z15: =VLOOKUP($B15,$R$3:$Z$9,9,FALSE) -> #N/A
R16: =B16 -> 0 | S16: =VLOOKUP($B16,$R$3:$X$9,2,FALSE) -> #N/A | T16: =VLOOKUP($B16,$R$3:$X$9,3,FALSE) -> #N/A | U16: =VLOOKUP($B16,$R$3:$X$9,4,FALSE) -> #N/A | V16: =VLOOKUP($B16,$R$3:$X$9,5,FALSE) -> #N/A | W16: =VLOOKUP($B16,$R$3:$X$9,6,FALSE) -> #N/A | X16: =VLOOKUP($B16,$R$3:$X$9,7,FALSE) -> #N/A | Y16: =VLOOKUP($B16,$R$3:$Z$9,8,FALSE) -> #N/A | Z16: =VLOOKUP($B16,$R$3:$Z$9,9,FALSE) -> #N/A
R17: =B17 -> 0 | S17: =VLOOKUP($B17,$R$3:$X$9,2,FALSE) -> #N/A | T17: =VLOOKUP($B17,$R$3:$X$9,3,FALSE) -> #N/A | U17: =VLOOKUP($B17,$R$3:$X$9,4,FALSE) -> #N/A | V17: =VLOOKUP($B17,$R$3:$X$9,5,FALSE) -> #N/A | W17: =VLOOKUP($B17,$R$3:$X$9,6,FALSE) -> #N/A | X17: =VLOOKUP($B17,$R$3:$X$9,7,FALSE) -> #N/A | Y17: =VLOOKUP($B17,$R$3:$Z$9,8,FALSE) -> #N/A | Z17: =VLOOKUP($B17,$R$3:$Z$9,9,FALSE) -> #N/A
R18: =B18 -> 0 | S18: =VLOOKUP($B18,$R$3:$X$9,2,FALSE) -> #N/A | T18: =VLOOKUP($B18,$R$3:$X$9,3,FALSE) -> #N/A | U18: =VLOOKUP($B18,$R$3:$X$9,4,FALSE) -> #N/A | V18: =VLOOKUP($B18,$R$3:$X$9,5,FALSE) -> #N/A | W18: =VLOOKUP($B18,$R$3:$X$9,6,FALSE) -> #N/A | X18: =VLOOKUP($B18,$R$3:$X$9,7,FALSE) -> #N/A | Y18: =VLOOKUP($B18,$R$3:$Z$9,8,FALSE) -> #N/A | Z18: =VLOOKUP($B18,$R$3:$Z$9,9,FALSE) -> #N/A
R19: =B19 -> 0 | S19: =VLOOKUP($B19,$R$3:$X$9,2,FALSE) -> #N/A | T19: =VLOOKUP($B19,$R$3:$X$9,3,FALSE) -> #N/A | U19: =VLOOKUP($B19,$R$3:$X$9,4,FALSE) -> #N/A | V19: =VLOOKUP($B19,$R$3:$X$9,5,FALSE) -> #N/A | W19: =VLOOKUP($B19,$R$3:$X$9,6,FALSE) -> #N/A | X19: =VLOOKUP($B19,$R$3:$X$9,7,FALSE) -> #N/A | Y19: =VLOOKUP($B19,$R$3:$Z$9,8,FALSE) -> #N/A | Z19: =VLOOKUP($B19,$R$3:$Z$9,9,FALSE) -> #N/A
R20: =B20 -> 0 | S20: =VLOOKUP($B20,$R$3:$X$9,2,FALSE) -> #N/A | T20: =VLOOKUP($B20,$R$3:$X$9,3,FALSE) -> #N/A | U20: =VLOOKUP($B20,$R$3:$X$9,4,FALSE) -> #N/A | V20: =VLOOKUP($B20,$R$3:$X$9,5,FALSE) -> #N/A | W20: =VLOOKUP($B20,$R$3:$X$9,6,FALSE) -> #N/A | X20: =VLOOKUP($B20,$R$3:$X$9,7,FALSE) -> #N/A | Y20: =VLOOKUP($B20,$R$3:$Z$9,8,FALSE) -> #N/A | Z20: =VLOOKUP($B20,$R$3:$Z$9,9,FALSE) -> #N/A
R21: =B21 -> 0 | S21: =VLOOKUP($B21,$R$3:$X$9,2,FALSE) -> #N/A | T21: =VLOOKUP($B21,$R$3:$X$9,3,FALSE) -> #N/A | U21: =VLOOKUP($B21,$R$3:$X$9,4,FALSE) -> #N/A | V21: =VLOOKUP($B21,$R$3:$X$9,5,FALSE) -> #N/A | W21: =VLOOKUP($B21,$R$3:$X$9,6,FALSE) -> #N/A | X21: =VLOOKUP($B21,$R$3:$X$9,7,FALSE) -> #N/A | Y21: =VLOOKUP($B21,$R$3:$Z$9,8,FALSE) -> #N/A | Z21: =VLOOKUP($B21,$R$3:$Z$9,9,FALSE) -> #N/A
B22: STARMALT | C22: =[22]Brewhouse!$A49 -> SM039 | D22: =[22]Brewhouse!$AH49 -> 51.1 | E22: =[22]Brewhouse!$AM49 -> 50.5 | F22: =[22]Brewhouse!$Z49 -> 87 | G22: =[22]Brewhouse!$AK49 -> 17.4 | I22: =[22]Brewhouse!$AY49 -> 94.281558 | J22: =[22]Brewhouse!$AZ49 -> 95.352952 | K22: =[22]Brewhouse!$U49 -> 5.8317025 | L22: =[22]Brewhouse!$T49 -> 61 | M22: =[22]Brewhouse!$Y49-[22]Brewhouse!$X49 -> 0.14027778 | N22: =[22]Brewhouse!$AD49 -> 0.30069444 | O22: =[22]Brewhouse!$BC49 -> D. Gomaz | R22: =B22 -> STARMALT | S22: =VLOOKUP($B22,$R$3:$X$9,2,FALSE) -> 17.1 | T22: =VLOOKUP($B22,$R$3:$X$9,3,FALSE) -> 17.5 | U22: =VLOOKUP($B22,$R$3:$X$9,4,FALSE) -> 0 | V22: =VLOOKUP($B22,$R$3:$X$9,5,FALSE) -> 0.13605324 | W22: =VLOOKUP($B22,$R$3:$X$9,6,FALSE) -> 0.27430556 | X22: =VLOOKUP($B22,$R$3:$X$9,7,FALSE) -> 0.30902778 | Y22: =VLOOKUP($B22,$R$3:$Z$9,8,FALSE) -> 0 | Z22: =VLOOKUP($B22,$R$3:$Z$9,9,FALSE) -> 60
B23: STARMALT | C23: =[22]Brewhouse!$A50 -> SM040 | D23: =[22]Brewhouse!$AH50 -> 52 | E23: =[22]Brewhouse!$AM50 -> 53 | F23: =[22]Brewhouse!$Z50 -> 73 | G23: =[22]Brewhouse!$AK50 -> 16.9 | I23: =[22]Brewhouse!$AY50 -> 97.243639 | J23: =[22]Brewhouse!$AZ50 -> 98.330261 | K23: =[22]Brewhouse!$U50 -> 5.7307692 | L23: =[22]Brewhouse!$T50 -> 62 | M23: =[22]Brewhouse!$Y50-[22]Brewhouse!$X50 -> 0.15069444 | N23: =[22]Brewhouse!$AD50 -> 0.30208333 | O23: =[22]Brewhouse!$BC50 -> D. Gomaz | R23: =B23 -> STARMALT | S23: =VLOOKUP($B23,$R$3:$X$9,2,FALSE) -> 17.1 | T23: =VLOOKUP($B23,$R$3:$X$9,3,FALSE) -> 17.5 | U23: =VLOOKUP($B23,$R$3:$X$9,4,FALSE) -> 0 | V23: =VLOOKUP($B23,$R$3:$X$9,5,FALSE) -> 0.13605324 | W23: =VLOOKUP($B23,$R$3:$X$9,6,FALSE) -> 0.27430556 | X23: =VLOOKUP($B23,$R$3:$X$9,7,FALSE) -> 0.30902778 | Y23: =VLOOKUP($B23,$R$3:$Z$9,8,FALSE) -> 0 | Z23: =VLOOKUP($B23,$R$3:$Z$9,9,FALSE) -> 60
R24: =B24 -> 0 | S24: =VLOOKUP($B24,$R$3:$X$9,2,FALSE) -> #N/A | T24: =VLOOKUP($B24,$R$3:$X$9,3,FALSE) -> #N/A | U24: =VLOOKUP($B24,$R$3:$X$9,4,FALSE) -> #N/A | V24: =VLOOKUP($B24,$R$3:$X$9,5,FALSE) -> #N/A | W24: =VLOOKUP($B24,$R$3:$X$9,6,FALSE) -> #N/A | X24: =VLOOKUP($B24,$R$3:$X$9,7,FALSE) -> #N/A | Y24: =VLOOKUP($B24,$R$3:$Z$9,8,FALSE) -> #N/A | Z24: =VLOOKUP($B24,$R$3:$Z$9,9,FALSE) -> #N/A
B25: CARIB | C25: =[24]Brewhouse!$A493 -> CA387 | D25: =[24]Brewhouse!$AF493 -> 52.6 | E25: =[24]Brewhouse!$AI493 -> 49.4 | F25: =[24]Brewhouse!$V493 -> 53 | G25: =[24]Brewhouse!$AG493 -> 11.8 | H25: 11.8 | I25: =[24]Brewhouse!$AU493 -> 94.26441 | J25: =[24]Brewhouse!$AV493 -> 96.343234 | K25: =[24]Brewhouse!$Q493 -> 53.2 | L25: =[24]Brewhouse!$P493 -> 62 | M25: =[24]Brewhouse!$U493-[24]Brewhouse!$T493 -> 0.10277778 | N25: =[24]Brewhouse!$Z493 -> 0.23472222 | O25: =[24]Brewhouse!$AX493 -> K.Benjamin | R25: =B25 -> CARIB | S25: =VLOOKUP($B25,$R$3:$X$9,2,FALSE) -> 11.6 | T25: =VLOOKUP($B25,$R$3:$X$9,3,FALSE) -> 12 | U25: =VLOOKUP($B25,$R$3:$X$9,4,FALSE) -> 0 | V25: =VLOOKUP($B25,$R$3:$X$9,5,FALSE) -> 0.11805556 | W25: =VLOOKUP($B25,$R$3:$X$9,6,FALSE) -> 0.22569444 | X25: =VLOOKUP($B25,$R$3:$X$9,7,FALSE) -> 0.26388889 | Y25: =VLOOKUP($B25,$R$3:$Z$9,8,FALSE) -> 0 | Z25: =VLOOKUP($B25,$R$3:$Z$9,9,FALSE) -> 60
B26: CARIB | C26: =[24]Brewhouse!$A494 -> CA388 | D26: =[24]Brewhouse!$AF494 -> 50.3 | E26: =[24]Brewhouse!$AI494 -> 49.2 | F26: =[24]Brewhouse!$V494 -> 50 | G26: =[24]Brewhouse!$AG494 -> 11.9 | H26: 11.8 | I26: =[24]Brewhouse!$AU494 -> 98.399061 | J26: =[24]Brewhouse!$AV494 -> 100.65837 | K26: =[24]Brewhouse!$Q494 -> 10.827338 | L26: =[24]Brewhouse!$P494 -> 61 | M26: =[24]Brewhouse!$U494-[24]Brewhouse!$T494 -> 0.10625 | N26: =[24]Brewhouse!$Z494 -> 0.23402778 | O26: =[24]Brewhouse!$AX494 -> K.Benjamin | R26: =B26 -> CARIB | S26: =VLOOKUP($B26,$R$3:$X$9,2,FALSE) -> 11.6 | T26: =VLOOKUP($B26,$R$3:$X$9,3,FALSE) -> 12 | U26: =VLOOKUP($B26,$R$3:$X$9,4,FALSE) -> 0 | V26: =VLOOKUP($B26,$R$3:$X$9,5,FALSE) -> 0.11805556 | W26: =VLOOKUP($B26,$R$3:$X$9,6,FALSE) -> 0.22569444 | X26: =VLOOKUP($B26,$R$3:$X$9,7,FALSE) -> 0.26388889 | Y26: =VLOOKUP($B26,$R$3:$Z$9,8,FALSE) -> 0 | Z26: =VLOOKUP($B26,$R$3:$Z$9,9,FALSE) -> 60
B27: CARIB | C27: =[24]Brewhouse!$A495 -> CA389 | D27: =[24]Brewhouse!$AF495 -> 51.2 | E27: =[24]Brewhouse!$AI495 -> 50.2 | F27: =[24]Brewhouse!$V495 -> 51 | G27: =[24]Brewhouse!$AG495 -> 11.7 | H27: 11.7 | I27: =[24]Brewhouse!$AU495 -> 94.297173 | J27: =[24]Brewhouse!$AV495 -> 96.466625 | K27: =[24]Brewhouse!$Q495 -> 9.8571429 | L27: =[24]Brewhouse!$P495 -> 58 | M27: =[24]Brewhouse!$U495-[24]Brewhouse!$T495 -> 0.11875 | N27: =[24]Brewhouse!$Z495 -> 0.24444444 | O27: =[24]Brewhouse!$AX495 -> K.Benjamin | R27: =B27 -> CARIB | S27: =VLOOKUP($B27,$R$3:$X$9,2,FALSE) -> 11.6 | T27: =VLOOKUP($B27,$R$3:$X$9,3,FALSE) -> 12 | U27: =VLOOKUP($B27,$R$3:$X$9,4,FALSE) -> 0 | V27: =VLOOKUP($B27,$R$3:$X$9,5,FALSE) -> 0.11805556 | W27: =VLOOKUP($B27,$R$3:$X$9,6,FALSE) -> 0.22569444 | X27: =VLOOKUP($B27,$R$3:$X$9,7,FALSE) -> 0.26388889 | Y27: =VLOOKUP($B27,$R$3:$Z$9,8,FALSE) -> 0 | Z27: =VLOOKUP($B27,$R$3:$Z$9,9,FALSE) -> 60
B28: CARIB | C28: =[24]Brewhouse!$A496 -> CA390 | D28: =[24]Brewhouse!$AF496 -> 64.3 | E28: =[24]Brewhouse!$AI496 -> 61.3 | F28: =[24]Brewhouse!$V496 -> 64 | G28: =[24]Brewhouse!$AG496 -> 12 | H28: 11.9 | I28: =[24]Brewhouse!$AU496 -> 119.86187 | J28: =[24]Brewhouse!$AV496 -> 122.61785 | K28: =[24]Brewhouse!$Q496 -> 6.118068 | L28: =[24]Brewhouse!$P496 -> 61 | M28: =[24]Brewhouse!$U496-[24]Brewhouse!$T496 -> 0.12430556 | N28: =[24]Brewhouse!$Z496 -> 0.27638889 | O28: =[24]Brewhouse!$AX496 -> R. Regis | R28: =B28 -> CARIB | S28: =VLOOKUP($B28,$R$3:$X$9,2,FALSE) -> 11.6 | T28: =VLOOKUP($B28,$R$3:$X$9,3,FALSE) -> 12 | U28: =VLOOKUP($B28,$R$3:$X$9,4,FALSE) -> 0 | V28: =VLOOKUP($B28,$R$3:$X$9,5,FALSE) -> 0.11805556 | W28: =VLOOKUP($B28,$R$3:$X$9,6,FALSE) -> 0.22569444 | X28: =VLOOKUP($B28,$R$3:$X$9,7,FALSE) -> 0.26388889 | Y28: =VLOOKUP($B28,$R$3:$Z$9,8,FALSE) -> 0 | Z28: =VLOOKUP($B28,$R$3:$Z$9,9,FALSE) -> 60
B29: CARIB | C29: =[24]Brewhouse!$A497 -> CA391 | D29: =[24]Brewhouse!$AF497 -> 53.5 | E29: =[24]Brewhouse!$AI497 -> 49 | F29: =[24]Brewhouse!$V497 -> 58 | G29: =[24]Brewhouse!$AG497 -> 11.8 | H29: 11.8 | I29: =[24]Brewhouse!$AU497 -> 92.795634 | J29: =[24]Brewhouse!$AV497 -> 95.446221 | K29: =[24]Brewhouse!$Q497 -> 4.9009009 | L29: =[24]Brewhouse!$P497 -> 60 | M29: =[24]Brewhouse!$U497-[24]Brewhouse!$T497 -> 0.11111111 | N29: =[24]Brewhouse!$Z497 -> 0.25347222 | O29: =[24]Brewhouse!$AX497 -> R. Regis | R29: =B29 -> CARIB | S29: =VLOOKUP($B29,$R$3:$X$9,2,FALSE) -> 11.6 | T29: =VLOOKUP($B29,$R$3:$X$9,3,FALSE) -> 12 | U29: =VLOOKUP($B29,$R$3:$X$9,4,FALSE) -> 0 | V29: =VLOOKUP($B29,$R$3:$X$9,5,FALSE) -> 0.11805556 | W29: =VLOOKUP($B29,$R$3:$X$9,6,FALSE) -> 0.22569444 | X29: =VLOOKUP($B29,$R$3:$X$9,7,FALSE) -> 0.26388889 | Y29: =VLOOKUP($B29,$R$3:$Z$9,8,FALSE) -> 0 | Z29: =VLOOKUP($B29,$R$3:$Z$9,9,FALSE) -> 60
R30: =B30 -> 0 | S30: =VLOOKUP($B30,$R$3:$X$9,2,FALSE) -> #N/A | T30: =VLOOKUP($B30,$R$3:$X$9,3,FALSE) -> #N/A | U30: =VLOOKUP($B30,$R$3:$X$9,4,FALSE) -> #N/A | V30: =VLOOKUP($B30,$R$3:$X$9,5,FALSE) -> #N/A | W30: =VLOOKUP($B30,$R$3:$X$9,6,FALSE) -> #N/A | X30: =VLOOKUP($B30,$R$3:$X$9,7,FALSE) -> #N/A | Y30: =VLOOKUP($B30,$R$3:$Z$9,8,FALSE) -> #N/A | Z30: =VLOOKUP($B30,$R$3:$Z$9,9,FALSE) -> #N/A
R31: =B31 -> 0 | S31: =VLOOKUP($B31,$R$3:$X$9,2,FALSE) -> #N/A | T31: =VLOOKUP($B31,$R$3:$X$9,3,FALSE) -> #N/A | U31: =VLOOKUP($B31,$R$3:$X$9,4,FALSE) -> #N/A | V31: =VLOOKUP($B31,$R$3:$X$9,5,FALSE) -> #N/A | W31: =VLOOKUP($B31,$R$3:$X$9,6,FALSE) -> #N/A | X31: =VLOOKUP($B31,$R$3:$X$9,7,FALSE) -> #N/A | Y31: =VLOOKUP($B31,$R$3:$Z$9,8,FALSE) -> #N/A | Z31: =VLOOKUP($B31,$R$3:$Z$9,9,FALSE) -> #N/A
R32: =B32 -> 0 | S32: =VLOOKUP($B32,$R$3:$X$9,2,FALSE) -> #N/A | T32: =VLOOKUP($B32,$R$3:$X$9,3,FALSE) -> #N/A | U32: =VLOOKUP($B32,$R$3:$X$9,4,FALSE) -> #N/A | V32: =VLOOKUP($B32,$R$3:$X$9,5,FALSE) -> #N/A | W32: =VLOOKUP($B32,$R$3:$X$9,6,FALSE) -> #N/A | X32: =VLOOKUP($B32,$R$3:$X$9,7,FALSE) -> #N/A | Y32: =VLOOKUP($B32,$R$3:$Z$9,8,FALSE) -> #N/A | Z32: =VLOOKUP($B32,$R$3:$Z$9,9,FALSE) -> #N/A
R33: =B33 -> 0 | S33: =VLOOKUP($B33,$R$3:$X$9,2,FALSE) -> #N/A | T33: =VLOOKUP($B33,$R$3:$X$9,3,FALSE) -> #N/A | U33: =VLOOKUP($B33,$R$3:$X$9,4,FALSE) -> #N/A | V33: =VLOOKUP($B33,$R$3:$X$9,5,FALSE) -> #N/A | W33: =VLOOKUP($B33,$R$3:$X$9,6,FALSE) -> #N/A | X33: =VLOOKUP($B33,$R$3:$X$9,7,FALSE) -> #N/A | Y33: =VLOOKUP($B33,$R$3:$Z$9,8,FALSE) -> #N/A | Z33: =VLOOKUP($B33,$R$3:$Z$9,9,FALSE) -> #N/A
R34: =B34 -> 0 | S34: =VLOOKUP($B34,$R$3:$X$9,2,FALSE) -> #N/A | T34: =VLOOKUP($B34,$R$3:$X$9,3,FALSE) -> #N/A | U34: =VLOOKUP($B34,$R$3:$X$9,4,FALSE) -> #N/A | V34: =VLOOKUP($B34,$R$3:$X$9,5,FALSE) -> #N/A | W34: =VLOOKUP($B34,$R$3:$X$9,6,FALSE) -> #N/A | X34: =VLOOKUP($B34,$R$3:$X$9,7,FALSE) -> #N/A | Y34: =VLOOKUP($B34,$R$3:$Z$9,8,FALSE) -> #N/A | Z34: =VLOOKUP($B34,$R$3:$Z$9,9,FALSE) -> #N/A
R35: =B35 -> 0 | S35: =VLOOKUP($B35,$R$3:$X$9,2,FALSE) -> #N/A | T35: =VLOOKUP($B35,$R$3:$X$9,3,FALSE) -> #N/A | U35: =VLOOKUP($B35,$R$3:$X$9,4,FALSE) -> #N/A | V35: =VLOOKUP($B35,$R$3:$X$9,5,FALSE) -> #N/A | W35: =VLOOKUP($B35,$R$3:$X$9,6,FALSE) -> #N/A | X35: =VLOOKUP($B35,$R$3:$X$9,7,FALSE) -> #N/A | Y35: =VLOOKUP($B35,$R$3:$Z$9,8,FALSE) -> #N/A | Z35: =VLOOKUP($B35,$R$3:$Z$9,9,FALSE) -> #N/A
R36: =B36 -> 0 | S36: =VLOOKUP($B36,$R$3:$X$9,2,FALSE) -> #N/A | T36: =VLOOKUP($B36,$R$3:$X$9,3,FALSE) -> #N/A | U36: =VLOOKUP($B36,$R$3:$X$9,4,FALSE) -> #N/A | V36: =VLOOKUP($B36,$R$3:$X$9,5,FALSE) -> #N/A | W36: =VLOOKUP($B36,$R$3:$X$9,6,FALSE) -> #N/A | X36: =VLOOKUP($B36,$R$3:$X$9,7,FALSE) -> #N/A | Y36: =VLOOKUP($B36,$R$3:$Z$9,8,FALSE) -> #N/A | Z36: =VLOOKUP($B36,$R$3:$Z$9,9,FALSE) -> #N/A
I37: EXTRACT RECOVERY | R37: =B37 -> 0 | S37: =VLOOKUP($B37,$R$3:$X$9,2,FALSE) -> #N/A | T37: =VLOOKUP($B37,$R$3:$X$9,3,FALSE) -> #N/A | U37: =VLOOKUP($B37,$R$3:$X$9,4,FALSE) -> #N/A | V37: =VLOOKUP($B37,$R$3:$X$9,5,FALSE) -> #N/A | W37: =VLOOKUP($B37,$R$3:$X$9,6,FALSE) -> #N/A | X37: =VLOOKUP($B37,$R$3:$X$9,7,FALSE) -> #N/A | Y37: =VLOOKUP($B37,$R$3:$Z$9,8,FALSE) -> #N/A | Z37: =VLOOKUP($B37,$R$3:$Z$9,9,FALSE) -> #N/A
B38: BRAND | D38: BBT P.G./ O.G | I38: Brand | J38: Actual | K38: MTD No. of Brews | L38: MTD | M38: YTD | N38: Target | R38: =B38 -> BRAND | S38: =VLOOKUP($B38,$R$3:$X$9,2,FALSE) -> #N/A | T38: =VLOOKUP($B38,$R$3:$X$9,3,FALSE) -> #N/A | U38: =VLOOKUP($B38,$R$3:$X$9,4,FALSE) -> #N/A | V38: =VLOOKUP($B38,$R$3:$X$9,5,FALSE) -> #N/A | W38: =VLOOKUP($B38,$R$3:$X$9,6,FALSE) -> #N/A | X38: =VLOOKUP($B38,$R$3:$X$9,7,FALSE) -> #N/A | Y38: =VLOOKUP($B38,$R$3:$Z$9,8,FALSE) -> #N/A | Z38: =VLOOKUP($B38,$R$3:$Z$9,9,FALSE) -> #N/A
B39: =I40 -> STAG | C39: =[25]Process!$D$211 -> 12.07 | D39: 11.82 | I39: CARIB | J39: =AVERAGE(I25:I29) -> 99.92363 | K39: =COUNTA([24]Brewhouse!$A$493:$A$497) -> 5 | L39: =AVERAGE([24]Brewhouse!$AU$493:$AU$497) -> 99.92363 | M39: =AVERAGE([24]Brewhouse!$AU$102:$AU$171,[24]Brewhouse!$AU$173:$AU$253,[24]Brewhouse!$AU$255:$AU$339,[24]Brewhouse!$AU$341:$AU$346,[24]Brewhouse!$AU$348,[24]Brewhouse!$AU$349:$AU$406,[24]Brewhouse!$AU$408:$AU$491,[24]Brewhouse!$AU$493:$AU$497) -> 97.689588 | N39: 98
C40: =[25]Process!D218 -> 11.63 | I40: STAG | M40: =AVERAGE([25]Brewhouse!$AS$15:$AS$64,[25]Brewhouse!$AS$66:$AS$103,[25]Brewhouse!$AS$105:$AS$140,[25]Brewhouse!$AS$142:$AS$193,[25]Brewhouse!$AS$195:$AS$240) -> 97.875553 | N40: 98
...

Sheet June 4th
S1: P.G. | U1: Hot Time | W1: Process Time | Y1: Cooling Time
B2: Brewing Department Daily Process Loss Report | S2: Lower | T2: Upper | U2: Lower | V2: Upper | W2: Lower | X2: Upper | Y2: Lower | Z2: Upper
R3: CARIB | S3: 11.6 | T3: 12 | U3: 0 | V3: 0.11805556 | W3: 0.22569444 | X3: 0.26388889 | Y3: 0 | Z3: 60 | AB3: HR- PISNER
B4: Date: | C4: 45813 | J4: LOT WORT COLOUR: 3.3 | M4: Filter Sheets (Target 20 days) | R4: STAG | S4: 11.6 | T4: 12 | U4: 0 | V4: 0.11805556 | W4: 0.22569444 | X4: 0.26388889 | Y4: 0 | Z4: 60
M5: Double | N5: Single | R5: GUINNESS | S5: 17 | T5: 17.5 | U5: 0 | V5: 0.10763889 | W5: 0.24652778 | X5: 0.28472222 | Y5: 0 | Z5: 60
J6: MALT LOT: Lot 37&38 | L6: Sheet Day | R6: MACKESON | S6: 13.3 | T6: 13.5 | U6: 0 | V6: 0.12905093 | W6: 0.27430556 | X6: 0.30208333 | Y6: 0
R7: STARMALT | S7: 17.1 | T7: 17.5 | U7: 0 | V7: 0.13605324 | W7: 0.27430556 | X7: 0.30902778 | Y7: 0 | Z7: 60
B8: Brand | C8: Brew no. | D8: Kett. Hls | E8: Wort | F8: Cool Time(Mins) | G8: Cast. P.G. (Lab Result) | H8: Cast P.G. (Cellar Operator)-gravity | I8: Extr. Rec (79.09%) | J8: Theor. Extr. (77.5%) | K8: Boil Off /Vol. (4-6%) | L8: Boil Time | M8: Total Hot | N8: Brewing | O8: Operator | R8: Hurricane Reef | S8: 16.6 | T8: 17 | U8: 0 | V8: 0.12905093 | W8: 0.27430556 | X8: 0.30208333 | Y8: 0
E9: Meter (Hls) | F9: Target(< 60Mins) | M9: Time | R9: VITAMALT | S9: 14.4 | T9: 14.6 | U9: 0 | V9: 0.13905093 | W9: 0.26041667 | X9: 0.29513889 | Y9: 0 | Z9: 75
B10: CARIB | C10: =[24]Brewhouse!$A498 -> CA392 | D10: =[24]Brewhouse!$AF498 -> 54.1 | E10: =[24]Brewhouse!$AI498 -> 51.3 | F10: =[24]Brewhouse!$V498 -> 70 | G10: =[24]Brewhouse!$AG498 -> 11.9 | H10: 11.8 | I10: =[24]Brewhouse!$AU498 -> 98.531406 | J10: =[24]Brewhouse!$AV498 -> 101.46577 | K10: =[24]Brewhouse!$Q498 -> 6.118068 | L10: =[24]Brewhouse!$P498 -> 60 | M10: =[24]Brewhouse!$U498-[24]Brewhouse!$T498 -> 0.11666667 | N10: =[24]Brewhouse!$Z498 -> 0.25 | O10: =[24]Brewhouse!$AX498 -> R. Regis | R10: =B10 -> CARIB | S10: =VLOOKUP($B10,$R$3:$X$9,2,FALSE) -> 11.6 | T10: =VLOOKUP($B10,$R$3:$X$9,3,FALSE) -> 12 | U10: =VLOOKUP($B10,$R$3:$X$9,4,FALSE) -> 0 | V10: =VLOOKUP($B10,$R$3:$X$9,5,FALSE) -> 0.11805556 | W10: =VLOOKUP($B10,$R$3:$X$9,6,FALSE) -> 0.22569444 | X10: =VLOOKUP($B10,$R$3:$X$9,7,FALSE) -> 0.26388889 | Y10: =VLOOKUP($B10,$R$3:$Z$9,8,FALSE) -> 0 | Z10: =VLOOKUP($B10,$R$3:$Z$9,9,FALSE) -> 60
B11: CARIB | C11: =[24]Brewhouse!$A499 -> CA393 | D11: =[24]Brewhouse!$AF499 -> 54.6 | E11: =[24]Brewhouse!$AI499 -> 52 | F11: =[24]Brewhouse!$V499 -> 71 | G11: =[24]Brewhouse!$AG499 -> 11.7 | H11: 11.8 | I11: =[24]Brewhouse!$AU499 -> 98.232113 | J11: =[24]Brewhouse!$AV499 -> 101.15741 | L11: =[24]Brewhouse!$P499 -> 56 | M11: =[24]Brewhouse!$U499-[24]Brewhouse!$T499 -> 0.11319444 | N11: =[24]Brewhouse!$Z499 -> 0.24375 | O11: =[24]Brewhouse!$AX499 -> D. Gomez | R11: =B11 -> CARIB | S11: =VLOOKUP($B11,$R$3:$X$9,2,FALSE) -> 11.6 | T11: =VLOOKUP($B11,$R$3:$X$9,3,FALSE) -> 12 | U11: =VLOOKUP($B11,$R$3:$X$9,4,FALSE) -> 0 | V11: =VLOOKUP($B11,$R$3:$X$9,5,FALSE) -> 0.11805556 | W11: =VLOOKUP($B11,$R$3:$X$9,6,FALSE) -> 0.22569444 | X11: =VLOOKUP($B11,$R$3:$X$9,7,FALSE) -> 0.26388889 | Y11: =VLOOKUP($B11,$R$3:$Z$9,8,FALSE) -> 0 | Z11: =VLOOKUP($B11,$R$3:$Z$9,9,FALSE) -> 60
B12: CARIB | C12: =[24]Brewhouse!$A500 -> CA394 | D12: =[24]Brewhouse!$AF500 -> 53.8 | E12: =[24]Brewhouse!$AI500 -> 51.6 | F12: =[24]Brewhouse!$V500 -> 82 | G12: =[24]Brewhouse!$AG500 -> 11.7 | H12: 11.8 | I12: =[24]Brewhouse!$AU500 -> 97.476481 | J12: =[24]Brewhouse!$AV500 -> 100.37927 | K12: =[24]Brewhouse!$Q500 -> 5.3308129 | L12: =[24]Brewhouse!$P500 -> 60 | M12: =[24]Brewhouse!$U500-[24]Brewhouse!$T500 -> 0.12361111 | N12: =[24]Brewhouse!$Z500 -> 0.25138889 | O12: =[24]Brewhouse!$AX500 -> D. Gomez | R12: =B12 -> CARIB | S12: =VLOOKUP($B12,$R$3:$X$9,2,FALSE) -> 11.6 | T12: =VLOOKUP($B12,$R$3:$X$9,3,FALSE) -> 12 | U12: =VLOOKUP($B12,$R$3:$X$9,4,FALSE) -> 0 | V12: =VLOOKUP($B12,$R$3:$X$9,5,FALSE) -> 0.11805556 | W12: =VLOOKUP($B12,$R$3:$X$9,6,FALSE) -> 0.22569444 | X12: =VLOOKUP($B12,$R$3:$X$9,7,FALSE) -> 0.26388889 | Y12: =VLOOKUP($B12,$R$3:$Z$9,8,FALSE) -> 0 | Z12: =VLOOKUP($B12,$R$3:$Z$9,9,FALSE) -> 60
B13: CARIB | C13: =[24]Brewhouse!$A501 -> CA395 | D13: =[24]Brewhouse!$AF501 -> 53.1 | E13: =[24]Brewhouse!$AI501 -> 50.5 | F13: =[24]Brewhouse!$V501 -> 66 | G13: =[24]Brewhouse!$AG501 -> 11.8 | H13: 11.8 | I13: =[24]Brewhouse!$AU501 -> 95.636317 | J13: =[24]Brewhouse!$AV501 -> 98.368044 | L13: =[24]Brewhouse!$P501 -> 61 | M13: =[24]Brewhouse!$U501-[24]Brewhouse!$T501 -> 0.11319444 | N13: =[24]Brewhouse!$Z501 -> 0.25 | O13: =[24]Brewhouse!$AX501 -> D. Gomez | R13: =B13 -> CARIB | S13: =VLOOKUP($B13,$R$3:$X$9,2,FALSE) -> 11.6 | T13: =VLOOKUP($B13,$R$3:$X$9,3,FALSE) -> 12 | U13: =VLOOKUP($B13,$R$3:$X$9,4,FALSE) -> 0 | V13: =VLOOKUP($B13,$R$3:$X$9,5,FALSE) -> 0.11805556 | W13: =VLOOKUP($B13,$R$3:$X$9,6,FALSE) -> 0.22569444 | X13: =VLOOKUP($B13,$R$3:$X$9,7,FALSE) -> 0.26388889 | Y13: =VLOOKUP($B13,$R$3:$Z$9,8,FALSE) -> 0 | Z13: =VLOOKUP($B13,$R$3:$Z$9,9,FALSE) -> 60
B14: CARIB | C14: =[24]Brewhouse!$A502 -> CA396 | D14: =[24]Brewhouse!$AF502 -> 52.9 | E14: =[24]Brewhouse!$AI502 -> 50 | F14: =[24]Brewhouse!$V502 -> 58 | G14: =[24]Brewhouse!$AG502 -> 11.9 | H14: 11.8 | I14: =[24]Brewhouse!$AU502 -> 96.480041 | J14: =[24]Brewhouse!$AV502 -> 99.233458 | K14: =[24]Brewhouse!$Q502 -> 6.2522852 | L14: =[24]Brewhouse!$P502 -> 60 | M14: =[24]Brewhouse!$U502-[24]Brewhouse!$T502 -> 0.10625 | N14: =[24]Brewhouse!$Z502 -> 0.24166667 | O14: =[24]Brewhouse!$AX502 -> K.Benjamin | R14: =B14 -> CARIB | S14: =VLOOKUP($B14,$R$3:$X$9,2,FALSE) -> 11.6 | T14: =VLOOKUP($B14,$R$3:$X$9,3,FALSE) -> 12 | U14: =VLOOKUP($B14,$R$3:$X$9,4,FALSE) -> 0 | V14: =VLOOKUP($B14,$R$3:$X$9,5,FALSE) -> 0.11805556 | W14: =VLOOKUP($B14,$R$3:$X$9,6,FALSE) -> 0.22569444 | X14: =VLOOKUP($B14,$R$3:$X$9,7,FALSE) -> 0.26388889 | Y14: =VLOOKUP($B14,$R$3:$Z$9,8,FALSE) -> 0 | Z14: =VLOOKUP($B14,$R$3:$Z$9,9,FALSE) -> 60
B15: CARIB | C15: =[24]Brewhouse!$A503 -> CA397 | D15: =[24]Brewhouse!$AF503 -> 53.4 | E15: =[24]Brewhouse!$AI503 -> 50.5 | F15: =[24]Brewhouse!$V503 -> 61 | G15: =[24]Brewhouse!$AG503 -> 11.9 | I15: =[24]Brewhouse!$AU503 -> 97.204067 | J15: =[24]Brewhouse!$AV503 -> 99.978758 | K15: =[24]Brewhouse!$Q503 -> 2.9834254 | L15: =[24]Brewhouse!$P503 -> 60 | M15: =[24]Brewhouse!$U503-[24]Brewhouse!$T503 -> 0.10902778 | N15: =[24]Brewhouse!$Z503 -> 0.23680556 | O15: =[24]Brewhouse!$AX503 -> K.Benjamin | R15: =B15 -> CARIB | S15: =VLOOKUP($B15,$R$3:$X$9,2,FALSE) -> 11.6 | T15: =VLOOKUP($B15,$R$3:$X$9,3,FALSE) -> 12 | U15: =VLOOKUP($B15,$R$3:$X$9,4,FALSE) -> 0 | V15: =VLOOKUP($B15,$R$3:$X$9,5,FALSE) -> 0.11805556 | W15: =VLOOKUP($B15,$R$3:$X$9,6,FALSE) -> 0.22569444 | X15: =VLOOKUP($B15,$R$3:$X$9,7,FALSE) -> 0.26388889 | Y15: =VLOOKUP($B15,$R$3:$Z$9,8,FALSE) -> 0 | Z15: =VLOOKUP($B15,$R$3:$Z$9,9,FALSE) -> 60
B16: CARIB | C16: =[24]Brewhouse!$A504 -> CA398 | D16: =[24]Brewhouse!$AF504 -> 53.3 | E16: =[24]Brewhouse!$AI504 -> 50.5 | F16: =[24]Brewhouse!$V504 -> 61 | G16: =[24]Brewhouse!$AG504 -> 11.9 | I16: =[24]Brewhouse!$AU504 -> 98.205514 | J16: =[24]Brewhouse!$AV504 -> 101.12857 | K16: =[24]Brewhouse!$Q504 -> 5.4316547 | L16: =[24]Brewhouse!$P504 -> 61 | M16: =[24]Brewhouse!$U504-[24]Brewhouse!$T504 -> 0.11180556 | N16: =[24]Brewhouse!$Z504 -> 0.23958333 | O16: =[24]Brewhouse!$AX504 -> K.Benjamin | R16: =B16 -> CARIB | S16: =VLOOKUP($B16,$R$3:$X$9,2,FALSE) -> 11.6 | T16: =VLOOKUP($B16,$R$3:$X$9,3,FALSE) -> 12 | U16: =VLOOKUP($B16,$R$3:$X$9,4,FALSE) -> 0 | V16: =VLOOKUP($B16,$R$3:$X$9,5,FALSE) -> 0.11805556 | W16: =VLOOKUP($B16,$R$3:$X$9,6,FALSE) -> 0.22569444 | X16: =VLOOKUP($B16,$R$3:$X$9,7,FALSE) -> 0.26388889 | Y16: =VLOOKUP($B16,$R$3:$Z$9,8,FALSE) -> 0 | Z16: =VLOOKUP($B16,$R$3:$Z$9,9,FALSE) -> 60
B17: CARIB | C17: =[24]Brewhouse!$A505 -> CA399 | D17: =[24]Brewhouse!$AF505 -> 53.6 | E17: =[24]Brewhouse!$AI505 -> 51 | F17: =[24]Brewhouse!$V505 -> 66 | G17: =[24]Brewhouse!$AG505 -> 11.7 | H17: 11.8 | I17: =[24]Brewhouse!$AU505 -> 97.425305 | J17: =[24]Brewhouse!$AV505 -> 100.32514 | K17: =[24]Brewhouse!$Q505 -> 3.8827839 | L17: =[24]Brewhouse!$P505 -> 53.2 | M17: =[24]Brewhouse!$U505-[24]Brewhouse!$T505 -> 0.11180556 | N17: =[24]Brewhouse!$Z505 -> 0.24027778 | O17: =[24]Brewhouse!$AX505 -> R. Regis | R17: =B17 -> CARIB | S17: =VLOOKUP($B17,$R$3:$X$9,2,FALSE) -> 11.6 | T17: =VLOOKUP($B17,$R$3:$X$9,3,FALSE) -> 12 | U17: =VLOOKUP($B17,$R$3:$X$9,4,FALSE) -> 0 | V17: =VLOOKUP($B17,$R$3:$X$9,5,FALSE) -> 0.11805556 | W17: =VLOOKUP($B17,$R$3:$X$9,6,FALSE) -> 0.22569444 | X17: =VLOOKUP($B17,$R$3:$X$9,7,FALSE) -> 0.26388889 | Y17: =VLOOKUP($B17,$R$3:$Z$9,8,FALSE) -> 0 | Z17: =VLOOKUP($B17,$R$3:$Z$9,9,FALSE) -> 60
B18: CARIB | C18: =[24]Brewhouse!$A506 -> CA400 | D18: =[24]Brewhouse!$AF506 -> 53.9 | E18: =[24]Brewhouse!$AI506 -> 51.1 | F18: =[24]Brewhouse!$V506 -> 65 | G18: =[24]Brewhouse!$AG506 -> 11.8 | H18: 11.8 | I18: =[24]Brewhouse!$AU506 -> 98.005016 | J18: =[24]Brewhouse!$AV506 -> 100.92275 | K18: =[24]Brewhouse!$Q506 -> 5.0357143 | L18: =[24]Brewhouse!$P506 -> 53.9 | M18: =[24]Brewhouse!$U506-[24]Brewhouse!$T506 -> 0.10902778 | N18: =[24]Brewhouse!$Z506 -> 0.23888889 | O18: =[24]Brewhouse!$AX506 -> R. Regis | R18: =B18 -> CARIB | S18: =VLOOKUP($B18,$R$3:$X$9,2,FALSE) -> 11.6 | T18: =VLOOKUP($B18,$R$3:$X$9,3,FALSE) -> 12 | U18: =VLOOKUP($B18,$R$3:$X$9,4,FALSE) -> 0 | V18: =VLOOKUP($B18,$R$3:$X$9,5,FALSE) -> 0.11805556 | W18: =VLOOKUP($B18,$R$3:$X$9,6,FALSE) -> 0.22569444 | X18: =VLOOKUP($B18,$R$3:$X$9,7,FALSE) -> 0.26388889 | Y18: =VLOOKUP($B18,$R$3:$Z$9,8,FALSE) -> 0 | Z18: =VLOOKUP($B18,$R$3:$Z$9,9,FALSE) -> 60
B19: CARIB | C19: =[24]Brewhouse!$A507 -> CA401 | D19: =[24]Brewhouse!$AF507 -> 52.8 | E19: =[24]Brewhouse!$AI507 -> 50.8 | F19: =[24]Brewhouse!$V507 -> 69 | G19: =[24]Brewhouse!$AG507 -> 11.8 | H19: 11.7 | I19: =[24]Brewhouse!$AU507 -> 97.30879 | J19: =[24]Brewhouse!$AV507 -> 100.20595 | K19: =[24]Brewhouse!$Q507 -> 7 | L19: =[24]Brewhouse!$P507 -> 52.8 | M19: =[24]Brewhouse!$U507-[24]Brewhouse!$T507 -> 0.12013889 | N19: =[24]Brewhouse!$Z507 -> 0.25972222 | O19: =[24]Brewhouse!$AX507 -> R. Regis | R19: =B19 -> CARIB | S19: =VLOOKUP($B19,$R$3:$X$9,2,FALSE) -> 11.6 | T19: =VLOOKUP($B19,$R$3:$X$9,3,FALSE) -> 12 | U19: =VLOOKUP($B19,$R$3:$X$9,4,FALSE) -> 0 | V19: =VLOOKUP($B19,$R$3:$X$9,5,FALSE) -> 0.11805556 | W19: =VLOOKUP($B19,$R$3:$X$9,6,FALSE) -> 0.22569444 | X19: =VLOOKUP($B19,$R$3:$X$9,7,FALSE) -> 0.26388889 | Y19: =VLOOKUP($B19,$R$3:$Z$9,8,FALSE) -> 0 | Z19: =VLOOKUP($B19,$R$3:$Z$9,9,FALSE) -> 60
R20: =B20 -> 0 | S20: =VLOOKUP($B20,$R$3:$X$9,2,FALSE) -> #N/A | T20: =VLOOKUP($B20,$R$3:$X$9,3,FALSE) -> #N/A | U20: =VLOOKUP($B20,$R$3:$X$9,4,FALSE) -> #N/A | V20: =VLOOKUP($B20,$R$3:$X$9,5,FALSE) -> #N/A | W20: =VLOOKUP($B20,$R$3:$X$9,6,FALSE) -> #N/A | X20: =VLOOKUP($B20,$R$3:$X$9,7,FALSE) -> #N/A | Y20: =VLOOKUP($B20,$R$3:$Z$9,8,FALSE) -> #N/A | Z20: =VLOOKUP($B20,$R$3:$Z$9,9,FALSE) -> #N/A
R21: =B21 -> 0 | S21: =VLOOKUP($B21,$R$3:$X$9,2,FALSE) -> #N/A | T21: =VLOOKUP($B21,$R$3:$X$9,3,FALSE) -> #N/A | U21: =VLOOKUP($B21,$R$3:$X$9,4,FALSE) -> #N/A | V21: =VLOOKUP($B21,$R$3:$X$9,5,FALSE) -> #N/A | W21: =VLOOKUP($B21,$R$3:$X$9,6,FALSE) -> #N/A | X21: =VLOOKUP($B21,$R$3:$X$9,7,FALSE) -> #N/A | Y21: =VLOOKUP($B21,$R$3:$Z$9,8,FALSE) -> #N/A | Z21: =VLOOKUP($B21,$R$3:$Z$9,9,FALSE) -> #N/A
R22: =B22 -> 0 | S22: =VLOOKUP($B22,$R$3:$X$9,2,FALSE) -> #N/A | T22: =VLOOKUP($B22,$R$3:$X$9,3,FALSE) -> #N/A | U22: =VLOOKUP($B22,$R$3:$X$9,4,FALSE) -> #N/A | V22: =VLOOKUP($B22,$R$3:$X$9,5,FALSE) -> #N/A | W22: =VLOOKUP($B22,$R$3:$X$9,6,FALSE) -> #N/A | X22: =VLOOKUP($B22,$R$3:$X$9,7,FALSE) -> #N/A | Y22: =VLOOKUP($B22,$R$3:$Z$9,8,FALSE) -> #N/A | Z22: =VLOOKUP($B22,$R$3:$Z$9,9,FALSE) -> #N/A
R23: =B23 -> 0 | S23: =VLOOKUP($B23,$R$3:$X$9,2,FALSE) -> #N/A | T23: =VLOOKUP($B23,$R$3:$X$9,3,FALSE) -> #N/A | U23: =VLOOKUP($B23,$R$3:$X$9,4,FALSE) -> #N/A | V23: =VLOOKUP($B23,$R$3:$X$9,5,FALSE) -> #N/A | W23: =VLOOKUP($B23,$R$3:$X$9,6,FALSE) -> #N/A | X23: =VLOOKUP($B23,$R$3:$X$9,7,FALSE) -> #N/A | Y23: =VLOOKUP($B23,$R$3:$Z$9,8,FALSE) -> #N/A | Z23: =VLOOKUP($B23,$R$3:$Z$9,9,FALSE) -> #N/A
R24: =B24 -> 0 | S24: =VLOOKUP($B24,$R$3:$X$9,2,FALSE) -> #N/A | T24: =VLOOKUP($B24,$R$3:$X$9,3,FALSE) -> #N/A | U24: =VLOOKUP($B24,$R$3:$X$9,4,FALSE) -> #N/A | V24: =VLOOKUP($B24,$R$3:$X$9,5,FALSE) -> #N/A | W24: =VLOOKUP($B24,$R$3:$X$9,6,FALSE) -> #N/A | X24: =VLOOKUP($B24,$R$3:$X$9,7,FALSE) -> #N/A | Y24: =VLOOKUP($B24,$R$3:$Z$9,8,FALSE) -> #N/A | Z24: =VLOOKUP($B24,$R$3:$Z$9,9,FALSE) -> #N/A
R25: =B25 -> 0 | S25: =VLOOKUP($B25,$R$3:$X$9,2,FALSE) -> #N/A | T25: =VLOOKUP($B25,$R$3:$X$9,3,FALSE) -> #N/A | U25: =VLOOKUP($B25,$R$3:$X$9,4,FALSE) -> #N/A | V25: =VLOOKUP($B25,$R$3:$X$9,5,FALSE) -> #N/A | W25: =VLOOKUP($B25,$R$3:$X$9,6,FALSE) -> #N/A | X25: =VLOOKUP($B25,$R$3:$X$9,7,FALSE) -> #N/A | Y25: =VLOOKUP($B25,$R$3:$Z$9,8,FALSE) -> #N/A | Z25: =VLOOKUP($B25,$R$3:$Z$9,9,FALSE) -> #N/A
R26: =B26 -> 0 | S26: =VLOOKUP($B26,$R$3:$X$9,2,FALSE) -> #N/A | T26: =VLOOKUP($B26,$R$3:$X$9,3,FALSE) -> #N/A | U26: =VLOOKUP($B26,$R$3:$X$9,4,FALSE) -> #N/A | V26: =VLOOKUP($B26,$R$3:$X$9,5,FALSE) -> #N/A | W26: =VLOOKUP($B26,$R$3:$X$9,6,FALSE) -> #N/A | X26: =VLOOKUP($B26,$R$3:$X$9,7,FALSE) -> #N/A | Y26: =VLOOKUP($B26,$R$3:$Z$9,8,FALSE) -> #N/A | Z26: =VLOOKUP($B26,$R$3:$Z$9,9,FALSE) -> #N/A
R27: =B27 -> 0 | S27: =VLOOKUP($B27,$R$3:$X$9,2,FALSE) -> #N/A | T27: =VLOOKUP($B27,$R$3:$X$9,3,FALSE) -> #N/A | U27: =VLOOKUP($B27,$R$3:$X$9,4,FALSE) -> #N/A | V27: =VLOOKUP($B27,$R$3:$X$9,5,FALSE) -> #N/A | W27: =VLOOKUP($B27,$R$3:$X$9,6,FALSE) -> #N/A | X27: =VLOOKUP($B27,$R$3:$X$9,7,FALSE) -> #N/A | Y27: =VLOOKUP($B27,$R$3:$Z$9,8,FALSE) -> #N/A | Z27: =VLOOKUP($B27,$R$3:$Z$9,9,FALSE) -> #N/A
R28: =B28 -> 0 | S28: =VLOOKUP($B28,$R$3:$X$9,2,FALSE) -> #N/A | T28: =VLOOKUP($B28,$R$3:$X$9,3,FALSE) -> #N/A | U28: =VLOOKUP($B28,$R$3:$X$9,4,FALSE) -> #N/A | V28: =VLOOKUP($B28,$R$3:$X$9,5,FALSE) -> #N/A | W28: =VLOOKUP($B28,$R$3:$X$9,6,FALSE) -> #N/A | X28: =VLOOKUP($B28,$R$3:$X$9,7,FALSE) -> #N/A | Y28: =VLOOKUP($B28,$R$3:$Z$9,8,FALSE) -> #N/A | Z28: =VLOOKUP($B28,$R$3:$Z$9,9,FALSE) -> #N/A
R29: =B29 -> 0 | S29: =VLOOKUP($B29,$R$3:$X$9,2,FALSE) -> #N/A | T29: =VLOOKUP($B29,$R$3:$X$9,3,FALSE) -> #N/A | U29: =VLOOKUP($B29,$R$3:$X$9,4,FALSE) -> #N/A | V29: =VLOOKUP($B29,$R$3:$X$9,5,FALSE) -> #N/A | W29: =VLOOKUP($B29,$R$3:$X$9,6,FALSE) -> #N/A | X29: =VLOOKUP($B29,$R$3:$X$9,7,FALSE) -> #N/A | Y29: =VLOOKUP($B29,$R$3:$Z$9,8,FALSE) -> #N/A | Z29: =VLOOKUP($B29,$R$3:$Z$9,9,FALSE) -> #N/A
R30: =B30 -> 0 | S30: =VLOOKUP($B30,$R$3:$X$9,2,FALSE) -> #N/A | T30: =VLOOKUP($B30,$R$3:$X$9,3,FALSE) -> #N/A | U30: =VLOOKUP($B30,$R$3:$X$9,4,FALSE) -> #N/A | V30: =VLOOKUP($B30,$R$3:$X$9,5,FALSE) -> #N/A | W30: =VLOOKUP($B30,$R$3:$X$9,6,FALSE) -> #N/A | X30: =VLOOKUP($B30,$R$3:$X$9,7,FALSE) -> #N/A | Y30: =VLOOKUP($B30,$R$3:$Z$9,8,FALSE) -> #N/A | Z30: =VLOOKUP($B30,$R$3:$Z$9,9,FALSE) -> #N/A
R31: =B31 -> 0 | S31: =VLOOKUP($B31,$R$3:$X$9,2,FALSE) -> #N/A | T31: =VLOOKUP($B31,$R$3:$X$9,3,FALSE) -> #N/A | U31: =VLOOKUP($B31,$R$3:$X$9,4,FALSE) -> #N/A | V31: =VLOOKUP($B31,$R$3:$X$9,5,FALSE) -> #N/A | W31: =VLOOKUP($B31,$R$3:$X$9,6,FALSE) -> #N/A | X31: =VLOOKUP($B31,$R$3:$X$9,7,FALSE) -> #N/A | Y31: =VLOOKUP($B31,$R$3:$Z$9,8,FALSE) -> #N/A | Z31: =VLOOKUP($B31,$R$3:$Z$9,9,FALSE) -> #N/A
... R36: =B36 -> 0 | S36: =VLOOKUP($B36,$R$3:$X$9,2,FALSE) -> #N/A | T36: =VLOOKUP($B36,$R$3:$X$9,3,FALSE) -> #N/A | U36: =VLOOKUP($B36,$R$3:$X$9,4,FALSE) -> #N/A | V36: =VLOOKUP($B36,$R$3:$X$9,5,FALSE) -> #N/A | W36: =VLOOKUP($B36,$R$3:$X$9,6,FALSE) -> #N/A | X36: =VLOOKUP($B36,$R$3:$X$9,7,FALSE) -> #N/A | Y36: =VLOOKUP($B36,$R$3:$Z$9,8,FALSE) -> #N/A | Z36: =VLOOKUP($B36,$R$3:$Z$9,9,FALSE) -> #N/A
I37: EXTRACT RECOVERY | R37: =B37 -> 0 | S37: =VLOOKUP($B37,$R$3:$X$9,2,FALSE) -> #N/A | T37: =VLOOKUP($B37,$R$3:$X$9,3,FALSE) -> #N/A | U37: =VLOOKUP($B37,$R$3:$X$9,4,FALSE) -> #N/A | V37: =VLOOKUP($B37,$R$3:$X$9,5,FALSE) -> #N/A | W37: =VLOOKUP($B37,$R$3:$X$9,6,FALSE) -> #N/A | X37: =VLOOKUP($B37,$R$3:$X$9,7,FALSE) -> #N/A | Y37: =VLOOKUP($B37,$R$3:$Z$9,8,FALSE) -> #N/A | Z37: =VLOOKUP($B37,$R$3:$Z$9,9,FALSE) -> #N/A
B38: BRAND | D38: BBT P.G./ O.G | I38: Brand | J38: Actual | K38: MTD No. of Brews | L38: MTD | M38: YTD | N38: Target | R38: =B38 -> BRAND | S38: =VLOOKUP($B38,$R$3:$X$9,2,FALSE) -> #N/A | T38: =VLOOKUP($B38,$R$3:$X$9,3,FALSE) -> #N/A | U38: =VLOOKUP($B38,$R$3:$X$9,4,FALSE) -> #N/A | V38: =VLOOKUP($B38,$R$3:$X$9,5,FALSE) -> #N/A | W38: =VLOOKUP($B38,$R$3:$X$9,6,FALSE) -> #N/A | X38: =VLOOKUP($B38,$R$3:$X$9,7,FALSE) -> #N/A | Y38: =VLOOKUP($B38,$R$3:$Z$9,8,FALSE) -> #N/A | Z38: =VLOOKUP($B38,$R$3:$Z$9,9,FALSE) -> #N/A
B39: =I39 -> CARIB | C39: =[24]Process!D432 -> 12.28 | D39: 11.92 | I39: CARIB | J39: =AVERAGE(I10:I19) -> 97.450505 | K39: =COUNTA([24]Brewhouse!$A$493:$A$507) -> 15 | L39: =AVERAGE([24]Brewhouse!$AU$493:$AU$507) -> 98.27488 | M39: =AVERAGE([24]Brewhouse!$AU$102:$AU$171,[24]Brewhouse!$AU$173:$AU$253,[24]Brewhouse!$AU$255:$AU$339,[24]Brewhouse!$AU$341:$AU$346,[24]Brewhouse!$AU$348,[24]Brewhouse!$AU$349:$AU$406,[24]Brewhouse!$AU$408:$AU$491,[24]Brewhouse!$AU$493:$AU$507) -> 97.683611 | N39: 98
C40: =[24]Process!D433 -> 12.43 | I40: STAG | M40: =AVERAGE([25]Brewhouse!$AS$15:$AS$64,[25]Brewhouse!$AS$66:$AS$103,[25]Brewhouse!$AS$105:$AS$140,[25]Brewhouse!$AS$142:$AS$193,[25]Brewhouse!$AS$195:$AS$240) -> 97.875553 | N40: 98
C41: =[24]Process!D456 -> 11.71 | D41: 11.96 | I41: GUINNESS | M41: =AVERAGE([26]Brewhouse!$AU$4:$AU$7,[26]Brewhouse!$AU$9:$AU$22,[26]Brewhouse!$AU$24:$AU$35,[26]Brewhouse!$AU$37:$AU$45,[26]Brewhouse!$AU$47:$AU$62) -> 97.179377 | N41: 98
