Workbook
Name ProductList: [1]November15!$R$3:$R$9
Name ProductList: [2]November15!$R$3:$R$9

Sheet Dec 18th
T1: P.G. | V1: Hot Time | X1: Process Time | Z1: Cooling Time
B2: Brewing Department Daily Process Loss Report | T2: Lower | U2: Upper | V2: Lower | W2: Upper | X2: Lower | Y2: Upper | Z2: Lower | AA2: Upper
S3: CARIB | T3: 11.6 | U3: 12 | V3: 0 | W3: 0.11805556 | X3: 0.17361111 | Y3: 0.21180556 | Z3: 0 | AA3: 60 | AC3: HR- PISNER
B4: Date: | C4: 45278 | J4: LOT WORT COLOUR: 3.4 | M4: Filter Sheets (Target 20 days) | S4: STAG | T4: 11.6 | U4: 12 | V4: 0 | W4: 0.11805556 | X4: 0.17361111 | Y4: 0.21180556 | Z4: 0 | AA4: 60
M5: Double | N5: Single | S5: GUINNESS | T5: 17 | U5: 17.5 | V5: 0 | W5: 0.10763889 | X5: 0.19444444 | Y5: 0.23263889 | Z5: 0 | AA5: 60
J6: MALT LOT: Lot 8 | L6: Sheet Day | S6: MACKESON | T6: 13.3 | U6: 13.5 | V6: 0 | W6: 0.12905093 | X6: 0.22222222 | Y6: 0.25347222 | Z6: 0
S7: STARMALT | T7: 17.1 | U7: 17.5 | V7: 0 | W7: 0.13605324 | X7: 0.20833333 | Y7: 0.24305556 | Z7: 0 | AA7: 60
B8: Brand | C8: Brew no. | D8: Kett. Hls | E8: Wort | F8: Cool Time(Mins) | G8: Cast. P.G. (Lab Result) | H8: Cast P.G. (Cellar Operator)-gravity | I8: Extr. Rec (79.1%) | J8: Theor. Extr. (77.5%) | K8: Boil Off /Vol. (4-6%) | L8: Boil Time | M8: Total Hot | N8: Brewing | P8: Comments | Q8: Actual Pilsen Malt | S8: Hurricane Reef | T8: 16.6 | U8: 17 | V8: 0 | W8: 0.12905093 | X8: 0.22222222 | Y8: 0.25347222 | Z8: 0
E9: Meter (Hls) | F9: Target(< 60Mins) | M9: Time | S9: VITAMALT | T9: 14.4 | U9: 14.6 | V9: 0 | W9: 0.13905093 | X9: 0.19097222 | Y9: 0.22569444 | Z9: 0 | AA9: 75
S10: =B10 -> 0 | T10: =VLOOKUP($B10,$S$3:$Y$9,2,FALSE) -> #N/A | U10: =VLOOKUP($B10,$S$3:$Y$9,3,FALSE) -> #N/A | V10: =VLOOKUP($B10,$S$3:$Y$9,4,FALSE) -> #N/A | W10: =VLOOKUP($B10,$S$3:$Y$9,5,FALSE) -> #N/A | X10: =VLOOKUP($B10,$S$3:$Y$9,6,FALSE) -> #N/A | Y10: =VLOOKUP($B10,$S$3:$Y$9,7,FALSE) -> #N/A | Z10: =VLOOKUP($B10,$S$3:$AA$9,8,FALSE) -> #N/A | AA10: =VLOOKUP($B10,$S$3:$AA$9,9,FALSE) -> #N/A
S11: =B11 -> 0 | T11: =VLOOKUP($B11,$S$3:$Y$9,2,FALSE) -> #N/A | U11: =VLOOKUP($B11,$S$3:$Y$9,3,FALSE) -> #N/A | V11: =VLOOKUP($B11,$S$3:$Y$9,4,FALSE) -> #N/A | W11: =VLOOKUP($B11,$S$3:$Y$9,5,FALSE) -> #N/A | X11: =VLOOKUP($B11,$S$3:$Y$9,6,FALSE) -> #N/A | Y11: =VLOOKUP($B11,$S$3:$Y$9,7,FALSE) -> #N/A | Z11: =VLOOKUP($B11,$S$3:$AA$9,8,FALSE) -> #N/A | AA11: =VLOOKUP($B11,$S$3:$AA$9,9,FALSE) -> #N/A
S12: =B12 -> 0 | T12: =VLOOKUP($B12,$S$3:$Y$9,2,FALSE) -> #N/A | U12: =VLOOKUP($B12,$S$3:$Y$9,3,FALSE) -> #N/A | V12: =VLOOKUP($B12,$S$3:$Y$9,4,FALSE) -> #N/A | W12: =VLOOKUP($B12,$S$3:$Y$9,5,FALSE) -> #N/A | X12: =VLOOKUP($B12,$S$3:$Y$9,6,FALSE) -> #N/A | Y12: =VLOOKUP($B12,$S$3:$Y$9,7,FALSE) -> #N/A | Z12: =VLOOKUP($B12,$S$3:$AA$9,8,FALSE) -> #N/A | AA12: =VLOOKUP($B12,$S$3:$AA$9,9,FALSE) -> #N/A
S13: =B13 -> 0 | T13: =VLOOKUP($B13,$S$3:$Y$9,2,FALSE) -> #N/A | U13: =VLOOKUP($B13,$S$3:$Y$9,3,FALSE) -> #N/A | V13: =VLOOKUP($B13,$S$3:$Y$9,4,FALSE) -> #N/A | W13: =VLOOKUP($B13,$S$3:$Y$9,5,FALSE) -> #N/A | X13: =VLOOKUP($B13,$S$3:$Y$9,6,FALSE) -> #N/A | Y13: =VLOOKUP($B13,$S$3:$Y$9,7,FALSE) -> #N/A | Z13: =VLOOKUP($B13,$S$3:$AA$9,8,FALSE) -> #N/A | AA13: =VLOOKUP($B13,$S$3:$AA$9,9,FALSE) -> #N/A
S14: =B14 -> 0 | T14: =VLOOKUP($B14,$S$3:$Y$9,2,FALSE) -> #N/A | U14: =VLOOKUP($B14,$S$3:$Y$9,3,FALSE) -> #N/A | V14: =VLOOKUP($B14,$S$3:$Y$9,4,FALSE) -> #N/A | W14: =VLOOKUP($B14,$S$3:$Y$9,5,FALSE) -> #N/A | X14: =VLOOKUP($B14,$S$3:$Y$9,6,FALSE) -> #N/A | Y14: =VLOOKUP($B14,$S$3:$Y$9,7,FALSE) -> #N/A | Z14: =VLOOKUP($B14,$S$3:$AA$9,8,FALSE) -> #N/A | AA14: =VLOOKUP($B14,$S$3:$AA$9,9,FALSE) -> #N/A
S15: =B15 -> 0 | T15: =VLOOKUP($B15,$S$3:$Y$9,2,FALSE) -> #N/A | U15: =VLOOKUP($B15,$S$3:$Y$9,3,FALSE) -> #N/A | V15: =VLOOKUP($B15,$S$3:$Y$9,4,FALSE) -> #N/A | W15: =VLOOKUP($B15,$S$3:$Y$9,5,FALSE) -> #N/A | X15: =VLOOKUP($B15,$S$3:$Y$9,6,FALSE) -> #N/A | Y15: =VLOOKUP($B15,$S$3:$Y$9,7,FALSE) -> #N/A | Z15: =VLOOKUP($B15,$S$3:$AA$9,8,FALSE) -> #N/A | AA15: =VLOOKUP($B15,$S$3:$AA$9,9,FALSE) -> #N/A
S16: =B16 -> 0 | T16: =VLOOKUP($B16,$S$3:$Y$9,2,FALSE) -> #N/A | U16: =VLOOKUP($B16,$S$3:$Y$9,3,FALSE) -> #N/A | V16: =VLOOKUP($B16,$S$3:$Y$9,4,FALSE) -> #N/A | W16: =VLOOKUP($B16,$S$3:$Y$9,5,FALSE) -> #N/A | X16: =VLOOKUP($B16,$S$3:$Y$9,6,FALSE) -> #N/A | Y16: =VLOOKUP($B16,$S$3:$Y$9,7,FALSE) -> #N/A | Z16: =VLOOKUP($B16,$S$3:$AA$9,8,FALSE) -> #N/A | AA16: =VLOOKUP($B16,$S$3:$AA$9,9,FALSE) -> #N/A
S17: =B17 -> 0 | T17: =VLOOKUP($B17,$S$3:$Y$9,2,FALSE) -> #N/A | U17: =VLOOKUP($B17,$S$3:$Y$9,3,FALSE) -> #N/A | V17: =VLOOKUP($B17,$S$3:$Y$9,4,FALSE) -> #N/A | W17: =VLOOKUP($B17,$S$3:$Y$9,5,FALSE) -> #N/A | X17: =VLOOKUP($B17,$S$3:$Y$9,6,FALSE) -> #N/A | Y17: =VLOOKUP($B17,$S$3:$Y$9,7,FALSE) -> #N/A | Z17: =VLOOKUP($B17,$S$3:$AA$9,8,FALSE) -> #N/A | AA17: =VLOOKUP($B17,$S$3:$AA$9,9,FALSE) -> #N/A
S18: =B18 -> 0 | T18: =VLOOKUP($B18,$S$3:$Y$9,2,FALSE) -> #N/A | U18: =VLOOKUP($B18,$S$3:$Y$9,3,FALSE) -> #N/A | V18: =VLOOKUP($B18,$S$3:$Y$9,4,FALSE) -> #N/A | W18: =VLOOKUP($B18,$S$3:$Y$9,5,FALSE) -> #N/A | X18: =VLOOKUP($B18,$S$3:$Y$9,6,FALSE) -> #N/A | Y18: =VLOOKUP($B18,$S$3:$Y$9,7,FALSE) -> #N/A | Z18: =VLOOKUP($B18,$S$3:$AA$9,8,FALSE) -> #N/A | AA18: =VLOOKUP($B18,$S$3:$AA$9,9,FALSE) -> #N/A
S19: =B19 -> 0 | T19: =VLOOKUP($B19,$S$3:$Y$9,2,FALSE) -> #N/A | U19: =VLOOKUP($B19,$S$3:$Y$9,3,FALSE) -> #N/A | V19: =VLOOKUP($B19,$S$3:$Y$9,4,FALSE) -> #N/A | W19: =VLOOKUP($B19,$S$3:$Y$9,5,FALSE) -> #N/A | X19: =VLOOKUP($B19,$S$3:$Y$9,6,FALSE) -> #N/A | Y19: =VLOOKUP($B19,$S$3:$Y$9,7,FALSE) -> #N/A | Z19: =VLOOKUP($B19,$S$3:$AA$9,8,FALSE) -> #N/A | AA19: =VLOOKUP($B19,$S$3:$AA$9,9,FALSE) -> #N/A
S20: =B20 -> 0 | T20: =VLOOKUP($B20,$S$3:$Y$9,2,FALSE) -> #N/A | U20: =VLOOKUP($B20,$S$3:$Y$9,3,FALSE) -> #N/A | V20: =VLOOKUP($B20,$S$3:$Y$9,4,FALSE) -> #N/A | W20: =VLOOKUP($B20,$S$3:$Y$9,5,FALSE) -> #N/A | X20: =VLOOKUP($B20,$S$3:$Y$9,6,FALSE) -> #N/A | Y20: =VLOOKUP($B20,$S$3:$Y$9,7,FALSE) -> #N/A | Z20: =VLOOKUP($B20,$S$3:$AA$9,8,FALSE) -> #N/A | AA20: =VLOOKUP($B20,$S$3:$AA$9,9,FALSE) -> #N/A
S21: =B21 -> 0 | T21: =VLOOKUP($B21,$S$3:$Y$9,2,FALSE) -> #N/A | U21: =VLOOKUP($B21,$S$3:$Y$9,3,FALSE) -> #N/A | V21: =VLOOKUP($B21,$S$3:$Y$9,4,FALSE) -> #N/A | W21: =VLOOKUP($B21,$S$3:$Y$9,5,FALSE) -> #N/A | X21: =VLOOKUP($B21,$S$3:$Y$9,6,FALSE) -> #N/A | Y21: =VLOOKUP($B21,$S$3:$Y$9,7,FALSE) -> #N/A | Z21: =VLOOKUP($B21,$S$3:$AA$9,8,FALSE) -> #N/A | AA21: =VLOOKUP($B21,$S$3:$AA$9,9,FALSE) -> #N/A
... S47: =B47 -> 0 | T47: =VLOOKUP($B47,$S$3:$Y$9,2,FALSE) -> #N/A | U47: =VLOOKUP($B47,$S$3:$Y$9,3,FALSE) -> #N/A | V47: =VLOOKUP($B47,$S$3:$Y$9,4,FALSE) -> #N/A | W47: =VLOOKUP($B47,$S$3:$Y$9,5,FALSE) -> #N/A | X47: =VLOOKUP($B47,$S$3:$Y$9,6,FALSE) -> #N/A | Y47: =VLOOKUP($B47,$S$3:$Y$9,7,FALSE) -> #N/A | Z47: =VLOOKUP($B47,$S$3:$AA$9,8,FALSE) -> #N/A | AA47: =VLOOKUP($B47,$S$3:$AA$9,9,FALSE) -> #N/A
I48: EXTRACT RECOVERY
B49: BRAND | D49: BBT P.G./ O.G | I49: Brand | J49: Actual | K49: MTD No. of Brews | L49: MTD | M49: YTD | N49: Target
B50: STAG | C50: 11.8 | D50: 11.73 | I50: CARIB | K50: =COUNTA([17]Brewhouse!$A$1596:$A$1619) -> 24 | L50: =AVERAGE([17]Brewhouse!$AU$1529,[17]Brewhouse!$AU$1531:$AU$1594,[17]Brewhouse!$AU$1596:$AU$1619) -> 98.205761 | M50: =AVERAGE([17]Brewhouse!$AU$849:$AU$924,[17]Brewhouse!$AU$926:$AU$971,[17]Brewhouse!$AU$973:$AU$1066,[17]Brewhouse!$AU$1068:$AU$1111,[17]Brewhouse!$AU$1113:$AU$1132,[17]Brewhouse!$AU$1134:$AU$1167,[17]Brewhouse!$AU$1169:$AU$1230,[17]Brewhouse!$AU$1232:$AU$1299,[17]Brewhouse!$AU$1301:$AU$1363,[17]Brewhouse!$AU$1365:$AU$1444,[17]Brewhouse!$AU$1446:$AU$1527,[17]Brewhouse!$AU$1529,[17]Brewhouse!$AU$1531:$AU$1594,[17]Brewhouse!$AU$1596:$AU$1619) -> 98.381806 | N50: 98
C51: 11.9 | I51: STAG | K51: =COUNTA([18]Brewhouse!$A$976:$A$1007) -> 32 | L51: =AVERAGE([18]Brewhouse!$AS$976:$AS$979,[18]Brewhouse!$AS$981:$AS$1007) -> 98.538567 | M51: =AVERAGE([18]Brewhouse!$AS$577:$AS$618,[18]Brewhouse!$AS$620:$AS$651,[18]Brewhouse!$AS$653:$AS$696,[18]Brewhouse!$AS$698:$AS$708,[18]Brewhouse!$AS$710:$AS$733,[18]Brewhouse!$AS$735:$AS$777,[18]Brewhouse!$AS$779:$AS$822,[18]Brewhouse!$AS$824:$AS$863,[18]Brewhouse!$AS$865:$AS$974,[18]Brewhouse!$AS$976:$AS$979,[18]Brewhouse!$AS$981:$AS$1007) -> 98.489671 | N51: 98
I52: GUINNESS | K52: =COUNTA([19]Brewhouse!$A$282:$A$289) -> 8 | L52: =AVERAGE([19]Brewhouse!$AU$269:$AU$279,[19]Brewhouse!$AU$282:$AU$289) -> 96.186177 | M52: =AVERAGE([19]Brewhouse!$AU$161:$AU$176,[19]Brewhouse!$AU$178:$AU$195,[19]Brewhouse!$AU$197:$AU$208,[19]Brewhouse!$AU$210:$AU$221,[19]Brewhouse!$AU$223:$AU$232,[19]Brewhouse!$AU$234:$AU$279,[19]Brewhouse!$AU$282:$AU$289) -> 96.64916 | N52: 98
I53: VITAMALT | K53: =COUNTA([20]Brewhouse!$A$158:$A$163) -> 6 | L53: =AVERAGE([20]Brewhouse!$AU$158:$AU$163) -> 94.60305 | M53: =AVERAGE([20]Brewhouse!$AU$91:$AU$101,[20]Brewhouse!$AU$103:$AU$112,[20]Brewhouse!$AU$114:$AU$123,[20]Brewhouse!$AU$125:$AU$134,[20]Brewhouse!$AU$136:$AU$145,[20]Brewhouse!$AU$147:$AU$156,[20]Brewhouse!$AU$158:$AU$163) -> 96.240014 | N53: 98
I54: MAXIMALT | N54: 98
I55: MACKESON | M55: =AVERAGE([21]Brewhouse!$AT$74:$AT$79) -> 93.959836 | N55: 98
I56: STARMALT | K56: =COUNTA([22]Brewhouse!$A$249:$A$254) -> 6 | L56: =AVERAGE([22]Brewhouse!$AY$249:$AY$254) -> 99.681996 | M56: =AVERAGE([22]Brewhouse!$AY$138:$AY$143,[22]Brewhouse!$AY$145:$AY$153,[22]Brewhouse!$AY$155,[22]Brewhouse!$AY$156:$AY$174,[22]Brewhouse!$AY$176:$AY$185,[22]Brewhouse!$AY$187:$AY$198,[22]Brewhouse!$AY$200:$AY$247,[22]Brewhouse!$AY$249:$AY$254) -> 98.774703 | N56: 98
I57: HR- P | M57: =AVERAGE([23]Brewhouse!$AW$13:$AW$14,[23]Brewhouse!$AW$16:$AW$17) -> 92.042628 | N57: 98
I58: Hurricane Reef | M58: =AVERAGE([23]Brewhouse!$AW$13:$AW$14) -> 88.376943 | N58: 98
K59: =SUM(K50:K58) -> 76 | L59: =((L50*K50)+(L51*K51)+(L52*K52)+(L53*K53)+(L54*K54)+(K57*L57)+(L55*K55)+(L56*K56)+(L58*K58))/(K59) -> 97.965422 | M59: =AVERAGE('[24]Closing- January 2023'!$L$42,'[25]Feb. 28th'!$L$42,'[26]March 31st'!$L$75,'[27]Apri 28th'!$L$51,L59) -> 98.06926 | N59: 98
J62: Daily Brewing Plan
J63: Brand | K63: Brews Achieved | L63: Average Brews per day
J64: CARIB | L64: MTD | M64: YTD | N64: TARGET
J65: STAG | K65: 5 | L65: =AVERAGE(#REF!,#REF!,K74,#REF!,#REF!,#REF!,#REF!,#REF!,#REF!,#REF!,#REF!) -> #REF! | M65: =AVERAGE(6,6,'[26]March 31st'!$L$80,'[28]June 30th '!$L$71,6,L65,'[29]July 31st'!$L$108,'[30]Aug 30th'!$L$124,7,[31]Oct.31st!$L$51) -> #REF! | N65: 9
J66: GUINN
J67: VITAMALT
...

Sheet June 2nd
S1: P.G. | U1: Hot Time | W1: Process Time | Y1: Cooling Time
B2: Brewing Department Daily Process Loss Report | S2: Lower | T2: Upper | U2: Lower | V2: Upper | W2: Lower | X2: Upper | Y2: Lower | Z2: Upper
R3: CARIB | S3: 11.6 | T3: 12 | U3: 0 | V3: 0.11805556 | W3: 0.22569444 | X3: 0.26388889 | Y3: 0 | Z3: 60 | AB3: HR- PISNER
B4: Date: | C4: 46174 | J4: LOT WORT COLOUR: | M4: Filter Sheets (Target 20 days) | R4: STAG | S4: 11.6 | T4: 12 | U4: 0 | V4: 0.11805556 | W4: 0.22569444 | X4: 0.26388889 | Y4: 0 | Z4: 60
M5: Double | N5: Single | R5: GUINNESS | S5: 17 | T5: 17.5 | U5: 0 | V5: 0.10763889 | W5: 0.24652778 | X5: 0.28472222 | Y5: 0 | Z5: 60
J6: MALT LOT: Lot #13 | L6: Sheet Day | R6: MACKESON | S6: 13.3 | T6: 13.5 | U6: 0 | V6: 0.12905093 | W6: 0.27430556 | X6: 0.30208333 | Y6: 0
R7: STARMALT | S7: 17 | T7: 17.4 | U7: 0 | V7: 0.13605324 | W7: 0.27430556 | X7: 0.30902778 | Y7: 0 | Z7: 85
B8: Brand | C8: Brew no. | D8: Kett. Hls | E8: Wort | F8: Cool Time(Mins) | G8: Cast. P.G. (Lab Result) | H8: Cast P.G. (Cellar Operator)-gravity | I8: Extr. Rec (77.9%) | J8: Theor. Extr. (77.5%) | K8: Boil Off /Vol. (4-6%) | L8: Boil Time | M8: Total Hot | N8: Brewing Time | O8: Operator | R8: Hurricane Reef | S8: 16.6 | T8: 17 | U8: 0 | V8: 0.12905093 | W8: 0.27430556 | X8: 0.30208333 | Y8: 0
E9: Meter (Hls) | F9: Target(< 60Mins) | M9: Time | R9: VITAMALT | S9: 14.2 | T9: 14.6 | U9: 0 | V9: 0.13905093 | W9: 0.26041667 | X9: 0.29513889 | Y9: 0 | Z9: 75
B10: CARIB | C10: =[3]Brewhouse!$A441 -> CA395 | D10: =[3]Brewhouse!$AF441 -> 47.9 | E10: =[3]Brewhouse!$AI441 -> 47.9 | F10: =[3]Brewhouse!$V441 -> 60 | G10: =[3]Brewhouse!AG441 -> 12 | H10: 12.2 | I10: =[3]Brewhouse!$AU441 -> 94.352991 | J10: =[3]Brewhouse!$AV441 -> 95.174307 | K10: =[3]Brewhouse!$Q441 -> 12.62963 | L10: =[3]Brewhouse!$P441 -> 57 | M10: =[3]Brewhouse!$U441-[3]Brewhouse!$T441 -> 0.12708333 | N10: =[3]Brewhouse!$Z441 -> 0.32847222 | O10: =[3]Brewhouse!$AX441 -> R. Regis | R10: =B10 -> CARIB | S10: =VLOOKUP($B10,$R$3:$X$9,2,FALSE) -> 11.6 | T10: =VLOOKUP($B10,$R$3:$X$9,3,FALSE) -> 12 | U10: =VLOOKUP($B10,$R$3:$X$9,4,FALSE) -> 0 | V10: =VLOOKUP($B10,$R$3:$X$9,5,FALSE) -> 0.11805556 | W10: =VLOOKUP($B10,$R$3:$X$9,6,FALSE) -> 0.22569444 | X10: =VLOOKUP($B10,$R$3:$X$9,7,FALSE) -> 0.26388889 | Y10: =VLOOKUP($B10,$R$3:$Z$9,8,FALSE) -> 0 | Z10: =VLOOKUP($B10,$R$3:$Z$9,9,FALSE) -> 60
B11: CARIB | C11: =[3]Brewhouse!$A442 -> CA396 | D11: =[3]Brewhouse!$AF442 -> 50.4 | E11: =[3]Brewhouse!$AI442 -> 50.1 | F11: =[3]Brewhouse!$V442 -> 47 | G11: =[3]Brewhouse!AG442 -> 12 | H11: 11.8 | I11: =[3]Brewhouse!$AU442 -> 99.788106 | J11: =[3]Brewhouse!$AV442 -> 100.65623 | K11: =[3]Brewhouse!$Q442 -> 9.6487985 | L11: =[3]Brewhouse!$P442 -> 60 | M11: =[3]Brewhouse!$U442-[3]Brewhouse!$T442 -> 0.10555556 | N11: =[3]Brewhouse!$Z442 -> 0.26527778 | O11: =[3]Brewhouse!$AX442 -> R. Sookram | R11: =B11 -> CARIB | S11: =VLOOKUP($B11,$R$3:$X$9,2,FALSE) -> 11.6 | T11: =VLOOKUP($B11,$R$3:$X$9,3,FALSE) -> 12 | U11: =VLOOKUP($B11,$R$3:$X$9,4,FALSE) -> 0 | V11: =VLOOKUP($B11,$R$3:$X$9,5,FALSE) -> 0.11805556 | W11: =VLOOKUP($B11,$R$3:$X$9,6,FALSE) -> 0.22569444 | X11: =VLOOKUP($B11,$R$3:$X$9,7,FALSE) -> 0.26388889 | Y11: =VLOOKUP($B11,$R$3:$Z$9,8,FALSE) -> 0 | Z11: =VLOOKUP($B11,$R$3:$Z$9,9,FALSE) -> 60
B12: CARIB | C12: =[3]Brewhouse!$A443 -> CA397 | D12: =[3]Brewhouse!$AF443 -> 49.8 | E12: =[3]Brewhouse!$AI443 -> 49.5 | F12: =[3]Brewhouse!$V443 -> 50 | G12: =[3]Brewhouse!AG443 -> 12 | H12: 12 | I12: =[3]Brewhouse!$AU443 -> 98.715472 | J12: =[3]Brewhouse!$AV443 -> 99.574203 | K12: =[3]Brewhouse!$Q443 -> 11.333333 | L12: =[3]Brewhouse!$P443 -> 60 | M12: =[3]Brewhouse!$U443-[3]Brewhouse!$T443 -> 0.10069444 | N12: =[3]Brewhouse!$Z443 -> 0.25694444 | O12: =[3]Brewhouse!$AX443 -> R. Sookram | R12: =B12 -> CARIB | S12: =VLOOKUP($B12,$R$3:$X$9,2,FALSE) -> 11.6 | T12: =VLOOKUP($B12,$R$3:$X$9,3,FALSE) -> 12 | U12: =VLOOKUP($B12,$R$3:$X$9,4,FALSE) -> 0 | V12: =VLOOKUP($B12,$R$3:$X$9,5,FALSE) -> 0.11805556 | W12: =VLOOKUP($B12,$R$3:$X$9,6,FALSE) -> 0.22569444 | X12: =VLOOKUP($B12,$R$3:$X$9,7,FALSE) -> 0.26388889 | Y12: =VLOOKUP($B12,$R$3:$Z$9,8,FALSE) -> 0 | Z12: =VLOOKUP($B12,$R$3:$Z$9,9,FALSE) -> 60
R14: =B14 -> 0 | S14: =VLOOKUP($B14,$R$3:$X$9,2,FALSE) -> #N/A | T14: =VLOOKUP($B14,$R$3:$X$9,3,FALSE) -> #N/A | U14: =VLOOKUP($B14,$R$3:$X$9,4,FALSE) -> #N/A | V14: =VLOOKUP($B14,$R$3:$X$9,5,FALSE) -> #N/A | W14: =VLOOKUP($B14,$R$3:$X$9,6,FALSE) -> #N/A | X14: =VLOOKUP($B14,$R$3:$X$9,7,FALSE) -> #N/A | Y14: =VLOOKUP($B14,$R$3:$Z$9,8,FALSE) -> #N/A | Z14: =VLOOKUP($B14,$R$3:$Z$9,9,FALSE) -> #N/A
R15: =B15 -> 0 | S15: =VLOOKUP($B15,$R$3:$X$9,2,FALSE) -> #N/A | T15: =VLOOKUP($B15,$R$3:$X$9,3,FALSE) -> #N/A | U15: =VLOOKUP($B15,$R$3:$X$9,4,FALSE) -> #N/A | V15: =VLOOKUP($B15,$R$3:$X$9,5,FALSE) -> #N/A | W15: =VLOOKUP($B15,$R$3:$X$9,6,FALSE) -> #N/A | X15: =VLOOKUP($B15,$R$3:$X$9,7,FALSE) -> #N/A | Y15: =VLOOKUP($B15,$R$3:$Z$9,8,FALSE) -> #N/A | Z15: =VLOOKUP($B15,$R$3:$Z$9,9,FALSE) -> #N/A
R16: =B16 -> 0 | S16: =VLOOKUP($B16,$R$3:$X$9,2,FALSE) -> #N/A | T16: =VLOOKUP($B16,$R$3:$X$9,3,FALSE) -> #N/A | U16: =VLOOKUP($B16,$R$3:$X$9,4,FALSE) -> #N/A | V16: =VLOOKUP($B16,$R$3:$X$9,5,FALSE) -> #N/A | W16: =VLOOKUP($B16,$R$3:$X$9,6,FALSE) -> #N/A | X16: =VLOOKUP($B16,$R$3:$X$9,7,FALSE) -> #N/A | Y16: =VLOOKUP($B16,$R$3:$Z$9,8,FALSE) -> #N/A | Z16: =VLOOKUP($B16,$R$3:$Z$9,9,FALSE) -> #N/A
R17: =B17 -> 0 | S17: =VLOOKUP($B17,$R$3:$X$9,2,FALSE) -> #N/A | T17: =VLOOKUP($B17,$R$3:$X$9,3,FALSE) -> #N/A | U17: =VLOOKUP($B17,$R$3:$X$9,4,FALSE) -> #N/A | V17: =VLOOKUP($B17,$R$3:$X$9,5,FALSE) -> #N/A | W17: =VLOOKUP($B17,$R$3:$X$9,6,FALSE) -> #N/A | X17: =VLOOKUP($B17,$R$3:$X$9,7,FALSE) -> #N/A | Y17: =VLOOKUP($B17,$R$3:$Z$9,8,FALSE) -> #N/A | Z17: =VLOOKUP($B17,$R$3:$Z$9,9,FALSE) -> #N/A
R18: =B18 -> 0 | S18: =VLOOKUP($B18,$R$3:$X$9,2,FALSE) -> #N/A | T18: =VLOOKUP($B18,$R$3:$X$9,3,FALSE) -> #N/A | U18: =VLOOKUP($B18,$R$3:$X$9,4,FALSE) -> #N/A | V18: =VLOOKUP($B18,$R$3:$X$9,5,FALSE) -> #N/A | W18: =VLOOKUP($B18,$R$3:$X$9,6,FALSE) -> #N/A | X18: =VLOOKUP($B18,$R$3:$X$9,7,FALSE) -> #N/A | Y18: =VLOOKUP($B18,$R$3:$Z$9,8,FALSE) -> #N/A | Z18: =VLOOKUP($B18,$R$3:$Z$9,9,FALSE) -> #N/A
B19: BRAND | D19: BBT P.G./ O.G | I19: Brand | K19: MTD No. of Brews | L19: MTD | M19: YTD | N19: Target | R19: =B19 -> BRAND | S19: =VLOOKUP($B19,$R$3:$X$9,2,FALSE) -> #N/A | T19: =VLOOKUP($B19,$R$3:$X$9,3,FALSE) -> #N/A | U19: =VLOOKUP($B19,$R$3:$X$9,4,FALSE) -> #N/A | V19: =VLOOKUP($B19,$R$3:$X$9,5,FALSE) -> #N/A | W19: =VLOOKUP($B19,$R$3:$X$9,6,FALSE) -> #N/A | X19: =VLOOKUP($B19,$R$3:$X$9,7,FALSE) -> #N/A | Y19: =VLOOKUP($B19,$R$3:$Z$9,8,FALSE) -> #N/A | Z19: =VLOOKUP($B19,$R$3:$Z$9,9,FALSE) -> #N/A
I20: CARIB | J20: =AVERAGE(I10:I14) -> 97.618857 | K20: =COUNTA([3]Brewhouse!$A$441:$A$444) -> 4 | L20: =AVERAGE([3]Brewhouse!$AU$441:$AU$444) -> 97.923972 | M20: =AVERAGE([3]Brewhouse!$AU$42:$AU$123,[3]Brewhouse!$AU$125:$AU$188,[3]Brewhouse!$AU$198:$AU$290,[3]Brewhouse!$AU$292:$AU$370,[3]Brewhouse!$AU$372:$AU$439,[3]Brewhouse!$AU$441:$AU$444) -> 97.974102 | N20: 98 | R20: =B20 -> 0 | S20: =VLOOKUP($B20,$R$3:$X$9,2,FALSE) -> #N/A | T20: =VLOOKUP($B20,$R$3:$X$9,3,FALSE) -> #N/A | U20: =VLOOKUP($B20,$R$3:$X$9,4,FALSE) -> #N/A | V20: =VLOOKUP($B20,$R$3:$X$9,5,FALSE) -> #N/A | W20: =VLOOKUP($B20,$R$3:$X$9,6,FALSE) -> #N/A | X20: =VLOOKUP($B20,$R$3:$X$9,7,FALSE) -> #N/A | Y20: =VLOOKUP($B20,$R$3:$Z$9,8,FALSE) -> #N/A | Z20: =VLOOKUP($B20,$R$3:$Z$9,9,FALSE) -> #N/A
I21: STAG | M21: =AVERAGE([4]Brewhouse!$AS$52:$AS$81,[4]Brewhouse!$AS$83:$AS$124,[4]Brewhouse!$AS$134:$AS$177,[4]Brewhouse!$AS$22:$AS$179,[4]Brewhouse!$AS$214:$AS$248) -> 97.973401 | N21: 98 | R21: =B21 -> 0 | S21: =VLOOKUP($B21,$R$3:$X$9,2,FALSE) -> #N/A | T21: =VLOOKUP($B21,$R$3:$X$9,3,FALSE) -> #N/A | U21: =VLOOKUP($B21,$R$3:$X$9,4,FALSE) -> #N/A | V21: =VLOOKUP($B21,$R$3:$X$9,5,FALSE) -> #N/A | W21: =VLOOKUP($B21,$R$3:$X$9,6,FALSE) -> #N/A | X21: =VLOOKUP($B21,$R$3:$X$9,7,FALSE) -> #N/A | Y21: =VLOOKUP($B21,$R$3:$Z$9,8,FALSE) -> #N/A | Z21: =VLOOKUP($B21,$R$3:$Z$9,9,FALSE) -> #N/A
I22: GUINNESS | M22: =AVERAGE([5]Brewhouse!$AU$16:$AU$23,[5]Brewhouse!$AU$25:$AU$32,[5]Brewhouse!$AU$34:$AU$41,[5]Brewhouse!$AU$43:$AU$55) -> 96.793457 | N22: 98 | R22: =B22 -> 0 | S22: =VLOOKUP($B22,$R$3:$X$9,2,FALSE) -> #N/A | T22: =VLOOKUP($B22,$R$3:$X$9,3,FALSE) -> #N/A | U22: =VLOOKUP($B22,$R$3:$X$9,4,FALSE) -> #N/A | V22: =VLOOKUP($B22,$R$3:$X$9,5,FALSE) -> #N/A | W22: =VLOOKUP($B22,$R$3:$X$9,6,FALSE) -> #N/A | X22: =VLOOKUP($B22,$R$3:$X$9,7,FALSE) -> #N/A | Y22: =VLOOKUP($B22,$R$3:$Z$9,8,FALSE) -> #N/A | Z22: =VLOOKUP($B22,$R$3:$Z$9,9,FALSE) -> #N/A
I23: VITAMALT | M23: =AVERAGE([6]Brewhouse!$AV$23:$AV$34,[6]Brewhouse!$AV$36,[6]Brewhouse!$AV$38:$AV$52,[6]Brewhouse!$AV$54:$AV$60,[6]Brewhouse!$AV$62:$AV$68) -> 97.579195 | N23: 98 | R23: =B23 -> 0 | S23: =VLOOKUP($B23,$R$3:$X$9,2,FALSE) -> #N/A | T23: =VLOOKUP($B23,$R$3:$X$9,3,FALSE) -> #N/A | U23: =VLOOKUP($B23,$R$3:$X$9,4,FALSE) -> #N/A | V23: =VLOOKUP($B23,$R$3:$X$9,5,FALSE) -> #N/A | W23: =VLOOKUP($B23,$R$3:$X$9,6,FALSE) -> #N/A | X23: =VLOOKUP($B23,$R$3:$X$9,7,FALSE) -> #N/A | Y23: =VLOOKUP($B23,$R$3:$Z$9,8,FALSE) -> #N/A | Z23: =VLOOKUP($B23,$R$3:$Z$9,9,FALSE) -> #N/A
I24: MAXIMALT | N24: 98 | R24: =B24 -> 0 | S24: =VLOOKUP($B24,$R$3:$X$9,2,FALSE) -> #N/A | T24: =VLOOKUP($B24,$R$3:$X$9,3,FALSE) -> #N/A | U24: =VLOOKUP($B24,$R$3:$X$9,4,FALSE) -> #N/A | V24: =VLOOKUP($B24,$R$3:$X$9,5,FALSE) -> #N/A | W24: =VLOOKUP($B24,$R$3:$X$9,6,FALSE) -> #N/A | X24: =VLOOKUP($B24,$R$3:$X$9,7,FALSE) -> #N/A | Y24: =VLOOKUP($B24,$R$3:$Z$9,8,FALSE) -> #N/A | Z24: =VLOOKUP($B24,$R$3:$Z$9,9,FALSE) -> #N/A
I25: MACKESON | M25: =AVERAGE([7]Brewhouse!$AT$4:$AT$11,[7]Brewhouse!$AT$13:$AT$16) -> 91.538375 | N25: 98 | R25: =B25 -> 0 | S25: =VLOOKUP($B25,$R$3:$X$9,2,FALSE) -> #N/A | T25: =VLOOKUP($B25,$R$3:$X$9,3,FALSE) -> #N/A | U25: =VLOOKUP($B25,$R$3:$X$9,4,FALSE) -> #N/A | V25: =VLOOKUP($B25,$R$3:$X$9,5,FALSE) -> #N/A | W25: =VLOOKUP($B25,$R$3:$X$9,6,FALSE) -> #N/A | X25: =VLOOKUP($B25,$R$3:$X$9,7,FALSE) -> #N/A | Y25: =VLOOKUP($B25,$R$3:$Z$9,8,FALSE) -> #N/A | Z25: =VLOOKUP($B25,$R$3:$Z$9,9,FALSE) -> #N/A
I26: STARMALT | M26: =AVERAGE([8]Brewhouse!$AY$5:$AY$14,[8]Brewhouse!$AY$16:$AY$23,[8]Brewhouse!$AY$42,[8]Brewhouse!$AY$44:$AY$51,[8]Brewhouse!$AY$53:$AY$64) -> 97.35935 | N26: 98 | R26: =B26 -> 0 | S26: =VLOOKUP($B26,$R$3:$X$9,2,FALSE) -> #N/A | T26: =VLOOKUP($B26,$R$3:$X$9,3,FALSE) -> #N/A | U26: =VLOOKUP($B26,$R$3:$X$9,4,FALSE) -> #N/A | V26: =VLOOKUP($B26,$R$3:$X$9,5,FALSE) -> #N/A | W26: =VLOOKUP($B26,$R$3:$X$9,6,FALSE) -> #N/A | X26: =VLOOKUP($B26,$R$3:$X$9,7,FALSE) -> #N/A | Y26: =VLOOKUP($B26,$R$3:$Z$9,8,FALSE) -> #N/A | Z26: =VLOOKUP($B26,$R$3:$Z$9,9,FALSE) -> #N/A
I27: HR- Pils | N27: 98 | R27: =B27 -> 0 | S27: =VLOOKUP($B27,$R$3:$X$9,2,FALSE) -> #N/A | T27: =VLOOKUP($B27,$R$3:$X$9,3,FALSE) -> #N/A | U27: =VLOOKUP($B27,$R$3:$X$9,4,FALSE) -> #N/A | V27: =VLOOKUP($B27,$R$3:$X$9,5,FALSE) -> #N/A | W27: =VLOOKUP($B27,$R$3:$X$9,6,FALSE) -> #N/A | X27: =VLOOKUP($B27,$R$3:$X$9,7,FALSE) -> #N/A | Y27: =VLOOKUP($B27,$R$3:$Z$9,8,FALSE) -> #N/A | Z27: =VLOOKUP($B27,$R$3:$Z$9,9,FALSE) -> #N/A
I28: HR- IPA | N28: 98 | R28: =B28 -> 0 | S28: =VLOOKUP($B28,$R$3:$X$9,2,FALSE) -> #N/A | T28: =VLOOKUP($B28,$R$3:$X$9,3,FALSE) -> #N/A | U28: =VLOOKUP($B28,$R$3:$X$9,4,FALSE) -> #N/A | V28: =VLOOKUP($B28,$R$3:$X$9,5,FALSE) -> #N/A | W28: =VLOOKUP($B28,$R$3:$X$9,6,FALSE) -> #N/A | X28: =VLOOKUP($B28,$R$3:$X$9,7,FALSE) -> #N/A | Y28: =VLOOKUP($B28,$R$3:$Z$9,8,FALSE) -> #N/A | Z28: =VLOOKUP($B28,$R$3:$Z$9,9,FALSE) -> #N/A
I29: HR- APA | N29: 98 | R29: =B29 -> 0 | S29: =VLOOKUP($B29,$R$3:$X$9,2,FALSE) -> #N/A | T29: =VLOOKUP($B29,$R$3:$X$9,3,FALSE) -> #N/A | U29: =VLOOKUP($B29,$R$3:$X$9,4,FALSE) -> #N/A | V29: =VLOOKUP($B29,$R$3:$X$9,5,FALSE) -> #N/A | W29: =VLOOKUP($B29,$R$3:$X$9,6,FALSE) -> #N/A | X29: =VLOOKUP($B29,$R$3:$X$9,7,FALSE) -> #N/A | Y29: =VLOOKUP($B29,$R$3:$Z$9,8,FALSE) -> #N/A | Z29: =VLOOKUP($B29,$R$3:$Z$9,9,FALSE) -> #N/A
K30: =SUM(K20:K29) -> 4 | L30: =((L20*K20)+(L21*K21)+(L22*K22)+(L23*K23)+(L24*K24)+(K27*L27)+(L25*K25)+(L26*K26)+(L29*K29))/(K30) -> 97.923972 | M30: =AVERAGE('[9]Jan30th-31st'!$L$42,L30) -> 97.876007 | N30: 98 | R30: =B30 -> 0 | S30: =VLOOKUP($B30,$R$3:$X$9,2,FALSE) -> #N/A | T30: =VLOOKUP($B30,$R$3:$X$9,3,FALSE) -> #N/A | U30: =VLOOKUP($B30,$R$3:$X$9,4,FALSE) -> #N/A | V30: =VLOOKUP($B30,$R$3:$X$9,5,FALSE) -> #N/A | W30: =VLOOKUP($B30,$R$3:$X$9,6,FALSE) -> #N/A | X30: =VLOOKUP($B30,$R$3:$X$9,7,FALSE) -> #N/A | Y30: =VLOOKUP($B30,$R$3:$Z$9,8,FALSE) -> #N/A | Z30: =VLOOKUP($B30,$R$3:$Z$9,9,FALSE) -> #N/A
R31: =B31 -> 0 | S31: =VLOOKUP($B31,$R$3:$X$9,2,FALSE) -> #N/A | T31: =VLOOKUP($B31,$R$3:$X$9,3,FALSE) -> #N/A | U31: =VLOOKUP($B31,$R$3:$X$9,4,FALSE) -> #N/A | V31: =VLOOKUP($B31,$R$3:$X$9,5,FALSE) -> #N/A | W31: =VLOOKUP($B31,$R$3:$X$9,6,FALSE) -> #N/A | X31: =VLOOKUP($B31,$R$3:$X$9,7,FALSE) -> #N/A | Y31: =VLOOKUP($B31,$R$3:$Z$9,8,FALSE) -> #N/A | Z31: =VLOOKUP($B31,$R$3:$Z$9,9,FALSE) -> #N/A
J32: Daily Brewing Plan
J33: Brand | K33: Brews Achieved | L33: Average Brews per day
J34: CARIB | K34: 3 | L34: MTD | M34: YTD | N34: TARGET
J35: STAG | L35: =AVERAGE(K44) -> 3 | M35: =AVERAGE('[9]Jan30th-31st'!$L$47,L35,'[10]Feb 26th '!$L$39,'[11]Mar 31st'!$L$47,'[12]Apr 30th'!$L$46,'[13]May 29th '!$L$40) -> 5.7713109 | N35: 9.2
J36: GUINN
J37: VITAMALT
J38: STARMALT
J39: MACKESON
J40: HURRICANE REEF- IPA
J41: HURRICANE REEF- APA
...

Sheet June 3rd
S1: P.G. | U1: Hot Time | W1: Process Time | Y1: Cooling Time
B2: Brewing Department Daily Process Loss Report | S2: Lower | T2: Upper | U2: Lower | V2: Upper | W2: Lower | X2: Upper | Y2: Lower | Z2: Upper
R3: CARIB | S3: 11.6 | T3: 12 | U3: 0 | V3: 0.11805556 | W3: 0.22569444 | X3: 0.26388889 | Y3: 0 | Z3: 60 | AB3: HR- PISNER
B4: Date: | C4: 46174 | J4: LOT WORT COLOUR: | M4: Filter Sheets (Target 20 days) | R4: STAG | S4: 11.6 | T4: 12 | U4: 0 | V4: 0.11805556 | W4: 0.22569444 | X4: 0.26388889 | Y4: 0 | Z4: 60
M5: Double | N5: Single | R5: GUINNESS | S5: 17 | T5: 17.5 | U5: 0 | V5: 0.10763889 | W5: 0.24652778 | X5: 0.28472222 | Y5: 0 | Z5: 60
J6: MALT LOT: Lot #13 | L6: Sheet Day | R6: MACKESON | S6: 13.3 | T6: 13.5 | U6: 0 | V6: 0.12905093 | W6: 0.27430556 | X6: 0.30208333 | Y6: 0
R7: STARMALT | S7: 17 | T7: 17.4 | U7: 0 | V7: 0.13605324 | W7: 0.27430556 | X7: 0.30902778 | Y7: 0 | Z7: 85
B8: Brand | C8: Brew no. | D8: Kett. Hls | E8: Wort | F8: Cool Time(Mins) | G8: Cast. P.G. (Lab Result) | H8: Cast P.G. (Cellar Operator)-gravity | I8: Extr. Rec (77.9%) | J8: Theor. Extr. (77.5%) | K8: Boil Off /Vol. (4-6%) | L8: Boil Time | M8: Total Hot | N8: Brewing Time | O8: Operator | R8: Hurricane Reef | S8: 16.6 | T8: 17 | U8: 0 | V8: 0.12905093 | W8: 0.27430556 | X8: 0.30208333 | Y8: 0
E9: Meter (Hls) | F9: Target(< 60Mins) | M9: Time | R9: VITAMALT | S9: 14.2 | T9: 14.6 | U9: 0 | V9: 0.13905093 | W9: 0.26041667 | X9: 0.29513889 | Y9: 0 | Z9: 75
B10: CARIB | C10: =[3]Brewhouse!$A444 -> CA398 | D10: =[3]Brewhouse!$AF444 -> 51 | E10: =[3]Brewhouse!$AI444 -> 50 | F10: =[3]Brewhouse!$V444 -> 55 | G10: =[3]Brewhouse!AG444 -> 11.9 | H10: 11.8 | I10: =[3]Brewhouse!$AU444 -> 98.839319 | J10: =[3]Brewhouse!$AV444 -> 99.699127 | K10: =[3]Brewhouse!$Q444 -> 7.6296296 | L10: =[3]Brewhouse!$P444 -> 61 | M10: =[3]Brewhouse!$U444-[3]Brewhouse!$T444 -> 0.10625 | N10: =[3]Brewhouse!$Z444 -> 0.24305556 | O10: =[3]Brewhouse!$AX444 -> K. Benjamin | R10: =B10 -> CARIB | S10: =VLOOKUP($B10,$R$3:$X$9,2,FALSE) -> 11.6 | T10: =VLOOKUP($B10,$R$3:$X$9,3,FALSE) -> 12 | U10: =VLOOKUP($B10,$R$3:$X$9,4,FALSE) -> 0 | V10: =VLOOKUP($B10,$R$3:$X$9,5,FALSE) -> 0.11805556 | W10: =VLOOKUP($B10,$R$3:$X$9,6,FALSE) -> 0.22569444 | X10: =VLOOKUP($B10,$R$3:$X$9,7,FALSE) -> 0.26388889 | Y10: =VLOOKUP($B10,$R$3:$Z$9,8,FALSE) -> 0 | Z10: =VLOOKUP($B10,$R$3:$Z$9,9,FALSE) -> 60
B11: CARIB | C11: =[3]Brewhouse!$A445 -> CA399 | D11: =[3]Brewhouse!$AF445 -> 50.9 | E11: =[3]Brewhouse!$AI445 -> 50.5 | F11: =[3]Brewhouse!$V445 -> 61 | G11: =[3]Brewhouse!AG445 -> 11.9 | H11: 11.9 | I11: =[3]Brewhouse!$AU445 -> 99.827713 | J11: =[3]Brewhouse!$AV445 -> 100.69612 | K11: =[3]Brewhouse!$Q445 -> 7.8148148 | L11: =[3]Brewhouse!$P445 -> 61 | M11: =[3]Brewhouse!$U445-[3]Brewhouse!$T445 -> 0.10625 | N11: =[3]Brewhouse!$Z445 -> 0.25833333 | O11: =[3]Brewhouse!$AX445 -> K. Benjamin | R11: =B11 -> CARIB | S11: =VLOOKUP($B11,$R$3:$X$9,2,FALSE) -> 11.6 | T11: =VLOOKUP($B11,$R$3:$X$9,3,FALSE) -> 12 | U11: =VLOOKUP($B11,$R$3:$X$9,4,FALSE) -> 0 | V11: =VLOOKUP($B11,$R$3:$X$9,5,FALSE) -> 0.11805556 | W11: =VLOOKUP($B11,$R$3:$X$9,6,FALSE) -> 0.22569444 | X11: =VLOOKUP($B11,$R$3:$X$9,7,FALSE) -> 0.26388889 | Y11: =VLOOKUP($B11,$R$3:$Z$9,8,FALSE) -> 0 | Z11: =VLOOKUP($B11,$R$3:$Z$9,9,FALSE) -> 60
B12: CARIB | C12: =[3]Brewhouse!$A446 -> CA400 | D12: =[3]Brewhouse!$AF446 -> 52.1 | E12: =[3]Brewhouse!$AI446 -> 51.77 | F12: =[3]Brewhouse!$V446 -> 60 | G12: =[3]Brewhouse!AG446 -> 12 | H12: 11.9 | I12: =[3]Brewhouse!$AU446 -> 102.60535 | J12: =[3]Brewhouse!$AV446 -> 103.49821 | K12: =[3]Brewhouse!$Q446 -> 8.1700555 | L12: =[3]Brewhouse!$P446 -> 61 | M12: =[3]Brewhouse!$U446-[3]Brewhouse!$T446 -> 0.11111111 | N12: =[3]Brewhouse!$Z446 -> 0.26319444 | O12: =[3]Brewhouse!$AX446 -> K. Benjamin | R12: =B12 -> CARIB | S12: =VLOOKUP($B12,$R$3:$X$9,2,FALSE) -> 11.6 | T12: =VLOOKUP($B12,$R$3:$X$9,3,FALSE) -> 12 | U12: =VLOOKUP($B12,$R$3:$X$9,4,FALSE) -> 0 | V12: =VLOOKUP($B12,$R$3:$X$9,5,FALSE) -> 0.11805556 | W12: =VLOOKUP($B12,$R$3:$X$9,6,FALSE) -> 0.22569444 | X12: =VLOOKUP($B12,$R$3:$X$9,7,FALSE) -> 0.26388889 | Y12: =VLOOKUP($B12,$R$3:$Z$9,8,FALSE) -> 0 | Z12: =VLOOKUP($B12,$R$3:$Z$9,9,FALSE) -> 60
B13: CARIB | C13: =[3]Brewhouse!$A447 -> CA401 | D13: =[3]Brewhouse!$AF447 -> 52.6 | E13: =[3]Brewhouse!$AI447 -> 53.3 | F13: =[3]Brewhouse!$V447 -> 65 | G13: =[3]Brewhouse!AG447 -> 11.6 | H13: 11.8 | I13: =[3]Brewhouse!$AU447 -> 101.06395 | J13: =[3]Brewhouse!$AV447 -> 101.9438 | K13: =[3]Brewhouse!$Q447 -> 6.5064695 | L13: =[3]Brewhouse!$P447 -> 62 | M13: =[3]Brewhouse!$U447-[3]Brewhouse!$T447 -> 0.11388889 | N13: =[3]Brewhouse!$Z447 -> 0.30625 | O13: =[3]Brewhouse!$AX447 -> R. Regis | R13: =B13 -> CARIB | S13: =VLOOKUP($B13,$R$3:$X$9,2,FALSE) -> 11.6 | T13: =VLOOKUP($B13,$R$3:$X$9,3,FALSE) -> 12 | U13: =VLOOKUP($B13,$R$3:$X$9,4,FALSE) -> 0 | V13: =VLOOKUP($B13,$R$3:$X$9,5,FALSE) -> 0.11805556 | W13: =VLOOKUP($B13,$R$3:$X$9,6,FALSE) -> 0.22569444 | X13: =VLOOKUP($B13,$R$3:$X$9,7,FALSE) -> 0.26388889 | Y13: =VLOOKUP($B13,$R$3:$Z$9,8,FALSE) -> 0 | Z13: =VLOOKUP($B13,$R$3:$Z$9,9,FALSE) -> 60
B14: CARIB | C14: =[3]Brewhouse!$A448 -> CA402 | D14: =[3]Brewhouse!$AF448 -> 50.9 | E14: =[3]Brewhouse!$AI448 -> 50.83 | F14: =[3]Brewhouse!$V448 -> 64 | G14: =[3]Brewhouse!AG448 -> 11.8 | H14: 11.7 | I14: =[3]Brewhouse!$AU448 -> 99.592276 | J14: =[3]Brewhouse!$AV448 -> 100.45863 | K14: =[3]Brewhouse!$Q448 -> 8.7245841 | L14: =[3]Brewhouse!$P448 -> 59 | M14: =[3]Brewhouse!$U448-[3]Brewhouse!$T448 -> 0.10902778 | N14: =[3]Brewhouse!$Z448 -> 0.275 | O14: =[3]Brewhouse!$AX448 -> R. Regis | R14: =B14 -> CARIB | S14: =VLOOKUP($B14,$R$3:$X$9,2,FALSE) -> 11.6 | T14: =VLOOKUP($B14,$R$3:$X$9,3,FALSE) -> 12 | U14: =VLOOKUP($B14,$R$3:$X$9,4,FALSE) -> 0 | V14: =VLOOKUP($B14,$R$3:$X$9,5,FALSE) -> 0.11805556 | W14: =VLOOKUP($B14,$R$3:$X$9,6,FALSE) -> 0.22569444 | X14: =VLOOKUP($B14,$R$3:$X$9,7,FALSE) -> 0.26388889 | Y14: =VLOOKUP($B14,$R$3:$Z$9,8,FALSE) -> 0 | Z14: =VLOOKUP($B14,$R$3:$Z$9,9,FALSE) -> 60
R15: =B15 -> 0 | S15: =VLOOKUP($B15,$R$3:$X$9,2,FALSE) -> #N/A | T15: =VLOOKUP($B15,$R$3:$X$9,3,FALSE) -> #N/A | U15: =VLOOKUP($B15,$R$3:$X$9,4,FALSE) -> #N/A | V15: =VLOOKUP($B15,$R$3:$X$9,5,FALSE) -> #N/A | W15: =VLOOKUP($B15,$R$3:$X$9,6,FALSE) -> #N/A | X15: =VLOOKUP($B15,$R$3:$X$9,7,FALSE) -> #N/A | Y15: =VLOOKUP($B15,$R$3:$Z$9,8,FALSE) -> #N/A | Z15: =VLOOKUP($B15,$R$3:$Z$9,9,FALSE) -> #N/A
B16: GUINNESS | C16: =[5]Brewhouse!$A62 -> GU043 | D16: =[5]Brewhouse!$AF62 -> 49.9 | E16: =[5]Brewhouse!$AI62 -> 49 | F16: =[5]Brewhouse!$V62 -> 57 | G16: =[5]Brewhouse!$AG62 -> 17.4 | H16: 17.3 | I16: =[5]Brewhouse!$AU62 -> 93.161813 | J16: =[5]Brewhouse!$AV62 -> 93.861712 | K16: =[5]Brewhouse!$R62 -> 14.224599 | L16: =[5]Brewhouse!$O62 -> 55 | M16: =[5]Brewhouse!$U62-[5]Brewhouse!$T62 -> 0.12013889 | N16: =[5]Brewhouse!$Z62 -> 0.27777778 | O16: =[5]Brewhouse!$AW62 -> R. Sookram | R16: =B16 -> GUINNESS | S16: =VLOOKUP($B16,$R$3:$X$9,2,FALSE) -> 17 | T16: =VLOOKUP($B16,$R$3:$X$9,3,FALSE) -> 17.5 | U16: =VLOOKUP($B16,$R$3:$X$9,4,FALSE) -> 0 | V16: =VLOOKUP($B16,$R$3:$X$9,5,FALSE) -> 0.10763889 | W16: =VLOOKUP($B16,$R$3:$X$9,6,FALSE) -> 0.24652778 | X16: =VLOOKUP($B16,$R$3:$X$9,7,FALSE) -> 0.28472222 | Y16: =VLOOKUP($B16,$R$3:$Z$9,8,FALSE) -> 0 | Z16: =VLOOKUP($B16,$R$3:$Z$9,9,FALSE) -> 60
B17: GUINNESS | C17: =[5]Brewhouse!$A63 -> GU044 | D17: =[5]Brewhouse!$AF63 -> 50.5 | E17: =[5]Brewhouse!$AI63 -> 49.4 | F17: =[5]Brewhouse!$V63 -> 59 | G17: =[5]Brewhouse!$AG63 -> 17.4 | H17: 17.7 | I17: =[5]Brewhouse!$AU63 -> 94.223464 | J17: =[5]Brewhouse!$AV63 -> 94.930841 | K17: =[5]Brewhouse!$R63 -> 12.285714 | L17: =[5]Brewhouse!$O63 -> 58 | M17: =[5]Brewhouse!$U63-[5]Brewhouse!$T63 -> 0.11875 | N17: =[5]Brewhouse!$Z63 -> 0.27708333 | O17: =[5]Brewhouse!$AW63 -> R. Sookram | R17: =B17 -> GUINNESS | S17: =VLOOKUP($B17,$R$3:$X$9,2,FALSE) -> 17 | T17: =VLOOKUP($B17,$R$3:$X$9,3,FALSE) -> 17.5 | U17: =VLOOKUP($B17,$R$3:$X$9,4,FALSE) -> 0 | V17: =VLOOKUP($B17,$R$3:$X$9,5,FALSE) -> 0.10763889 | W17: =VLOOKUP($B17,$R$3:$X$9,6,FALSE) -> 0.24652778 | X17: =VLOOKUP($B17,$R$3:$X$9,7,FALSE) -> 0.28472222 | Y17: =VLOOKUP($B17,$R$3:$Z$9,8,FALSE) -> 0 | Z17: =VLOOKUP($B17,$R$3:$Z$9,9,FALSE) -> 60
B18: GUINNESS | C18: =[5]Brewhouse!$A64 -> GU045 | D18: =[5]Brewhouse!$AF64 -> 51.9 | E18: =[5]Brewhouse!$AI64 -> 50.7 | F18: =[5]Brewhouse!$V64 -> 55 | G18: =[5]Brewhouse!$AG64 -> 17.4 | H18: 17.4 | I18: =[5]Brewhouse!$AU64 -> 96.163448 | J18: =[5]Brewhouse!$AV64 -> 96.886276 | K18: =[5]Brewhouse!$R64 -> 12.821429 | L18: =[5]Brewhouse!$O64 -> 61 | M18: =[5]Brewhouse!$U64-[5]Brewhouse!$T64 -> 0.11666667 | N18: =[5]Brewhouse!$Z64 -> 0.27430556 | O18: =[5]Brewhouse!$AW64 -> R. Sookram | R18: =B18 -> GUINNESS | S18: =VLOOKUP($B18,$R$3:$X$9,2,FALSE) -> 17 | T18: =VLOOKUP($B18,$R$3:$X$9,3,FALSE) -> 17.5 | U18: =VLOOKUP($B18,$R$3:$X$9,4,FALSE) -> 0 | V18: =VLOOKUP($B18,$R$3:$X$9,5,FALSE) -> 0.10763889 | W18: =VLOOKUP($B18,$R$3:$X$9,6,FALSE) -> 0.24652778 | X18: =VLOOKUP($B18,$R$3:$X$9,7,FALSE) -> 0.28472222 | Y18: =VLOOKUP($B18,$R$3:$Z$9,8,FALSE) -> 0 | Z18: =VLOOKUP($B18,$R$3:$Z$9,9,FALSE) -> 60
R19: =B19 -> 0 | S19: =VLOOKUP($B19,$R$3:$X$9,2,FALSE) -> #N/A | T19: =VLOOKUP($B19,$R$3:$X$9,3,FALSE) -> #N/A | U19: =VLOOKUP($B19,$R$3:$X$9,4,FALSE) -> #N/A | V19: =VLOOKUP($B19,$R$3:$X$9,5,FALSE) -> #N/A | W19: =VLOOKUP($B19,$R$3:$X$9,6,FALSE) -> #N/A | X19: =VLOOKUP($B19,$R$3:$X$9,7,FALSE) -> #N/A | Y19: =VLOOKUP($B19,$R$3:$Z$9,8,FALSE) -> #N/A | Z19: =VLOOKUP($B19,$R$3:$Z$9,9,FALSE) -> #N/A
R20: =B20 -> 0 | S20: =VLOOKUP($B20,$R$3:$X$9,2,FALSE) -> #N/A | T20: =VLOOKUP($B20,$R$3:$X$9,3,FALSE) -> #N/A | U20: =VLOOKUP($B20,$R$3:$X$9,4,FALSE) -> #N/A | V20: =VLOOKUP($B20,$R$3:$X$9,5,FALSE) -> #N/A | W20: =VLOOKUP($B20,$R$3:$X$9,6,FALSE) -> #N/A | X20: =VLOOKUP($B20,$R$3:$X$9,7,FALSE) -> #N/A | Y20: =VLOOKUP($B20,$R$3:$Z$9,8,FALSE) -> #N/A | Z20: =VLOOKUP($B20,$R$3:$Z$9,9,FALSE) -> #N/A
R21: =B21 -> 0 | S21: =VLOOKUP($B21,$R$3:$X$9,2,FALSE) -> #N/A | T21: =VLOOKUP($B21,$R$3:$X$9,3,FALSE) -> #N/A | U21: =VLOOKUP($B21,$R$3:$X$9,4,FALSE) -> #N/A | V21: =VLOOKUP($B21,$R$3:$X$9,5,FALSE) -> #N/A | W21: =VLOOKUP($B21,$R$3:$X$9,6,FALSE) -> #N/A | X21: =VLOOKUP($B21,$R$3:$X$9,7,FALSE) -> #N/A | Y21: =VLOOKUP($B21,$R$3:$Z$9,8,FALSE) -> #N/A | Z21: =VLOOKUP($B21,$R$3:$Z$9,9,FALSE) -> #N/A
R22: =B22 -> 0 | S22: =VLOOKUP($B22,$R$3:$X$9,2,FALSE) -> #N/A | T22: =VLOOKUP($B22,$R$3:$X$9,3,FALSE) -> #N/A | U22: =VLOOKUP($B22,$R$3:$X$9,4,FALSE) -> #N/A | V22: =VLOOKUP($B22,$R$3:$X$9,5,FALSE) -> #N/A | W22: =VLOOKUP($B22,$R$3:$X$9,6,FALSE) -> #N/A | X22: =VLOOKUP($B22,$R$3:$X$9,7,FALSE) -> #N/A | Y22: =VLOOKUP($B22,$R$3:$Z$9,8,FALSE) -> #N/A | Z22: =VLOOKUP($B22,$R$3:$Z$9,9,FALSE) -> #N/A
R23: =B23 -> 0 | S23: =VLOOKUP($B23,$R$3:$X$9,2,FALSE) -> #N/A | T23: =VLOOKUP($B23,$R$3:$X$9,3,FALSE) -> #N/A | U23: =VLOOKUP($B23,$R$3:$X$9,4,FALSE) -> #N/A | V23: =VLOOKUP($B23,$R$3:$X$9,5,FALSE) -> #N/A | W23: =VLOOKUP($B23,$R$3:$X$9,6,FALSE) -> #N/A | X23: =VLOOKUP($B23,$R$3:$X$9,7,FALSE) -> #N/A | Y23: =VLOOKUP($B23,$R$3:$Z$9,8,FALSE) -> #N/A | Z23: =VLOOKUP($B23,$R$3:$Z$9,9,FALSE) -> #N/A
R24: =B24 -> 0 | S24: =VLOOKUP($B24,$R$3:$X$9,2,FALSE) -> #N/A | T24: =VLOOKUP($B24,$R$3:$X$9,3,FALSE) -> #N/A | U24: =VLOOKUP($B24,$R$3:$X$9,4,FALSE) -> #N/A | V24: =VLOOKUP($B24,$R$3:$X$9,5,FALSE) -> #N/A | W24: =VLOOKUP($B24,$R$3:$X$9,6,FALSE) -> #N/A | X24: =VLOOKUP($B24,$R$3:$X$9,7,FALSE) -> #N/A | Y24: =VLOOKUP($B24,$R$3:$Z$9,8,FALSE) -> #N/A | Z24: =VLOOKUP($B24,$R$3:$Z$9,9,FALSE) -> #N/A
R25: =B25 -> 0 | S25: =VLOOKUP($B25,$R$3:$X$9,2,FALSE) -> #N/A | T25: =VLOOKUP($B25,$R$3:$X$9,3,FALSE) -> #N/A | U25: =VLOOKUP($B25,$R$3:$X$9,4,FALSE) -> #N/A | V25: =VLOOKUP($B25,$R$3:$X$9,5,FALSE) -> #N/A | W25: =VLOOKUP($B25,$R$3:$X$9,6,FALSE) -> #N/A | X25: =VLOOKUP($B25,$R$3:$X$9,7,FALSE) -> #N/A | Y25: =VLOOKUP($B25,$R$3:$Z$9,8,FALSE) -> #N/A | Z25: =VLOOKUP($B25,$R$3:$Z$9,9,FALSE) -> #N/A
R26: =B26 -> 0 | S26: =VLOOKUP($B26,$R$3:$X$9,2,FALSE) -> #N/A | T26: =VLOOKUP($B26,$R$3:$X$9,3,FALSE) -> #N/A | U26: =VLOOKUP($B26,$R$3:$X$9,4,FALSE) -> #N/A | V26: =VLOOKUP($B26,$R$3:$X$9,5,FALSE) -> #N/A | W26: =VLOOKUP($B26,$R$3:$X$9,6,FALSE) -> #N/A | X26: =VLOOKUP($B26,$R$3:$X$9,7,FALSE) -> #N/A | Y26: =VLOOKUP($B26,$R$3:$Z$9,8,FALSE) -> #N/A | Z26: =VLOOKUP($B26,$R$3:$Z$9,9,FALSE) -> #N/A
B27: BRAND | D27: BBT P.G./ O.G | I27: Brand | K27: MTD No. of Brews | L27: MTD | M27: YTD | N27: Target | R27: =B27 -> BRAND | S27: =VLOOKUP($B27,$R$3:$X$9,2,FALSE) -> #N/A | T27: =VLOOKUP($B27,$R$3:$X$9,3,FALSE) -> #N/A | U27: =VLOOKUP($B27,$R$3:$X$9,4,FALSE) -> #N/A | V27: =VLOOKUP($B27,$R$3:$X$9,5,FALSE) -> #N/A | W27: =VLOOKUP($B27,$R$3:$X$9,6,FALSE) -> #N/A | X27: =VLOOKUP($B27,$R$3:$X$9,7,FALSE) -> #N/A | Y27: =VLOOKUP($B27,$R$3:$Z$9,8,FALSE) -> #N/A | Z27: =VLOOKUP($B27,$R$3:$Z$9,9,FALSE) -> #N/A
I28: CARIB | J28: =AVERAGE(I10:I14) -> 100.38572 | K28: =COUNTA([3]Brewhouse!$A$441:$A$448) -> 8 | L28: =AVERAGE([3]Brewhouse!$AU$441:$AU$448) -> 99.348147 | M28: =AVERAGE([3]Brewhouse!$AU$42:$AU$123,[3]Brewhouse!$AU$125:$AU$188,[3]Brewhouse!$AU$198:$AU$290,[3]Brewhouse!$AU$292:$AU$370,[3]Brewhouse!$AU$372:$AU$439,[3]Brewhouse!$AU$441:$AU$448) -> 98.002583 | N28: 98 | R28: =B28 -> 0 | S28: =VLOOKUP($B28,$R$3:$X$9,2,FALSE) -> #N/A | T28: =VLOOKUP($B28,$R$3:$X$9,3,FALSE) -> #N/A | U28: =VLOOKUP($B28,$R$3:$X$9,4,FALSE) -> #N/A | V28: =VLOOKUP($B28,$R$3:$X$9,5,FALSE) -> #N/A | W28: =VLOOKUP($B28,$R$3:$X$9,6,FALSE) -> #N/A | X28: =VLOOKUP($B28,$R$3:$X$9,7,FALSE) -> #N/A | Y28: =VLOOKUP($B28,$R$3:$Z$9,8,FALSE) -> #N/A | Z28: =VLOOKUP($B28,$R$3:$Z$9,9,FALSE) -> #N/A
I29: STAG | M29: =AVERAGE([4]Brewhouse!$AS$52:$AS$81,[4]Brewhouse!$AS$83:$AS$124,[4]Brewhouse!$AS$134:$AS$177,[4]Brewhouse!$AS$22:$AS$179,[4]Brewhouse!$AS$214:$AS$248) -> 97.973401 | N29: 98 | R29: =B29 -> 0 | S29: =VLOOKUP($B29,$R$3:$X$9,2,FALSE) -> #N/A | T29: =VLOOKUP($B29,$R$3:$X$9,3,FALSE) -> #N/A | U29: =VLOOKUP($B29,$R$3:$X$9,4,FALSE) -> #N/A | V29: =VLOOKUP($B29,$R$3:$X$9,5,FALSE) -> #N/A | W29: =VLOOKUP($B29,$R$3:$X$9,6,FALSE) -> #N/A | X29: =VLOOKUP($B29,$R$3:$X$9,7,FALSE) -> #N/A | Y29: =VLOOKUP($B29,$R$3:$Z$9,8,FALSE) -> #N/A | Z29: =VLOOKUP($B29,$R$3:$Z$9,9,FALSE) -> #N/A
I30: GUINNESS | J30: =AVERAGE(I16:I18) -> 94.516242 | K30: =COUNTA([5]Brewhouse!$A$62:$A$64) -> 3 | L30: =AVERAGE([5]Brewhouse!$AU$62:$AU$64) -> 94.516242 | M30: =AVERAGE([5]Brewhouse!$AU$16:$AU$23,[5]Brewhouse!$AU$25:$AU$32,[5]Brewhouse!$AU$34:$AU$41,[5]Brewhouse!$AU$43:$AU$60,[5]Brewhouse!$AU$62:$AU$64) -> 96.73262 | N30: 98 | R30: =B30 -> 0 | S30: =VLOOKUP($B30,$R$3:$X$9,2,FALSE) -> #N/A | T30: =VLOOKUP($B30,$R$3:$X$9,3,FALSE) -> #N/A | U30: =VLOOKUP($B30,$R$3:$X$9,4,FALSE) -> #N/A | V30: =VLOOKUP($B30,$R$3:$X$9,5,FALSE) -> #N/A | W30: =VLOOKUP($B30,$R$3:$X$9,6,FALSE) -> #N/A | X30: =VLOOKUP($B30,$R$3:$X$9,7,FALSE) -> #N/A | Y30: =VLOOKUP($B30,$R$3:$Z$9,8,FALSE) -> #N/A | Z30: =VLOOKUP($B30,$R$3:$Z$9,9,FALSE) -> #N/A
I31: VITAMALT | M31: =AVERAGE([6]Brewhouse!$AV$23:$AV$34,[6]Brewhouse!$AV$36,[6]Brewhouse!$AV$38:$AV$52,[6]Brewhouse!$AV$54:$AV$60,[6]Brewhouse!$AV$62:$AV$68) -> 97.579195 | N31: 98 | R31: =B31 -> 0 | S31: =VLOOKUP($B31,$R$3:$X$9,2,FALSE) -> #N/A | T31: =VLOOKUP($B31,$R$3:$X$9,3,FALSE) -> #N/A | U31: =VLOOKUP($B31,$R$3:$X$9,4,FALSE) -> #N/A | V31: =VLOOKUP($B31,$R$3:$X$9,5,FALSE) -> #N/A | W31: =VLOOKUP($B31,$R$3:$X$9,6,FALSE) -> #N/A | X31: =VLOOKUP($B31,$R$3:$X$9,7,FALSE) -> #N/A | Y31: =VLOOKUP($B31,$R$3:$Z$9,8,FALSE) -> #N/A | Z31: =VLOOKUP($B31,$R$3:$Z$9,9,FALSE) -> #N/A
I32: MAXIMALT | N32: 98 | R32: =B32 -> 0 | S32: =VLOOKUP($B32,$R$3:$X$9,2,FALSE) -> #N/A | T32: =VLOOKUP($B32,$R$3:$X$9,3,FALSE) -> #N/A | U32: =VLOOKUP($B32,$R$3:$X$9,4,FALSE) -> #N/A | V32: =VLOOKUP($B32,$R$3:$X$9,5,FALSE) -> #N/A | W32: =VLOOKUP($B32,$R$3:$X$9,6,FALSE) -> #N/A | X32: =VLOOKUP($B32,$R$3:$X$9,7,FALSE) -> #N/A | Y32: =VLOOKUP($B32,$R$3:$Z$9,8,FALSE) -> #N/A | Z32: =VLOOKUP($B32,$R$3:$Z$9,9,FALSE) -> #N/A
I33: MACKESON | M33: =AVERAGE([7]Brewhouse!$AT$4:$AT$11,[7]Brewhouse!$AT$13:$AT$16) -> 91.538375 | N33: 98 | R33: =B33 -> 0 | S33: =VLOOKUP($B33,$R$3:$X$9,2,FALSE) -> #N/A | T33: =VLOOKUP($B33,$R$3:$X$9,3,FALSE) -> #N/A | U33: =VLOOKUP($B33,$R$3:$X$9,4,FALSE) -> #N/A | V33: =VLOOKUP($B33,$R$3:$X$9,5,FALSE) -> #N/A | W33: =VLOOKUP($B33,$R$3:$X$9,6,FALSE) -> #N/A | X33: =VLOOKUP($B33,$R$3:$X$9,7,FALSE) -> #N/A | Y33: =VLOOKUP($B33,$R$3:$Z$9,8,FALSE) -> #N/A | Z33: =VLOOKUP($B33,$R$3:$Z$9,9,FALSE) -> #N/A
I34: STARMALT | M34: =AVERAGE([8]Brewhouse!$AY$5:$AY$14,[8]Brewhouse!$AY$16:$AY$23,[8]Brewhouse!$AY$42,[8]Brewhouse!$AY$44:$AY$51,[8]Brewhouse!$AY$53:$AY$64) -> 97.35935 | N34: 98 | R34: =B34 -> 0 | S34: =VLOOKUP($B34,$R$3:$X$9,2,FALSE) -> #N/A | T34: =VLOOKUP($B34,$R$3:$X$9,3,FALSE) -> #N/A | U34: =VLOOKUP($B34,$R$3:$X$9,4,FALSE) -> #N/A | V34: =VLOOKUP($B34,$R$3:$X$9,5,FALSE) -> #N/A | W34: =VLOOKUP($B34,$R$3:$X$9,6,FALSE) -> #N/A | X34: =VLOOKUP($B34,$R$3:$X$9,7,FALSE) -> #N/A | Y34: =VLOOKUP($B34,$R$3:$Z$9,8,FALSE) -> #N/A | Z34: =VLOOKUP($B34,$R$3:$Z$9,9,FALSE) -> #N/A
I35: HR- Pils | N35: 98 | R35: =B35 -> 0 | S35: =VLOOKUP($B35,$R$3:$X$9,2,FALSE) -> #N/A | T35: =VLOOKUP($B35,$R$3:$X$9,3,FALSE) -> #N/A | U35: =VLOOKUP($B35,$R$3:$X$9,4,FALSE) -> #N/A | V35: =VLOOKUP($B35,$R$3:$X$9,5,FALSE) -> #N/A | W35: =VLOOKUP($B35,$R$3:$X$9,6,FALSE) -> #N/A | X35: =VLOOKUP($B35,$R$3:$X$9,7,FALSE) -> #N/A | Y35: =VLOOKUP($B35,$R$3:$Z$9,8,FALSE) -> #N/A | Z35: =VLOOKUP($B35,$R$3:$Z$9,9,FALSE) -> #N/A
I36: HR- IPA | N36: 98 | R36: =B36 -> 0 | S36: =VLOOKUP($B36,$R$3:$X$9,2,FALSE) -> #N/A | T36: =VLOOKUP($B36,$R$3:$X$9,3,FALSE) -> #N/A | U36: =VLOOKUP($B36,$R$3:$X$9,4,FALSE) -> #N/A | V36: =VLOOKUP($B36,$R$3:$X$9,5,FALSE) -> #N/A | W36: =VLOOKUP($B36,$R$3:$X$9,6,FALSE) -> #N/A | X36: =VLOOKUP($B36,$R$3:$X$9,7,FALSE) -> #N/A | Y36: =VLOOKUP($B36,$R$3:$Z$9,8,FALSE) -> #N/A | Z36: =VLOOKUP($B36,$R$3:$Z$9,9,FALSE) -> #N/A
I37: HR- APA | N37: 98 | R37: =B37 -> 0 | S37: =VLOOKUP($B37,$R$3:$X$9,2,FALSE) -> #N/A | T37: =VLOOKUP($B37,$R$3:$X$9,3,FALSE) -> #N/A | U37: =VLOOKUP($B37,$R$3:$X$9,4,FALSE) -> #N/A | V37: =VLOOKUP($B37,$R$3:$X$9,5,FALSE) -> #N/A | W37: =VLOOKUP($B37,$R$3:$X$9,6,FALSE) -> #N/A | X37: =VLOOKUP($B37,$R$3:$X$9,7,FALSE) -> #N/A | Y37: =VLOOKUP($B37,$R$3:$Z$9,8,FALSE) -> #N/A | Z37: =VLOOKUP($B37,$R$3:$Z$9,9,FALSE) -> #N/A
K38: =SUM(K28:K37) -> 11 | L38: =((L28*K28)+(L29*K29)+(L30*K30)+(L31*K31)+(L32*K32)+(K35*L35)+(L33*K33)+(L34*K34)+(L37*K37))/(K38) -> 98.030354 | M38: =AVERAGE('[9]Jan30th-31st'!$L$42,L38) -> 97.929198 | N38: 98 | R38: =B38 -> 0 | S38: =VLOOKUP($B38,$R$3:$X$9,2,FALSE) -> #N/A | T38: =VLOOKUP($B38,$R$3:$X$9,3,FALSE) -> #N/A | U38: =VLOOKUP($B38,$R$3:$X$9,4,FALSE) -> #N/A | V38: =VLOOKUP($B38,$R$3:$X$9,5,FALSE) -> #N/A | W38: =VLOOKUP($B38,$R$3:$X$9,6,FALSE) -> #N/A | X38: =VLOOKUP($B38,$R$3:$X$9,7,FALSE) -> #N/A | Y38: =VLOOKUP($B38,$R$3:$Z$9,8,FALSE) -> #N/A | Z38: =VLOOKUP($B38,$R$3:$Z$9,9,FALSE) -> #N/A
R39: =B39 -> 0 | S39: =VLOOKUP($B39,$R$3:$X$9,2,FALSE) -> #N/A | T39: =VLOOKUP($B39,$R$3:$X$9,3,FALSE) -> #N/A | U39: =VLOOKUP($B39,$R$3:$X$9,4,FALSE) -> #N/A | V39: =VLOOKUP($B39,$R$3:$X$9,5,FALSE) -> #N/A | W39: =VLOOKUP($B39,$R$3:$X$9,6,FALSE) -> #N/A | X39: =VLOOKUP($B39,$R$3:$X$9,7,FALSE) -> #N/A | Y39: =VLOOKUP($B39,$R$3:$Z$9,8,FALSE) -> #N/A | Z39: =VLOOKUP($B39,$R$3:$Z$9,9,FALSE) -> #N/A
J40: Daily Brewing Plan
...

Sheet June 4th
S1: P.G. | U1: Hot Time | W1: Process Time | Y1: Cooling Time
B2: Brewing Department Daily Process Loss Report | S2: Lower | T2: Upper | U2: Lower | V2: Upper | W2: Lower | X2: Upper | Y2: Lower | Z2: Upper
R3: CARIB | S3: 11.6 | T3: 12 | U3: 0 | V3: 0.11805556 | W3: 0.22569444 | X3: 0.26388889 | Y3: 0 | Z3: 60 | AB3: HR- PISNER
B4: Date: | C4: 46178 | J4: LOT WORT COLOUR: | M4: Filter Sheets (Target 20 days) | R4: STAG | S4: 11.6 | T4: 12 | U4: 0 | V4: 0.11805556 | W4: 0.22569444 | X4: 0.26388889 | Y4: 0 | Z4: 60
M5: Double | N5: Single | R5: GUINNESS | S5: 17 | T5: 17.5 | U5: 0 | V5: 0.10763889 | W5: 0.24652778 | X5: 0.28472222 | Y5: 0 | Z5: 60
J6: MALT LOT: Lot #13 | L6: Sheet Day | R6: MACKESON | S6: 13.3 | T6: 13.5 | U6: 0 | V6: 0.12905093 | W6: 0.27430556 | X6: 0.30208333 | Y6: 0
R7: STARMALT | S7: 17 | T7: 17.4 | U7: 0 | V7: 0.13605324 | W7: 0.27430556 | X7: 0.30902778 | Y7: 0 | Z7: 85
B8: Brand | C8: Brew no. | D8: Kett. Hls | E8: Wort | F8: Cool Time(Mins) | G8: Cast. P.G. (Lab Result) | H8: Cast P.G. (Cellar Operator)-gravity | I8: Extr. Rec (77.9%) | J8: Theor. Extr. (77.5%) | K8: Boil Off /Vol. (4-6%) | L8: Boil Time | M8: Total Hot | N8: Brewing Time | O8: Operator | R8: Hurricane Reef | S8: 16.6 | T8: 17 | U8: 0 | V8: 0.12905093 | W8: 0.27430556 | X8: 0.30208333 | Y8: 0
E9: Meter (Hls) | F9: Target(< 60Mins) | M9: Time | R9: VITAMALT | S9: 14.2 | T9: 14.6 | U9: 0 | V9: 0.13905093 | W9: 0.26041667 | X9: 0.29513889 | Y9: 0 | Z9: 75
B10: GUINNESS | C10: =[5]Brewhouse!$A65 -> GU046 | D10: =[5]Brewhouse!$AF65 -> 51.3 | E10: =[5]Brewhouse!$AI65 -> 50.3 | F10: =[5]Brewhouse!$V65 -> 60 | G10: =[5]Brewhouse!$AG65 -> 17.2 | H10: 17.5 | I10: =[5]Brewhouse!$AU65 -> 94.716056 | J10: =[5]Brewhouse!$AV65 -> 95.389393 | K10: =[5]Brewhouse!$R65 -> 12.464286 | L10: =[5]Brewhouse!$O65 -> 60 | M10: =[5]Brewhouse!$U65-[5]Brewhouse!$T65 -> 0.11736111 | N10: =[5]Brewhouse!$Z65 -> 0.27430556 | O10: =[5]Brewhouse!$AW65 -> K. Benjamin | R10: =B10 -> GUINNESS | S10: =VLOOKUP($B10,$R$3:$X$9,2,FALSE) -> 17 | T10: =VLOOKUP($B10,$R$3:$X$9,3,FALSE) -> 17.5 | U10: =VLOOKUP($B10,$R$3:$X$9,4,FALSE) -> 0 | V10: =VLOOKUP($B10,$R$3:$X$9,5,FALSE) -> 0.10763889 | W10: =VLOOKUP($B10,$R$3:$X$9,6,FALSE) -> 0.24652778 | X10: =VLOOKUP($B10,$R$3:$X$9,7,FALSE) -> 0.28472222 | Y10: =VLOOKUP($B10,$R$3:$Z$9,8,FALSE) -> 0 | Z10: =VLOOKUP($B10,$R$3:$Z$9,9,FALSE) -> 60
B11: GUINNESS | C11: =[5]Brewhouse!$A66 -> GU047 | D11: =[5]Brewhouse!$AF66 -> 51.4 | E11: =[5]Brewhouse!$AI66 -> 49.3 | F11: =[5]Brewhouse!$V66 -> 58 | G11: =[5]Brewhouse!$AG66 -> 17.5 | H11: 17.4 | I11: =[5]Brewhouse!$AU66 -> 94.701981 | J11: =[5]Brewhouse!$AV66 -> 95.374981 | K11: =[5]Brewhouse!$R66 -> 11.75 | L11: =[5]Brewhouse!$O66 -> 58 | M11: =[5]Brewhouse!$U66-[5]Brewhouse!$T66 -> 0.11111111 | N11: =[5]Brewhouse!$Z66 -> 0.27361111 | O11: =[5]Brewhouse!$AW66 -> K. Benjamin | R11: =B11 -> GUINNESS | S11: =VLOOKUP($B11,$R$3:$X$9,2,FALSE) -> 17 | T11: =VLOOKUP($B11,$R$3:$X$9,3,FALSE) -> 17.5 | U11: =VLOOKUP($B11,$R$3:$X$9,4,FALSE) -> 0 | V11: =VLOOKUP($B11,$R$3:$X$9,5,FALSE) -> 0.10763889 | W11: =VLOOKUP($B11,$R$3:$X$9,6,FALSE) -> 0.24652778 | X11: =VLOOKUP($B11,$R$3:$X$9,7,FALSE) -> 0.28472222 | Y11: =VLOOKUP($B11,$R$3:$Z$9,8,FALSE) -> 0 | Z11: =VLOOKUP($B11,$R$3:$Z$9,9,FALSE) -> 60
B12: GUINNESS | C12: =[5]Brewhouse!$A67 -> GU048 | D12: =[5]Brewhouse!$AF67 -> 52.9 | E12: =[5]Brewhouse!$AI67 -> 50.1 | F12: =[5]Brewhouse!$V67 -> 61 | G12: =[5]Brewhouse!$AG67 -> 17.3 | H12: 17.4 | I12: =[5]Brewhouse!$AU67 -> 95.107716 | J12: =[5]Brewhouse!$AV67 -> 95.783599 | K12: =[5]Brewhouse!$R67 -> 15.650624 | L12: =[5]Brewhouse!$O67 -> 59 | M12: =[5]Brewhouse!$U67-[5]Brewhouse!$T67 -> 0.14166667 | N12: =[5]Brewhouse!$Z67 -> 0.30208333 | O12: =[5]Brewhouse!$AW67 -> R. Regis | R12: =B12 -> GUINNESS | S12: =VLOOKUP($B12,$R$3:$X$9,2,FALSE) -> 17 | T12: =VLOOKUP($B12,$R$3:$X$9,3,FALSE) -> 17.5 | U12: =VLOOKUP($B12,$R$3:$X$9,4,FALSE) -> 0 | V12: =VLOOKUP($B12,$R$3:$X$9,5,FALSE) -> 0.10763889 | W12: =VLOOKUP($B12,$R$3:$X$9,6,FALSE) -> 0.24652778 | X12: =VLOOKUP($B12,$R$3:$X$9,7,FALSE) -> 0.28472222 | Y12: =VLOOKUP($B12,$R$3:$Z$9,8,FALSE) -> 0 | Z12: =VLOOKUP($B12,$R$3:$Z$9,9,FALSE) -> 60
B13: GUINNESS | C13: =[5]Brewhouse!$A68 -> GU049 | D13: =[5]Brewhouse!$AF68 -> 54 | E13: =[5]Brewhouse!$AI68 -> 52.8 | F13: =[5]Brewhouse!$V68 -> 64 | G13: =[5]Brewhouse!$AG68 -> 17.2 | H13: 16.9 | I13: =[5]Brewhouse!$AU68 -> 99.423614 | J13: =[5]Brewhouse!$AV68 -> 100.13042 | K13: =[5]Brewhouse!$R68 -> 9.9465241 | L13: =[5]Brewhouse!$O68 -> 58 | M13: =[5]Brewhouse!$U68-[5]Brewhouse!$T68 -> 0.11666667 | N13: =[5]Brewhouse!$Z68 -> 0.29375 | O13: =[5]Brewhouse!$AW68 -> R. Regis | R13: =B13 -> GUINNESS | S13: =VLOOKUP($B13,$R$3:$X$9,2,FALSE) -> 17 | T13: =VLOOKUP($B13,$R$3:$X$9,3,FALSE) -> 17.5 | U13: =VLOOKUP($B13,$R$3:$X$9,4,FALSE) -> 0 | V13: =VLOOKUP($B13,$R$3:$X$9,5,FALSE) -> 0.10763889 | W13: =VLOOKUP($B13,$R$3:$X$9,6,FALSE) -> 0.24652778 | X13: =VLOOKUP($B13,$R$3:$X$9,7,FALSE) -> 0.28472222 | Y13: =VLOOKUP($B13,$R$3:$Z$9,8,FALSE) -> 0 | Z13: =VLOOKUP($B13,$R$3:$Z$9,9,FALSE) -> 60
B14: GUINNESS | C14: =[5]Brewhouse!$A69 -> GU050 | D14: =[5]Brewhouse!$AF69 -> 53.2 | E14: =[5]Brewhouse!$AI69 -> 52.5 | F14: =[5]Brewhouse!$V69 -> 63 | G14: =[5]Brewhouse!$AG69 -> 17.3 | H14: 17 | I14: =[5]Brewhouse!$AU69 -> 99.424513 | J14: =[5]Brewhouse!$AV69 -> 100.13145 | K14: =[5]Brewhouse!$R69 -> 11.729055 | L14: =[5]Brewhouse!$O69 -> 56 | M14: =[5]Brewhouse!$U69-[5]Brewhouse!$T69 -> 0.11458333 | N14: =[5]Brewhouse!$Z69 -> 0.26805556 | O14: =[5]Brewhouse!$AW69 -> R. Regis | R14: =B14 -> GUINNESS | S14: =VLOOKUP($B14,$R$3:$X$9,2,FALSE) -> 17 | T14: =VLOOKUP($B14,$R$3:$X$9,3,FALSE) -> 17.5 | U14: =VLOOKUP($B14,$R$3:$X$9,4,FALSE) -> 0 | V14: =VLOOKUP($B14,$R$3:$X$9,5,FALSE) -> 0.10763889 | W14: =VLOOKUP($B14,$R$3:$X$9,6,FALSE) -> 0.24652778 | X14: =VLOOKUP($B14,$R$3:$X$9,7,FALSE) -> 0.28472222 | Y14: =VLOOKUP($B14,$R$3:$Z$9,8,FALSE) -> 0 | Z14: =VLOOKUP($B14,$R$3:$Z$9,9,FALSE) -> 60
R15: =B15 -> 0 | S15: =VLOOKUP($B15,$R$3:$X$9,2,FALSE) -> #N/A | T15: =VLOOKUP($B15,$R$3:$X$9,3,FALSE) -> #N/A | U15: =VLOOKUP($B15,$R$3:$X$9,4,FALSE) -> #N/A | V15: =VLOOKUP($B15,$R$3:$X$9,5,FALSE) -> #N/A | W15: =VLOOKUP($B15,$R$3:$X$9,6,FALSE) -> #N/A | X15: =VLOOKUP($B15,$R$3:$X$9,7,FALSE) -> #N/A | Y15: =VLOOKUP($B15,$R$3:$Z$9,8,FALSE) -> #N/A | Z15: =VLOOKUP($B15,$R$3:$Z$9,9,FALSE) -> #N/A
R16: =B16 -> 0 | S16: =VLOOKUP($B16,$R$3:$X$9,2,FALSE) -> #N/A | T16: =VLOOKUP($B16,$R$3:$X$9,3,FALSE) -> #N/A | U16: =VLOOKUP($B16,$R$3:$X$9,4,FALSE) -> #N/A | V16: =VLOOKUP($B16,$R$3:$X$9,5,FALSE) -> #N/A | W16: =VLOOKUP($B16,$R$3:$X$9,6,FALSE) -> #N/A | X16: =VLOOKUP($B16,$R$3:$X$9,7,FALSE) -> #N/A | Y16: =VLOOKUP($B16,$R$3:$Z$9,8,FALSE) -> #N/A | Z16: =VLOOKUP($B16,$R$3:$Z$9,9,FALSE) -> #N/A
R17: =B17 -> 0 | S17: =VLOOKUP($B17,$R$3:$X$9,2,FALSE) -> #N/A | T17: =VLOOKUP($B17,$R$3:$X$9,3,FALSE) -> #N/A | U17: =VLOOKUP($B17,$R$3:$X$9,4,FALSE) -> #N/A | V17: =VLOOKUP($B17,$R$3:$X$9,5,FALSE) -> #N/A | W17: =VLOOKUP($B17,$R$3:$X$9,6,FALSE) -> #N/A | X17: =VLOOKUP($B17,$R$3:$X$9,7,FALSE) -> #N/A | Y17: =VLOOKUP($B17,$R$3:$Z$9,8,FALSE) -> #N/A | Z17: =VLOOKUP($B17,$R$3:$Z$9,9,FALSE) -> #N/A
R18: =B18 -> 0 | S18: =VLOOKUP($B18,$R$3:$X$9,2,FALSE) -> #N/A | T18: =VLOOKUP($B18,$R$3:$X$9,3,FALSE) -> #N/A | U18: =VLOOKUP($B18,$R$3:$X$9,4,FALSE) -> #N/A | V18: =VLOOKUP($B18,$R$3:$X$9,5,FALSE) -> #N/A | W18: =VLOOKUP($B18,$R$3:$X$9,6,FALSE) -> #N/A | X18: =VLOOKUP($B18,$R$3:$X$9,7,FALSE) -> #N/A | Y18: =VLOOKUP($B18,$R$3:$Z$9,8,FALSE) -> #N/A | Z18: =VLOOKUP($B18,$R$3:$Z$9,9,FALSE) -> #N/A
R19: =B19 -> 0 | S19: =VLOOKUP($B19,$R$3:$X$9,2,FALSE) -> #N/A | T19: =VLOOKUP($B19,$R$3:$X$9,3,FALSE) -> #N/A | U19: =VLOOKUP($B19,$R$3:$X$9,4,FALSE) -> #N/A | V19: =VLOOKUP($B19,$R$3:$X$9,5,FALSE) -> #N/A | W19: =VLOOKUP($B19,$R$3:$X$9,6,FALSE) -> #N/A | X19: =VLOOKUP($B19,$R$3:$X$9,7,FALSE) -> #N/A | Y19: =VLOOKUP($B19,$R$3:$Z$9,8,FALSE) -> #N/A | Z19: =VLOOKUP($B19,$R$3:$Z$9,9,FALSE) -> #N/A
R20: =B20 -> 0 | S20: =VLOOKUP($B20,$R$3:$X$9,2,FALSE) -> #N/A | T20: =VLOOKUP($B20,$R$3:$X$9,3,FALSE) -> #N/A | U20: =VLOOKUP($B20,$R$3:$X$9,4,FALSE) -> #N/A | V20: =VLOOKUP($B20,$R$3:$X$9,5,FALSE) -> #N/A | W20: =VLOOKUP($B20,$R$3:$X$9,6,FALSE) -> #N/A | X20: =VLOOKUP($B20,$R$3:$X$9,7,FALSE) -> #N/A | Y20: =VLOOKUP($B20,$R$3:$Z$9,8,FALSE) -> #N/A | Z20: =VLOOKUP($B20,$R$3:$Z$9,9,FALSE) -> #N/A
R21: =B21 -> 0 | S21: =VLOOKUP($B21,$R$3:$X$9,2,FALSE) -> #N/A | T21: =VLOOKUP($B21,$R$3:$X$9,3,FALSE) -> #N/A | U21: =VLOOKUP($B21,$R$3:$X$9,4,FALSE) -> #N/A | V21: =VLOOKUP($B21,$R$3:$X$9,5,FALSE) -> #N/A | W21: =VLOOKUP($B21,$R$3:$X$9,6,FALSE) -> #N/A | X21: =VLOOKUP($B21,$R$3:$X$9,7,FALSE) -> #N/A | Y21: =VLOOKUP($B21,$R$3:$Z$9,8,FALSE) -> #N/A | Z21: =VLOOKUP($B21,$R$3:$Z$9,9,FALSE) -> #N/A
B22: BRAND | D22: BBT P.G./ O.G | I22: Brand | K22: MTD No. of Brews | L22: MTD | M22: YTD | N22: Target | R22: =B22 -> BRAND | S22: =VLOOKUP($B22,$R$3:$X$9,2,FALSE) -> #N/A | T22: =VLOOKUP($B22,$R$3:$X$9,3,FALSE) -> #N/A | U22: =VLOOKUP($B22,$R$3:$X$9,4,FALSE) -> #N/A | V22: =VLOOKUP($B22,$R$3:$X$9,5,FALSE) -> #N/A | W22: =VLOOKUP($B22,$R$3:$X$9,6,FALSE) -> #N/A | X22: =VLOOKUP($B22,$R$3:$X$9,7,FALSE) -> #N/A | Y22: =VLOOKUP($B22,$R$3:$Z$9,8,FALSE) -> #N/A | Z22: =VLOOKUP($B22,$R$3:$Z$9,9,FALSE) -> #N/A
I23: CARIB | K23: =COUNTA([3]Brewhouse!$A$441:$A$448) -> 8 | L23: =AVERAGE([3]Brewhouse!$AU$441:$AU$448) -> 99.348147 | M23: =AVERAGE([3]Brewhouse!$AU$42:$AU$123,[3]Brewhouse!$AU$125:$AU$188,[3]Brewhouse!$AU$198:$AU$290,[3]Brewhouse!$AU$292:$AU$370,[3]Brewhouse!$AU$372:$AU$439,[3]Brewhouse!$AU$441:$AU$448) -> 98.002583 | N23: 98 | R23: =B23 -> 0 | S23: =VLOOKUP($B23,$R$3:$X$9,2,FALSE) -> #N/A | T23: =VLOOKUP($B23,$R$3:$X$9,3,FALSE) -> #N/A | U23: =VLOOKUP($B23,$R$3:$X$9,4,FALSE) -> #N/A | V23: =VLOOKUP($B23,$R$3:$X$9,5,FALSE) -> #N/A | W23: =VLOOKUP($B23,$R$3:$X$9,6,FALSE) -> #N/A | X23: =VLOOKUP($B23,$R$3:$X$9,7,FALSE) -> #N/A | Y23: =VLOOKUP($B23,$R$3:$Z$9,8,FALSE) -> #N/A | Z23: =VLOOKUP($B23,$R$3:$Z$9,9,FALSE) -> #N/A
I24: STAG | M24: =AVERAGE([4]Brewhouse!$AS$52:$AS$81,[4]Brewhouse!$AS$83:$AS$124,[4]Brewhouse!$AS$134:$AS$177,[4]Brewhouse!$AS$22:$AS$179,[4]Brewhouse!$AS$214:$AS$248) -> 97.973401 | N24: 98 | R24: =B24 -> 0 | S24: =VLOOKUP($B24,$R$3:$X$9,2,FALSE) -> #N/A | T24: =VLOOKUP($B24,$R$3:$X$9,3,FALSE) -> #N/A | U24: =VLOOKUP($B24,$R$3:$X$9,4,FALSE) -> #N/A | V24: =VLOOKUP($B24,$R$3:$X$9,5,FALSE) -> #N/A | W24: =VLOOKUP($B24,$R$3:$X$9,6,FALSE) -> #N/A | X24: =VLOOKUP($B24,$R$3:$X$9,7,FALSE) -> #N/A | Y24: =VLOOKUP($B24,$R$3:$Z$9,8,FALSE) -> #N/A | Z24: =VLOOKUP($B24,$R$3:$Z$9,9,FALSE) -> #N/A
I25: GUINNESS | J25: =AVERAGE(I10:I14) -> 96.674776 | K25: =COUNTA([5]Brewhouse!$A$62:$A$69) -> 8 | L25: =AVERAGE([5]Brewhouse!$AU$62:$AU$69) -> 95.865326 | M25: =AVERAGE([5]Brewhouse!$AU$16:$AU$23,[5]Brewhouse!$AU$25:$AU$32,[5]Brewhouse!$AU$34:$AU$41,[5]Brewhouse!$AU$43:$AU$60,[5]Brewhouse!$AU$62:$AU$69) -> 96.726836 | N25: 98 | R25: =B25 -> 0 | S25: =VLOOKUP($B25,$R$3:$X$9,2,FALSE) -> #N/A | T25: =VLOOKUP($B25,$R$3:$X$9,3,FALSE) -> #N/A | U25: =VLOOKUP($B25,$R$3:$X$9,4,FALSE) -> #N/A | V25: =VLOOKUP($B25,$R$3:$X$9,5,FALSE) -> #N/A | W25: =VLOOKUP($B25,$R$3:$X$9,6,FALSE) -> #N/A | X25: =VLOOKUP($B25,$R$3:$X$9,7,FALSE) -> #N/A | Y25: =VLOOKUP($B25,$R$3:$Z$9,8,FALSE) -> #N/A | Z25: =VLOOKUP($B25,$R$3:$Z$9,9,FALSE) -> #N/A
I26: VITAMALT | M26: =AVERAGE([6]Brewhouse!$AV$23:$AV$34,[6]Brewhouse!$AV$36,[6]Brewhouse!$AV$38:$AV$52,[6]Brewhouse!$AV$54:$AV$60,[6]Brewhouse!$AV$62:$AV$68) -> 97.579195 | N26: 98 | R26: =B26 -> 0 | S26: =VLOOKUP($B26,$R$3:$X$9,2,FALSE) -> #N/A | T26: =VLOOKUP($B26,$R$3:$X$9,3,FALSE) -> #N/A | U26: =VLOOKUP($B26,$R$3:$X$9,4,FALSE) -> #N/A | V26: =VLOOKUP($B26,$R$3:$X$9,5,FALSE) -> #N/A | W26: =VLOOKUP($B26,$R$3:$X$9,6,FALSE) -> #N/A | X26: =VLOOKUP($B26,$R$3:$X$9,7,FALSE) -> #N/A | Y26: =VLOOKUP($B26,$R$3:$Z$9,8,FALSE) -> #N/A | Z26: =VLOOKUP($B26,$R$3:$Z$9,9,FALSE) -> #N/A
I27: MAXIMALT | N27: 98 | R27: =B27 -> 0 | S27: =VLOOKUP($B27,$R$3:$X$9,2,FALSE) -> #N/A | T27: =VLOOKUP($B27,$R$3:$X$9,3,FALSE) -> #N/A | U27: =VLOOKUP($B27,$R$3:$X$9,4,FALSE) -> #N/A | V27: =VLOOKUP($B27,$R$3:$X$9,5,FALSE) -> #N/A | W27: =VLOOKUP($B27,$R$3:$X$9,6,FALSE) -> #N/A | X27: =VLOOKUP($B27,$R$3:$X$9,7,FALSE) -> #N/A | Y27: =VLOOKUP($B27,$R$3:$Z$9,8,FALSE) -> #N/A | Z27: =VLOOKUP($B27,$R$3:$Z$9,9,FALSE) -> #N/A
I28: MACKESON | M28: =AVERAGE([7]Brewhouse!$AT$4:$AT$11,[7]Brewhouse!$AT$13:$AT$16) -> 91.538375 | N28: 98 | R28: =B28 -> 0 | S28: =VLOOKUP($B28,$R$3:$X$9,2,FALSE) -> #N/A | T28: =VLOOKUP($B28,$R$3:$X$9,3,FALSE) -> #N/A | U28: =VLOOKUP($B28,$R$3:$X$9,4,FALSE) -> #N/A | V28: =VLOOKUP($B28,$R$3:$X$9,5,FALSE) -> #N/A | W28: =VLOOKUP($B28,$R$3:$X$9,6,FALSE) -> #N/A | X28: =VLOOKUP($B28,$R$3:$X$9,7,FALSE) -> #N/A | Y28: =VLOOKUP($B28,$R$3:$Z$9,8,FALSE) -> #N/A | Z28: =VLOOKUP($B28,$R$3:$Z$9,9,FALSE) -> #N/A
I29: STARMALT | M29: =AVERAGE([8]Brewhouse!$AY$5:$AY$14,[8]Brewhouse!$AY$16:$AY$23,[8]Brewhouse!$AY$42,[8]Brewhouse!$AY$44:$AY$51,[8]Brewhouse!$AY$53:$AY$64) -> 97.35935 | N29: 98 | R29: =B29 -> 0 | S29: =VLOOKUP($B29,$R$3:$X$9,2,FALSE) -> #N/A | T29: =VLOOKUP($B29,$R$3:$X$9,3,FALSE) -> #N/A | U29: =VLOOKUP($B29,$R$3:$X$9,4,FALSE) -> #N/A | V29: =VLOOKUP($B29,$R$3:$X$9,5,FALSE) -> #N/A | W29: =VLOOKUP($B29,$R$3:$X$9,6,FALSE) -> #N/A | X29: =VLOOKUP($B29,$R$3:$X$9,7,FALSE) -> #N/A | Y29: =VLOOKUP($B29,$R$3:$Z$9,8,FALSE) -> #N/A | Z29: =VLOOKUP($B29,$R$3:$Z$9,9,FALSE) -> #N/A
I30: HR- Pils | N30: 98 | R30: =B30 -> 0 | S30: =VLOOKUP($B30,$R$3:$X$9,2,FALSE) -> #N/A | T30: =VLOOKUP($B30,$R$3:$X$9,3,FALSE) -> #N/A | U30: =VLOOKUP($B30,$R$3:$X$9,4,FALSE) -> #N/A | V30: =VLOOKUP($B30,$R$3:$X$9,5,FALSE) -> #N/A | W30: =VLOOKUP($B30,$R$3:$X$9,6,FALSE) -> #N/A | X30: =VLOOKUP($B30,$R$3:$X$9,7,FALSE) -> #N/A | Y30: =VLOOKUP($B30,$R$3:$Z$9,8,FALSE) -> #N/A | Z30: =VLOOKUP($B30,$R$3:$Z$9,9,FALSE) -> #N/A
I31: HR- IPA | N31: 98 | R31: =B31 -> 0 | S31: =VLOOKUP($B31,$R$3:$X$9,2,FALSE) -> #N/A | T31: =VLOOKUP($B31,$R$3:$X$9,3,FALSE) -> #N/A | U31: =VLOOKUP($B31,$R$3:$X$9,4,FALSE) -> #N/A | V31: =VLOOKUP($B31,$R$3:$X$9,5,FALSE) -> #N/A | W31: =VLOOKUP($B31,$R$3:$X$9,6,FALSE) -> #N/A | X31: =VLOOKUP($B31,$R$3:$X$9,7,FALSE) -> #N/A | Y31: =VLOOKUP($B31,$R$3:$Z$9,8,FALSE) -> #N/A | Z31: =VLOOKUP($B31,$R$3:$Z$9,9,FALSE) -> #N/A
I32: HR- APA | N32: 98 | R32: =B32 -> 0 | S32: =VLOOKUP($B32,$R$3:$X$9,2,FALSE) -> #N/A | T32: =VLOOKUP($B32,$R$3:$X$9,3,FALSE) -> #N/A | U32: =VLOOKUP($B32,$R$3:$X$9,4,FALSE) -> #N/A | V32: =VLOOKUP($B32,$R$3:$X$9,5,FALSE) -> #N/A | W32: =VLOOKUP($B32,$R$3:$X$9,6,FALSE) -> #N/A | X32: =VLOOKUP($B32,$R$3:$X$9,7,FALSE) -> #N/A | Y32: =VLOOKUP($B32,$R$3:$Z$9,8,FALSE) -> #N/A | Z32: =VLOOKUP($B32,$R$3:$Z$9,9,FALSE) -> #N/A
K33: =SUM(K23:K32) -> 16 | L33: =((L23*K23)+(L24*K24)+(L25*K25)+(L26*K26)+(L27*K27)+(K30*L30)+(L28*K28)+(L29*K29)+(L32*K32))/(K33) -> 97.606736 | M33: =AVERAGE('[9]Jan30th-31st'!$L$42,L33) -> 97.717389 | N33: 98 | R33: =B33 -> 0 | S33: =VLOOKUP($B33,$R$3:$X$9,2,FALSE) -> #N/A | T33: =VLOOKUP($B33,$R$3:$X$9,3,FALSE) -> #N/A | U33: =VLOOKUP($B33,$R$3:$X$9,4,FALSE) -> #N/A | V33: =VLOOKUP($B33,$R$3:$X$9,5,FALSE) -> #N/A | W33: =VLOOKUP($B33,$R$3:$X$9,6,FALSE) -> #N/A | X33: =VLOOKUP($B33,$R$3:$X$9,7,FALSE) -> #N/A | Y33: =VLOOKUP($B33,$R$3:$Z$9,8,FALSE) -> #N/A | Z33: =VLOOKUP($B33,$R$3:$Z$9,9,FALSE) -> #N/A
R34: =B34 -> 0 | S34: =VLOOKUP($B34,$R$3:$X$9,2,FALSE) -> #N/A | T34: =VLOOKUP($B34,$R$3:$X$9,3,FALSE) -> #N/A | U34: =VLOOKUP($B34,$R$3:$X$9,4,FALSE) -> #N/A | V34: =VLOOKUP($B34,$R$3:$X$9,5,FALSE) -> #N/A | W34: =VLOOKUP($B34,$R$3:$X$9,6,FALSE) -> #N/A | X34: =VLOOKUP($B34,$R$3:$X$9,7,FALSE) -> #N/A | Y34: =VLOOKUP($B34,$R$3:$Z$9,8,FALSE) -> #N/A | Z34: =VLOOKUP($B34,$R$3:$Z$9,9,FALSE) -> #N/A
J35: Daily Brewing Plan
J36: Brand | K36: Brews Achieved | L36: Average Brews per day
J37: CARIB | L37: MTD | M37: YTD | N37: TARGET
J38: STAG | L38: =AVERAGE('June 2nd'!K44,'June 3rd'!K52,K47) -> 5.3333333 | M38: =AVERAGE('[9]Jan30th-31st'!$L$47,L38,'[10]Feb 26th '!$L$39,'[11]Mar 31st'!$L$47,'[12]Apr 30th'!$L$46,'[13]May 29th '!$L$40) -> 6.1601998 | N38: 9.2
J39: GUINN | K39: 5
J40: VITAMALT
...

Sheet June 5th
S1: P.G. | U1: Hot Time | W1: Process Time | Y1: Cooling Time
B2: Brewing Department Daily Process Loss Report | S2: Lower | T2: Upper | U2: Lower | V2: Upper | W2: Lower | X2: Upper | Y2: Lower | Z2: Upper
R3: CARIB | S3: 11.6 | T3: 12 | U3: 0 | V3: 0.11805556 | W3: 0.22569444 | X3: 0.26388889 | Y3: 0 | Z3: 60 | AB3: HR- PISNER
B4: Date: | C4: 46181 | J4: LOT WORT COLOUR: | M4: Filter Sheets (Target 20 days) | R4: STAG | S4: 11.6 | T4: 12 | U4: 0 | V4: 0.11805556 | W4: 0.22569444 | X4: 0.26388889 | Y4: 0 | Z4: 60
M5: Double | N5: Single | R5: GUINNESS | S5: 17 | T5: 17.5 | U5: 0 | V5: 0.10763889 | W5: 0.24652778 | X5: 0.28472222 | Y5: 0 | Z5: 60
