Workbook
Name ProductList: [1]November15!$R$3:$R$9
Name ProductList: [2]November15!$R$3:$R$9

Sheet Dec 18th
T1: P.G. | V1: Hot Time | X1: Process Time | Z1: Cooling Time
B2: Brewing Department Daily Process Loss Report | T2: Lower | U2: Upper | V2: Lower | W2: Upper | X2: Lower | Y2: Upper | Z2: Lower | AA2: Upper
S3: CARIB | T3: 11.6 | U3: 12 | V3: 0 | W3: 0.11805556 | X3: 0.17361111 | Y3: 0.21180556 | Z3: 0 | AA3: 60 | AC3: HR- PISNER
B4: Date: | C4: 45278 | J4: LOT WORT COLOUR: 3.4 | M4: Filter Sheets (Target 20 days) | S4: STAG | T4: 11.6 | U4: 12 | V4: 0 | W4: 0.11805556 | X4: 0.17361111 | Y4: 0.21180556 | Z4: 0 | AA4: 60
M5: Double | N5: Single | S5: GUINNESS | T5: 17 | U5: 17.5 | V5: 0 | W5: 0.10763889 | X5: 0.19444444 | Y5: 0.23263889 | Z5: 0 | AA5: 60
J6: MALT LOT: Lot 8 | L6: Sheet Day | S6: MACKESON | T6: 13.3 | U6: 13.5 | V6: 0 | W6: 0.12905093 | X6: 0.22222222 | Y6: 0.25347222 | Z6: 0
S7: STARMALT | T7: 17.1 | U7: 17.5 | V7: 0 | W7: 0.13605324 | X7: 0.20833333 | Y7: 0.24305556 | Z7: 0 | AA7: 60
B8: Brand | C8: Brew no. | D8: Kett. Hls | E8: Wort | F8: Cool Time(Mins) | G8: Cast. P.G. (Lab Result) | H8: Cast P.G. (Cellar Operator)-gravity | I8: Extr. Rec (79.1%) | J8: Theor. Extr. (77.5%) | K8: Boil Off /Vol. (4-6%) | L8: Boil Time | M8: Total Hot | N8: Brewing | P8: Comments | Q8: Actual Pilsen Malt | S8: Hurricane Reef | T8: 16.6 | U8: 17 | V8: 0 | W8: 0.12905093 | X8: 0.22222222 | Y8: 0.25347222 | Z8: 0
E9: Meter (Hls) | F9: Target(< 60Mins) | M9: Time | S9: VITAMALT | T9: 14.4 | U9: 14.6 | V9: 0 | W9: 0.13905093 | X9: 0.19097222 | Y9: 0.22569444 | Z9: 0 | AA9: 75
S10: =B10 -> 0 | T10: =VLOOKUP($B10,$S$3:$Y$9,2,FALSE) -> #N/A | U10: =VLOOKUP($B10,$S$3:$Y$9,3,FALSE) -> #N/A | V10: =VLOOKUP($B10,$S$3:$Y$9,4,FALSE) -> #N/A | W10: =VLOOKUP($B10,$S$3:$Y$9,5,FALSE) -> #N/A | X10: =VLOOKUP($B10,$S$3:$Y$9,6,FALSE) -> #N/A | Y10: =VLOOKUP($B10,$S$3:$Y$9,7,FALSE) -> #N/A | Z10: =VLOOKUP($B10,$S$3:$AA$9,8,FALSE) -> #N/A | AA10: =VLOOKUP($B10,$S$3:$AA$9,9,FALSE) -> #N/A
S11: =B11 -> 0 | T11: =VLOOKUP($B11,$S$3:$Y$9,2,FALSE) -> #N/A | U11: =VLOOKUP($B11,$S$3:$Y$9,3,FALSE) -> #N/A | V11: =VLOOKUP($B11,$S$3:$Y$9,4,FALSE) -> #N/A | W11: =VLOOKUP($B11,$S$3:$Y$9,5,FALSE) -> #N/A | X11: =VLOOKUP($B11,$S$3:$Y$9,6,FALSE) -> #N/A | Y11: =VLOOKUP($B11,$S$3:$Y$9,7,FALSE) -> #N/A | Z11: =VLOOKUP($B11,$S$3:$AA$9,8,FALSE) -> #N/A | AA11: =VLOOKUP($B11,$S$3:$AA$9,9,FALSE) -> #N/A
S12: =B12 -> 0 | T12: =VLOOKUP($B12,$S$3:$Y$9,2,FALSE) -> #N/A | U12: =VLOOKUP($B12,$S$3:$Y$9,3,FALSE) -> #N/A | V12: =VLOOKUP($B12,$S$3:$Y$9,4,FALSE) -> #N/A | W12: =VLOOKUP($B12,$S$3:$Y$9,5,FALSE) -> #N/A | X12: =VLOOKUP($B12,$S$3:$Y$9,6,FALSE) -> #N/A | Y12: =VLOOKUP($B12,$S$3:$Y$9,7,FALSE) -> #N/A | Z12: =VLOOKUP($B12,$S$3:$AA$9,8,FALSE) -> #N/A | AA12: =VLOOKUP($B12,$S$3:$AA$9,9,FALSE) -> #N/A
S13: =B13 -> 0 | T13: =VLOOKUP($B13,$S$3:$Y$9,2,FALSE) -> #N/A | U13: =VLOOKUP($B13,$S$3:$Y$9,3,FALSE) -> #N/A | V13: =VLOOKUP($B13,$S$3:$Y$9,4,FALSE) -> #N/A | W13: =VLOOKUP($B13,$S$3:$Y$9,5,FALSE) -> #N/A | X13: =VLOOKUP($B13,$S$3:$Y$9,6,FALSE) -> #N/A | Y13: =VLOOKUP($B13,$S$3:$Y$9,7,FALSE) -> #N/A | Z13: =VLOOKUP($B13,$S$3:$AA$9,8,FALSE) -> #N/A | AA13: =VLOOKUP($B13,$S$3:$AA$9,9,FALSE) -> #N/A
S14: =B14 -> 0 | T14: =VLOOKUP($B14,$S$3:$Y$9,2,FALSE) -> #N/A | U14: =VLOOKUP($B14,$S$3:$Y$9,3,FALSE) -> #N/A | V14: =VLOOKUP($B14,$S$3:$Y$9,4,FALSE) -> #N/A | W14: =VLOOKUP($B14,$S$3:$Y$9,5,FALSE) -> #N/A | X14: =VLOOKUP($B14,$S$3:$Y$9,6,FALSE) -> #N/A | Y14: =VLOOKUP($B14,$S$3:$Y$9,7,FALSE) -> #N/A | Z14: =VLOOKUP($B14,$S$3:$AA$9,8,FALSE) -> #N/A | AA14: =VLOOKUP($B14,$S$3:$AA$9,9,FALSE) -> #N/A
S15: =B15 -> 0 | T15: =VLOOKUP($B15,$S$3:$Y$9,2,FALSE) -> #N/A | U15: =VLOOKUP($B15,$S$3:$Y$9,3,FALSE) -> #N/A | V15: =VLOOKUP($B15,$S$3:$Y$9,4,FALSE) -> #N/A | W15: =VLOOKUP($B15,$S$3:$Y$9,5,FALSE) -> #N/A | X15: =VLOOKUP($B15,$S$3:$Y$9,6,FALSE) -> #N/A | Y15: =VLOOKUP($B15,$S$3:$Y$9,7,FALSE) -> #N/A | Z15: =VLOOKUP($B15,$S$3:$AA$9,8,FALSE) -> #N/A | AA15: =VLOOKUP($B15,$S$3:$AA$9,9,FALSE) -> #N/A
S16: =B16 -> 0 | T16: =VLOOKUP($B16,$S$3:$Y$9,2,FALSE) -> #N/A | U16: =VLOOKUP($B16,$S$3:$Y$9,3,FALSE) -> #N/A | V16: =VLOOKUP($B16,$S$3:$Y$9,4,FALSE) -> #N/A | W16: =VLOOKUP($B16,$S$3:$Y$9,5,FALSE) -> #N/A | X16: =VLOOKUP($B16,$S$3:$Y$9,6,FALSE) -> #N/A | Y16: =VLOOKUP($B16,$S$3:$Y$9,7,FALSE) -> #N/A | Z16: =VLOOKUP($B16,$S$3:$AA$9,8,FALSE) -> #N/A | AA16: =VLOOKUP($B16,$S$3:$AA$9,9,FALSE) -> #N/A
S17: =B17 -> 0 | T17: =VLOOKUP($B17,$S$3:$Y$9,2,FALSE) -> #N/A | U17: =VLOOKUP($B17,$S$3:$Y$9,3,FALSE) -> #N/A | V17: =VLOOKUP($B17,$S$3:$Y$9,4,FALSE) -> #N/A | W17: =VLOOKUP($B17,$S$3:$Y$9,5,FALSE) -> #N/A | X17: =VLOOKUP($B17,$S$3:$Y$9,6,FALSE) -> #N/A | Y17: =VLOOKUP($B17,$S$3:$Y$9,7,FALSE) -> #N/A | Z17: =VLOOKUP($B17,$S$3:$AA$9,8,FALSE) -> #N/A | AA17: =VLOOKUP($B17,$S$3:$AA$9,9,FALSE) -> #N/A
S18: =B18 -> 0 | T18: =VLOOKUP($B18,$S$3:$Y$9,2,FALSE) -> #N/A | U18: =VLOOKUP($B18,$S$3:$Y$9,3,FALSE) -> #N/A | V18: =VLOOKUP($B18,$S$3:$Y$9,4,FALSE) -> #N/A | W18: =VLOOKUP($B18,$S$3:$Y$9,5,FALSE) -> #N/A | X18: =VLOOKUP($B18,$S$3:$Y$9,6,FALSE) -> #N/A | Y18: =VLOOKUP($B18,$S$3:$Y$9,7,FALSE) -> #N/A | Z18: =VLOOKUP($B18,$S$3:$AA$9,8,FALSE) -> #N/A | AA18: =VLOOKUP($B18,$S$3:$AA$9,9,FALSE) -> #N/A
S19: =B19 -> 0 | T19: =VLOOKUP($B19,$S$3:$Y$9,2,FALSE) -> #N/A | U19: =VLOOKUP($B19,$S$3:$Y$9,3,FALSE) -> #N/A | V19: =VLOOKUP($B19,$S$3:$Y$9,4,FALSE) -> #N/A | W19: =VLOOKUP($B19,$S$3:$Y$9,5,FALSE) -> #N/A | X19: =VLOOKUP($B19,$S$3:$Y$9,6,FALSE) -> #N/A | Y19: =VLOOKUP($B19,$S$3:$Y$9,7,FALSE) -> #N/A | Z19: =VLOOKUP($B19,$S$3:$AA$9,8,FALSE) -> #N/A | AA19: =VLOOKUP($B19,$S$3:$AA$9,9,FALSE) -> #N/A
S20: =B20 -> 0 | T20: =VLOOKUP($B20,$S$3:$Y$9,2,FALSE) -> #N/A | U20: =VLOOKUP($B20,$S$3:$Y$9,3,FALSE) -> #N/A | V20: =VLOOKUP($B20,$S$3:$Y$9,4,FALSE) -> #N/A | W20: =VLOOKUP($B20,$S$3:$Y$9,5,FALSE) -> #N/A | X20: =VLOOKUP($B20,$S$3:$Y$9,6,FALSE) -> #N/A | Y20: =VLOOKUP($B20,$S$3:$Y$9,7,FALSE) -> #N/A | Z20: =VLOOKUP($B20,$S$3:$AA$9,8,FALSE) -> #N/A | AA20: =VLOOKUP($B20,$S$3:$AA$9,9,FALSE) -> #N/A
S21: =B21 -> 0 | T21: =VLOOKUP($B21,$S$3:$Y$9,2,FALSE) -> #N/A | U21: =VLOOKUP($B21,$S$3:$Y$9,3,FALSE) -> #N/A | V21: =VLOOKUP($B21,$S$3:$Y$9,4,FALSE) -> #N/A | W21: =VLOOKUP($B21,$S$3:$Y$9,5,FALSE) -> #N/A | X21: =VLOOKUP($B21,$S$3:$Y$9,6,FALSE) -> #N/A | Y21: =VLOOKUP($B21,$S$3:$Y$9,7,FALSE) -> #N/A | Z21: =VLOOKUP($B21,$S$3:$AA$9,8,FALSE) -> #N/A | AA21: =VLOOKUP($B21,$S$3:$AA$9,9,FALSE) -> #N/A
... S47: =B47 -> 0 | T47: =VLOOKUP($B47,$S$3:$Y$9,2,FALSE) -> #N/A | U47: =VLOOKUP($B47,$S$3:$Y$9,3,FALSE) -> #N/A | V47: =VLOOKUP($B47,$S$3:$Y$9,4,FALSE) -> #N/A | W47: =VLOOKUP($B47,$S$3:$Y$9,5,FALSE) -> #N/A | X47: =VLOOKUP($B47,$S$3:$Y$9,6,FALSE) -> #N/A | Y47: =VLOOKUP($B47,$S$3:$Y$9,7,FALSE) -> #N/A | Z47: =VLOOKUP($B47,$S$3:$AA$9,8,FALSE) -> #N/A | AA47: =VLOOKUP($B47,$S$3:$AA$9,9,FALSE) -> #N/A
I48: EXTRACT RECOVERY
B49: BRAND | D49: BBT P.G./ O.G | I49: Brand | J49: Actual | K49: MTD No. of Brews | L49: MTD | M49: YTD | N49: Target
B50: STAG | C50: 11.8 | D50: 11.73 | I50: CARIB | K50: =COUNTA([3]Brewhouse!$A$1596:$A$1619) -> 24 | L50: =AVERAGE([3]Brewhouse!$AU$1529,[3]Brewhouse!$AU$1531:$AU$1594,[3]Brewhouse!$AU$1596:$AU$1619) -> 98.205761 | M50: =AVERAGE([3]Brewhouse!$AU$849:$AU$924,[3]Brewhouse!$AU$926:$AU$971,[3]Brewhouse!$AU$973:$AU$1066,[3]Brewhouse!$AU$1068:$AU$1111,[3]Brewhouse!$AU$1113:$AU$1132,[3]Brewhouse!$AU$1134:$AU$1167,[3]Brewhouse!$AU$1169:$AU$1230,[3]Brewhouse!$AU$1232:$AU$1299,[3]Brewhouse!$AU$1301:$AU$1363,[3]Brewhouse!$AU$1365:$AU$1444,[3]Brewhouse!$AU$1446:$AU$1527,[3]Brewhouse!$AU$1529,[3]Brewhouse!$AU$1531:$AU$1594,[3]Brewhouse!$AU$1596:$AU$1619) -> 98.381806 | N50: 98
C51: 11.9 | I51: STAG | K51: =COUNTA([4]Brewhouse!$A$976:$A$1007) -> 32 | L51: =AVERAGE([4]Brewhouse!$AS$976:$AS$979,[4]Brewhouse!$AS$981:$AS$1007) -> 98.538567 | M51: =AVERAGE([4]Brewhouse!$AS$577:$AS$618,[4]Brewhouse!$AS$620:$AS$651,[4]Brewhouse!$AS$653:$AS$696,[4]Brewhouse!$AS$698:$AS$708,[4]Brewhouse!$AS$710:$AS$733,[4]Brewhouse!$AS$735:$AS$777,[4]Brewhouse!$AS$779:$AS$822,[4]Brewhouse!$AS$824:$AS$863,[4]Brewhouse!$AS$865:$AS$974,[4]Brewhouse!$AS$976:$AS$979,[4]Brewhouse!$AS$981:$AS$1007) -> 98.489671 | N51: 98
I52: GUINNESS | K52: =COUNTA([5]Brewhouse!$A$282:$A$289) -> 8 | L52: =AVERAGE([5]Brewhouse!$AU$269:$AU$279,[5]Brewhouse!$AU$282:$AU$289) -> 96.186177 | M52: =AVERAGE([5]Brewhouse!$AU$161:$AU$176,[5]Brewhouse!$AU$178:$AU$195,[5]Brewhouse!$AU$197:$AU$208,[5]Brewhouse!$AU$210:$AU$221,[5]Brewhouse!$AU$223:$AU$232,[5]Brewhouse!$AU$234:$AU$279,[5]Brewhouse!$AU$282:$AU$289) -> 96.64916 | N52: 98
I53: VITAMALT | K53: =COUNTA([6]Brewhouse!$A$158:$A$163) -> 6 | L53: =AVERAGE([6]Brewhouse!$AU$158:$AU$163) -> 94.60305 | M53: =AVERAGE([6]Brewhouse!$AU$91:$AU$101,[6]Brewhouse!$AU$103:$AU$112,[6]Brewhouse!$AU$114:$AU$123,[6]Brewhouse!$AU$125:$AU$134,[6]Brewhouse!$AU$136:$AU$145,[6]Brewhouse!$AU$147:$AU$156,[6]Brewhouse!$AU$158:$AU$163) -> 96.240014 | N53: 98
I54: MAXIMALT | N54: 98
I55: MACKESON | M55: =AVERAGE([7]Brewhouse!$AT$74:$AT$79) -> 93.959836 | N55: 98
I56: STARMALT | K56: =COUNTA([8]Brewhouse!$A$249:$A$254) -> 6 | L56: =AVERAGE([8]Brewhouse!$AY$249:$AY$254) -> 99.681996 | M56: =AVERAGE([8]Brewhouse!$AY$138:$AY$143,[8]Brewhouse!$AY$145:$AY$153,[8]Brewhouse!$AY$155,[8]Brewhouse!$AY$156:$AY$174,[8]Brewhouse!$AY$176:$AY$185,[8]Brewhouse!$AY$187:$AY$198,[8]Brewhouse!$AY$200:$AY$247,[8]Brewhouse!$AY$249:$AY$254) -> 98.774703 | N56: 98
I57: HR- P | M57: =AVERAGE([9]Brewhouse!$AW$13:$AW$14,[9]Brewhouse!$AW$16:$AW$17) -> 92.042628 | N57: 98
I58: Hurricane Reef | M58: =AVERAGE([9]Brewhouse!$AW$13:$AW$14) -> 88.376943 | N58: 98
K59: =SUM(K50:K58) -> 76 | L59: =((L50*K50)+(L51*K51)+(L52*K52)+(L53*K53)+(L54*K54)+(K57*L57)+(L55*K55)+(L56*K56)+(L58*K58))/(K59) -> 97.965422 | M59: =AVERAGE('[10]Closing- January 2023'!$L$42,'[11]Feb. 28th'!$L$42,'[12]March 31st'!$L$75,'[13]Apri 28th'!$L$51,L59) -> 98.06926 | N59: 98
J62: Daily Brewing Plan
J63: Brand | K63: Brews Achieved | L63: Average Brews per day
J64: CARIB | L64: MTD | M64: YTD | N64: TARGET
J65: STAG | K65: 5 | L65: =AVERAGE(#REF!,#REF!,K74,#REF!,#REF!,#REF!,#REF!,#REF!,#REF!,#REF!,#REF!) -> #REF! | M65: =AVERAGE(6,6,'[12]March 31st'!$L$80,'[14]June 30th '!$L$71,6,L65,'[15]July 31st'!$L$108,'[16]Aug 30th'!$L$124,7,[17]Oct.31st!$L$51) -> #REF! | N65: 9
J66: GUINN
J67: VITAMALT
...

Sheet Mar. 3rd
T1: P.G. | V1: Hot Time | X1: Process Time | Z1: Cooling Time
B2: Brewing Department Daily Process Loss Report | T2: Lower | U2: Upper | V2: Lower | W2: Upper | X2: Lower | Y2: Upper | Z2: Lower | AA2: Upper
S3: CARIB | T3: 11.6 | U3: 12 | V3: 0 | W3: 0.11805556 | X3: 0.22569444 | Y3: 0.26388889 | Z3: 0 | AA3: 60 | AC3: HR- PISNER
B4: Date: | C4: 45720 | J4: LOT WORT COLOUR: 3.0 | M4: Filter Sheets (Target 20 days) | S4: STAG | T4: 11.6 | U4: 12 | V4: 0 | W4: 0.11805556 | X4: 0.22569444 | Y4: 0.26388889 | Z4: 0 | AA4: 60
M5: Double | N5: Single | S5: GUINNESS | T5: 17 | U5: 17.5 | V5: 0 | W5: 0.10763889 | X5: 0.24652778 | Y5: 0.28472222 | Z5: 0 | AA5: 60
J6: MALT LOT: Lot 18 | L6: Sheet Day | S6: MACKESON | T6: 13.3 | U6: 13.5 | V6: 0 | W6: 0.12905093 | X6: 0.27430556 | Y6: 0.30208333 | Z6: 0
S7: STARMALT | T7: 17.1 | U7: 17.5 | V7: 0 | W7: 0.13605324 | X7: 0.27430556 | Y7: 0.30902778 | Z7: 0 | AA7: 60
B8: Brand | C8: Brew no. | D8: Kett. Hls | E8: Wort | F8: Cool Time(Mins) | G8: Cast. P.G. (Lab Result) | H8: Cast P.G. (Cellar Operator)-gravity | I8: Extr. Rec (80.9%) | J8: Theor. Extr. (77.5%) | K8: Boil Off /Vol. (4-6%) | L8: Boil Time | M8: Total Hot | N8: Brewing | O8: Operator | P8: Comments | Q8: Actual Pilsen Malt | S8: Hurricane Reef | T8: 16.6 | U8: 17 | V8: 0 | W8: 0.12905093 | X8: 0.27430556 | Y8: 0.30208333 | Z8: 0
E9: Meter (Hls) | F9: Target(< 60Mins) | M9: Time | S9: VITAMALT | T9: 14.4 | U9: 14.6 | V9: 0 | W9: 0.13905093 | X9: 0.26041667 | Y9: 0.29513889 | Z9: 0 | AA9: 75
B10: STARMALT | C10: =[22]Brewhouse!$A22 -> SM015 | D10: =[22]Brewhouse!$AH22 -> 55.1 | E10: =[22]Brewhouse!$AM22 -> 50.1 | F10: =[22]Brewhouse!$Z22 -> 67 | G10: =[22]Brewhouse!$AK22 -> 17.1 | H10: 17 | I10: =[22]Brewhouse!$AY22 -> 94.95313 | J10: =[22]Brewhouse!$AZ22 -> 94.587322 | K10: =[22]Brewhouse!$U22 -> 5.2268603 | L10: =[22]Brewhouse!$T22 -> 60 | M10: =[22]Brewhouse!$Y22-[22]Brewhouse!$X22 -> 0.12986111 | N10: =[22]Brewhouse!$AD22 -> 0.30763889 | O10: =[22]Brewhouse!$BC22 -> R.Sookram | S10: =B10 -> STARMALT | T10: =VLOOKUP($B10,$S$3:$Y$9,2,FALSE) -> 17.1 | U10: =VLOOKUP($B10,$S$3:$Y$9,3,FALSE) -> 17.5 | V10: =VLOOKUP($B10,$S$3:$Y$9,4,FALSE) -> 0 | W10: =VLOOKUP($B10,$S$3:$Y$9,5,FALSE) -> 0.13605324 | X10: =VLOOKUP($B10,$S$3:$Y$9,6,FALSE) -> 0.27430556 | Y10: =VLOOKUP($B10,$S$3:$Y$9,7,FALSE) -> 0.30902778 | Z10: =VLOOKUP($B10,$S$3:$AA$9,8,FALSE) -> 0 | AA10: =VLOOKUP($B10,$S$3:$AA$9,9,FALSE) -> 60
B11: STARMALT | C11: =[22]Brewhouse!$A23 -> SM016 | D11: =[22]Brewhouse!$AH23 -> 53.5 | E11: =[22]Brewhouse!$AM23 -> 50.7 | F11: =[22]Brewhouse!$Z23 -> 66 | G11: =[22]Brewhouse!$AK23 -> 17.8 | H11: 17.5 | I11: =[22]Brewhouse!$AY23 -> 100.21796 | J11: =[22]Brewhouse!$AZ23 -> 99.831509 | K11: =[22]Brewhouse!$U23 -> 3.7009346 | L11: =[22]Brewhouse!$T23 -> 60 | M11: =[22]Brewhouse!$Y23-[22]Brewhouse!$X23 -> 0.14444444 | N11: =[22]Brewhouse!$AD23 -> 0.31180556 | O11: =[22]Brewhouse!$BC23 -> K. Benjamin | S11: =B11 -> STARMALT | T11: =VLOOKUP($B11,$S$3:$Y$9,2,FALSE) -> 17.1 | U11: =VLOOKUP($B11,$S$3:$Y$9,3,FALSE) -> 17.5 | V11: =VLOOKUP($B11,$S$3:$Y$9,4,FALSE) -> 0 | W11: =VLOOKUP($B11,$S$3:$Y$9,5,FALSE) -> 0.13605324 | X11: =VLOOKUP($B11,$S$3:$Y$9,6,FALSE) -> 0.27430556 | Y11: =VLOOKUP($B11,$S$3:$Y$9,7,FALSE) -> 0.30902778 | Z11: =VLOOKUP($B11,$S$3:$AA$9,8,FALSE) -> 0 | AA11: =VLOOKUP($B11,$S$3:$AA$9,9,FALSE) -> 60
B12: STARMALT | C12: =[22]Brewhouse!$A24 -> SM017 | D12: =[22]Brewhouse!$AH24 -> 53.5 | E12: =[22]Brewhouse!$AM24 -> 51.3 | F12: =[22]Brewhouse!$Z24 -> 72 | G12: =[22]Brewhouse!$AK24 -> 17.2 | H12: 17 | I12: =[22]Brewhouse!$AY24 -> 92.417462 | J12: =[22]Brewhouse!$AZ24 -> 92.061092 | K12: =[22]Brewhouse!$U24 -> 1.8317757 | L12: =[22]Brewhouse!$T24 -> 60 | M12: =[22]Brewhouse!$Y24-[22]Brewhouse!$X24 -> 0.13194444 | N12: =[22]Brewhouse!$AD24 -> 0.29097222 | O12: =[22]Brewhouse!$BC24 -> K. Benjamin | S12: =B12 -> STARMALT | T12: =VLOOKUP($B12,$S$3:$Y$9,2,FALSE) -> 17.1 | U12: =VLOOKUP($B12,$S$3:$Y$9,3,FALSE) -> 17.5 | V12: =VLOOKUP($B12,$S$3:$Y$9,4,FALSE) -> 0 | W12: =VLOOKUP($B12,$S$3:$Y$9,5,FALSE) -> 0.13605324 | X12: =VLOOKUP($B12,$S$3:$Y$9,6,FALSE) -> 0.27430556 | Y12: =VLOOKUP($B12,$S$3:$Y$9,7,FALSE) -> 0.30902778 | Z12: =VLOOKUP($B12,$S$3:$AA$9,8,FALSE) -> 0 | AA12: =VLOOKUP($B12,$S$3:$AA$9,9,FALSE) -> 60
B13: STARMALT | C13: =[22]Brewhouse!$A25 -> SM018 | D13: =[22]Brewhouse!$AH25 -> 53.8 | E13: =[22]Brewhouse!$AM25 -> 50 | F13: =[22]Brewhouse!$Z25 -> 67 | G13: =[22]Brewhouse!$AK25 -> 17.7 | H13: 17.6 | I13: =[22]Brewhouse!$AY25 -> 98.212354 | J13: =[22]Brewhouse!$AZ25 -> 97.833638 | K13: =[22]Brewhouse!$U25 -> 3.866171 | L13: =[22]Brewhouse!$T25 -> 60 | M13: =[22]Brewhouse!$Y25-[22]Brewhouse!$X25 -> 0.12777778 | N13: =[22]Brewhouse!$AD25 -> 0.31041667 | O13: =[22]Brewhouse!$BC25 -> K. Benjamin | S13: =B13 -> STARMALT | T13: =VLOOKUP($B13,$S$3:$Y$9,2,FALSE) -> 17.1 | U13: =VLOOKUP($B13,$S$3:$Y$9,3,FALSE) -> 17.5 | V13: =VLOOKUP($B13,$S$3:$Y$9,4,FALSE) -> 0 | W13: =VLOOKUP($B13,$S$3:$Y$9,5,FALSE) -> 0.13605324 | X13: =VLOOKUP($B13,$S$3:$Y$9,6,FALSE) -> 0.27430556 | Y13: =VLOOKUP($B13,$S$3:$Y$9,7,FALSE) -> 0.30902778 | Z13: =VLOOKUP($B13,$S$3:$AA$9,8,FALSE) -> 0 | AA13: =VLOOKUP($B13,$S$3:$AA$9,9,FALSE) -> 60
B14: STARMALT | C14: =[22]Brewhouse!$A26 -> SM019 | D14: =[22]Brewhouse!$AH26 -> 53.4 | E14: =[22]Brewhouse!$AM26 -> 51 | F14: =[22]Brewhouse!$Z26 -> 72 | G14: =[22]Brewhouse!$AK26 -> 17.73 | H14: 17.6 | I14: =[22]Brewhouse!$AY26 -> 100.1766 | J14: =[22]Brewhouse!$AZ26 -> 99.790311 | K14: =[22]Brewhouse!$U26 -> 3.1460674 | L14: =[22]Brewhouse!$T26 -> 60 | M14: =[22]Brewhouse!$Y26-[22]Brewhouse!$X26 -> 0.12708333 | N14: =[22]Brewhouse!$AD26 -> 0.31319444 | O14: =[22]Brewhouse!$BC26 -> R. Regis | S14: =B14 -> STARMALT | T14: =VLOOKUP($B14,$S$3:$Y$9,2,FALSE) -> 17.1 | U14: =VLOOKUP($B14,$S$3:$Y$9,3,FALSE) -> 17.5 | V14: =VLOOKUP($B14,$S$3:$Y$9,4,FALSE) -> 0 | W14: =VLOOKUP($B14,$S$3:$Y$9,5,FALSE) -> 0.13605324 | X14: =VLOOKUP($B14,$S$3:$Y$9,6,FALSE) -> 0.27430556 | Y14: =VLOOKUP($B14,$S$3:$Y$9,7,FALSE) -> 0.30902778 | Z14: =VLOOKUP($B14,$S$3:$AA$9,8,FALSE) -> 0 | AA14: =VLOOKUP($B14,$S$3:$AA$9,9,FALSE) -> 60
B15: STARMALT | C15: =[22]Brewhouse!$A27 -> SM020 | D15: =[22]Brewhouse!$AH27 -> 53.8 | E15: =[22]Brewhouse!$AM27 -> 53 | F15: =[22]Brewhouse!$Z27 -> 54 | G15: =[22]Brewhouse!$AK27 -> 17.26 | H15: 17.1 | I15: =[22]Brewhouse!$AY27 -> 101.71397 | J15: =[22]Brewhouse!$AZ27 -> 101.32212 | K15: =[22]Brewhouse!$U27 -> 2.5650558 | L15: =[22]Brewhouse!$T27 -> 60 | M15: =[22]Brewhouse!$Y27-[22]Brewhouse!$X27 -> 0.125 | N15: =[22]Brewhouse!$AD27 -> 0.27777778 | O15: =[22]Brewhouse!$BC27 -> R. Regis | S15: =B15 -> STARMALT | T15: =VLOOKUP($B15,$S$3:$Y$9,2,FALSE) -> 17.1 | U15: =VLOOKUP($B15,$S$3:$Y$9,3,FALSE) -> 17.5 | V15: =VLOOKUP($B15,$S$3:$Y$9,4,FALSE) -> 0 | W15: =VLOOKUP($B15,$S$3:$Y$9,5,FALSE) -> 0.13605324 | X15: =VLOOKUP($B15,$S$3:$Y$9,6,FALSE) -> 0.27430556 | Y15: =VLOOKUP($B15,$S$3:$Y$9,7,FALSE) -> 0.30902778 | Z15: =VLOOKUP($B15,$S$3:$AA$9,8,FALSE) -> 0 | AA15: =VLOOKUP($B15,$S$3:$AA$9,9,FALSE) -> 60
B16: STARMALT | C16: =[22]Brewhouse!$A28 -> SM021 | D16: =[22]Brewhouse!$AH28 -> 53 | E16: =[22]Brewhouse!$AM28 -> 50.5 | F16: =[22]Brewhouse!$Z28 -> 70 | G16: =[22]Brewhouse!$AK28 -> 17.4 | I16: =[22]Brewhouse!$AY28 -> 97.028255 | J16: =[22]Brewhouse!$AZ28 -> 96.652378 | K16: =[22]Brewhouse!$U28 -> 0.90566038 | L16: =[22]Brewhouse!$T28 -> 59 | M16: =[22]Brewhouse!$Y28-[22]Brewhouse!$X28 -> 0.12222222 | N16: =[22]Brewhouse!$AD28 -> 0.27430556 | O16: =[22]Brewhouse!$BC28 -> R.Sookram | S16: =B16 -> STARMALT | T16: =VLOOKUP($B16,$S$3:$Y$9,2,FALSE) -> 17.1 | U16: =VLOOKUP($B16,$S$3:$Y$9,3,FALSE) -> 17.5 | V16: =VLOOKUP($B16,$S$3:$Y$9,4,FALSE) -> 0 | W16: =VLOOKUP($B16,$S$3:$Y$9,5,FALSE) -> 0.13605324 | X16: =VLOOKUP($B16,$S$3:$Y$9,6,FALSE) -> 0.27430556 | Y16: =VLOOKUP($B16,$S$3:$Y$9,7,FALSE) -> 0.30902778 | Z16: =VLOOKUP($B16,$S$3:$AA$9,8,FALSE) -> 0 | AA16: =VLOOKUP($B16,$S$3:$AA$9,9,FALSE) -> 60
B17: STARMALT | C17: =[22]Brewhouse!$A29 -> SM022 | D17: =[22]Brewhouse!$AH29 -> 52.9 | E17: =[22]Brewhouse!$AM29 -> 51.6 | F17: =[22]Brewhouse!$Z29 -> 84 | G17: =[22]Brewhouse!$AK29 -> 17.48 | I17: =[22]Brewhouse!$AY29 -> 99.806942 | J17: =[22]Brewhouse!$AZ29 -> 99.420655 | K17: =[22]Brewhouse!$U29 -> 0.71833648 | L17: =[22]Brewhouse!$T29 -> 60 | M17: =[22]Brewhouse!$Y29-[22]Brewhouse!$X29 -> 0.13541667 | N17: =[22]Brewhouse!$AD29 -> 0.2875 | O17: =[22]Brewhouse!$BC29 -> R.Sookram | S17: =B17 -> STARMALT | T17: =VLOOKUP($B17,$S$3:$Y$9,2,FALSE) -> 17.1 | U17: =VLOOKUP($B17,$S$3:$Y$9,3,FALSE) -> 17.5 | V17: =VLOOKUP($B17,$S$3:$Y$9,4,FALSE) -> 0 | W17: =VLOOKUP($B17,$S$3:$Y$9,5,FALSE) -> 0.13605324 | X17: =VLOOKUP($B17,$S$3:$Y$9,6,FALSE) -> 0.27430556 | Y17: =VLOOKUP($B17,$S$3:$Y$9,7,FALSE) -> 0.30902778 | Z17: =VLOOKUP($B17,$S$3:$AA$9,8,FALSE) -> 0 | AA17: =VLOOKUP($B17,$S$3:$AA$9,9,FALSE) -> 60
S20: =B20 -> 0 | T20: =VLOOKUP($B20,$S$3:$Y$9,2,FALSE) -> #N/A | U20: =VLOOKUP($B20,$S$3:$Y$9,3,FALSE) -> #N/A | V20: =VLOOKUP($B20,$S$3:$Y$9,4,FALSE) -> #N/A | W20: =VLOOKUP($B20,$S$3:$Y$9,5,FALSE) -> #N/A | X20: =VLOOKUP($B20,$S$3:$Y$9,6,FALSE) -> #N/A | Y20: =VLOOKUP($B20,$S$3:$Y$9,7,FALSE) -> #N/A | Z20: =VLOOKUP($B20,$S$3:$AA$9,8,FALSE) -> #N/A | AA20: =VLOOKUP($B20,$S$3:$AA$9,9,FALSE) -> #N/A
S21: =B21 -> 0 | T21: =VLOOKUP($B21,$S$3:$Y$9,2,FALSE) -> #N/A | U21: =VLOOKUP($B21,$S$3:$Y$9,3,FALSE) -> #N/A | V21: =VLOOKUP($B21,$S$3:$Y$9,4,FALSE) -> #N/A | W21: =VLOOKUP($B21,$S$3:$Y$9,5,FALSE) -> #N/A | X21: =VLOOKUP($B21,$S$3:$Y$9,6,FALSE) -> #N/A | Y21: =VLOOKUP($B21,$S$3:$Y$9,7,FALSE) -> #N/A | Z21: =VLOOKUP($B21,$S$3:$AA$9,8,FALSE) -> #N/A | AA21: =VLOOKUP($B21,$S$3:$AA$9,9,FALSE) -> #N/A
S22: =B22 -> 0 | T22: =VLOOKUP($B22,$S$3:$Y$9,2,FALSE) -> #N/A | U22: =VLOOKUP($B22,$S$3:$Y$9,3,FALSE) -> #N/A | V22: =VLOOKUP($B22,$S$3:$Y$9,4,FALSE) -> #N/A | W22: =VLOOKUP($B22,$S$3:$Y$9,5,FALSE) -> #N/A | X22: =VLOOKUP($B22,$S$3:$Y$9,6,FALSE) -> #N/A | Y22: =VLOOKUP($B22,$S$3:$Y$9,7,FALSE) -> #N/A | Z22: =VLOOKUP($B22,$S$3:$AA$9,8,FALSE) -> #N/A | AA22: =VLOOKUP($B22,$S$3:$AA$9,9,FALSE) -> #N/A
S23: =B23 -> 0 | T23: =VLOOKUP($B23,$S$3:$Y$9,2,FALSE) -> #N/A | U23: =VLOOKUP($B23,$S$3:$Y$9,3,FALSE) -> #N/A | V23: =VLOOKUP($B23,$S$3:$Y$9,4,FALSE) -> #N/A | W23: =VLOOKUP($B23,$S$3:$Y$9,5,FALSE) -> #N/A | X23: =VLOOKUP($B23,$S$3:$Y$9,6,FALSE) -> #N/A | Y23: =VLOOKUP($B23,$S$3:$Y$9,7,FALSE) -> #N/A | Z23: =VLOOKUP($B23,$S$3:$AA$9,8,FALSE) -> #N/A | AA23: =VLOOKUP($B23,$S$3:$AA$9,9,FALSE) -> #N/A
S24: =B24 -> 0 | T24: =VLOOKUP($B24,$S$3:$Y$9,2,FALSE) -> #N/A | U24: =VLOOKUP($B24,$S$3:$Y$9,3,FALSE) -> #N/A | V24: =VLOOKUP($B24,$S$3:$Y$9,4,FALSE) -> #N/A | W24: =VLOOKUP($B24,$S$3:$Y$9,5,FALSE) -> #N/A | X24: =VLOOKUP($B24,$S$3:$Y$9,6,FALSE) -> #N/A | Y24: =VLOOKUP($B24,$S$3:$Y$9,7,FALSE) -> #N/A | Z24: =VLOOKUP($B24,$S$3:$AA$9,8,FALSE) -> #N/A | AA24: =VLOOKUP($B24,$S$3:$AA$9,9,FALSE) -> #N/A
S25: =B25 -> 0 | T25: =VLOOKUP($B25,$S$3:$Y$9,2,FALSE) -> #N/A | U25: =VLOOKUP($B25,$S$3:$Y$9,3,FALSE) -> #N/A | V25: =VLOOKUP($B25,$S$3:$Y$9,4,FALSE) -> #N/A | W25: =VLOOKUP($B25,$S$3:$Y$9,5,FALSE) -> #N/A | X25: =VLOOKUP($B25,$S$3:$Y$9,6,FALSE) -> #N/A | Y25: =VLOOKUP($B25,$S$3:$Y$9,7,FALSE) -> #N/A | Z25: =VLOOKUP($B25,$S$3:$AA$9,8,FALSE) -> #N/A | AA25: =VLOOKUP($B25,$S$3:$AA$9,9,FALSE) -> #N/A
S26: =B26 -> 0 | T26: =VLOOKUP($B26,$S$3:$Y$9,2,FALSE) -> #N/A | U26: =VLOOKUP($B26,$S$3:$Y$9,3,FALSE) -> #N/A | V26: =VLOOKUP($B26,$S$3:$Y$9,4,FALSE) -> #N/A | W26: =VLOOKUP($B26,$S$3:$Y$9,5,FALSE) -> #N/A | X26: =VLOOKUP($B26,$S$3:$Y$9,6,FALSE) -> #N/A | Y26: =VLOOKUP($B26,$S$3:$Y$9,7,FALSE) -> #N/A | Z26: =VLOOKUP($B26,$S$3:$AA$9,8,FALSE) -> #N/A | AA26: =VLOOKUP($B26,$S$3:$AA$9,9,FALSE) -> #N/A
S27: =B27 -> 0 | T27: =VLOOKUP($B27,$S$3:$Y$9,2,FALSE) -> #N/A | U27: =VLOOKUP($B27,$S$3:$Y$9,3,FALSE) -> #N/A | V27: =VLOOKUP($B27,$S$3:$Y$9,4,FALSE) -> #N/A | W27: =VLOOKUP($B27,$S$3:$Y$9,5,FALSE) -> #N/A | X27: =VLOOKUP($B27,$S$3:$Y$9,6,FALSE) -> #N/A | Y27: =VLOOKUP($B27,$S$3:$Y$9,7,FALSE) -> #N/A | Z27: =VLOOKUP($B27,$S$3:$AA$9,8,FALSE) -> #N/A | AA27: =VLOOKUP($B27,$S$3:$AA$9,9,FALSE) -> #N/A
S28: =B28 -> 0 | T28: =VLOOKUP($B28,$S$3:$Y$9,2,FALSE) -> #N/A | U28: =VLOOKUP($B28,$S$3:$Y$9,3,FALSE) -> #N/A | V28: =VLOOKUP($B28,$S$3:$Y$9,4,FALSE) -> #N/A | W28: =VLOOKUP($B28,$S$3:$Y$9,5,FALSE) -> #N/A | X28: =VLOOKUP($B28,$S$3:$Y$9,6,FALSE) -> #N/A | Y28: =VLOOKUP($B28,$S$3:$Y$9,7,FALSE) -> #N/A | Z28: =VLOOKUP($B28,$S$3:$AA$9,8,FALSE) -> #N/A | AA28: =VLOOKUP($B28,$S$3:$AA$9,9,FALSE) -> #N/A
S29: =B29 -> 0 | T29: =VLOOKUP($B29,$S$3:$Y$9,2,FALSE) -> #N/A | U29: =VLOOKUP($B29,$S$3:$Y$9,3,FALSE) -> #N/A | V29: =VLOOKUP($B29,$S$3:$Y$9,4,FALSE) -> #N/A | W29: =VLOOKUP($B29,$S$3:$Y$9,5,FALSE) -> #N/A | X29: =VLOOKUP($B29,$S$3:$Y$9,6,FALSE) -> #N/A | Y29: =VLOOKUP($B29,$S$3:$Y$9,7,FALSE) -> #N/A | Z29: =VLOOKUP($B29,$S$3:$AA$9,8,FALSE) -> #N/A | AA29: =VLOOKUP($B29,$S$3:$AA$9,9,FALSE) -> #N/A
S30: =B30 -> 0 | T30: =VLOOKUP($B30,$S$3:$Y$9,2,FALSE) -> #N/A | U30: =VLOOKUP($B30,$S$3:$Y$9,3,FALSE) -> #N/A | V30: =VLOOKUP($B30,$S$3:$Y$9,4,FALSE) -> #N/A | W30: =VLOOKUP($B30,$S$3:$Y$9,5,FALSE) -> #N/A | X30: =VLOOKUP($B30,$S$3:$Y$9,6,FALSE) -> #N/A | Y30: =VLOOKUP($B30,$S$3:$Y$9,7,FALSE) -> #N/A | Z30: =VLOOKUP($B30,$S$3:$AA$9,8,FALSE) -> #N/A | AA30: =VLOOKUP($B30,$S$3:$AA$9,9,FALSE) -> #N/A
S31: =B31 -> 0 | T31: =VLOOKUP($B31,$S$3:$Y$9,2,FALSE) -> #N/A | U31: =VLOOKUP($B31,$S$3:$Y$9,3,FALSE) -> #N/A | V31: =VLOOKUP($B31,$S$3:$Y$9,4,FALSE) -> #N/A | W31: =VLOOKUP($B31,$S$3:$Y$9,5,FALSE) -> #N/A | X31: =VLOOKUP($B31,$S$3:$Y$9,6,FALSE) -> #N/A | Y31: =VLOOKUP($B31,$S$3:$Y$9,7,FALSE) -> #N/A | Z31: =VLOOKUP($B31,$S$3:$AA$9,8,FALSE) -> #N/A | AA31: =VLOOKUP($B31,$S$3:$AA$9,9,FALSE) -> #N/A
... S53: =B53 -> 0 | T53: =VLOOKUP($B53,$S$3:$Y$9,2,FALSE) -> #N/A | U53: =VLOOKUP($B53,$S$3:$Y$9,3,FALSE) -> #N/A | V53: =VLOOKUP($B53,$S$3:$Y$9,4,FALSE) -> #N/A | W53: =VLOOKUP($B53,$S$3:$Y$9,5,FALSE) -> #N/A | X53: =VLOOKUP($B53,$S$3:$Y$9,6,FALSE) -> #N/A | Y53: =VLOOKUP($B53,$S$3:$Y$9,7,FALSE) -> #N/A | Z53: =VLOOKUP($B53,$S$3:$AA$9,8,FALSE) -> #N/A | AA53: =VLOOKUP($B53,$S$3:$AA$9,9,FALSE) -> #N/A
I54: EXTRACT RECOVERY
B55: BRAND | D55: BBT P.G./ O.G | I55: Brand | J55: Actual | K55: MTD No. of Brews | L55: MTD | M55: YTD | N55: Target
I56: CARIB | M56: =AVERAGE([23]Brewhouse!$AU$102:$AU$171,[23]Brewhouse!$AU$173:$AU$253) -> 95.607057 | N56: 98
I57: STAG | M57: =AVERAGE([24]Brewhouse!$AS$15:$AS$64,[24]Brewhouse!$AS$66:$AS$102) -> 95.902722 | N57: 98
I58: GUINNESS | M58: =AVERAGE([25]Brewhouse!$AU$4:$AU$7,[25]Brewhouse!$AU$9:$AU$22) -> 96.218977 | N58: 98
I59: VITAMALT | M59: =AVERAGE([26]Brewhouse!$AV$5:$AV$14,[26]Brewhouse!$AV$16:$AV$19) -> 98.230958 | N59: 98
I60: MAXIMALT | N60: 98
I61: MACKESON | M61: =AVERAGE([27]Brewhouse!$AT$4:$AT$11) -> 94.812617 | N61: 98
I62: STARMALT | J62: =AVERAGE(I10:I17) -> 98.065834 | K62: =COUNTA([22]Brewhouse!$A$22:$A$29) -> 8 | L62: =AVERAGE([22]Brewhouse!$AY$22:$AY$29) -> 98.065834 | M62: =AVERAGE([22]Brewhouse!$AY$6:$AY$13,[22]Brewhouse!$AY$15:$AY$20,[22]Brewhouse!$AY$22:$AY$29) -> 95.660462 | N62: 98
I63: HR- Pils | M63: =AVERAGE([28]Brewhouse!$AU$5:$AU$8) -> 91.006888 | N63: 98
...

Sheet Mar. 4th
T1: P.G. | V1: Hot Time | X1: Process Time | Z1: Cooling Time
B2: Brewing Department Daily Process Loss Report | T2: Lower | U2: Upper | V2: Lower | W2: Upper | X2: Lower | Y2: Upper | Z2: Lower | AA2: Upper
S3: CARIB | T3: 11.6 | U3: 12 | V3: 0 | W3: 0.11805556 | X3: 0.22569444 | Y3: 0.26388889 | Z3: 0 | AA3: 60 | AC3: HR- PISNER
B4: Date: | C4: 45721 | J4: LOT WORT COLOUR: 3.0 | M4: Filter Sheets (Target 20 days) | S4: STAG | T4: 11.6 | U4: 12 | V4: 0 | W4: 0.11805556 | X4: 0.22569444 | Y4: 0.26388889 | Z4: 0 | AA4: 60
M5: Double | N5: Single | S5: GUINNESS | T5: 17 | U5: 17.5 | V5: 0 | W5: 0.10763889 | X5: 0.24652778 | Y5: 0.28472222 | Z5: 0 | AA5: 60
J6: MALT LOT: Lot 18 | L6: Sheet Day | S6: MACKESON | T6: 13.3 | U6: 13.5 | V6: 0 | W6: 0.12905093 | X6: 0.27430556 | Y6: 0.30208333 | Z6: 0
S7: STARMALT | T7: 17.1 | U7: 17.5 | V7: 0 | W7: 0.13605324 | X7: 0.27430556 | Y7: 0.30902778 | Z7: 0 | AA7: 60
B8: Brand | C8: Brew no. | D8: Kett. Hls | E8: Wort | F8: Cool Time(Mins) | G8: Cast. P.G. (Lab Result) | H8: Cast P.G. (Cellar Operator)-gravity | I8: Extr. Rec (80.9%) | J8: Theor. Extr. (77.5%) | K8: Boil Off /Vol. (4-6%) | L8: Boil Time | M8: Total Hot | N8: Brewing | O8: Operator | P8: Comments | Q8: Actual Pilsen Malt | S8: Hurricane Reef | T8: 16.6 | U8: 17 | V8: 0 | W8: 0.12905093 | X8: 0.27430556 | Y8: 0.30208333 | Z8: 0
E9: Meter (Hls) | F9: Target(< 60Mins) | M9: Time | S9: VITAMALT | T9: 14.4 | U9: 14.6 | V9: 0 | W9: 0.13905093 | X9: 0.26041667 | Y9: 0.29513889 | Z9: 0 | AA9: 75
B10: CARIB | C10: =[23]Brewhouse!$A255 -> CA152 | D10: =[23]Brewhouse!$AF255 -> 55.6 | E10: =[23]Brewhouse!$AI255 -> 52 | F10: =[23]Brewhouse!$V255 -> 60 | G10: =[23]Brewhouse!$AG255 -> 11.9 | H10: 11.9 | I10: =[23]Brewhouse!$AU255 -> 102.72901 | J10: =[23]Brewhouse!$AV255 -> 101.94335 | K10: =[23]Brewhouse!$Q255 -> 8.1769912 | L10: =[23]Brewhouse!$P255 -> 58 | M10: =[23]Brewhouse!$U255-[23]Brewhouse!$T255 -> 0.13611111 | N10: =[23]Brewhouse!$Z255 -> 0.28541667 | O10: =[23]Brewhouse!$AX255 -> R.Sookram | S10: =B10 -> CARIB | T10: =VLOOKUP($B10,$S$3:$Y$9,2,FALSE) -> 11.6 | U10: =VLOOKUP($B10,$S$3:$Y$9,3,FALSE) -> 12 | V10: =VLOOKUP($B10,$S$3:$Y$9,4,FALSE) -> 0 | W10: =VLOOKUP($B10,$S$3:$Y$9,5,FALSE) -> 0.11805556 | X10: =VLOOKUP($B10,$S$3:$Y$9,6,FALSE) -> 0.22569444 | Y10: =VLOOKUP($B10,$S$3:$Y$9,7,FALSE) -> 0.26388889 | Z10: =VLOOKUP($B10,$S$3:$AA$9,8,FALSE) -> 0 | AA10: =VLOOKUP($B10,$S$3:$AA$9,9,FALSE) -> 60
B11: CARIB | C11: =[23]Brewhouse!$A256 -> CA153 | D11: =[23]Brewhouse!$AF256 -> 53.3 | E11: =[23]Brewhouse!$AI256 -> 49.9 | F11: =[23]Brewhouse!$V256 -> 62 | G11: =[23]Brewhouse!$AG256 -> 11.8 | H11: 11.9 | I11: =[23]Brewhouse!$AU256 -> 97.709347 | J11: =[23]Brewhouse!$AV256 -> 96.962078 | K11: =[23]Brewhouse!$Q256 -> 6.1071429 | L11: =[23]Brewhouse!$P256 -> 61 | M11: =[23]Brewhouse!$U256-[23]Brewhouse!$T256 -> 0.11180556 | N11: =[23]Brewhouse!$Z256 -> 0.27083333 | O11: =[23]Brewhouse!$AX256 -> K.Benjamin | S11: =B11 -> CARIB | T11: =VLOOKUP($B11,$S$3:$Y$9,2,FALSE) -> 11.6 | U11: =VLOOKUP($B11,$S$3:$Y$9,3,FALSE) -> 12 | V11: =VLOOKUP($B11,$S$3:$Y$9,4,FALSE) -> 0 | W11: =VLOOKUP($B11,$S$3:$Y$9,5,FALSE) -> 0.11805556 | X11: =VLOOKUP($B11,$S$3:$Y$9,6,FALSE) -> 0.22569444 | Y11: =VLOOKUP($B11,$S$3:$Y$9,7,FALSE) -> 0.26388889 | Z11: =VLOOKUP($B11,$S$3:$AA$9,8,FALSE) -> 0 | AA11: =VLOOKUP($B11,$S$3:$AA$9,9,FALSE) -> 60
B12: CARIB | C12: =[23]Brewhouse!$A257 -> CA154 | D12: =[23]Brewhouse!$AF257 -> 52.4 | E12: =[23]Brewhouse!$AI257 -> 49 | F12: =[23]Brewhouse!$V257 -> 65 | G12: =[23]Brewhouse!$AG257 -> 11.9 | H12: 11.8 | I12: =[23]Brewhouse!$AU257 -> 97.03902 | J12: =[23]Brewhouse!$AV257 -> 96.297038 | K12: =[23]Brewhouse!$Q257 -> 7.2172352 | L12: =[23]Brewhouse!$P257 -> 60 | M12: =[23]Brewhouse!$U257-[23]Brewhouse!$T257 -> 0.11875 | N12: =[23]Brewhouse!$Z257 -> 0.28472222 | O12: =[23]Brewhouse!$AX257 -> K.Benjamin | S12: =B12 -> CARIB | T12: =VLOOKUP($B12,$S$3:$Y$9,2,FALSE) -> 11.6 | U12: =VLOOKUP($B12,$S$3:$Y$9,3,FALSE) -> 12 | V12: =VLOOKUP($B12,$S$3:$Y$9,4,FALSE) -> 0 | W12: =VLOOKUP($B12,$S$3:$Y$9,5,FALSE) -> 0.11805556 | X12: =VLOOKUP($B12,$S$3:$Y$9,6,FALSE) -> 0.22569444 | Y12: =VLOOKUP($B12,$S$3:$Y$9,7,FALSE) -> 0.26388889 | Z12: =VLOOKUP($B12,$S$3:$AA$9,8,FALSE) -> 0 | AA12: =VLOOKUP($B12,$S$3:$AA$9,9,FALSE) -> 60
B13: CARIB | C13: =[23]Brewhouse!$A258 -> CA155 | D13: =[23]Brewhouse!$AF258 -> 51.9 | E13: =[23]Brewhouse!$AI258 -> 49.5 | F13: =[23]Brewhouse!$V258 -> 58 | G13: =[23]Brewhouse!$AG258 -> 12.06 | H13: 11.7 | I13: =[23]Brewhouse!$AU258 -> 100.56008 | J13: =[23]Brewhouse!$AV258 -> 99.75845 | K13: =[23]Brewhouse!$Q258 -> 8.9323843 | L13: =[23]Brewhouse!$P258 -> 60 | M13: =[23]Brewhouse!$U258-[23]Brewhouse!$T258 -> 0.1125 | N13: =[23]Brewhouse!$Z258 -> 0.26180556 | O13: =[23]Brewhouse!$AX258 -> K.Benjamin | S13: =B13 -> CARIB | T13: =VLOOKUP($B13,$S$3:$Y$9,2,FALSE) -> 11.6 | U13: =VLOOKUP($B13,$S$3:$Y$9,3,FALSE) -> 12 | V13: =VLOOKUP($B13,$S$3:$Y$9,4,FALSE) -> 0 | W13: =VLOOKUP($B13,$S$3:$Y$9,5,FALSE) -> 0.11805556 | X13: =VLOOKUP($B13,$S$3:$Y$9,6,FALSE) -> 0.22569444 | Y13: =VLOOKUP($B13,$S$3:$Y$9,7,FALSE) -> 0.26388889 | Z13: =VLOOKUP($B13,$S$3:$AA$9,8,FALSE) -> 0 | AA13: =VLOOKUP($B13,$S$3:$AA$9,9,FALSE) -> 60
B14: CARIB | C14: =[23]Brewhouse!$A259 -> CA156 | D14: =[23]Brewhouse!$AF259 -> 52.9 | E14: =[23]Brewhouse!$AI259 -> 49.6 | F14: =[23]Brewhouse!$V259 -> 61 | G14: =[23]Brewhouse!$AG259 -> 12 | H14: 11.9 | I14: =[23]Brewhouse!$AU259 -> 100.13521 | J14: =[23]Brewhouse!$AV259 -> 99.33705 | K14: =[23]Brewhouse!$Q259 -> 9.0780142 | L14: =[23]Brewhouse!$P259 -> 62 | M14: =[23]Brewhouse!$U259-[23]Brewhouse!$T259 -> 0.1125 | N14: =[23]Brewhouse!$Z259 -> 0.27986111 | O14: =[23]Brewhouse!$AX259 -> R.Regis | S14: =B14 -> CARIB | T14: =VLOOKUP($B14,$S$3:$Y$9,2,FALSE) -> 11.6 | U14: =VLOOKUP($B14,$S$3:$Y$9,3,FALSE) -> 12 | V14: =VLOOKUP($B14,$S$3:$Y$9,4,FALSE) -> 0 | W14: =VLOOKUP($B14,$S$3:$Y$9,5,FALSE) -> 0.11805556 | X14: =VLOOKUP($B14,$S$3:$Y$9,6,FALSE) -> 0.22569444 | Y14: =VLOOKUP($B14,$S$3:$Y$9,7,FALSE) -> 0.26388889 | Z14: =VLOOKUP($B14,$S$3:$AA$9,8,FALSE) -> 0 | AA14: =VLOOKUP($B14,$S$3:$AA$9,9,FALSE) -> 60
B15: CARIB | C15: =[23]Brewhouse!$A260 -> CA157 | D15: =[23]Brewhouse!$AF260 -> 53.2 | E15: =[23]Brewhouse!$AI260 -> 50.1 | F15: =[23]Brewhouse!$V260 -> 49 | G15: =[23]Brewhouse!$AG260 -> 11.8 | H15: 11.7 | I15: =[23]Brewhouse!$AU260 -> 99.006073 | J15: =[23]Brewhouse!$AV260 -> 98.216788 | K15: =[23]Brewhouse!$Q260 -> 5.6115108 | L15: =[23]Brewhouse!$P260 -> 59 | M15: =[23]Brewhouse!$U260-[23]Brewhouse!$T260 -> 0.10902778 | N15: =[23]Brewhouse!$Z260 -> 0.27430556 | O15: =[23]Brewhouse!$AX260 -> R.Regis | S15: =B15 -> CARIB | T15: =VLOOKUP($B15,$S$3:$Y$9,2,FALSE) -> 11.6 | U15: =VLOOKUP($B15,$S$3:$Y$9,3,FALSE) -> 12 | V15: =VLOOKUP($B15,$S$3:$Y$9,4,FALSE) -> 0 | W15: =VLOOKUP($B15,$S$3:$Y$9,5,FALSE) -> 0.11805556 | X15: =VLOOKUP($B15,$S$3:$Y$9,6,FALSE) -> 0.22569444 | Y15: =VLOOKUP($B15,$S$3:$Y$9,7,FALSE) -> 0.26388889 | Z15: =VLOOKUP($B15,$S$3:$AA$9,8,FALSE) -> 0 | AA15: =VLOOKUP($B15,$S$3:$AA$9,9,FALSE) -> 60
B16: CARIB | C16: =[23]Brewhouse!$A261 -> CA158 | D16: =[23]Brewhouse!$AF261 -> 53.4 | E16: =[23]Brewhouse!$AI261 -> 50.4 | F16: =[23]Brewhouse!$V261 -> 63 | G16: =[23]Brewhouse!$AG261 -> 11.76 | I16: =[23]Brewhouse!$AU261 -> 99.47649 | J16: =[23]Brewhouse!$AV261 -> 98.683411 | K16: =[23]Brewhouse!$Q261 -> 6.5957447 | L16: =[23]Brewhouse!$P261 -> 61 | M16: =[23]Brewhouse!$U261-[23]Brewhouse!$T261 -> 0.12361111 | N16: =[23]Brewhouse!$Z261 -> 0.26180556 | O16: =[23]Brewhouse!$AX261 -> R.Regis | S16: =B16 -> CARIB | T16: =VLOOKUP($B16,$S$3:$Y$9,2,FALSE) -> 11.6 | U16: =VLOOKUP($B16,$S$3:$Y$9,3,FALSE) -> 12 | V16: =VLOOKUP($B16,$S$3:$Y$9,4,FALSE) -> 0 | W16: =VLOOKUP($B16,$S$3:$Y$9,5,FALSE) -> 0.11805556 | X16: =VLOOKUP($B16,$S$3:$Y$9,6,FALSE) -> 0.22569444 | Y16: =VLOOKUP($B16,$S$3:$Y$9,7,FALSE) -> 0.26388889 | Z16: =VLOOKUP($B16,$S$3:$AA$9,8,FALSE) -> 0 | AA16: =VLOOKUP($B16,$S$3:$AA$9,9,FALSE) -> 60
S17: =B17 -> 0 | T17: =VLOOKUP($B17,$S$3:$Y$9,2,FALSE) -> #N/A | U17: =VLOOKUP($B17,$S$3:$Y$9,3,FALSE) -> #N/A | V17: =VLOOKUP($B17,$S$3:$Y$9,4,FALSE) -> #N/A | W17: =VLOOKUP($B17,$S$3:$Y$9,5,FALSE) -> #N/A | X17: =VLOOKUP($B17,$S$3:$Y$9,6,FALSE) -> #N/A | Y17: =VLOOKUP($B17,$S$3:$Y$9,7,FALSE) -> #N/A | Z17: =VLOOKUP($B17,$S$3:$AA$9,8,FALSE) -> #N/A | AA17: =VLOOKUP($B17,$S$3:$AA$9,9,FALSE) -> #N/A
B18: STAG | C18: =[24]Brewhouse!$A105 -> ST089 | D18: =[24]Brewhouse!$AD105 -> 51.6 | E18: =[24]Brewhouse!$AG105 -> 48.2 | F18: =[24]Brewhouse!$V105 -> 63 | G18: =[24]Brewhouse!$AE105 -> 11.85 | H18: 11.8 | I18: =[24]Brewhouse!$AS105 -> 96.818003 | J18: =[24]Brewhouse!$AT105 -> 96.178448 | K18: =[24]Brewhouse!$Q105 -> 6.6298343 | L18: =[24]Brewhouse!$P105 -> 61 | M18: =[24]Brewhouse!$U105-[24]Brewhouse!$T105 -> 0.11666667 | N18: =[24]Brewhouse!$AW105 -> 0.26111111 | O18: =[24]Brewhouse!$AV105 -> R.Sookram | S18: =B18 -> STAG | T18: =VLOOKUP($B18,$S$3:$Y$9,2,FALSE) -> 11.6 | U18: =VLOOKUP($B18,$S$3:$Y$9,3,FALSE) -> 12 | V18: =VLOOKUP($B18,$S$3:$Y$9,4,FALSE) -> 0 | W18: =VLOOKUP($B18,$S$3:$Y$9,5,FALSE) -> 0.11805556 | X18: =VLOOKUP($B18,$S$3:$Y$9,6,FALSE) -> 0.22569444 | Y18: =VLOOKUP($B18,$S$3:$Y$9,7,FALSE) -> 0.26388889 | Z18: =VLOOKUP($B18,$S$3:$AA$9,8,FALSE) -> 0 | AA18: =VLOOKUP($B18,$S$3:$AA$9,9,FALSE) -> 60
B19: 45721
B20: STAG | C20: =[24]Brewhouse!$A106 -> ST090 | D20: =[24]Brewhouse!$AD106 -> 52.4 | E20: =[24]Brewhouse!$AG106 -> 48.9 | F20: =[24]Brewhouse!$V106 -> 58 | G20: =[24]Brewhouse!$AE106 -> 11.74 | I20: =[24]Brewhouse!$AS106 -> 96.728268 | J20: =[24]Brewhouse!$AT106 -> 96.089719 | K20: =[24]Brewhouse!$Q106 -> 7.4275362 | L20: =[24]Brewhouse!$P106 -> 62 | M20: =[24]Brewhouse!$U106-[24]Brewhouse!$T106 -> 0.10833333 | N20: =[24]Brewhouse!$AW106 -> 0.26111111 | O20: =[24]Brewhouse!$AV106 -> R.Sookram | S20: =B20 -> STAG | T20: =VLOOKUP($B20,$S$3:$Y$9,2,FALSE) -> 11.6 | U20: =VLOOKUP($B20,$S$3:$Y$9,3,FALSE) -> 12 | V20: =VLOOKUP($B20,$S$3:$Y$9,4,FALSE) -> 0 | W20: =VLOOKUP($B20,$S$3:$Y$9,5,FALSE) -> 0.11805556 | X20: =VLOOKUP($B20,$S$3:$Y$9,6,FALSE) -> 0.22569444 | Y20: =VLOOKUP($B20,$S$3:$Y$9,7,FALSE) -> 0.26388889 | Z20: =VLOOKUP($B20,$S$3:$AA$9,8,FALSE) -> 0 | AA20: =VLOOKUP($B20,$S$3:$AA$9,9,FALSE) -> 60
S21: =B21 -> 0 | T21: =VLOOKUP($B21,$S$3:$Y$9,2,FALSE) -> #N/A | U21: =VLOOKUP($B21,$S$3:$Y$9,3,FALSE) -> #N/A | V21: =VLOOKUP($B21,$S$3:$Y$9,4,FALSE) -> #N/A | W21: =VLOOKUP($B21,$S$3:$Y$9,5,FALSE) -> #N/A | X21: =VLOOKUP($B21,$S$3:$Y$9,6,FALSE) -> #N/A | Y21: =VLOOKUP($B21,$S$3:$Y$9,7,FALSE) -> #N/A | Z21: =VLOOKUP($B21,$S$3:$AA$9,8,FALSE) -> #N/A | AA21: =VLOOKUP($B21,$S$3:$AA$9,9,FALSE) -> #N/A
S22: =B22 -> 0 | T22: =VLOOKUP($B22,$S$3:$Y$9,2,FALSE) -> #N/A | U22: =VLOOKUP($B22,$S$3:$Y$9,3,FALSE) -> #N/A | V22: =VLOOKUP($B22,$S$3:$Y$9,4,FALSE) -> #N/A | W22: =VLOOKUP($B22,$S$3:$Y$9,5,FALSE) -> #N/A | X22: =VLOOKUP($B22,$S$3:$Y$9,6,FALSE) -> #N/A | Y22: =VLOOKUP($B22,$S$3:$Y$9,7,FALSE) -> #N/A | Z22: =VLOOKUP($B22,$S$3:$AA$9,8,FALSE) -> #N/A | AA22: =VLOOKUP($B22,$S$3:$AA$9,9,FALSE) -> #N/A
S23: =B23 -> 0 | T23: =VLOOKUP($B23,$S$3:$Y$9,2,FALSE) -> #N/A | U23: =VLOOKUP($B23,$S$3:$Y$9,3,FALSE) -> #N/A | V23: =VLOOKUP($B23,$S$3:$Y$9,4,FALSE) -> #N/A | W23: =VLOOKUP($B23,$S$3:$Y$9,5,FALSE) -> #N/A | X23: =VLOOKUP($B23,$S$3:$Y$9,6,FALSE) -> #N/A | Y23: =VLOOKUP($B23,$S$3:$Y$9,7,FALSE) -> #N/A | Z23: =VLOOKUP($B23,$S$3:$AA$9,8,FALSE) -> #N/A | AA23: =VLOOKUP($B23,$S$3:$AA$9,9,FALSE) -> #N/A
S24: =B24 -> 0 | T24: =VLOOKUP($B24,$S$3:$Y$9,2,FALSE) -> #N/A | U24: =VLOOKUP($B24,$S$3:$Y$9,3,FALSE) -> #N/A | V24: =VLOOKUP($B24,$S$3:$Y$9,4,FALSE) -> #N/A | W24: =VLOOKUP($B24,$S$3:$Y$9,5,FALSE) -> #N/A | X24: =VLOOKUP($B24,$S$3:$Y$9,6,FALSE) -> #N/A | Y24: =VLOOKUP($B24,$S$3:$Y$9,7,FALSE) -> #N/A | Z24: =VLOOKUP($B24,$S$3:$AA$9,8,FALSE) -> #N/A | AA24: =VLOOKUP($B24,$S$3:$AA$9,9,FALSE) -> #N/A
S25: =B25 -> 0 | T25: =VLOOKUP($B25,$S$3:$Y$9,2,FALSE) -> #N/A | U25: =VLOOKUP($B25,$S$3:$Y$9,3,FALSE) -> #N/A | V25: =VLOOKUP($B25,$S$3:$Y$9,4,FALSE) -> #N/A | W25: =VLOOKUP($B25,$S$3:$Y$9,5,FALSE) -> #N/A | X25: =VLOOKUP($B25,$S$3:$Y$9,6,FALSE) -> #N/A | Y25: =VLOOKUP($B25,$S$3:$Y$9,7,FALSE) -> #N/A | Z25: =VLOOKUP($B25,$S$3:$AA$9,8,FALSE) -> #N/A | AA25: =VLOOKUP($B25,$S$3:$AA$9,9,FALSE) -> #N/A
S26: =B26 -> 0 | T26: =VLOOKUP($B26,$S$3:$Y$9,2,FALSE) -> #N/A | U26: =VLOOKUP($B26,$S$3:$Y$9,3,FALSE) -> #N/A | V26: =VLOOKUP($B26,$S$3:$Y$9,4,FALSE) -> #N/A | W26: =VLOOKUP($B26,$S$3:$Y$9,5,FALSE) -> #N/A | X26: =VLOOKUP($B26,$S$3:$Y$9,6,FALSE) -> #N/A | Y26: =VLOOKUP($B26,$S$3:$Y$9,7,FALSE) -> #N/A | Z26: =VLOOKUP($B26,$S$3:$AA$9,8,FALSE) -> #N/A | AA26: =VLOOKUP($B26,$S$3:$AA$9,9,FALSE) -> #N/A
S27: =B27 -> 0 | T27: =VLOOKUP($B27,$S$3:$Y$9,2,FALSE) -> #N/A | U27: =VLOOKUP($B27,$S$3:$Y$9,3,FALSE) -> #N/A | V27: =VLOOKUP($B27,$S$3:$Y$9,4,FALSE) -> #N/A | W27: =VLOOKUP($B27,$S$3:$Y$9,5,FALSE) -> #N/A | X27: =VLOOKUP($B27,$S$3:$Y$9,6,FALSE) -> #N/A | Y27: =VLOOKUP($B27,$S$3:$Y$9,7,FALSE) -> #N/A | Z27: =VLOOKUP($B27,$S$3:$AA$9,8,FALSE) -> #N/A | AA27: =VLOOKUP($B27,$S$3:$AA$9,9,FALSE) -> #N/A
S28: =B28 -> 0 | T28: =VLOOKUP($B28,$S$3:$Y$9,2,FALSE) -> #N/A | U28: =VLOOKUP($B28,$S$3:$Y$9,3,FALSE) -> #N/A | V28: =VLOOKUP($B28,$S$3:$Y$9,4,FALSE) -> #N/A | W28: =VLOOKUP($B28,$S$3:$Y$9,5,FALSE) -> #N/A | X28: =VLOOKUP($B28,$S$3:$Y$9,6,FALSE) -> #N/A | Y28: =VLOOKUP($B28,$S$3:$Y$9,7,FALSE) -> #N/A | Z28: =VLOOKUP($B28,$S$3:$AA$9,8,FALSE) -> #N/A | AA28: =VLOOKUP($B28,$S$3:$AA$9,9,FALSE) -> #N/A
S29: =B29 -> 0 | T29: =VLOOKUP($B29,$S$3:$Y$9,2,FALSE) -> #N/A | U29: =VLOOKUP($B29,$S$3:$Y$9,3,FALSE) -> #N/A | V29: =VLOOKUP($B29,$S$3:$Y$9,4,FALSE) -> #N/A | W29: =VLOOKUP($B29,$S$3:$Y$9,5,FALSE) -> #N/A | X29: =VLOOKUP($B29,$S$3:$Y$9,6,FALSE) -> #N/A | Y29: =VLOOKUP($B29,$S$3:$Y$9,7,FALSE) -> #N/A | Z29: =VLOOKUP($B29,$S$3:$AA$9,8,FALSE) -> #N/A | AA29: =VLOOKUP($B29,$S$3:$AA$9,9,FALSE) -> #N/A
S30: =B30 -> 0 | T30: =VLOOKUP($B30,$S$3:$Y$9,2,FALSE) -> #N/A | U30: =VLOOKUP($B30,$S$3:$Y$9,3,FALSE) -> #N/A | V30: =VLOOKUP($B30,$S$3:$Y$9,4,FALSE) -> #N/A | W30: =VLOOKUP($B30,$S$3:$Y$9,5,FALSE) -> #N/A | X30: =VLOOKUP($B30,$S$3:$Y$9,6,FALSE) -> #N/A | Y30: =VLOOKUP($B30,$S$3:$Y$9,7,FALSE) -> #N/A | Z30: =VLOOKUP($B30,$S$3:$AA$9,8,FALSE) -> #N/A | AA30: =VLOOKUP($B30,$S$3:$AA$9,9,FALSE) -> #N/A
S31: =B31 -> 0 | T31: =VLOOKUP($B31,$S$3:$Y$9,2,FALSE) -> #N/A | U31: =VLOOKUP($B31,$S$3:$Y$9,3,FALSE) -> #N/A | V31: =VLOOKUP($B31,$S$3:$Y$9,4,FALSE) -> #N/A | W31: =VLOOKUP($B31,$S$3:$Y$9,5,FALSE) -> #N/A | X31: =VLOOKUP($B31,$S$3:$Y$9,6,FALSE) -> #N/A | Y31: =VLOOKUP($B31,$S$3:$Y$9,7,FALSE) -> #N/A | Z31: =VLOOKUP($B31,$S$3:$AA$9,8,FALSE) -> #N/A | AA31: =VLOOKUP($B31,$S$3:$AA$9,9,FALSE) -> #N/A
S32: =B32 -> 0 | T32: =VLOOKUP($B32,$S$3:$Y$9,2,FALSE) -> #N/A | U32: =VLOOKUP($B32,$S$3:$Y$9,3,FALSE) -> #N/A | V32: =VLOOKUP($B32,$S$3:$Y$9,4,FALSE) -> #N/A | W32: =VLOOKUP($B32,$S$3:$Y$9,5,FALSE) -> #N/A | X32: =VLOOKUP($B32,$S$3:$Y$9,6,FALSE) -> #N/A | Y32: =VLOOKUP($B32,$S$3:$Y$9,7,FALSE) -> #N/A | Z32: =VLOOKUP($B32,$S$3:$AA$9,8,FALSE) -> #N/A | AA32: =VLOOKUP($B32,$S$3:$AA$9,9,FALSE) -> #N/A
... S54: =B54 -> 0 | T54: =VLOOKUP($B54,$S$3:$Y$9,2,FALSE) -> #N/A | U54: =VLOOKUP($B54,$S$3:$Y$9,3,FALSE) -> #N/A | V54: =VLOOKUP($B54,$S$3:$Y$9,4,FALSE) -> #N/A | W54: =VLOOKUP($B54,$S$3:$Y$9,5,FALSE) -> #N/A | X54: =VLOOKUP($B54,$S$3:$Y$9,6,FALSE) -> #N/A | Y54: =VLOOKUP($B54,$S$3:$Y$9,7,FALSE) -> #N/A | Z54: =VLOOKUP($B54,$S$3:$AA$9,8,FALSE) -> #N/A | AA54: =VLOOKUP($B54,$S$3:$AA$9,9,FALSE) -> #N/A
I55: EXTRACT RECOVERY
B56: BRAND | D56: BBT P.G./ O.G | I56: Brand | J56: Actual | K56: MTD No. of Brews | L56: MTD | M56: YTD | N56: Target
B57: =I57 -> CARIB | C57: {=[23]Process!$D$209:$D$216} -> 12.06 | D57: 11.88 | I57: CARIB | J57: =AVERAGE(I10:I16) -> 99.522175 | K57: =COUNTA([23]Brewhouse!$A$255:$A$261) -> 7 | L57: =AVERAGE([23]Brewhouse!$AU$255:$AU$261) -> 99.522175 | M57: =AVERAGE([23]Brewhouse!$AU$102:$AU$171,[23]Brewhouse!$AU$173:$AU$253,[23]Brewhouse!$AU$255:$AU$261) -> 95.780512 | N57: 98
C58: 11.9 | I58: STAG | J58: =AVERAGE(I18) -> 96.818003 | K58: =COUNTA([24]Brewhouse!$A$105) -> 1 | L58: =AVERAGE([24]Brewhouse!$AS$105) -> 96.818003 | M58: =AVERAGE([24]Brewhouse!$AS$15:$AS$64,[24]Brewhouse!$AS$66:$AS$103,[24]Brewhouse!$AS$105) -> 95.898348 | N58: 98
C59: 11.8 | D59: 11.92 | I59: GUINNESS | M59: =AVERAGE([25]Brewhouse!$AU$4:$AU$7,[25]Brewhouse!$AU$9:$AU$22) -> 96.218977 | N59: 98
C60: 11.7 | I60: VITAMALT | M60: =AVERAGE([26]Brewhouse!$AV$5:$AV$14,[26]Brewhouse!$AV$16:$AV$19) -> 98.230958 | N60: 98
C61: 11.89 | D61: 11.94 | I61: MAXIMALT | N61: 98
...

Sheet Mar. 5th 
T1: P.G. | V1: Hot Time | X1: Process Time | Z1: Cooling Time
B2: Brewing Department Daily Process Loss Report | T2: Lower | U2: Upper | V2: Lower | W2: Upper | X2: Lower | Y2: Upper | Z2: Lower | AA2: Upper
S3: CARIB | T3: 11.6 | U3: 12 | V3: 0 | W3: 0.11805556 | X3: 0.22569444 | Y3: 0.26388889 | Z3: 0 | AA3: 60 | AC3: HR- PISNER
B4: Date: | J4: LOT WORT COLOUR: 3.0 | M4: Filter Sheets (Target 20 days) | S4: STAG | T4: 11.6 | U4: 12 | V4: 0 | W4: 0.11805556 | X4: 0.22569444 | Y4: 0.26388889 | Z4: 0 | AA4: 60
C5: 45722 | M5: Double | N5: Single | S5: GUINNESS | T5: 17 | U5: 17.5 | V5: 0 | W5: 0.10763889 | X5: 0.24652778 | Y5: 0.28472222 | Z5: 0 | AA5: 60
J6: MALT LOT: Lot 18 | L6: Sheet Day | S6: MACKESON | T6: 13.3 | U6: 13.5 | V6: 0 | W6: 0.12905093 | X6: 0.27430556 | Y6: 0.30208333 | Z6: 0
S7: STARMALT | T7: 17.1 | U7: 17.5 | V7: 0 | W7: 0.13605324 | X7: 0.27430556 | Y7: 0.30902778 | Z7: 0 | AA7: 60
B8: Brand | C8: Brew no. | D8: Kett. Hls | E8: Wort | F8: Cool Time(Mins) | G8: Cast. P.G. (Lab Result) | H8: Cast P.G. (Cellar Operator)-gravity | I8: Extr. Rec (80.9%) | J8: Theor. Extr. (77.5%) | K8: Boil Off /Vol. (4-6%) | L8: Boil Time | M8: Total Hot | N8: Brewing | O8: Operator | P8: Comments | Q8: Actual Pilsen Malt | S8: Hurricane Reef | T8: 16.6 | U8: 17 | V8: 0 | W8: 0.12905093 | X8: 0.27430556 | Y8: 0.30208333 | Z8: 0
E9: Meter (Hls) | F9: Target(< 60Mins) | M9: Time | S9: VITAMALT | T9: 14.4 | U9: 14.6 | V9: 0 | W9: 0.13905093 | X9: 0.26041667 | Y9: 0.29513889 | Z9: 0 | AA9: 75
B10: STAG | C10: =[24]Brewhouse!$A106 -> ST090 | D10: =[24]Brewhouse!$AD106 -> 52.4 | E10: =[24]Brewhouse!$AG106 -> 48.9 | F10: =[24]Brewhouse!$V106 -> 58 | G10: =[24]Brewhouse!$AE106 -> 11.74 | H10: 11.8 | I10: =[24]Brewhouse!$AS106 -> 96.728268 | J10: =[24]Brewhouse!$AT106 -> 96.089719 | K10: =[24]Brewhouse!$Q106 -> 7.4275362 | L10: =[24]Brewhouse!$P106 -> 62 | M10: =[24]Brewhouse!$U106-[24]Brewhouse!$T106 -> 0.10833333 | N10: =[24]Brewhouse!$AW106 -> 0.26111111 | O10: =[24]Brewhouse!$AV106 -> R.Sookram | S10: =B10 -> STAG | T10: =VLOOKUP($B10,$S$3:$Y$9,2,FALSE) -> 11.6 | U10: =VLOOKUP($B10,$S$3:$Y$9,3,FALSE) -> 12 | V10: =VLOOKUP($B10,$S$3:$Y$9,4,FALSE) -> 0 | W10: =VLOOKUP($B10,$S$3:$Y$9,5,FALSE) -> 0.11805556 | X10: =VLOOKUP($B10,$S$3:$Y$9,6,FALSE) -> 0.22569444 | Y10: =VLOOKUP($B10,$S$3:$Y$9,7,FALSE) -> 0.26388889 | Z10: =VLOOKUP($B10,$S$3:$AA$9,8,FALSE) -> 0 | AA10: =VLOOKUP($B10,$S$3:$AA$9,9,FALSE) -> 60
B11: STAG | C11: =[24]Brewhouse!$A107 -> ST091 | D11: =[24]Brewhouse!$AD107 -> 50.5 | E11: =[24]Brewhouse!$AG107 -> 47.1 | F11: =[24]Brewhouse!$V107 -> 57 | G11: =[24]Brewhouse!$AE107 -> 11.9 | H11: 11.8 | I11: =[24]Brewhouse!$AS107 -> 94.725921 | J11: =[24]Brewhouse!$AT107 -> 94.100388 | K11: =[24]Brewhouse!$Q107 -> 7.4626866 | L11: =[24]Brewhouse!$P107 -> 60 | M11: =[24]Brewhouse!$U107-[24]Brewhouse!$T107 -> 0.12152778 | N11: =[24]Brewhouse!$AW107 -> 0.30138889 | O11: =[24]Brewhouse!$AV107 -> R.Sookram | S11: =B11 -> STAG | T11: =VLOOKUP($B11,$S$3:$Y$9,2,FALSE) -> 11.6 | U11: =VLOOKUP($B11,$S$3:$Y$9,3,FALSE) -> 12 | V11: =VLOOKUP($B11,$S$3:$Y$9,4,FALSE) -> 0 | W11: =VLOOKUP($B11,$S$3:$Y$9,5,FALSE) -> 0.11805556 | X11: =VLOOKUP($B11,$S$3:$Y$9,6,FALSE) -> 0.22569444 | Y11: =VLOOKUP($B11,$S$3:$Y$9,7,FALSE) -> 0.26388889 | Z11: =VLOOKUP($B11,$S$3:$AA$9,8,FALSE) -> 0 | AA11: =VLOOKUP($B11,$S$3:$AA$9,9,FALSE) -> 60
B12: STAG | C12: =[24]Brewhouse!$A108 -> ST092 | D12: =[24]Brewhouse!$AD108 -> 52.2 | E12: =[24]Brewhouse!$AG108 -> 48.9 | F12: =[24]Brewhouse!$V108 -> 68 | G12: =[24]Brewhouse!$AE108 -> 11.7 | I12: =[24]Brewhouse!$AS108 -> 96.728268 | J12: =[24]Brewhouse!$AT108 -> 96.089719 | K12: =[24]Brewhouse!$Q108 -> 4.8598131 | L12: =[24]Brewhouse!$P108 -> 59 | M12: =[24]Brewhouse!$U108-[24]Brewhouse!$T108 -> 0.11805556 | N12: =[24]Brewhouse!$AW108 -> 0.27083333 | O12: =[24]Brewhouse!$AV108 -> K. Benjamin | S12: =B12 -> STAG | T12: =VLOOKUP($B12,$S$3:$Y$9,2,FALSE) -> 11.6 | U12: =VLOOKUP($B12,$S$3:$Y$9,3,FALSE) -> 12 | V12: =VLOOKUP($B12,$S$3:$Y$9,4,FALSE) -> 0 | W12: =VLOOKUP($B12,$S$3:$Y$9,5,FALSE) -> 0.11805556 | X12: =VLOOKUP($B12,$S$3:$Y$9,6,FALSE) -> 0.22569444 | Y12: =VLOOKUP($B12,$S$3:$Y$9,7,FALSE) -> 0.26388889 | Z12: =VLOOKUP($B12,$S$3:$AA$9,8,FALSE) -> 0 | AA12: =VLOOKUP($B12,$S$3:$AA$9,9,FALSE) -> 60
B14: CARIB | C14: =[23]Brewhouse!$A262 -> CA159 | D14: =[23]Brewhouse!$AF262 -> 52.9 | E14: =[23]Brewhouse!$AI262 -> 48.8 | F14: =[23]Brewhouse!$V262 -> 71 | G14: =[23]Brewhouse!$AG262 -> 12.2 | H14: 12.2 | I14: =[23]Brewhouse!$AU262 -> 103.4404 | J14: =[23]Brewhouse!$AV262 -> 102.61706 | K14: =[23]Brewhouse!$Q262 -> 3.575419 | L14: =[23]Brewhouse!$P262 -> 61 | M14: =[23]Brewhouse!$U262-[23]Brewhouse!$T262 -> 0.12222222 | N14: =[23]Brewhouse!$Z262 -> 0.25833333 | O14: =[23]Brewhouse!$AX262 -> K.Benjamin | S14: =B14 -> CARIB | T14: =VLOOKUP($B14,$S$3:$Y$9,2,FALSE) -> 11.6 | U14: =VLOOKUP($B14,$S$3:$Y$9,3,FALSE) -> 12 | V14: =VLOOKUP($B14,$S$3:$Y$9,4,FALSE) -> 0 | W14: =VLOOKUP($B14,$S$3:$Y$9,5,FALSE) -> 0.11805556 | X14: =VLOOKUP($B14,$S$3:$Y$9,6,FALSE) -> 0.22569444 | Y14: =VLOOKUP($B14,$S$3:$Y$9,7,FALSE) -> 0.26388889 | Z14: =VLOOKUP($B14,$S$3:$AA$9,8,FALSE) -> 0 | AA14: =VLOOKUP($B14,$S$3:$AA$9,9,FALSE) -> 60
B15: CARIB | C15: =[23]Brewhouse!$A263 -> CA160 | D15: =[23]Brewhouse!$AF263 -> 53.5 | E15: =[23]Brewhouse!$AI263 -> 49.9 | F15: =[23]Brewhouse!$V263 -> 59 | G15: =[23]Brewhouse!$AG263 -> 12 | H15: 12 | I15: =[23]Brewhouse!$AU263 -> 103.55524 | J15: =[23]Brewhouse!$AV263 -> 102.73084 | K15: =[23]Brewhouse!$Q263 -> 5.7913669 | L15: =[23]Brewhouse!$P263 -> 61 | M15: =[23]Brewhouse!$U263-[23]Brewhouse!$T263 -> 0.11388889 | N15: =[23]Brewhouse!$Z263 -> 0.26041667 | O15: =[23]Brewhouse!$AX263 -> K.Benjamin | S15: =B15 -> CARIB | T15: =VLOOKUP($B15,$S$3:$Y$9,2,FALSE) -> 11.6 | U15: =VLOOKUP($B15,$S$3:$Y$9,3,FALSE) -> 12 | V15: =VLOOKUP($B15,$S$3:$Y$9,4,FALSE) -> 0 | W15: =VLOOKUP($B15,$S$3:$Y$9,5,FALSE) -> 0.11805556 | X15: =VLOOKUP($B15,$S$3:$Y$9,6,FALSE) -> 0.22569444 | Y15: =VLOOKUP($B15,$S$3:$Y$9,7,FALSE) -> 0.26388889 | Z15: =VLOOKUP($B15,$S$3:$AA$9,8,FALSE) -> 0 | AA15: =VLOOKUP($B15,$S$3:$AA$9,9,FALSE) -> 60
B16: CARIB | C16: =[23]Brewhouse!$A264 -> CA161 | D16: =[23]Brewhouse!$AF264 -> 54.2 | E16: =[23]Brewhouse!$AI264 -> 51 | F16: =[23]Brewhouse!$V264 -> 69 | G16: =[23]Brewhouse!$AG264 -> 11.7 | H16: 11.7 | I16: =[23]Brewhouse!$AU264 -> 103.31965 | J16: =[23]Brewhouse!$AV264 -> 102.49722 | K16: =[23]Brewhouse!$Q264 -> 6.5034965 | L16: =[23]Brewhouse!$P264 -> 60 | M16: =[23]Brewhouse!$U264-[23]Brewhouse!$T264 -> 0.12083333 | N16: =[23]Brewhouse!$Z264 -> 0.26458333 | O16: =[23]Brewhouse!$AX264 -> R.Regis | S16: =B16 -> CARIB | T16: =VLOOKUP($B16,$S$3:$Y$9,2,FALSE) -> 11.6 | U16: =VLOOKUP($B16,$S$3:$Y$9,3,FALSE) -> 12 | V16: =VLOOKUP($B16,$S$3:$Y$9,4,FALSE) -> 0 | W16: =VLOOKUP($B16,$S$3:$Y$9,5,FALSE) -> 0.11805556 | X16: =VLOOKUP($B16,$S$3:$Y$9,6,FALSE) -> 0.22569444 | Y16: =VLOOKUP($B16,$S$3:$Y$9,7,FALSE) -> 0.26388889 | Z16: =VLOOKUP($B16,$S$3:$AA$9,8,FALSE) -> 0 | AA16: =VLOOKUP($B16,$S$3:$AA$9,9,FALSE) -> 60
B17: CARIB | C17: =[23]Brewhouse!$A265 -> CA162 | D17: =[23]Brewhouse!$AF265 -> 53.8 | E17: =[23]Brewhouse!$AI265 -> 48.8 | F17: =[23]Brewhouse!$V265 -> 75 | G17: =[23]Brewhouse!$AG265 -> 11.7 | H17: 11.7 | I17: =[23]Brewhouse!$AU265 -> 95.931616 | J17: =[23]Brewhouse!$AV265 -> 95.166965 | K17: =[23]Brewhouse!$Q265 -> 5.5516014 | L17: =[23]Brewhouse!$P265 -> 61 | M17: =[23]Brewhouse!$U265-[23]Brewhouse!$T265 -> 0.12430556 | N17: =[23]Brewhouse!$Z265 -> 0.26527778 | O17: =[23]Brewhouse!$AX265 -> R.Regis | S17: =B17 -> CARIB | T17: =VLOOKUP($B17,$S$3:$Y$9,2,FALSE) -> 11.6 | U17: =VLOOKUP($B17,$S$3:$Y$9,3,FALSE) -> 12 | V17: =VLOOKUP($B17,$S$3:$Y$9,4,FALSE) -> 0 | W17: =VLOOKUP($B17,$S$3:$Y$9,5,FALSE) -> 0.11805556 | X17: =VLOOKUP($B17,$S$3:$Y$9,6,FALSE) -> 0.22569444 | Y17: =VLOOKUP($B17,$S$3:$Y$9,7,FALSE) -> 0.26388889 | Z17: =VLOOKUP($B17,$S$3:$AA$9,8,FALSE) -> 0 | AA17: =VLOOKUP($B17,$S$3:$AA$9,9,FALSE) -> 60
B18: CARIB | C18: =[23]Brewhouse!$A266 -> CA163 | D18: =[23]Brewhouse!$AF266 -> 53.3 | E18: =[23]Brewhouse!$AI266 -> 50.3 | F18: =[23]Brewhouse!$V266 -> 81 | G18: =[23]Brewhouse!$AG266 -> 12.6 | H18: 12.5 | I18: =[23]Brewhouse!$AU266 -> 106.48989 | J18: =[23]Brewhouse!$AV266 -> 105.64095 | K18: =[23]Brewhouse!$Q266 -> 6.797153 | L18: =[23]Brewhouse!$P266 -> 63 | M18: =[23]Brewhouse!$U266-[23]Brewhouse!$T266 -> 0.13611111 | N18: =[23]Brewhouse!$Z266 -> 0.28611111 | O18: =[23]Brewhouse!$AX266 -> R.Regis | S18: =B18 -> CARIB | T18: =VLOOKUP($B18,$S$3:$Y$9,2,FALSE) -> 11.6 | U18: =VLOOKUP($B18,$S$3:$Y$9,3,FALSE) -> 12 | V18: =VLOOKUP($B18,$S$3:$Y$9,4,FALSE) -> 0 | W18: =VLOOKUP($B18,$S$3:$Y$9,5,FALSE) -> 0.11805556 | X18: =VLOOKUP($B18,$S$3:$Y$9,6,FALSE) -> 0.22569444 | Y18: =VLOOKUP($B18,$S$3:$Y$9,7,FALSE) -> 0.26388889 | Z18: =VLOOKUP($B18,$S$3:$AA$9,8,FALSE) -> 0 | AA18: =VLOOKUP($B18,$S$3:$AA$9,9,FALSE) -> 60
B19: CARIB | C19: =[23]Brewhouse!$A267 -> CA164 | D19: =[23]Brewhouse!$AF267 -> 56.1 | E19: =[23]Brewhouse!$AI267 -> 52.8 | F19: =[23]Brewhouse!$V267 -> 84 | G19: =[23]Brewhouse!$AG267 -> 11.62 | H19: 11.5 | I19: =[23]Brewhouse!$AU267 -> 102.73439 | J19: =[23]Brewhouse!$AV267 -> 101.91547 | K19: =[23]Brewhouse!$Q267 -> 5.0085763 | L19: =[23]Brewhouse!$P267 -> 59 | M19: =[23]Brewhouse!$U267-[23]Brewhouse!$T267 -> 0.16111111 | N19: =[23]Brewhouse!$Z267 -> 0.59930556 | O19: =[23]Brewhouse!$AX267 -> K.Benjamin | P19: Grist conveyor monitor tripped + extra 20 mins boil to correct low gravity | S19: =B19 -> CARIB | T19: =VLOOKUP($B19,$S$3:$Y$9,2,FALSE) -> 11.6 | U19: =VLOOKUP($B19,$S$3:$Y$9,3,FALSE) -> 12 | V19: =VLOOKUP($B19,$S$3:$Y$9,4,FALSE) -> 0 | W19: =VLOOKUP($B19,$S$3:$Y$9,5,FALSE) -> 0.11805556 | X19: =VLOOKUP($B19,$S$3:$Y$9,6,FALSE) -> 0.22569444 | Y19: =VLOOKUP($B19,$S$3:$Y$9,7,FALSE) -> 0.26388889 | Z19: =VLOOKUP($B19,$S$3:$AA$9,8,FALSE) -> 0 | AA19: =VLOOKUP($B19,$S$3:$AA$9,9,FALSE) -> 60
S20: =B20 -> 0 | T20: =VLOOKUP($B20,$S$3:$Y$9,2,FALSE) -> #N/A | U20: =VLOOKUP($B20,$S$3:$Y$9,3,FALSE) -> #N/A | V20: =VLOOKUP($B20,$S$3:$Y$9,4,FALSE) -> #N/A | W20: =VLOOKUP($B20,$S$3:$Y$9,5,FALSE) -> #N/A | X20: =VLOOKUP($B20,$S$3:$Y$9,6,FALSE) -> #N/A | Y20: =VLOOKUP($B20,$S$3:$Y$9,7,FALSE) -> #N/A | Z20: =VLOOKUP($B20,$S$3:$AA$9,8,FALSE) -> #N/A | AA20: =VLOOKUP($B20,$S$3:$AA$9,9,FALSE) -> #N/A
S21: =B21 -> 0 | T21: =VLOOKUP($B21,$S$3:$Y$9,2,FALSE) -> #N/A | U21: =VLOOKUP($B21,$S$3:$Y$9,3,FALSE) -> #N/A | V21: =VLOOKUP($B21,$S$3:$Y$9,4,FALSE) -> #N/A | W21: =VLOOKUP($B21,$S$3:$Y$9,5,FALSE) -> #N/A | X21: =VLOOKUP($B21,$S$3:$Y$9,6,FALSE) -> #N/A | Y21: =VLOOKUP($B21,$S$3:$Y$9,7,FALSE) -> #N/A | Z21: =VLOOKUP($B21,$S$3:$AA$9,8,FALSE) -> #N/A | AA21: =VLOOKUP($B21,$S$3:$AA$9,9,FALSE) -> #N/A
S22: =B22 -> 0 | T22: =VLOOKUP($B22,$S$3:$Y$9,2,FALSE) -> #N/A | U22: =VLOOKUP($B22,$S$3:$Y$9,3,FALSE) -> #N/A | V22: =VLOOKUP($B22,$S$3:$Y$9,4,FALSE) -> #N/A | W22: =VLOOKUP($B22,$S$3:$Y$9,5,FALSE) -> #N/A | X22: =VLOOKUP($B22,$S$3:$Y$9,6,FALSE) -> #N/A | Y22: =VLOOKUP($B22,$S$3:$Y$9,7,FALSE) -> #N/A | Z22: =VLOOKUP($B22,$S$3:$AA$9,8,FALSE) -> #N/A | AA22: =VLOOKUP($B22,$S$3:$AA$9,9,FALSE) -> #N/A
S23: =B23 -> 0 | T23: =VLOOKUP($B23,$S$3:$Y$9,2,FALSE) -> #N/A | U23: =VLOOKUP($B23,$S$3:$Y$9,3,FALSE) -> #N/A | V23: =VLOOKUP($B23,$S$3:$Y$9,4,FALSE) -> #N/A | W23: =VLOOKUP($B23,$S$3:$Y$9,5,FALSE) -> #N/A | X23: =VLOOKUP($B23,$S$3:$Y$9,6,FALSE) -> #N/A | Y23: =VLOOKUP($B23,$S$3:$Y$9,7,FALSE) -> #N/A | Z23: =VLOOKUP($B23,$S$3:$AA$9,8,FALSE) -> #N/A | AA23: =VLOOKUP($B23,$S$3:$AA$9,9,FALSE) -> #N/A
I24: EXTRACT RECOVERY
B25: BRAND | D25: BBT P.G./ O.G | I25: Brand | J25: Actual | K25: MTD No. of Brews | L25: MTD | M25: YTD | N25: Target
B26: GUINNESS | C26: {=[25]Process!$D$29:$D$30} -> 17.6 | D26: 17.65 | I26: CARIB | J26: =AVERAGE(I14:I19) -> 102.57853 | K26: =COUNTA([23]Brewhouse!$A$255:$A$267) -> 13 | L26: =AVERAGE([23]Brewhouse!$AU$255:$AU$267) -> 100.9328 | M26: =AVERAGE([23]Brewhouse!$AU$102:$AU$171,[23]Brewhouse!$AU$173:$AU$253,[23]Brewhouse!$AU$255:$AU$267) -> 96.02922 | N26: 98
C27: 17.5 | I27: STAG | J27: =AVERAGE(I10:I12) -> 96.060819 | K27: =COUNTA([24]Brewhouse!$A$105:$A$108) -> 4 | L27: =AVERAGE([24]Brewhouse!$AS$105:$AS$108) -> 96.250115 | M27: =AVERAGE([24]Brewhouse!$AS$15:$AS$64,[24]Brewhouse!$AS$66:$AS$103,[24]Brewhouse!$AS$105:$AS$108) -> 95.903646 | N27: 98
C28: {=[25]Process!$D$33:$D$34} -> 17.4 | D28: 17.52 | I28: GUINNESS | M28: =AVERAGE([25]Brewhouse!$AU$4:$AU$7,[25]Brewhouse!$AU$9:$AU$22) -> 96.218977 | N28: 98
C29: 17.4 | I29: VITAMALT | M29: =AVERAGE([26]Brewhouse!$AV$5:$AV$14,[26]Brewhouse!$AV$16:$AV$19) -> 98.230958 | N29: 98
I30: MAXIMALT | N30: 98
I31: MACKESON | M31: =AVERAGE([27]Brewhouse!$AT$4:$AT$11) -> 94.812617 | N31: 98
I32: STARMALT | K32: =COUNTA([22]Brewhouse!$A$22:$A$29) -> 8 | L32: =AVERAGE([22]Brewhouse!$AY$22:$AY$29) -> 98.065834 | M32: =AVERAGE([22]Brewhouse!$AY$6:$AY$13,[22]Brewhouse!$AY$15:$AY$20,[22]Brewhouse!$AY$22:$AY$29) -> 95.660462 | N32: 98
I33: HR- Pils | M33: =AVERAGE([28]Brewhouse!$AU$5:$AU$8) -> 91.006888 | N33: 98
I34: HR- IPA
I35: HR- APA | N35: 98
K36: =SUM(K26:K35) -> 25 | L36: =((L26*K26)+(L27*K27)+(L28*K28)+(L29*K29)+(L30*K30)+(K33*L33)+(L31*K31)+(L32*K32)+(L35*K35))/(K36) -> 99.266142 | M36: =AVERAGE('[29]Jan 31st'!$L$65,'[30]Feb 28th'!$L$35,L36) -> 96.90304 | N36: 98
B38: STARMALT | C38: {=[22]Process!$D$21:$D$24} -> 17.1 | D38: 17.17 | J38: Daily Brewing Plan
C39: 17.8 | J39: Brand | K39: Brews Achieved | L39: Average Brews per day
C40: 17.2 | D40: 17.05 | J40: CARIB | K40: =COUNTA(B14:B19) -> 6 | L40: MTD | M40: YTD | N40: TARGET
C41: 17.7 | J41: STAG | K41: =COUNTA(B10:B12) -> 3 | L41: =AVERAGE('Mar. 3rd'!K80,'Mar. 4th'!K81,K50) -> 8.3333333 | M41: =AVERAGE('[29]Jan 29th '!$M$70,'[30]Feb 28th'!$L$40,L41) -> 7.2814408
J42: GUINN
...

Sheet Mar. 6th
T1: P.G. | V1: Hot Time | X1: Process Time | Z1: Cooling Time
B2: Brewing Department Daily Process Loss Report | T2: Lower | U2: Upper | V2: Lower | W2: Upper | X2: Lower | Y2: Upper | Z2: Lower | AA2: Upper
S3: CARIB | T3: 11.6 | U3: 12 | V3: 0 | W3: 0.11805556 | X3: 0.22569444 | Y3: 0.26388889 | Z3: 0 | AA3: 60 | AC3: HR- PISNER
B4: Date: | J4: LOT WORT COLOUR: 3/3.6 | M4: Filter Sheets (Target 20 days) | S4: STAG | T4: 11.6 | U4: 12 | V4: 0 | W4: 0.11805556 | X4: 0.22569444 | Y4: 0.26388889 | Z4: 0 | AA4: 60
C5: 45723 | M5: Double | N5: Single | S5: GUINNESS | T5: 17 | U5: 17.5 | V5: 0 | W5: 0.10763889 | X5: 0.24652778 | Y5: 0.28472222 | Z5: 0 | AA5: 60
J6: MALT LOT: Lot 18/32 | L6: Sheet Day | M6: 17 | N6: 13 | S6: MACKESON | T6: 13.3 | U6: 13.5 | V6: 0 | W6: 0.12905093 | X6: 0.27430556 | Y6: 0.30208333 | Z6: 0
S7: STARMALT | T7: 17.1 | U7: 17.5 | V7: 0 | W7: 0.13605324 | X7: 0.27430556 | Y7: 0.30902778 | Z7: 0 | AA7: 60
B8: Brand | C8: Brew no. | D8: Kett. Hls | E8: Wort | F8: Cool Time(Mins) | G8: Cast. P.G. (Lab Result) | H8: Cast P.G. (Cellar Operator)-gravity | I8: Extr. Rec (80.9%) | J8: Theor. Extr. (77.5%) | K8: Boil Off /Vol. (4-6%) | L8: Boil Time | M8: Total Hot | N8: Brewing | O8: Operator | P8: Comments | Q8: Actual Pilsen Malt | S8: Hurricane Reef | T8: 16.6 | U8: 17 | V8: 0 | W8: 0.12905093 | X8: 0.27430556 | Y8: 0.30208333 | Z8: 0
E9: Meter (Hls) | F9: Target(< 60Mins) | M9: Time | S9: VITAMALT | T9: 14.4 | U9: 14.6 | V9: 0 | W9: 0.13905093 | X9: 0.26041667 | Y9: 0.29513889 | Z9: 0 | AA9: 75
B10: CARIB | C10: =[23]Brewhouse!$A268 -> CA165 | D10: =[23]Brewhouse!$AF268 -> 52.3 | E10: =[23]Brewhouse!$AI268 -> 49.2 | F10: =[23]Brewhouse!$V268 -> 78 | G10: =[23]Brewhouse!$AG268 -> 12.3 | H10: 12.4 | I10: =[23]Brewhouse!$AU268 -> 101.93739 | J10: =[23]Brewhouse!$AV268 -> 101.12487 | K10: =[23]Brewhouse!$Q268 -> 3.0451128 | L10: =[23]Brewhouse!$P268 -> 63 | M10: =[23]Brewhouse!$U268-[23]Brewhouse!$T268 -> 0.13472222 | N10: =[23]Brewhouse!$Z268 -> 0.30486111 | O10: =[23]Brewhouse!$AX268 -> K.Benjamin | P10: Brew kettle up in pre-run tank due to delays on previous brew | S10: =B10 -> CARIB | T10: =VLOOKUP($B10,$S$3:$Y$9,2,FALSE) -> 11.6 | U10: =VLOOKUP($B10,$S$3:$Y$9,3,FALSE) -> 12 | V10: =VLOOKUP($B10,$S$3:$Y$9,4,FALSE) -> 0 | W10: =VLOOKUP($B10,$S$3:$Y$9,5,FALSE) -> 0.11805556 | X10: =VLOOKUP($B10,$S$3:$Y$9,6,FALSE) -> 0.22569444 | Y10: =VLOOKUP($B10,$S$3:$Y$9,7,FALSE) -> 0.26388889 | Z10: =VLOOKUP($B10,$S$3:$AA$9,8,FALSE) -> 0 | AA10: =VLOOKUP($B10,$S$3:$AA$9,9,FALSE) -> 60
B11: CARIB | C11: =[23]Brewhouse!$A269 -> CA166 | D11: =[23]Brewhouse!$AF269 -> 54.8 | E11: =[23]Brewhouse!$AI269 -> 51.7 | F11: =[23]Brewhouse!$V269 -> 98 | G11: =[23]Brewhouse!$AG269 -> 11.93 | H11: 11.9 | I11: =[23]Brewhouse!$AU269 -> 94.916088 | J11: =[23]Brewhouse!$AV269 -> 94.159449 | K11: =[23]Brewhouse!$Q269 -> 2.7338129 | L11: =[23]Brewhouse!$P269 -> 58 | M11: =[23]Brewhouse!$U269-[23]Brewhouse!$T269 -> 0.13263889 | N11: =[23]Brewhouse!$Z269 -> 0.28958333 | O11: =[23]Brewhouse!$AX269 -> K.Benjamin | P11: Slow cooling (high temp) | S11: =B11 -> CARIB | T11: =VLOOKUP($B11,$S$3:$Y$9,2,FALSE) -> 11.6 | U11: =VLOOKUP($B11,$S$3:$Y$9,3,FALSE) -> 12 | V11: =VLOOKUP($B11,$S$3:$Y$9,4,FALSE) -> 0 | W11: =VLOOKUP($B11,$S$3:$Y$9,5,FALSE) -> 0.11805556 | X11: =VLOOKUP($B11,$S$3:$Y$9,6,FALSE) -> 0.22569444 | Y11: =VLOOKUP($B11,$S$3:$Y$9,7,FALSE) -> 0.26388889 | Z11: =VLOOKUP($B11,$S$3:$AA$9,8,FALSE) -> 0 | AA11: =VLOOKUP($B11,$S$3:$AA$9,9,FALSE) -> 60
