Workbook
Name ProductList: [1]November15!$R$3:$R$9
Name ProductList: [2]November15!$R$3:$R$9

Sheet Dec 18th
T1: P.G. | V1: Hot Time | X1: Process Time | Z1: Cooling Time
B2: Brewing Department Daily Process Loss Report | T2: Lower | U2: Upper | V2: Lower | W2: Upper | X2: Lower | Y2: Upper | Z2: Lower | AA2: Upper
S3: CARIB | T3: 11.6 | U3: 12 | V3: 0 | W3: 0.11805556 | X3: 0.17361111 | Y3: 0.21180556 | Z3: 0 | AA3: 60 | AC3: HR- PISNER
B4: Date: | C4: 45278 | J4: LOT WORT COLOUR: 3.4 | M4: Filter Sheets (Target 20 days) | S4: STAG | T4: 11.6 | U4: 12 | V4: 0 | W4: 0.11805556 | X4: 0.17361111 | Y4: 0.21180556 | Z4: 0 | AA4: 60
M5: Double | N5: Single | S5: GUINNESS | T5: 17 | U5: 17.5 | V5: 0 | W5: 0.10763889 | X5: 0.19444444 | Y5: 0.23263889 | Z5: 0 | AA5: 60
J6: MALT LOT: Lot 8 | L6: Sheet Day | S6: MACKESON | T6: 13.3 | U6: 13.5 | V6: 0 | W6: 0.12905093 | X6: 0.22222222 | Y6: 0.25347222 | Z6: 0
S7: STARMALT | T7: 17.1 | U7: 17.5 | V7: 0 | W7: 0.13605324 | X7: 0.20833333 | Y7: 0.24305556 | Z7: 0 | AA7: 60
B8: Brand | C8: Brew no. | D8: Kett. Hls | E8: Wort | F8: Cool Time(Mins) | G8: Cast. P.G. (Lab Result) | H8: Cast P.G. (Cellar Operator)-gravity | I8: Extr. Rec (79.1%) | J8: Theor. Extr. (77.5%) | K8: Boil Off /Vol. (4-6%) | L8: Boil Time | M8: Total Hot | N8: Brewing | P8: Comments | Q8: Actual Pilsen Malt | S8: Hurricane Reef | T8: 16.6 | U8: 17 | V8: 0 | W8: 0.12905093 | X8: 0.22222222 | Y8: 0.25347222 | Z8: 0
E9: Meter (Hls) | F9: Target(< 60Mins) | M9: Time | S9: VITAMALT | T9: 14.4 | U9: 14.6 | V9: 0 | W9: 0.13905093 | X9: 0.19097222 | Y9: 0.22569444 | Z9: 0 | AA9: 75
S10: =B10 -> 0 | T10: =VLOOKUP($B10,$S$3:$Y$9,2,FALSE) -> #N/A | U10: =VLOOKUP($B10,$S$3:$Y$9,3,FALSE) -> #N/A | V10: =VLOOKUP($B10,$S$3:$Y$9,4,FALSE) -> #N/A | W10: =VLOOKUP($B10,$S$3:$Y$9,5,FALSE) -> #N/A | X10: =VLOOKUP($B10,$S$3:$Y$9,6,FALSE) -> #N/A | Y10: =VLOOKUP($B10,$S$3:$Y$9,7,FALSE) -> #N/A | Z10: =VLOOKUP($B10,$S$3:$AA$9,8,FALSE) -> #N/A | AA10: =VLOOKUP($B10,$S$3:$AA$9,9,FALSE) -> #N/A
S11: =B11 -> 0 | T11: =VLOOKUP($B11,$S$3:$Y$9,2,FALSE) -> #N/A | U11: =VLOOKUP($B11,$S$3:$Y$9,3,FALSE) -> #N/A | V11: =VLOOKUP($B11,$S$3:$Y$9,4,FALSE) -> #N/A | W11: =VLOOKUP($B11,$S$3:$Y$9,5,FALSE) -> #N/A | X11: =VLOOKUP($B11,$S$3:$Y$9,6,FALSE) -> #N/A | Y11: =VLOOKUP($B11,$S$3:$Y$9,7,FALSE) -> #N/A | Z11: =VLOOKUP($B11,$S$3:$AA$9,8,FALSE) -> #N/A | AA11: =VLOOKUP($B11,$S$3:$AA$9,9,FALSE) -> #N/A
S12: =B12 -> 0 | T12: =VLOOKUP($B12,$S$3:$Y$9,2,FALSE) -> #N/A | U12: =VLOOKUP($B12,$S$3:$Y$9,3,FALSE) -> #N/A | V12: =VLOOKUP($B12,$S$3:$Y$9,4,FALSE) -> #N/A | W12: =VLOOKUP($B12,$S$3:$Y$9,5,FALSE) -> #N/A | X12: =VLOOKUP($B12,$S$3:$Y$9,6,FALSE) -> #N/A | Y12: =VLOOKUP($B12,$S$3:$Y$9,7,FALSE) -> #N/A | Z12: =VLOOKUP($B12,$S$3:$AA$9,8,FALSE) -> #N/A | AA12: =VLOOKUP($B12,$S$3:$AA$9,9,FALSE) -> #N/A
S13: =B13 -> 0 | T13: =VLOOKUP($B13,$S$3:$Y$9,2,FALSE) -> #N/A | U13: =VLOOKUP($B13,$S$3:$Y$9,3,FALSE) -> #N/A | V13: =VLOOKUP($B13,$S$3:$Y$9,4,FALSE) -> #N/A | W13: =VLOOKUP($B13,$S$3:$Y$9,5,FALSE) -> #N/A | X13: =VLOOKUP($B13,$S$3:$Y$9,6,FALSE) -> #N/A | Y13: =VLOOKUP($B13,$S$3:$Y$9,7,FALSE) -> #N/A | Z13: =VLOOKUP($B13,$S$3:$AA$9,8,FALSE) -> #N/A | AA13: =VLOOKUP($B13,$S$3:$AA$9,9,FALSE) -> #N/A
S14: =B14 -> 0 | T14: =VLOOKUP($B14,$S$3:$Y$9,2,FALSE) -> #N/A | U14: =VLOOKUP($B14,$S$3:$Y$9,3,FALSE) -> #N/A | V14: =VLOOKUP($B14,$S$3:$Y$9,4,FALSE) -> #N/A | W14: =VLOOKUP($B14,$S$3:$Y$9,5,FALSE) -> #N/A | X14: =VLOOKUP($B14,$S$3:$Y$9,6,FALSE) -> #N/A | Y14: =VLOOKUP($B14,$S$3:$Y$9,7,FALSE) -> #N/A | Z14: =VLOOKUP($B14,$S$3:$AA$9,8,FALSE) -> #N/A | AA14: =VLOOKUP($B14,$S$3:$AA$9,9,FALSE) -> #N/A
S15: =B15 -> 0 | T15: =VLOOKUP($B15,$S$3:$Y$9,2,FALSE) -> #N/A | U15: =VLOOKUP($B15,$S$3:$Y$9,3,FALSE) -> #N/A | V15: =VLOOKUP($B15,$S$3:$Y$9,4,FALSE) -> #N/A | W15: =VLOOKUP($B15,$S$3:$Y$9,5,FALSE) -> #N/A | X15: =VLOOKUP($B15,$S$3:$Y$9,6,FALSE) -> #N/A | Y15: =VLOOKUP($B15,$S$3:$Y$9,7,FALSE) -> #N/A | Z15: =VLOOKUP($B15,$S$3:$AA$9,8,FALSE) -> #N/A | AA15: =VLOOKUP($B15,$S$3:$AA$9,9,FALSE) -> #N/A
S16: =B16 -> 0 | T16: =VLOOKUP($B16,$S$3:$Y$9,2,FALSE) -> #N/A | U16: =VLOOKUP($B16,$S$3:$Y$9,3,FALSE) -> #N/A | V16: =VLOOKUP($B16,$S$3:$Y$9,4,FALSE) -> #N/A | W16: =VLOOKUP($B16,$S$3:$Y$9,5,FALSE) -> #N/A | X16: =VLOOKUP($B16,$S$3:$Y$9,6,FALSE) -> #N/A | Y16: =VLOOKUP($B16,$S$3:$Y$9,7,FALSE) -> #N/A | Z16: =VLOOKUP($B16,$S$3:$AA$9,8,FALSE) -> #N/A | AA16: =VLOOKUP($B16,$S$3:$AA$9,9,FALSE) -> #N/A
S17: =B17 -> 0 | T17: =VLOOKUP($B17,$S$3:$Y$9,2,FALSE) -> #N/A | U17: =VLOOKUP($B17,$S$3:$Y$9,3,FALSE) -> #N/A | V17: =VLOOKUP($B17,$S$3:$Y$9,4,FALSE) -> #N/A | W17: =VLOOKUP($B17,$S$3:$Y$9,5,FALSE) -> #N/A | X17: =VLOOKUP($B17,$S$3:$Y$9,6,FALSE) -> #N/A | Y17: =VLOOKUP($B17,$S$3:$Y$9,7,FALSE) -> #N/A | Z17: =VLOOKUP($B17,$S$3:$AA$9,8,FALSE) -> #N/A | AA17: =VLOOKUP($B17,$S$3:$AA$9,9,FALSE) -> #N/A
S18: =B18 -> 0 | T18: =VLOOKUP($B18,$S$3:$Y$9,2,FALSE) -> #N/A | U18: =VLOOKUP($B18,$S$3:$Y$9,3,FALSE) -> #N/A | V18: =VLOOKUP($B18,$S$3:$Y$9,4,FALSE) -> #N/A | W18: =VLOOKUP($B18,$S$3:$Y$9,5,FALSE) -> #N/A | X18: =VLOOKUP($B18,$S$3:$Y$9,6,FALSE) -> #N/A | Y18: =VLOOKUP($B18,$S$3:$Y$9,7,FALSE) -> #N/A | Z18: =VLOOKUP($B18,$S$3:$AA$9,8,FALSE) -> #N/A | AA18: =VLOOKUP($B18,$S$3:$AA$9,9,FALSE) -> #N/A
S19: =B19 -> 0 | T19: =VLOOKUP($B19,$S$3:$Y$9,2,FALSE) -> #N/A | U19: =VLOOKUP($B19,$S$3:$Y$9,3,FALSE) -> #N/A | V19: =VLOOKUP($B19,$S$3:$Y$9,4,FALSE) -> #N/A | W19: =VLOOKUP($B19,$S$3:$Y$9,5,FALSE) -> #N/A | X19: =VLOOKUP($B19,$S$3:$Y$9,6,FALSE) -> #N/A | Y19: =VLOOKUP($B19,$S$3:$Y$9,7,FALSE) -> #N/A | Z19: =VLOOKUP($B19,$S$3:$AA$9,8,FALSE) -> #N/A | AA19: =VLOOKUP($B19,$S$3:$AA$9,9,FALSE) -> #N/A
S20: =B20 -> 0 | T20: =VLOOKUP($B20,$S$3:$Y$9,2,FALSE) -> #N/A | U20: =VLOOKUP($B20,$S$3:$Y$9,3,FALSE) -> #N/A | V20: =VLOOKUP($B20,$S$3:$Y$9,4,FALSE) -> #N/A | W20: =VLOOKUP($B20,$S$3:$Y$9,5,FALSE) -> #N/A | X20: =VLOOKUP($B20,$S$3:$Y$9,6,FALSE) -> #N/A | Y20: =VLOOKUP($B20,$S$3:$Y$9,7,FALSE) -> #N/A | Z20: =VLOOKUP($B20,$S$3:$AA$9,8,FALSE) -> #N/A | AA20: =VLOOKUP($B20,$S$3:$AA$9,9,FALSE) -> #N/A
S21: =B21 -> 0 | T21: =VLOOKUP($B21,$S$3:$Y$9,2,FALSE) -> #N/A | U21: =VLOOKUP($B21,$S$3:$Y$9,3,FALSE) -> #N/A | V21: =VLOOKUP($B21,$S$3:$Y$9,4,FALSE) -> #N/A | W21: =VLOOKUP($B21,$S$3:$Y$9,5,FALSE) -> #N/A | X21: =VLOOKUP($B21,$S$3:$Y$9,6,FALSE) -> #N/A | Y21: =VLOOKUP($B21,$S$3:$Y$9,7,FALSE) -> #N/A | Z21: =VLOOKUP($B21,$S$3:$AA$9,8,FALSE) -> #N/A | AA21: =VLOOKUP($B21,$S$3:$AA$9,9,FALSE) -> #N/A
... S47: =B47 -> 0 | T47: =VLOOKUP($B47,$S$3:$Y$9,2,FALSE) -> #N/A | U47: =VLOOKUP($B47,$S$3:$Y$9,3,FALSE) -> #N/A | V47: =VLOOKUP($B47,$S$3:$Y$9,4,FALSE) -> #N/A | W47: =VLOOKUP($B47,$S$3:$Y$9,5,FALSE) -> #N/A | X47: =VLOOKUP($B47,$S$3:$Y$9,6,FALSE) -> #N/A | Y47: =VLOOKUP($B47,$S$3:$Y$9,7,FALSE) -> #N/A | Z47: =VLOOKUP($B47,$S$3:$AA$9,8,FALSE) -> #N/A | AA47: =VLOOKUP($B47,$S$3:$AA$9,9,FALSE) -> #N/A
I48: EXTRACT RECOVERY
B49: BRAND | D49: BBT P.G./ O.G | I49: Brand | J49: Actual | K49: MTD No. of Brews | L49: MTD | M49: YTD | N49: Target
B50: STAG | C50: 11.8 | D50: 11.73 | I50: CARIB | K50: =COUNTA([16]Brewhouse!$A$1596:$A$1619) -> 24 | L50: =AVERAGE([16]Brewhouse!$AU$1529,[16]Brewhouse!$AU$1531:$AU$1594,[16]Brewhouse!$AU$1596:$AU$1619) -> 98.205761 | M50: =AVERAGE([16]Brewhouse!$AU$849:$AU$924,[16]Brewhouse!$AU$926:$AU$971,[16]Brewhouse!$AU$973:$AU$1066,[16]Brewhouse!$AU$1068:$AU$1111,[16]Brewhouse!$AU$1113:$AU$1132,[16]Brewhouse!$AU$1134:$AU$1167,[16]Brewhouse!$AU$1169:$AU$1230,[16]Brewhouse!$AU$1232:$AU$1299,[16]Brewhouse!$AU$1301:$AU$1363,[16]Brewhouse!$AU$1365:$AU$1444,[16]Brewhouse!$AU$1446:$AU$1527,[16]Brewhouse!$AU$1529,[16]Brewhouse!$AU$1531:$AU$1594,[16]Brewhouse!$AU$1596:$AU$1619) -> 98.381806 | N50: 98
C51: 11.9 | I51: STAG | K51: =COUNTA([17]Brewhouse!$A$976:$A$1007) -> 32 | L51: =AVERAGE([17]Brewhouse!$AS$976:$AS$979,[17]Brewhouse!$AS$981:$AS$1007) -> 98.538567 | M51: =AVERAGE([17]Brewhouse!$AS$577:$AS$618,[17]Brewhouse!$AS$620:$AS$651,[17]Brewhouse!$AS$653:$AS$696,[17]Brewhouse!$AS$698:$AS$708,[17]Brewhouse!$AS$710:$AS$733,[17]Brewhouse!$AS$735:$AS$777,[17]Brewhouse!$AS$779:$AS$822,[17]Brewhouse!$AS$824:$AS$863,[17]Brewhouse!$AS$865:$AS$974,[17]Brewhouse!$AS$976:$AS$979,[17]Brewhouse!$AS$981:$AS$1007) -> 98.489671 | N51: 98
I52: GUINNESS | K52: =COUNTA([18]Brewhouse!$A$282:$A$289) -> 8 | L52: =AVERAGE([18]Brewhouse!$AU$269:$AU$279,[18]Brewhouse!$AU$282:$AU$289) -> 96.186177 | M52: =AVERAGE([18]Brewhouse!$AU$161:$AU$176,[18]Brewhouse!$AU$178:$AU$195,[18]Brewhouse!$AU$197:$AU$208,[18]Brewhouse!$AU$210:$AU$221,[18]Brewhouse!$AU$223:$AU$232,[18]Brewhouse!$AU$234:$AU$279,[18]Brewhouse!$AU$282:$AU$289) -> 96.64916 | N52: 98
I53: VITAMALT | K53: =COUNTA([19]Brewhouse!$A$158:$A$163) -> 6 | L53: =AVERAGE([19]Brewhouse!$AU$158:$AU$163) -> 94.60305 | M53: =AVERAGE([19]Brewhouse!$AU$91:$AU$101,[19]Brewhouse!$AU$103:$AU$112,[19]Brewhouse!$AU$114:$AU$123,[19]Brewhouse!$AU$125:$AU$134,[19]Brewhouse!$AU$136:$AU$145,[19]Brewhouse!$AU$147:$AU$156,[19]Brewhouse!$AU$158:$AU$163) -> 96.240014 | N53: 98
I54: MAXIMALT | N54: 98
I55: MACKESON | M55: =AVERAGE([20]Brewhouse!$AT$74:$AT$79) -> 93.959836 | N55: 98
I56: STARMALT | K56: =COUNTA([21]Brewhouse!$A$249:$A$254) -> 6 | L56: =AVERAGE([21]Brewhouse!$AY$249:$AY$254) -> 99.681996 | M56: =AVERAGE([21]Brewhouse!$AY$138:$AY$143,[21]Brewhouse!$AY$145:$AY$153,[21]Brewhouse!$AY$155,[21]Brewhouse!$AY$156:$AY$174,[21]Brewhouse!$AY$176:$AY$185,[21]Brewhouse!$AY$187:$AY$198,[21]Brewhouse!$AY$200:$AY$247,[21]Brewhouse!$AY$249:$AY$254) -> 98.774703 | N56: 98
I57: HR- P | M57: =AVERAGE([22]Brewhouse!$AW$13:$AW$14,[22]Brewhouse!$AW$16:$AW$17) -> 92.042628 | N57: 98
I58: Hurricane Reef | M58: =AVERAGE([22]Brewhouse!$AW$13:$AW$14) -> 88.376943 | N58: 98
K59: =SUM(K50:K58) -> 76 | L59: =((L50*K50)+(L51*K51)+(L52*K52)+(L53*K53)+(L54*K54)+(K57*L57)+(L55*K55)+(L56*K56)+(L58*K58))/(K59) -> 97.965422 | M59: =AVERAGE('[23]Closing- January 2023'!$L$42,'[24]Feb. 28th'!$L$42,'[25]March 31st'!$L$75,'[26]Apri 28th'!$L$51,L59) -> 98.06926 | N59: 98
J62: Daily Brewing Plan
J63: Brand | K63: Brews Achieved | L63: Average Brews per day
J64: CARIB | L64: MTD | M64: YTD | N64: TARGET
J65: STAG | K65: 5 | L65: =AVERAGE(#REF!,#REF!,K74,#REF!,#REF!,#REF!,#REF!,#REF!,#REF!,#REF!,#REF!) -> #REF! | M65: =AVERAGE(6,6,'[25]March 31st'!$L$80,'[27]June 30th '!$L$71,6,L65,'[28]July 31st'!$L$108,'[29]Aug 30th'!$L$124,7,[30]Oct.31st!$L$51) -> #REF! | N65: 9
J66: GUINN
J67: VITAMALT
...

Sheet Mar 1st
S1: P.G. | U1: Hot Time | W1: Process Time | Y1: Cooling Time
B2: Brewing Department Daily Process Loss Report | S2: Lower | T2: Upper | U2: Lower | V2: Upper | W2: Lower | X2: Upper | Y2: Lower | Z2: Upper
R3: CARIB | S3: 11.6 | T3: 12 | U3: 0 | V3: 0.11805556 | W3: 0.22569444 | X3: 0.26388889 | Y3: 0 | Z3: 60 | AB3: HR- PISNER
B4: Date: | C4: 46080 | J4: LOT WORT COLOUR: | M4: Filter Sheets (Target 20 days) | R4: STAG | S4: 11.6 | T4: 12 | U4: 0 | V4: 0.11805556 | W4: 0.22569444 | X4: 0.26388889 | Y4: 0 | Z4: 60
M5: Double | N5: Single | R5: GUINNESS | S5: 17 | T5: 17.5 | U5: 0 | V5: 0.10763889 | W5: 0.24652778 | X5: 0.28472222 | Y5: 0 | Z5: 60
J6: MALT LOT: Lot #13 | L6: Sheet Day | R6: MACKESON | S6: 13.3 | T6: 13.5 | U6: 0 | V6: 0.12905093 | W6: 0.27430556 | X6: 0.30208333 | Y6: 0
R7: STARMALT | S7: 17 | T7: 17.4 | U7: 0 | V7: 0.13605324 | W7: 0.27430556 | X7: 0.30902778 | Y7: 0 | Z7: 85
B8: Brand | C8: Brew no. | D8: Kett. Hls | E8: Wort | F8: Cool Time(Mins) | G8: Cast. P.G. (Lab Result) | H8: Cast P.G. (Cellar Operator)-gravity | I8: Extr. Rec (77.9%) | J8: Theor. Extr. (77.5%) | K8: Boil Off /Vol. (4-6%) | L8: Boil Time | M8: Total Hot | N8: Brewing Time | O8: Operator | R8: Hurricane Reef | S8: 16.6 | T8: 17 | U8: 0 | V8: 0.12905093 | W8: 0.27430556 | X8: 0.30208333 | Y8: 0
E9: Meter (Hls) | F9: Target(< 60Mins) | M9: Time | R9: VITAMALT | S9: 14.2 | T9: 14.6 | U9: 0 | V9: 0.13905093 | W9: 0.26041667 | X9: 0.29513889 | Y9: 0 | Z9: 75
B10: VITAMALT | C10: =[6]Brewhouse!A38 -> VM014 | D10: =[6]Brewhouse!AE38 -> 50 | E10: =[6]Brewhouse!AJ38 -> 44.2 | F10: =[6]Brewhouse!X38 -> 79 | G10: =[6]Brewhouse!AH38 -> 15.5 | H10: 15.4 | I10: =[6]Brewhouse!AV38 -> 96.780048 | J10: =[6]Brewhouse!AW38 -> 97.096495 | K10: =[6]Brewhouse!S38 -> 15.52 | L10: =[6]Brewhouse!R38 -> 61 | M10: =[6]Brewhouse!$W38-[6]Brewhouse!$V38 -> 0.13680556 | N10: =[6]Brewhouse!AB38 -> 0.31041667 | O10: =[6]Brewhouse!$AZ38 -> D. Gomaz | R10: =B10 -> VITAMALT | S10: =VLOOKUP($B10,$R$3:$X$9,2,FALSE) -> 14.2 | T10: =VLOOKUP($B10,$R$3:$X$9,3,FALSE) -> 14.6 | U10: =VLOOKUP($B10,$R$3:$X$9,4,FALSE) -> 0 | V10: =VLOOKUP($B10,$R$3:$X$9,5,FALSE) -> 0.13905093 | W10: =VLOOKUP($B10,$R$3:$X$9,6,FALSE) -> 0.26041667 | X10: =VLOOKUP($B10,$R$3:$X$9,7,FALSE) -> 0.29513889 | Y10: =VLOOKUP($B10,$R$3:$Z$9,8,FALSE) -> 0 | Z10: =VLOOKUP($B10,$R$3:$Z$9,9,FALSE) -> 75
B11: VITAMALT | C11: =[6]Brewhouse!A39 -> VM015 | D11: =[6]Brewhouse!AE39 -> 50 | E11: =[6]Brewhouse!AJ39 -> 47.1 | F11: =[6]Brewhouse!X39 -> 85 | G11: =[6]Brewhouse!AH39 -> 14.5 | H11: 14.4 | I11: =[6]Brewhouse!AV39 -> 97.023342 | J11: =[6]Brewhouse!AW39 -> 97.329084 | K11: =[6]Brewhouse!S39 -> 13.72 | L11: =[6]Brewhouse!R39 -> 62 | M11: =[6]Brewhouse!$W39-[6]Brewhouse!$V39 -> 0.13888889 | N11: =[6]Brewhouse!AB39 -> 0.31388889 | O11: =[6]Brewhouse!$AZ39 -> D. Gomaz | R11: =B11 -> VITAMALT | S11: =VLOOKUP($B11,$R$3:$X$9,2,FALSE) -> 14.2 | T11: =VLOOKUP($B11,$R$3:$X$9,3,FALSE) -> 14.6 | U11: =VLOOKUP($B11,$R$3:$X$9,4,FALSE) -> 0 | V11: =VLOOKUP($B11,$R$3:$X$9,5,FALSE) -> 0.13905093 | W11: =VLOOKUP($B11,$R$3:$X$9,6,FALSE) -> 0.26041667 | X11: =VLOOKUP($B11,$R$3:$X$9,7,FALSE) -> 0.29513889 | Y11: =VLOOKUP($B11,$R$3:$Z$9,8,FALSE) -> 0 | Z11: =VLOOKUP($B11,$R$3:$Z$9,9,FALSE) -> 75
B12: VITAMALT | C12: =[6]Brewhouse!A40 -> VM016 | D12: =[6]Brewhouse!AE40 -> 50.1 | E12: =[6]Brewhouse!AJ40 -> 47.6 | F12: =[6]Brewhouse!X40 -> 85 | G12: =[6]Brewhouse!AH40 -> 14.3 | H12: 14.4 | I12: =[6]Brewhouse!AV40 -> 96.378271 | J12: =[6]Brewhouse!AW40 -> 96.684538 | K12: =[6]Brewhouse!S40 -> 9.500998 | L12: =[6]Brewhouse!R40 -> 62 | M12: =[6]Brewhouse!$W40-[6]Brewhouse!$V40 -> 0.13819444 | N12: =[6]Brewhouse!AB40 -> 0.30138889 | O12: =[6]Brewhouse!$AZ40 -> D. Gomaz | R12: =B12 -> VITAMALT | S12: =VLOOKUP($B12,$R$3:$X$9,2,FALSE) -> 14.2 | T12: =VLOOKUP($B12,$R$3:$X$9,3,FALSE) -> 14.6 | U12: =VLOOKUP($B12,$R$3:$X$9,4,FALSE) -> 0 | V12: =VLOOKUP($B12,$R$3:$X$9,5,FALSE) -> 0.13905093 | W12: =VLOOKUP($B12,$R$3:$X$9,6,FALSE) -> 0.26041667 | X12: =VLOOKUP($B12,$R$3:$X$9,7,FALSE) -> 0.29513889 | Y12: =VLOOKUP($B12,$R$3:$Z$9,8,FALSE) -> 0 | Z12: =VLOOKUP($B12,$R$3:$Z$9,9,FALSE) -> 75
B13: VITAMALT | C13: =[6]Brewhouse!A41 -> VM017 | D13: =[6]Brewhouse!AE41 -> 52 | E13: =[6]Brewhouse!AJ41 -> 47.4 | F13: =[6]Brewhouse!X41 -> 85 | G13: =[6]Brewhouse!AH41 -> 14.4 | H13: 14.3 | I13: =[6]Brewhouse!AV41 -> 96.736023 | J13: =[6]Brewhouse!AW41 -> 97.043426 | K13: =[6]Brewhouse!S41 -> 11.269231 | L13: =[6]Brewhouse!R41 -> 61 | M13: =[6]Brewhouse!$W41-[6]Brewhouse!$V41 -> 0.1375 | N13: =[6]Brewhouse!AB41 -> 0.30277778 | O13: =[6]Brewhouse!$AZ41 -> D. Gomaz | R13: =B13 -> VITAMALT | S13: =VLOOKUP($B13,$R$3:$X$9,2,FALSE) -> 14.2 | T13: =VLOOKUP($B13,$R$3:$X$9,3,FALSE) -> 14.6 | U13: =VLOOKUP($B13,$R$3:$X$9,4,FALSE) -> 0 | V13: =VLOOKUP($B13,$R$3:$X$9,5,FALSE) -> 0.13905093 | W13: =VLOOKUP($B13,$R$3:$X$9,6,FALSE) -> 0.26041667 | X13: =VLOOKUP($B13,$R$3:$X$9,7,FALSE) -> 0.29513889 | Y13: =VLOOKUP($B13,$R$3:$Z$9,8,FALSE) -> 0 | Z13: =VLOOKUP($B13,$R$3:$Z$9,9,FALSE) -> 75
B14: VITAMALT | C14: =[6]Brewhouse!A42 -> VM018 | D14: =[6]Brewhouse!AE42 -> 53.1 | E14: =[6]Brewhouse!AJ42 -> 47.6 | F14: =[6]Brewhouse!X42 -> 83 | G14: =[6]Brewhouse!AH42 -> 14.5 | H14: 14.5 | I14: =[6]Brewhouse!AV42 -> 97.94969 | J14: =[6]Brewhouse!AW42 -> 98.259652 | K14: =[6]Brewhouse!S42 -> 14.613936 | L14: =[6]Brewhouse!R42 -> 60 | M14: =[6]Brewhouse!$W42-[6]Brewhouse!$V42 -> 0.14097222 | N14: =[6]Brewhouse!AB42 -> 0.30555556 | O14: =[6]Brewhouse!$AZ42 -> D. Gomaz | R14: =B14 -> VITAMALT | S14: =VLOOKUP($B14,$R$3:$X$9,2,FALSE) -> 14.2 | T14: =VLOOKUP($B14,$R$3:$X$9,3,FALSE) -> 14.6 | U14: =VLOOKUP($B14,$R$3:$X$9,4,FALSE) -> 0 | V14: =VLOOKUP($B14,$R$3:$X$9,5,FALSE) -> 0.13905093 | W14: =VLOOKUP($B14,$R$3:$X$9,6,FALSE) -> 0.26041667 | X14: =VLOOKUP($B14,$R$3:$X$9,7,FALSE) -> 0.29513889 | Y14: =VLOOKUP($B14,$R$3:$Z$9,8,FALSE) -> 0 | Z14: =VLOOKUP($B14,$R$3:$Z$9,9,FALSE) -> 75
B15: VITAMALT | C15: =[6]Brewhouse!A43 -> VM019 | D15: =[6]Brewhouse!AE43 -> 52.1 | E15: =[6]Brewhouse!AJ43 -> 47 | F15: =[6]Brewhouse!X43 -> 84 | G15: =[6]Brewhouse!AH43 -> 14.4 | H15: 14.4 | I15: =[6]Brewhouse!AV43 -> 95.81853 | J15: =[6]Brewhouse!AW43 -> 96.124285 | K15: =[6]Brewhouse!S43 -> 10.863724 | L15: =[6]Brewhouse!R43 -> 60 | M15: =[6]Brewhouse!$W43-[6]Brewhouse!$V43 -> 0.15069444 | N15: =[6]Brewhouse!AB43 -> 0.46666667 | O15: =[6]Brewhouse!$AZ43 -> R. Regis | R15: =B15 -> VITAMALT | S15: =VLOOKUP($B15,$R$3:$X$9,2,FALSE) -> 14.2 | T15: =VLOOKUP($B15,$R$3:$X$9,3,FALSE) -> 14.6 | U15: =VLOOKUP($B15,$R$3:$X$9,4,FALSE) -> 0 | V15: =VLOOKUP($B15,$R$3:$X$9,5,FALSE) -> 0.13905093 | W15: =VLOOKUP($B15,$R$3:$X$9,6,FALSE) -> 0.26041667 | X15: =VLOOKUP($B15,$R$3:$X$9,7,FALSE) -> 0.29513889 | Y15: =VLOOKUP($B15,$R$3:$Z$9,8,FALSE) -> 0 | Z15: =VLOOKUP($B15,$R$3:$Z$9,9,FALSE) -> 75
B16: VITAMALT | C16: =[6]Brewhouse!A44 -> VM020 | D16: =[6]Brewhouse!AE44 -> 50.1 | E16: =[6]Brewhouse!AJ44 -> 47.2 | F16: =[6]Brewhouse!X44 -> 85 | G16: =[6]Brewhouse!AH44 -> 14.6 | H16: 14.7 | I16: =[6]Brewhouse!AV44 -> 97.823512 | J16: =[6]Brewhouse!AW44 -> 98.133075 | K16: =[6]Brewhouse!S44 -> 14.091816 | L16: =[6]Brewhouse!R44 -> 61 | M16: =[6]Brewhouse!$W44-[6]Brewhouse!$V44 -> 0.15486111 | N16: =[6]Brewhouse!AB44 -> 0.31597222 | O16: =[6]Brewhouse!$AZ44 -> R. Regis | R16: =B16 -> VITAMALT | S16: =VLOOKUP($B16,$R$3:$X$9,2,FALSE) -> 14.2 | T16: =VLOOKUP($B16,$R$3:$X$9,3,FALSE) -> 14.6 | U16: =VLOOKUP($B16,$R$3:$X$9,4,FALSE) -> 0 | V16: =VLOOKUP($B16,$R$3:$X$9,5,FALSE) -> 0.13905093 | W16: =VLOOKUP($B16,$R$3:$X$9,6,FALSE) -> 0.26041667 | X16: =VLOOKUP($B16,$R$3:$X$9,7,FALSE) -> 0.29513889 | Y16: =VLOOKUP($B16,$R$3:$Z$9,8,FALSE) -> 0 | Z16: =VLOOKUP($B16,$R$3:$Z$9,9,FALSE) -> 75
R17: =B17 -> 0 | S17: =VLOOKUP($B17,$R$3:$X$9,2,FALSE) -> #N/A | T17: =VLOOKUP($B17,$R$3:$X$9,3,FALSE) -> #N/A | U17: =VLOOKUP($B17,$R$3:$X$9,4,FALSE) -> #N/A | V17: =VLOOKUP($B17,$R$3:$X$9,5,FALSE) -> #N/A | W17: =VLOOKUP($B17,$R$3:$X$9,6,FALSE) -> #N/A | X17: =VLOOKUP($B17,$R$3:$X$9,7,FALSE) -> #N/A | Y17: =VLOOKUP($B17,$R$3:$Z$9,8,FALSE) -> #N/A | Z17: =VLOOKUP($B17,$R$3:$Z$9,9,FALSE) -> #N/A
R18: =B18 -> 0 | S18: =VLOOKUP($B18,$R$3:$X$9,2,FALSE) -> #N/A | T18: =VLOOKUP($B18,$R$3:$X$9,3,FALSE) -> #N/A | U18: =VLOOKUP($B18,$R$3:$X$9,4,FALSE) -> #N/A | V18: =VLOOKUP($B18,$R$3:$X$9,5,FALSE) -> #N/A | W18: =VLOOKUP($B18,$R$3:$X$9,6,FALSE) -> #N/A | X18: =VLOOKUP($B18,$R$3:$X$9,7,FALSE) -> #N/A | Y18: =VLOOKUP($B18,$R$3:$Z$9,8,FALSE) -> #N/A | Z18: =VLOOKUP($B18,$R$3:$Z$9,9,FALSE) -> #N/A
R19: =B19 -> 0 | S19: =VLOOKUP($B19,$R$3:$X$9,2,FALSE) -> #N/A | T19: =VLOOKUP($B19,$R$3:$X$9,3,FALSE) -> #N/A | U19: =VLOOKUP($B19,$R$3:$X$9,4,FALSE) -> #N/A | V19: =VLOOKUP($B19,$R$3:$X$9,5,FALSE) -> #N/A | W19: =VLOOKUP($B19,$R$3:$X$9,6,FALSE) -> #N/A | X19: =VLOOKUP($B19,$R$3:$X$9,7,FALSE) -> #N/A | Y19: =VLOOKUP($B19,$R$3:$Z$9,8,FALSE) -> #N/A | Z19: =VLOOKUP($B19,$R$3:$Z$9,9,FALSE) -> #N/A
R20: =B20 -> 0 | S20: =VLOOKUP($B20,$R$3:$X$9,2,FALSE) -> #N/A | T20: =VLOOKUP($B20,$R$3:$X$9,3,FALSE) -> #N/A | U20: =VLOOKUP($B20,$R$3:$X$9,4,FALSE) -> #N/A | V20: =VLOOKUP($B20,$R$3:$X$9,5,FALSE) -> #N/A | W20: =VLOOKUP($B20,$R$3:$X$9,6,FALSE) -> #N/A | X20: =VLOOKUP($B20,$R$3:$X$9,7,FALSE) -> #N/A | Y20: =VLOOKUP($B20,$R$3:$Z$9,8,FALSE) -> #N/A | Z20: =VLOOKUP($B20,$R$3:$Z$9,9,FALSE) -> #N/A
R21: =B21 -> 0 | S21: =VLOOKUP($B21,$R$3:$X$9,2,FALSE) -> #N/A | T21: =VLOOKUP($B21,$R$3:$X$9,3,FALSE) -> #N/A | U21: =VLOOKUP($B21,$R$3:$X$9,4,FALSE) -> #N/A | V21: =VLOOKUP($B21,$R$3:$X$9,5,FALSE) -> #N/A | W21: =VLOOKUP($B21,$R$3:$X$9,6,FALSE) -> #N/A | X21: =VLOOKUP($B21,$R$3:$X$9,7,FALSE) -> #N/A | Y21: =VLOOKUP($B21,$R$3:$Z$9,8,FALSE) -> #N/A | Z21: =VLOOKUP($B21,$R$3:$Z$9,9,FALSE) -> #N/A
R22: =B22 -> 0 | S22: =VLOOKUP($B22,$R$3:$X$9,2,FALSE) -> #N/A | T22: =VLOOKUP($B22,$R$3:$X$9,3,FALSE) -> #N/A | U22: =VLOOKUP($B22,$R$3:$X$9,4,FALSE) -> #N/A | V22: =VLOOKUP($B22,$R$3:$X$9,5,FALSE) -> #N/A | W22: =VLOOKUP($B22,$R$3:$X$9,6,FALSE) -> #N/A | X22: =VLOOKUP($B22,$R$3:$X$9,7,FALSE) -> #N/A | Y22: =VLOOKUP($B22,$R$3:$Z$9,8,FALSE) -> #N/A | Z22: =VLOOKUP($B22,$R$3:$Z$9,9,FALSE) -> #N/A
R23: =B23 -> 0 | S23: =VLOOKUP($B23,$R$3:$X$9,2,FALSE) -> #N/A | T23: =VLOOKUP($B23,$R$3:$X$9,3,FALSE) -> #N/A | U23: =VLOOKUP($B23,$R$3:$X$9,4,FALSE) -> #N/A | V23: =VLOOKUP($B23,$R$3:$X$9,5,FALSE) -> #N/A | W23: =VLOOKUP($B23,$R$3:$X$9,6,FALSE) -> #N/A | X23: =VLOOKUP($B23,$R$3:$X$9,7,FALSE) -> #N/A | Y23: =VLOOKUP($B23,$R$3:$Z$9,8,FALSE) -> #N/A | Z23: =VLOOKUP($B23,$R$3:$Z$9,9,FALSE) -> #N/A
R24: =B24 -> 0 | S24: =VLOOKUP($B24,$R$3:$X$9,2,FALSE) -> #N/A | T24: =VLOOKUP($B24,$R$3:$X$9,3,FALSE) -> #N/A | U24: =VLOOKUP($B24,$R$3:$X$9,4,FALSE) -> #N/A | V24: =VLOOKUP($B24,$R$3:$X$9,5,FALSE) -> #N/A | W24: =VLOOKUP($B24,$R$3:$X$9,6,FALSE) -> #N/A | X24: =VLOOKUP($B24,$R$3:$X$9,7,FALSE) -> #N/A | Y24: =VLOOKUP($B24,$R$3:$Z$9,8,FALSE) -> #N/A | Z24: =VLOOKUP($B24,$R$3:$Z$9,9,FALSE) -> #N/A
R25: =B25 -> 0 | S25: =VLOOKUP($B25,$R$3:$X$9,2,FALSE) -> #N/A | T25: =VLOOKUP($B25,$R$3:$X$9,3,FALSE) -> #N/A | U25: =VLOOKUP($B25,$R$3:$X$9,4,FALSE) -> #N/A | V25: =VLOOKUP($B25,$R$3:$X$9,5,FALSE) -> #N/A | W25: =VLOOKUP($B25,$R$3:$X$9,6,FALSE) -> #N/A | X25: =VLOOKUP($B25,$R$3:$X$9,7,FALSE) -> #N/A | Y25: =VLOOKUP($B25,$R$3:$Z$9,8,FALSE) -> #N/A | Z25: =VLOOKUP($B25,$R$3:$Z$9,9,FALSE) -> #N/A
R26: =B26 -> 0 | S26: =VLOOKUP($B26,$R$3:$X$9,2,FALSE) -> #N/A | T26: =VLOOKUP($B26,$R$3:$X$9,3,FALSE) -> #N/A | U26: =VLOOKUP($B26,$R$3:$X$9,4,FALSE) -> #N/A | V26: =VLOOKUP($B26,$R$3:$X$9,5,FALSE) -> #N/A | W26: =VLOOKUP($B26,$R$3:$X$9,6,FALSE) -> #N/A | X26: =VLOOKUP($B26,$R$3:$X$9,7,FALSE) -> #N/A | Y26: =VLOOKUP($B26,$R$3:$Z$9,8,FALSE) -> #N/A | Z26: =VLOOKUP($B26,$R$3:$Z$9,9,FALSE) -> #N/A
R27: =B27 -> 0 | S27: =VLOOKUP($B27,$R$3:$X$9,2,FALSE) -> #N/A | T27: =VLOOKUP($B27,$R$3:$X$9,3,FALSE) -> #N/A | U27: =VLOOKUP($B27,$R$3:$X$9,4,FALSE) -> #N/A | V27: =VLOOKUP($B27,$R$3:$X$9,5,FALSE) -> #N/A | W27: =VLOOKUP($B27,$R$3:$X$9,6,FALSE) -> #N/A | X27: =VLOOKUP($B27,$R$3:$X$9,7,FALSE) -> #N/A | Y27: =VLOOKUP($B27,$R$3:$Z$9,8,FALSE) -> #N/A | Z27: =VLOOKUP($B27,$R$3:$Z$9,9,FALSE) -> #N/A
R28: =B28 -> 0 | S28: =VLOOKUP($B28,$R$3:$X$9,2,FALSE) -> #N/A | T28: =VLOOKUP($B28,$R$3:$X$9,3,FALSE) -> #N/A | U28: =VLOOKUP($B28,$R$3:$X$9,4,FALSE) -> #N/A | V28: =VLOOKUP($B28,$R$3:$X$9,5,FALSE) -> #N/A | W28: =VLOOKUP($B28,$R$3:$X$9,6,FALSE) -> #N/A | X28: =VLOOKUP($B28,$R$3:$X$9,7,FALSE) -> #N/A | Y28: =VLOOKUP($B28,$R$3:$Z$9,8,FALSE) -> #N/A | Z28: =VLOOKUP($B28,$R$3:$Z$9,9,FALSE) -> #N/A
R29: =B29 -> 0 | S29: =VLOOKUP($B29,$R$3:$X$9,2,FALSE) -> #N/A | T29: =VLOOKUP($B29,$R$3:$X$9,3,FALSE) -> #N/A | U29: =VLOOKUP($B29,$R$3:$X$9,4,FALSE) -> #N/A | V29: =VLOOKUP($B29,$R$3:$X$9,5,FALSE) -> #N/A | W29: =VLOOKUP($B29,$R$3:$X$9,6,FALSE) -> #N/A | X29: =VLOOKUP($B29,$R$3:$X$9,7,FALSE) -> #N/A | Y29: =VLOOKUP($B29,$R$3:$Z$9,8,FALSE) -> #N/A | Z29: =VLOOKUP($B29,$R$3:$Z$9,9,FALSE) -> #N/A
B30: BRAND | D30: BBT P.G./ O.G | I30: Brand | K30: MTD No. of Brews | L30: MTD | M30: YTD | N30: Target | R30: =B30 -> BRAND | S30: =VLOOKUP($B30,$R$3:$X$9,2,FALSE) -> #N/A | T30: =VLOOKUP($B30,$R$3:$X$9,3,FALSE) -> #N/A | U30: =VLOOKUP($B30,$R$3:$X$9,4,FALSE) -> #N/A | V30: =VLOOKUP($B30,$R$3:$X$9,5,FALSE) -> #N/A | W30: =VLOOKUP($B30,$R$3:$X$9,6,FALSE) -> #N/A | X30: =VLOOKUP($B30,$R$3:$X$9,7,FALSE) -> #N/A | Y30: =VLOOKUP($B30,$R$3:$Z$9,8,FALSE) -> #N/A | Z30: =VLOOKUP($B30,$R$3:$Z$9,9,FALSE) -> #N/A
I31: CARIB | M31: =AVERAGE([4]Brewhouse!$AU$42:$AU$123,[4]Brewhouse!$AU$125:$AU$188) -> 97.596349 | N31: 98 | R31: =B31 -> 0 | S31: =VLOOKUP($B31,$R$3:$X$9,2,FALSE) -> #N/A | T31: =VLOOKUP($B31,$R$3:$X$9,3,FALSE) -> #N/A | U31: =VLOOKUP($B31,$R$3:$X$9,4,FALSE) -> #N/A | V31: =VLOOKUP($B31,$R$3:$X$9,5,FALSE) -> #N/A | W31: =VLOOKUP($B31,$R$3:$X$9,6,FALSE) -> #N/A | X31: =VLOOKUP($B31,$R$3:$X$9,7,FALSE) -> #N/A | Y31: =VLOOKUP($B31,$R$3:$Z$9,8,FALSE) -> #N/A | Z31: =VLOOKUP($B31,$R$3:$Z$9,9,FALSE) -> #N/A
I32: STAG | M32: =AVERAGE([3]Brewhouse!$AS$52:$AS$81,[3]Brewhouse!$AS$83:$AS$124) -> 98.316611 | N32: 98 | R32: =B32 -> 0 | S32: =VLOOKUP($B32,$R$3:$X$9,2,FALSE) -> #N/A | T32: =VLOOKUP($B32,$R$3:$X$9,3,FALSE) -> #N/A | U32: =VLOOKUP($B32,$R$3:$X$9,4,FALSE) -> #N/A | V32: =VLOOKUP($B32,$R$3:$X$9,5,FALSE) -> #N/A | W32: =VLOOKUP($B32,$R$3:$X$9,6,FALSE) -> #N/A | X32: =VLOOKUP($B32,$R$3:$X$9,7,FALSE) -> #N/A | Y32: =VLOOKUP($B32,$R$3:$Z$9,8,FALSE) -> #N/A | Z32: =VLOOKUP($B32,$R$3:$Z$9,9,FALSE) -> #N/A
I33: GUINNESS | M33: =AVERAGE([5]Brewhouse!$AU$16:$AU$23,[5]Brewhouse!$AU$25:$AU$27) -> 97.93389 | N33: 98 | R33: =B33 -> 0 | S33: =VLOOKUP($B33,$R$3:$X$9,2,FALSE) -> #N/A | T33: =VLOOKUP($B33,$R$3:$X$9,3,FALSE) -> #N/A | U33: =VLOOKUP($B33,$R$3:$X$9,4,FALSE) -> #N/A | V33: =VLOOKUP($B33,$R$3:$X$9,5,FALSE) -> #N/A | W33: =VLOOKUP($B33,$R$3:$X$9,6,FALSE) -> #N/A | X33: =VLOOKUP($B33,$R$3:$X$9,7,FALSE) -> #N/A | Y33: =VLOOKUP($B33,$R$3:$Z$9,8,FALSE) -> #N/A | Z33: =VLOOKUP($B33,$R$3:$Z$9,9,FALSE) -> #N/A
I34: VITAMALT | J34: =AVERAGE(I10:I16) -> 96.929916 | K34: =COUNTA([6]Brewhouse!$A$38:$A$44) -> 7 | L34: =AVERAGE([6]Brewhouse!$AV$38:$AV$44) -> 96.929916 | M34: =AVERAGE([6]Brewhouse!$AV$23:$AV$34,[6]Brewhouse!$AV$36,[6]Brewhouse!$AV$38:$AV$44) -> 97.740552 | N34: 98 | R34: =B34 -> 0 | S34: =VLOOKUP($B34,$R$3:$X$9,2,FALSE) -> #N/A | T34: =VLOOKUP($B34,$R$3:$X$9,3,FALSE) -> #N/A | U34: =VLOOKUP($B34,$R$3:$X$9,4,FALSE) -> #N/A | V34: =VLOOKUP($B34,$R$3:$X$9,5,FALSE) -> #N/A | W34: =VLOOKUP($B34,$R$3:$X$9,6,FALSE) -> #N/A | X34: =VLOOKUP($B34,$R$3:$X$9,7,FALSE) -> #N/A | Y34: =VLOOKUP($B34,$R$3:$Z$9,8,FALSE) -> #N/A | Z34: =VLOOKUP($B34,$R$3:$Z$9,9,FALSE) -> #N/A
I35: MAXIMALT | N35: 98 | R35: =B35 -> 0 | S35: =VLOOKUP($B35,$R$3:$X$9,2,FALSE) -> #N/A | T35: =VLOOKUP($B35,$R$3:$X$9,3,FALSE) -> #N/A | U35: =VLOOKUP($B35,$R$3:$X$9,4,FALSE) -> #N/A | V35: =VLOOKUP($B35,$R$3:$X$9,5,FALSE) -> #N/A | W35: =VLOOKUP($B35,$R$3:$X$9,6,FALSE) -> #N/A | X35: =VLOOKUP($B35,$R$3:$X$9,7,FALSE) -> #N/A | Y35: =VLOOKUP($B35,$R$3:$Z$9,8,FALSE) -> #N/A | Z35: =VLOOKUP($B35,$R$3:$Z$9,9,FALSE) -> #N/A
I36: MACKESON | M36: =AVERAGE([7]Brewhouse!$AT$4:$AT$11) -> 92.826225 | N36: 98 | R36: =B36 -> 0 | S36: =VLOOKUP($B36,$R$3:$X$9,2,FALSE) -> #N/A | T36: =VLOOKUP($B36,$R$3:$X$9,3,FALSE) -> #N/A | U36: =VLOOKUP($B36,$R$3:$X$9,4,FALSE) -> #N/A | V36: =VLOOKUP($B36,$R$3:$X$9,5,FALSE) -> #N/A | W36: =VLOOKUP($B36,$R$3:$X$9,6,FALSE) -> #N/A | X36: =VLOOKUP($B36,$R$3:$X$9,7,FALSE) -> #N/A | Y36: =VLOOKUP($B36,$R$3:$Z$9,8,FALSE) -> #N/A | Z36: =VLOOKUP($B36,$R$3:$Z$9,9,FALSE) -> #N/A
I37: STARMALT | M37: =AVERAGE([8]Brewhouse!$AY$5:$AY$14,[8]Brewhouse!$AY$16:$AY$23) -> 97.293615 | N37: 98 | R37: =B37 -> 0 | S37: =VLOOKUP($B37,$R$3:$X$9,2,FALSE) -> #N/A | T37: =VLOOKUP($B37,$R$3:$X$9,3,FALSE) -> #N/A | U37: =VLOOKUP($B37,$R$3:$X$9,4,FALSE) -> #N/A | V37: =VLOOKUP($B37,$R$3:$X$9,5,FALSE) -> #N/A | W37: =VLOOKUP($B37,$R$3:$X$9,6,FALSE) -> #N/A | X37: =VLOOKUP($B37,$R$3:$X$9,7,FALSE) -> #N/A | Y37: =VLOOKUP($B37,$R$3:$Z$9,8,FALSE) -> #N/A | Z37: =VLOOKUP($B37,$R$3:$Z$9,9,FALSE) -> #N/A
I38: HR- Pils | N38: 98 | R38: =B38 -> 0 | S38: =VLOOKUP($B38,$R$3:$X$9,2,FALSE) -> #N/A | T38: =VLOOKUP($B38,$R$3:$X$9,3,FALSE) -> #N/A | U38: =VLOOKUP($B38,$R$3:$X$9,4,FALSE) -> #N/A | V38: =VLOOKUP($B38,$R$3:$X$9,5,FALSE) -> #N/A | W38: =VLOOKUP($B38,$R$3:$X$9,6,FALSE) -> #N/A | X38: =VLOOKUP($B38,$R$3:$X$9,7,FALSE) -> #N/A | Y38: =VLOOKUP($B38,$R$3:$Z$9,8,FALSE) -> #N/A | Z38: =VLOOKUP($B38,$R$3:$Z$9,9,FALSE) -> #N/A
I39: HR- IPA | N39: 98 | R39: =B39 -> 0 | S39: =VLOOKUP($B39,$R$3:$X$9,2,FALSE) -> #N/A | T39: =VLOOKUP($B39,$R$3:$X$9,3,FALSE) -> #N/A | U39: =VLOOKUP($B39,$R$3:$X$9,4,FALSE) -> #N/A | V39: =VLOOKUP($B39,$R$3:$X$9,5,FALSE) -> #N/A | W39: =VLOOKUP($B39,$R$3:$X$9,6,FALSE) -> #N/A | X39: =VLOOKUP($B39,$R$3:$X$9,7,FALSE) -> #N/A | Y39: =VLOOKUP($B39,$R$3:$Z$9,8,FALSE) -> #N/A | Z39: =VLOOKUP($B39,$R$3:$Z$9,9,FALSE) -> #N/A
I40: HR- APA | N40: 98 | R40: =B40 -> 0 | S40: =VLOOKUP($B40,$R$3:$X$9,2,FALSE) -> #N/A | T40: =VLOOKUP($B40,$R$3:$X$9,3,FALSE) -> #N/A | U40: =VLOOKUP($B40,$R$3:$X$9,4,FALSE) -> #N/A | V40: =VLOOKUP($B40,$R$3:$X$9,5,FALSE) -> #N/A | W40: =VLOOKUP($B40,$R$3:$X$9,6,FALSE) -> #N/A | X40: =VLOOKUP($B40,$R$3:$X$9,7,FALSE) -> #N/A | Y40: =VLOOKUP($B40,$R$3:$Z$9,8,FALSE) -> #N/A | Z40: =VLOOKUP($B40,$R$3:$Z$9,9,FALSE) -> #N/A
...

Sheet Mar 2nd
S1: P.G. | U1: Hot Time | W1: Process Time | Y1: Cooling Time
B2: Brewing Department Daily Process Loss Report | S2: Lower | T2: Upper | U2: Lower | V2: Upper | W2: Lower | X2: Upper | Y2: Lower | Z2: Upper
R3: CARIB | S3: 11.6 | T3: 12 | U3: 0 | V3: 0.11805556 | W3: 0.22569444 | X3: 0.26388889 | Y3: 0 | Z3: 60 | AB3: HR- PISNER
B4: Date: | C4: 46080 | J4: LOT WORT COLOUR: | M4: Filter Sheets (Target 20 days) | R4: STAG | S4: 11.6 | T4: 12 | U4: 0 | V4: 0.11805556 | W4: 0.22569444 | X4: 0.26388889 | Y4: 0 | Z4: 60
M5: Double | N5: Single | R5: GUINNESS | S5: 17 | T5: 17.5 | U5: 0 | V5: 0.10763889 | W5: 0.24652778 | X5: 0.28472222 | Y5: 0 | Z5: 60
J6: MALT LOT: Lot #13 | L6: Sheet Day | R6: MACKESON | S6: 13.3 | T6: 13.5 | U6: 0 | V6: 0.12905093 | W6: 0.27430556 | X6: 0.30208333 | Y6: 0
R7: STARMALT | S7: 17 | T7: 17.4 | U7: 0 | V7: 0.13605324 | W7: 0.27430556 | X7: 0.30902778 | Y7: 0 | Z7: 85
B8: Brand | C8: Brew no. | D8: Kett. Hls | E8: Wort | F8: Cool Time(Mins) | G8: Cast. P.G. (Lab Result) | H8: Cast P.G. (Cellar Operator)-gravity | I8: Extr. Rec (77.9%) | J8: Theor. Extr. (77.5%) | K8: Boil Off /Vol. (4-6%) | L8: Boil Time | M8: Total Hot | N8: Brewing Time | O8: Operator | R8: Hurricane Reef | S8: 16.6 | T8: 17 | U8: 0 | V8: 0.12905093 | W8: 0.27430556 | X8: 0.30208333 | Y8: 0
E9: Meter (Hls) | F9: Target(< 60Mins) | M9: Time | R9: VITAMALT | S9: 14.2 | T9: 14.6 | U9: 0 | V9: 0.13905093 | W9: 0.26041667 | X9: 0.29513889 | Y9: 0 | Z9: 75
B10: GUINNESS | C10: =[5]Brewhouse!$A34 -> GU017 | D10: =[5]Brewhouse!$AF34 -> 49.5 | E10: =[5]Brewhouse!$AI34 -> 48.4 | F10: =[5]Brewhouse!$V34 -> 62 | G10: =[5]Brewhouse!$AG34 -> 17.3 | I10: =[5]Brewhouse!$AU34 -> 90.90717 | J10: =[5]Brewhouse!$AV34 -> 92.090918 | K10: =[5]Brewhouse!$R34 -> 16.928571 | L10: =[5]Brewhouse!$O34 -> 60 | M10: =[5]Brewhouse!$U34-[5]Brewhouse!$T34 -> 0.12013889 | N10: =[5]Brewhouse!$Z34 -> 0.26736111 | O10: =[5]Brewhouse!$AW34 -> K. Benjamin | R10: =B10 -> GUINNESS | S10: =VLOOKUP($B10,$R$3:$X$9,2,FALSE) -> 17 | T10: =VLOOKUP($B10,$R$3:$X$9,3,FALSE) -> 17.5 | U10: =VLOOKUP($B10,$R$3:$X$9,4,FALSE) -> 0 | V10: =VLOOKUP($B10,$R$3:$X$9,5,FALSE) -> 0.10763889 | W10: =VLOOKUP($B10,$R$3:$X$9,6,FALSE) -> 0.24652778 | X10: =VLOOKUP($B10,$R$3:$X$9,7,FALSE) -> 0.28472222 | Y10: =VLOOKUP($B10,$R$3:$Z$9,8,FALSE) -> 0 | Z10: =VLOOKUP($B10,$R$3:$Z$9,9,FALSE) -> 60
B11: GUINNESS | C11: =[5]Brewhouse!$A35 -> GU018 | D11: =[5]Brewhouse!$AF35 -> 49.7 | E11: =[5]Brewhouse!$AI35 -> 49.2 | F11: =[5]Brewhouse!$V35 -> 60 | G11: =[5]Brewhouse!$AG35 -> 17.1 | I11: =[5]Brewhouse!$AU35 -> 91.553614 | J11: =[5]Brewhouse!$AV35 -> 92.744944 | K11: =[5]Brewhouse!$R35 -> 13.714286 | L11: =[5]Brewhouse!$O35 -> 59 | M11: =[5]Brewhouse!$U35-[5]Brewhouse!$T35 -> 0.11597222 | N11: =[5]Brewhouse!$Z35 -> 0.26944444 | O11: =[5]Brewhouse!$AW35 -> K. Benjamin | R11: =B11 -> GUINNESS | S11: =VLOOKUP($B11,$R$3:$X$9,2,FALSE) -> 17 | T11: =VLOOKUP($B11,$R$3:$X$9,3,FALSE) -> 17.5 | U11: =VLOOKUP($B11,$R$3:$X$9,4,FALSE) -> 0 | V11: =VLOOKUP($B11,$R$3:$X$9,5,FALSE) -> 0.10763889 | W11: =VLOOKUP($B11,$R$3:$X$9,6,FALSE) -> 0.24652778 | X11: =VLOOKUP($B11,$R$3:$X$9,7,FALSE) -> 0.28472222 | Y11: =VLOOKUP($B11,$R$3:$Z$9,8,FALSE) -> 0 | Z11: =VLOOKUP($B11,$R$3:$Z$9,9,FALSE) -> 60
B12: GUINNESS | C12: =[5]Brewhouse!$A36 -> GU019 | D12: =[5]Brewhouse!$AF36 -> 51.2 | E12: =[5]Brewhouse!$AI36 -> 50.3 | F12: =[5]Brewhouse!$V36 -> 61 | G12: =[5]Brewhouse!$AG36 -> 17.5 | I12: =[5]Brewhouse!$AU36 -> 95.905976 | J12: =[5]Brewhouse!$AV36 -> 97.153941 | K12: =[5]Brewhouse!$R36 -> 12.263815 | L12: =[5]Brewhouse!$O36 -> 60 | M12: =[5]Brewhouse!$U36-[5]Brewhouse!$T36 -> 0.11527778 | N12: =[5]Brewhouse!$Z36 -> 0.27083333 | O12: =[5]Brewhouse!$AW36 -> R. Regis | R12: =B12 -> GUINNESS | S12: =VLOOKUP($B12,$R$3:$X$9,2,FALSE) -> 17 | T12: =VLOOKUP($B12,$R$3:$X$9,3,FALSE) -> 17.5 | U12: =VLOOKUP($B12,$R$3:$X$9,4,FALSE) -> 0 | V12: =VLOOKUP($B12,$R$3:$X$9,5,FALSE) -> 0.10763889 | W12: =VLOOKUP($B12,$R$3:$X$9,6,FALSE) -> 0.24652778 | X12: =VLOOKUP($B12,$R$3:$X$9,7,FALSE) -> 0.28472222 | Y12: =VLOOKUP($B12,$R$3:$Z$9,8,FALSE) -> 0 | Z12: =VLOOKUP($B12,$R$3:$Z$9,9,FALSE) -> 60
R13: =B13 -> 0 | S13: =VLOOKUP($B13,$R$3:$X$9,2,FALSE) -> #N/A | T13: =VLOOKUP($B13,$R$3:$X$9,3,FALSE) -> #N/A | U13: =VLOOKUP($B13,$R$3:$X$9,4,FALSE) -> #N/A | V13: =VLOOKUP($B13,$R$3:$X$9,5,FALSE) -> #N/A | W13: =VLOOKUP($B13,$R$3:$X$9,6,FALSE) -> #N/A | X13: =VLOOKUP($B13,$R$3:$X$9,7,FALSE) -> #N/A | Y13: =VLOOKUP($B13,$R$3:$Z$9,8,FALSE) -> #N/A | Z13: =VLOOKUP($B13,$R$3:$Z$9,9,FALSE) -> #N/A
R14: =B14 -> 0 | S14: =VLOOKUP($B14,$R$3:$X$9,2,FALSE) -> #N/A | T14: =VLOOKUP($B14,$R$3:$X$9,3,FALSE) -> #N/A | U14: =VLOOKUP($B14,$R$3:$X$9,4,FALSE) -> #N/A | V14: =VLOOKUP($B14,$R$3:$X$9,5,FALSE) -> #N/A | W14: =VLOOKUP($B14,$R$3:$X$9,6,FALSE) -> #N/A | X14: =VLOOKUP($B14,$R$3:$X$9,7,FALSE) -> #N/A | Y14: =VLOOKUP($B14,$R$3:$Z$9,8,FALSE) -> #N/A | Z14: =VLOOKUP($B14,$R$3:$Z$9,9,FALSE) -> #N/A
R15: =B15 -> 0 | S15: =VLOOKUP($B15,$R$3:$X$9,2,FALSE) -> #N/A | T15: =VLOOKUP($B15,$R$3:$X$9,3,FALSE) -> #N/A | U15: =VLOOKUP($B15,$R$3:$X$9,4,FALSE) -> #N/A | V15: =VLOOKUP($B15,$R$3:$X$9,5,FALSE) -> #N/A | W15: =VLOOKUP($B15,$R$3:$X$9,6,FALSE) -> #N/A | X15: =VLOOKUP($B15,$R$3:$X$9,7,FALSE) -> #N/A | Y15: =VLOOKUP($B15,$R$3:$Z$9,8,FALSE) -> #N/A | Z15: =VLOOKUP($B15,$R$3:$Z$9,9,FALSE) -> #N/A
R16: =B16 -> 0 | S16: =VLOOKUP($B16,$R$3:$X$9,2,FALSE) -> #N/A | T16: =VLOOKUP($B16,$R$3:$X$9,3,FALSE) -> #N/A | U16: =VLOOKUP($B16,$R$3:$X$9,4,FALSE) -> #N/A | V16: =VLOOKUP($B16,$R$3:$X$9,5,FALSE) -> #N/A | W16: =VLOOKUP($B16,$R$3:$X$9,6,FALSE) -> #N/A | X16: =VLOOKUP($B16,$R$3:$X$9,7,FALSE) -> #N/A | Y16: =VLOOKUP($B16,$R$3:$Z$9,8,FALSE) -> #N/A | Z16: =VLOOKUP($B16,$R$3:$Z$9,9,FALSE) -> #N/A
R17: =B17 -> 0 | S17: =VLOOKUP($B17,$R$3:$X$9,2,FALSE) -> #N/A | T17: =VLOOKUP($B17,$R$3:$X$9,3,FALSE) -> #N/A | U17: =VLOOKUP($B17,$R$3:$X$9,4,FALSE) -> #N/A | V17: =VLOOKUP($B17,$R$3:$X$9,5,FALSE) -> #N/A | W17: =VLOOKUP($B17,$R$3:$X$9,6,FALSE) -> #N/A | X17: =VLOOKUP($B17,$R$3:$X$9,7,FALSE) -> #N/A | Y17: =VLOOKUP($B17,$R$3:$Z$9,8,FALSE) -> #N/A | Z17: =VLOOKUP($B17,$R$3:$Z$9,9,FALSE) -> #N/A
R18: =B18 -> 0 | S18: =VLOOKUP($B18,$R$3:$X$9,2,FALSE) -> #N/A | T18: =VLOOKUP($B18,$R$3:$X$9,3,FALSE) -> #N/A | U18: =VLOOKUP($B18,$R$3:$X$9,4,FALSE) -> #N/A | V18: =VLOOKUP($B18,$R$3:$X$9,5,FALSE) -> #N/A | W18: =VLOOKUP($B18,$R$3:$X$9,6,FALSE) -> #N/A | X18: =VLOOKUP($B18,$R$3:$X$9,7,FALSE) -> #N/A | Y18: =VLOOKUP($B18,$R$3:$Z$9,8,FALSE) -> #N/A | Z18: =VLOOKUP($B18,$R$3:$Z$9,9,FALSE) -> #N/A
R19: =B19 -> 0 | S19: =VLOOKUP($B19,$R$3:$X$9,2,FALSE) -> #N/A | T19: =VLOOKUP($B19,$R$3:$X$9,3,FALSE) -> #N/A | U19: =VLOOKUP($B19,$R$3:$X$9,4,FALSE) -> #N/A | V19: =VLOOKUP($B19,$R$3:$X$9,5,FALSE) -> #N/A | W19: =VLOOKUP($B19,$R$3:$X$9,6,FALSE) -> #N/A | X19: =VLOOKUP($B19,$R$3:$X$9,7,FALSE) -> #N/A | Y19: =VLOOKUP($B19,$R$3:$Z$9,8,FALSE) -> #N/A | Z19: =VLOOKUP($B19,$R$3:$Z$9,9,FALSE) -> #N/A
R20: =B20 -> 0 | S20: =VLOOKUP($B20,$R$3:$X$9,2,FALSE) -> #N/A | T20: =VLOOKUP($B20,$R$3:$X$9,3,FALSE) -> #N/A | U20: =VLOOKUP($B20,$R$3:$X$9,4,FALSE) -> #N/A | V20: =VLOOKUP($B20,$R$3:$X$9,5,FALSE) -> #N/A | W20: =VLOOKUP($B20,$R$3:$X$9,6,FALSE) -> #N/A | X20: =VLOOKUP($B20,$R$3:$X$9,7,FALSE) -> #N/A | Y20: =VLOOKUP($B20,$R$3:$Z$9,8,FALSE) -> #N/A | Z20: =VLOOKUP($B20,$R$3:$Z$9,9,FALSE) -> #N/A
R21: =B21 -> 0 | S21: =VLOOKUP($B21,$R$3:$X$9,2,FALSE) -> #N/A | T21: =VLOOKUP($B21,$R$3:$X$9,3,FALSE) -> #N/A | U21: =VLOOKUP($B21,$R$3:$X$9,4,FALSE) -> #N/A | V21: =VLOOKUP($B21,$R$3:$X$9,5,FALSE) -> #N/A | W21: =VLOOKUP($B21,$R$3:$X$9,6,FALSE) -> #N/A | X21: =VLOOKUP($B21,$R$3:$X$9,7,FALSE) -> #N/A | Y21: =VLOOKUP($B21,$R$3:$Z$9,8,FALSE) -> #N/A | Z21: =VLOOKUP($B21,$R$3:$Z$9,9,FALSE) -> #N/A
R22: =B22 -> 0 | S22: =VLOOKUP($B22,$R$3:$X$9,2,FALSE) -> #N/A | T22: =VLOOKUP($B22,$R$3:$X$9,3,FALSE) -> #N/A | U22: =VLOOKUP($B22,$R$3:$X$9,4,FALSE) -> #N/A | V22: =VLOOKUP($B22,$R$3:$X$9,5,FALSE) -> #N/A | W22: =VLOOKUP($B22,$R$3:$X$9,6,FALSE) -> #N/A | X22: =VLOOKUP($B22,$R$3:$X$9,7,FALSE) -> #N/A | Y22: =VLOOKUP($B22,$R$3:$Z$9,8,FALSE) -> #N/A | Z22: =VLOOKUP($B22,$R$3:$Z$9,9,FALSE) -> #N/A
R23: =B23 -> 0 | S23: =VLOOKUP($B23,$R$3:$X$9,2,FALSE) -> #N/A | T23: =VLOOKUP($B23,$R$3:$X$9,3,FALSE) -> #N/A | U23: =VLOOKUP($B23,$R$3:$X$9,4,FALSE) -> #N/A | V23: =VLOOKUP($B23,$R$3:$X$9,5,FALSE) -> #N/A | W23: =VLOOKUP($B23,$R$3:$X$9,6,FALSE) -> #N/A | X23: =VLOOKUP($B23,$R$3:$X$9,7,FALSE) -> #N/A | Y23: =VLOOKUP($B23,$R$3:$Z$9,8,FALSE) -> #N/A | Z23: =VLOOKUP($B23,$R$3:$Z$9,9,FALSE) -> #N/A
B24: BRAND | D24: BBT P.G./ O.G | I24: Brand | K24: MTD No. of Brews | L24: MTD | M24: YTD | N24: Target | R24: =B24 -> BRAND | S24: =VLOOKUP($B24,$R$3:$X$9,2,FALSE) -> #N/A | T24: =VLOOKUP($B24,$R$3:$X$9,3,FALSE) -> #N/A | U24: =VLOOKUP($B24,$R$3:$X$9,4,FALSE) -> #N/A | V24: =VLOOKUP($B24,$R$3:$X$9,5,FALSE) -> #N/A | W24: =VLOOKUP($B24,$R$3:$X$9,6,FALSE) -> #N/A | X24: =VLOOKUP($B24,$R$3:$X$9,7,FALSE) -> #N/A | Y24: =VLOOKUP($B24,$R$3:$Z$9,8,FALSE) -> #N/A | Z24: =VLOOKUP($B24,$R$3:$Z$9,9,FALSE) -> #N/A
I25: CARIB | M25: =AVERAGE([4]Brewhouse!$AU$42:$AU$123,[4]Brewhouse!$AU$125:$AU$188) -> 97.596349 | N25: 98 | R25: =B25 -> 0 | S25: =VLOOKUP($B25,$R$3:$X$9,2,FALSE) -> #N/A | T25: =VLOOKUP($B25,$R$3:$X$9,3,FALSE) -> #N/A | U25: =VLOOKUP($B25,$R$3:$X$9,4,FALSE) -> #N/A | V25: =VLOOKUP($B25,$R$3:$X$9,5,FALSE) -> #N/A | W25: =VLOOKUP($B25,$R$3:$X$9,6,FALSE) -> #N/A | X25: =VLOOKUP($B25,$R$3:$X$9,7,FALSE) -> #N/A | Y25: =VLOOKUP($B25,$R$3:$Z$9,8,FALSE) -> #N/A | Z25: =VLOOKUP($B25,$R$3:$Z$9,9,FALSE) -> #N/A
I26: STAG | M26: =AVERAGE([3]Brewhouse!$AS$52:$AS$81,[3]Brewhouse!$AS$83:$AS$124) -> 98.316611 | N26: 98 | R26: =B26 -> 0 | S26: =VLOOKUP($B26,$R$3:$X$9,2,FALSE) -> #N/A | T26: =VLOOKUP($B26,$R$3:$X$9,3,FALSE) -> #N/A | U26: =VLOOKUP($B26,$R$3:$X$9,4,FALSE) -> #N/A | V26: =VLOOKUP($B26,$R$3:$X$9,5,FALSE) -> #N/A | W26: =VLOOKUP($B26,$R$3:$X$9,6,FALSE) -> #N/A | X26: =VLOOKUP($B26,$R$3:$X$9,7,FALSE) -> #N/A | Y26: =VLOOKUP($B26,$R$3:$Z$9,8,FALSE) -> #N/A | Z26: =VLOOKUP($B26,$R$3:$Z$9,9,FALSE) -> #N/A
I27: GUINNESS | M27: =AVERAGE([5]Brewhouse!$AU$16:$AU$23,[5]Brewhouse!$AU$25:$AU$27) -> 97.93389 | N27: 98 | R27: =B27 -> 0 | S27: =VLOOKUP($B27,$R$3:$X$9,2,FALSE) -> #N/A | T27: =VLOOKUP($B27,$R$3:$X$9,3,FALSE) -> #N/A | U27: =VLOOKUP($B27,$R$3:$X$9,4,FALSE) -> #N/A | V27: =VLOOKUP($B27,$R$3:$X$9,5,FALSE) -> #N/A | W27: =VLOOKUP($B27,$R$3:$X$9,6,FALSE) -> #N/A | X27: =VLOOKUP($B27,$R$3:$X$9,7,FALSE) -> #N/A | Y27: =VLOOKUP($B27,$R$3:$Z$9,8,FALSE) -> #N/A | Z27: =VLOOKUP($B27,$R$3:$Z$9,9,FALSE) -> #N/A
I28: VITAMALT | J28: =AVERAGE(I10:I10) -> 90.90717 | K28: =COUNTA([6]Brewhouse!$A$38:$A$44) -> 7 | L28: =AVERAGE([6]Brewhouse!$AV$38:$AV$44) -> 96.929916 | M28: =AVERAGE([6]Brewhouse!$AV$23:$AV$34,[6]Brewhouse!$AV$36,[6]Brewhouse!$AV$38:$AV$44) -> 97.740552 | N28: 98 | R28: =B28 -> 0 | S28: =VLOOKUP($B28,$R$3:$X$9,2,FALSE) -> #N/A | T28: =VLOOKUP($B28,$R$3:$X$9,3,FALSE) -> #N/A | U28: =VLOOKUP($B28,$R$3:$X$9,4,FALSE) -> #N/A | V28: =VLOOKUP($B28,$R$3:$X$9,5,FALSE) -> #N/A | W28: =VLOOKUP($B28,$R$3:$X$9,6,FALSE) -> #N/A | X28: =VLOOKUP($B28,$R$3:$X$9,7,FALSE) -> #N/A | Y28: =VLOOKUP($B28,$R$3:$Z$9,8,FALSE) -> #N/A | Z28: =VLOOKUP($B28,$R$3:$Z$9,9,FALSE) -> #N/A
I29: MAXIMALT | N29: 98 | R29: =B29 -> 0 | S29: =VLOOKUP($B29,$R$3:$X$9,2,FALSE) -> #N/A | T29: =VLOOKUP($B29,$R$3:$X$9,3,FALSE) -> #N/A | U29: =VLOOKUP($B29,$R$3:$X$9,4,FALSE) -> #N/A | V29: =VLOOKUP($B29,$R$3:$X$9,5,FALSE) -> #N/A | W29: =VLOOKUP($B29,$R$3:$X$9,6,FALSE) -> #N/A | X29: =VLOOKUP($B29,$R$3:$X$9,7,FALSE) -> #N/A | Y29: =VLOOKUP($B29,$R$3:$Z$9,8,FALSE) -> #N/A | Z29: =VLOOKUP($B29,$R$3:$Z$9,9,FALSE) -> #N/A
I30: MACKESON | M30: =AVERAGE([7]Brewhouse!$AT$4:$AT$11) -> 92.826225 | N30: 98 | R30: =B30 -> 0 | S30: =VLOOKUP($B30,$R$3:$X$9,2,FALSE) -> #N/A | T30: =VLOOKUP($B30,$R$3:$X$9,3,FALSE) -> #N/A | U30: =VLOOKUP($B30,$R$3:$X$9,4,FALSE) -> #N/A | V30: =VLOOKUP($B30,$R$3:$X$9,5,FALSE) -> #N/A | W30: =VLOOKUP($B30,$R$3:$X$9,6,FALSE) -> #N/A | X30: =VLOOKUP($B30,$R$3:$X$9,7,FALSE) -> #N/A | Y30: =VLOOKUP($B30,$R$3:$Z$9,8,FALSE) -> #N/A | Z30: =VLOOKUP($B30,$R$3:$Z$9,9,FALSE) -> #N/A
I31: STARMALT | M31: =AVERAGE([8]Brewhouse!$AY$5:$AY$14,[8]Brewhouse!$AY$16:$AY$23) -> 97.293615 | N31: 98 | R31: =B31 -> 0 | S31: =VLOOKUP($B31,$R$3:$X$9,2,FALSE) -> #N/A | T31: =VLOOKUP($B31,$R$3:$X$9,3,FALSE) -> #N/A | U31: =VLOOKUP($B31,$R$3:$X$9,4,FALSE) -> #N/A | V31: =VLOOKUP($B31,$R$3:$X$9,5,FALSE) -> #N/A | W31: =VLOOKUP($B31,$R$3:$X$9,6,FALSE) -> #N/A | X31: =VLOOKUP($B31,$R$3:$X$9,7,FALSE) -> #N/A | Y31: =VLOOKUP($B31,$R$3:$Z$9,8,FALSE) -> #N/A | Z31: =VLOOKUP($B31,$R$3:$Z$9,9,FALSE) -> #N/A
I32: HR- Pils | N32: 98 | R32: =B32 -> 0 | S32: =VLOOKUP($B32,$R$3:$X$9,2,FALSE) -> #N/A | T32: =VLOOKUP($B32,$R$3:$X$9,3,FALSE) -> #N/A | U32: =VLOOKUP($B32,$R$3:$X$9,4,FALSE) -> #N/A | V32: =VLOOKUP($B32,$R$3:$X$9,5,FALSE) -> #N/A | W32: =VLOOKUP($B32,$R$3:$X$9,6,FALSE) -> #N/A | X32: =VLOOKUP($B32,$R$3:$X$9,7,FALSE) -> #N/A | Y32: =VLOOKUP($B32,$R$3:$Z$9,8,FALSE) -> #N/A | Z32: =VLOOKUP($B32,$R$3:$Z$9,9,FALSE) -> #N/A
I33: HR- IPA | N33: 98 | R33: =B33 -> 0 | S33: =VLOOKUP($B33,$R$3:$X$9,2,FALSE) -> #N/A | T33: =VLOOKUP($B33,$R$3:$X$9,3,FALSE) -> #N/A | U33: =VLOOKUP($B33,$R$3:$X$9,4,FALSE) -> #N/A | V33: =VLOOKUP($B33,$R$3:$X$9,5,FALSE) -> #N/A | W33: =VLOOKUP($B33,$R$3:$X$9,6,FALSE) -> #N/A | X33: =VLOOKUP($B33,$R$3:$X$9,7,FALSE) -> #N/A | Y33: =VLOOKUP($B33,$R$3:$Z$9,8,FALSE) -> #N/A | Z33: =VLOOKUP($B33,$R$3:$Z$9,9,FALSE) -> #N/A
I34: HR- APA | N34: 98 | R34: =B34 -> 0 | S34: =VLOOKUP($B34,$R$3:$X$9,2,FALSE) -> #N/A | T34: =VLOOKUP($B34,$R$3:$X$9,3,FALSE) -> #N/A | U34: =VLOOKUP($B34,$R$3:$X$9,4,FALSE) -> #N/A | V34: =VLOOKUP($B34,$R$3:$X$9,5,FALSE) -> #N/A | W34: =VLOOKUP($B34,$R$3:$X$9,6,FALSE) -> #N/A | X34: =VLOOKUP($B34,$R$3:$X$9,7,FALSE) -> #N/A | Y34: =VLOOKUP($B34,$R$3:$Z$9,8,FALSE) -> #N/A | Z34: =VLOOKUP($B34,$R$3:$Z$9,9,FALSE) -> #N/A
K35: =SUM(K25:K34) -> 7 | L35: =((L25*K25)+(L26*K26)+(L27*K27)+(L28*K28)+(L29*K29)+(K32*L32)+(L30*K30)+(L31*K31)+(L34*K34))/(K35) -> 96.929916 | M35: =AVERAGE('[9]Jan30th-31st'!$L$42,L35) -> 97.378979 | N35: 98 | R35: =B35 -> 0 | S35: =VLOOKUP($B35,$R$3:$X$9,2,FALSE) -> #N/A | T35: =VLOOKUP($B35,$R$3:$X$9,3,FALSE) -> #N/A | U35: =VLOOKUP($B35,$R$3:$X$9,4,FALSE) -> #N/A | V35: =VLOOKUP($B35,$R$3:$X$9,5,FALSE) -> #N/A | W35: =VLOOKUP($B35,$R$3:$X$9,6,FALSE) -> #N/A | X35: =VLOOKUP($B35,$R$3:$X$9,7,FALSE) -> #N/A | Y35: =VLOOKUP($B35,$R$3:$Z$9,8,FALSE) -> #N/A | Z35: =VLOOKUP($B35,$R$3:$Z$9,9,FALSE) -> #N/A
R36: =B36 -> 0 | S36: =VLOOKUP($B36,$R$3:$X$9,2,FALSE) -> #N/A | T36: =VLOOKUP($B36,$R$3:$X$9,3,FALSE) -> #N/A | U36: =VLOOKUP($B36,$R$3:$X$9,4,FALSE) -> #N/A | V36: =VLOOKUP($B36,$R$3:$X$9,5,FALSE) -> #N/A | W36: =VLOOKUP($B36,$R$3:$X$9,6,FALSE) -> #N/A | X36: =VLOOKUP($B36,$R$3:$X$9,7,FALSE) -> #N/A | Y36: =VLOOKUP($B36,$R$3:$Z$9,8,FALSE) -> #N/A | Z36: =VLOOKUP($B36,$R$3:$Z$9,9,FALSE) -> #N/A
J37: Daily Brewing Plan
J38: Brand | K38: Brews Achieved | L38: Average Brews per day
J39: CARIB | L39: MTD | M39: YTD | N39: TARGET
J40: STAG | L40: =AVERAGE(K49,'Mar 1st'!K55) -> 5 | M40: =AVERAGE('[9]Jan30th-31st'!$L$47,L40,'[10]Feb 26th '!$L$39) -> 5.7289855 | N40: 9.2
...

Sheet Mar 3rd
S1: P.G. | U1: Hot Time | W1: Process Time | Y1: Cooling Time
B2: Brewing Department Daily Process Loss Report | S2: Lower | T2: Upper | U2: Lower | V2: Upper | W2: Lower | X2: Upper | Y2: Lower | Z2: Upper
R3: CARIB | S3: 11.6 | T3: 12 | U3: 0 | V3: 0.11805556 | W3: 0.22569444 | X3: 0.26388889 | Y3: 0 | Z3: 60 | AB3: HR- PISNER
B4: Date: | C4: 46085 | J4: LOT WORT COLOUR: | M4: Filter Sheets (Target 20 days) | R4: STAG | S4: 11.6 | T4: 12 | U4: 0 | V4: 0.11805556 | W4: 0.22569444 | X4: 0.26388889 | Y4: 0 | Z4: 60
M5: Double | N5: Single | R5: GUINNESS | S5: 17 | T5: 17.5 | U5: 0 | V5: 0.10763889 | W5: 0.24652778 | X5: 0.28472222 | Y5: 0 | Z5: 60
J6: MALT LOT: Lot #13 | L6: Sheet Day | R6: MACKESON | S6: 13.3 | T6: 13.5 | U6: 0 | V6: 0.12905093 | W6: 0.27430556 | X6: 0.30208333 | Y6: 0
R7: STARMALT | S7: 17 | T7: 17.4 | U7: 0 | V7: 0.13605324 | W7: 0.27430556 | X7: 0.30902778 | Y7: 0 | Z7: 85
B8: Brand | C8: Brew no. | D8: Kett. Hls | E8: Wort | F8: Cool Time(Mins) | G8: Cast. P.G. (Lab Result) | H8: Cast P.G. (Cellar Operator)-gravity | I8: Extr. Rec (77.9%) | J8: Theor. Extr. (77.5%) | K8: Boil Off /Vol. (4-6%) | L8: Boil Time | M8: Total Hot | N8: Brewing Time | O8: Operator | R8: Hurricane Reef | S8: 16.6 | T8: 17 | U8: 0 | V8: 0.12905093 | W8: 0.27430556 | X8: 0.30208333 | Y8: 0
E9: Meter (Hls) | F9: Target(< 60Mins) | M9: Time | R9: VITAMALT | S9: 14.2 | T9: 14.6 | U9: 0 | V9: 0.13905093 | W9: 0.26041667 | X9: 0.29513889 | Y9: 0 | Z9: 75
B10: GUINNESS | C10: =[5]Brewhouse!$A37 -> GU020 | D10: =[5]Brewhouse!$AF37 -> 50.9 | E10: =[5]Brewhouse!$AI37 -> 50.4 | F10: =[5]Brewhouse!$V37 -> 60 | G10: =[5]Brewhouse!$AG37 -> 17.5 | I10: =[5]Brewhouse!$AU37 -> 96.879053 | J10: =[5]Brewhouse!$AV37 -> 97.191656 | K10: =[5]Brewhouse!$R37 -> 12.107143 | L10: =[5]Brewhouse!$O37 -> 59 | M10: =[5]Brewhouse!$U37-[5]Brewhouse!$T37 -> 0.12083333 | N10: =[5]Brewhouse!$Z37 -> 0.28055556 | O10: =[5]Brewhouse!$AW37 -> R. Regis | R10: =B10 -> GUINNESS | S10: =VLOOKUP($B10,$R$3:$X$9,2,FALSE) -> 17 | T10: =VLOOKUP($B10,$R$3:$X$9,3,FALSE) -> 17.5 | U10: =VLOOKUP($B10,$R$3:$X$9,4,FALSE) -> 0 | V10: =VLOOKUP($B10,$R$3:$X$9,5,FALSE) -> 0.10763889 | W10: =VLOOKUP($B10,$R$3:$X$9,6,FALSE) -> 0.24652778 | X10: =VLOOKUP($B10,$R$3:$X$9,7,FALSE) -> 0.28472222 | Y10: =VLOOKUP($B10,$R$3:$Z$9,8,FALSE) -> 0 | Z10: =VLOOKUP($B10,$R$3:$Z$9,9,FALSE) -> 60
B11: GUINNESS | C11: =[5]Brewhouse!$A38 -> GU021 | D11: =[5]Brewhouse!$AF38 -> 51.5 | E11: =[5]Brewhouse!$AI38 -> 50 | F11: =[5]Brewhouse!$V38 -> 67 | G11: =[5]Brewhouse!$AG38 -> 17.4 | I11: =[5]Brewhouse!$AU38 -> 95.46915 | J11: =[5]Brewhouse!$AV38 -> 95.777257 | K11: =[5]Brewhouse!$R38 -> 11.194296 | L11: =[5]Brewhouse!$O38 -> 58 | M11: =[5]Brewhouse!$U38-[5]Brewhouse!$T38 -> 0.12291667 | N11: =[5]Brewhouse!$Z38 -> 0.26875 | O11: =[5]Brewhouse!$AW38 -> R. Regis | R11: =B11 -> GUINNESS | S11: =VLOOKUP($B11,$R$3:$X$9,2,FALSE) -> 17 | T11: =VLOOKUP($B11,$R$3:$X$9,3,FALSE) -> 17.5 | U11: =VLOOKUP($B11,$R$3:$X$9,4,FALSE) -> 0 | V11: =VLOOKUP($B11,$R$3:$X$9,5,FALSE) -> 0.10763889 | W11: =VLOOKUP($B11,$R$3:$X$9,6,FALSE) -> 0.24652778 | X11: =VLOOKUP($B11,$R$3:$X$9,7,FALSE) -> 0.28472222 | Y11: =VLOOKUP($B11,$R$3:$Z$9,8,FALSE) -> 0 | Z11: =VLOOKUP($B11,$R$3:$Z$9,9,FALSE) -> 60
B12: GUINNESS | C12: =[5]Brewhouse!$A39 -> GU022 | D12: =[5]Brewhouse!$AF39 -> 50 | E12: =[5]Brewhouse!$AI39 -> 50.3 | F12: =[5]Brewhouse!$V39 -> 63 | G12: =[5]Brewhouse!$AG39 -> 17.2 | I12: =[5]Brewhouse!$AU39 -> 94.854987 | J12: =[5]Brewhouse!$AV39 -> 95.161113 | K12: =[5]Brewhouse!$R39 -> 14.581105 | L12: =[5]Brewhouse!$O39 -> 60 | M12: =[5]Brewhouse!$U39-[5]Brewhouse!$T39 -> 0.11319444 | N12: =[5]Brewhouse!$Z39 -> 0.30277778 | O12: =[5]Brewhouse!$AW39 -> D. Gomaz | R12: =B12 -> GUINNESS | S12: =VLOOKUP($B12,$R$3:$X$9,2,FALSE) -> 17 | T12: =VLOOKUP($B12,$R$3:$X$9,3,FALSE) -> 17.5 | U12: =VLOOKUP($B12,$R$3:$X$9,4,FALSE) -> 0 | V12: =VLOOKUP($B12,$R$3:$X$9,5,FALSE) -> 0.10763889 | W12: =VLOOKUP($B12,$R$3:$X$9,6,FALSE) -> 0.24652778 | X12: =VLOOKUP($B12,$R$3:$X$9,7,FALSE) -> 0.28472222 | Y12: =VLOOKUP($B12,$R$3:$Z$9,8,FALSE) -> 0 | Z12: =VLOOKUP($B12,$R$3:$Z$9,9,FALSE) -> 60
B13: GUINNESS | C13: =[5]Brewhouse!$A40 -> GU023 | D13: =[5]Brewhouse!$AF40 -> 50.9 | E13: =[5]Brewhouse!$AI40 -> 50.1 | F13: =[5]Brewhouse!$V40 -> 57 | G13: =[5]Brewhouse!$AG40 -> 17.5 | I13: =[5]Brewhouse!$AU40 -> 96.379391 | J13: =[5]Brewhouse!$AV40 -> 96.690327 | K13: =[5]Brewhouse!$R40 -> 11.729055 | L13: =[5]Brewhouse!$O40 -> 59 | M13: =[5]Brewhouse!$U40-[5]Brewhouse!$T40 -> 0.12777778 | N13: =[5]Brewhouse!$Z40 -> 0.26944444 | O13: =[5]Brewhouse!$AW40 -> D. Gomaz | R13: =B13 -> GUINNESS | S13: =VLOOKUP($B13,$R$3:$X$9,2,FALSE) -> 17 | T13: =VLOOKUP($B13,$R$3:$X$9,3,FALSE) -> 17.5 | U13: =VLOOKUP($B13,$R$3:$X$9,4,FALSE) -> 0 | V13: =VLOOKUP($B13,$R$3:$X$9,5,FALSE) -> 0.10763889 | W13: =VLOOKUP($B13,$R$3:$X$9,6,FALSE) -> 0.24652778 | X13: =VLOOKUP($B13,$R$3:$X$9,7,FALSE) -> 0.28472222 | Y13: =VLOOKUP($B13,$R$3:$Z$9,8,FALSE) -> 0 | Z13: =VLOOKUP($B13,$R$3:$Z$9,9,FALSE) -> 60
B14: GUINNESS | C14: =[5]Brewhouse!$A41 -> GU024 | D14: =[5]Brewhouse!$AF41 -> 51 | E14: =[5]Brewhouse!$AI41 -> 50.1 | F14: =[5]Brewhouse!$V41 -> 59 | G14: =[5]Brewhouse!$AG41 -> 17.6 | I14: =[5]Brewhouse!$AU41 -> 96.151545 | J14: =[5]Brewhouse!$AV41 -> 96.46234 | K14: =[5]Brewhouse!$R41 -> 13.892857 | L14: =[5]Brewhouse!$O41 -> 59 | M14: =[5]Brewhouse!$U41-[5]Brewhouse!$T41 -> 0.11666667 | N14: =[5]Brewhouse!$Z41 -> 0.27986111 | O14: =[5]Brewhouse!$AW41 -> K. Benjamin | R14: =B14 -> GUINNESS | S14: =VLOOKUP($B14,$R$3:$X$9,2,FALSE) -> 17 | T14: =VLOOKUP($B14,$R$3:$X$9,3,FALSE) -> 17.5 | U14: =VLOOKUP($B14,$R$3:$X$9,4,FALSE) -> 0 | V14: =VLOOKUP($B14,$R$3:$X$9,5,FALSE) -> 0.10763889 | W14: =VLOOKUP($B14,$R$3:$X$9,6,FALSE) -> 0.24652778 | X14: =VLOOKUP($B14,$R$3:$X$9,7,FALSE) -> 0.28472222 | Y14: =VLOOKUP($B14,$R$3:$Z$9,8,FALSE) -> 0 | Z14: =VLOOKUP($B14,$R$3:$Z$9,9,FALSE) -> 60
R15: =B15 -> 0 | S15: =VLOOKUP($B15,$R$3:$X$9,2,FALSE) -> #N/A | T15: =VLOOKUP($B15,$R$3:$X$9,3,FALSE) -> #N/A | U15: =VLOOKUP($B15,$R$3:$X$9,4,FALSE) -> #N/A | V15: =VLOOKUP($B15,$R$3:$X$9,5,FALSE) -> #N/A | W15: =VLOOKUP($B15,$R$3:$X$9,6,FALSE) -> #N/A | X15: =VLOOKUP($B15,$R$3:$X$9,7,FALSE) -> #N/A | Y15: =VLOOKUP($B15,$R$3:$Z$9,8,FALSE) -> #N/A | Z15: =VLOOKUP($B15,$R$3:$Z$9,9,FALSE) -> #N/A
R16: =B16 -> 0 | S16: =VLOOKUP($B16,$R$3:$X$9,2,FALSE) -> #N/A | T16: =VLOOKUP($B16,$R$3:$X$9,3,FALSE) -> #N/A | U16: =VLOOKUP($B16,$R$3:$X$9,4,FALSE) -> #N/A | V16: =VLOOKUP($B16,$R$3:$X$9,5,FALSE) -> #N/A | W16: =VLOOKUP($B16,$R$3:$X$9,6,FALSE) -> #N/A | X16: =VLOOKUP($B16,$R$3:$X$9,7,FALSE) -> #N/A | Y16: =VLOOKUP($B16,$R$3:$Z$9,8,FALSE) -> #N/A | Z16: =VLOOKUP($B16,$R$3:$Z$9,9,FALSE) -> #N/A
B17: CARIB | C17: =[4]Brewhouse!$A198 -> CA155 | D17: =[4]Brewhouse!$AF198 -> 48.6 | E17: =[4]Brewhouse!$AI198 -> 48.9 | F17: =[4]Brewhouse!$V198 -> 56 | G17: =[4]Brewhouse!AG198 -> 11.6 | I17: =[4]Brewhouse!$AU198 -> 96.242072 | J17: =[4]Brewhouse!$AV198 -> 96.597066 | K17: =[4]Brewhouse!$Q198 -> 11.169811 | L17: =[4]Brewhouse!$P198 -> 60 | M17: =[4]Brewhouse!$U198-[4]Brewhouse!$T198 -> 0.11041667 | N17: =[4]Brewhouse!$Z198 -> 0.25972222 | O17: =[4]Brewhouse!$AX198 -> K. Benjamin | R17: =B17 -> CARIB | S17: =VLOOKUP($B17,$R$3:$X$9,2,FALSE) -> 11.6 | T17: =VLOOKUP($B17,$R$3:$X$9,3,FALSE) -> 12 | U17: =VLOOKUP($B17,$R$3:$X$9,4,FALSE) -> 0 | V17: =VLOOKUP($B17,$R$3:$X$9,5,FALSE) -> 0.11805556 | W17: =VLOOKUP($B17,$R$3:$X$9,6,FALSE) -> 0.22569444 | X17: =VLOOKUP($B17,$R$3:$X$9,7,FALSE) -> 0.26388889 | Y17: =VLOOKUP($B17,$R$3:$Z$9,8,FALSE) -> 0 | Z17: =VLOOKUP($B17,$R$3:$Z$9,9,FALSE) -> 60
B18: CARIB | C18: =[4]Brewhouse!$A199 -> CA156 | D18: =[4]Brewhouse!$AF199 -> 49.8 | E18: =[4]Brewhouse!$AI199 -> 50.3 | F18: =[4]Brewhouse!$V199 -> 61 | G18: =[4]Brewhouse!AG199 -> 11.6 | I18: =[4]Brewhouse!$AU199 -> 98.872547 | J18: =[4]Brewhouse!$AV199 -> 99.237275 | K18: =[4]Brewhouse!$Q199 -> 11.3371 | L18: =[4]Brewhouse!$P199 -> 60 | M18: =[4]Brewhouse!$U199-[4]Brewhouse!$T199 -> 0.11180556 | N18: =[4]Brewhouse!$Z199 -> 0.26041667 | O18: =[4]Brewhouse!$AX199 -> R. Regis | R18: =B18 -> CARIB | S18: =VLOOKUP($B18,$R$3:$X$9,2,FALSE) -> 11.6 | T18: =VLOOKUP($B18,$R$3:$X$9,3,FALSE) -> 12 | U18: =VLOOKUP($B18,$R$3:$X$9,4,FALSE) -> 0 | V18: =VLOOKUP($B18,$R$3:$X$9,5,FALSE) -> 0.11805556 | W18: =VLOOKUP($B18,$R$3:$X$9,6,FALSE) -> 0.22569444 | X18: =VLOOKUP($B18,$R$3:$X$9,7,FALSE) -> 0.26388889 | Y18: =VLOOKUP($B18,$R$3:$Z$9,8,FALSE) -> 0 | Z18: =VLOOKUP($B18,$R$3:$Z$9,9,FALSE) -> 60
B19: CARIB | C19: =[4]Brewhouse!$A200 -> CA157 | D19: =[4]Brewhouse!$AF200 -> 49.2 | E19: =[4]Brewhouse!$AI200 -> 49.8 | F19: =[4]Brewhouse!$V200 -> 51 | G19: =[4]Brewhouse!AG200 -> 12 | I19: =[4]Brewhouse!$AU200 -> 101.57164 | J19: =[4]Brewhouse!$AV200 -> 101.94629 | K19: =[4]Brewhouse!$Q200 -> 10.207156 | L19: =[4]Brewhouse!$P200 -> 60 | M19: =[4]Brewhouse!$U200-[4]Brewhouse!$T200 -> 0.1125 | N19: =[4]Brewhouse!$Z200 -> 0.26458333 | O19: =[4]Brewhouse!$AX200 -> R. Regis | R19: =B19 -> CARIB | S19: =VLOOKUP($B19,$R$3:$X$9,2,FALSE) -> 11.6 | T19: =VLOOKUP($B19,$R$3:$X$9,3,FALSE) -> 12 | U19: =VLOOKUP($B19,$R$3:$X$9,4,FALSE) -> 0 | V19: =VLOOKUP($B19,$R$3:$X$9,5,FALSE) -> 0.11805556 | W19: =VLOOKUP($B19,$R$3:$X$9,6,FALSE) -> 0.22569444 | X19: =VLOOKUP($B19,$R$3:$X$9,7,FALSE) -> 0.26388889 | Y19: =VLOOKUP($B19,$R$3:$Z$9,8,FALSE) -> 0 | Z19: =VLOOKUP($B19,$R$3:$Z$9,9,FALSE) -> 60
R20: =B20 -> 0 | S20: =VLOOKUP($B20,$R$3:$X$9,2,FALSE) -> #N/A | T20: =VLOOKUP($B20,$R$3:$X$9,3,FALSE) -> #N/A | U20: =VLOOKUP($B20,$R$3:$X$9,4,FALSE) -> #N/A | V20: =VLOOKUP($B20,$R$3:$X$9,5,FALSE) -> #N/A | W20: =VLOOKUP($B20,$R$3:$X$9,6,FALSE) -> #N/A | X20: =VLOOKUP($B20,$R$3:$X$9,7,FALSE) -> #N/A | Y20: =VLOOKUP($B20,$R$3:$Z$9,8,FALSE) -> #N/A | Z20: =VLOOKUP($B20,$R$3:$Z$9,9,FALSE) -> #N/A
R21: =B21 -> 0 | S21: =VLOOKUP($B21,$R$3:$X$9,2,FALSE) -> #N/A | T21: =VLOOKUP($B21,$R$3:$X$9,3,FALSE) -> #N/A | U21: =VLOOKUP($B21,$R$3:$X$9,4,FALSE) -> #N/A | V21: =VLOOKUP($B21,$R$3:$X$9,5,FALSE) -> #N/A | W21: =VLOOKUP($B21,$R$3:$X$9,6,FALSE) -> #N/A | X21: =VLOOKUP($B21,$R$3:$X$9,7,FALSE) -> #N/A | Y21: =VLOOKUP($B21,$R$3:$Z$9,8,FALSE) -> #N/A | Z21: =VLOOKUP($B21,$R$3:$Z$9,9,FALSE) -> #N/A
R22: =B22 -> 0 | S22: =VLOOKUP($B22,$R$3:$X$9,2,FALSE) -> #N/A | T22: =VLOOKUP($B22,$R$3:$X$9,3,FALSE) -> #N/A | U22: =VLOOKUP($B22,$R$3:$X$9,4,FALSE) -> #N/A | V22: =VLOOKUP($B22,$R$3:$X$9,5,FALSE) -> #N/A | W22: =VLOOKUP($B22,$R$3:$X$9,6,FALSE) -> #N/A | X22: =VLOOKUP($B22,$R$3:$X$9,7,FALSE) -> #N/A | Y22: =VLOOKUP($B22,$R$3:$Z$9,8,FALSE) -> #N/A | Z22: =VLOOKUP($B22,$R$3:$Z$9,9,FALSE) -> #N/A
R23: =B23 -> 0 | S23: =VLOOKUP($B23,$R$3:$X$9,2,FALSE) -> #N/A | T23: =VLOOKUP($B23,$R$3:$X$9,3,FALSE) -> #N/A | U23: =VLOOKUP($B23,$R$3:$X$9,4,FALSE) -> #N/A | V23: =VLOOKUP($B23,$R$3:$X$9,5,FALSE) -> #N/A | W23: =VLOOKUP($B23,$R$3:$X$9,6,FALSE) -> #N/A | X23: =VLOOKUP($B23,$R$3:$X$9,7,FALSE) -> #N/A | Y23: =VLOOKUP($B23,$R$3:$Z$9,8,FALSE) -> #N/A | Z23: =VLOOKUP($B23,$R$3:$Z$9,9,FALSE) -> #N/A
B24: BRAND | D24: BBT P.G./ O.G | I24: Brand | K24: MTD No. of Brews | L24: MTD | M24: YTD | N24: Target | R24: =B24 -> BRAND | S24: =VLOOKUP($B24,$R$3:$X$9,2,FALSE) -> #N/A | T24: =VLOOKUP($B24,$R$3:$X$9,3,FALSE) -> #N/A | U24: =VLOOKUP($B24,$R$3:$X$9,4,FALSE) -> #N/A | V24: =VLOOKUP($B24,$R$3:$X$9,5,FALSE) -> #N/A | W24: =VLOOKUP($B24,$R$3:$X$9,6,FALSE) -> #N/A | X24: =VLOOKUP($B24,$R$3:$X$9,7,FALSE) -> #N/A | Y24: =VLOOKUP($B24,$R$3:$Z$9,8,FALSE) -> #N/A | Z24: =VLOOKUP($B24,$R$3:$Z$9,9,FALSE) -> #N/A
I25: CARIB | J25: =AVERAGE(I17:I19) -> 98.89542 | K25: =COUNTA([4]Brewhouse!$A$198:$A$200) -> 3 | L25: =AVERAGE([4]Brewhouse!$AU$198:$AU$200) -> 98.89542 | M25: =AVERAGE([4]Brewhouse!$AU$42:$AU$123,[4]Brewhouse!$AU$125:$AU$188,[4]Brewhouse!$AU$198:$AU$200) -> 97.622505 | N25: 98 | R25: =B25 -> 0 | S25: =VLOOKUP($B25,$R$3:$X$9,2,FALSE) -> #N/A | T25: =VLOOKUP($B25,$R$3:$X$9,3,FALSE) -> #N/A | U25: =VLOOKUP($B25,$R$3:$X$9,4,FALSE) -> #N/A | V25: =VLOOKUP($B25,$R$3:$X$9,5,FALSE) -> #N/A | W25: =VLOOKUP($B25,$R$3:$X$9,6,FALSE) -> #N/A | X25: =VLOOKUP($B25,$R$3:$X$9,7,FALSE) -> #N/A | Y25: =VLOOKUP($B25,$R$3:$Z$9,8,FALSE) -> #N/A | Z25: =VLOOKUP($B25,$R$3:$Z$9,9,FALSE) -> #N/A
I26: STAG | M26: =AVERAGE([3]Brewhouse!$AS$52:$AS$81,[3]Brewhouse!$AS$83:$AS$124) -> 98.316611 | N26: 98 | R26: =B26 -> 0 | S26: =VLOOKUP($B26,$R$3:$X$9,2,FALSE) -> #N/A | T26: =VLOOKUP($B26,$R$3:$X$9,3,FALSE) -> #N/A | U26: =VLOOKUP($B26,$R$3:$X$9,4,FALSE) -> #N/A | V26: =VLOOKUP($B26,$R$3:$X$9,5,FALSE) -> #N/A | W26: =VLOOKUP($B26,$R$3:$X$9,6,FALSE) -> #N/A | X26: =VLOOKUP($B26,$R$3:$X$9,7,FALSE) -> #N/A | Y26: =VLOOKUP($B26,$R$3:$Z$9,8,FALSE) -> #N/A | Z26: =VLOOKUP($B26,$R$3:$Z$9,9,FALSE) -> #N/A
I27: GUINNESS | J27: =AVERAGE(I10:I14) -> 95.946825 | K27: =COUNTA([5]Brewhouse!$A$34:$A$41) -> 8 | L27: =AVERAGE([5]Brewhouse!$AU$34:$AU$41) -> 94.762611 | M27: =AVERAGE([5]Brewhouse!$AU$16:$AU$23,[5]Brewhouse!$AU$25:$AU$32,[5]Brewhouse!$AU$34:$AU$41) -> 97.131454 | N27: 98 | R27: =B27 -> 0 | S27: =VLOOKUP($B27,$R$3:$X$9,2,FALSE) -> #N/A | T27: =VLOOKUP($B27,$R$3:$X$9,3,FALSE) -> #N/A | U27: =VLOOKUP($B27,$R$3:$X$9,4,FALSE) -> #N/A | V27: =VLOOKUP($B27,$R$3:$X$9,5,FALSE) -> #N/A | W27: =VLOOKUP($B27,$R$3:$X$9,6,FALSE) -> #N/A | X27: =VLOOKUP($B27,$R$3:$X$9,7,FALSE) -> #N/A | Y27: =VLOOKUP($B27,$R$3:$Z$9,8,FALSE) -> #N/A | Z27: =VLOOKUP($B27,$R$3:$Z$9,9,FALSE) -> #N/A
I28: VITAMALT | K28: =COUNTA([6]Brewhouse!$A$38:$A$44) -> 7 | L28: =AVERAGE([6]Brewhouse!$AV$38:$AV$44) -> 96.929916 | M28: =AVERAGE([6]Brewhouse!$AV$23:$AV$34,[6]Brewhouse!$AV$36,[6]Brewhouse!$AV$38:$AV$44) -> 97.740552 | N28: 98 | R28: =B28 -> 0 | S28: =VLOOKUP($B28,$R$3:$X$9,2,FALSE) -> #N/A | T28: =VLOOKUP($B28,$R$3:$X$9,3,FALSE) -> #N/A | U28: =VLOOKUP($B28,$R$3:$X$9,4,FALSE) -> #N/A | V28: =VLOOKUP($B28,$R$3:$X$9,5,FALSE) -> #N/A | W28: =VLOOKUP($B28,$R$3:$X$9,6,FALSE) -> #N/A | X28: =VLOOKUP($B28,$R$3:$X$9,7,FALSE) -> #N/A | Y28: =VLOOKUP($B28,$R$3:$Z$9,8,FALSE) -> #N/A | Z28: =VLOOKUP($B28,$R$3:$Z$9,9,FALSE) -> #N/A
I29: MAXIMALT | N29: 98 | R29: =B29 -> 0 | S29: =VLOOKUP($B29,$R$3:$X$9,2,FALSE) -> #N/A | T29: =VLOOKUP($B29,$R$3:$X$9,3,FALSE) -> #N/A | U29: =VLOOKUP($B29,$R$3:$X$9,4,FALSE) -> #N/A | V29: =VLOOKUP($B29,$R$3:$X$9,5,FALSE) -> #N/A | W29: =VLOOKUP($B29,$R$3:$X$9,6,FALSE) -> #N/A | X29: =VLOOKUP($B29,$R$3:$X$9,7,FALSE) -> #N/A | Y29: =VLOOKUP($B29,$R$3:$Z$9,8,FALSE) -> #N/A | Z29: =VLOOKUP($B29,$R$3:$Z$9,9,FALSE) -> #N/A
I30: MACKESON | M30: =AVERAGE([7]Brewhouse!$AT$4:$AT$11) -> 92.826225 | N30: 98 | R30: =B30 -> 0 | S30: =VLOOKUP($B30,$R$3:$X$9,2,FALSE) -> #N/A | T30: =VLOOKUP($B30,$R$3:$X$9,3,FALSE) -> #N/A | U30: =VLOOKUP($B30,$R$3:$X$9,4,FALSE) -> #N/A | V30: =VLOOKUP($B30,$R$3:$X$9,5,FALSE) -> #N/A | W30: =VLOOKUP($B30,$R$3:$X$9,6,FALSE) -> #N/A | X30: =VLOOKUP($B30,$R$3:$X$9,7,FALSE) -> #N/A | Y30: =VLOOKUP($B30,$R$3:$Z$9,8,FALSE) -> #N/A | Z30: =VLOOKUP($B30,$R$3:$Z$9,9,FALSE) -> #N/A
I31: STARMALT | M31: =AVERAGE([8]Brewhouse!$AY$5:$AY$14,[8]Brewhouse!$AY$16:$AY$23) -> 97.293615 | N31: 98 | R31: =B31 -> 0 | S31: =VLOOKUP($B31,$R$3:$X$9,2,FALSE) -> #N/A | T31: =VLOOKUP($B31,$R$3:$X$9,3,FALSE) -> #N/A | U31: =VLOOKUP($B31,$R$3:$X$9,4,FALSE) -> #N/A | V31: =VLOOKUP($B31,$R$3:$X$9,5,FALSE) -> #N/A | W31: =VLOOKUP($B31,$R$3:$X$9,6,FALSE) -> #N/A | X31: =VLOOKUP($B31,$R$3:$X$9,7,FALSE) -> #N/A | Y31: =VLOOKUP($B31,$R$3:$Z$9,8,FALSE) -> #N/A | Z31: =VLOOKUP($B31,$R$3:$Z$9,9,FALSE) -> #N/A
I32: HR- Pils | N32: 98 | R32: =B32 -> 0 | S32: =VLOOKUP($B32,$R$3:$X$9,2,FALSE) -> #N/A | T32: =VLOOKUP($B32,$R$3:$X$9,3,FALSE) -> #N/A | U32: =VLOOKUP($B32,$R$3:$X$9,4,FALSE) -> #N/A | V32: =VLOOKUP($B32,$R$3:$X$9,5,FALSE) -> #N/A | W32: =VLOOKUP($B32,$R$3:$X$9,6,FALSE) -> #N/A | X32: =VLOOKUP($B32,$R$3:$X$9,7,FALSE) -> #N/A | Y32: =VLOOKUP($B32,$R$3:$Z$9,8,FALSE) -> #N/A | Z32: =VLOOKUP($B32,$R$3:$Z$9,9,FALSE) -> #N/A
