Workbook

Sheet Entries March.'25
B1: ENTRIES FOR DAILY CONS. MONITOR | O1: =B1 -> ENTRIES FOR DAILY CONS. MONITOR
C2: old | F2: old | O2: Service 227.3 cubic meters (2273 Hls)Filtered 189.3 cubic meters(1893 Hls)
D3: FUEL | J3: ELECT. | L3: CO2 | O3: WATER | AG3: CO2 Scrubber (m3) | AH3: Supply to Washdown Area (m3) | AI3: Supply to RUs (m3) | AJ3: Steam Mass Flow Meter | AK3: CO2 TANKS' READING
B4: Boilers tot. | C4: Boiler 1 | D4: Gen. meter | E4: Tank level | F4: Boiler 1 | G4: Boiler 2 | H4: Gen | I4: Meter1 | J4: Meter 2 | K4: Gen Meter | L4: Collection | M4: Consumption | N4: Consumption (Filler) (kg) | O4: Nawasa Meter (m3) | P4: Annandale Supply (m3) | Q4: Service Supply to Plant (m3) | R4: Cellars/Filtration (m3) | S4: Brewhouse Meter (m3) | T4: Cellars/Process Areas (m3) | U4: Pasteuriser (m3) | V4: Water Plant-Nawasa Annadale (m3) | W4: Water Plant-Well # 1 (m3) | X4: CIP Process | Y4: Bottle Washer | Z4: Boiler | AA4: Permeate #1 | AB4: Permeate #2 | AC4: Bottle Filler (m3) | AD4: RO # 1 Totaliser (m3) | AE4: RO # 2 Totaliser (m3) | AF4: Recovered Water (m3) | AK4: (Kg.) | AL4: ` | AM4: (Lbs.) | AN4: (Kg.)
A5: DATE | B5: (liters) | C5: (liters) | D5: (Imp. gals) | E5: (inches) | F5: Hrs | G5: Hrs | H5: Hrs. | I5: (Kwhr) | J5: (Kwhr) | K5: (Kwhr) | L5: Meter (kg) | M5: Meter (kg) | X5: (m3) | Y5: (m3) | Z5: (m3) | AK5: Tank "A" | AL5: Tank "B" | AM5: Mobile Tanker | AN5: Inside Tank
A6: -
A7: 1 | B7: 7222980 | E7: 70 | F7: 2790.8 | G7: 68209 | I7: 312699 | J7: 886109 | K7: 466400 | N7: 709.64 | O7: 170538 | P7: 8010 | Q7: 889883 | S7: 35099 | U7: 20636 | V7: 1285230 | X7: 31073 | Y7: 29173 | Z7: 5490 | AA7: 97122 | AC7: 39340 | AD7: 258781 | AJ7: 7266613
A8: 2 | B8: 7223390 | E8: 70 | F8: 2797.3 | G8: 68209 | I8: 315005 | J8: 888285 | K8: 466400 | N8: 709.64 | O8: 170538 | P8: 8196 | Q8: 889957 | S8: 35100 | U8: 20636 | V8: 1285426 | X8: 31073 | Y8: 29209 | Z8: 5496 | AA8: 97122 | AC8: 39340 | AD8: 258781 | AJ8: 7266613
A9: 3 | B9: 7223930 | E9: 70 | F9: 2800.2 | G9: 68209 | I9: 317175 | J9: 890331 | K9: 466400 | N9: 709.64 | O9: 170538 | P9: 8196 | Q9: 889988 | S9: 35100 | U9: 20636 | V9: 1285426 | X9: 31073 | Y9: 29209 | Z9: 5496 | AA9: 97122 | AC9: 39340 | AD9: 258781 | AJ9: 7266613
A10: 4 | B10: 7226410 | E10: 70 | F10: 2818.2 | G10: 68209 | I10: 321262 | J10: 894192 | K10: 466400 | N10: 709.64 | O10: 170917 | P10: 8208 | Q10: 890095 | S10: 35287 | U10: 20636 | V10: 1285438 | X10: 31094 | Y10: 29272 | Z10: 5505 | AA10: 97122 | AC10: 39342 | AD10: 258893 | AJ10: 7266766.6
A11: 5 | B11: 7229680 | E11: 70 | F11: 2840.5 | G11: 68209 | I11: 325655 | J11: 898346 | K11: 466400 | N11: 851.51 | O11: 171359 | P11: 8208 | Q11: 890327 | S11: 35499 | U11: 20644 | V11: 1285439 | X11: 31139 | Y11: 29355 | Z11: 5523 | AA11: 97122 | AC11: 39364 | AD11: 258947 | AJ11: 7266891.1
A12: 6 | B12: 7232720 | E12: 70 | F12: 2861.3 | G12: 68209 | I12: 329893 | J12: 902349 | K12: 466400 | N12: 880.47 | O12: 171795 | P12: 8208 | Q12: 890533 | S12: 35672 | U12: 20644 | V12: 1285439 | X12: 31209 | Y12: 29415 | Z12: 5538 | AA12: 97122 | AC12: 39379 | AD12: 258993 | AJ12: 7266901.5
A13: 7 | B13: 7235440 | E13: 70 | F13: 2881.5 | G13: 68209 | I13: 334041 | J13: 906267 | K13: 466400 | N13: 915.52 | O13: 172053 | P13: 8208 | Q13: 890734 | S13: 35865 | U13: 20644 | V13: 1285439 | X13: 31294 | Y13: 29473 | Z13: 5556 | AA13: 97122 | AC13: 39402 | AD13: 259023 | AJ13: 7267605.2
A14: 8 | B14: 7237820 | E14: 70 | F14: 2899 | G14: 68209 | I14: 337821 | J14: 909835 | K14: 466400 | N14: 953.19 | O14: 172294 | P14: 8328 | Q14: 890888 | S14: 36081 | U14: 20644 | V14: 1285569 | X14: 31315 | Y14: 29521 | Z14: 5556 | AA14: 97122 | AC14: 39415 | AD14: 259023 | AJ14: 7267940.9
A15: 9 | B15: 7238820 | E15: 70 | F15: 2907.6 | G15: 68209 | I15: 340200 | J15: 912080 | K15: 466400 | N15: 958.15 | O15: 172436 | P15: 8409 | Q15: 890988 | S15: 36152 | U15: 20644 | V15: 1285651 | X15: 31329 | Y15: 29546 | Z15: 5571 | AA15: 97122 | AC15: 39415 | AD15: 259023 | AJ15: 7268276.7
A16: 10 | B16: 7238920 | E16: 70 | F16: 2908.5 | G16: 68209 | I16: 342345 | J16: 914108 | K16: 466400 | N16: 958.15 | O16: 172513 | P16: 8430 | Q16: 890998 | S16: 36152 | U16: 20644 | V16: 1285673 | X16: 31329 | Y16: 29546 | Z16: 5572 | AA16: 97122 | AC16: 39415 | AD16: 259023 | AJ16: 7268276.7
A17: 11 | B17: 7242020 | E17: 70 | F17: 2928 | G17: 68209 | I17: 346459 | J17: 917994 | K17: 466400 | N17: 978.29 | O17: 172578 | P17: 8525 | Q17: 891163 | S17: 36343 | U17: 20666 | V17: 1285825 | X17: 31388 | Y17: 29585 | Z17: 5598 | AA17: 97122 | AC17: 39429 | AD17: 259023 | AJ17: 7268280.5
A18: 12 | B18: 7245060 | E18: 70 | F18: 2949.9 | G18: 68209 | I18: 350745 | J18: 922046 | K18: 466400 | N18: 1003.78 | O18: 172826 | P18: 8643 | Q18: 891285 | S18: 36491 | U18: 20669 | V18: 1285825 | X18: 31407 | Y18: 29620 | Z18: 5634 | AA18: 97122 | AC18: 39443 | AD18: 259023 | AJ18: 7268410.9
... A38: 1 | B38: 7286550 | E38: 60 | F38: 3237.2 | G38: 68209 | I38: 423002 | J38: 990124 | K38: 468000 | N38: 1443.16 | O38: 175016 | P38: 11772 | Q38: 894109 | S38: 39003 | U38: 20678 | V38: 1288667 | X38: 31994 | Y38: 30669 | Z38: 6258 | AA38: 97122 | AC38: 39679 | AD38: 259026 | AJ38: 7268541.2

Sheet Utility Analysis March. 2025
F2: GRENADA BREWERIES LIMITED
F3: UTILITY ANALYSIS
A5: MONTH: | E5: 39295
A7: DATE | B7: ELECTRICITY GRENLEC | C7: CARIB GENSET | D7: ELECTRICITY TOTAL | E7: WATER | F7: FUEL | G7: CO2 | H7: PRODUCTION - HL | M7: UTILITY RATIOS
M8: Elect | N8: Water | O8: Fuel | P8: CO2 | Q8: Comments
B9: USAGE (kwh) | C9: USAGE (kwh) | D9: USAGE (kwh) | E9: USAGE (Hl) | F9: USAGE (l) | G9: USAGE (Kg.) | H9: BREWED | I9: BOTTLED | J9: KEGS | K9: OTHER | L9: TOTAL | M9: KWH/Hl | N9: Hl/hl | O9: Litres/hl | P9: kg./Hl
A10: 1 | B10: =IF(('Entries March.''25'!I8-'Entries March.''25'!I7)+('Entries March.''25'!J8-'Entries March.''25'!J7)<1,"0",('Entries March.''25'!I8-'Entries March.''25'!I7)+('Entries March.''25'!J8-'Entries March.''25'!J7)) -> 4482 | C10: =IF('Entries March.''25'!K8-'Entries March.''25'!K7<=0,"0",'Entries March.''25'!K8-'Entries March.''25'!K7) -> 0 | D10: =B10+C10 -> 4482 | E10: ='Water '!$S7 -> -100 | F10: =IF('Entries March.''25'!B8-'Entries March.''25'!B7<1,"0",'Entries March.''25'!B8-'Entries March.''25'!B7) -> 410 | G10: ='CO2'!B7 -> 0 | H10: =+'PROD.FIG. '!F5 -> 0 | I10: =+'PROD.FIG. '!C5 -> 0 | J10: =+'PROD.FIG. '!D5 -> 0 | K10: =+'PROD.FIG. '!E5 -> 0 | M10: =IF(SUM($I10:$J10)<1,0,B10/SUM($I10:$J10)) -> 0 | N10: =IF(SUM($I10:$J10)<1,0,E10/SUM($I10:$J10)) -> 0 | O10: =IF(SUM($I10:$J10)<1,0,F10/SUM($I10:$J10)) -> 0 | P10: =IF(SUM($I10:$J10)<1,0,G10/SUM($I10:$J10)) -> 0
A11: 2 | B11: =IF(('Entries March.''25'!I9-'Entries March.''25'!I8)+('Entries March.''25'!J9-'Entries March.''25'!J8)<1,"0",('Entries March.''25'!I9-'Entries March.''25'!I8)+('Entries March.''25'!J9-'Entries March.''25'!J8)) -> 4216 | C11: =IF('Entries March.''25'!K9-'Entries March.''25'!K8<=0,"0",'Entries March.''25'!K9-'Entries March.''25'!K8) -> 0 | D11: =B11+C11 -> 4216 | E11: ='Water '!$S8 -> 0 | F11: =IF('Entries March.''25'!B9-'Entries March.''25'!B8<1,"0",'Entries March.''25'!B9-'Entries March.''25'!B8) -> 540 | G11: ='CO2'!B8 -> 0 | H11: =+'PROD.FIG. '!F6 -> 0 | I11: =+'PROD.FIG. '!C6 -> 0 | J11: =+'PROD.FIG. '!D6 -> 0 | K11: =+'PROD.FIG. '!E6 -> 0 | M11: =IF(SUM($I11:$J11)<1,0,B11/SUM($I11:$J11)) -> 0 | N11: =IF(SUM($I11:$J11)<1,0,E11/SUM($I11:$J11)) -> 0 | O11: =IF(SUM($I11:$J11)<1,0,F11/SUM($I11:$J11)) -> 0 | P11: =IF(SUM($I11:$J11)<1,0,G11/SUM($I11:$J11)) -> 0
A12: 3 | B12: =IF(('Entries March.''25'!I10-'Entries March.''25'!I9)+('Entries March.''25'!J10-'Entries March.''25'!J9)<1,"0",('Entries March.''25'!I10-'Entries March.''25'!I9)+('Entries March.''25'!J10-'Entries March.''25'!J9)) -> 7948 | C12: =IF('Entries March.''25'!K10-'Entries March.''25'!K9<=0,"0",'Entries March.''25'!K10-'Entries March.''25'!K9) -> 0 | D12: =B12+C12 -> 7948 | E12: ='Water '!$S9 -> 3790 | F12: =IF('Entries March.''25'!B10-'Entries March.''25'!B9<1,"0",'Entries March.''25'!B10-'Entries March.''25'!B9) -> 2480 | G12: ='CO2'!B9 -> 0 | H12: =+'PROD.FIG. '!F7 -> 0 | I12: =+'PROD.FIG. '!C7 -> 0 | J12: =+'PROD.FIG. '!D7 -> 0 | K12: =+'PROD.FIG. '!E7 -> 0 | M12: =IF(SUM($I12:$J12)<1,0,B12/SUM($I12:$J12)) -> 0 | N12: =IF(SUM($I12:$J12)<1,0,E12/SUM($I12:$J12)) -> 0 | O12: =IF(SUM($I12:$J12)<1,0,F12/SUM($I12:$J12)) -> 0 | P12: =IF(SUM($I12:$J12)<1,0,G12/SUM($I12:$J12)) -> 0
A13: 4 | B13: =IF(('Entries March.''25'!I11-'Entries March.''25'!I10)+('Entries March.''25'!J11-'Entries March.''25'!J10)<1,"0",('Entries March.''25'!I11-'Entries March.''25'!I10)+('Entries March.''25'!J11-'Entries March.''25'!J10)) -> 8547 | C13: =IF('Entries March.''25'!K11-'Entries March.''25'!K10<=0,"0",'Entries March.''25'!K11-'Entries March.''25'!K10) -> 0 | D13: =B13+C13 -> 8547 | E13: ='Water '!$S10 -> 4410 | F13: =IF('Entries March.''25'!B11-'Entries March.''25'!B10<1,"0",'Entries March.''25'!B11-'Entries March.''25'!B10) -> 3270 | G13: ='CO2'!B10 -> 141.87 | H13: =+'PROD.FIG. '!F8 -> 0 | I13: =+'PROD.FIG. '!C8 -> 0 | J13: =+'PROD.FIG. '!D8 -> 0 | K13: =+'PROD.FIG. '!E8 -> 0 | M13: =IF(SUM($I13:$J13)<1,0,B13/SUM($I13:$J13)) -> 0 | N13: =IF(SUM($I13:$J13)<1,0,E13/SUM($I13:$J13)) -> 0 | O13: =IF(SUM($I13:$J13)<1,0,F13/SUM($I13:$J13)) -> 0 | P13: =IF(SUM($I13:$J13)<1,0,G13/SUM($I13:$J13)) -> 0
A14: 5 | B14: =IF(('Entries March.''25'!I12-'Entries March.''25'!I11)+('Entries March.''25'!J12-'Entries March.''25'!J11)<1,"0",('Entries March.''25'!I12-'Entries March.''25'!I11)+('Entries March.''25'!J12-'Entries March.''25'!J11)) -> 8241 | C14: =IF('Entries March.''25'!K12-'Entries March.''25'!K11<=0,"0",'Entries March.''25'!K12-'Entries March.''25'!K11) -> 0 | D14: =B14+C14 -> 8241 | E14: ='Water '!$S11 -> 4360 | F14: =IF('Entries March.''25'!B12-'Entries March.''25'!B11<1,"0",'Entries March.''25'!B12-'Entries March.''25'!B11) -> 3040 | G14: ='CO2'!B11 -> 28.96 | H14: =+'PROD.FIG. '!F9 -> 0 | I14: =+'PROD.FIG. '!C9 -> 0 | J14: =+'PROD.FIG. '!D9 -> 0 | K14: =+'PROD.FIG. '!E9 -> 0 | M14: =IF(SUM($I14:$J14)<1,0,B14/SUM($I14:$J14)) -> 0 | N14: =IF(SUM($I14:$J14)<1,0,E14/SUM($I14:$J14)) -> 0 | O14: =IF(SUM($I14:$J14)<1,0,F14/SUM($I14:$J14)) -> 0 | P14: =IF(SUM($I14:$J14)<1,0,G14/SUM($I14:$J14)) -> 0
A15: 6 | B15: =IF(('Entries March.''25'!I13-'Entries March.''25'!I12)+('Entries March.''25'!J13-'Entries March.''25'!J12)<1,"0",('Entries March.''25'!I13-'Entries March.''25'!I12)+('Entries March.''25'!J13-'Entries March.''25'!J12)) -> 8066 | C15: =IF('Entries March.''25'!K13-'Entries March.''25'!K12<=0,"0",'Entries March.''25'!K13-'Entries March.''25'!K12) -> 0 | D15: =B15+C15 -> 8066 | E15: ='Water '!$S12 -> 2580 | F15: =IF('Entries March.''25'!B13-'Entries March.''25'!B12<1,"0",'Entries March.''25'!B13-'Entries March.''25'!B12) -> 2720 | G15: ='CO2'!B12 -> 35.05 | H15: =+'PROD.FIG. '!F10 -> 0 | I15: =+'PROD.FIG. '!C10 -> 0 | J15: =+'PROD.FIG. '!D10 -> 0 | K15: =+'PROD.FIG. '!E10 -> 0 | M15: =IF(SUM($I15:$J15)<1,0,B15/SUM($I15:$J15)) -> 0 | N15: =IF(SUM($I15:$J15)<1,0,E15/SUM($I15:$J15)) -> 0 | O15: =IF(SUM($I15:$J15)<1,0,F15/SUM($I15:$J15)) -> 0 | P15: =IF(SUM($I15:$J15)<1,0,G15/SUM($I15:$J15)) -> 0
A16: 7 | B16: =IF(('Entries March.''25'!I14-'Entries March.''25'!I13)+('Entries March.''25'!J14-'Entries March.''25'!J13)<1,"0",('Entries March.''25'!I14-'Entries March.''25'!I13)+('Entries March.''25'!J14-'Entries March.''25'!J13)) -> 7348 | C16: =IF('Entries March.''25'!K14-'Entries March.''25'!K13<=0,"0",'Entries March.''25'!K14-'Entries March.''25'!K13) -> 0 | D16: =B16+C16 -> 7348 | E16: ='Water '!$S13 -> 2310 | F16: =IF('Entries March.''25'!B14-'Entries March.''25'!B13<1,"0",'Entries March.''25'!B14-'Entries March.''25'!B13) -> 2380 | G16: ='CO2'!B13 -> 37.67 | H16: =+'PROD.FIG. '!F11 -> 0 | I16: =+'PROD.FIG. '!C11 -> 0 | J16: =+'PROD.FIG. '!D11 -> 0 | K16: =+'PROD.FIG. '!E11 -> 0 | M16: =IF(SUM($I16:$J16)<1,0,B16/SUM($I16:$J16)) -> 0 | N16: =IF(SUM($I16:$J16)<1,0,E16/SUM($I16:$J16)) -> 0 | O16: =IF(SUM($I16:$J16)<1,0,F16/SUM($I16:$J16)) -> 0 | P16: =IF(SUM($I16:$J16)<1,0,G16/SUM($I16:$J16)) -> 0
A17: 8 | B17: =IF(('Entries March.''25'!I15-'Entries March.''25'!I14)+('Entries March.''25'!J15-'Entries March.''25'!J14)<1,"0",('Entries March.''25'!I15-'Entries March.''25'!I14)+('Entries March.''25'!J15-'Entries March.''25'!J14)) -> 4624 | C17: =IF('Entries March.''25'!K15-'Entries March.''25'!K14<=0,"0",'Entries March.''25'!K15-'Entries March.''25'!K14) -> 0 | D17: =B17+C17 -> 4624 | E17: ='Water '!$S14 -> 1410 | F17: =IF('Entries March.''25'!B15-'Entries March.''25'!B14<1,"0",'Entries March.''25'!B15-'Entries March.''25'!B14) -> 1000 | G17: ='CO2'!B14 -> 4.96 | H17: =+'PROD.FIG. '!F12 -> 0 | I17: =+'PROD.FIG. '!C12 -> 0 | J17: =+'PROD.FIG. '!D12 -> 0 | K17: =+'PROD.FIG. '!E12 -> 0 | M17: =IF(SUM($I17:$J17)<1,0,B17/SUM($I17:$J17)) -> 0 | N17: =IF(SUM($I17:$J17)<1,0,E17/SUM($I17:$J17)) -> 0 | O17: =IF(SUM($I17:$J17)<1,0,F17/SUM($I17:$J17)) -> 0 | P17: =IF(SUM($I17:$J17)<1,0,G17/SUM($I17:$J17)) -> 0
A18: 9 | B18: =IF(('Entries March.''25'!I16-'Entries March.''25'!I15)+('Entries March.''25'!J16-'Entries March.''25'!J15)<1,"0",('Entries March.''25'!I16-'Entries March.''25'!I15)+('Entries March.''25'!J16-'Entries March.''25'!J15)) -> 4173 | C18: =IF('Entries March.''25'!K16-'Entries March.''25'!K15<=0,"0",'Entries March.''25'!K16-'Entries March.''25'!K15) -> 0 | D18: =B18+C18 -> 4173 | E18: ='Water '!$S15 -> 760 | F18: =IF('Entries March.''25'!B16-'Entries March.''25'!B15<1,"0",'Entries March.''25'!B16-'Entries March.''25'!B15) -> 100 | G18: ='CO2'!B15 -> 0 | H18: =+'PROD.FIG. '!F13 -> 0 | I18: =+'PROD.FIG. '!C13 -> 0 | J18: =+'PROD.FIG. '!D13 -> 0 | K18: =+'PROD.FIG. '!E13 -> 0 | M18: =IF(SUM($I18:$J18)<1,0,B18/SUM($I18:$J18)) -> 0 | N18: =IF(SUM($I18:$J18)<1,0,E18/SUM($I18:$J18)) -> 0 | O18: =IF(SUM($I18:$J18)<1,0,F18/SUM($I18:$J18)) -> 0 | P18: =IF(SUM($I18:$J18)<1,0,G18/SUM($I18:$J18)) -> 0
A19: 10 | B19: =IF(('Entries March.''25'!I17-'Entries March.''25'!I16)+('Entries March.''25'!J17-'Entries March.''25'!J16)<1,"0",('Entries March.''25'!I17-'Entries March.''25'!I16)+('Entries March.''25'!J17-'Entries March.''25'!J16)) -> 8000 | C19: =IF('Entries March.''25'!K17-'Entries March.''25'!K16<=0,"0",'Entries March.''25'!K17-'Entries March.''25'!K16) -> 0 | D19: =B19+C19 -> 8000 | E19: ='Water '!$S16 -> 80 | F19: =IF('Entries March.''25'!B17-'Entries March.''25'!B16<1,"0",'Entries March.''25'!B17-'Entries March.''25'!B16) -> 3100 | G19: ='CO2'!B16 -> 20.14 | H19: =+'PROD.FIG. '!F14 -> 0 | I19: =+'PROD.FIG. '!C14 -> 0 | J19: =+'PROD.FIG. '!D14 -> 0 | K19: =+'PROD.FIG. '!E14 -> 0 | M19: =IF(SUM($I19:$J19)<1,0,B19/SUM($I19:$J19)) -> 0 | N19: =IF(SUM($I19:$J19)<1,0,E19/SUM($I19:$J19)) -> 0 | O19: =IF(SUM($I19:$J19)<1,0,F19/SUM($I19:$J19)) -> 0 | P19: =IF(SUM($I19:$J19)<1,0,G19/SUM($I19:$J19)) -> 0
A20: 11 | B20: =IF(('Entries March.''25'!I18-'Entries March.''25'!I17)+('Entries March.''25'!J18-'Entries March.''25'!J17)<1,"0",('Entries March.''25'!I18-'Entries March.''25'!I17)+('Entries March.''25'!J18-'Entries March.''25'!J17)) -> 8338 | C20: =IF('Entries March.''25'!K18-'Entries March.''25'!K17<=0,"0",'Entries March.''25'!K18-'Entries March.''25'!K17) -> 0 | D20: =B20+C20 -> 8338 | E20: ='Water '!$S17 -> 3660 | F20: =IF('Entries March.''25'!B18-'Entries March.''25'!B17<1,"0",'Entries March.''25'!B18-'Entries March.''25'!B17) -> 3040 | G20: ='CO2'!B17 -> 25.49 | H20: =+'PROD.FIG. '!F15 -> 0 | I20: =+'PROD.FIG. '!C15 -> 0 | J20: =+'PROD.FIG. '!D15 -> 0 | K20: =+'PROD.FIG. '!E15 -> 0 | M20: =IF(SUM($I20:$J20)<1,0,B20/SUM($I20:$J20)) -> 0 | N20: =IF(SUM($I20:$J20)<1,0,E20/SUM($I20:$J20)) -> 0 | O20: =IF(SUM($I20:$J20)<1,0,F20/SUM($I20:$J20)) -> 0 | P20: =IF(SUM($I20:$J20)<1,0,G20/SUM($I20:$J20)) -> 0
A21: 12 | B21: =IF(('Entries March.''25'!I19-'Entries March.''25'!I18)+('Entries March.''25'!J19-'Entries March.''25'!J18)<1,"0",('Entries March.''25'!I19-'Entries March.''25'!I18)+('Entries March.''25'!J19-'Entries March.''25'!J18)) -> 8475 | C21: =IF('Entries March.''25'!K19-'Entries March.''25'!K18<=0,"0",'Entries March.''25'!K19-'Entries March.''25'!K18) -> 0 | D21: =B21+C21 -> 8475 | E21: ='Water '!$S18 -> 2030 | F21: =IF('Entries March.''25'!B19-'Entries March.''25'!B18<1,"0",'Entries March.''25'!B19-'Entries March.''25'!B18) -> 2800 | G21: ='CO2'!B18 -> 16.74 | H21: =+'PROD.FIG. '!F16 -> 0 | I21: =+'PROD.FIG. '!C16 -> 0 | J21: =+'PROD.FIG. '!D16 -> 0 | K21: =+'PROD.FIG. '!E16 -> 0 | M21: =IF(SUM($I21:$J21)<1,0,B21/SUM($I21:$J21)) -> 0 | N21: =IF(SUM($I21:$J21)<1,0,E21/SUM($I21:$J21)) -> 0 | O21: =IF(SUM($I21:$J21)<1,0,F21/SUM($I21:$J21)) -> 0 | P21: =IF(SUM($I21:$J21)<1,0,G21/SUM($I21:$J21)) -> 0
... A40: 31 | B40: =IF(('Entries March.''25'!I38-'Entries March.''25'!I37)+('Entries March.''25'!J38-'Entries March.''25'!J37)<1,"0",('Entries March.''25'!I38-'Entries March.''25'!I37)+('Entries March.''25'!J38-'Entries March.''25'!J37)) -> 7462 | C40: =IF('Entries March.''25'!K38-'Entries March.''25'!K37<=0,"0",'Entries March.''25'!K38-'Entries March.''25'!K37) -> 0 | D40: =B40+C40 -> 7462 | E40: ='Water '!$S37 -> 620 | F40: =IF('Entries March.''25'!B38-'Entries March.''25'!B37<1,"0",'Entries March.''25'!B38-'Entries March.''25'!B37) -> 2670 | G40: ='CO2'!B37 -> 42.06 | H40: =+'PROD.FIG. '!F35 -> 0 | I40: =+'PROD.FIG. '!C35 -> 0 | J40: =+'PROD.FIG. '!D35 -> 0 | K40: =+'PROD.FIG. '!E35 -> 0 | M40: =IF(SUM($I40:$J40)<1,0,B40/SUM($I40:$J40)) -> 0 | N40: =IF(SUM($I40:$J40)<1,0,E40/SUM($I40:$J40)) -> 0 | O40: =IF(SUM($I40:$J40)<1,0,F40/SUM($I40:$J40)) -> 0 | P40: =IF(SUM($I40:$J40)<1,0,G40/SUM($I40:$J40)) -> 0
B42: Kwhr | C42: Kwhr | D42: Kwhr | E42: Hl | F42: L | G42: kg. | H42: hl | I42: hl | J42: hl | K42: hl | L42: hl | M42: KWH/Hl | N42: Hl/hl | O42: Litres/hl | P42: kg./Hl
A43: Total | B43: =SUM(B10:B40) -> 214318 | C43: =SUM(C10:C40) -> 1600 | D43: =SUM(D10:D40) -> 215918 | E43: =SUM(E10:E40) -> 48030 | F43: =SUM(F10:F40) -> 63570 | G43: =SUM(G10:G40) -> 733.52 | H43: =SUM(H10:H40) -> 0 | I43: =SUM(I10:I40) -> 0 | ... P43: =SUM(P10:P40) -> 0

Sheet Steam Mass Flow 
A3: DATE | B3: Steam Mass Flow Reading
A5: 1 | B5: =IF('Entries March.''25'!AJ8-'Entries March.''25'!AJ7<1,"0",'Entries March.''25'!AJ8-'Entries March.''25'!AJ7) -> 0
A6: 2 | B6: =IF('Entries March.''25'!AJ9-'Entries March.''25'!AJ8<1,"0",'Entries March.''25'!AJ9-'Entries March.''25'!AJ8) -> 0
A7: 3 | B7: =IF('Entries March.''25'!AJ10-'Entries March.''25'!AJ9<1,"0",'Entries March.''25'!AJ10-'Entries March.''25'!AJ9) -> 153.613
A8: 4 | B8: =IF('Entries March.''25'!AJ11-'Entries March.''25'!AJ10<1,"0",'Entries March.''25'!AJ11-'Entries March.''25'!AJ10) -> 124.467
A9: 5 | B9: =IF('Entries March.''25'!AJ12-'Entries March.''25'!AJ11<1,"0",'Entries March.''25'!AJ12-'Entries March.''25'!AJ11) -> 10.485
A10: 6 | B10: =IF('Entries March.''25'!AJ13-'Entries March.''25'!AJ12<1,"0",'Entries March.''25'!AJ13-'Entries March.''25'!AJ12) -> 703.626
A11: 7 | B11: =IF('Entries March.''25'!AJ14-'Entries March.''25'!AJ13<1,"0",'Entries March.''25'!AJ14-'Entries March.''25'!AJ13) -> 335.783
A12: 8 | B12: =IF('Entries March.''25'!AJ15-'Entries March.''25'!AJ14<1,"0",'Entries March.''25'!AJ15-'Entries March.''25'!AJ14) -> 335.784
A13: 9 | B13: =IF('Entries March.''25'!AJ16-'Entries March.''25'!AJ15<1,"0",'Entries March.''25'!AJ16-'Entries March.''25'!AJ15) -> 0
A14: 10 | B14: =IF('Entries March.''25'!AJ17-'Entries March.''25'!AJ16<1,"0",'Entries March.''25'!AJ17-'Entries March.''25'!AJ16) -> 3.806
A15: 11 | B15: =IF('Entries March.''25'!AJ18-'Entries March.''25'!AJ17<1,"0",'Entries March.''25'!AJ18-'Entries March.''25'!AJ17) -> 130.371
A16: 12 | B16: =IF('Entries March.''25'!AJ19-'Entries March.''25'!AJ18<1,"0",'Entries March.''25'!AJ19-'Entries March.''25'!AJ18) -> 54.878
... A35: 31 | B35: =IF('Entries March.''25'!AJ38-'Entries March.''25'!AJ37<1,"0",'Entries March.''25'!AJ38-'Entries March.''25'!AJ37) -> 24.428
B36: =SUM(B5:B35) -> 1927.754

Sheet CO2
A3: CO2 Daily Consumption for MARCH 2025
E4: FILLER
A5: DATE | B5: FILLER Cons. (Kg.) | C5: CO2 (kg.) (Ex. Vap'r) | D5: Total Prod.(HL) | E5: CO2 ( Kg./HL) | F5: CO2 (Ex. Vap'r) (Kg./HL) | L5: Tank A | M5: Tank B | N5: Mobile | O5: Inside Tank | S5: 4 | T5: Usage | U5: time | V5: 5 | W5: Usage | X5: Time | Y5: 6 | Z5: Usage | AA5: time | AB5: 7 | AC5: Usage | AD5: Time | AE5: 8 | AF5: Usage | AG5: time | AH5: 9 | AI5: Usage | AJ5: Time | AK5: 10 | AL5: Usage | AM5: time | AN5: 11 | AO5: Usage | AP5: Time | AQ5: 12 | AR5: Usage | AS5: time | AT5: 13 | AU5: Usage | AV5: Time | AW5: 14 | AX5: Usage | AY5: time | AZ5: 15 | BA5: Usage | BB5: Time | BC5: 16 | BD5: Usage | BE5: time | BF5: 17 | BG5: Usage | BH5: Time | BI5: 18 | BJ5: Usage | BK5: time | BL5: 19 | BM5: Usage | BN5: Time | BO5: 20 | BP5: Usage | BQ5: time | BR5: 21 | BS5: Usage | BT5: Time | BU5: 22 | BV5: Usage | BW5: time | BX5: 23 | BY5: Usage | BZ5: Time | CA5: 24 | CB5: Usage | CC5: time | CD5: 25 | CE5: Usage | CF5: Time | CG5: 26 | CH5: Usage | CI5: time | CJ5: 27 | CK5: Usage | CL5: Time | CM5: 28 | CN5: Usage | CO5: time | CP5: 29 | CQ5: Usage | CR5: Time | CS5: 30 | CT5: Usage | CU5: time | CV5: 31 | CW5: Usage | CX5: Time | CY5: 2 | CZ5: Usage
H6: Collection | U6: 630 | AA6: 630 | AG6: 630 | AM6: 630 | AS6: 630 | AY6: 630 | BE6: 630 | BK6: 630 | BQ6: 630 | BW6: 630 | CC6: 630 | CI6: 630 | CO6: 630 | CU6: 630
A7: 1 | B7: =IF('Entries March.''25'!N8-'Entries March.''25'!N7<1,"0",'Entries March.''25'!N8-'Entries March.''25'!N7) -> 0 | C7: {=TRANSPOSE('Daily KPIs'!B74:AF74)} -> 0 | D7: {=TRANSPOSE('Daily KPIs'!B9:AF9)} -> 0 | E7: =IF(D7=0,"0",(B7/D7)) -> 0 | F7: =IF(D7=0,"0",(C7/D7)) -> 0 | H7: ='Entries March.''25'!L8-'Entries March.''25'!L7 -> 0 | I7: =+$B7 -> 0 | L7: =IF((('Entries March.''25'!AK7-'Entries March.''25'!AK8)/10)*5455<0,"0",(('Entries March.''25'!AK7-'Entries March.''25'!AK8)/10)*5455) -> 0 | M7: =IF((('Entries March.''25'!AL7-'Entries March.''25'!AL8)/10)*5455<0,"0",(('Entries March.''25'!AL7-'Entries March.''25'!AL8)/10)*5455) -> 0 | N7: =IF(('Entries March.''25'!AM7-'Entries March.''25'!AM8)/2.2<0,"0",('Entries March.''25'!AM7-'Entries March.''25'!AM8)/2.2) -> 0 | O7: =IF(('Entries March.''25'!AN7-'Entries March.''25'!AN8)<0,"0",('Entries March.''25'!AN7-'Entries March.''25'!AN8)) -> 0 | T7: =S7-S6 -> 0 | U7: 730 | W7: =V7-V6 -> 0 | Z7: =Y7-Y6 -> 0 | AA7: 730 | AC7: =AB7-AB6 -> 0 | AF7: =AE7-AE6 -> 0 | AG7: 730 | AI7: =AH7-AH6 -> 0 | AL7: =AK7-AK6 -> 0 | AM7: 730 | AO7: =AN7-AN6 -> 0 | AR7: =AQ7-AQ6 -> 0 | AS7: 730 | AU7: =AT7-AT6 -> 0 | AX7: =AW7-AW6 -> 0 | AY7: 730 | BA7: =AZ7-AZ6 -> 0 | BD7: =BC7-BC6 -> 0 | BE7: 730 | BG7: =BF7-BF6 -> 0 | BJ7: =BI7-BI6 -> 0 | BK7: 730 | BM7: =BL7-BL6 -> 0 | BP7: =BO7-BO6 -> 0 | BQ7: 730 | BS7: =BR7-BR6 -> 0 | BV7: =BU7-BU6 -> 0 | BW7: 730 | BY7: =BX7-BX6 -> 0 | CB7: =CA7-CA6 -> 0 | CC7: 730 | CE7: =CD7-CD6 -> 0 | CH7: =CG7-CG6 -> 0 | CI7: 730 | CK7: =CJ7-CJ6 -> 0 | CN7: =CM7-CM6 -> 0 | CO7: 730 | CQ7: =CP7-CP6 -> 0 | CT7: =CS7-CS6 -> 0 | CU7: 730 | CW7: =CV7-CV6 -> 0 | CZ7: =CY7-CY6 -> 0
A8: 2 | B8: =IF('Entries March.''25'!N9-'Entries March.''25'!N8<1,"0",'Entries March.''25'!N9-'Entries March.''25'!N8) -> 0 | C8: 3700 | D8: 0 | E8: =IF(D8=0,"0",(B8/D8)) -> 0 | F8: =IF(D8=0,"0",(C8/D8)) -> 0 | H8: ='Entries March.''25'!L9-'Entries March.''25'!L8 -> 0 | I8: =+$B8 -> 0 | L8: =IF((('Entries March.''25'!AK8-'Entries March.''25'!AK9)/10)*5455<0,"0",(('Entries March.''25'!AK8-'Entries March.''25'!AK9)/10)*5455) -> 0 | M8: =IF((('Entries March.''25'!AL8-'Entries March.''25'!AL9)/10)*5455<0,"0",(('Entries March.''25'!AL8-'Entries March.''25'!AL9)/10)*5455) -> 0 | N8: =IF(('Entries March.''25'!AM8-'Entries March.''25'!AM9)/2.2<0,"0",('Entries March.''25'!AM8-'Entries March.''25'!AM9)/2.2) -> 0 | O8: =IF(('Entries March.''25'!AN8-'Entries March.''25'!AN9)<0,"0",('Entries March.''25'!AN8-'Entries March.''25'!AN9)) -> 0 | T8: =S8-S7 -> 0 | W8: =V8-V7 -> 0 | Z8: =Y8-Y7 -> 0 | AC8: =AB8-AB7 -> 0 | AF8: =AE8-AE7 -> 0 | AI8: =AH8-AH7 -> 0 | AL8: =AK8-AK7 -> 0 | AO8: =AN8-AN7 -> 0 | AR8: =AQ8-AQ7 -> 0 | AU8: =AT8-AT7 -> 0 | AX8: =AW8-AW7 -> 0 | BA8: =AZ8-AZ7 -> 0 | BD8: =BC8-BC7 -> 0 | BG8: =BF8-BF7 -> 0 | BJ8: =BI8-BI7 -> 0 | BM8: =BL8-BL7 -> 0 | BP8: =BO8-BO7 -> 0 | BS8: =BR8-BR7 -> 0 | BV8: =BU8-BU7 -> 0 | BY8: =BX8-BX7 -> 0 | CB8: =CA8-CA7 -> 0 | CE8: =CD8-CD7 -> 0 | CH8: =CG8-CG7 -> 0 | CK8: =CJ8-CJ7 -> 0 | CN8: =CM8-CM7 -> 0 | CQ8: =CP8-CP7 -> 0 | CT8: =CS8-CS7 -> 0 | CW8: =CV8-CV7 -> 0 | CZ8: =CY8-CY7 -> 0
A9: 3 | B9: =IF('Entries March.''25'!N10-'Entries March.''25'!N9<1,"0",'Entries March.''25'!N10-'Entries March.''25'!N9) -> 0 | C9: 2500 | D9: 356.4 | E9: =IF(D9=0,"0",(B9/D9)) -> 0 | F9: =IF(D9=0,"0",(C9/D9)) -> 7.0145903 | H9: ='Entries March.''25'!L10-'Entries March.''25'!L9 -> 0 | I9: =+$B9 -> 0 | L9: =IF((('Entries March.''25'!AK9-'Entries March.''25'!AK10)/10)*5455<0,"0",(('Entries March.''25'!AK9-'Entries March.''25'!AK10)/10)*5455) -> 0 | M9: =IF((('Entries March.''25'!AL9-'Entries March.''25'!AL10)/10)*5455<0,"0",(('Entries March.''25'!AL9-'Entries March.''25'!AL10)/10)*5455) -> 0 | N9: =IF(('Entries March.''25'!AM9-'Entries March.''25'!AM10)/2.2<0,"0",('Entries March.''25'!AM9-'Entries March.''25'!AM10)/2.2) -> 0 | O9: =IF(('Entries March.''25'!AN9-'Entries March.''25'!AN10)<0,"0",('Entries March.''25'!AN9-'Entries March.''25'!AN10)) -> 0 | T9: =S9-S8 -> 0 | W9: =V9-V8 -> 0 | Z9: =Y9-Y8 -> 0 | AC9: =AB9-AB8 -> 0 | AF9: =AE9-AE8 -> 0 | AI9: =AH9-AH8 -> 0 | AL9: =AK9-AK8 -> 0 | AO9: =AN9-AN8 -> 0 | AR9: =AQ9-AQ8 -> 0 | AU9: =AT9-AT8 -> 0 | AX9: =AW9-AW8 -> 0 | BA9: =AZ9-AZ8 -> 0 | BD9: =BC9-BC8 -> 0 | BG9: =BF9-BF8 -> 0 | BJ9: =BI9-BI8 -> 0 | BM9: =BL9-BL8 -> 0 | BP9: =BO9-BO8 -> 0 | BS9: =BR9-BR8 -> 0 | BV9: =BU9-BU8 -> 0 | BY9: =BX9-BX8 -> 0 | CB9: =CA9-CA8 -> 0 | CE9: =CD9-CD8 -> 0 | CH9: =CG9-CG8 -> 0 | CK9: =CJ9-CJ8 -> 0 | CN9: =CM9-CM8 -> 0 | CQ9: =CP9-CP8 -> 0 | CT9: =CS9-CS8 -> 0 | CW9: =CV9-CV8 -> 0 | CZ9: =CY9-CY8 -> 0
A10: 4 | B10: =IF('Entries March.''25'!N11-'Entries March.''25'!N10<1,"0",'Entries March.''25'!N11-'Entries March.''25'!N10) -> 141.87 | C10: 2100 | D10: 476.982 | E10: =IF(D10=0,"0",(B10/D10)) -> 0.29743261 | F10: =IF(D10=0,"0",(C10/D10)) -> 4.4026819 | H10: ='Entries March.''25'!L11-'Entries March.''25'!L10 -> 0 | I10: =+$B10 -> 141.87 | L10: =IF((('Entries March.''25'!AK10-'Entries March.''25'!AK11)/10)*5455<0,"0",(('Entries March.''25'!AK10-'Entries March.''25'!AK11)/10)*5455) -> 0 | M10: =IF((('Entries March.''25'!AL10-'Entries March.''25'!AL11)/10)*5455<0,"0",(('Entries March.''25'!AL10-'Entries March.''25'!AL11)/10)*5455) -> 0 | N10: =IF(('Entries March.''25'!AM10-'Entries March.''25'!AM11)/2.2<0,"0",('Entries March.''25'!AM10-'Entries March.''25'!AM11)/2.2) -> 0 | O10: =IF(('Entries March.''25'!AN10-'Entries March.''25'!AN11)<0,"0",('Entries March.''25'!AN10-'Entries March.''25'!AN11)) -> 0 | T10: =S10-S9 -> 0 | W10: =V10-V9 -> 0 | Z10: =Y10-Y9 -> 0 | AC10: =AB10-AB9 -> 0 | AF10: =AE10-AE9 -> 0 | AI10: =AH10-AH9 -> 0 | AL10: =AK10-AK9 -> 0 | AO10: =AN10-AN9 -> 0 | AR10: =AQ10-AQ9 -> 0 | AU10: =AT10-AT9 -> 0 | AX10: =AW10-AW9 -> 0 | BA10: =AZ10-AZ9 -> 0 | BD10: =BC10-BC9 -> 0 | BG10: =BF10-BF9 -> 0 | BJ10: =BI10-BI9 -> 0 | BM10: =BL10-BL9 -> 0 | BP10: =BO10-BO9 -> 0 | BS10: =BR10-BR9 -> 0 | BV10: =BU10-BU9 -> 0 | BY10: =BX10-BX9 -> 0 | CB10: =CA10-CA9 -> 0 | CE10: =CD10-CD9 -> 0 | CH10: =CG10-CG9 -> 0 | CK10: =CJ10-CJ9 -> 0 | CN10: =CM10-CM9 -> 0 | CQ10: =CP10-CP9 -> 0 | CT10: =CS10-CS9 -> 0 | CW10: =CV10-CV9 -> 0 | CZ10: =CY10-CY9 -> 0
A11: 5 | B11: =IF('Entries March.''25'!N12-'Entries March.''25'!N11<1,"0",'Entries March.''25'!N12-'Entries March.''25'!N11) -> 28.96 | C11: 1500 | D11: 345.114 | E11: =IF(D11=0,"0",(B11/D11)) -> 0.083914301 | F11: =IF(D11=0,"0",(C11/D11)) -> 4.3463899 | H11: ='Entries March.''25'!L12-'Entries March.''25'!L11 -> 0 | I11: =+$B11 -> 28.96 | L11: =IF((('Entries March.''25'!AK11-'Entries March.''25'!AK12)/10)*5455<0,"0",(('Entries March.''25'!AK11-'Entries March.''25'!AK12)/10)*5455) -> 0 | M11: =IF((('Entries March.''25'!AL11-'Entries March.''25'!AL12)/10)*5455<0,"0",(('Entries March.''25'!AL11-'Entries March.''25'!AL12)/10)*5455) -> 0 | N11: =IF(('Entries March.''25'!AM11-'Entries March.''25'!AM12)/2.2<0,"0",('Entries March.''25'!AM11-'Entries March.''25'!AM12)/2.2) -> 0 | O11: =IF(('Entries March.''25'!AN11-'Entries March.''25'!AN12)<0,"0",('Entries March.''25'!AN11-'Entries March.''25'!AN12)) -> 0 | T11: =S11-S10 -> 0 | W11: =V11-V10 -> 0 | Z11: =Y11-Y10 -> 0 | AC11: =AB11-AB10 -> 0 | AF11: =AE11-AE10 -> 0 | AI11: =AH11-AH10 -> 0 | AL11: =AK11-AK10 -> 0 | AO11: =AN11-AN10 -> 0 | AR11: =AQ11-AQ10 -> 0 | AU11: =AT11-AT10 -> 0 | AX11: =AW11-AW10 -> 0 | BA11: =AZ11-AZ10 -> 0 | BD11: =BC11-BC10 -> 0 | BG11: =BF11-BF10 -> 0 | BJ11: =BI11-BI10 -> 0 | BM11: =BL11-BL10 -> 0 | BP11: =BO11-BO10 -> 0 | BS11: =BR11-BR10 -> 0 | BV11: =BU11-BU10 -> 0 | BY11: =BX11-BX10 -> 0 | CB11: =CA11-CA10 -> 0 | CE11: =CD11-CD10 -> 0 | CH11: =CG11-CG10 -> 0 | CK11: =CJ11-CJ10 -> 0 | CN11: =CM11-CM10 -> 0 | CQ11: =CP11-CP10 -> 0 | CT11: =CS11-CS10 -> 0 | CW11: =CV11-CV10 -> 0 | CZ11: =CY11-CY10 -> 0
A12: 6 | B12: =IF('Entries March.''25'!N13-'Entries March.''25'!N12<1,"0",'Entries March.''25'!N13-'Entries March.''25'!N12) -> 35.05 | C12: 1500 | D12: 383.79 | E12: =IF(D12=0,"0",(B12/D12)) -> 0.091325986 | F12: =IF(D12=0,"0",(C12/D12)) -> 3.9083874 | H12: ='Entries March.''25'!L13-'Entries March.''25'!L12 -> 0 | I12: =+$B12 -> 35.05 | L12: =IF((('Entries March.''25'!AK12-'Entries March.''25'!AK13)/10)*5455<0,"0",(('Entries March.''25'!AK12-'Entries March.''25'!AK13)/10)*5455) -> 0 | M12: =IF((('Entries March.''25'!AL12-'Entries March.''25'!AL13)/10)*5455<0,"0",(('Entries March.''25'!AL12-'Entries March.''25'!AL13)/10)*5455) -> 0 | N12: =IF(('Entries March.''25'!AM12-'Entries March.''25'!AM13)/2.2<0,"0",('Entries March.''25'!AM12-'Entries March.''25'!AM13)/2.2) -> 0 | O12: =IF(('Entries March.''25'!AN12-'Entries March.''25'!AN13)<0,"0",('Entries March.''25'!AN12-'Entries March.''25'!AN13)) -> 0 | T12: =S12-S11 -> 0 | W12: =V12-V11 -> 0 | Z12: =Y12-Y11 -> 0 | AC12: =AB12-AB11 -> 0 | AF12: =AE12-AE11 -> 0 | AI12: =AH12-AH11 -> 0 | AL12: =AK12-AK11 -> 0 | AO12: =AN12-AN11 -> 0 | AR12: =AQ12-AQ11 -> 0 | AU12: =AT12-AT11 -> 0 | AX12: =AW12-AW11 -> 0 | BA12: =AZ12-AZ11 -> 0 | BD12: =BC12-BC11 -> 0 | BG12: =BF12-BF11 -> 0 | BJ12: =BI12-BI11 -> 0 | BM12: =BL12-BL11 -> 0 | BP12: =BO12-BO11 -> 0 | BS12: =BR12-BR11 -> 0 | BV12: =BU12-BU11 -> 0 | BY12: =BX12-BX11 -> 0 | CB12: =CA12-CA11 -> 0 | CE12: =CD12-CD11 -> 0 | CH12: =CG12-CG11 -> 0 | CK12: =CJ12-CJ11 -> 0 | CN12: =CM12-CM11 -> 0 | CQ12: =CP12-CP11 -> 0 | CT12: =CS12-CS11 -> 0 | CW12: =CV12-CV11 -> 0 | CZ12: =CY12-CY11 -> 0
A13: 7 | B13: =IF('Entries March.''25'!N14-'Entries March.''25'!N13<1,"0",'Entries March.''25'!N14-'Entries March.''25'!N13) -> 37.67 | C13: 1400 | D13: 328.482 | E13: =IF(D13=0,"0",(B13/D13)) -> 0.11467904 | F13: =IF(D13=0,"0",(C13/D13)) -> 4.2620296 | H13: ='Entries March.''25'!L14-'Entries March.''25'!L13 -> 0 | I13: =+$B13 -> 37.67 | L13: =IF((('Entries March.''25'!AK13-'Entries March.''25'!AK14)/10)*5455<0,"0",(('Entries March.''25'!AK13-'Entries March.''25'!AK14)/10)*5455) -> 0 | M13: =IF((('Entries March.''25'!AL13-'Entries March.''25'!AL14)/10)*5455<0,"0",(('Entries March.''25'!AL13-'Entries March.''25'!AL14)/10)*5455) -> 0 | N13: =IF(('Entries March.''25'!AM13-'Entries March.''25'!AM14)/2.2<0,"0",('Entries March.''25'!AM13-'Entries March.''25'!AM14)/2.2) -> 0 | O13: =IF(('Entries March.''25'!AN13-'Entries March.''25'!AN14)<0,"0",('Entries March.''25'!AN13-'Entries March.''25'!AN14)) -> 0 | T13: =S13-S12 -> 0 | W13: =V13-V12 -> 0 | Z13: =Y13-Y12 -> 0 | AC13: =AB13-AB12 -> 0 | AF13: =AE13-AE12 -> 0 | AI13: =AH13-AH12 -> 0 | AL13: =AK13-AK12 -> 0 | AO13: =AN13-AN12 -> 0 | AR13: =AQ13-AQ12 -> 0 | AU13: =AT13-AT12 -> 0 | AX13: =AW13-AW12 -> 0 | BA13: =AZ13-AZ12 -> 0 | BD13: =BC13-BC12 -> 0 | BG13: =BF13-BF12 -> 0 | BJ13: =BI13-BI12 -> 0 | BM13: =BL13-BL12 -> 0 | BP13: =BO13-BO12 -> 0 | BS13: =BR13-BR12 -> 0 | BV13: =BU13-BU12 -> 0 | BY13: =BX13-BX12 -> 0 | CB13: =CA13-CA12 -> 0 | CE13: =CD13-CD12 -> 0 | CH13: =CG13-CG12 -> 0 | CK13: =CJ13-CJ12 -> 0 | CN13: =CM13-CM12 -> 0 | CQ13: =CP13-CP12 -> 0 | CT13: =CS13-CS12 -> 0 | CW13: =CV13-CV12 -> 0 | CZ13: =CY13-CY12 -> 0
A14: 8 | B14: =IF('Entries March.''25'!N15-'Entries March.''25'!N14<1,"0",'Entries March.''25'!N15-'Entries March.''25'!N14) -> 4.96 | C14: 600 | D14: 0 | E14: =IF(D14=0,"0",(B14/D14)) -> 0 | F14: =IF(D14=0,"0",(C14/D14)) -> 0 | H14: ='Entries March.''25'!L15-'Entries March.''25'!L14 -> 0 | I14: =+$B14 -> 4.96 | L14: =IF((('Entries March.''25'!AK14-'Entries March.''25'!AK15)/10)*5455<0,"0",(('Entries March.''25'!AK14-'Entries March.''25'!AK15)/10)*5455) -> 0 | M14: =IF((('Entries March.''25'!AL14-'Entries March.''25'!AL15)/10)*5455<0,"0",(('Entries March.''25'!AL14-'Entries March.''25'!AL15)/10)*5455) -> 0 | N14: =IF(('Entries March.''25'!AM14-'Entries March.''25'!AM15)/2.2<0,"0",('Entries March.''25'!AM14-'Entries March.''25'!AM15)/2.2) -> 0 | O14: =IF(('Entries March.''25'!AN14-'Entries March.''25'!AN15)<0,"0",('Entries March.''25'!AN14-'Entries March.''25'!AN15)) -> 0 | T14: =S14-S13 -> 0 | W14: =V14-V13 -> 0 | Z14: =Y14-Y13 -> 0 | AC14: =AB14-AB13 -> 0 | AF14: =AE14-AE13 -> 0 | AI14: =AH14-AH13 -> 0 | AL14: =AK14-AK13 -> 0 | AO14: =AN14-AN13 -> 0 | AR14: =AQ14-AQ13 -> 0 | AU14: =AT14-AT13 -> 0 | AX14: =AW14-AW13 -> 0 | BA14: =AZ14-AZ13 -> 0 | BD14: =BC14-BC13 -> 0 | BG14: =BF14-BF13 -> 0 | BJ14: =BI14-BI13 -> 0 | BM14: =BL14-BL13 -> 0 | BP14: =BO14-BO13 -> 0 | BS14: =BR14-BR13 -> 0 | BV14: =BU14-BU13 -> 0 | BY14: =BX14-BX13 -> 0 | CB14: =CA14-CA13 -> 0 | CE14: =CD14-CD13 -> 0 | CH14: =CG14-CG13 -> 0 | CK14: =CJ14-CJ13 -> 0 | CN14: =CM14-CM13 -> 0 | CQ14: =CP14-CP13 -> 0 | CT14: =CS14-CS13 -> 0 | CW14: =CV14-CV13 -> 0 | CZ14: =CY14-CY13 -> 0
A15: 9 | B15: =IF('Entries March.''25'!N16-'Entries March.''25'!N15<1,"0",'Entries March.''25'!N16-'Entries March.''25'!N15) -> 0 | C15: 0 | D15: 0 | E15: =IF(D15=0,"0",(B15/D15)) -> 0 | F15: =IF(D15=0,"0",(C15/D15)) -> 0 | H15: ='Entries March.''25'!L16-'Entries March.''25'!L15 -> 0 | I15: =+$B15 -> 0 | L15: =IF((('Entries March.''25'!AK15-'Entries March.''25'!AK16)/10)*5455<0,"0",(('Entries March.''25'!AK15-'Entries March.''25'!AK16)/10)*5455) -> 0 | M15: =IF((('Entries March.''25'!AL15-'Entries March.''25'!AL16)/10)*5455<0,"0",(('Entries March.''25'!AL15-'Entries March.''25'!AL16)/10)*5455) -> 0 | N15: =IF(('Entries March.''25'!AM15-'Entries March.''25'!AM16)/2.2<0,"0",('Entries March.''25'!AM15-'Entries March.''25'!AM16)/2.2) -> 0 | O15: =IF(('Entries March.''25'!AN15-'Entries March.''25'!AN16)<0,"0",('Entries March.''25'!AN15-'Entries March.''25'!AN16)) -> 0 | T15: =S15-S14 -> 0 | W15: =V15-V14 -> 0 | Z15: =Y15-Y14 -> 0 | AC15: =AB15-AB14 -> 0 | AF15: =AE15-AE14 -> 0 | AI15: =AH15-AH14 -> 0 | AL15: =AK15-AK14 -> 0 | AO15: =AN15-AN14 -> 0 | AR15: =AQ15-AQ14 -> 0 | AU15: =AT15-AT14 -> 0 | AX15: =AW15-AW14 -> 0 | BA15: =AZ15-AZ14 -> 0 | BD15: =BC15-BC14 -> 0 | BG15: =BF15-BF14 -> 0 | BJ15: =BI15-BI14 -> 0 | BM15: =BL15-BL14 -> 0 | BP15: =BO15-BO14 -> 0 | BS15: =BR15-BR14 -> 0 | BV15: =BU15-BU14 -> 0 | BY15: =BX15-BX14 -> 0 | CB15: =CA15-CA14 -> 0 | CE15: =CD15-CD14 -> 0 | CH15: =CG15-CG14 -> 0 | CK15: =CJ15-CJ14 -> 0 | CN15: =CM15-CM14 -> 0 | CQ15: =CP15-CP14 -> 0 | CT15: =CS15-CS14 -> 0 | CW15: =CV15-CV14 -> 0 | CZ15: =CY15-CY14 -> 0
A16: 10 | B16: =IF('Entries March.''25'!N17-'Entries March.''25'!N16<1,"0",'Entries March.''25'!N17-'Entries March.''25'!N16) -> 20.14 | C16: 900 | D16: 228.36 | E16: =IF(D16=0,"0",(B16/D16)) -> 0.08819408 | F16: =IF(D16=0,"0",(C16/D16)) -> 3.9411456 | H16: ='Entries March.''25'!L17-'Entries March.''25'!L16 -> 0 | I16: =+$B16 -> 20.14 | L16: =IF((('Entries March.''25'!AK16-'Entries March.''25'!AK17)/10)*5455<0,"0",(('Entries March.''25'!AK16-'Entries March.''25'!AK17)/10)*5455) -> 0 | M16: =IF((('Entries March.''25'!AL16-'Entries March.''25'!AL17)/10)*5455<0,"0",(('Entries March.''25'!AL16-'Entries March.''25'!AL17)/10)*5455) -> 0 | N16: =IF(('Entries March.''25'!AM16-'Entries March.''25'!AM17)/2.2<0,"0",('Entries March.''25'!AM16-'Entries March.''25'!AM17)/2.2) -> 0 | O16: =IF(('Entries March.''25'!AN16-'Entries March.''25'!AN17)<0,"0",('Entries March.''25'!AN16-'Entries March.''25'!AN17)) -> 0 | T16: =S16-S15 -> 0 | W16: =V16-V15 -> 0 | Z16: =Y16-Y15 -> 0 | AC16: =AB16-AB15 -> 0 | AF16: =AE16-AE15 -> 0 | AI16: =AH16-AH15 -> 0 | AL16: =AK16-AK15 -> 0 | AO16: =AN16-AN15 -> 0 | AR16: =AQ16-AQ15 -> 0 | AU16: =AT16-AT15 -> 0 | AX16: =AW16-AW15 -> 0 | BA16: =AZ16-AZ15 -> 0 | BD16: =BC16-BC15 -> 0 | BG16: =BF16-BF15 -> 0 | BJ16: =BI16-BI15 -> 0 | BM16: =BL16-BL15 -> 0 | BP16: =BO16-BO15 -> 0 | BS16: =BR16-BR15 -> 0 | BV16: =BU16-BU15 -> 0 | BY16: =BX16-BX15 -> 0 | CB16: =CA16-CA15 -> 0 | CE16: =CD16-CD15 -> 0 | CH16: =CG16-CG15 -> 0 | CK16: =CJ16-CJ15 -> 0 | CN16: =CM16-CM15 -> 0 | CQ16: =CP16-CP15 -> 0 | CT16: =CS16-CS15 -> 0 | CW16: =CV16-CV15 -> 0 | CZ16: =CY16-CY15 -> 0
A17: 11 | B17: =IF('Entries March.''25'!N18-'Entries March.''25'!N17<1,"0",'Entries March.''25'!N18-'Entries March.''25'!N17) -> 25.49 | C17: 1500 | D17: 187.11 | E17: =IF(D17=0,"0",(B17/D17)) -> 0.13623003 | F17: =IF(D17=0,"0",(C17/D17)) -> 8.0166747 | H17: ='Entries March.''25'!L18-'Entries March.''25'!L17 -> 0 | I17: =+$B17 -> 25.49 | L17: =IF((('Entries March.''25'!AK17-'Entries March.''25'!AK18)/10)*5455<0,"0",(('Entries March.''25'!AK17-'Entries March.''25'!AK18)/10)*5455) -> 0 | M17: =IF((('Entries March.''25'!AL17-'Entries March.''25'!AL18)/10)*5455<0,"0",(('Entries March.''25'!AL17-'Entries March.''25'!AL18)/10)*5455) -> 0 | N17: =IF(('Entries March.''25'!AM17-'Entries March.''25'!AM18)/2.2<0,"0",('Entries March.''25'!AM17-'Entries March.''25'!AM18)/2.2) -> 0 | O17: =IF(('Entries March.''25'!AN17-'Entries March.''25'!AN18)<0,"0",('Entries March.''25'!AN17-'Entries March.''25'!AN18)) -> 0 | T17: =S17-S16 -> 0 | W17: =V17-V16 -> 0 | Z17: =Y17-Y16 -> 0 | AC17: =AB17-AB16 -> 0 | AF17: =AE17-AE16 -> 0 | AI17: =AH17-AH16 -> 0 | AL17: =AK17-AK16 -> 0 | AO17: =AN17-AN16 -> 0 | AR17: =AQ17-AQ16 -> 0 | AU17: =AT17-AT16 -> 0 | AX17: =AW17-AW16 -> 0 | BA17: =AZ17-AZ16 -> 0 | BD17: =BC17-BC16 -> 0 | BG17: =BF17-BF16 -> 0 | BJ17: =BI17-BI16 -> 0 | BM17: =BL17-BL16 -> 0 | BP17: =BO17-BO16 -> 0 | BS17: =BR17-BR16 -> 0 | BV17: =BU17-BU16 -> 0 | BY17: =BX17-BX16 -> 0 | CB17: =CA17-CA16 -> 0 | CE17: =CD17-CD16 -> 0 | CH17: =CG17-CG16 -> 0 | CK17: =CJ17-CJ16 -> 0 | CN17: =CM17-CM16 -> 0 | CQ17: =CP17-CP16 -> 0 | CT17: =CS17-CS16 -> 0 | CW17: =CV17-CV16 -> 0 | CZ17: =CY17-CY16 -> 0
A18: 12 | B18: =IF('Entries March.''25'!N19-'Entries March.''25'!N18<1,"0",'Entries March.''25'!N19-'Entries March.''25'!N18) -> 16.74 | C18: 1400 | D18: 135.036 | E18: =IF(D18=0,"0",(B18/D18)) -> 0.12396694 | F18: =IF(D18=0,"0",(C18/D18)) -> 10.367606 | H18: ='Entries March.''25'!L19-'Entries March.''25'!L18 -> 0 | I18: =+$B18 -> 16.74 | L18: =IF((('Entries March.''25'!AK18-'Entries March.''25'!AK19)/10)*5455<0,"0",(('Entries March.''25'!AK18-'Entries March.''25'!AK19)/10)*5455) -> 0 | M18: =IF((('Entries March.''25'!AL18-'Entries March.''25'!AL19)/10)*5455<0,"0",(('Entries March.''25'!AL18-'Entries March.''25'!AL19)/10)*5455) -> 0 | N18: =IF(('Entries March.''25'!AM18-'Entries March.''25'!AM19)/2.2<0,"0",('Entries March.''25'!AM18-'Entries March.''25'!AM19)/2.2) -> 0 | O18: =IF(('Entries March.''25'!AN18-'Entries March.''25'!AN19)<0,"0",('Entries March.''25'!AN18-'Entries March.''25'!AN19)) -> 0 | T18: =S18-S17 -> 0 | W18: =V18-V17 -> 0 | Z18: =Y18-Y17 -> 0 | AC18: =AB18-AB17 -> 0 | AF18: =AE18-AE17 -> 0 | AI18: =AH18-AH17 -> 0 | AL18: =AK18-AK17 -> 0 | AO18: =AN18-AN17 -> 0 | AR18: =AQ18-AQ17 -> 0 | AU18: =AT18-AT17 -> 0 | AX18: =AW18-AW17 -> 0 | BA18: =AZ18-AZ17 -> 0 | BD18: =BC18-BC17 -> 0 | BG18: =BF18-BF17 -> 0 | BJ18: =BI18-BI17 -> 0 | BM18: =BL18-BL17 -> 0 | BP18: =BO18-BO17 -> 0 | BS18: =BR18-BR17 -> 0 | BV18: =BU18-BU17 -> 0 | BY18: =BX18-BX17 -> 0 | CB18: =CA18-CA17 -> 0 | CE18: =CD18-CD17 -> 0 | CH18: =CG18-CG17 -> 0 | CK18: =CJ18-CJ17 -> 0 | CN18: =CM18-CM17 -> 0 | CQ18: =CP18-CP17 -> 0 | CT18: =CS18-CS17 -> 0 | CW18: =CV18-CV17 -> 0 | CZ18: =CY18-CY17 -> 0
A19: 13 | B19: =IF('Entries March.''25'!N20-'Entries March.''25'!N19<1,"0",'Entries March.''25'!N20-'Entries March.''25'!N19) -> 33.09 | C19: 1500 | D19: 360.624 | E19: =IF(D19=0,"0",(B19/D19)) -> 0.09175762 | F19: =IF(D19=0,"0",(C19/D19)) -> 4.1594569 | H19: ='Entries March.''25'!L20-'Entries March.''25'!L19 -> 0 | I19: =+$B19 -> 33.09 | L19: =IF((('Entries March.''25'!AK19-'Entries March.''25'!AK20)/10)*5455<0,"0",(('Entries March.''25'!AK19-'Entries March.''25'!AK20)/10)*5455) -> 0 | M19: =IF((('Entries March.''25'!AL19-'Entries March.''25'!AL20)/10)*5455<0,"0",(('Entries March.''25'!AL19-'Entries March.''25'!AL20)/10)*5455) -> 0 | N19: =IF(('Entries March.''25'!AM19-'Entries March.''25'!AM20)/2.2<0,"0",('Entries March.''25'!AM19-'Entries March.''25'!AM20)/2.2) -> 0 | O19: =IF(('Entries March.''25'!AN19-'Entries March.''25'!AN20)<0,"0",('Entries March.''25'!AN19-'Entries March.''25'!AN20)) -> 0 | T19: =S19-S18 -> 0 | W19: =V19-V18 -> 0 | Z19: =Y19-Y18 -> 0 | AC19: =AB19-AB18 -> 0 | AF19: =AE19-AE18 -> 0 | AI19: =AH19-AH18 -> 0 | AL19: =AK19-AK18 -> 0 | AO19: =AN19-AN18 -> 0 | AR19: =AQ19-AQ18 -> 0 | AU19: =AT19-AT18 -> 0 | AX19: =AW19-AW18 -> 0 | BA19: =AZ19-AZ18 -> 0 | BD19: =BC19-BC18 -> 0 | BG19: =BF19-BF18 -> 0 | BJ19: =BI19-BI18 -> 0 | BM19: =BL19-BL18 -> 0 | BP19: =BO19-BO18 -> 0 | BS19: =BR19-BR18 -> 0 | BV19: =BU19-BU18 -> 0 | BY19: =BX19-BX18 -> 0 | CB19: =CA19-CA18 -> 0 | CE19: =CD19-CD18 -> 0 | CH19: =CG19-CG18 -> 0 | CK19: =CJ19-CJ18 -> 0 | CN19: =CM19-CM18 -> 0 | CQ19: =CP19-CP18 -> 0 | CT19: =CS19-CS18 -> 0 | CW19: =CV19-CV18 -> 0 | CZ19: =CY19-CY18 -> 0
... A30: 24 | B30: =IF('Entries March.''25'!N31-'Entries March.''25'!N30<1,"0",'Entries March.''25'!N31-'Entries March.''25'!N30) -> 15.45 | C30: 1200 | D30: 67.386 | E30: =IF(D30=0,"0",(B30/D30)) -> 0.22927611 | F30: =IF(D30=0,"0",(C30/D30)) -> 17.807853 | H30: ='Entries March.''25'!L31-'Entries March.''25'!L30 -> 0 | I30: =+$B30 -> 15.45 | L30: =IF((('Entries March.''25'!AK30-'Entries March.''25'!AK31)/10)*5455<0,"0",(('Entries March.''25'!AK30-'Entries March.''25'!AK31)/10)*5455) -> 0 | M30: =IF((('Entries March.''25'!AL30-'Entries March.''25'!AL31)/10)*5455<0,"0",(('Entries March.''25'!AL30-'Entries March.''25'!AL31)/10)*5455) -> 0 | N30: =IF(('Entries March.''25'!AM30-'Entries March.''25'!AM31)/2.2<0,"0",('Entries March.''25'!AM30-'Entries March.''25'!AM31)/2.2) -> 0 | O30: =IF(('Entries March.''25'!AN30-'Entries March.''25'!AN31)<0,"0",('Entries March.''25'!AN30-'Entries March.''25'!AN31)) -> 0 | T30: =S30-S29 -> 0 | W30: =V30-V29 -> 0 | Z30: =Y30-Y29 -> 0 | AC30: =AB30-AB29 -> 0 | AF30: =AE30-AE29 -> 0 | AI30: =AH30-AH29 -> 0 | AL30: =AK30-AK29 -> 0 | AO30: =AN30-AN29 -> 0 | AR30: =AQ30-AQ29 -> 0 | AU30: =AT30-AT29 -> 0 | AX30: =AW30-AW29 -> 0 | BA30: =AZ30-AZ29 -> 0 | BD30: =BC30-BC29 -> 0 | BG30: =BF30-BF29 -> 0 | BJ30: =BI30-BI29 -> 0 | BM30: =BL30-BL29 -> 0 | BP30: =BO30-BO29 -> 0 | BS30: =BR30-BR29 -> 0 | BV30: =BU30-BU29 -> 0 | BY30: =BX30-BX29 -> 0 | CB30: =CA30-CA29 -> 0 | CE30: =CD30-CD29 -> 0 | CH30: =CG30-CG29 -> 0 | CK30: =CJ30-CJ29 -> 0 | CN30: =CM30-CM29 -> 0 | CQ30: =CP30-CP29 -> 0 | CT30: =CS30-CS29 -> 0 | CW30: =CV30-CV29 -> 0 | CZ30: =CY30-CY29 -> 0
A31: 25 | B31: =IF('Entries March.''25'!N32-'Entries March.''25'!N31<1,"0",'Entries March.''25'!N32-'Entries March.''25'!N31) -> 55.9 | C31: 3100 | D31: 623.436 | E31: =IF(D31=0,"0",(B31/D31)) -> 0.089664376 | F31: =IF(D31=0,"0",(C31/D31)) -> 4.972443 | H31: ='Entries March.''25'!L32-'Entries March.''25'!L31 -> 0 | I31: =+$B31 -> 55.9 | L31: =IF((('Entries March.''25'!AK31-'Entries March.''25'!AK32)/10)*5455<0,"0",(('Entries March.''25'!AK31-'Entries March.''25'!AK32)/10)*5455) -> 0 | M31: =IF((('Entries March.''25'!AL31-'Entries March.''25'!AL32)/10)*5455<0,"0",(('Entries March.''25'!AL31-'Entries March.''25'!AL32)/10)*5455) -> 0 | N31: =IF(('Entries March.''25'!AM31-'Entries March.''25'!AM32)/2.2<0,"0",('Entries March.''25'!AM31-'Entries March.''25'!AM32)/2.2) -> 0 | O31: =IF(('Entries March.''25'!AN31-'Entries March.''25'!AN32)<0,"0",('Entries March.''25'!AN31-'Entries March.''25'!AN32)) -> 0 | T31: =SUM(T6:T29) -> 0 | W31: =SUM(W6:W29) -> 0 | Z31: =SUM(Z6:Z29) -> 0 | AC31: =SUM(AC6:AC29) -> 0 | AF31: =SUM(AF6:AF29) -> 0 | AI31: =SUM(AI6:AI29) -> 0 | AL31: =SUM(AL6:AL29) -> 0 | AO31: =SUM(AO6:AO29) -> 0 | AR31: =SUM(AR6:AR29) -> 0 | AU31: =SUM(AU6:AU29) -> 0 | AX31: =SUM(AX6:AX29) -> 0 | BA31: =SUM(BA6:BA29) -> 0 | BD31: =SUM(BD6:BD29) -> 0 | BG31: =SUM(BG6:BG29) -> 0 | BJ31: =SUM(BJ6:BJ29) -> 0 | BM31: =SUM(BM6:BM29) -> 0 | BP31: =SUM(BP6:BP29) -> 0 | BS31: =SUM(BS6:BS29) -> 0 | BV31: =SUM(BV6:BV29) -> 0 | BY31: =SUM(BY6:BY29) -> 0 | CB31: =SUM(CB6:CB29) -> 0 | CE31: =SUM(CE6:CE29) -> 0 | CH31: =SUM(CH6:CH29) -> 0 | CK31: =SUM(CK6:CK29) -> 0 | CN31: =SUM(CN6:CN29) -> 0 | CQ31: =SUM(CQ6:CQ29) -> 0 | CT31: =SUM(CT6:CT29) -> 0 | CW31: =SUM(CW6:CW29) -> 0 | CZ31: =SUM(CZ6:CZ29) -> 0
A32: 26 | B32: =IF('Entries March.''25'!N33-'Entries March.''25'!N32<1,"0",'Entries March.''25'!N33-'Entries March.''25'!N32) -> 48.95 | C32: 2400 | D32: 589.314 | E32: =IF(D32=0,"0",(B32/D32)) -> 0.08306268 | F32: =IF(D32=0,"0",(C32/D32)) -> 4.0725318 | H32: ='Entries March.''25'!L33-'Entries March.''25'!L32 -> 0 | I32: =+$B32 -> 48.95 | L32: =IF((('Entries March.''25'!AK32-'Entries March.''25'!AK33)/10)*5455<0,"0",(('Entries March.''25'!AK32-'Entries March.''25'!AK33)/10)*5455) -> 0 | M32: =IF((('Entries March.''25'!AL32-'Entries March.''25'!AL33)/10)*5455<0,"0",(('Entries March.''25'!AL32-'Entries March.''25'!AL33)/10)*5455) -> 0 | N32: =IF(('Entries March.''25'!AM32-'Entries March.''25'!AM33)/2.2<0,"0",('Entries March.''25'!AM32-'Entries March.''25'!AM33)/2.2) -> 0 | O32: =IF(('Entries March.''25'!AN32-'Entries March.''25'!AN33)<0,"0",('Entries March.''25'!AN32-'Entries March.''25'!AN33)) -> 0
A33: 27 | B33: =IF('Entries March.''25'!N34-'Entries March.''25'!N33<1,"0",'Entries March.''25'!N34-'Entries March.''25'!N33) -> 47.21 | C33: 2500 | D33: 535.854 | E33: =IF(D33=0,"0",(B33/D33)) -> 0.088102356 | F33: =IF(D33=0,"0",(C33/D33)) -> 4.6654499 | H33: ='Entries March.''25'!L34-'Entries March.''25'!L33 -> 0 | I33: =+$B33 -> 47.21 | L33: =IF((('Entries March.''25'!AK33-'Entries March.''25'!AK34)/10)*5455<0,"0",(('Entries March.''25'!AK33-'Entries March.''25'!AK34)/10)*5455) -> 0 | M33: =IF((('Entries March.''25'!AL33-'Entries March.''25'!AL34)/10)*5455<0,"0",(('Entries March.''25'!AL33-'Entries March.''25'!AL34)/10)*5455) -> 0 | N33: =IF(('Entries March.''25'!AM33-'Entries March.''25'!AM34)/2.2<0,"0",('Entries March.''25'!AM33-'Entries March.''25'!AM34)/2.2) -> 0 | O33: =IF(('Entries March.''25'!AN33-'Entries March.''25'!AN34)<0,"0",('Entries March.''25'!AN33-'Entries March.''25'!AN34)) -> 0
A34: 28 | B34: =IF('Entries March.''25'!N35-'Entries March.''25'!N34<1,"0",'Entries March.''25'!N35-'Entries March.''25'!N34) -> 14.24 | C34: 1600 | D34: 181.8144 | E34: =IF(D34=0,"0",(B34/D34)) -> 0.078321629 | F34: =IF(D34=0,"0",(C34/D34)) -> 8.800183 | H34: ='Entries March.''25'!L35-'Entries March.''25'!L34 -> 0 | I34: =+$B34 -> 14.24 | L34: =IF((('Entries March.''25'!AK34-'Entries March.''25'!AK35)/10)*5455<0,"0",(('Entries March.''25'!AK34-'Entries March.''25'!AK35)/10)*5455) -> 0 | M34: =IF((('Entries March.''25'!AL34-'Entries March.''25'!AL35)/10)*5455<0,"0",(('Entries March.''25'!AL34-'Entries March.''25'!AL35)/10)*5455) -> 0 | N34: =IF(('Entries March.''25'!AM34-'Entries March.''25'!AM35)/2.2<0,"0",('Entries March.''25'!AM34-'Entries March.''25'!AM35)/2.2) -> 0 | O34: =IF(('Entries March.''25'!AN34-'Entries March.''25'!AN35)<0,"0",('Entries March.''25'!AN34-'Entries March.''25'!AN35)) -> 0
A35: 29 | B35: =IF('Entries March.''25'!N36-'Entries March.''25'!N35<1,"0",'Entries March.''25'!N36-'Entries March.''25'!N35) -> 0 | C35: 0 | D35: 31.7625 | E35: =IF(D35=0,"0",(B35/D35)) -> 0 | F35: =IF(D35=0,"0",(C35/D35)) -> 0
A36: 30 | B36: =IF('Entries March.''25'!N37-'Entries March.''25'!N36<1,"0",'Entries March.''25'!N37-'Entries March.''25'!N36) -> 0 | C36: 0 | D36: 0 | E36: =IF(D36=0,"0",(B36/D36)) -> 0 | F36: =IF(D36=0,"0",(C36/D36)) -> 0
A37: 31 | B37: =IF('Entries March.''25'!N38-'Entries March.''25'!N37<1,"0",'Entries March.''25'!N38-'Entries March.''25'!N37) -> 42.06 | C37: 1700 | D37: 423.126 | E37: =IF(D37=0,"0",(B37/D37)) -> 0.099403015 | F37: =IF(D37=0,"0",(C37/D37)) -> 4.0177158 | G37: TARGET | H37: %
A38: MTD | B38: =SUM(B7:B37) -> 733.52 | C38: =SUM(C7:C37) -> 43400 | D38: =SUM(D7:D37) -> 6994.2849 | E38: =IF(D38=0,"0",(B38/D38)) -> 0.1048742 | F38: =IF(D38=0,"0",(C38/D38)) -> 6.2050661 | G38: 5 | H38: =F38/G38*100 -> 124.10132

Sheet Fuel 
A1: DAILY FUEL CONSUMPTION FOR MARCH 2025
A4: DATE | B4: Boiler 1 | C4: Boiler 1 | D4: Boiler 2 | E4: Boiler 2 | F4: Gen. | G4: Gen | H4: Boiler 1 sp. | I4: Boiler 2 sp. | J4: Gen. sp | K4: Daily cons. | L4: Total Prod.(HL) | M4: Fuel(Litres/HL)
B5: Cons ( l ) | C5: Hrs | D5: Cons ( l ) | E5: Hrs | F5: Cons ( l ) | G5: Hrs | H5: cons (l/hr) | I5: cons (l/hr) | J5: Cons.(l/hr) | K5: (litres)
B6: =IF('Entries March.''25'!B6=0,0,+'Entries March.''25'!B6-'Entries March.''25'!B5) -> 0
A7: 1 | B7: =IF('Entries March.''25'!B8-'Entries March.''25'!B7<1,"0",'Entries March.''25'!B8-'Entries March.''25'!B7) -> 410 | C7: =IF('Entries March.''25'!F8-'Entries March.''25'!F7<1,"0",'Entries March.''25'!F8-'Entries March.''25'!F7) -> 6.5 | D7: =IF('Entries March.''25'!C7=0,0,+'Entries March.''25'!C7-'Entries March.''25'!C6) -> 0 | E7: =IF('Entries March.''25'!G8-'Entries March.''25'!G7<1,"0",'Entries March.''25'!G8-'Entries March.''25'!G7) -> 0 | H7: =IF(C7=0,"0", B7/C7) -> 63.076923 | I7: =IF(E7=0,"0", D7/E7) -> 0 | J7: =IF(G7=0,"0", F7/G7) -> 0 | K7: =B7+D7+F7 -> 410 | L7: {=IF(TRANSPOSE('Daily KPIs'!B9:AF9)=0,"0",TRANSPOSE('Daily KPIs'!B9:AF9))} -> 0 | M7: =IF(L7=0,"0",(K7/L7)) -> 0
A8: 2 | B8: =IF('Entries March.''25'!B9-'Entries March.''25'!B8<1,"0",'Entries March.''25'!B9-'Entries March.''25'!B8) -> 540 | C8: =IF('Entries March.''25'!F9-'Entries March.''25'!F8<1,"0",'Entries March.''25'!F9-'Entries March.''25'!F8) -> 2.9 | D8: =IF('Entries March.''25'!C8=0,0,+'Entries March.''25'!C8-'Entries March.''25'!C7) -> 0 | E8: =IF('Entries March.''25'!G9-'Entries March.''25'!G8<1,"0",'Entries March.''25'!G9-'Entries March.''25'!G8) -> 0 | H8: =IF(C8=0,"0", B8/C8) -> 186.2069 | I8: =IF(E8=0,"0", D8/E8) -> 0 | J8: =IF(G8=0,"0", F8/G8) -> 0 | K8: =B8+D8+F8 -> 540 | L8: 0 | M8: =IF(L8=0,"0",(K8/L8)) -> 0
A9: 3 | B9: =IF('Entries March.''25'!B10-'Entries March.''25'!B9<1,"0",'Entries March.''25'!B10-'Entries March.''25'!B9) -> 2480 | C9: =IF('Entries March.''25'!F10-'Entries March.''25'!F9<1,"0",'Entries March.''25'!F10-'Entries March.''25'!F9) -> 18 | D9: =IF('Entries March.''25'!C9=0,0,+'Entries March.''25'!C9-'Entries March.''25'!C8) -> 0 | E9: =IF('Entries March.''25'!G10-'Entries March.''25'!G9<1,"0",'Entries March.''25'!G10-'Entries March.''25'!G9) -> 0 | H9: =IF(C9=0,"0", B9/C9) -> 137.77778 | I9: =IF(E9=0,"0", D9/E9) -> 0 | J9: =IF(G9=0,"0", F9/G9) -> 0 | K9: =B9+D9+F9 -> 2480 | L9: 356.4 | M9: =IF(L9=0,"0",(K9/L9)) -> 6.9584736
A10: 4 | B10: =IF('Entries March.''25'!B11-'Entries March.''25'!B10<1,"0",'Entries March.''25'!B11-'Entries March.''25'!B10) -> 3270 | C10: =IF('Entries March.''25'!F11-'Entries March.''25'!F10<1,"0",'Entries March.''25'!F11-'Entries March.''25'!F10) -> 22.3 | D10: =IF('Entries March.''25'!C12=0,0,+'Entries March.''25'!C12-'Entries March.''25'!C9) -> 0 | E10: =IF('Entries March.''25'!G11-'Entries March.''25'!G10<1,"0",'Entries March.''25'!G11-'Entries March.''25'!G10) -> 0 | H10: =IF(C10=0,"0", B10/C10) -> 146.63677 | I10: =IF(E10=0,"0", D10/E10) -> 0 | J10: =IF(G10=0,"0", F10/G10) -> 0 | K10: =B10+D10+F10 -> 3270 | L10: 476.982 | M10: =IF(L10=0,"0",(K10/L10)) -> 6.8556046
A11: 5 | B11: =IF('Entries March.''25'!B12-'Entries March.''25'!B11<1,"0",'Entries March.''25'!B12-'Entries March.''25'!B11) -> 3040 | C11: =IF('Entries March.''25'!F12-'Entries March.''25'!F11<1,"0",'Entries March.''25'!F12-'Entries March.''25'!F11) -> 20.8 | D11: =IF('Entries March.''25'!C11=0,0,+'Entries March.''25'!C11-'Entries March.''25'!C12) -> 0 | E11: =IF('Entries March.''25'!G12-'Entries March.''25'!G11<1,"0",'Entries March.''25'!G12-'Entries March.''25'!G11) -> 0 | H11: =IF(C11=0,"0", B11/C11) -> 146.15385 | I11: =IF(E11=0,"0", D11/E11) -> 0 | J11: =IF(G11=0,"0", F11/G11) -> 0 | K11: =B11+D11+F11 -> 3040 | L11: 345.114 | M11: =IF(L11=0,"0",(K11/L11)) -> 8.8086835
A12: 6 | B12: =IF('Entries March.''25'!B13-'Entries March.''25'!B12<1,"0",'Entries March.''25'!B13-'Entries March.''25'!B12) -> 2720 | C12: =IF('Entries March.''25'!F13-'Entries March.''25'!F12<1,"0",'Entries March.''25'!F13-'Entries March.''25'!F12) -> 20.2 | D12: =IF('Entries March.''25'!C13=0,0,+'Entries March.''25'!C13-'Entries March.''25'!C11) -> 0 | E12: =IF('Entries March.''25'!G13-'Entries March.''25'!G12<1,"0",'Entries March.''25'!G13-'Entries March.''25'!G12) -> 0 | H12: =IF(C12=0,"0", B12/C12) -> 134.65347 | I12: =IF(E12=0,"0", D12/E12) -> 0 | J12: =IF(G12=0,"0", F12/G12) -> 0 | K12: =B12+D12+F12 -> 2720 | L12: 383.79 | M12: =IF(L12=0,"0",(K12/L12)) -> 7.0872092
A13: 7 | B13: =IF('Entries March.''25'!B14-'Entries March.''25'!B13<1,"0",'Entries March.''25'!B14-'Entries March.''25'!B13) -> 2380 | C13: =IF('Entries March.''25'!F14-'Entries March.''25'!F13<1,"0",'Entries March.''25'!F14-'Entries March.''25'!F13) -> 17.5 | D13: =IF('Entries March.''25'!C14=0,0,+'Entries March.''25'!C14-'Entries March.''25'!C12) -> 0 | E13: =IF('Entries March.''25'!G14-'Entries March.''25'!G13<1,"0",'Entries March.''25'!G14-'Entries March.''25'!G13) -> 0 | H13: =IF(C13=0,"0", B13/C13) -> 136 | I13: =IF(E13=0,"0", D13/E13) -> 0 | J13: =IF(G13=0,"0", F13/G13) -> 0 | K13: =B13+D13+F13 -> 2380 | L13: 328.482 | M13: =IF(L13=0,"0",(K13/L13)) -> 7.2454503
A14: 8 | B14: =IF('Entries March.''25'!B15-'Entries March.''25'!B14<1,"0",'Entries March.''25'!B15-'Entries March.''25'!B14) -> 1000 | C14: =IF('Entries March.''25'!F15-'Entries March.''25'!F14<1,"0",'Entries March.''25'!F15-'Entries March.''25'!F14) -> 8.6 | D14: =IF('Entries March.''25'!C14=0,0,+'Entries March.''25'!C14-'Entries March.''25'!#REF!) -> 0 | E14: =IF('Entries March.''25'!G15-'Entries March.''25'!G14<1,"0",'Entries March.''25'!G15-'Entries March.''25'!G14) -> 0 | H14: =IF(C14=0,"0", B14/C14) -> 116.27907 | I14: =IF(E14=0,"0", D14/E14) -> 0 | J14: =IF(G14=0,"0", F14/G14) -> 0 | K14: =B14+D14+F14 -> 1000 | L14: 0 | M14: =IF(L14=0,"0",(K14/L14)) -> 0
A15: 9 | B15: =IF('Entries March.''25'!B16-'Entries March.''25'!B15<1,"0",'Entries March.''25'!B16-'Entries March.''25'!B15) -> 100 | C15: =IF('Entries March.''25'!F16-'Entries March.''25'!F15<1,"0",'Entries March.''25'!F16-'Entries March.''25'!F15) -> 0 | D15: =IF('Entries March.''25'!C15=0,0,+'Entries March.''25'!C15-'Entries March.''25'!C14) -> 0 | E15: =IF('Entries March.''25'!G16-'Entries March.''25'!G15<1,"0",'Entries March.''25'!G16-'Entries March.''25'!G15) -> 0 | H15: =IF(C15=0,"0", B15/C15) -> 0 | I15: =IF(E15=0,"0", D15/E15) -> 0 | J15: =IF(G15=0,"0", F15/G15) -> 0 | K15: =B15+D15+F15 -> 100 | L15: 0 | M15: =IF(L15=0,"0",(K15/L15)) -> 0
A16: 10 | B16: =IF('Entries March.''25'!B17-'Entries March.''25'!B16<1,"0",'Entries March.''25'!B17-'Entries March.''25'!B16) -> 3100 | C16: =IF('Entries March.''25'!F17-'Entries March.''25'!F16<1,"0",'Entries March.''25'!F17-'Entries March.''25'!F16) -> 19.5 | D16: =IF('Entries March.''25'!C16=0,0,+'Entries March.''25'!C16-'Entries March.''25'!C15) -> 0 | E16: =IF('Entries March.''25'!G17-'Entries March.''25'!G16<1,"0",'Entries March.''25'!G17-'Entries March.''25'!G16) -> 0 | H16: =IF(C16=0,"0", B16/C16) -> 158.97436 | I16: =IF(E16=0,"0", D16/E16) -> 0 | J16: =IF(G16=0,"0", F16/G16) -> 0 | K16: =B16+D16+F16 -> 3100 | L16: 228.36 | M16: =IF(L16=0,"0",(K16/L16)) -> 13.575057
A17: 11 | B17: =IF('Entries March.''25'!B18-'Entries March.''25'!B17<1,"0",'Entries March.''25'!B18-'Entries March.''25'!B17) -> 3040 | C17: =IF('Entries March.''25'!F18-'Entries March.''25'!F17<1,"0",'Entries March.''25'!F18-'Entries March.''25'!F17) -> 21.9 | D17: =IF('Entries March.''25'!C17=0,0,+'Entries March.''25'!C17-'Entries March.''25'!C16) -> 0 | E17: =IF('Entries March.''25'!G18-'Entries March.''25'!G17<1,"0",'Entries March.''25'!G18-'Entries March.''25'!G17) -> 0 | H17: =IF(C17=0,"0", B17/C17) -> 138.81279 | I17: =IF(E17=0,"0", D17/E17) -> 0 | J17: =IF(G17=0,"0", F17/G17) -> 0 | K17: =B17+D17+F17 -> 3040 | L17: 187.11 | M17: =IF(L17=0,"0",(K17/L17)) -> 16.247127
A18: 12 | B18: =IF('Entries March.''25'!B19-'Entries March.''25'!B18<1,"0",'Entries March.''25'!B19-'Entries March.''25'!B18) -> 2800 | C18: =IF('Entries March.''25'!F19-'Entries March.''25'!F18<1,"0",'Entries March.''25'!F19-'Entries March.''25'!F18) -> 21.3 | D18: =IF('Entries March.''25'!C18=0,0,+'Entries March.''25'!C18-'Entries March.''25'!C17) -> 0 | E18: =IF('Entries March.''25'!G19-'Entries March.''25'!G18<1,"0",'Entries March.''25'!G19-'Entries March.''25'!G18) -> 0 | H18: =IF(C18=0,"0", B18/C18) -> 131.4554 | I18: =IF(E18=0,"0", D18/E18) -> 0 | J18: =IF(G18=0,"0", F18/G18) -> 0 | K18: =B18+D18+F18 -> 2800 | L18: 135.036 | M18: =IF(L18=0,"0",(K18/L18)) -> 20.735211
A19: 13 | B19: =IF('Entries March.''25'!B20-'Entries March.''25'!B19<1,"0",'Entries March.''25'!B20-'Entries March.''25'!B19) -> 3010 | C19: =IF('Entries March.''25'!F20-'Entries March.''25'!F19<1,"0",'Entries March.''25'!F20-'Entries March.''25'!F19) -> 21 | D19: =IF('Entries March.''25'!C19=0,0,+'Entries March.''25'!C19-'Entries March.''25'!C18) -> 0 | E19: =IF('Entries March.''25'!G20-'Entries March.''25'!G19<1,"0",'Entries March.''25'!G20-'Entries March.''25'!G19) -> 0 | H19: =IF(C19=0,"0", B19/C19) -> 143.33333 | I19: =IF(E19=0,"0", D19/E19) -> 0 | J19: =IF(G19=0,"0", F19/G19) -> 0 | K19: =B19+D19+F19 -> 3010 | L19: 360.624 | M19: =IF(L19=0,"0",(K19/L19)) -> 8.3466436
A20: 14 | B20: =IF('Entries March.''25'!B21-'Entries March.''25'!B20<1,"0",'Entries March.''25'!B21-'Entries March.''25'!B20) -> 2410 | C20: =IF('Entries March.''25'!F21-'Entries March.''25'!F20<1,"0",'Entries March.''25'!F21-'Entries March.''25'!F20) -> 18.5 | D20: =IF('Entries March.''25'!C20=0,0,+'Entries March.''25'!C20-'Entries March.''25'!C19) -> 0 | E20: =IF('Entries March.''25'!G21-'Entries March.''25'!G20<1,"0",'Entries March.''25'!G21-'Entries March.''25'!G20) -> 0 | H20: =IF(C20=0,"0", B20/C20) -> 130.27027 | I20: =IF(E20=0,"0", D20/E20) -> 0 | J20: =IF(G20=0,"0", F20/G20) -> 0 | K20: =B20+D20+F20 -> 2410 | L20: 272.448 | M20: =IF(L20=0,"0",(K20/L20)) -> 8.8457247
A21: 15 | B21: =IF('Entries March.''25'!B22-'Entries March.''25'!B21<1,"0",'Entries March.''25'!B22-'Entries March.''25'!B21) -> 0 | C21: =IF('Entries March.''25'!F22-'Entries March.''25'!F21<1,"0",'Entries March.''25'!F22-'Entries March.''25'!F21) -> 0 | D21: =IF('Entries March.''25'!C21=0,0,+'Entries March.''25'!C21-'Entries March.''25'!C20) -> 0 | E21: =IF('Entries March.''25'!G22-'Entries March.''25'!G21<1,"0",'Entries March.''25'!G22-'Entries March.''25'!G21) -> 0 | H21: =IF(C21=0,"0", B21/C21) -> 0 | I21: =IF(E21=0,"0", D21/E21) -> 0 | J21: =IF(G21=0,"0", F21/G21) -> 0 | K21: =B21+D21+F21 -> 0 | L21: 0 | M21: =IF(L21=0,"0",(K21/L21)) -> 0
A22: 16 | B22: =IF('Entries March.''25'!B23-'Entries March.''25'!B22<1,"0",'Entries March.''25'!B23-'Entries March.''25'!B22) -> 1320 | C22: =IF('Entries March.''25'!F23-'Entries March.''25'!F22<1,"0",'Entries March.''25'!F23-'Entries March.''25'!F22) -> 8 | D22: =IF('Entries March.''25'!C22=0,0,+'Entries March.''25'!C22-'Entries March.''25'!C21) -> 0 | E22: =IF('Entries March.''25'!G23-'Entries March.''25'!G22<1,"0",'Entries March.''25'!G23-'Entries March.''25'!G22) -> 0 | H22: =IF(C22=0,"0", B22/C22) -> 165 | I22: =IF(E22=0,"0", D22/E22) -> 0 | J22: =IF(G22=0,"0", F22/G22) -> 0 | K22: =B22+D22+F22 -> 1320 | L22: 0 | M22: =IF(L22=0,"0",(K22/L22)) -> 0
