Workbook
Name ProductList: [1]November15!$R$3:$R$9
Name ProductList: [2]November15!$R$3:$R$9

Sheet Dec 18th
T1: P.G. | V1: Hot Time | X1: Process Time | Z1: Cooling Time
B2: Brewing Department Daily Process Loss Report | T2: Lower | U2: Upper | V2: Lower | W2: Upper | X2: Lower | Y2: Upper | Z2: Lower | AA2: Upper
S3: CARIB | T3: 11.6 | U3: 12 | V3: 0 | W3: 0.11805556 | X3: 0.17361111 | Y3: 0.21180556 | Z3: 0 | AA3: 60 | AC3: HR- PISNER
B4: Date: | C4: 45278 | J4: LOT WORT COLOUR: 3.4 | M4: Filter Sheets (Target 20 days) | S4: STAG | T4: 11.6 | U4: 12 | V4: 0 | W4: 0.11805556 | X4: 0.17361111 | Y4: 0.21180556 | Z4: 0 | AA4: 60
M5: Double | N5: Single | S5: GUINNESS | T5: 17 | U5: 17.5 | V5: 0 | W5: 0.10763889 | X5: 0.19444444 | Y5: 0.23263889 | Z5: 0 | AA5: 60
J6: MALT LOT: Lot 8 | L6: Sheet Day | S6: MACKESON | T6: 13.3 | U6: 13.5 | V6: 0 | W6: 0.12905093 | X6: 0.22222222 | Y6: 0.25347222 | Z6: 0
S7: STARMALT | T7: 17.1 | U7: 17.5 | V7: 0 | W7: 0.13605324 | X7: 0.20833333 | Y7: 0.24305556 | Z7: 0 | AA7: 60
B8: Brand | C8: Brew no. | D8: Kett. Hls | E8: Wort | F8: Cool Time(Mins) | G8: Cast. P.G. (Lab Result) | H8: Cast P.G. (Cellar Operator)-gravity | I8: Extr. Rec (79.1%) | J8: Theor. Extr. (77.5%) | K8: Boil Off /Vol. (4-6%) | L8: Boil Time | M8: Total Hot | N8: Brewing | P8: Comments | Q8: Actual Pilsen Malt | S8: Hurricane Reef | T8: 16.6 | U8: 17 | V8: 0 | W8: 0.12905093 | X8: 0.22222222 | Y8: 0.25347222 | Z8: 0
E9: Meter (Hls) | F9: Target(< 60Mins) | M9: Time | S9: VITAMALT | T9: 14.4 | U9: 14.6 | V9: 0 | W9: 0.13905093 | X9: 0.19097222 | Y9: 0.22569444 | Z9: 0 | AA9: 75
S10: =B10 -> 0 | T10: =VLOOKUP($B10,$S$3:$Y$9,2,FALSE) -> #N/A | U10: =VLOOKUP($B10,$S$3:$Y$9,3,FALSE) -> #N/A | V10: =VLOOKUP($B10,$S$3:$Y$9,4,FALSE) -> #N/A | W10: =VLOOKUP($B10,$S$3:$Y$9,5,FALSE) -> #N/A | X10: =VLOOKUP($B10,$S$3:$Y$9,6,FALSE) -> #N/A | Y10: =VLOOKUP($B10,$S$3:$Y$9,7,FALSE) -> #N/A | Z10: =VLOOKUP($B10,$S$3:$AA$9,8,FALSE) -> #N/A | AA10: =VLOOKUP($B10,$S$3:$AA$9,9,FALSE) -> #N/A
S11: =B11 -> 0 | T11: =VLOOKUP($B11,$S$3:$Y$9,2,FALSE) -> #N/A | U11: =VLOOKUP($B11,$S$3:$Y$9,3,FALSE) -> #N/A | V11: =VLOOKUP($B11,$S$3:$Y$9,4,FALSE) -> #N/A | W11: =VLOOKUP($B11,$S$3:$Y$9,5,FALSE) -> #N/A | X11: =VLOOKUP($B11,$S$3:$Y$9,6,FALSE) -> #N/A | Y11: =VLOOKUP($B11,$S$3:$Y$9,7,FALSE) -> #N/A | Z11: =VLOOKUP($B11,$S$3:$AA$9,8,FALSE) -> #N/A | AA11: =VLOOKUP($B11,$S$3:$AA$9,9,FALSE) -> #N/A
S12: =B12 -> 0 | T12: =VLOOKUP($B12,$S$3:$Y$9,2,FALSE) -> #N/A | U12: =VLOOKUP($B12,$S$3:$Y$9,3,FALSE) -> #N/A | V12: =VLOOKUP($B12,$S$3:$Y$9,4,FALSE) -> #N/A | W12: =VLOOKUP($B12,$S$3:$Y$9,5,FALSE) -> #N/A | X12: =VLOOKUP($B12,$S$3:$Y$9,6,FALSE) -> #N/A | Y12: =VLOOKUP($B12,$S$3:$Y$9,7,FALSE) -> #N/A | Z12: =VLOOKUP($B12,$S$3:$AA$9,8,FALSE) -> #N/A | AA12: =VLOOKUP($B12,$S$3:$AA$9,9,FALSE) -> #N/A
S13: =B13 -> 0 | T13: =VLOOKUP($B13,$S$3:$Y$9,2,FALSE) -> #N/A | U13: =VLOOKUP($B13,$S$3:$Y$9,3,FALSE) -> #N/A | V13: =VLOOKUP($B13,$S$3:$Y$9,4,FALSE) -> #N/A | W13: =VLOOKUP($B13,$S$3:$Y$9,5,FALSE) -> #N/A | X13: =VLOOKUP($B13,$S$3:$Y$9,6,FALSE) -> #N/A | Y13: =VLOOKUP($B13,$S$3:$Y$9,7,FALSE) -> #N/A | Z13: =VLOOKUP($B13,$S$3:$AA$9,8,FALSE) -> #N/A | AA13: =VLOOKUP($B13,$S$3:$AA$9,9,FALSE) -> #N/A
S14: =B14 -> 0 | T14: =VLOOKUP($B14,$S$3:$Y$9,2,FALSE) -> #N/A | U14: =VLOOKUP($B14,$S$3:$Y$9,3,FALSE) -> #N/A | V14: =VLOOKUP($B14,$S$3:$Y$9,4,FALSE) -> #N/A | W14: =VLOOKUP($B14,$S$3:$Y$9,5,FALSE) -> #N/A | X14: =VLOOKUP($B14,$S$3:$Y$9,6,FALSE) -> #N/A | Y14: =VLOOKUP($B14,$S$3:$Y$9,7,FALSE) -> #N/A | Z14: =VLOOKUP($B14,$S$3:$AA$9,8,FALSE) -> #N/A | AA14: =VLOOKUP($B14,$S$3:$AA$9,9,FALSE) -> #N/A
S15: =B15 -> 0 | T15: =VLOOKUP($B15,$S$3:$Y$9,2,FALSE) -> #N/A | U15: =VLOOKUP($B15,$S$3:$Y$9,3,FALSE) -> #N/A | V15: =VLOOKUP($B15,$S$3:$Y$9,4,FALSE) -> #N/A | W15: =VLOOKUP($B15,$S$3:$Y$9,5,FALSE) -> #N/A | X15: =VLOOKUP($B15,$S$3:$Y$9,6,FALSE) -> #N/A | Y15: =VLOOKUP($B15,$S$3:$Y$9,7,FALSE) -> #N/A | Z15: =VLOOKUP($B15,$S$3:$AA$9,8,FALSE) -> #N/A | AA15: =VLOOKUP($B15,$S$3:$AA$9,9,FALSE) -> #N/A
S16: =B16 -> 0 | T16: =VLOOKUP($B16,$S$3:$Y$9,2,FALSE) -> #N/A | U16: =VLOOKUP($B16,$S$3:$Y$9,3,FALSE) -> #N/A | V16: =VLOOKUP($B16,$S$3:$Y$9,4,FALSE) -> #N/A | W16: =VLOOKUP($B16,$S$3:$Y$9,5,FALSE) -> #N/A | X16: =VLOOKUP($B16,$S$3:$Y$9,6,FALSE) -> #N/A | Y16: =VLOOKUP($B16,$S$3:$Y$9,7,FALSE) -> #N/A | Z16: =VLOOKUP($B16,$S$3:$AA$9,8,FALSE) -> #N/A | AA16: =VLOOKUP($B16,$S$3:$AA$9,9,FALSE) -> #N/A
S17: =B17 -> 0 | T17: =VLOOKUP($B17,$S$3:$Y$9,2,FALSE) -> #N/A | U17: =VLOOKUP($B17,$S$3:$Y$9,3,FALSE) -> #N/A | V17: =VLOOKUP($B17,$S$3:$Y$9,4,FALSE) -> #N/A | W17: =VLOOKUP($B17,$S$3:$Y$9,5,FALSE) -> #N/A | X17: =VLOOKUP($B17,$S$3:$Y$9,6,FALSE) -> #N/A | Y17: =VLOOKUP($B17,$S$3:$Y$9,7,FALSE) -> #N/A | Z17: =VLOOKUP($B17,$S$3:$AA$9,8,FALSE) -> #N/A | AA17: =VLOOKUP($B17,$S$3:$AA$9,9,FALSE) -> #N/A
S18: =B18 -> 0 | T18: =VLOOKUP($B18,$S$3:$Y$9,2,FALSE) -> #N/A | U18: =VLOOKUP($B18,$S$3:$Y$9,3,FALSE) -> #N/A | V18: =VLOOKUP($B18,$S$3:$Y$9,4,FALSE) -> #N/A | W18: =VLOOKUP($B18,$S$3:$Y$9,5,FALSE) -> #N/A | X18: =VLOOKUP($B18,$S$3:$Y$9,6,FALSE) -> #N/A | Y18: =VLOOKUP($B18,$S$3:$Y$9,7,FALSE) -> #N/A | Z18: =VLOOKUP($B18,$S$3:$AA$9,8,FALSE) -> #N/A | AA18: =VLOOKUP($B18,$S$3:$AA$9,9,FALSE) -> #N/A
S19: =B19 -> 0 | T19: =VLOOKUP($B19,$S$3:$Y$9,2,FALSE) -> #N/A | U19: =VLOOKUP($B19,$S$3:$Y$9,3,FALSE) -> #N/A | V19: =VLOOKUP($B19,$S$3:$Y$9,4,FALSE) -> #N/A | W19: =VLOOKUP($B19,$S$3:$Y$9,5,FALSE) -> #N/A | X19: =VLOOKUP($B19,$S$3:$Y$9,6,FALSE) -> #N/A | Y19: =VLOOKUP($B19,$S$3:$Y$9,7,FALSE) -> #N/A | Z19: =VLOOKUP($B19,$S$3:$AA$9,8,FALSE) -> #N/A | AA19: =VLOOKUP($B19,$S$3:$AA$9,9,FALSE) -> #N/A
S20: =B20 -> 0 | T20: =VLOOKUP($B20,$S$3:$Y$9,2,FALSE) -> #N/A | U20: =VLOOKUP($B20,$S$3:$Y$9,3,FALSE) -> #N/A | V20: =VLOOKUP($B20,$S$3:$Y$9,4,FALSE) -> #N/A | W20: =VLOOKUP($B20,$S$3:$Y$9,5,FALSE) -> #N/A | X20: =VLOOKUP($B20,$S$3:$Y$9,6,FALSE) -> #N/A | Y20: =VLOOKUP($B20,$S$3:$Y$9,7,FALSE) -> #N/A | Z20: =VLOOKUP($B20,$S$3:$AA$9,8,FALSE) -> #N/A | AA20: =VLOOKUP($B20,$S$3:$AA$9,9,FALSE) -> #N/A
S21: =B21 -> 0 | T21: =VLOOKUP($B21,$S$3:$Y$9,2,FALSE) -> #N/A | U21: =VLOOKUP($B21,$S$3:$Y$9,3,FALSE) -> #N/A | V21: =VLOOKUP($B21,$S$3:$Y$9,4,FALSE) -> #N/A | W21: =VLOOKUP($B21,$S$3:$Y$9,5,FALSE) -> #N/A | X21: =VLOOKUP($B21,$S$3:$Y$9,6,FALSE) -> #N/A | Y21: =VLOOKUP($B21,$S$3:$Y$9,7,FALSE) -> #N/A | Z21: =VLOOKUP($B21,$S$3:$AA$9,8,FALSE) -> #N/A | AA21: =VLOOKUP($B21,$S$3:$AA$9,9,FALSE) -> #N/A
... S47: =B47 -> 0 | T47: =VLOOKUP($B47,$S$3:$Y$9,2,FALSE) -> #N/A | U47: =VLOOKUP($B47,$S$3:$Y$9,3,FALSE) -> #N/A | V47: =VLOOKUP($B47,$S$3:$Y$9,4,FALSE) -> #N/A | W47: =VLOOKUP($B47,$S$3:$Y$9,5,FALSE) -> #N/A | X47: =VLOOKUP($B47,$S$3:$Y$9,6,FALSE) -> #N/A | Y47: =VLOOKUP($B47,$S$3:$Y$9,7,FALSE) -> #N/A | Z47: =VLOOKUP($B47,$S$3:$AA$9,8,FALSE) -> #N/A | AA47: =VLOOKUP($B47,$S$3:$AA$9,9,FALSE) -> #N/A
I48: EXTRACT RECOVERY
B49: BRAND | D49: BBT P.G./ O.G | I49: Brand | J49: Actual | K49: MTD No. of Brews | L49: MTD | M49: YTD | N49: Target
B50: STAG | C50: 11.8 | D50: 11.73 | I50: CARIB | K50: =COUNTA([3]Brewhouse!$A$1596:$A$1619) -> 24 | L50: =AVERAGE([3]Brewhouse!$AU$1529,[3]Brewhouse!$AU$1531:$AU$1594,[3]Brewhouse!$AU$1596:$AU$1619) -> 98.205761 | M50: =AVERAGE([3]Brewhouse!$AU$849:$AU$924,[3]Brewhouse!$AU$926:$AU$971,[3]Brewhouse!$AU$973:$AU$1066,[3]Brewhouse!$AU$1068:$AU$1111,[3]Brewhouse!$AU$1113:$AU$1132,[3]Brewhouse!$AU$1134:$AU$1167,[3]Brewhouse!$AU$1169:$AU$1230,[3]Brewhouse!$AU$1232:$AU$1299,[3]Brewhouse!$AU$1301:$AU$1363,[3]Brewhouse!$AU$1365:$AU$1444,[3]Brewhouse!$AU$1446:$AU$1527,[3]Brewhouse!$AU$1529,[3]Brewhouse!$AU$1531:$AU$1594,[3]Brewhouse!$AU$1596:$AU$1619) -> 98.381806 | N50: 98
C51: 11.9 | I51: STAG | K51: =COUNTA([4]Brewhouse!$A$976:$A$1007) -> 32 | L51: =AVERAGE([4]Brewhouse!$AS$976:$AS$979,[4]Brewhouse!$AS$981:$AS$1007) -> 98.538567 | M51: =AVERAGE([4]Brewhouse!$AS$577:$AS$618,[4]Brewhouse!$AS$620:$AS$651,[4]Brewhouse!$AS$653:$AS$696,[4]Brewhouse!$AS$698:$AS$708,[4]Brewhouse!$AS$710:$AS$733,[4]Brewhouse!$AS$735:$AS$777,[4]Brewhouse!$AS$779:$AS$822,[4]Brewhouse!$AS$824:$AS$863,[4]Brewhouse!$AS$865:$AS$974,[4]Brewhouse!$AS$976:$AS$979,[4]Brewhouse!$AS$981:$AS$1007) -> 98.489671 | N51: 98
I52: GUINNESS | K52: =COUNTA([5]Brewhouse!$A$282:$A$289) -> 8 | L52: =AVERAGE([5]Brewhouse!$AU$269:$AU$279,[5]Brewhouse!$AU$282:$AU$289) -> 96.186177 | M52: =AVERAGE([5]Brewhouse!$AU$161:$AU$176,[5]Brewhouse!$AU$178:$AU$195,[5]Brewhouse!$AU$197:$AU$208,[5]Brewhouse!$AU$210:$AU$221,[5]Brewhouse!$AU$223:$AU$232,[5]Brewhouse!$AU$234:$AU$279,[5]Brewhouse!$AU$282:$AU$289) -> 96.64916 | N52: 98
I53: VITAMALT | K53: =COUNTA([6]Brewhouse!$A$158:$A$163) -> 6 | L53: =AVERAGE([6]Brewhouse!$AU$158:$AU$163) -> 94.60305 | M53: =AVERAGE([6]Brewhouse!$AU$91:$AU$101,[6]Brewhouse!$AU$103:$AU$112,[6]Brewhouse!$AU$114:$AU$123,[6]Brewhouse!$AU$125:$AU$134,[6]Brewhouse!$AU$136:$AU$145,[6]Brewhouse!$AU$147:$AU$156,[6]Brewhouse!$AU$158:$AU$163) -> 96.240014 | N53: 98
I54: MAXIMALT | N54: 98
I55: MACKESON | M55: =AVERAGE([7]Brewhouse!$AT$74:$AT$79) -> 93.959836 | N55: 98
I56: STARMALT | K56: =COUNTA([8]Brewhouse!$A$249:$A$254) -> 6 | L56: =AVERAGE([8]Brewhouse!$AY$249:$AY$254) -> 99.681996 | M56: =AVERAGE([8]Brewhouse!$AY$138:$AY$143,[8]Brewhouse!$AY$145:$AY$153,[8]Brewhouse!$AY$155,[8]Brewhouse!$AY$156:$AY$174,[8]Brewhouse!$AY$176:$AY$185,[8]Brewhouse!$AY$187:$AY$198,[8]Brewhouse!$AY$200:$AY$247,[8]Brewhouse!$AY$249:$AY$254) -> 98.774703 | N56: 98
I57: HR- P | M57: =AVERAGE([9]Brewhouse!$AW$13:$AW$14,[9]Brewhouse!$AW$16:$AW$17) -> 92.042628 | N57: 98
I58: Hurricane Reef | M58: =AVERAGE([9]Brewhouse!$AW$13:$AW$14) -> 88.376943 | N58: 98
K59: =SUM(K50:K58) -> 76 | L59: =((L50*K50)+(L51*K51)+(L52*K52)+(L53*K53)+(L54*K54)+(K57*L57)+(L55*K55)+(L56*K56)+(L58*K58))/(K59) -> 97.965422 | M59: =AVERAGE('[10]Closing- January 2023'!$L$42,'[11]Feb. 28th'!$L$42,'[12]March 31st'!$L$75,'[13]Apri 28th'!$L$51,L59) -> 98.06926 | N59: 98
J62: Daily Brewing Plan
J63: Brand | K63: Brews Achieved | L63: Average Brews per day
J64: CARIB | L64: MTD | M64: YTD | N64: TARGET
J65: STAG | K65: 5 | L65: =AVERAGE(#REF!,#REF!,K74,#REF!,#REF!,#REF!,#REF!,#REF!,#REF!,#REF!,#REF!) -> #REF! | M65: =AVERAGE(6,6,'[12]March 31st'!$L$80,'[14]June 30th '!$L$71,6,L65,'[15]July 31st'!$L$108,'[16]Aug 30th'!$L$124,7,[17]Oct.31st!$L$51) -> #REF! | N65: 9
J66: GUINN
J67: VITAMALT
...

Sheet May 2nd -4th
S1: P.G. | U1: Hot Time | W1: Process Time | Y1: Cooling Time
B2: Brewing Department Daily Process Loss Report | S2: Lower | T2: Upper | U2: Lower | V2: Upper | W2: Lower | X2: Upper | Y2: Lower | Z2: Upper
R3: CARIB | S3: 11.6 | T3: 12 | U3: 0 | V3: 0.11805556 | W3: 0.22569444 | X3: 0.26388889 | Y3: 0 | Z3: 60 | AB3: HR- PISNER
B4: Date: | C4: 45782 | J4: LOT WORT COLOUR: 3.5 | M4: Filter Sheets (Target 20 days) | R4: STAG | S4: 11.6 | T4: 12 | U4: 0 | V4: 0.11805556 | W4: 0.22569444 | X4: 0.26388889 | Y4: 0 | Z4: 60
M5: Double | N5: Single | R5: GUINNESS | S5: 17 | T5: 17.5 | U5: 0 | V5: 0.10763889 | W5: 0.24652778 | X5: 0.28472222 | Y5: 0 | Z5: 60
J6: MALT LOT: Lot 35 | L6: Sheet Day | R6: MACKESON | S6: 13.3 | T6: 13.5 | U6: 0 | V6: 0.12905093 | W6: 0.27430556 | X6: 0.30208333 | Y6: 0
R7: STARMALT | S7: 17.1 | T7: 17.5 | U7: 0 | V7: 0.13605324 | W7: 0.27430556 | X7: 0.30902778 | Y7: 0 | Z7: 60
B8: Brand | C8: Brew no. | D8: Kett. Hls | E8: Wort | F8: Cool Time(Mins) | G8: Cast. P.G. (Lab Result) | H8: Cast P.G. (Cellar Operator)-gravity | I8: Extr. Rec (78.95%) | J8: Theor. Extr. (77.5%) | K8: Boil Off /Vol. (4-6%) | L8: Boil Time | M8: Total Hot | N8: Brewing | O8: Operator | P8: Actual Pilsen Malt | R8: Hurricane Reef | S8: 16.6 | T8: 17 | U8: 0 | V8: 0.12905093 | W8: 0.27430556 | X8: 0.30208333 | Y8: 0
E9: Meter (Hls) | F9: Target(< 60Mins) | M9: Time | R9: VITAMALT | S9: 14.4 | T9: 14.6 | U9: 0 | V9: 0.13905093 | W9: 0.26041667 | X9: 0.29513889 | Y9: 0 | Z9: 75
B10: May 2nd | R10: =B10 -> May 2nd | S10: =VLOOKUP($B10,$R$3:$X$9,2,FALSE) -> #N/A | T10: =VLOOKUP($B10,$R$3:$X$9,3,FALSE) -> #N/A | U10: =VLOOKUP($B10,$R$3:$X$9,4,FALSE) -> #N/A | V10: =VLOOKUP($B10,$R$3:$X$9,5,FALSE) -> #N/A | W10: =VLOOKUP($B10,$R$3:$X$9,6,FALSE) -> #N/A | X10: =VLOOKUP($B10,$R$3:$X$9,7,FALSE) -> #N/A | Y10: =VLOOKUP($B10,$R$3:$Z$9,8,FALSE) -> #N/A | Z10: =VLOOKUP($B10,$R$3:$Z$9,9,FALSE) -> #N/A
B11: CARIB | C11: =[22]Brewhouse!$A408 -> CA303 | D11: =[22]Brewhouse!$AF408 -> 54.3 | E11: =[22]Brewhouse!$AI408 -> 50.2 | F11: =[22]Brewhouse!$V408 -> 63 | G11: =[22]Brewhouse!$AG408 -> 11.7 | H11: 11.7 | I11: =[22]Brewhouse!$AU408 -> 95.631382 | J11: =[22]Brewhouse!$AV408 -> 97.269006 | K11: =[22]Brewhouse!$Q408 -> 8.25 | L11: =[22]Brewhouse!$P408 -> 56 | M11: =[22]Brewhouse!$U408-[22]Brewhouse!$T408 -> 0.11180556 | N11: =[22]Brewhouse!$Z408 -> 0.25069444 | O11: =[22]Brewhouse!$AX408 -> R. Sookram | R11: =B11 -> CARIB | S11: =VLOOKUP($B11,$R$3:$X$9,2,FALSE) -> 11.6 | T11: =VLOOKUP($B11,$R$3:$X$9,3,FALSE) -> 12 | U11: =VLOOKUP($B11,$R$3:$X$9,4,FALSE) -> 0 | V11: =VLOOKUP($B11,$R$3:$X$9,5,FALSE) -> 0.11805556 | W11: =VLOOKUP($B11,$R$3:$X$9,6,FALSE) -> 0.22569444 | X11: =VLOOKUP($B11,$R$3:$X$9,7,FALSE) -> 0.26388889 | Y11: =VLOOKUP($B11,$R$3:$Z$9,8,FALSE) -> 0 | Z11: =VLOOKUP($B11,$R$3:$Z$9,9,FALSE) -> 60
B12: CARIB | C12: =[22]Brewhouse!$A409 -> CA304 | D12: =[22]Brewhouse!$AF409 -> 54.9 | E12: =[22]Brewhouse!$AI409 -> 51.3 | F12: =[22]Brewhouse!$V409 -> 58 | G12: =[22]Brewhouse!$AG409 -> 11.9 | H12: 11.8 | I12: =[22]Brewhouse!$AU409 -> 99.607342 | J12: =[22]Brewhouse!$AV409 -> 101.31287 | K12: =[22]Brewhouse!$Q409 -> 5.9074733 | L12: =[22]Brewhouse!$P409 -> 57 | M12: =[22]Brewhouse!$U409-[22]Brewhouse!$T409 -> 0.099305556 | N12: =[22]Brewhouse!$Z409 -> 0.24166667 | O12: =[22]Brewhouse!$AX409 -> R. Sookram | R12: =B12 -> CARIB | S12: =VLOOKUP($B12,$R$3:$X$9,2,FALSE) -> 11.6 | T12: =VLOOKUP($B12,$R$3:$X$9,3,FALSE) -> 12 | U12: =VLOOKUP($B12,$R$3:$X$9,4,FALSE) -> 0 | V12: =VLOOKUP($B12,$R$3:$X$9,5,FALSE) -> 0.11805556 | W12: =VLOOKUP($B12,$R$3:$X$9,6,FALSE) -> 0.22569444 | X12: =VLOOKUP($B12,$R$3:$X$9,7,FALSE) -> 0.26388889 | Y12: =VLOOKUP($B12,$R$3:$Z$9,8,FALSE) -> 0 | Z12: =VLOOKUP($B12,$R$3:$Z$9,9,FALSE) -> 60
B13: CARIB | C13: =[22]Brewhouse!$A410 -> CA305 | D13: =[22]Brewhouse!$AF410 -> 53.5 | E13: =[22]Brewhouse!$AI410 -> 49.8 | F13: =[22]Brewhouse!$V410 -> 57 | G13: =[22]Brewhouse!$AG410 -> 11.9 | H13: 11.8 | I13: =[22]Brewhouse!$AU410 -> 96.933536 | J13: =[22]Brewhouse!$AV410 -> 98.592914 | K13: =[22]Brewhouse!$Q410 -> 5.5813953 | L13: =[22]Brewhouse!$P410 -> 57 | M13: =[22]Brewhouse!$U410-[22]Brewhouse!$T410 -> 0.10208333 | N13: =[22]Brewhouse!$Z410 -> 0.25833333 | O13: =[22]Brewhouse!$AX410 -> R. Sookram | R13: =B13 -> CARIB | S13: =VLOOKUP($B13,$R$3:$X$9,2,FALSE) -> 11.6 | T13: =VLOOKUP($B13,$R$3:$X$9,3,FALSE) -> 12 | U13: =VLOOKUP($B13,$R$3:$X$9,4,FALSE) -> 0 | V13: =VLOOKUP($B13,$R$3:$X$9,5,FALSE) -> 0.11805556 | W13: =VLOOKUP($B13,$R$3:$X$9,6,FALSE) -> 0.22569444 | X13: =VLOOKUP($B13,$R$3:$X$9,7,FALSE) -> 0.26388889 | Y13: =VLOOKUP($B13,$R$3:$Z$9,8,FALSE) -> 0 | Z13: =VLOOKUP($B13,$R$3:$Z$9,9,FALSE) -> 60
B14: CARIB | C14: =[22]Brewhouse!$A411 -> CA306 | D14: =[22]Brewhouse!$AF411 -> 53.9 | E14: =[22]Brewhouse!$AI411 -> 50.3 | F14: =[22]Brewhouse!$V411 -> 53 | G14: =[22]Brewhouse!$AG411 -> 11.8 | H14: 11.8 | I14: =[22]Brewhouse!$AU411 -> 93.912148 | J14: =[22]Brewhouse!$AV411 -> 95.52442 | K14: =[22]Brewhouse!$Q411 -> 6.3732394 | L14: =[22]Brewhouse!$P411 -> 58 | M14: =[22]Brewhouse!$U411-[22]Brewhouse!$T411 -> 0.10208333 | N14: =[22]Brewhouse!$Z411 -> 0.26388889 | O14: =[22]Brewhouse!$AX411 -> D. Gomez | R14: =B14 -> CARIB | S14: =VLOOKUP($B14,$R$3:$X$9,2,FALSE) -> 11.6 | T14: =VLOOKUP($B14,$R$3:$X$9,3,FALSE) -> 12 | U14: =VLOOKUP($B14,$R$3:$X$9,4,FALSE) -> 0 | V14: =VLOOKUP($B14,$R$3:$X$9,5,FALSE) -> 0.11805556 | W14: =VLOOKUP($B14,$R$3:$X$9,6,FALSE) -> 0.22569444 | X14: =VLOOKUP($B14,$R$3:$X$9,7,FALSE) -> 0.26388889 | Y14: =VLOOKUP($B14,$R$3:$Z$9,8,FALSE) -> 0 | Z14: =VLOOKUP($B14,$R$3:$Z$9,9,FALSE) -> 60
B15: CARIB | C15: =[22]Brewhouse!$A412 -> CA307 | D15: =[22]Brewhouse!$AF412 -> 55 | E15: =[22]Brewhouse!$AI412 -> 51.6 | F15: =[22]Brewhouse!$V412 -> 64 | G15: =[22]Brewhouse!$AG412 -> 11.9 | H15: 11.9 | I15: =[22]Brewhouse!$AU412 -> 100.64037 | J15: =[22]Brewhouse!$AV412 -> 102.43751 | K15: =[22]Brewhouse!$Q412 -> 5.3546099 | L15: =[22]Brewhouse!$P412 -> 60 | M15: =[22]Brewhouse!$U412-[22]Brewhouse!$T412 -> 0.1125 | N15: =[22]Brewhouse!$Z412 -> 0.26736111 | O15: =[22]Brewhouse!$AX412 -> D. Gomez | R15: =B15 -> CARIB | S15: =VLOOKUP($B15,$R$3:$X$9,2,FALSE) -> 11.6 | T15: =VLOOKUP($B15,$R$3:$X$9,3,FALSE) -> 12 | U15: =VLOOKUP($B15,$R$3:$X$9,4,FALSE) -> 0 | V15: =VLOOKUP($B15,$R$3:$X$9,5,FALSE) -> 0.11805556 | W15: =VLOOKUP($B15,$R$3:$X$9,6,FALSE) -> 0.22569444 | X15: =VLOOKUP($B15,$R$3:$X$9,7,FALSE) -> 0.26388889 | Y15: =VLOOKUP($B15,$R$3:$Z$9,8,FALSE) -> 0 | Z15: =VLOOKUP($B15,$R$3:$Z$9,9,FALSE) -> 60
B16: CARIB | C16: =[22]Brewhouse!$A413 -> CA308 | D16: =[22]Brewhouse!$AF413 -> 54.1 | E16: =[22]Brewhouse!$AI413 -> 51.2 | F16: =[22]Brewhouse!$V413 -> 64 | G16: =[22]Brewhouse!$AG413 -> 12 | H16: 12 | I16: =[22]Brewhouse!$AU413 -> 100.74251 | J16: =[22]Brewhouse!$AV413 -> 102.54147 | K16: =[22]Brewhouse!$Q413 -> 5.5614973 | L16: =[22]Brewhouse!$P413 -> 62 | M16: =[22]Brewhouse!$U413-[22]Brewhouse!$T413 -> 0.10902778 | N16: =[22]Brewhouse!$Z413 -> 0.25763889 | O16: =[22]Brewhouse!$AX413 -> D. Gomez | R16: =B16 -> CARIB | S16: =VLOOKUP($B16,$R$3:$X$9,2,FALSE) -> 11.6 | T16: =VLOOKUP($B16,$R$3:$X$9,3,FALSE) -> 12 | U16: =VLOOKUP($B16,$R$3:$X$9,4,FALSE) -> 0 | V16: =VLOOKUP($B16,$R$3:$X$9,5,FALSE) -> 0.11805556 | W16: =VLOOKUP($B16,$R$3:$X$9,6,FALSE) -> 0.22569444 | X16: =VLOOKUP($B16,$R$3:$X$9,7,FALSE) -> 0.26388889 | Y16: =VLOOKUP($B16,$R$3:$Z$9,8,FALSE) -> 0 | Z16: =VLOOKUP($B16,$R$3:$Z$9,9,FALSE) -> 60
B17: CARIB | C17: =[22]Brewhouse!$A414 -> CA309 | D17: =[22]Brewhouse!$AF414 -> 54.8 | E17: =[22]Brewhouse!$AI414 -> 51.3 | F17: =[22]Brewhouse!$V414 -> 62 | G17: =[22]Brewhouse!$AG414 -> 11.8 | H17: 11.8 | I17: =[22]Brewhouse!$AU414 -> 98.56175 | J17: =[22]Brewhouse!$AV414 -> 100.32225 | K17: =[22]Brewhouse!$Q414 -> 5.9180036 | L17: =[22]Brewhouse!$P414 -> 58 | M17: =[22]Brewhouse!$U414-[22]Brewhouse!$T414 -> 0.10625 | N17: =[22]Brewhouse!$Z414 -> 0.25972222 | O17: =[22]Brewhouse!$AX414 -> D. Gomez | R17: =B17 -> CARIB | S17: =VLOOKUP($B17,$R$3:$X$9,2,FALSE) -> 11.6 | T17: =VLOOKUP($B17,$R$3:$X$9,3,FALSE) -> 12 | U17: =VLOOKUP($B17,$R$3:$X$9,4,FALSE) -> 0 | V17: =VLOOKUP($B17,$R$3:$X$9,5,FALSE) -> 0.11805556 | W17: =VLOOKUP($B17,$R$3:$X$9,6,FALSE) -> 0.22569444 | X17: =VLOOKUP($B17,$R$3:$X$9,7,FALSE) -> 0.26388889 | Y17: =VLOOKUP($B17,$R$3:$Z$9,8,FALSE) -> 0 | Z17: =VLOOKUP($B17,$R$3:$Z$9,9,FALSE) -> 60
B19: May 3rd
B20: CARIB | C20: =[22]Brewhouse!$A415 -> CA310 | D20: =[22]Brewhouse!$AF415 -> 53.8 | E20: =[22]Brewhouse!$AI415 -> 50.7 | F20: =[22]Brewhouse!$V415 -> 64 | G20: =[22]Brewhouse!$AG415 -> 11.7 | H20: 11.7 | I20: =[22]Brewhouse!$AU415 -> 97.01766 | J20: =[22]Brewhouse!$AV415 -> 98.750203 | K20: =[22]Brewhouse!$Q415 -> 1.5213358 | L20: =[22]Brewhouse!$P415 -> 60 | M20: =[22]Brewhouse!$U415-[22]Brewhouse!$T415 -> 0.10763889 | N20: =[22]Brewhouse!$Z415 -> 0.24444444 | O20: =[22]Brewhouse!$AX415 -> G. Mason | R20: =B20 -> CARIB | S20: =VLOOKUP($B20,$R$3:$X$9,2,FALSE) -> 11.6 | T20: =VLOOKUP($B20,$R$3:$X$9,3,FALSE) -> 12 | U20: =VLOOKUP($B20,$R$3:$X$9,4,FALSE) -> 0 | V20: =VLOOKUP($B20,$R$3:$X$9,5,FALSE) -> 0.11805556 | W20: =VLOOKUP($B20,$R$3:$X$9,6,FALSE) -> 0.22569444 | X20: =VLOOKUP($B20,$R$3:$X$9,7,FALSE) -> 0.26388889 | Y20: =VLOOKUP($B20,$R$3:$Z$9,8,FALSE) -> 0 | Z20: =VLOOKUP($B20,$R$3:$Z$9,9,FALSE) -> 60
B21: CARIB | C21: =[22]Brewhouse!$A416 -> CA311 | D21: =[22]Brewhouse!$AF416 -> 53.9 | E21: =[22]Brewhouse!$AI416 -> 49.9 | F21: =[22]Brewhouse!$V416 -> 58 | G21: =[22]Brewhouse!$AG416 -> 11.9 | H21: 11.8 | I21: =[22]Brewhouse!$AU416 -> 96.889013 | J21: =[22]Brewhouse!$AV416 -> 98.547992 | K21: =[22]Brewhouse!$Q416 -> 6.4642857 | L21: =[22]Brewhouse!$P416 -> 57 | M21: =[22]Brewhouse!$U416-[22]Brewhouse!$T416 -> 0.10347222 | N21: =[22]Brewhouse!$Z416 -> 0.23611111 | O21: =[22]Brewhouse!$AX416 -> G. Mason | R21: =B21 -> CARIB | S21: =VLOOKUP($B21,$R$3:$X$9,2,FALSE) -> 11.6 | T21: =VLOOKUP($B21,$R$3:$X$9,3,FALSE) -> 12 | U21: =VLOOKUP($B21,$R$3:$X$9,4,FALSE) -> 0 | V21: =VLOOKUP($B21,$R$3:$X$9,5,FALSE) -> 0.11805556 | W21: =VLOOKUP($B21,$R$3:$X$9,6,FALSE) -> 0.22569444 | X21: =VLOOKUP($B21,$R$3:$X$9,7,FALSE) -> 0.26388889 | Y21: =VLOOKUP($B21,$R$3:$Z$9,8,FALSE) -> 0 | Z21: =VLOOKUP($B21,$R$3:$Z$9,9,FALSE) -> 60
B22: CARIB | C22: =[22]Brewhouse!$A417 -> CA312 | D22: =[22]Brewhouse!$AF417 -> 54.3 | E22: =[22]Brewhouse!$AI417 -> 50.8 | F22: =[22]Brewhouse!$V417 -> 66 | G22: =[22]Brewhouse!$AG417 -> 12 | H22: 11.8 | I22: =[22]Brewhouse!$AU417 -> 99.141807 | J22: =[22]Brewhouse!$AV417 -> 100.83991 | K22: =[22]Brewhouse!$Q417 -> 5.0357143 | L22: =[22]Brewhouse!$P417 -> 57 | M22: =[22]Brewhouse!$U417-[22]Brewhouse!$T417 -> 0.10625 | N22: =[22]Brewhouse!$Z417 -> 0.24027778 | O22: =[22]Brewhouse!$AX417 -> G. Mason | R22: =B22 -> CARIB | S22: =VLOOKUP($B22,$R$3:$X$9,2,FALSE) -> 11.6 | T22: =VLOOKUP($B22,$R$3:$X$9,3,FALSE) -> 12 | U22: =VLOOKUP($B22,$R$3:$X$9,4,FALSE) -> 0 | V22: =VLOOKUP($B22,$R$3:$X$9,5,FALSE) -> 0.11805556 | W22: =VLOOKUP($B22,$R$3:$X$9,6,FALSE) -> 0.22569444 | X22: =VLOOKUP($B22,$R$3:$X$9,7,FALSE) -> 0.26388889 | Y22: =VLOOKUP($B22,$R$3:$Z$9,8,FALSE) -> 0 | Z22: =VLOOKUP($B22,$R$3:$Z$9,9,FALSE) -> 60
B23: CARIB | C23: =[22]Brewhouse!$A418 -> CA313 | D23: =[22]Brewhouse!$AF418 -> 54.7 | E23: =[22]Brewhouse!$AI418 -> 51.5 | F23: =[22]Brewhouse!$V418 -> 61 | G23: =[22]Brewhouse!$AG418 -> 11.6 | H23: 11.8 | I23: =[22]Brewhouse!$AU418 -> 97.782921 | J23: =[22]Brewhouse!$AV418 -> 99.529034 | K23: =[22]Brewhouse!$Q418 -> -1.2977099 | L23: =[22]Brewhouse!$P418 -> 57 | M23: =[22]Brewhouse!$U418-[22]Brewhouse!$T418 -> 0.11111111 | N23: =[22]Brewhouse!$Z418 -> 0.25138889 | O23: =[22]Brewhouse!$AX418 -> G. Mason | R23: =B23 -> CARIB | S23: =VLOOKUP($B23,$R$3:$X$9,2,FALSE) -> 11.6 | T23: =VLOOKUP($B23,$R$3:$X$9,3,FALSE) -> 12 | U23: =VLOOKUP($B23,$R$3:$X$9,4,FALSE) -> 0 | V23: =VLOOKUP($B23,$R$3:$X$9,5,FALSE) -> 0.11805556 | W23: =VLOOKUP($B23,$R$3:$X$9,6,FALSE) -> 0.22569444 | X23: =VLOOKUP($B23,$R$3:$X$9,7,FALSE) -> 0.26388889 | Y23: =VLOOKUP($B23,$R$3:$Z$9,8,FALSE) -> 0 | Z23: =VLOOKUP($B23,$R$3:$Z$9,9,FALSE) -> 60
B24: CARIB | C24: =[22]Brewhouse!$A419 -> CA314 | D24: =[22]Brewhouse!$AF419 -> 54.2 | E24: =[22]Brewhouse!$AI419 -> 50.8 | F24: =[22]Brewhouse!$V419 -> 64 | G24: =[22]Brewhouse!$AG419 -> 11.9 | H24: 11.8 | I24: =[22]Brewhouse!$AU419 -> 99.202738 | J24: =[22]Brewhouse!$AV419 -> 100.97411 | K24: =[22]Brewhouse!$Q419 -> 6.0530973 | L24: =[22]Brewhouse!$P419 -> 57 | M24: =[22]Brewhouse!$U419-[22]Brewhouse!$T419 -> 0.10694444 | N24: =[22]Brewhouse!$Z419 -> 0.24375 | O24: =[22]Brewhouse!$AX419 -> K.Benjamin | R24: =B24 -> CARIB | S24: =VLOOKUP($B24,$R$3:$X$9,2,FALSE) -> 11.6 | T24: =VLOOKUP($B24,$R$3:$X$9,3,FALSE) -> 12 | U24: =VLOOKUP($B24,$R$3:$X$9,4,FALSE) -> 0 | V24: =VLOOKUP($B24,$R$3:$X$9,5,FALSE) -> 0.11805556 | W24: =VLOOKUP($B24,$R$3:$X$9,6,FALSE) -> 0.22569444 | X24: =VLOOKUP($B24,$R$3:$X$9,7,FALSE) -> 0.26388889 | Y24: =VLOOKUP($B24,$R$3:$Z$9,8,FALSE) -> 0 | Z24: =VLOOKUP($B24,$R$3:$Z$9,9,FALSE) -> 60
B25: CARIB | C25: =[22]Brewhouse!$A420 -> CA315 | D25: =[22]Brewhouse!$AF420 -> 55.3 | E25: =[22]Brewhouse!$AI420 -> 52 | F25: =[22]Brewhouse!$V420 -> 54 | G25: =[22]Brewhouse!$AG420 -> 11.7 | H25: 11.8 | I25: =[22]Brewhouse!$AU420 -> 98.938732 | J25: =[22]Brewhouse!$AV420 -> 100.63318 | K25: =[22]Brewhouse!$Q420 -> 4.822695 | L25: =[22]Brewhouse!$P420 -> 58 | M25: =[22]Brewhouse!$U420-[22]Brewhouse!$T420 -> 0.10277778 | N25: =[22]Brewhouse!$Z420 -> 0.24305556 | O25: =[22]Brewhouse!$AX420 -> K.Benjamin | R25: =B25 -> CARIB | S25: =VLOOKUP($B25,$R$3:$X$9,2,FALSE) -> 11.6 | T25: =VLOOKUP($B25,$R$3:$X$9,3,FALSE) -> 12 | U25: =VLOOKUP($B25,$R$3:$X$9,4,FALSE) -> 0 | V25: =VLOOKUP($B25,$R$3:$X$9,5,FALSE) -> 0.11805556 | W25: =VLOOKUP($B25,$R$3:$X$9,6,FALSE) -> 0.22569444 | X25: =VLOOKUP($B25,$R$3:$X$9,7,FALSE) -> 0.26388889 | Y25: =VLOOKUP($B25,$R$3:$Z$9,8,FALSE) -> 0 | Z25: =VLOOKUP($B25,$R$3:$Z$9,9,FALSE) -> 60
B26: CARIB | C26: =[22]Brewhouse!$A421 -> CA316 | D26: =[22]Brewhouse!$AF421 -> 54.4 | E26: =[22]Brewhouse!$AI421 -> 51.2 | F26: =[22]Brewhouse!$V421 -> 60 | G26: =[22]Brewhouse!$AG421 -> 11.8 | H26: 11.8 | I26: =[22]Brewhouse!$AU421 -> 95.251171 | J26: =[22]Brewhouse!$AV421 -> 96.886932 | K26: =[22]Brewhouse!$Q421 -> 4.822695 | L26: =[22]Brewhouse!$P421 -> 59 | M26: =[22]Brewhouse!$U421-[22]Brewhouse!$T421 -> 0.10347222 | N26: =[22]Brewhouse!$Z421 -> 0.24375 | O26: =[22]Brewhouse!$AX421 -> K.Benjamin | R26: =B26 -> CARIB | S26: =VLOOKUP($B26,$R$3:$X$9,2,FALSE) -> 11.6 | T26: =VLOOKUP($B26,$R$3:$X$9,3,FALSE) -> 12 | U26: =VLOOKUP($B26,$R$3:$X$9,4,FALSE) -> 0 | V26: =VLOOKUP($B26,$R$3:$X$9,5,FALSE) -> 0.11805556 | W26: =VLOOKUP($B26,$R$3:$X$9,6,FALSE) -> 0.22569444 | X26: =VLOOKUP($B26,$R$3:$X$9,7,FALSE) -> 0.26388889 | Y26: =VLOOKUP($B26,$R$3:$Z$9,8,FALSE) -> 0 | Z26: =VLOOKUP($B26,$R$3:$Z$9,9,FALSE) -> 60
B27: CARIB | C27: =[22]Brewhouse!$A422 -> CA317 | D27: =[22]Brewhouse!$AF422 -> 53 | E27: =[22]Brewhouse!$AI422 -> 51.2 | F27: =[22]Brewhouse!$V422 -> 64 | G27: =[22]Brewhouse!$AG422 -> 11.8 | H27: 11.8 | I27: =[22]Brewhouse!$AU422 -> 98.855651 | J27: =[22]Brewhouse!$AV422 -> 100.62102 | K27: =[22]Brewhouse!$Q422 -> 7.7954145 | L27: =[22]Brewhouse!$P422 -> 60 | M27: =[22]Brewhouse!$U422-[22]Brewhouse!$T422 -> 0.11041667 | N27: =[22]Brewhouse!$Z422 -> 0.25208333 | O27: =[22]Brewhouse!$AX422 -> K.Benjamin | R27: =B27 -> CARIB | S27: =VLOOKUP($B27,$R$3:$X$9,2,FALSE) -> 11.6 | T27: =VLOOKUP($B27,$R$3:$X$9,3,FALSE) -> 12 | U27: =VLOOKUP($B27,$R$3:$X$9,4,FALSE) -> 0 | V27: =VLOOKUP($B27,$R$3:$X$9,5,FALSE) -> 0.11805556 | W27: =VLOOKUP($B27,$R$3:$X$9,6,FALSE) -> 0.22569444 | X27: =VLOOKUP($B27,$R$3:$X$9,7,FALSE) -> 0.26388889 | Y27: =VLOOKUP($B27,$R$3:$Z$9,8,FALSE) -> 0 | Z27: =VLOOKUP($B27,$R$3:$Z$9,9,FALSE) -> 60
B28: CARIB | C28: =[22]Brewhouse!$A423 -> CA318 | D28: =[22]Brewhouse!$AF423 -> 54 | E28: =[22]Brewhouse!$AI423 -> 51.1 | F28: =[22]Brewhouse!$V423 -> 58 | G28: =[22]Brewhouse!$AG423 -> 11.9 | H28: 11.9 | I28: =[22]Brewhouse!$AU423 -> 99.296757 | J28: =[22]Brewhouse!$AV423 -> 101.07019 | K28: =[22]Brewhouse!$Q423 -> 6.5263158 | L28: =[22]Brewhouse!$P423 -> 58 | M28: =[22]Brewhouse!$U423-[22]Brewhouse!$T423 -> 0.11875 | N28: =[22]Brewhouse!$Z423 -> 0.24791667 | O28: =[22]Brewhouse!$AX423 -> K.Benjamin | R28: =B28 -> CARIB | S28: =VLOOKUP($B28,$R$3:$X$9,2,FALSE) -> 11.6 | T28: =VLOOKUP($B28,$R$3:$X$9,3,FALSE) -> 12 | U28: =VLOOKUP($B28,$R$3:$X$9,4,FALSE) -> 0 | V28: =VLOOKUP($B28,$R$3:$X$9,5,FALSE) -> 0.11805556 | W28: =VLOOKUP($B28,$R$3:$X$9,6,FALSE) -> 0.22569444 | X28: =VLOOKUP($B28,$R$3:$X$9,7,FALSE) -> 0.26388889 | Y28: =VLOOKUP($B28,$R$3:$Z$9,8,FALSE) -> 0 | Z28: =VLOOKUP($B28,$R$3:$Z$9,9,FALSE) -> 60
R34: =B34 -> 0 | S34: =VLOOKUP($B34,$R$3:$X$9,2,FALSE) -> #N/A | T34: =VLOOKUP($B34,$R$3:$X$9,3,FALSE) -> #N/A | U34: =VLOOKUP($B34,$R$3:$X$9,4,FALSE) -> #N/A | V34: =VLOOKUP($B34,$R$3:$X$9,5,FALSE) -> #N/A | W34: =VLOOKUP($B34,$R$3:$X$9,6,FALSE) -> #N/A | X34: =VLOOKUP($B34,$R$3:$X$9,7,FALSE) -> #N/A | Y34: =VLOOKUP($B34,$R$3:$Z$9,8,FALSE) -> #N/A | Z34: =VLOOKUP($B34,$R$3:$Z$9,9,FALSE) -> #N/A
R35: =B35 -> 0 | S35: =VLOOKUP($B35,$R$3:$X$9,2,FALSE) -> #N/A | T35: =VLOOKUP($B35,$R$3:$X$9,3,FALSE) -> #N/A | U35: =VLOOKUP($B35,$R$3:$X$9,4,FALSE) -> #N/A | V35: =VLOOKUP($B35,$R$3:$X$9,5,FALSE) -> #N/A | W35: =VLOOKUP($B35,$R$3:$X$9,6,FALSE) -> #N/A | X35: =VLOOKUP($B35,$R$3:$X$9,7,FALSE) -> #N/A | Y35: =VLOOKUP($B35,$R$3:$Z$9,8,FALSE) -> #N/A | Z35: =VLOOKUP($B35,$R$3:$Z$9,9,FALSE) -> #N/A
R36: =B36 -> 0 | S36: =VLOOKUP($B36,$R$3:$X$9,2,FALSE) -> #N/A | T36: =VLOOKUP($B36,$R$3:$X$9,3,FALSE) -> #N/A | U36: =VLOOKUP($B36,$R$3:$X$9,4,FALSE) -> #N/A | V36: =VLOOKUP($B36,$R$3:$X$9,5,FALSE) -> #N/A | W36: =VLOOKUP($B36,$R$3:$X$9,6,FALSE) -> #N/A | X36: =VLOOKUP($B36,$R$3:$X$9,7,FALSE) -> #N/A | Y36: =VLOOKUP($B36,$R$3:$Z$9,8,FALSE) -> #N/A | Z36: =VLOOKUP($B36,$R$3:$Z$9,9,FALSE) -> #N/A
R37: =B37 -> 0 | S37: =VLOOKUP($B37,$R$3:$X$9,2,FALSE) -> #N/A | T37: =VLOOKUP($B37,$R$3:$X$9,3,FALSE) -> #N/A | U37: =VLOOKUP($B37,$R$3:$X$9,4,FALSE) -> #N/A | V37: =VLOOKUP($B37,$R$3:$X$9,5,FALSE) -> #N/A | W37: =VLOOKUP($B37,$R$3:$X$9,6,FALSE) -> #N/A | X37: =VLOOKUP($B37,$R$3:$X$9,7,FALSE) -> #N/A | Y37: =VLOOKUP($B37,$R$3:$Z$9,8,FALSE) -> #N/A | Z37: =VLOOKUP($B37,$R$3:$Z$9,9,FALSE) -> #N/A
R38: =B38 -> 0 | S38: =VLOOKUP($B38,$R$3:$X$9,2,FALSE) -> #N/A | T38: =VLOOKUP($B38,$R$3:$X$9,3,FALSE) -> #N/A | U38: =VLOOKUP($B38,$R$3:$X$9,4,FALSE) -> #N/A | V38: =VLOOKUP($B38,$R$3:$X$9,5,FALSE) -> #N/A | W38: =VLOOKUP($B38,$R$3:$X$9,6,FALSE) -> #N/A | X38: =VLOOKUP($B38,$R$3:$X$9,7,FALSE) -> #N/A | Y38: =VLOOKUP($B38,$R$3:$Z$9,8,FALSE) -> #N/A | Z38: =VLOOKUP($B38,$R$3:$Z$9,9,FALSE) -> #N/A
R39: =B39 -> 0 | S39: =VLOOKUP($B39,$R$3:$X$9,2,FALSE) -> #N/A | T39: =VLOOKUP($B39,$R$3:$X$9,3,FALSE) -> #N/A | U39: =VLOOKUP($B39,$R$3:$X$9,4,FALSE) -> #N/A | V39: =VLOOKUP($B39,$R$3:$X$9,5,FALSE) -> #N/A | W39: =VLOOKUP($B39,$R$3:$X$9,6,FALSE) -> #N/A | X39: =VLOOKUP($B39,$R$3:$X$9,7,FALSE) -> #N/A | Y39: =VLOOKUP($B39,$R$3:$Z$9,8,FALSE) -> #N/A | Z39: =VLOOKUP($B39,$R$3:$Z$9,9,FALSE) -> #N/A
R40: =B40 -> 0 | S40: =VLOOKUP($B40,$R$3:$X$9,2,FALSE) -> #N/A | T40: =VLOOKUP($B40,$R$3:$X$9,3,FALSE) -> #N/A | U40: =VLOOKUP($B40,$R$3:$X$9,4,FALSE) -> #N/A | V40: =VLOOKUP($B40,$R$3:$X$9,5,FALSE) -> #N/A | W40: =VLOOKUP($B40,$R$3:$X$9,6,FALSE) -> #N/A | X40: =VLOOKUP($B40,$R$3:$X$9,7,FALSE) -> #N/A | Y40: =VLOOKUP($B40,$R$3:$Z$9,8,FALSE) -> #N/A | Z40: =VLOOKUP($B40,$R$3:$Z$9,9,FALSE) -> #N/A
R41: =B41 -> 0 | S41: =VLOOKUP($B41,$R$3:$X$9,2,FALSE) -> #N/A | T41: =VLOOKUP($B41,$R$3:$X$9,3,FALSE) -> #N/A | U41: =VLOOKUP($B41,$R$3:$X$9,4,FALSE) -> #N/A | V41: =VLOOKUP($B41,$R$3:$X$9,5,FALSE) -> #N/A | W41: =VLOOKUP($B41,$R$3:$X$9,6,FALSE) -> #N/A | X41: =VLOOKUP($B41,$R$3:$X$9,7,FALSE) -> #N/A | Y41: =VLOOKUP($B41,$R$3:$Z$9,8,FALSE) -> #N/A | Z41: =VLOOKUP($B41,$R$3:$Z$9,9,FALSE) -> #N/A
R42: =B42 -> 0 | S42: =VLOOKUP($B42,$R$3:$X$9,2,FALSE) -> #N/A | T42: =VLOOKUP($B42,$R$3:$X$9,3,FALSE) -> #N/A | U42: =VLOOKUP($B42,$R$3:$X$9,4,FALSE) -> #N/A | V42: =VLOOKUP($B42,$R$3:$X$9,5,FALSE) -> #N/A | W42: =VLOOKUP($B42,$R$3:$X$9,6,FALSE) -> #N/A | X42: =VLOOKUP($B42,$R$3:$X$9,7,FALSE) -> #N/A | Y42: =VLOOKUP($B42,$R$3:$Z$9,8,FALSE) -> #N/A | Z42: =VLOOKUP($B42,$R$3:$Z$9,9,FALSE) -> #N/A
R43: =B43 -> 0 | S43: =VLOOKUP($B43,$R$3:$X$9,2,FALSE) -> #N/A | T43: =VLOOKUP($B43,$R$3:$X$9,3,FALSE) -> #N/A | U43: =VLOOKUP($B43,$R$3:$X$9,4,FALSE) -> #N/A | V43: =VLOOKUP($B43,$R$3:$X$9,5,FALSE) -> #N/A | W43: =VLOOKUP($B43,$R$3:$X$9,6,FALSE) -> #N/A | X43: =VLOOKUP($B43,$R$3:$X$9,7,FALSE) -> #N/A | Y43: =VLOOKUP($B43,$R$3:$Z$9,8,FALSE) -> #N/A | Z43: =VLOOKUP($B43,$R$3:$Z$9,9,FALSE) -> #N/A
I44: EXTRACT RECOVERY | R44: =B44 -> 0 | S44: =VLOOKUP($B44,$R$3:$X$9,2,FALSE) -> #N/A | T44: =VLOOKUP($B44,$R$3:$X$9,3,FALSE) -> #N/A | U44: =VLOOKUP($B44,$R$3:$X$9,4,FALSE) -> #N/A | V44: =VLOOKUP($B44,$R$3:$X$9,5,FALSE) -> #N/A | W44: =VLOOKUP($B44,$R$3:$X$9,6,FALSE) -> #N/A | X44: =VLOOKUP($B44,$R$3:$X$9,7,FALSE) -> #N/A | Y44: =VLOOKUP($B44,$R$3:$Z$9,8,FALSE) -> #N/A | Z44: =VLOOKUP($B44,$R$3:$Z$9,9,FALSE) -> #N/A
B45: BRAND | D45: BBT P.G./ O.G | I45: Brand | J45: Actual | K45: MTD No. of Brews | L45: MTD | M45: YTD | N45: Target
I46: CARIB | J46: =AVERAGE(I11:I17,I20:I28) -> 98.025343 | K46: =COUNTA([22]Brewhouse!$A$408:$A$423) -> 16 | L46: =AVERAGE([22]Brewhouse!$AU$408:$AU$423) -> 98.025343 | M46: =AVERAGE([22]Brewhouse!$AU$102:$AU$171,[22]Brewhouse!$AU$173:$AU$253,[22]Brewhouse!$AU$255:$AU$339,[22]Brewhouse!$AU$341:$AU$346,[22]Brewhouse!$AU$348,[22]Brewhouse!$AU$349:$AU$406) -> 97.396136 | N46: 98
...

Sheet May 5th
S1: P.G. | U1: Hot Time | W1: Process Time | Y1: Cooling Time
B2: Brewing Department Daily Process Loss Report | S2: Lower | T2: Upper | U2: Lower | V2: Upper | W2: Lower | X2: Upper | Y2: Lower | Z2: Upper
R3: CARIB | S3: 11.6 | T3: 12 | U3: 0 | V3: 0.11805556 | W3: 0.22569444 | X3: 0.26388889 | Y3: 0 | Z3: 60 | AB3: HR- PISNER
B4: Date: | C4: 45783 | J4: LOT WORT COLOUR: 3.5 | M4: Filter Sheets (Target 20 days) | R4: STAG | S4: 11.6 | T4: 12 | U4: 0 | V4: 0.11805556 | W4: 0.22569444 | X4: 0.26388889 | Y4: 0 | Z4: 60
M5: Double | N5: Single | R5: GUINNESS | S5: 17 | T5: 17.5 | U5: 0 | V5: 0.10763889 | W5: 0.24652778 | X5: 0.28472222 | Y5: 0 | Z5: 60
J6: MALT LOT: Lot 35 | L6: Sheet Day | R6: MACKESON | S6: 13.3 | T6: 13.5 | U6: 0 | V6: 0.12905093 | W6: 0.27430556 | X6: 0.30208333 | Y6: 0
R7: STARMALT | S7: 17.1 | T7: 17.5 | U7: 0 | V7: 0.13605324 | W7: 0.27430556 | X7: 0.30902778 | Y7: 0 | Z7: 60
B8: Brand | C8: Brew no. | D8: Kett. Hls | E8: Wort | F8: Cool Time(Mins) | G8: Cast. P.G. (Lab Result) | H8: Cast P.G. (Cellar Operator)-gravity | I8: Extr. Rec (78.95%) | J8: Theor. Extr. (77.5%) | K8: Boil Off /Vol. (4-6%) | L8: Boil Time | M8: Total Hot | N8: Brewing | O8: Operator | P8: Actual Pilsen Malt | R8: Hurricane Reef | S8: 16.6 | T8: 17 | U8: 0 | V8: 0.12905093 | W8: 0.27430556 | X8: 0.30208333 | Y8: 0
E9: Meter (Hls) | F9: Target(< 60Mins) | M9: Time | R9: VITAMALT | S9: 14.4 | T9: 14.6 | U9: 0 | V9: 0.13905093 | W9: 0.26041667 | X9: 0.29513889 | Y9: 0 | Z9: 75
R10: =B10 -> 0 | S10: =VLOOKUP($B10,$R$3:$X$9,2,FALSE) -> #N/A | T10: =VLOOKUP($B10,$R$3:$X$9,3,FALSE) -> #N/A | U10: =VLOOKUP($B10,$R$3:$X$9,4,FALSE) -> #N/A | V10: =VLOOKUP($B10,$R$3:$X$9,5,FALSE) -> #N/A | W10: =VLOOKUP($B10,$R$3:$X$9,6,FALSE) -> #N/A | X10: =VLOOKUP($B10,$R$3:$X$9,7,FALSE) -> #N/A | Y10: =VLOOKUP($B10,$R$3:$Z$9,8,FALSE) -> #N/A | Z10: =VLOOKUP($B10,$R$3:$Z$9,9,FALSE) -> #N/A
R11: =B11 -> 0 | S11: =VLOOKUP($B11,$R$3:$X$9,2,FALSE) -> #N/A | T11: =VLOOKUP($B11,$R$3:$X$9,3,FALSE) -> #N/A | U11: =VLOOKUP($B11,$R$3:$X$9,4,FALSE) -> #N/A | V11: =VLOOKUP($B11,$R$3:$X$9,5,FALSE) -> #N/A | W11: =VLOOKUP($B11,$R$3:$X$9,6,FALSE) -> #N/A | X11: =VLOOKUP($B11,$R$3:$X$9,7,FALSE) -> #N/A | Y11: =VLOOKUP($B11,$R$3:$Z$9,8,FALSE) -> #N/A | Z11: =VLOOKUP($B11,$R$3:$Z$9,9,FALSE) -> #N/A
R12: =B12 -> 0 | S12: =VLOOKUP($B12,$R$3:$X$9,2,FALSE) -> #N/A | T12: =VLOOKUP($B12,$R$3:$X$9,3,FALSE) -> #N/A | U12: =VLOOKUP($B12,$R$3:$X$9,4,FALSE) -> #N/A | V12: =VLOOKUP($B12,$R$3:$X$9,5,FALSE) -> #N/A | W12: =VLOOKUP($B12,$R$3:$X$9,6,FALSE) -> #N/A | X12: =VLOOKUP($B12,$R$3:$X$9,7,FALSE) -> #N/A | Y12: =VLOOKUP($B12,$R$3:$Z$9,8,FALSE) -> #N/A | Z12: =VLOOKUP($B12,$R$3:$Z$9,9,FALSE) -> #N/A
R13: =B13 -> 0 | S13: =VLOOKUP($B13,$R$3:$X$9,2,FALSE) -> #N/A | T13: =VLOOKUP($B13,$R$3:$X$9,3,FALSE) -> #N/A | U13: =VLOOKUP($B13,$R$3:$X$9,4,FALSE) -> #N/A | V13: =VLOOKUP($B13,$R$3:$X$9,5,FALSE) -> #N/A | W13: =VLOOKUP($B13,$R$3:$X$9,6,FALSE) -> #N/A | X13: =VLOOKUP($B13,$R$3:$X$9,7,FALSE) -> #N/A | Y13: =VLOOKUP($B13,$R$3:$Z$9,8,FALSE) -> #N/A | Z13: =VLOOKUP($B13,$R$3:$Z$9,9,FALSE) -> #N/A
R14: =B14 -> 0 | S14: =VLOOKUP($B14,$R$3:$X$9,2,FALSE) -> #N/A | T14: =VLOOKUP($B14,$R$3:$X$9,3,FALSE) -> #N/A | U14: =VLOOKUP($B14,$R$3:$X$9,4,FALSE) -> #N/A | V14: =VLOOKUP($B14,$R$3:$X$9,5,FALSE) -> #N/A | W14: =VLOOKUP($B14,$R$3:$X$9,6,FALSE) -> #N/A | X14: =VLOOKUP($B14,$R$3:$X$9,7,FALSE) -> #N/A | Y14: =VLOOKUP($B14,$R$3:$Z$9,8,FALSE) -> #N/A | Z14: =VLOOKUP($B14,$R$3:$Z$9,9,FALSE) -> #N/A
R15: =B15 -> 0 | S15: =VLOOKUP($B15,$R$3:$X$9,2,FALSE) -> #N/A | T15: =VLOOKUP($B15,$R$3:$X$9,3,FALSE) -> #N/A | U15: =VLOOKUP($B15,$R$3:$X$9,4,FALSE) -> #N/A | V15: =VLOOKUP($B15,$R$3:$X$9,5,FALSE) -> #N/A | W15: =VLOOKUP($B15,$R$3:$X$9,6,FALSE) -> #N/A | X15: =VLOOKUP($B15,$R$3:$X$9,7,FALSE) -> #N/A | Y15: =VLOOKUP($B15,$R$3:$Z$9,8,FALSE) -> #N/A | Z15: =VLOOKUP($B15,$R$3:$Z$9,9,FALSE) -> #N/A
R16: =B16 -> 0 | S16: =VLOOKUP($B16,$R$3:$X$9,2,FALSE) -> #N/A | T16: =VLOOKUP($B16,$R$3:$X$9,3,FALSE) -> #N/A | U16: =VLOOKUP($B16,$R$3:$X$9,4,FALSE) -> #N/A | V16: =VLOOKUP($B16,$R$3:$X$9,5,FALSE) -> #N/A | W16: =VLOOKUP($B16,$R$3:$X$9,6,FALSE) -> #N/A | X16: =VLOOKUP($B16,$R$3:$X$9,7,FALSE) -> #N/A | Y16: =VLOOKUP($B16,$R$3:$Z$9,8,FALSE) -> #N/A | Z16: =VLOOKUP($B16,$R$3:$Z$9,9,FALSE) -> #N/A
R17: =B17 -> 0 | S17: =VLOOKUP($B17,$R$3:$X$9,2,FALSE) -> #N/A | T17: =VLOOKUP($B17,$R$3:$X$9,3,FALSE) -> #N/A | U17: =VLOOKUP($B17,$R$3:$X$9,4,FALSE) -> #N/A | V17: =VLOOKUP($B17,$R$3:$X$9,5,FALSE) -> #N/A | W17: =VLOOKUP($B17,$R$3:$X$9,6,FALSE) -> #N/A | X17: =VLOOKUP($B17,$R$3:$X$9,7,FALSE) -> #N/A | Y17: =VLOOKUP($B17,$R$3:$Z$9,8,FALSE) -> #N/A | Z17: =VLOOKUP($B17,$R$3:$Z$9,9,FALSE) -> #N/A
R18: =B18 -> 0 | S18: =VLOOKUP($B18,$R$3:$X$9,2,FALSE) -> #N/A | T18: =VLOOKUP($B18,$R$3:$X$9,3,FALSE) -> #N/A | U18: =VLOOKUP($B18,$R$3:$X$9,4,FALSE) -> #N/A | V18: =VLOOKUP($B18,$R$3:$X$9,5,FALSE) -> #N/A | W18: =VLOOKUP($B18,$R$3:$X$9,6,FALSE) -> #N/A | X18: =VLOOKUP($B18,$R$3:$X$9,7,FALSE) -> #N/A | Y18: =VLOOKUP($B18,$R$3:$Z$9,8,FALSE) -> #N/A | Z18: =VLOOKUP($B18,$R$3:$Z$9,9,FALSE) -> #N/A
R19: =B19 -> 0 | S19: =VLOOKUP($B19,$R$3:$X$9,2,FALSE) -> #N/A | T19: =VLOOKUP($B19,$R$3:$X$9,3,FALSE) -> #N/A | U19: =VLOOKUP($B19,$R$3:$X$9,4,FALSE) -> #N/A | V19: =VLOOKUP($B19,$R$3:$X$9,5,FALSE) -> #N/A | W19: =VLOOKUP($B19,$R$3:$X$9,6,FALSE) -> #N/A | X19: =VLOOKUP($B19,$R$3:$X$9,7,FALSE) -> #N/A | Y19: =VLOOKUP($B19,$R$3:$Z$9,8,FALSE) -> #N/A | Z19: =VLOOKUP($B19,$R$3:$Z$9,9,FALSE) -> #N/A
R20: =B20 -> 0 | S20: =VLOOKUP($B20,$R$3:$X$9,2,FALSE) -> #N/A | T20: =VLOOKUP($B20,$R$3:$X$9,3,FALSE) -> #N/A | U20: =VLOOKUP($B20,$R$3:$X$9,4,FALSE) -> #N/A | V20: =VLOOKUP($B20,$R$3:$X$9,5,FALSE) -> #N/A | W20: =VLOOKUP($B20,$R$3:$X$9,6,FALSE) -> #N/A | X20: =VLOOKUP($B20,$R$3:$X$9,7,FALSE) -> #N/A | Y20: =VLOOKUP($B20,$R$3:$Z$9,8,FALSE) -> #N/A | Z20: =VLOOKUP($B20,$R$3:$Z$9,9,FALSE) -> #N/A
R21: =B21 -> 0 | S21: =VLOOKUP($B21,$R$3:$X$9,2,FALSE) -> #N/A | T21: =VLOOKUP($B21,$R$3:$X$9,3,FALSE) -> #N/A | U21: =VLOOKUP($B21,$R$3:$X$9,4,FALSE) -> #N/A | V21: =VLOOKUP($B21,$R$3:$X$9,5,FALSE) -> #N/A | W21: =VLOOKUP($B21,$R$3:$X$9,6,FALSE) -> #N/A | X21: =VLOOKUP($B21,$R$3:$X$9,7,FALSE) -> #N/A | Y21: =VLOOKUP($B21,$R$3:$Z$9,8,FALSE) -> #N/A | Z21: =VLOOKUP($B21,$R$3:$Z$9,9,FALSE) -> #N/A
B22: STAG | C22: =[23]Brewhouse!$A195 -> ST177 | D22: =[23]Brewhouse!$AD195 -> 52.5 | E22: =[23]Brewhouse!$AG195 -> 48.7 | F22: =[23]Brewhouse!$V195 -> 55 | G22: =[23]Brewhouse!$AE195 -> 11.73 | H22: 11.8 | I22: =[23]Brewhouse!$AS195 -> 94.420069 | J22: =[23]Brewhouse!$AT195 -> 95.816026 | K22: =[23]Brewhouse!$Q195 -> 2.2727273 | L22: =[23]Brewhouse!$P195 -> 59 | M22: =[23]Brewhouse!$U195-[23]Brewhouse!$T195 -> 0.10208333 | N22: =[23]Brewhouse!$AW195 -> 0.24652778 | O22: =[23]Brewhouse!$AV195 -> R.Sookram | R22: =B22 -> STAG | S22: =VLOOKUP($B22,$R$3:$X$9,2,FALSE) -> 11.6 | T22: =VLOOKUP($B22,$R$3:$X$9,3,FALSE) -> 12 | U22: =VLOOKUP($B22,$R$3:$X$9,4,FALSE) -> 0 | V22: =VLOOKUP($B22,$R$3:$X$9,5,FALSE) -> 0.11805556 | W22: =VLOOKUP($B22,$R$3:$X$9,6,FALSE) -> 0.22569444 | X22: =VLOOKUP($B22,$R$3:$X$9,7,FALSE) -> 0.26388889 | Y22: =VLOOKUP($B22,$R$3:$Z$9,8,FALSE) -> 0 | Z22: =VLOOKUP($B22,$R$3:$Z$9,9,FALSE) -> 60
B23: STAG | C23: =[23]Brewhouse!$A196 -> ST178 | D23: =[23]Brewhouse!$AD196 -> 54.6 | E23: =[23]Brewhouse!$AG196 -> 51.4 | F23: =[23]Brewhouse!$V196 -> 59 | G23: =[23]Brewhouse!$AE196 -> 11.9 | H23: 11.9 | I23: =[23]Brewhouse!$AS196 -> 101.4475 | J23: =[23]Brewhouse!$AT196 -> 102.94736 | K23: =[23]Brewhouse!$Q196 -> 5.4151625 | L23: =[23]Brewhouse!$P196 -> 60 | M23: =[23]Brewhouse!$U196-[23]Brewhouse!$T196 -> 0.11319444 | N23: =[23]Brewhouse!$AW196 -> 0.26805556 | O23: =[23]Brewhouse!$AV196 -> K. Benjamin | R23: =B23 -> STAG | S23: =VLOOKUP($B23,$R$3:$X$9,2,FALSE) -> 11.6 | T23: =VLOOKUP($B23,$R$3:$X$9,3,FALSE) -> 12 | U23: =VLOOKUP($B23,$R$3:$X$9,4,FALSE) -> 0 | V23: =VLOOKUP($B23,$R$3:$X$9,5,FALSE) -> 0.11805556 | W23: =VLOOKUP($B23,$R$3:$X$9,6,FALSE) -> 0.22569444 | X23: =VLOOKUP($B23,$R$3:$X$9,7,FALSE) -> 0.26388889 | Y23: =VLOOKUP($B23,$R$3:$Z$9,8,FALSE) -> 0 | Z23: =VLOOKUP($B23,$R$3:$Z$9,9,FALSE) -> 60
B24: STAG | C24: =[23]Brewhouse!$A197 -> ST179 | D24: =[23]Brewhouse!$AD197 -> 54.8 | E24: =[23]Brewhouse!$AG197 -> 51.9 | F24: =[23]Brewhouse!$V197 -> 60 | G24: =[23]Brewhouse!$AE197 -> 12 | H24: 12 | I24: =[23]Brewhouse!$AS197 -> 103.33939 | J24: =[23]Brewhouse!$AT197 -> 104.86721 | K24: =[23]Brewhouse!$Q197 -> 4.9270073 | L24: =[23]Brewhouse!$P197 -> 62 | M24: =[23]Brewhouse!$U197-[23]Brewhouse!$T197 -> 0.12916667 | N24: =[23]Brewhouse!$AW197 -> 0.28263889 | O24: =[23]Brewhouse!$AV197 -> K. Benjamin | P24: Spent grain rake didn't go down automatically | R24: =B24 -> STAG | S24: =VLOOKUP($B24,$R$3:$X$9,2,FALSE) -> 11.6 | T24: =VLOOKUP($B24,$R$3:$X$9,3,FALSE) -> 12 | U24: =VLOOKUP($B24,$R$3:$X$9,4,FALSE) -> 0 | V24: =VLOOKUP($B24,$R$3:$X$9,5,FALSE) -> 0.11805556 | W24: =VLOOKUP($B24,$R$3:$X$9,6,FALSE) -> 0.22569444 | X24: =VLOOKUP($B24,$R$3:$X$9,7,FALSE) -> 0.26388889 | Y24: =VLOOKUP($B24,$R$3:$Z$9,8,FALSE) -> 0 | Z24: =VLOOKUP($B24,$R$3:$Z$9,9,FALSE) -> 60
B25: STAG | C25: =[23]Brewhouse!$A198 -> ST180 | D25: =[23]Brewhouse!$AD198 -> 54.3 | E25: =[23]Brewhouse!$AG198 -> 51.2 | F25: =[23]Brewhouse!$V198 -> 63 | G25: =[23]Brewhouse!$AE198 -> 11.6 | H25: 11.7 | I25: =[23]Brewhouse!$AS198 -> 98.251297 | J25: =[23]Brewhouse!$AT198 -> 99.704369 | K25: =[23]Brewhouse!$Q198 -> 3.8461538 | L25: =[23]Brewhouse!$P198 -> 62 | M25: =[23]Brewhouse!$U198-[23]Brewhouse!$T198 -> 0.11041667 | N25: =[23]Brewhouse!$AW198 -> 0.26319444 | O25: =[23]Brewhouse!$AV198 -> K. Benjamin | P25: Brew copper up in pre-run tank | R25: =B25 -> STAG | S25: =VLOOKUP($B25,$R$3:$X$9,2,FALSE) -> 11.6 | T25: =VLOOKUP($B25,$R$3:$X$9,3,FALSE) -> 12 | U25: =VLOOKUP($B25,$R$3:$X$9,4,FALSE) -> 0 | V25: =VLOOKUP($B25,$R$3:$X$9,5,FALSE) -> 0.11805556 | W25: =VLOOKUP($B25,$R$3:$X$9,6,FALSE) -> 0.22569444 | X25: =VLOOKUP($B25,$R$3:$X$9,7,FALSE) -> 0.26388889 | Y25: =VLOOKUP($B25,$R$3:$Z$9,8,FALSE) -> 0 | Z25: =VLOOKUP($B25,$R$3:$Z$9,9,FALSE) -> 60
B26: STAG | C26: =[23]Brewhouse!$A199 -> ST181 | D26: =[23]Brewhouse!$AD199 -> 53.7 | E26: =[23]Brewhouse!$AG199 -> 50.5 | F26: =[23]Brewhouse!$V199 -> 65 | G26: =[23]Brewhouse!$AE199 -> 12.04 | H26: 11.8 | I26: =[23]Brewhouse!$AS199 -> 100.42613 | J26: =[23]Brewhouse!$AT199 -> 101.91137 | K26: =[23]Brewhouse!$Q199 -> 3.2967033 | L26: =[23]Brewhouse!$P199 -> 59 | M26: =[23]Brewhouse!$U199-[23]Brewhouse!$T199 -> 0.13541667 | N26: =[23]Brewhouse!$AW199 -> 0.28472222 | O26: =[23]Brewhouse!$AV199 -> K. Benjamin | P26: Extra boiled | R26: =B26 -> STAG | S26: =VLOOKUP($B26,$R$3:$X$9,2,FALSE) -> 11.6 | T26: =VLOOKUP($B26,$R$3:$X$9,3,FALSE) -> 12 | U26: =VLOOKUP($B26,$R$3:$X$9,4,FALSE) -> 0 | V26: =VLOOKUP($B26,$R$3:$X$9,5,FALSE) -> 0.11805556 | W26: =VLOOKUP($B26,$R$3:$X$9,6,FALSE) -> 0.22569444 | X26: =VLOOKUP($B26,$R$3:$X$9,7,FALSE) -> 0.26388889 | Y26: =VLOOKUP($B26,$R$3:$Z$9,8,FALSE) -> 0 | Z26: =VLOOKUP($B26,$R$3:$Z$9,9,FALSE) -> 60
B27: STAG | C27: =[23]Brewhouse!$A200 -> ST182 | D27: =[23]Brewhouse!$AD200 -> 53.7 | E27: =[23]Brewhouse!$AG200 -> 50.6 | F27: =[23]Brewhouse!$V200 -> 75 | G27: =[23]Brewhouse!$AE200 -> 12.01 | H27: 12 | I27: =[23]Brewhouse!$AS200 -> 100.62499 | J27: =[23]Brewhouse!$AT200 -> 102.11317 | K27: =[23]Brewhouse!$Q200 -> 4.9001815 | L27: =[23]Brewhouse!$P200 -> 55 | M27: =[23]Brewhouse!$U200-[23]Brewhouse!$T200 -> 0.12777778 | N27: =[23]Brewhouse!$AW200 -> 0.29583333 | O27: =[23]Brewhouse!$AV200 -> K. Benjamin | P27: Heating up problem | R27: =B27 -> STAG | S27: =VLOOKUP($B27,$R$3:$X$9,2,FALSE) -> 11.6 | T27: =VLOOKUP($B27,$R$3:$X$9,3,FALSE) -> 12 | U27: =VLOOKUP($B27,$R$3:$X$9,4,FALSE) -> 0 | V27: =VLOOKUP($B27,$R$3:$X$9,5,FALSE) -> 0.11805556 | W27: =VLOOKUP($B27,$R$3:$X$9,6,FALSE) -> 0.22569444 | X27: =VLOOKUP($B27,$R$3:$X$9,7,FALSE) -> 0.26388889 | Y27: =VLOOKUP($B27,$R$3:$Z$9,8,FALSE) -> 0 | Z27: =VLOOKUP($B27,$R$3:$Z$9,9,FALSE) -> 60
B28: STAG | C28: =[23]Brewhouse!$A201 -> ST183 | D28: =[23]Brewhouse!$AD201 -> 54.1 | E28: =[23]Brewhouse!$AG201 -> 50.7 | F28: =[23]Brewhouse!$V201 -> 69 | G28: =[23]Brewhouse!$AE201 -> 11.68 | H28: 11.8 | I28: =[23]Brewhouse!$AS201 -> 98.29769 | J28: =[23]Brewhouse!$AT201 -> 99.750975 | K28: =[23]Brewhouse!$Q201 -> 3.4482759 | L28: =[23]Brewhouse!$P201 -> 62 | M28: =[23]Brewhouse!$U201-[23]Brewhouse!$T201 -> 0.11388889 | N28: =[23]Brewhouse!$AW201 -> 0.28680556 | O28: =[23]Brewhouse!$AV201 -> D. Gomaz | P28: Heating up problem | R28: =B28 -> STAG | S28: =VLOOKUP($B28,$R$3:$X$9,2,FALSE) -> 11.6 | T28: =VLOOKUP($B28,$R$3:$X$9,3,FALSE) -> 12 | U28: =VLOOKUP($B28,$R$3:$X$9,4,FALSE) -> 0 | V28: =VLOOKUP($B28,$R$3:$X$9,5,FALSE) -> 0.11805556 | W28: =VLOOKUP($B28,$R$3:$X$9,6,FALSE) -> 0.22569444 | X28: =VLOOKUP($B28,$R$3:$X$9,7,FALSE) -> 0.26388889 | Y28: =VLOOKUP($B28,$R$3:$Z$9,8,FALSE) -> 0 | Z28: =VLOOKUP($B28,$R$3:$Z$9,9,FALSE) -> 60
B29: STAG | C29: =[23]Brewhouse!$A202 -> ST184 | D29: =[23]Brewhouse!$AD202 -> 54.7 | E29: =[23]Brewhouse!$AG202 -> 51.8 | F29: =[23]Brewhouse!$V202 -> 68 | G29: =[23]Brewhouse!$AE202 -> 11.74 | H29: 11.7 | I29: =[23]Brewhouse!$AS202 -> 100.30485 | J29: =[23]Brewhouse!$AT202 -> 101.78829 | K29: =[23]Brewhouse!$Q202 -> 3.2667877 | L29: =[23]Brewhouse!$P202 -> 58 | M29: =[23]Brewhouse!$U202-[23]Brewhouse!$T202 -> 0.11319444 | N29: =[23]Brewhouse!$AW202 -> 0.26527778 | O29: =[23]Brewhouse!$AV202 -> D. Gomaz | P29: Heating up problem | R29: =B29 -> STAG | S29: =VLOOKUP($B29,$R$3:$X$9,2,FALSE) -> 11.6 | T29: =VLOOKUP($B29,$R$3:$X$9,3,FALSE) -> 12 | U29: =VLOOKUP($B29,$R$3:$X$9,4,FALSE) -> 0 | V29: =VLOOKUP($B29,$R$3:$X$9,5,FALSE) -> 0.11805556 | W29: =VLOOKUP($B29,$R$3:$X$9,6,FALSE) -> 0.22569444 | X29: =VLOOKUP($B29,$R$3:$X$9,7,FALSE) -> 0.26388889 | Y29: =VLOOKUP($B29,$R$3:$Z$9,8,FALSE) -> 0 | Z29: =VLOOKUP($B29,$R$3:$Z$9,9,FALSE) -> 60
B31: STARMALT | C31: =[27]Brewhouse!$A36 -> SM027 | D31: =[27]Brewhouse!$AH$36 -> 54.1 | E31: =[27]Brewhouse!$AM$36 -> 52.1 | F31: =[27]Brewhouse!$Z36 -> 86 | G31: =[27]Brewhouse!$AK36 -> 17.32 | H31: 17.3 | I31: =[27]Brewhouse!$AY36 -> 98.749265 | J31: =[27]Brewhouse!$AZ36 -> 99.601552 | K31: =[27]Brewhouse!$U36 -> 0.70240296 | L31: =[27]Brewhouse!$T36 -> 60 | M31: =[27]Brewhouse!$Y36-[27]Brewhouse!$X36 -> 0.13611111 | N31: =[27]Brewhouse!$AD36 -> 0.28263889 | O31: =[27]Brewhouse!$BC36 -> D. Gomaz | P31: Poor cooling
R42: =B42 -> 0 | S42: =VLOOKUP($B42,$R$3:$X$9,2,FALSE) -> #N/A | T42: =VLOOKUP($B42,$R$3:$X$9,3,FALSE) -> #N/A | U42: =VLOOKUP($B42,$R$3:$X$9,4,FALSE) -> #N/A | V42: =VLOOKUP($B42,$R$3:$X$9,5,FALSE) -> #N/A | W42: =VLOOKUP($B42,$R$3:$X$9,6,FALSE) -> #N/A | X42: =VLOOKUP($B42,$R$3:$X$9,7,FALSE) -> #N/A | Y42: =VLOOKUP($B42,$R$3:$Z$9,8,FALSE) -> #N/A | Z42: =VLOOKUP($B42,$R$3:$Z$9,9,FALSE) -> #N/A
R43: =B43 -> 0 | S43: =VLOOKUP($B43,$R$3:$X$9,2,FALSE) -> #N/A | T43: =VLOOKUP($B43,$R$3:$X$9,3,FALSE) -> #N/A | U43: =VLOOKUP($B43,$R$3:$X$9,4,FALSE) -> #N/A | V43: =VLOOKUP($B43,$R$3:$X$9,5,FALSE) -> #N/A | W43: =VLOOKUP($B43,$R$3:$X$9,6,FALSE) -> #N/A | X43: =VLOOKUP($B43,$R$3:$X$9,7,FALSE) -> #N/A | Y43: =VLOOKUP($B43,$R$3:$Z$9,8,FALSE) -> #N/A | Z43: =VLOOKUP($B43,$R$3:$Z$9,9,FALSE) -> #N/A
R44: =B44 -> 0 | S44: =VLOOKUP($B44,$R$3:$X$9,2,FALSE) -> #N/A | T44: =VLOOKUP($B44,$R$3:$X$9,3,FALSE) -> #N/A | U44: =VLOOKUP($B44,$R$3:$X$9,4,FALSE) -> #N/A | V44: =VLOOKUP($B44,$R$3:$X$9,5,FALSE) -> #N/A | W44: =VLOOKUP($B44,$R$3:$X$9,6,FALSE) -> #N/A | X44: =VLOOKUP($B44,$R$3:$X$9,7,FALSE) -> #N/A | Y44: =VLOOKUP($B44,$R$3:$Z$9,8,FALSE) -> #N/A | Z44: =VLOOKUP($B44,$R$3:$Z$9,9,FALSE) -> #N/A
R45: =B45 -> 0 | S45: =VLOOKUP($B45,$R$3:$X$9,2,FALSE) -> #N/A | T45: =VLOOKUP($B45,$R$3:$X$9,3,FALSE) -> #N/A | U45: =VLOOKUP($B45,$R$3:$X$9,4,FALSE) -> #N/A | V45: =VLOOKUP($B45,$R$3:$X$9,5,FALSE) -> #N/A | W45: =VLOOKUP($B45,$R$3:$X$9,6,FALSE) -> #N/A | X45: =VLOOKUP($B45,$R$3:$X$9,7,FALSE) -> #N/A | Y45: =VLOOKUP($B45,$R$3:$Z$9,8,FALSE) -> #N/A | Z45: =VLOOKUP($B45,$R$3:$Z$9,9,FALSE) -> #N/A
R46: =B46 -> 0 | S46: =VLOOKUP($B46,$R$3:$X$9,2,FALSE) -> #N/A | T46: =VLOOKUP($B46,$R$3:$X$9,3,FALSE) -> #N/A | U46: =VLOOKUP($B46,$R$3:$X$9,4,FALSE) -> #N/A | V46: =VLOOKUP($B46,$R$3:$X$9,5,FALSE) -> #N/A | W46: =VLOOKUP($B46,$R$3:$X$9,6,FALSE) -> #N/A | X46: =VLOOKUP($B46,$R$3:$X$9,7,FALSE) -> #N/A | Y46: =VLOOKUP($B46,$R$3:$Z$9,8,FALSE) -> #N/A | Z46: =VLOOKUP($B46,$R$3:$Z$9,9,FALSE) -> #N/A
R47: =B47 -> 0 | S47: =VLOOKUP($B47,$R$3:$X$9,2,FALSE) -> #N/A | T47: =VLOOKUP($B47,$R$3:$X$9,3,FALSE) -> #N/A | U47: =VLOOKUP($B47,$R$3:$X$9,4,FALSE) -> #N/A | V47: =VLOOKUP($B47,$R$3:$X$9,5,FALSE) -> #N/A | W47: =VLOOKUP($B47,$R$3:$X$9,6,FALSE) -> #N/A | X47: =VLOOKUP($B47,$R$3:$X$9,7,FALSE) -> #N/A | Y47: =VLOOKUP($B47,$R$3:$Z$9,8,FALSE) -> #N/A | Z47: =VLOOKUP($B47,$R$3:$Z$9,9,FALSE) -> #N/A
R48: =B48 -> 0 | S48: =VLOOKUP($B48,$R$3:$X$9,2,FALSE) -> #N/A | T48: =VLOOKUP($B48,$R$3:$X$9,3,FALSE) -> #N/A | U48: =VLOOKUP($B48,$R$3:$X$9,4,FALSE) -> #N/A | V48: =VLOOKUP($B48,$R$3:$X$9,5,FALSE) -> #N/A | W48: =VLOOKUP($B48,$R$3:$X$9,6,FALSE) -> #N/A | X48: =VLOOKUP($B48,$R$3:$X$9,7,FALSE) -> #N/A | Y48: =VLOOKUP($B48,$R$3:$Z$9,8,FALSE) -> #N/A | Z48: =VLOOKUP($B48,$R$3:$Z$9,9,FALSE) -> #N/A
R49: =B49 -> 0 | S49: =VLOOKUP($B49,$R$3:$X$9,2,FALSE) -> #N/A | T49: =VLOOKUP($B49,$R$3:$X$9,3,FALSE) -> #N/A | U49: =VLOOKUP($B49,$R$3:$X$9,4,FALSE) -> #N/A | V49: =VLOOKUP($B49,$R$3:$X$9,5,FALSE) -> #N/A | W49: =VLOOKUP($B49,$R$3:$X$9,6,FALSE) -> #N/A | X49: =VLOOKUP($B49,$R$3:$X$9,7,FALSE) -> #N/A | Y49: =VLOOKUP($B49,$R$3:$Z$9,8,FALSE) -> #N/A | Z49: =VLOOKUP($B49,$R$3:$Z$9,9,FALSE) -> #N/A
R50: =B50 -> 0 | S50: =VLOOKUP($B50,$R$3:$X$9,2,FALSE) -> #N/A | T50: =VLOOKUP($B50,$R$3:$X$9,3,FALSE) -> #N/A | U50: =VLOOKUP($B50,$R$3:$X$9,4,FALSE) -> #N/A | V50: =VLOOKUP($B50,$R$3:$X$9,5,FALSE) -> #N/A | W50: =VLOOKUP($B50,$R$3:$X$9,6,FALSE) -> #N/A | X50: =VLOOKUP($B50,$R$3:$X$9,7,FALSE) -> #N/A | Y50: =VLOOKUP($B50,$R$3:$Z$9,8,FALSE) -> #N/A | Z50: =VLOOKUP($B50,$R$3:$Z$9,9,FALSE) -> #N/A
I51: EXTRACT RECOVERY | R51: =B51 -> 0 | S51: =VLOOKUP($B51,$R$3:$X$9,2,FALSE) -> #N/A | T51: =VLOOKUP($B51,$R$3:$X$9,3,FALSE) -> #N/A | U51: =VLOOKUP($B51,$R$3:$X$9,4,FALSE) -> #N/A | V51: =VLOOKUP($B51,$R$3:$X$9,5,FALSE) -> #N/A | W51: =VLOOKUP($B51,$R$3:$X$9,6,FALSE) -> #N/A | X51: =VLOOKUP($B51,$R$3:$X$9,7,FALSE) -> #N/A | Y51: =VLOOKUP($B51,$R$3:$Z$9,8,FALSE) -> #N/A | Z51: =VLOOKUP($B51,$R$3:$Z$9,9,FALSE) -> #N/A
...

Sheet May 6th
S1: P.G. | U1: Hot Time | W1: Process Time | Y1: Cooling Time
B2: Brewing Department Daily Process Loss Report | S2: Lower | T2: Upper | U2: Lower | V2: Upper | W2: Lower | X2: Upper | Y2: Lower | Z2: Upper
R3: CARIB | S3: 11.6 | T3: 12 | U3: 0 | V3: 0.11805556 | W3: 0.22569444 | X3: 0.26388889 | Y3: 0 | Z3: 60 | AB3: HR- PISNER
B4: Date: | C4: 45784 | J4: LOT WORT COLOUR: 3.5 | M4: Filter Sheets (Target 20 days) | R4: STAG | S4: 11.6 | T4: 12 | U4: 0 | V4: 0.11805556 | W4: 0.22569444 | X4: 0.26388889 | Y4: 0 | Z4: 60
M5: Double | N5: Single | R5: GUINNESS | S5: 17 | T5: 17.5 | U5: 0 | V5: 0.10763889 | W5: 0.24652778 | X5: 0.28472222 | Y5: 0 | Z5: 60
J6: MALT LOT: Lot 35 | L6: Sheet Day | R6: MACKESON | S6: 13.3 | T6: 13.5 | U6: 0 | V6: 0.12905093 | W6: 0.27430556 | X6: 0.30208333 | Y6: 0
R7: STARMALT | S7: 17.1 | T7: 17.5 | U7: 0 | V7: 0.13605324 | W7: 0.27430556 | X7: 0.30902778 | Y7: 0 | Z7: 60
B8: Brand | C8: Brew no. | D8: Kett. Hls | E8: Wort | F8: Cool Time(Mins) | G8: Cast. P.G. (Lab Result) | H8: Cast P.G. (Cellar Operator)-gravity | I8: Extr. Rec (78.95%) | J8: Theor. Extr. (77.5%) | K8: Boil Off /Vol. (4-6%) | L8: Boil Time | M8: Total Hot | N8: Brewing | O8: Operator | P8: Actual Pilsen Malt | R8: Hurricane Reef | S8: 16.6 | T8: 17 | U8: 0 | V8: 0.12905093 | W8: 0.27430556 | X8: 0.30208333 | Y8: 0
E9: Meter (Hls) | F9: Target(< 60Mins) | M9: Time | R9: VITAMALT | S9: 14.4 | T9: 14.6 | U9: 0 | V9: 0.13905093 | W9: 0.26041667 | X9: 0.29513889 | Y9: 0 | Z9: 75
B10: STARMALT | C10: =[27]Brewhouse!$A37 -> SM028 | D10: =[27]Brewhouse!$AH36 -> 54.1 | E10: =[27]Brewhouse!$AM36 -> 52.1 | F10: =[27]Brewhouse!$Z37 -> 76 | G10: =[27]Brewhouse!$AK37 -> 17.6 | I10: =[27]Brewhouse!$AY37 -> 96.781968 | J10: =[27]Brewhouse!$AZ37 -> 97.6165 | K10: =[27]Brewhouse!$U37 -> 3.9846743 | L10: =[27]Brewhouse!$T37 -> 61 | M10: =[27]Brewhouse!$Y37-[27]Brewhouse!$X37 -> 0.12708333 | N10: =[27]Brewhouse!$AD37 -> 0.27847222 | O10: =[27]Brewhouse!$BC37 -> R.Sookram | P10: Compressor down | R10: =B10 -> STARMALT | S10: =VLOOKUP($B10,$R$3:$X$9,2,FALSE) -> 17.1 | T10: =VLOOKUP($B10,$R$3:$X$9,3,FALSE) -> 17.5 | U10: =VLOOKUP($B10,$R$3:$X$9,4,FALSE) -> 0 | V10: =VLOOKUP($B10,$R$3:$X$9,5,FALSE) -> 0.13605324 | W10: =VLOOKUP($B10,$R$3:$X$9,6,FALSE) -> 0.27430556 | X10: =VLOOKUP($B10,$R$3:$X$9,7,FALSE) -> 0.30902778 | Y10: =VLOOKUP($B10,$R$3:$Z$9,8,FALSE) -> 0 | Z10: =VLOOKUP($B10,$R$3:$Z$9,9,FALSE) -> 60
B11: STARMALT | C11: =[27]Brewhouse!$A38 -> SM029 | D11: =[27]Brewhouse!$AH37 -> 52.2 | E11: =[27]Brewhouse!$AM37 -> 50.1 | F11: =[27]Brewhouse!$Z38 -> 70 | G11: =[27]Brewhouse!$AK38 -> 17.5 | I11: =[27]Brewhouse!$AY38 -> 97.813869 | J11: =[27]Brewhouse!$AZ38 -> 98.658084 | K11: =[27]Brewhouse!$U38 -> 4.1132075 | L11: =[27]Brewhouse!$T38 -> 60 | M11: =[27]Brewhouse!$Y38-[27]Brewhouse!$X38 -> 0.12361111 | N11: =[27]Brewhouse!$AD38 -> 0.27083333 | O11: =[27]Brewhouse!$BC38 -> K. Benjamin | P11: Compressor down | R11: =B11 -> STARMALT | S11: =VLOOKUP($B11,$R$3:$X$9,2,FALSE) -> 17.1 | T11: =VLOOKUP($B11,$R$3:$X$9,3,FALSE) -> 17.5 | U11: =VLOOKUP($B11,$R$3:$X$9,4,FALSE) -> 0 | V11: =VLOOKUP($B11,$R$3:$X$9,5,FALSE) -> 0.13605324 | W11: =VLOOKUP($B11,$R$3:$X$9,6,FALSE) -> 0.27430556 | X11: =VLOOKUP($B11,$R$3:$X$9,7,FALSE) -> 0.30902778 | Y11: =VLOOKUP($B11,$R$3:$Z$9,8,FALSE) -> 0 | Z11: =VLOOKUP($B11,$R$3:$Z$9,9,FALSE) -> 60
B12: STARMALT | C12: =[27]Brewhouse!$A39 -> SM030 | D12: =[27]Brewhouse!$AH38 -> 53 | E12: =[27]Brewhouse!$AM38 -> 51 | F12: =[27]Brewhouse!$Z39 -> 81 | G12: =[27]Brewhouse!$AK39 -> 17.14 | I12: =[27]Brewhouse!$AY39 -> 99.687121 | J12: =[27]Brewhouse!$AZ39 -> 100.5483 | K12: =[27]Brewhouse!$U39 -> 2.6235741 | L12: =[27]Brewhouse!$T39 -> 61 | M12: =[27]Brewhouse!$Y39-[27]Brewhouse!$X39 -> 0.13819444 | N12: =[27]Brewhouse!$AD39 -> 0.29027778 | O12: =[27]Brewhouse!$BC39 -> K. Benjamin | P12: Compressor down | R12: =B12 -> STARMALT | S12: =VLOOKUP($B12,$R$3:$X$9,2,FALSE) -> 17.1 | T12: =VLOOKUP($B12,$R$3:$X$9,3,FALSE) -> 17.5 | U12: =VLOOKUP($B12,$R$3:$X$9,4,FALSE) -> 0 | V12: =VLOOKUP($B12,$R$3:$X$9,5,FALSE) -> 0.13605324 | W12: =VLOOKUP($B12,$R$3:$X$9,6,FALSE) -> 0.27430556 | X12: =VLOOKUP($B12,$R$3:$X$9,7,FALSE) -> 0.30902778 | Y12: =VLOOKUP($B12,$R$3:$Z$9,8,FALSE) -> 0 | Z12: =VLOOKUP($B12,$R$3:$Z$9,9,FALSE) -> 60
B13: STARMALT | C13: =[27]Brewhouse!$A40 -> SM031 | D13: =[27]Brewhouse!$AH39 -> 52.6 | E13: =[27]Brewhouse!$AM39 -> 53.3 | F13: =[27]Brewhouse!$Z40 -> 83 | G13: =[27]Brewhouse!$AK40 -> 16.87 | I13: =[27]Brewhouse!$AY40 -> 98.326954 | J13: =[27]Brewhouse!$AZ40 -> 99.175597 | K13: =[27]Brewhouse!$U40 -> 4.0445269 | L13: =[27]Brewhouse!$T40 -> 59 | M13: =[27]Brewhouse!$Y40-[27]Brewhouse!$X40 -> 0.13819444 | N13: =[27]Brewhouse!$AD40 -> 0.29375 | O13: =[27]Brewhouse!$BC40 -> K. Benjamin | P13: Compensation brews | R13: =B13 -> STARMALT | S13: =VLOOKUP($B13,$R$3:$X$9,2,FALSE) -> 17.1 | T13: =VLOOKUP($B13,$R$3:$X$9,3,FALSE) -> 17.5 | U13: =VLOOKUP($B13,$R$3:$X$9,4,FALSE) -> 0 | V13: =VLOOKUP($B13,$R$3:$X$9,5,FALSE) -> 0.13605324 | W13: =VLOOKUP($B13,$R$3:$X$9,6,FALSE) -> 0.27430556 | X13: =VLOOKUP($B13,$R$3:$X$9,7,FALSE) -> 0.30902778 | Y13: =VLOOKUP($B13,$R$3:$Z$9,8,FALSE) -> 0 | Z13: =VLOOKUP($B13,$R$3:$Z$9,9,FALSE) -> 60
B14: STARMALT | C14: =[27]Brewhouse!$A41 -> SM032 | D14: =[27]Brewhouse!$AH40 -> 53.9 | E14: =[27]Brewhouse!$AM40 -> 53.2 | F14: =[27]Brewhouse!$Z41 -> 101 | G14: =[27]Brewhouse!$AK41 -> 17 | I14: =[27]Brewhouse!$AY41 -> 98.820484 | J14: =[27]Brewhouse!$AZ41 -> 99.672593 | K14: =[27]Brewhouse!$U41 -> 2.5988701 | L14: =[27]Brewhouse!$T41 -> 60 | M14: =[27]Brewhouse!$Y41-[27]Brewhouse!$X41 -> 0.14513889 | N14: =[27]Brewhouse!$AD41 -> 0.30347222 | O14: =[27]Brewhouse!$BC41 -> K. Benjamin | P14: Compensation brews | R14: =B14 -> STARMALT | S14: =VLOOKUP($B14,$R$3:$X$9,2,FALSE) -> 17.1 | T14: =VLOOKUP($B14,$R$3:$X$9,3,FALSE) -> 17.5 | U14: =VLOOKUP($B14,$R$3:$X$9,4,FALSE) -> 0 | V14: =VLOOKUP($B14,$R$3:$X$9,5,FALSE) -> 0.13605324 | W14: =VLOOKUP($B14,$R$3:$X$9,6,FALSE) -> 0.27430556 | X14: =VLOOKUP($B14,$R$3:$X$9,7,FALSE) -> 0.30902778 | Y14: =VLOOKUP($B14,$R$3:$Z$9,8,FALSE) -> 0 | Z14: =VLOOKUP($B14,$R$3:$Z$9,9,FALSE) -> 60
B15: STARMALT | C15: =[27]Brewhouse!$A42 -> SM033 | D15: =[27]Brewhouse!$AH41 -> 53.1 | E15: =[27]Brewhouse!$AM41 -> 53.1 | F15: =[27]Brewhouse!$Z42 -> 89 | G15: =[27]Brewhouse!$AK42 -> 16.9 | I15: =[27]Brewhouse!$AY42 -> 95.562254 | J15: =[27]Brewhouse!$AZ42 -> 96.432694 | K15: =[27]Brewhouse!$U42 -> 4.2616822 | L15: =[27]Brewhouse!$T42 -> 60 | M15: =[27]Brewhouse!$Y42-[27]Brewhouse!$X42 -> 0.13541667 | N15: =[27]Brewhouse!$AD42 -> 0.29444444 | O15: =[27]Brewhouse!$BC42 -> D. Gomaz | P15: Compensation brews | R15: =B15 -> STARMALT | S15: =VLOOKUP($B15,$R$3:$X$9,2,FALSE) -> 17.1 | T15: =VLOOKUP($B15,$R$3:$X$9,3,FALSE) -> 17.5 | U15: =VLOOKUP($B15,$R$3:$X$9,4,FALSE) -> 0 | V15: =VLOOKUP($B15,$R$3:$X$9,5,FALSE) -> 0.13605324 | W15: =VLOOKUP($B15,$R$3:$X$9,6,FALSE) -> 0.27430556 | X15: =VLOOKUP($B15,$R$3:$X$9,7,FALSE) -> 0.30902778 | Y15: =VLOOKUP($B15,$R$3:$Z$9,8,FALSE) -> 0 | Z15: =VLOOKUP($B15,$R$3:$Z$9,9,FALSE) -> 60
B16: STARMALT | C16: =[27]Brewhouse!$A43 -> SM034 | D16: =[27]Brewhouse!$AH42 -> 53.5 | E16: =[27]Brewhouse!$AM42 -> 49.1 | F16: =[27]Brewhouse!$Z43 -> 86 | G16: =[27]Brewhouse!$AK43 -> 16.82 | I16: =[27]Brewhouse!$AY43 -> 101.88658 | J16: =[27]Brewhouse!$AZ43 -> 102.81463 | K16: =[27]Brewhouse!$U43 -> 7.0289855 | L16: =[27]Brewhouse!$T43 -> 62 | M16: =[27]Brewhouse!$Y43-[27]Brewhouse!$X43 -> 0.13611111 | N16: =[27]Brewhouse!$AD43 -> 0.29166667 | O16: =[27]Brewhouse!$BC43 -> D. Gomaz | P16: Compensation brews | R16: =B16 -> STARMALT | S16: =VLOOKUP($B16,$R$3:$X$9,2,FALSE) -> 17.1 | T16: =VLOOKUP($B16,$R$3:$X$9,3,FALSE) -> 17.5 | U16: =VLOOKUP($B16,$R$3:$X$9,4,FALSE) -> 0 | V16: =VLOOKUP($B16,$R$3:$X$9,5,FALSE) -> 0.13605324 | W16: =VLOOKUP($B16,$R$3:$X$9,6,FALSE) -> 0.27430556 | X16: =VLOOKUP($B16,$R$3:$X$9,7,FALSE) -> 0.30902778 | Y16: =VLOOKUP($B16,$R$3:$Z$9,8,FALSE) -> 0 | Z16: =VLOOKUP($B16,$R$3:$Z$9,9,FALSE) -> 60
R17: =B17 -> 0 | S17: =VLOOKUP($B17,$R$3:$X$9,2,FALSE) -> #N/A | T17: =VLOOKUP($B17,$R$3:$X$9,3,FALSE) -> #N/A | U17: =VLOOKUP($B17,$R$3:$X$9,4,FALSE) -> #N/A | V17: =VLOOKUP($B17,$R$3:$X$9,5,FALSE) -> #N/A | W17: =VLOOKUP($B17,$R$3:$X$9,6,FALSE) -> #N/A | X17: =VLOOKUP($B17,$R$3:$X$9,7,FALSE) -> #N/A | Y17: =VLOOKUP($B17,$R$3:$Z$9,8,FALSE) -> #N/A | Z17: =VLOOKUP($B17,$R$3:$Z$9,9,FALSE) -> #N/A
R18: =B18 -> 0 | S18: =VLOOKUP($B18,$R$3:$X$9,2,FALSE) -> #N/A | T18: =VLOOKUP($B18,$R$3:$X$9,3,FALSE) -> #N/A | U18: =VLOOKUP($B18,$R$3:$X$9,4,FALSE) -> #N/A | V18: =VLOOKUP($B18,$R$3:$X$9,5,FALSE) -> #N/A | W18: =VLOOKUP($B18,$R$3:$X$9,6,FALSE) -> #N/A | X18: =VLOOKUP($B18,$R$3:$X$9,7,FALSE) -> #N/A | Y18: =VLOOKUP($B18,$R$3:$Z$9,8,FALSE) -> #N/A | Z18: =VLOOKUP($B18,$R$3:$Z$9,9,FALSE) -> #N/A
