Workbook
Name ProductList: [1]November15!$R$3:$R$9
Name ProductList: [2]November15!$R$3:$R$9

Sheet Dec 18th
T1: P.G. | V1: Hot Time | X1: Process Time | Z1: Cooling Time
B2: Brewing Department Daily Process Loss Report | T2: Lower | U2: Upper | V2: Lower | W2: Upper | X2: Lower | Y2: Upper | Z2: Lower | AA2: Upper
S3: CARIB | T3: 11.6 | U3: 12 | V3: 0 | W3: 0.11805556 | X3: 0.17361111 | Y3: 0.21180556 | Z3: 0 | AA3: 60 | AC3: HR- PISNER
B4: Date: | C4: 45278 | J4: LOT WORT COLOUR: 3.4 | M4: Filter Sheets (Target 20 days) | S4: STAG | T4: 11.6 | U4: 12 | V4: 0 | W4: 0.11805556 | X4: 0.17361111 | Y4: 0.21180556 | Z4: 0 | AA4: 60
M5: Double | N5: Single | S5: GUINNESS | T5: 17 | U5: 17.5 | V5: 0 | W5: 0.10763889 | X5: 0.19444444 | Y5: 0.23263889 | Z5: 0 | AA5: 60
J6: MALT LOT: Lot 8 | L6: Sheet Day | S6: MACKESON | T6: 13.3 | U6: 13.5 | V6: 0 | W6: 0.12905093 | X6: 0.22222222 | Y6: 0.25347222 | Z6: 0
S7: STARMALT | T7: 17.1 | U7: 17.5 | V7: 0 | W7: 0.13605324 | X7: 0.20833333 | Y7: 0.24305556 | Z7: 0 | AA7: 60
B8: Brand | C8: Brew no. | D8: Kett. Hls | E8: Wort | F8: Cool Time(Mins) | G8: Cast. P.G. (Lab Result) | H8: Cast P.G. (Cellar Operator)-gravity | I8: Extr. Rec (79.1%) | J8: Theor. Extr. (77.5%) | K8: Boil Off /Vol. (4-6%) | L8: Boil Time | M8: Total Hot | N8: Brewing | P8: Comments | Q8: Actual Pilsen Malt | S8: Hurricane Reef | T8: 16.6 | U8: 17 | V8: 0 | W8: 0.12905093 | X8: 0.22222222 | Y8: 0.25347222 | Z8: 0
E9: Meter (Hls) | F9: Target(< 60Mins) | M9: Time | S9: VITAMALT | T9: 14.4 | U9: 14.6 | V9: 0 | W9: 0.13905093 | X9: 0.19097222 | Y9: 0.22569444 | Z9: 0 | AA9: 75
S10: =B10 -> 0 | T10: =VLOOKUP($B10,$S$3:$Y$9,2,FALSE) -> #N/A | U10: =VLOOKUP($B10,$S$3:$Y$9,3,FALSE) -> #N/A | V10: =VLOOKUP($B10,$S$3:$Y$9,4,FALSE) -> #N/A | W10: =VLOOKUP($B10,$S$3:$Y$9,5,FALSE) -> #N/A | X10: =VLOOKUP($B10,$S$3:$Y$9,6,FALSE) -> #N/A | Y10: =VLOOKUP($B10,$S$3:$Y$9,7,FALSE) -> #N/A | Z10: =VLOOKUP($B10,$S$3:$AA$9,8,FALSE) -> #N/A | AA10: =VLOOKUP($B10,$S$3:$AA$9,9,FALSE) -> #N/A
S11: =B11 -> 0 | T11: =VLOOKUP($B11,$S$3:$Y$9,2,FALSE) -> #N/A | U11: =VLOOKUP($B11,$S$3:$Y$9,3,FALSE) -> #N/A | V11: =VLOOKUP($B11,$S$3:$Y$9,4,FALSE) -> #N/A | W11: =VLOOKUP($B11,$S$3:$Y$9,5,FALSE) -> #N/A | X11: =VLOOKUP($B11,$S$3:$Y$9,6,FALSE) -> #N/A | Y11: =VLOOKUP($B11,$S$3:$Y$9,7,FALSE) -> #N/A | Z11: =VLOOKUP($B11,$S$3:$AA$9,8,FALSE) -> #N/A | AA11: =VLOOKUP($B11,$S$3:$AA$9,9,FALSE) -> #N/A
S12: =B12 -> 0 | T12: =VLOOKUP($B12,$S$3:$Y$9,2,FALSE) -> #N/A | U12: =VLOOKUP($B12,$S$3:$Y$9,3,FALSE) -> #N/A | V12: =VLOOKUP($B12,$S$3:$Y$9,4,FALSE) -> #N/A | W12: =VLOOKUP($B12,$S$3:$Y$9,5,FALSE) -> #N/A | X12: =VLOOKUP($B12,$S$3:$Y$9,6,FALSE) -> #N/A | Y12: =VLOOKUP($B12,$S$3:$Y$9,7,FALSE) -> #N/A | Z12: =VLOOKUP($B12,$S$3:$AA$9,8,FALSE) -> #N/A | AA12: =VLOOKUP($B12,$S$3:$AA$9,9,FALSE) -> #N/A
S13: =B13 -> 0 | T13: =VLOOKUP($B13,$S$3:$Y$9,2,FALSE) -> #N/A | U13: =VLOOKUP($B13,$S$3:$Y$9,3,FALSE) -> #N/A | V13: =VLOOKUP($B13,$S$3:$Y$9,4,FALSE) -> #N/A | W13: =VLOOKUP($B13,$S$3:$Y$9,5,FALSE) -> #N/A | X13: =VLOOKUP($B13,$S$3:$Y$9,6,FALSE) -> #N/A | Y13: =VLOOKUP($B13,$S$3:$Y$9,7,FALSE) -> #N/A | Z13: =VLOOKUP($B13,$S$3:$AA$9,8,FALSE) -> #N/A | AA13: =VLOOKUP($B13,$S$3:$AA$9,9,FALSE) -> #N/A
S14: =B14 -> 0 | T14: =VLOOKUP($B14,$S$3:$Y$9,2,FALSE) -> #N/A | U14: =VLOOKUP($B14,$S$3:$Y$9,3,FALSE) -> #N/A | V14: =VLOOKUP($B14,$S$3:$Y$9,4,FALSE) -> #N/A | W14: =VLOOKUP($B14,$S$3:$Y$9,5,FALSE) -> #N/A | X14: =VLOOKUP($B14,$S$3:$Y$9,6,FALSE) -> #N/A | Y14: =VLOOKUP($B14,$S$3:$Y$9,7,FALSE) -> #N/A | Z14: =VLOOKUP($B14,$S$3:$AA$9,8,FALSE) -> #N/A | AA14: =VLOOKUP($B14,$S$3:$AA$9,9,FALSE) -> #N/A
S15: =B15 -> 0 | T15: =VLOOKUP($B15,$S$3:$Y$9,2,FALSE) -> #N/A | U15: =VLOOKUP($B15,$S$3:$Y$9,3,FALSE) -> #N/A | V15: =VLOOKUP($B15,$S$3:$Y$9,4,FALSE) -> #N/A | W15: =VLOOKUP($B15,$S$3:$Y$9,5,FALSE) -> #N/A | X15: =VLOOKUP($B15,$S$3:$Y$9,6,FALSE) -> #N/A | Y15: =VLOOKUP($B15,$S$3:$Y$9,7,FALSE) -> #N/A | Z15: =VLOOKUP($B15,$S$3:$AA$9,8,FALSE) -> #N/A | AA15: =VLOOKUP($B15,$S$3:$AA$9,9,FALSE) -> #N/A
S16: =B16 -> 0 | T16: =VLOOKUP($B16,$S$3:$Y$9,2,FALSE) -> #N/A | U16: =VLOOKUP($B16,$S$3:$Y$9,3,FALSE) -> #N/A | V16: =VLOOKUP($B16,$S$3:$Y$9,4,FALSE) -> #N/A | W16: =VLOOKUP($B16,$S$3:$Y$9,5,FALSE) -> #N/A | X16: =VLOOKUP($B16,$S$3:$Y$9,6,FALSE) -> #N/A | Y16: =VLOOKUP($B16,$S$3:$Y$9,7,FALSE) -> #N/A | Z16: =VLOOKUP($B16,$S$3:$AA$9,8,FALSE) -> #N/A | AA16: =VLOOKUP($B16,$S$3:$AA$9,9,FALSE) -> #N/A
S17: =B17 -> 0 | T17: =VLOOKUP($B17,$S$3:$Y$9,2,FALSE) -> #N/A | U17: =VLOOKUP($B17,$S$3:$Y$9,3,FALSE) -> #N/A | V17: =VLOOKUP($B17,$S$3:$Y$9,4,FALSE) -> #N/A | W17: =VLOOKUP($B17,$S$3:$Y$9,5,FALSE) -> #N/A | X17: =VLOOKUP($B17,$S$3:$Y$9,6,FALSE) -> #N/A | Y17: =VLOOKUP($B17,$S$3:$Y$9,7,FALSE) -> #N/A | Z17: =VLOOKUP($B17,$S$3:$AA$9,8,FALSE) -> #N/A | AA17: =VLOOKUP($B17,$S$3:$AA$9,9,FALSE) -> #N/A
S18: =B18 -> 0 | T18: =VLOOKUP($B18,$S$3:$Y$9,2,FALSE) -> #N/A | U18: =VLOOKUP($B18,$S$3:$Y$9,3,FALSE) -> #N/A | V18: =VLOOKUP($B18,$S$3:$Y$9,4,FALSE) -> #N/A | W18: =VLOOKUP($B18,$S$3:$Y$9,5,FALSE) -> #N/A | X18: =VLOOKUP($B18,$S$3:$Y$9,6,FALSE) -> #N/A | Y18: =VLOOKUP($B18,$S$3:$Y$9,7,FALSE) -> #N/A | Z18: =VLOOKUP($B18,$S$3:$AA$9,8,FALSE) -> #N/A | AA18: =VLOOKUP($B18,$S$3:$AA$9,9,FALSE) -> #N/A
S19: =B19 -> 0 | T19: =VLOOKUP($B19,$S$3:$Y$9,2,FALSE) -> #N/A | U19: =VLOOKUP($B19,$S$3:$Y$9,3,FALSE) -> #N/A | V19: =VLOOKUP($B19,$S$3:$Y$9,4,FALSE) -> #N/A | W19: =VLOOKUP($B19,$S$3:$Y$9,5,FALSE) -> #N/A | X19: =VLOOKUP($B19,$S$3:$Y$9,6,FALSE) -> #N/A | Y19: =VLOOKUP($B19,$S$3:$Y$9,7,FALSE) -> #N/A | Z19: =VLOOKUP($B19,$S$3:$AA$9,8,FALSE) -> #N/A | AA19: =VLOOKUP($B19,$S$3:$AA$9,9,FALSE) -> #N/A
S20: =B20 -> 0 | T20: =VLOOKUP($B20,$S$3:$Y$9,2,FALSE) -> #N/A | U20: =VLOOKUP($B20,$S$3:$Y$9,3,FALSE) -> #N/A | V20: =VLOOKUP($B20,$S$3:$Y$9,4,FALSE) -> #N/A | W20: =VLOOKUP($B20,$S$3:$Y$9,5,FALSE) -> #N/A | X20: =VLOOKUP($B20,$S$3:$Y$9,6,FALSE) -> #N/A | Y20: =VLOOKUP($B20,$S$3:$Y$9,7,FALSE) -> #N/A | Z20: =VLOOKUP($B20,$S$3:$AA$9,8,FALSE) -> #N/A | AA20: =VLOOKUP($B20,$S$3:$AA$9,9,FALSE) -> #N/A
S21: =B21 -> 0 | T21: =VLOOKUP($B21,$S$3:$Y$9,2,FALSE) -> #N/A | U21: =VLOOKUP($B21,$S$3:$Y$9,3,FALSE) -> #N/A | V21: =VLOOKUP($B21,$S$3:$Y$9,4,FALSE) -> #N/A | W21: =VLOOKUP($B21,$S$3:$Y$9,5,FALSE) -> #N/A | X21: =VLOOKUP($B21,$S$3:$Y$9,6,FALSE) -> #N/A | Y21: =VLOOKUP($B21,$S$3:$Y$9,7,FALSE) -> #N/A | Z21: =VLOOKUP($B21,$S$3:$AA$9,8,FALSE) -> #N/A | AA21: =VLOOKUP($B21,$S$3:$AA$9,9,FALSE) -> #N/A
... S47: =B47 -> 0 | T47: =VLOOKUP($B47,$S$3:$Y$9,2,FALSE) -> #N/A | U47: =VLOOKUP($B47,$S$3:$Y$9,3,FALSE) -> #N/A | V47: =VLOOKUP($B47,$S$3:$Y$9,4,FALSE) -> #N/A | W47: =VLOOKUP($B47,$S$3:$Y$9,5,FALSE) -> #N/A | X47: =VLOOKUP($B47,$S$3:$Y$9,6,FALSE) -> #N/A | Y47: =VLOOKUP($B47,$S$3:$Y$9,7,FALSE) -> #N/A | Z47: =VLOOKUP($B47,$S$3:$AA$9,8,FALSE) -> #N/A | AA47: =VLOOKUP($B47,$S$3:$AA$9,9,FALSE) -> #N/A
I48: EXTRACT RECOVERY
B49: BRAND | D49: BBT P.G./ O.G | I49: Brand | J49: Actual | K49: MTD No. of Brews | L49: MTD | M49: YTD | N49: Target
B50: STAG | C50: 11.8 | D50: 11.73 | I50: CARIB | K50: =COUNTA([14]Brewhouse!$A$1596:$A$1619) -> 24 | L50: =AVERAGE([14]Brewhouse!$AU$1529,[14]Brewhouse!$AU$1531:$AU$1594,[14]Brewhouse!$AU$1596:$AU$1619) -> 98.205761 | M50: =AVERAGE([14]Brewhouse!$AU$849:$AU$924,[14]Brewhouse!$AU$926:$AU$971,[14]Brewhouse!$AU$973:$AU$1066,[14]Brewhouse!$AU$1068:$AU$1111,[14]Brewhouse!$AU$1113:$AU$1132,[14]Brewhouse!$AU$1134:$AU$1167,[14]Brewhouse!$AU$1169:$AU$1230,[14]Brewhouse!$AU$1232:$AU$1299,[14]Brewhouse!$AU$1301:$AU$1363,[14]Brewhouse!$AU$1365:$AU$1444,[14]Brewhouse!$AU$1446:$AU$1527,[14]Brewhouse!$AU$1529,[14]Brewhouse!$AU$1531:$AU$1594,[14]Brewhouse!$AU$1596:$AU$1619) -> 98.381806 | N50: 98
C51: 11.9 | I51: STAG | K51: =COUNTA([15]Brewhouse!$A$976:$A$1007) -> 32 | L51: =AVERAGE([15]Brewhouse!$AS$976:$AS$979,[15]Brewhouse!$AS$981:$AS$1007) -> 98.538567 | M51: =AVERAGE([15]Brewhouse!$AS$577:$AS$618,[15]Brewhouse!$AS$620:$AS$651,[15]Brewhouse!$AS$653:$AS$696,[15]Brewhouse!$AS$698:$AS$708,[15]Brewhouse!$AS$710:$AS$733,[15]Brewhouse!$AS$735:$AS$777,[15]Brewhouse!$AS$779:$AS$822,[15]Brewhouse!$AS$824:$AS$863,[15]Brewhouse!$AS$865:$AS$974,[15]Brewhouse!$AS$976:$AS$979,[15]Brewhouse!$AS$981:$AS$1007) -> 98.489671 | N51: 98
I52: GUINNESS | K52: =COUNTA([16]Brewhouse!$A$282:$A$289) -> 8 | L52: =AVERAGE([16]Brewhouse!$AU$269:$AU$279,[16]Brewhouse!$AU$282:$AU$289) -> 96.186177 | M52: =AVERAGE([16]Brewhouse!$AU$161:$AU$176,[16]Brewhouse!$AU$178:$AU$195,[16]Brewhouse!$AU$197:$AU$208,[16]Brewhouse!$AU$210:$AU$221,[16]Brewhouse!$AU$223:$AU$232,[16]Brewhouse!$AU$234:$AU$279,[16]Brewhouse!$AU$282:$AU$289) -> 96.64916 | N52: 98
I53: VITAMALT | K53: =COUNTA([17]Brewhouse!$A$158:$A$163) -> 6 | L53: =AVERAGE([17]Brewhouse!$AU$158:$AU$163) -> 94.60305 | M53: =AVERAGE([17]Brewhouse!$AU$91:$AU$101,[17]Brewhouse!$AU$103:$AU$112,[17]Brewhouse!$AU$114:$AU$123,[17]Brewhouse!$AU$125:$AU$134,[17]Brewhouse!$AU$136:$AU$145,[17]Brewhouse!$AU$147:$AU$156,[17]Brewhouse!$AU$158:$AU$163) -> 96.240014 | N53: 98
I54: MAXIMALT | N54: 98
I55: MACKESON | M55: =AVERAGE([18]Brewhouse!$AT$74:$AT$79) -> 93.959836 | N55: 98
I56: STARMALT | K56: =COUNTA([19]Brewhouse!$A$249:$A$254) -> 6 | L56: =AVERAGE([19]Brewhouse!$AY$249:$AY$254) -> 99.681996 | M56: =AVERAGE([19]Brewhouse!$AY$138:$AY$143,[19]Brewhouse!$AY$145:$AY$153,[19]Brewhouse!$AY$155,[19]Brewhouse!$AY$156:$AY$174,[19]Brewhouse!$AY$176:$AY$185,[19]Brewhouse!$AY$187:$AY$198,[19]Brewhouse!$AY$200:$AY$247,[19]Brewhouse!$AY$249:$AY$254) -> 98.774703 | N56: 98
I57: HR- P | M57: =AVERAGE([20]Brewhouse!$AW$13:$AW$14,[20]Brewhouse!$AW$16:$AW$17) -> 92.042628 | N57: 98
I58: Hurricane Reef | M58: =AVERAGE([20]Brewhouse!$AW$13:$AW$14) -> 88.376943 | N58: 98
K59: =SUM(K50:K58) -> 76 | L59: =((L50*K50)+(L51*K51)+(L52*K52)+(L53*K53)+(L54*K54)+(K57*L57)+(L55*K55)+(L56*K56)+(L58*K58))/(K59) -> 97.965422 | M59: =AVERAGE('[21]Closing- January 2023'!$L$42,'[22]Feb. 28th'!$L$42,'[23]March 31st'!$L$75,'[24]Apri 28th'!$L$51,L59) -> 98.06926 | N59: 98
J62: Daily Brewing Plan
J63: Brand | K63: Brews Achieved | L63: Average Brews per day
J64: CARIB | L64: MTD | M64: YTD | N64: TARGET
J65: STAG | K65: 5 | L65: =AVERAGE(#REF!,#REF!,K74,#REF!,#REF!,#REF!,#REF!,#REF!,#REF!,#REF!,#REF!) -> #REF! | M65: =AVERAGE(6,6,'[23]March 31st'!$L$80,'[25]June 30th '!$L$71,6,L65,'[26]July 31st'!$L$108,'[27]Aug 30th'!$L$124,7,[28]Oct.31st!$L$51) -> #REF! | N65: 9
J66: GUINN
J67: VITAMALT
...

Sheet May 2nd-23rd
S1: P.G. | U1: Hot Time | W1: Process Time | Y1: Cooling Time
B2: Brewing Department Daily Process Loss Report | S2: Lower | T2: Upper | U2: Lower | V2: Upper | W2: Lower | X2: Upper | Y2: Lower | Z2: Upper
R3: CARIB | S3: 11.6 | T3: 12 | U3: 0 | V3: 0.11805556 | W3: 0.22569444 | X3: 0.26388889 | Y3: 0 | Z3: 60 | AB3: HR- PISNER
B4: Date: | C4: 46147 | J4: LOT WORT COLOUR: | M4: Filter Sheets (Target 20 days) | R4: STAG | S4: 11.6 | T4: 12 | U4: 0 | V4: 0.11805556 | W4: 0.22569444 | X4: 0.26388889 | Y4: 0 | Z4: 60
M5: Double | N5: Single | R5: GUINNESS | S5: 17 | T5: 17.5 | U5: 0 | V5: 0.10763889 | W5: 0.24652778 | X5: 0.28472222 | Y5: 0 | Z5: 60
J6: MALT LOT: Lot #13 | L6: Sheet Day | R6: MACKESON | S6: 13.3 | T6: 13.5 | U6: 0 | V6: 0.12905093 | W6: 0.27430556 | X6: 0.30208333 | Y6: 0
R7: STARMALT | S7: 17 | T7: 17.4 | U7: 0 | V7: 0.13605324 | W7: 0.27430556 | X7: 0.30902778 | Y7: 0 | Z7: 85
B8: Brand | C8: Brew no. | D8: Kett. Hls | E8: Wort | F8: Cool Time(Mins) | G8: Cast. P.G. (Lab Result) | H8: Cast P.G. (Cellar Operator)-gravity | I8: Extr. Rec (77.9%) | J8: Theor. Extr. (77.5%) | K8: Boil Off /Vol. (4-6%) | L8: Boil Time | M8: Total Hot | N8: Brewing Time | O8: Operator | R8: Hurricane Reef | S8: 16.6 | T8: 17 | U8: 0 | V8: 0.12905093 | W8: 0.27430556 | X8: 0.30208333 | Y8: 0
E9: Meter (Hls) | F9: Target(< 60Mins) | M9: Time | R9: VITAMALT | S9: 14.2 | T9: 14.6 | U9: 0 | V9: 0.13905093 | W9: 0.26041667 | X9: 0.29513889 | Y9: 0 | Z9: 75
B10: CARIB | C10: =[4]Brewhouse!$A372 -> CA327 | D10: =[4]Brewhouse!$AF372 -> 52.1 | E10: =[4]Brewhouse!$AI372 -> 49.9 | F10: =[4]Brewhouse!$V372 -> 57 | G10: =[4]Brewhouse!AG372 -> 11.8 | I10: =[4]Brewhouse!$AU372 -> 96.564624 | J10: =[4]Brewhouse!$AV372 -> 98.133389 | K10: =[4]Brewhouse!$Q372 -> 5.5925926 | L10: =[4]Brewhouse!$P372 -> 46 | M10: =[4]Brewhouse!$U372-[4]Brewhouse!$T372 -> 0.12013889 | N10: =[4]Brewhouse!$Z372 -> 0.27569444 | O10: =[4]Brewhouse!$AX372 -> K. Benjamin | R10: =B10 -> CARIB | S10: =VLOOKUP($B10,$R$3:$X$9,2,FALSE) -> 11.6 | T10: =VLOOKUP($B10,$R$3:$X$9,3,FALSE) -> 12 | U10: =VLOOKUP($B10,$R$3:$X$9,4,FALSE) -> 0 | V10: =VLOOKUP($B10,$R$3:$X$9,5,FALSE) -> 0.11805556 | W10: =VLOOKUP($B10,$R$3:$X$9,6,FALSE) -> 0.22569444 | X10: =VLOOKUP($B10,$R$3:$X$9,7,FALSE) -> 0.26388889 | Y10: =VLOOKUP($B10,$R$3:$Z$9,8,FALSE) -> 0 | Z10: =VLOOKUP($B10,$R$3:$Z$9,9,FALSE) -> 60
B11: CARIB | C11: =[4]Brewhouse!$A373 -> CA328 | D11: =[4]Brewhouse!$AF373 -> 53 | E11: =[4]Brewhouse!$AI373 -> 51 | F11: =[4]Brewhouse!$V373 -> 56 | G11: =[4]Brewhouse!AG373 -> 11.9 | I11: =[4]Brewhouse!$AU373 -> 99.45013 | J11: =[4]Brewhouse!$AV373 -> 101.06588 | K11: =[4]Brewhouse!$Q373 -> 3.1851852 | L11: =[4]Brewhouse!$P373 -> 58 | M11: =[4]Brewhouse!$U373-[4]Brewhouse!$T373 -> 0.12013889 | N11: =[4]Brewhouse!$Z373 -> 0.27916667 | O11: =[4]Brewhouse!$AX373 -> K. Benjamin | R11: =B11 -> CARIB | S11: =VLOOKUP($B11,$R$3:$X$9,2,FALSE) -> 11.6 | T11: =VLOOKUP($B11,$R$3:$X$9,3,FALSE) -> 12 | U11: =VLOOKUP($B11,$R$3:$X$9,4,FALSE) -> 0 | V11: =VLOOKUP($B11,$R$3:$X$9,5,FALSE) -> 0.11805556 | W11: =VLOOKUP($B11,$R$3:$X$9,6,FALSE) -> 0.22569444 | X11: =VLOOKUP($B11,$R$3:$X$9,7,FALSE) -> 0.26388889 | Y11: =VLOOKUP($B11,$R$3:$Z$9,8,FALSE) -> 0 | Z11: =VLOOKUP($B11,$R$3:$Z$9,9,FALSE) -> 60
B12: CARIB | C12: =[4]Brewhouse!$A374 -> CA329 | D12: =[4]Brewhouse!$AF374 -> 53.3 | E12: =[4]Brewhouse!$AI374 -> 51.7 | F12: =[4]Brewhouse!$V374 -> 63 | G12: =[4]Brewhouse!AG374 -> 11.8 | I12: =[4]Brewhouse!$AU374 -> 99.924396 | J12: =[4]Brewhouse!$AV374 -> 101.54785 | K12: =[4]Brewhouse!$Q374 -> 2.6296296 | L12: =[4]Brewhouse!$P374 -> 63 | M12: =[4]Brewhouse!$U374-[4]Brewhouse!$T374 -> 0.125 | N12: =[4]Brewhouse!$Z374 -> 0.27222222 | O12: =[4]Brewhouse!$AX374 -> K. Benjamin | R12: =B12 -> CARIB | S12: =VLOOKUP($B12,$R$3:$X$9,2,FALSE) -> 11.6 | T12: =VLOOKUP($B12,$R$3:$X$9,3,FALSE) -> 12 | U12: =VLOOKUP($B12,$R$3:$X$9,4,FALSE) -> 0 | V12: =VLOOKUP($B12,$R$3:$X$9,5,FALSE) -> 0.11805556 | W12: =VLOOKUP($B12,$R$3:$X$9,6,FALSE) -> 0.22569444 | X12: =VLOOKUP($B12,$R$3:$X$9,7,FALSE) -> 0.26388889 | Y12: =VLOOKUP($B12,$R$3:$Z$9,8,FALSE) -> 0 | Z12: =VLOOKUP($B12,$R$3:$Z$9,9,FALSE) -> 60
B13: CARIB | C13: =[4]Brewhouse!$A375 -> CA330 | D13: =[4]Brewhouse!$AF375 -> 52.2 | E13: =[4]Brewhouse!$AI375 -> 50.5 | F13: =[4]Brewhouse!$V375 -> 63 | G13: =[4]Brewhouse!AG375 -> 11.7 | I13: =[4]Brewhouse!$AU375 -> 96.735006 | J13: =[4]Brewhouse!$AV375 -> 98.306642 | K13: =[4]Brewhouse!$Q375 -> 4.8428835 | L13: =[4]Brewhouse!$P375 -> 58 | M13: =[4]Brewhouse!$U375-[4]Brewhouse!$T375 -> 0.10694444 | N13: =[4]Brewhouse!$Z375 -> 0.26944444 | O13: =[4]Brewhouse!$AX375 -> K. Benjamin | R13: =B13 -> CARIB | S13: =VLOOKUP($B13,$R$3:$X$9,2,FALSE) -> 11.6 | T13: =VLOOKUP($B13,$R$3:$X$9,3,FALSE) -> 12 | U13: =VLOOKUP($B13,$R$3:$X$9,4,FALSE) -> 0 | V13: =VLOOKUP($B13,$R$3:$X$9,5,FALSE) -> 0.11805556 | W13: =VLOOKUP($B13,$R$3:$X$9,6,FALSE) -> 0.22569444 | X13: =VLOOKUP($B13,$R$3:$X$9,7,FALSE) -> 0.26388889 | Y13: =VLOOKUP($B13,$R$3:$Z$9,8,FALSE) -> 0 | Z13: =VLOOKUP($B13,$R$3:$Z$9,9,FALSE) -> 60
B14: CARIB | C14: =[4]Brewhouse!$A376 -> CA331 | D14: =[4]Brewhouse!$AF376 -> 52.5 | E14: =[4]Brewhouse!$AI376 -> 50.8 | F14: =[4]Brewhouse!$V376 -> 64 | G14: =[4]Brewhouse!AG376 -> 11.8 | I14: =[4]Brewhouse!$AU376 -> 100.92622 | J14: =[4]Brewhouse!$AV376 -> 102.56353 | K14: =[4]Brewhouse!$Q376 -> 4.2883549 | L14: =[4]Brewhouse!$P376 -> 57 | M14: =[4]Brewhouse!$U376-[4]Brewhouse!$T376 -> 0.1125 | N14: =[4]Brewhouse!$Z376 -> 0.27291667 | O14: =[4]Brewhouse!$AX376 -> K. Benjamin | R14: =B14 -> CARIB | S14: =VLOOKUP($B14,$R$3:$X$9,2,FALSE) -> 11.6 | T14: =VLOOKUP($B14,$R$3:$X$9,3,FALSE) -> 12 | U14: =VLOOKUP($B14,$R$3:$X$9,4,FALSE) -> 0 | V14: =VLOOKUP($B14,$R$3:$X$9,5,FALSE) -> 0.11805556 | W14: =VLOOKUP($B14,$R$3:$X$9,6,FALSE) -> 0.22569444 | X14: =VLOOKUP($B14,$R$3:$X$9,7,FALSE) -> 0.26388889 | Y14: =VLOOKUP($B14,$R$3:$Z$9,8,FALSE) -> 0 | Z14: =VLOOKUP($B14,$R$3:$Z$9,9,FALSE) -> 60
B15: CARIB | C15: =[4]Brewhouse!$A377 -> CA332 | D15: =[4]Brewhouse!$AF377 -> 52.6 | E15: =[4]Brewhouse!$AI377 -> 51 | F15: =[4]Brewhouse!$V377 -> 64 | G15: =[4]Brewhouse!AG377 -> 11.8 | I15: =[4]Brewhouse!$AU377 -> 101.71081 | J15: =[4]Brewhouse!$AV377 -> 103.36051 | K15: =[4]Brewhouse!$Q377 -> 4.103512 | L15: =[4]Brewhouse!$P377 -> 58 | M15: =[4]Brewhouse!$U377-[4]Brewhouse!$T377 -> 0.11180556 | N15: =[4]Brewhouse!$Z377 -> 0.27638889 | O15: =[4]Brewhouse!$AX377 -> R. Sookram | R15: =B15 -> CARIB | S15: =VLOOKUP($B15,$R$3:$X$9,2,FALSE) -> 11.6 | T15: =VLOOKUP($B15,$R$3:$X$9,3,FALSE) -> 12 | U15: =VLOOKUP($B15,$R$3:$X$9,4,FALSE) -> 0 | V15: =VLOOKUP($B15,$R$3:$X$9,5,FALSE) -> 0.11805556 | W15: =VLOOKUP($B15,$R$3:$X$9,6,FALSE) -> 0.22569444 | X15: =VLOOKUP($B15,$R$3:$X$9,7,FALSE) -> 0.26388889 | Y15: =VLOOKUP($B15,$R$3:$Z$9,8,FALSE) -> 0 | Z15: =VLOOKUP($B15,$R$3:$Z$9,9,FALSE) -> 60
B16: CARIB | C16: =[4]Brewhouse!$A378 -> CA333 | D16: =[4]Brewhouse!$AF378 -> 51.8 | E16: =[4]Brewhouse!$AI378 -> 50.1 | F16: =[4]Brewhouse!$V378 -> 63 | G16: =[4]Brewhouse!AG378 -> 11.8 | I16: =[4]Brewhouse!$AU378 -> 99.915911 | J16: =[4]Brewhouse!$AV378 -> 101.5365 | K16: =[4]Brewhouse!$Q378 -> 5.5822551 | L16: =[4]Brewhouse!$P378 -> 57 | M16: =[4]Brewhouse!$U378-[4]Brewhouse!$T378 -> 0.13819444 | N16: =[4]Brewhouse!$Z378 -> 0.30833333 | O16: =[4]Brewhouse!$AX378 -> R. Sookram | R16: =B16 -> CARIB | S16: =VLOOKUP($B16,$R$3:$X$9,2,FALSE) -> 11.6 | T16: =VLOOKUP($B16,$R$3:$X$9,3,FALSE) -> 12 | U16: =VLOOKUP($B16,$R$3:$X$9,4,FALSE) -> 0 | V16: =VLOOKUP($B16,$R$3:$X$9,5,FALSE) -> 0.11805556 | W16: =VLOOKUP($B16,$R$3:$X$9,6,FALSE) -> 0.22569444 | X16: =VLOOKUP($B16,$R$3:$X$9,7,FALSE) -> 0.26388889 | Y16: =VLOOKUP($B16,$R$3:$Z$9,8,FALSE) -> 0 | Z16: =VLOOKUP($B16,$R$3:$Z$9,9,FALSE) -> 60
B17: 46145
B18: CARIB | C18: =[4]Brewhouse!$A379 -> CA334 | D18: =[4]Brewhouse!$AF379 -> 52.9 | E18: =[4]Brewhouse!$AI379 -> 51.1 | F18: =[4]Brewhouse!$V379 -> 71 | G18: =[4]Brewhouse!AG379 -> 11.6 | I18: =[4]Brewhouse!$AU379 -> 100.09336 | J18: =[4]Brewhouse!$AV379 -> 101.71683 | K18: =[4]Brewhouse!$Q379 -> 3.5489834 | L18: =[4]Brewhouse!$P379 -> 58 | M18: =[4]Brewhouse!$U379-[4]Brewhouse!$T379 -> 0.11458333 | N18: =[4]Brewhouse!$Z379 -> 0.26944444 | O18: =[4]Brewhouse!$AX379 -> R. Sookram | R18: =B18 -> CARIB | S18: =VLOOKUP($B18,$R$3:$X$9,2,FALSE) -> 11.6 | T18: =VLOOKUP($B18,$R$3:$X$9,3,FALSE) -> 12 | U18: =VLOOKUP($B18,$R$3:$X$9,4,FALSE) -> 0 | V18: =VLOOKUP($B18,$R$3:$X$9,5,FALSE) -> 0.11805556 | W18: =VLOOKUP($B18,$R$3:$X$9,6,FALSE) -> 0.22569444 | X18: =VLOOKUP($B18,$R$3:$X$9,7,FALSE) -> 0.26388889 | Y18: =VLOOKUP($B18,$R$3:$Z$9,8,FALSE) -> 0 | Z18: =VLOOKUP($B18,$R$3:$Z$9,9,FALSE) -> 60
R19: =B19 -> 0 | S19: =VLOOKUP($B19,$R$3:$X$9,2,FALSE) -> #N/A | T19: =VLOOKUP($B19,$R$3:$X$9,3,FALSE) -> #N/A | U19: =VLOOKUP($B19,$R$3:$X$9,4,FALSE) -> #N/A | V19: =VLOOKUP($B19,$R$3:$X$9,5,FALSE) -> #N/A | W19: =VLOOKUP($B19,$R$3:$X$9,6,FALSE) -> #N/A | X19: =VLOOKUP($B19,$R$3:$X$9,7,FALSE) -> #N/A | Y19: =VLOOKUP($B19,$R$3:$Z$9,8,FALSE) -> #N/A | Z19: =VLOOKUP($B19,$R$3:$Z$9,9,FALSE) -> #N/A
R20: =B20 -> 0 | S20: =VLOOKUP($B20,$R$3:$X$9,2,FALSE) -> #N/A | T20: =VLOOKUP($B20,$R$3:$X$9,3,FALSE) -> #N/A | U20: =VLOOKUP($B20,$R$3:$X$9,4,FALSE) -> #N/A | V20: =VLOOKUP($B20,$R$3:$X$9,5,FALSE) -> #N/A | W20: =VLOOKUP($B20,$R$3:$X$9,6,FALSE) -> #N/A | X20: =VLOOKUP($B20,$R$3:$X$9,7,FALSE) -> #N/A | Y20: =VLOOKUP($B20,$R$3:$Z$9,8,FALSE) -> #N/A | Z20: =VLOOKUP($B20,$R$3:$Z$9,9,FALSE) -> #N/A
R21: =B21 -> 0 | S21: =VLOOKUP($B21,$R$3:$X$9,2,FALSE) -> #N/A | T21: =VLOOKUP($B21,$R$3:$X$9,3,FALSE) -> #N/A | U21: =VLOOKUP($B21,$R$3:$X$9,4,FALSE) -> #N/A | V21: =VLOOKUP($B21,$R$3:$X$9,5,FALSE) -> #N/A | W21: =VLOOKUP($B21,$R$3:$X$9,6,FALSE) -> #N/A | X21: =VLOOKUP($B21,$R$3:$X$9,7,FALSE) -> #N/A | Y21: =VLOOKUP($B21,$R$3:$Z$9,8,FALSE) -> #N/A | Z21: =VLOOKUP($B21,$R$3:$Z$9,9,FALSE) -> #N/A
R22: =B22 -> 0 | S22: =VLOOKUP($B22,$R$3:$X$9,2,FALSE) -> #N/A | T22: =VLOOKUP($B22,$R$3:$X$9,3,FALSE) -> #N/A | U22: =VLOOKUP($B22,$R$3:$X$9,4,FALSE) -> #N/A | V22: =VLOOKUP($B22,$R$3:$X$9,5,FALSE) -> #N/A | W22: =VLOOKUP($B22,$R$3:$X$9,6,FALSE) -> #N/A | X22: =VLOOKUP($B22,$R$3:$X$9,7,FALSE) -> #N/A | Y22: =VLOOKUP($B22,$R$3:$Z$9,8,FALSE) -> #N/A | Z22: =VLOOKUP($B22,$R$3:$Z$9,9,FALSE) -> #N/A
R23: =B23 -> 0 | S23: =VLOOKUP($B23,$R$3:$X$9,2,FALSE) -> #N/A | T23: =VLOOKUP($B23,$R$3:$X$9,3,FALSE) -> #N/A | U23: =VLOOKUP($B23,$R$3:$X$9,4,FALSE) -> #N/A | V23: =VLOOKUP($B23,$R$3:$X$9,5,FALSE) -> #N/A | W23: =VLOOKUP($B23,$R$3:$X$9,6,FALSE) -> #N/A | X23: =VLOOKUP($B23,$R$3:$X$9,7,FALSE) -> #N/A | Y23: =VLOOKUP($B23,$R$3:$Z$9,8,FALSE) -> #N/A | Z23: =VLOOKUP($B23,$R$3:$Z$9,9,FALSE) -> #N/A
R24: =B24 -> 0 | S24: =VLOOKUP($B24,$R$3:$X$9,2,FALSE) -> #N/A | T24: =VLOOKUP($B24,$R$3:$X$9,3,FALSE) -> #N/A | U24: =VLOOKUP($B24,$R$3:$X$9,4,FALSE) -> #N/A | V24: =VLOOKUP($B24,$R$3:$X$9,5,FALSE) -> #N/A | W24: =VLOOKUP($B24,$R$3:$X$9,6,FALSE) -> #N/A | X24: =VLOOKUP($B24,$R$3:$X$9,7,FALSE) -> #N/A | Y24: =VLOOKUP($B24,$R$3:$Z$9,8,FALSE) -> #N/A | Z24: =VLOOKUP($B24,$R$3:$Z$9,9,FALSE) -> #N/A
R25: =B25 -> 0 | S25: =VLOOKUP($B25,$R$3:$X$9,2,FALSE) -> #N/A | T25: =VLOOKUP($B25,$R$3:$X$9,3,FALSE) -> #N/A | U25: =VLOOKUP($B25,$R$3:$X$9,4,FALSE) -> #N/A | V25: =VLOOKUP($B25,$R$3:$X$9,5,FALSE) -> #N/A | W25: =VLOOKUP($B25,$R$3:$X$9,6,FALSE) -> #N/A | X25: =VLOOKUP($B25,$R$3:$X$9,7,FALSE) -> #N/A | Y25: =VLOOKUP($B25,$R$3:$Z$9,8,FALSE) -> #N/A | Z25: =VLOOKUP($B25,$R$3:$Z$9,9,FALSE) -> #N/A
R26: =B26 -> 0 | S26: =VLOOKUP($B26,$R$3:$X$9,2,FALSE) -> #N/A | T26: =VLOOKUP($B26,$R$3:$X$9,3,FALSE) -> #N/A | U26: =VLOOKUP($B26,$R$3:$X$9,4,FALSE) -> #N/A | V26: =VLOOKUP($B26,$R$3:$X$9,5,FALSE) -> #N/A | W26: =VLOOKUP($B26,$R$3:$X$9,6,FALSE) -> #N/A | X26: =VLOOKUP($B26,$R$3:$X$9,7,FALSE) -> #N/A | Y26: =VLOOKUP($B26,$R$3:$Z$9,8,FALSE) -> #N/A | Z26: =VLOOKUP($B26,$R$3:$Z$9,9,FALSE) -> #N/A
R27: =B27 -> 0 | S27: =VLOOKUP($B27,$R$3:$X$9,2,FALSE) -> #N/A | T27: =VLOOKUP($B27,$R$3:$X$9,3,FALSE) -> #N/A | U27: =VLOOKUP($B27,$R$3:$X$9,4,FALSE) -> #N/A | V27: =VLOOKUP($B27,$R$3:$X$9,5,FALSE) -> #N/A | W27: =VLOOKUP($B27,$R$3:$X$9,6,FALSE) -> #N/A | X27: =VLOOKUP($B27,$R$3:$X$9,7,FALSE) -> #N/A | Y27: =VLOOKUP($B27,$R$3:$Z$9,8,FALSE) -> #N/A | Z27: =VLOOKUP($B27,$R$3:$Z$9,9,FALSE) -> #N/A
B28: BRAND | D28: BBT P.G./ O.G | I28: Brand | K28: MTD No. of Brews | L28: MTD | M28: YTD | N28: Target | R28: =B28 -> BRAND | S28: =VLOOKUP($B28,$R$3:$X$9,2,FALSE) -> #N/A | T28: =VLOOKUP($B28,$R$3:$X$9,3,FALSE) -> #N/A | U28: =VLOOKUP($B28,$R$3:$X$9,4,FALSE) -> #N/A | V28: =VLOOKUP($B28,$R$3:$X$9,5,FALSE) -> #N/A | W28: =VLOOKUP($B28,$R$3:$X$9,6,FALSE) -> #N/A | X28: =VLOOKUP($B28,$R$3:$X$9,7,FALSE) -> #N/A | Y28: =VLOOKUP($B28,$R$3:$Z$9,8,FALSE) -> #N/A | Z28: =VLOOKUP($B28,$R$3:$Z$9,9,FALSE) -> #N/A
I29: CARIB | J29: =AVERAGE(I10:I18) -> 99.415057 | K29: =COUNTA([4]Brewhouse!$A$372:$A$379) -> 8 | L29: =AVERAGE([4]Brewhouse!$AU$372:$AU$379) -> 99.415057 | M29: =AVERAGE([4]Brewhouse!$AU$42:$AU$123,[4]Brewhouse!$AU$125:$AU$188,[4]Brewhouse!$AU$198:$AU$290,[4]Brewhouse!$AU$292:$AU$370,[4]Brewhouse!$AU$372:$AU$379) -> 98.039368 | N29: 98 | R29: =B29 -> 0 | S29: =VLOOKUP($B29,$R$3:$X$9,2,FALSE) -> #N/A | T29: =VLOOKUP($B29,$R$3:$X$9,3,FALSE) -> #N/A | U29: =VLOOKUP($B29,$R$3:$X$9,4,FALSE) -> #N/A | V29: =VLOOKUP($B29,$R$3:$X$9,5,FALSE) -> #N/A | W29: =VLOOKUP($B29,$R$3:$X$9,6,FALSE) -> #N/A | X29: =VLOOKUP($B29,$R$3:$X$9,7,FALSE) -> #N/A | Y29: =VLOOKUP($B29,$R$3:$Z$9,8,FALSE) -> #N/A | Z29: =VLOOKUP($B29,$R$3:$Z$9,9,FALSE) -> #N/A
I30: STAG | M30: =AVERAGE([3]Brewhouse!$AS$52:$AS$81,[3]Brewhouse!$AS$83:$AS$124,[3]Brewhouse!$AS$134:$AS$177,[3]Brewhouse!$AS$22:$AS$179) -> 97.946758 | N30: 98 | R30: =B30 -> 0 | S30: =VLOOKUP($B30,$R$3:$X$9,2,FALSE) -> #N/A | T30: =VLOOKUP($B30,$R$3:$X$9,3,FALSE) -> #N/A | U30: =VLOOKUP($B30,$R$3:$X$9,4,FALSE) -> #N/A | V30: =VLOOKUP($B30,$R$3:$X$9,5,FALSE) -> #N/A | W30: =VLOOKUP($B30,$R$3:$X$9,6,FALSE) -> #N/A | X30: =VLOOKUP($B30,$R$3:$X$9,7,FALSE) -> #N/A | Y30: =VLOOKUP($B30,$R$3:$Z$9,8,FALSE) -> #N/A | Z30: =VLOOKUP($B30,$R$3:$Z$9,9,FALSE) -> #N/A
I31: GUINNESS | M31: =AVERAGE([5]Brewhouse!$AU$16:$AU$23,[5]Brewhouse!$AU$25:$AU$32,[5]Brewhouse!$AU$34:$AU$41,[5]Brewhouse!$AU$43:$AU$55) -> 96.793457 | N31: 98 | R31: =B31 -> 0 | S31: =VLOOKUP($B31,$R$3:$X$9,2,FALSE) -> #N/A | T31: =VLOOKUP($B31,$R$3:$X$9,3,FALSE) -> #N/A | U31: =VLOOKUP($B31,$R$3:$X$9,4,FALSE) -> #N/A | V31: =VLOOKUP($B31,$R$3:$X$9,5,FALSE) -> #N/A | W31: =VLOOKUP($B31,$R$3:$X$9,6,FALSE) -> #N/A | X31: =VLOOKUP($B31,$R$3:$X$9,7,FALSE) -> #N/A | Y31: =VLOOKUP($B31,$R$3:$Z$9,8,FALSE) -> #N/A | Z31: =VLOOKUP($B31,$R$3:$Z$9,9,FALSE) -> #N/A
I32: VITAMALT | M32: =AVERAGE([6]Brewhouse!$AV$23:$AV$34,[6]Brewhouse!$AV$36,[6]Brewhouse!$AV$38:$AV$52,[6]Brewhouse!$AV$54:$AV$60) -> 97.437513 | N32: 98 | R32: =B32 -> 0 | S32: =VLOOKUP($B32,$R$3:$X$9,2,FALSE) -> #N/A | T32: =VLOOKUP($B32,$R$3:$X$9,3,FALSE) -> #N/A | U32: =VLOOKUP($B32,$R$3:$X$9,4,FALSE) -> #N/A | V32: =VLOOKUP($B32,$R$3:$X$9,5,FALSE) -> #N/A | W32: =VLOOKUP($B32,$R$3:$X$9,6,FALSE) -> #N/A | X32: =VLOOKUP($B32,$R$3:$X$9,7,FALSE) -> #N/A | Y32: =VLOOKUP($B32,$R$3:$Z$9,8,FALSE) -> #N/A | Z32: =VLOOKUP($B32,$R$3:$Z$9,9,FALSE) -> #N/A
I33: MAXIMALT | N33: 98 | R33: =B33 -> 0 | S33: =VLOOKUP($B33,$R$3:$X$9,2,FALSE) -> #N/A | T33: =VLOOKUP($B33,$R$3:$X$9,3,FALSE) -> #N/A | U33: =VLOOKUP($B33,$R$3:$X$9,4,FALSE) -> #N/A | V33: =VLOOKUP($B33,$R$3:$X$9,5,FALSE) -> #N/A | W33: =VLOOKUP($B33,$R$3:$X$9,6,FALSE) -> #N/A | X33: =VLOOKUP($B33,$R$3:$X$9,7,FALSE) -> #N/A | Y33: =VLOOKUP($B33,$R$3:$Z$9,8,FALSE) -> #N/A | Z33: =VLOOKUP($B33,$R$3:$Z$9,9,FALSE) -> #N/A
I34: MACKESON | M34: =AVERAGE([7]Brewhouse!$AT$4:$AT$11) -> 92.826225 | N34: 98 | R34: =B34 -> 0 | S34: =VLOOKUP($B34,$R$3:$X$9,2,FALSE) -> #N/A | T34: =VLOOKUP($B34,$R$3:$X$9,3,FALSE) -> #N/A | U34: =VLOOKUP($B34,$R$3:$X$9,4,FALSE) -> #N/A | V34: =VLOOKUP($B34,$R$3:$X$9,5,FALSE) -> #N/A | W34: =VLOOKUP($B34,$R$3:$X$9,6,FALSE) -> #N/A | X34: =VLOOKUP($B34,$R$3:$X$9,7,FALSE) -> #N/A | Y34: =VLOOKUP($B34,$R$3:$Z$9,8,FALSE) -> #N/A | Z34: =VLOOKUP($B34,$R$3:$Z$9,9,FALSE) -> #N/A
I35: STARMALT | M35: =AVERAGE([8]Brewhouse!$AY$5:$AY$14,[8]Brewhouse!$AY$16:$AY$23,[8]Brewhouse!$AY$42,[8]Brewhouse!$AY$44:$AY$51) -> 97.608428 | N35: 98 | R35: =B35 -> 0 | S35: =VLOOKUP($B35,$R$3:$X$9,2,FALSE) -> #N/A | T35: =VLOOKUP($B35,$R$3:$X$9,3,FALSE) -> #N/A | U35: =VLOOKUP($B35,$R$3:$X$9,4,FALSE) -> #N/A | V35: =VLOOKUP($B35,$R$3:$X$9,5,FALSE) -> #N/A | W35: =VLOOKUP($B35,$R$3:$X$9,6,FALSE) -> #N/A | X35: =VLOOKUP($B35,$R$3:$X$9,7,FALSE) -> #N/A | Y35: =VLOOKUP($B35,$R$3:$Z$9,8,FALSE) -> #N/A | Z35: =VLOOKUP($B35,$R$3:$Z$9,9,FALSE) -> #N/A
I36: HR- Pils | N36: 98 | R36: =B36 -> 0 | S36: =VLOOKUP($B36,$R$3:$X$9,2,FALSE) -> #N/A | T36: =VLOOKUP($B36,$R$3:$X$9,3,FALSE) -> #N/A | U36: =VLOOKUP($B36,$R$3:$X$9,4,FALSE) -> #N/A | V36: =VLOOKUP($B36,$R$3:$X$9,5,FALSE) -> #N/A | W36: =VLOOKUP($B36,$R$3:$X$9,6,FALSE) -> #N/A | X36: =VLOOKUP($B36,$R$3:$X$9,7,FALSE) -> #N/A | Y36: =VLOOKUP($B36,$R$3:$Z$9,8,FALSE) -> #N/A | Z36: =VLOOKUP($B36,$R$3:$Z$9,9,FALSE) -> #N/A
I37: HR- IPA | N37: 98 | R37: =B37 -> 0 | S37: =VLOOKUP($B37,$R$3:$X$9,2,FALSE) -> #N/A | T37: =VLOOKUP($B37,$R$3:$X$9,3,FALSE) -> #N/A | U37: =VLOOKUP($B37,$R$3:$X$9,4,FALSE) -> #N/A | V37: =VLOOKUP($B37,$R$3:$X$9,5,FALSE) -> #N/A | W37: =VLOOKUP($B37,$R$3:$X$9,6,FALSE) -> #N/A | X37: =VLOOKUP($B37,$R$3:$X$9,7,FALSE) -> #N/A | Y37: =VLOOKUP($B37,$R$3:$Z$9,8,FALSE) -> #N/A | Z37: =VLOOKUP($B37,$R$3:$Z$9,9,FALSE) -> #N/A
I38: HR- APA | N38: 98 | R38: =B38 -> 0 | S38: =VLOOKUP($B38,$R$3:$X$9,2,FALSE) -> #N/A | T38: =VLOOKUP($B38,$R$3:$X$9,3,FALSE) -> #N/A | U38: =VLOOKUP($B38,$R$3:$X$9,4,FALSE) -> #N/A | V38: =VLOOKUP($B38,$R$3:$X$9,5,FALSE) -> #N/A | W38: =VLOOKUP($B38,$R$3:$X$9,6,FALSE) -> #N/A | X38: =VLOOKUP($B38,$R$3:$X$9,7,FALSE) -> #N/A | Y38: =VLOOKUP($B38,$R$3:$Z$9,8,FALSE) -> #N/A | Z38: =VLOOKUP($B38,$R$3:$Z$9,9,FALSE) -> #N/A
K39: =SUM(K29:K38) -> 8 | L39: =((L29*K29)+(L30*K30)+(L31*K31)+(L32*K32)+(L33*K33)+(K36*L36)+(L34*K34)+(L35*K35)+(L38*K38))/(K39) -> 99.415057 | M39: =AVERAGE('[9]Jan30th-31st'!$L$42,L39) -> 98.62155 | N39: 98 | R39: =B39 -> 0 | S39: =VLOOKUP($B39,$R$3:$X$9,2,FALSE) -> #N/A | T39: =VLOOKUP($B39,$R$3:$X$9,3,FALSE) -> #N/A | U39: =VLOOKUP($B39,$R$3:$X$9,4,FALSE) -> #N/A | V39: =VLOOKUP($B39,$R$3:$X$9,5,FALSE) -> #N/A | W39: =VLOOKUP($B39,$R$3:$X$9,6,FALSE) -> #N/A | X39: =VLOOKUP($B39,$R$3:$X$9,7,FALSE) -> #N/A | Y39: =VLOOKUP($B39,$R$3:$Z$9,8,FALSE) -> #N/A | Z39: =VLOOKUP($B39,$R$3:$Z$9,9,FALSE) -> #N/A
R40: =B40 -> 0 | S40: =VLOOKUP($B40,$R$3:$X$9,2,FALSE) -> #N/A | T40: =VLOOKUP($B40,$R$3:$X$9,3,FALSE) -> #N/A | U40: =VLOOKUP($B40,$R$3:$X$9,4,FALSE) -> #N/A | V40: =VLOOKUP($B40,$R$3:$X$9,5,FALSE) -> #N/A | W40: =VLOOKUP($B40,$R$3:$X$9,6,FALSE) -> #N/A | X40: =VLOOKUP($B40,$R$3:$X$9,7,FALSE) -> #N/A | Y40: =VLOOKUP($B40,$R$3:$Z$9,8,FALSE) -> #N/A | Z40: =VLOOKUP($B40,$R$3:$Z$9,9,FALSE) -> #N/A
...

Sheet May 4th
S1: P.G. | U1: Hot Time | W1: Process Time | Y1: Cooling Time
B2: Brewing Department Daily Process Loss Report | S2: Lower | T2: Upper | U2: Lower | V2: Upper | W2: Lower | X2: Upper | Y2: Lower | Z2: Upper
R3: CARIB | S3: 11.6 | T3: 12 | U3: 0 | V3: 0.11805556 | W3: 0.22569444 | X3: 0.26388889 | Y3: 0 | Z3: 60 | AB3: HR- PISNER
B4: Date: | C4: 46147 | J4: LOT WORT COLOUR: | M4: Filter Sheets (Target 20 days) | R4: STAG | S4: 11.6 | T4: 12 | U4: 0 | V4: 0.11805556 | W4: 0.22569444 | X4: 0.26388889 | Y4: 0 | Z4: 60
M5: Double | N5: Single | R5: GUINNESS | S5: 17 | T5: 17.5 | U5: 0 | V5: 0.10763889 | W5: 0.24652778 | X5: 0.28472222 | Y5: 0 | Z5: 60
J6: MALT LOT: Lot #13 | L6: Sheet Day | R6: MACKESON | S6: 13.3 | T6: 13.5 | U6: 0 | V6: 0.12905093 | W6: 0.27430556 | X6: 0.30208333 | Y6: 0
R7: STARMALT | S7: 17 | T7: 17.4 | U7: 0 | V7: 0.13605324 | W7: 0.27430556 | X7: 0.30902778 | Y7: 0 | Z7: 85
B8: Brand | C8: Brew no. | D8: Kett. Hls | E8: Wort | F8: Cool Time(Mins) | G8: Cast. P.G. (Lab Result) | H8: Cast P.G. (Cellar Operator)-gravity | I8: Extr. Rec (77.9%) | J8: Theor. Extr. (77.5%) | K8: Boil Off /Vol. (4-6%) | L8: Boil Time | M8: Total Hot | N8: Brewing Time | O8: Operator | R8: Hurricane Reef | S8: 16.6 | T8: 17 | U8: 0 | V8: 0.12905093 | W8: 0.27430556 | X8: 0.30208333 | Y8: 0
E9: Meter (Hls) | F9: Target(< 60Mins) | M9: Time | R9: VITAMALT | S9: 14.2 | T9: 14.6 | U9: 0 | V9: 0.13905093 | W9: 0.26041667 | X9: 0.29513889 | Y9: 0 | Z9: 75
B10: CARIB | C10: =[4]Brewhouse!$A380 -> CA335 | D10: =[4]Brewhouse!$AF380 -> 52 | E10: =[4]Brewhouse!$AI380 -> 49.5 | F10: =[4]Brewhouse!$V380 -> 69 | G10: =[4]Brewhouse!AG380 -> 11.9 | H10: 11.9 | I10: =[4]Brewhouse!$AU380 -> 97.004179 | J10: =[4]Brewhouse!$AV380 -> 98.579776 | K10: =[4]Brewhouse!$Q380 -> 6.5064695 | L10: =[4]Brewhouse!$P380 -> 58 | M10: =[4]Brewhouse!$U380-[4]Brewhouse!$T380 -> 0.12013889 | N10: =[4]Brewhouse!$Z380 -> 0.27569444 | O10: =[4]Brewhouse!$AX380 -> R. Sookram | R10: =B10 -> CARIB | S10: =VLOOKUP($B10,$R$3:$X$9,2,FALSE) -> 11.6 | T10: =VLOOKUP($B10,$R$3:$X$9,3,FALSE) -> 12 | U10: =VLOOKUP($B10,$R$3:$X$9,4,FALSE) -> 0 | V10: =VLOOKUP($B10,$R$3:$X$9,5,FALSE) -> 0.11805556 | W10: =VLOOKUP($B10,$R$3:$X$9,6,FALSE) -> 0.22569444 | X10: =VLOOKUP($B10,$R$3:$X$9,7,FALSE) -> 0.26388889 | Y10: =VLOOKUP($B10,$R$3:$Z$9,8,FALSE) -> 0 | Z10: =VLOOKUP($B10,$R$3:$Z$9,9,FALSE) -> 60
B11: CARIB | C11: =[4]Brewhouse!$A381 -> CA336 | D11: =[4]Brewhouse!$AF381 -> 55.3 | E11: =[4]Brewhouse!$AI381 -> 53.4 | F11: =[4]Brewhouse!$V381 -> 65 | G11: =[4]Brewhouse!AG381 -> 11.2 | H11: 11.2 | I11: =[4]Brewhouse!$AU381 -> 98.419019 | J11: =[4]Brewhouse!$AV381 -> 100.01739 | K11: =[4]Brewhouse!$Q381 -> 5.3974122 | L11: =[4]Brewhouse!$P381 -> 57 | M11: =[4]Brewhouse!$U381-[4]Brewhouse!$T381 -> 0.11388889 | N11: =[4]Brewhouse!$Z381 -> 0.27986111 | O11: =[4]Brewhouse!$AX381 -> R. Sookram | R11: =B11 -> CARIB | S11: =VLOOKUP($B11,$R$3:$X$9,2,FALSE) -> 11.6 | T11: =VLOOKUP($B11,$R$3:$X$9,3,FALSE) -> 12 | U11: =VLOOKUP($B11,$R$3:$X$9,4,FALSE) -> 0 | V11: =VLOOKUP($B11,$R$3:$X$9,5,FALSE) -> 0.11805556 | W11: =VLOOKUP($B11,$R$3:$X$9,6,FALSE) -> 0.22569444 | X11: =VLOOKUP($B11,$R$3:$X$9,7,FALSE) -> 0.26388889 | Y11: =VLOOKUP($B11,$R$3:$Z$9,8,FALSE) -> 0 | Z11: =VLOOKUP($B11,$R$3:$Z$9,9,FALSE) -> 60
B12: CARIB | C12: =[4]Brewhouse!$A382 -> CA337 | D12: =[4]Brewhouse!$AF382 -> 50.1 | E12: =[4]Brewhouse!$AI382 -> 49.2 | F12: =[4]Brewhouse!$V382 -> 56 | G12: =[4]Brewhouse!AG382 -> 12.3 | H12: 12.6 | I12: =[4]Brewhouse!$AU382 -> 100.07209 | J12: =[4]Brewhouse!$AV382 -> 101.6973 | K12: =[4]Brewhouse!$Q382 -> 8.7245841 | L12: =[4]Brewhouse!$P382 -> 61 | M12: =[4]Brewhouse!$U382-[4]Brewhouse!$T382 -> 0.12430556 | N12: =[4]Brewhouse!$Z382 -> 0.34861111 | O12: =[4]Brewhouse!$AX382 -> R. Sookram | P12: low sparging temp due to hot water circulation pump not turning on, extra boil (15mins) | R12: =B12 -> CARIB | S12: =VLOOKUP($B12,$R$3:$X$9,2,FALSE) -> 11.6 | T12: =VLOOKUP($B12,$R$3:$X$9,3,FALSE) -> 12 | U12: =VLOOKUP($B12,$R$3:$X$9,4,FALSE) -> 0 | V12: =VLOOKUP($B12,$R$3:$X$9,5,FALSE) -> 0.11805556 | W12: =VLOOKUP($B12,$R$3:$X$9,6,FALSE) -> 0.22569444 | X12: =VLOOKUP($B12,$R$3:$X$9,7,FALSE) -> 0.26388889 | Y12: =VLOOKUP($B12,$R$3:$Z$9,8,FALSE) -> 0 | Z12: =VLOOKUP($B12,$R$3:$Z$9,9,FALSE) -> 60
B13: CARIB | C13: =[4]Brewhouse!$A383 -> CA338 | D13: =[4]Brewhouse!$AF383 -> 52.4 | E13: =[4]Brewhouse!$AI383 -> 50.5 | F13: =[4]Brewhouse!$V383 -> 55 | G13: =[4]Brewhouse!AG383 -> 11.9 | H13: 12.2 | I13: =[4]Brewhouse!$AU383 -> 99.210049 | J13: =[4]Brewhouse!$AV383 -> 100.82126 | K13: =[4]Brewhouse!$Q383 -> 5.037037 | L13: =[4]Brewhouse!$P383 -> 61 | M13: =[4]Brewhouse!$U383-[4]Brewhouse!$T383 -> 0.11111111 | N13: =[4]Brewhouse!$Z383 -> 0.25902778 | O13: =[4]Brewhouse!$AX383 -> R. Sookram | R13: =B13 -> CARIB | S13: =VLOOKUP($B13,$R$3:$X$9,2,FALSE) -> 11.6 | T13: =VLOOKUP($B13,$R$3:$X$9,3,FALSE) -> 12 | U13: =VLOOKUP($B13,$R$3:$X$9,4,FALSE) -> 0 | V13: =VLOOKUP($B13,$R$3:$X$9,5,FALSE) -> 0.11805556 | W13: =VLOOKUP($B13,$R$3:$X$9,6,FALSE) -> 0.22569444 | X13: =VLOOKUP($B13,$R$3:$X$9,7,FALSE) -> 0.26388889 | Y13: =VLOOKUP($B13,$R$3:$Z$9,8,FALSE) -> 0 | Z13: =VLOOKUP($B13,$R$3:$Z$9,9,FALSE) -> 60
B14: CARIB | C14: =[4]Brewhouse!$A384 -> CA339 | D14: =[4]Brewhouse!$AF384 -> 50.4 | E14: =[4]Brewhouse!$AI384 -> 49.5 | F14: =[4]Brewhouse!$V384 -> 52 | G14: =[4]Brewhouse!AG384 -> 11.7 | H14: 12 | I14: =[4]Brewhouse!$AU384 -> 95.646067 | J14: =[4]Brewhouse!$AV384 -> 97.199296 | K14: =[4]Brewhouse!$Q384 -> 8 | L14: =[4]Brewhouse!$P384 -> 59 | M14: =[4]Brewhouse!$U384-[4]Brewhouse!$T384 -> 0.11597222 | N14: =[4]Brewhouse!$Z384 -> 0.27569444 | O14: =[4]Brewhouse!$AX384 -> K. Benjamin | R14: =B14 -> CARIB | S14: =VLOOKUP($B14,$R$3:$X$9,2,FALSE) -> 11.6 | T14: =VLOOKUP($B14,$R$3:$X$9,3,FALSE) -> 12 | U14: =VLOOKUP($B14,$R$3:$X$9,4,FALSE) -> 0 | V14: =VLOOKUP($B14,$R$3:$X$9,5,FALSE) -> 0.11805556 | W14: =VLOOKUP($B14,$R$3:$X$9,6,FALSE) -> 0.22569444 | X14: =VLOOKUP($B14,$R$3:$X$9,7,FALSE) -> 0.26388889 | Y14: =VLOOKUP($B14,$R$3:$Z$9,8,FALSE) -> 0 | Z14: =VLOOKUP($B14,$R$3:$Z$9,9,FALSE) -> 60
B15: CARIB | C15: =[4]Brewhouse!$A385 -> CA340 | D15: =[4]Brewhouse!$AF385 -> 52.5 | E15: =[4]Brewhouse!$AI385 -> 50.9 | F15: =[4]Brewhouse!$V385 -> 63 | G15: =[4]Brewhouse!AG385 -> 11.9 | H15: 11.8 | I15: =[4]Brewhouse!$AU385 -> 99.871647 | J15: =[4]Brewhouse!$AV385 -> 101.49371 | K15: =[4]Brewhouse!$Q385 -> 4.1111111 | L15: =[4]Brewhouse!$P385 -> 61 | M15: =[4]Brewhouse!$U385-[4]Brewhouse!$T385 -> 0.11319444 | N15: =[4]Brewhouse!$Z385 -> 0.27569444 | O15: =[4]Brewhouse!$AX385 -> K. Benjamin | R15: =B15 -> CARIB | S15: =VLOOKUP($B15,$R$3:$X$9,2,FALSE) -> 11.6 | T15: =VLOOKUP($B15,$R$3:$X$9,3,FALSE) -> 12 | U15: =VLOOKUP($B15,$R$3:$X$9,4,FALSE) -> 0 | V15: =VLOOKUP($B15,$R$3:$X$9,5,FALSE) -> 0.11805556 | W15: =VLOOKUP($B15,$R$3:$X$9,6,FALSE) -> 0.22569444 | X15: =VLOOKUP($B15,$R$3:$X$9,7,FALSE) -> 0.26388889 | Y15: =VLOOKUP($B15,$R$3:$Z$9,8,FALSE) -> 0 | Z15: =VLOOKUP($B15,$R$3:$Z$9,9,FALSE) -> 60
B16: CARIB | C16: =[4]Brewhouse!$A386 -> CA341 | D16: =[4]Brewhouse!$AF386 -> 52.7 | E16: =[4]Brewhouse!$AI386 -> 50.8 | F16: =[4]Brewhouse!$V386 -> 59 | G16: =[4]Brewhouse!AG386 -> 11.8 | H16: 11.8 | I16: =[4]Brewhouse!$AU386 -> 98.917653 | J16: =[4]Brewhouse!$AV386 -> 100.52412 | K16: =[4]Brewhouse!$Q386 -> 3.9186691 | L16: =[4]Brewhouse!$P386 -> 61 | M16: =[4]Brewhouse!$U386-[4]Brewhouse!$T386 -> 0.10763889 | N16: =[4]Brewhouse!$Z386 -> 0.26944444 | O16: =[4]Brewhouse!$AX386 -> K. Benjamin | R16: =B16 -> CARIB | S16: =VLOOKUP($B16,$R$3:$X$9,2,FALSE) -> 11.6 | T16: =VLOOKUP($B16,$R$3:$X$9,3,FALSE) -> 12 | U16: =VLOOKUP($B16,$R$3:$X$9,4,FALSE) -> 0 | V16: =VLOOKUP($B16,$R$3:$X$9,5,FALSE) -> 0.11805556 | W16: =VLOOKUP($B16,$R$3:$X$9,6,FALSE) -> 0.22569444 | X16: =VLOOKUP($B16,$R$3:$X$9,7,FALSE) -> 0.26388889 | Y16: =VLOOKUP($B16,$R$3:$Z$9,8,FALSE) -> 0 | Z16: =VLOOKUP($B16,$R$3:$Z$9,9,FALSE) -> 60
B17: CARIB | C17: =[4]Brewhouse!$A387 -> CA342 | D17: =[4]Brewhouse!$AF387 -> 52.6 | E17: =[4]Brewhouse!$AI387 -> 50.9 | F17: =[4]Brewhouse!$V387 -> 63 | G17: =[4]Brewhouse!AG387 -> 11.7 | H17: 11.8 | I17: =[4]Brewhouse!$AU387 -> 97.985121 | J17: =[4]Brewhouse!$AV387 -> 99.576651 | K17: =[4]Brewhouse!$Q387 -> 3.9259259 | L17: =[4]Brewhouse!$P387 -> 59 | M17: =[4]Brewhouse!$U387-[4]Brewhouse!$T387 -> 0.11041667 | N17: =[4]Brewhouse!$Z387 -> 0.32013889 | O17: =[4]Brewhouse!$AX387 -> K. Benjamin | P17: spent grain transfer issues | R17: =B17 -> CARIB | S17: =VLOOKUP($B17,$R$3:$X$9,2,FALSE) -> 11.6 | T17: =VLOOKUP($B17,$R$3:$X$9,3,FALSE) -> 12 | U17: =VLOOKUP($B17,$R$3:$X$9,4,FALSE) -> 0 | V17: =VLOOKUP($B17,$R$3:$X$9,5,FALSE) -> 0.11805556 | W17: =VLOOKUP($B17,$R$3:$X$9,6,FALSE) -> 0.22569444 | X17: =VLOOKUP($B17,$R$3:$X$9,7,FALSE) -> 0.26388889 | Y17: =VLOOKUP($B17,$R$3:$Z$9,8,FALSE) -> 0 | Z17: =VLOOKUP($B17,$R$3:$Z$9,9,FALSE) -> 60
R18: =B18 -> 0 | S18: =VLOOKUP($B18,$R$3:$X$9,2,FALSE) -> #N/A | T18: =VLOOKUP($B18,$R$3:$X$9,3,FALSE) -> #N/A | U18: =VLOOKUP($B18,$R$3:$X$9,4,FALSE) -> #N/A | V18: =VLOOKUP($B18,$R$3:$X$9,5,FALSE) -> #N/A | W18: =VLOOKUP($B18,$R$3:$X$9,6,FALSE) -> #N/A | X18: =VLOOKUP($B18,$R$3:$X$9,7,FALSE) -> #N/A | Y18: =VLOOKUP($B18,$R$3:$Z$9,8,FALSE) -> #N/A | Z18: =VLOOKUP($B18,$R$3:$Z$9,9,FALSE) -> #N/A
R19: =B19 -> 0 | S19: =VLOOKUP($B19,$R$3:$X$9,2,FALSE) -> #N/A | T19: =VLOOKUP($B19,$R$3:$X$9,3,FALSE) -> #N/A | U19: =VLOOKUP($B19,$R$3:$X$9,4,FALSE) -> #N/A | V19: =VLOOKUP($B19,$R$3:$X$9,5,FALSE) -> #N/A | W19: =VLOOKUP($B19,$R$3:$X$9,6,FALSE) -> #N/A | X19: =VLOOKUP($B19,$R$3:$X$9,7,FALSE) -> #N/A | Y19: =VLOOKUP($B19,$R$3:$Z$9,8,FALSE) -> #N/A | Z19: =VLOOKUP($B19,$R$3:$Z$9,9,FALSE) -> #N/A
R20: =B20 -> 0 | S20: =VLOOKUP($B20,$R$3:$X$9,2,FALSE) -> #N/A | T20: =VLOOKUP($B20,$R$3:$X$9,3,FALSE) -> #N/A | U20: =VLOOKUP($B20,$R$3:$X$9,4,FALSE) -> #N/A | V20: =VLOOKUP($B20,$R$3:$X$9,5,FALSE) -> #N/A | W20: =VLOOKUP($B20,$R$3:$X$9,6,FALSE) -> #N/A | X20: =VLOOKUP($B20,$R$3:$X$9,7,FALSE) -> #N/A | Y20: =VLOOKUP($B20,$R$3:$Z$9,8,FALSE) -> #N/A | Z20: =VLOOKUP($B20,$R$3:$Z$9,9,FALSE) -> #N/A
R21: =B21 -> 0 | S21: =VLOOKUP($B21,$R$3:$X$9,2,FALSE) -> #N/A | T21: =VLOOKUP($B21,$R$3:$X$9,3,FALSE) -> #N/A | U21: =VLOOKUP($B21,$R$3:$X$9,4,FALSE) -> #N/A | V21: =VLOOKUP($B21,$R$3:$X$9,5,FALSE) -> #N/A | W21: =VLOOKUP($B21,$R$3:$X$9,6,FALSE) -> #N/A | X21: =VLOOKUP($B21,$R$3:$X$9,7,FALSE) -> #N/A | Y21: =VLOOKUP($B21,$R$3:$Z$9,8,FALSE) -> #N/A | Z21: =VLOOKUP($B21,$R$3:$Z$9,9,FALSE) -> #N/A
R22: =B22 -> 0 | S22: =VLOOKUP($B22,$R$3:$X$9,2,FALSE) -> #N/A | T22: =VLOOKUP($B22,$R$3:$X$9,3,FALSE) -> #N/A | U22: =VLOOKUP($B22,$R$3:$X$9,4,FALSE) -> #N/A | V22: =VLOOKUP($B22,$R$3:$X$9,5,FALSE) -> #N/A | W22: =VLOOKUP($B22,$R$3:$X$9,6,FALSE) -> #N/A | X22: =VLOOKUP($B22,$R$3:$X$9,7,FALSE) -> #N/A | Y22: =VLOOKUP($B22,$R$3:$Z$9,8,FALSE) -> #N/A | Z22: =VLOOKUP($B22,$R$3:$Z$9,9,FALSE) -> #N/A
R23: =B23 -> 0 | S23: =VLOOKUP($B23,$R$3:$X$9,2,FALSE) -> #N/A | T23: =VLOOKUP($B23,$R$3:$X$9,3,FALSE) -> #N/A | U23: =VLOOKUP($B23,$R$3:$X$9,4,FALSE) -> #N/A | V23: =VLOOKUP($B23,$R$3:$X$9,5,FALSE) -> #N/A | W23: =VLOOKUP($B23,$R$3:$X$9,6,FALSE) -> #N/A | X23: =VLOOKUP($B23,$R$3:$X$9,7,FALSE) -> #N/A | Y23: =VLOOKUP($B23,$R$3:$Z$9,8,FALSE) -> #N/A | Z23: =VLOOKUP($B23,$R$3:$Z$9,9,FALSE) -> #N/A
R24: =B24 -> 0 | S24: =VLOOKUP($B24,$R$3:$X$9,2,FALSE) -> #N/A | T24: =VLOOKUP($B24,$R$3:$X$9,3,FALSE) -> #N/A | U24: =VLOOKUP($B24,$R$3:$X$9,4,FALSE) -> #N/A | V24: =VLOOKUP($B24,$R$3:$X$9,5,FALSE) -> #N/A | W24: =VLOOKUP($B24,$R$3:$X$9,6,FALSE) -> #N/A | X24: =VLOOKUP($B24,$R$3:$X$9,7,FALSE) -> #N/A | Y24: =VLOOKUP($B24,$R$3:$Z$9,8,FALSE) -> #N/A | Z24: =VLOOKUP($B24,$R$3:$Z$9,9,FALSE) -> #N/A
R25: =B25 -> 0 | S25: =VLOOKUP($B25,$R$3:$X$9,2,FALSE) -> #N/A | T25: =VLOOKUP($B25,$R$3:$X$9,3,FALSE) -> #N/A | U25: =VLOOKUP($B25,$R$3:$X$9,4,FALSE) -> #N/A | V25: =VLOOKUP($B25,$R$3:$X$9,5,FALSE) -> #N/A | W25: =VLOOKUP($B25,$R$3:$X$9,6,FALSE) -> #N/A | X25: =VLOOKUP($B25,$R$3:$X$9,7,FALSE) -> #N/A | Y25: =VLOOKUP($B25,$R$3:$Z$9,8,FALSE) -> #N/A | Z25: =VLOOKUP($B25,$R$3:$Z$9,9,FALSE) -> #N/A
B26: BRAND | D26: BBT P.G./ O.G | I26: Brand | K26: MTD No. of Brews | L26: MTD | M26: YTD | N26: Target | R26: =B26 -> BRAND | S26: =VLOOKUP($B26,$R$3:$X$9,2,FALSE) -> #N/A | T26: =VLOOKUP($B26,$R$3:$X$9,3,FALSE) -> #N/A | U26: =VLOOKUP($B26,$R$3:$X$9,4,FALSE) -> #N/A | V26: =VLOOKUP($B26,$R$3:$X$9,5,FALSE) -> #N/A | W26: =VLOOKUP($B26,$R$3:$X$9,6,FALSE) -> #N/A | X26: =VLOOKUP($B26,$R$3:$X$9,7,FALSE) -> #N/A | Y26: =VLOOKUP($B26,$R$3:$Z$9,8,FALSE) -> #N/A | Z26: =VLOOKUP($B26,$R$3:$Z$9,9,FALSE) -> #N/A
I27: CARIB | J27: =AVERAGE(I10:I17) -> 98.390728 | K27: =COUNTA([4]Brewhouse!$A$372:$A$387) -> 16 | L27: =AVERAGE([4]Brewhouse!$AU$372:$AU$387) -> 98.902892 | M27: =AVERAGE([4]Brewhouse!$AU$42:$AU$123,[4]Brewhouse!$AU$125:$AU$188,[4]Brewhouse!$AU$198:$AU$290,[4]Brewhouse!$AU$292:$AU$370,[4]Brewhouse!$AU$372:$AU$387) -> 98.047809 | N27: 98 | R27: =B27 -> 0 | S27: =VLOOKUP($B27,$R$3:$X$9,2,FALSE) -> #N/A | T27: =VLOOKUP($B27,$R$3:$X$9,3,FALSE) -> #N/A | U27: =VLOOKUP($B27,$R$3:$X$9,4,FALSE) -> #N/A | V27: =VLOOKUP($B27,$R$3:$X$9,5,FALSE) -> #N/A | W27: =VLOOKUP($B27,$R$3:$X$9,6,FALSE) -> #N/A | X27: =VLOOKUP($B27,$R$3:$X$9,7,FALSE) -> #N/A | Y27: =VLOOKUP($B27,$R$3:$Z$9,8,FALSE) -> #N/A | Z27: =VLOOKUP($B27,$R$3:$Z$9,9,FALSE) -> #N/A
I28: STAG | M28: =AVERAGE([3]Brewhouse!$AS$52:$AS$81,[3]Brewhouse!$AS$83:$AS$124,[3]Brewhouse!$AS$134:$AS$177,[3]Brewhouse!$AS$22:$AS$179) -> 97.946758 | N28: 98 | R28: =B28 -> 0 | S28: =VLOOKUP($B28,$R$3:$X$9,2,FALSE) -> #N/A | T28: =VLOOKUP($B28,$R$3:$X$9,3,FALSE) -> #N/A | U28: =VLOOKUP($B28,$R$3:$X$9,4,FALSE) -> #N/A | V28: =VLOOKUP($B28,$R$3:$X$9,5,FALSE) -> #N/A | W28: =VLOOKUP($B28,$R$3:$X$9,6,FALSE) -> #N/A | X28: =VLOOKUP($B28,$R$3:$X$9,7,FALSE) -> #N/A | Y28: =VLOOKUP($B28,$R$3:$Z$9,8,FALSE) -> #N/A | Z28: =VLOOKUP($B28,$R$3:$Z$9,9,FALSE) -> #N/A
I29: GUINNESS | M29: =AVERAGE([5]Brewhouse!$AU$16:$AU$23,[5]Brewhouse!$AU$25:$AU$32,[5]Brewhouse!$AU$34:$AU$41,[5]Brewhouse!$AU$43:$AU$55) -> 96.793457 | N29: 98 | R29: =B29 -> 0 | S29: =VLOOKUP($B29,$R$3:$X$9,2,FALSE) -> #N/A | T29: =VLOOKUP($B29,$R$3:$X$9,3,FALSE) -> #N/A | U29: =VLOOKUP($B29,$R$3:$X$9,4,FALSE) -> #N/A | V29: =VLOOKUP($B29,$R$3:$X$9,5,FALSE) -> #N/A | W29: =VLOOKUP($B29,$R$3:$X$9,6,FALSE) -> #N/A | X29: =VLOOKUP($B29,$R$3:$X$9,7,FALSE) -> #N/A | Y29: =VLOOKUP($B29,$R$3:$Z$9,8,FALSE) -> #N/A | Z29: =VLOOKUP($B29,$R$3:$Z$9,9,FALSE) -> #N/A
I30: VITAMALT | M30: =AVERAGE([6]Brewhouse!$AV$23:$AV$34,[6]Brewhouse!$AV$36,[6]Brewhouse!$AV$38:$AV$52,[6]Brewhouse!$AV$54:$AV$60) -> 97.437513 | N30: 98 | R30: =B30 -> 0 | S30: =VLOOKUP($B30,$R$3:$X$9,2,FALSE) -> #N/A | T30: =VLOOKUP($B30,$R$3:$X$9,3,FALSE) -> #N/A | U30: =VLOOKUP($B30,$R$3:$X$9,4,FALSE) -> #N/A | V30: =VLOOKUP($B30,$R$3:$X$9,5,FALSE) -> #N/A | W30: =VLOOKUP($B30,$R$3:$X$9,6,FALSE) -> #N/A | X30: =VLOOKUP($B30,$R$3:$X$9,7,FALSE) -> #N/A | Y30: =VLOOKUP($B30,$R$3:$Z$9,8,FALSE) -> #N/A | Z30: =VLOOKUP($B30,$R$3:$Z$9,9,FALSE) -> #N/A
I31: MAXIMALT | N31: 98 | R31: =B31 -> 0 | S31: =VLOOKUP($B31,$R$3:$X$9,2,FALSE) -> #N/A | T31: =VLOOKUP($B31,$R$3:$X$9,3,FALSE) -> #N/A | U31: =VLOOKUP($B31,$R$3:$X$9,4,FALSE) -> #N/A | V31: =VLOOKUP($B31,$R$3:$X$9,5,FALSE) -> #N/A | W31: =VLOOKUP($B31,$R$3:$X$9,6,FALSE) -> #N/A | X31: =VLOOKUP($B31,$R$3:$X$9,7,FALSE) -> #N/A | Y31: =VLOOKUP($B31,$R$3:$Z$9,8,FALSE) -> #N/A | Z31: =VLOOKUP($B31,$R$3:$Z$9,9,FALSE) -> #N/A
I32: MACKESON | M32: =AVERAGE([7]Brewhouse!$AT$4:$AT$11) -> 92.826225 | N32: 98 | R32: =B32 -> 0 | S32: =VLOOKUP($B32,$R$3:$X$9,2,FALSE) -> #N/A | T32: =VLOOKUP($B32,$R$3:$X$9,3,FALSE) -> #N/A | U32: =VLOOKUP($B32,$R$3:$X$9,4,FALSE) -> #N/A | V32: =VLOOKUP($B32,$R$3:$X$9,5,FALSE) -> #N/A | W32: =VLOOKUP($B32,$R$3:$X$9,6,FALSE) -> #N/A | X32: =VLOOKUP($B32,$R$3:$X$9,7,FALSE) -> #N/A | Y32: =VLOOKUP($B32,$R$3:$Z$9,8,FALSE) -> #N/A | Z32: =VLOOKUP($B32,$R$3:$Z$9,9,FALSE) -> #N/A
I33: STARMALT | M33: =AVERAGE([8]Brewhouse!$AY$5:$AY$14,[8]Brewhouse!$AY$16:$AY$23,[8]Brewhouse!$AY$42,[8]Brewhouse!$AY$44:$AY$51) -> 97.608428 | N33: 98 | R33: =B33 -> 0 | S33: =VLOOKUP($B33,$R$3:$X$9,2,FALSE) -> #N/A | T33: =VLOOKUP($B33,$R$3:$X$9,3,FALSE) -> #N/A | U33: =VLOOKUP($B33,$R$3:$X$9,4,FALSE) -> #N/A | V33: =VLOOKUP($B33,$R$3:$X$9,5,FALSE) -> #N/A | W33: =VLOOKUP($B33,$R$3:$X$9,6,FALSE) -> #N/A | X33: =VLOOKUP($B33,$R$3:$X$9,7,FALSE) -> #N/A | Y33: =VLOOKUP($B33,$R$3:$Z$9,8,FALSE) -> #N/A | Z33: =VLOOKUP($B33,$R$3:$Z$9,9,FALSE) -> #N/A
I34: HR- Pils | N34: 98 | R34: =B34 -> 0 | S34: =VLOOKUP($B34,$R$3:$X$9,2,FALSE) -> #N/A | T34: =VLOOKUP($B34,$R$3:$X$9,3,FALSE) -> #N/A | U34: =VLOOKUP($B34,$R$3:$X$9,4,FALSE) -> #N/A | V34: =VLOOKUP($B34,$R$3:$X$9,5,FALSE) -> #N/A | W34: =VLOOKUP($B34,$R$3:$X$9,6,FALSE) -> #N/A | X34: =VLOOKUP($B34,$R$3:$X$9,7,FALSE) -> #N/A | Y34: =VLOOKUP($B34,$R$3:$Z$9,8,FALSE) -> #N/A | Z34: =VLOOKUP($B34,$R$3:$Z$9,9,FALSE) -> #N/A
I35: HR- IPA | N35: 98 | R35: =B35 -> 0 | S35: =VLOOKUP($B35,$R$3:$X$9,2,FALSE) -> #N/A | T35: =VLOOKUP($B35,$R$3:$X$9,3,FALSE) -> #N/A | U35: =VLOOKUP($B35,$R$3:$X$9,4,FALSE) -> #N/A | V35: =VLOOKUP($B35,$R$3:$X$9,5,FALSE) -> #N/A | W35: =VLOOKUP($B35,$R$3:$X$9,6,FALSE) -> #N/A | X35: =VLOOKUP($B35,$R$3:$X$9,7,FALSE) -> #N/A | Y35: =VLOOKUP($B35,$R$3:$Z$9,8,FALSE) -> #N/A | Z35: =VLOOKUP($B35,$R$3:$Z$9,9,FALSE) -> #N/A
I36: HR- APA | N36: 98 | R36: =B36 -> 0 | S36: =VLOOKUP($B36,$R$3:$X$9,2,FALSE) -> #N/A | T36: =VLOOKUP($B36,$R$3:$X$9,3,FALSE) -> #N/A | U36: =VLOOKUP($B36,$R$3:$X$9,4,FALSE) -> #N/A | V36: =VLOOKUP($B36,$R$3:$X$9,5,FALSE) -> #N/A | W36: =VLOOKUP($B36,$R$3:$X$9,6,FALSE) -> #N/A | X36: =VLOOKUP($B36,$R$3:$X$9,7,FALSE) -> #N/A | Y36: =VLOOKUP($B36,$R$3:$Z$9,8,FALSE) -> #N/A | Z36: =VLOOKUP($B36,$R$3:$Z$9,9,FALSE) -> #N/A
K37: =SUM(K27:K36) -> 16 | L37: =((L27*K27)+(L28*K28)+(L29*K29)+(L30*K30)+(L31*K31)+(K34*L34)+(L32*K32)+(L33*K33)+(L36*K36))/(K37) -> 98.902892 | M37: =AVERAGE('[9]Jan30th-31st'!$L$42,L37) -> 98.365467 | N37: 98 | R37: =B37 -> 0 | S37: =VLOOKUP($B37,$R$3:$X$9,2,FALSE) -> #N/A | T37: =VLOOKUP($B37,$R$3:$X$9,3,FALSE) -> #N/A | U37: =VLOOKUP($B37,$R$3:$X$9,4,FALSE) -> #N/A | V37: =VLOOKUP($B37,$R$3:$X$9,5,FALSE) -> #N/A | W37: =VLOOKUP($B37,$R$3:$X$9,6,FALSE) -> #N/A | X37: =VLOOKUP($B37,$R$3:$X$9,7,FALSE) -> #N/A | Y37: =VLOOKUP($B37,$R$3:$Z$9,8,FALSE) -> #N/A | Z37: =VLOOKUP($B37,$R$3:$Z$9,9,FALSE) -> #N/A
R38: =B38 -> 0 | S38: =VLOOKUP($B38,$R$3:$X$9,2,FALSE) -> #N/A | T38: =VLOOKUP($B38,$R$3:$X$9,3,FALSE) -> #N/A | U38: =VLOOKUP($B38,$R$3:$X$9,4,FALSE) -> #N/A | V38: =VLOOKUP($B38,$R$3:$X$9,5,FALSE) -> #N/A | W38: =VLOOKUP($B38,$R$3:$X$9,6,FALSE) -> #N/A | X38: =VLOOKUP($B38,$R$3:$X$9,7,FALSE) -> #N/A | Y38: =VLOOKUP($B38,$R$3:$Z$9,8,FALSE) -> #N/A | Z38: =VLOOKUP($B38,$R$3:$Z$9,9,FALSE) -> #N/A
J39: Daily Brewing Plan
J40: Brand | K40: Brews Achieved | L40: Average Brews per day
...

Sheet May 5th
S1: P.G. | U1: Hot Time | W1: Process Time | Y1: Cooling Time
B2: Brewing Department Daily Process Loss Report | S2: Lower | T2: Upper | U2: Lower | V2: Upper | W2: Lower | X2: Upper | Y2: Lower | Z2: Upper
R3: CARIB | S3: 11.6 | T3: 12 | U3: 0 | V3: 0.11805556 | W3: 0.22569444 | X3: 0.26388889 | Y3: 0 | Z3: 60 | AB3: HR- PISNER
B4: Date: | C4: 46148 | J4: LOT WORT COLOUR: | M4: Filter Sheets (Target 20 days) | R4: STAG | S4: 11.6 | T4: 12 | U4: 0 | V4: 0.11805556 | W4: 0.22569444 | X4: 0.26388889 | Y4: 0 | Z4: 60
M5: Double | N5: Single | R5: GUINNESS | S5: 17 | T5: 17.5 | U5: 0 | V5: 0.10763889 | W5: 0.24652778 | X5: 0.28472222 | Y5: 0 | Z5: 60
J6: MALT LOT: Lot #13 | L6: Sheet Day | R6: MACKESON | S6: 13.3 | T6: 13.5 | U6: 0 | V6: 0.12905093 | W6: 0.27430556 | X6: 0.30208333 | Y6: 0
R7: STARMALT | S7: 17 | T7: 17.4 | U7: 0 | V7: 0.13605324 | W7: 0.27430556 | X7: 0.30902778 | Y7: 0 | Z7: 85
B8: Brand | C8: Brew no. | D8: Kett. Hls | E8: Wort | F8: Cool Time(Mins) | G8: Cast. P.G. (Lab Result) | H8: Cast P.G. (Cellar Operator)-gravity | I8: Extr. Rec (77.9%) | J8: Theor. Extr. (77.5%) | K8: Boil Off /Vol. (4-6%) | L8: Boil Time | M8: Total Hot | N8: Brewing Time | O8: Operator | R8: Hurricane Reef | S8: 16.6 | T8: 17 | U8: 0 | V8: 0.12905093 | W8: 0.27430556 | X8: 0.30208333 | Y8: 0
E9: Meter (Hls) | F9: Target(< 60Mins) | M9: Time | R9: VITAMALT | S9: 14.2 | T9: 14.6 | U9: 0 | V9: 0.13905093 | W9: 0.26041667 | X9: 0.29513889 | Y9: 0 | Z9: 75
B10: STAG | C10: =[3]Brewhouse!$A214 -> ST160 | D10: =[3]Brewhouse!$AB214 -> 53.1 | E10: =[3]Brewhouse!$AG214 -> 47 | F10: =[3]Brewhouse!$V214 -> 59 | G10: =[3]Brewhouse!$AE214 -> 12 | I10: =[3]Brewhouse!$AS214 -> 94.64295 | J10: =[3]Brewhouse!$AT214 -> 95.923205 | K10: =[3]Brewhouse!$Q214 -> 7.4858757 | L10: =[3]Brewhouse!$P214 -> 60 | M10: =[3]Brewhouse!$U214-[3]Brewhouse!$T214 -> 0.22569444 | N10: =[3]Brewhouse!$AW214 -> 0.38680556 | O10: =[3]Brewhouse!$AV214 -> R.Sookram | P10: wort transfer pump and valve issue | R10: =B10 -> STAG | S10: =VLOOKUP($B10,$R$3:$X$9,2,FALSE) -> 11.6 | T10: =VLOOKUP($B10,$R$3:$X$9,3,FALSE) -> 12 | U10: =VLOOKUP($B10,$R$3:$X$9,4,FALSE) -> 0 | V10: =VLOOKUP($B10,$R$3:$X$9,5,FALSE) -> 0.11805556 | W10: =VLOOKUP($B10,$R$3:$X$9,6,FALSE) -> 0.22569444 | X10: =VLOOKUP($B10,$R$3:$X$9,7,FALSE) -> 0.26388889 | Y10: =VLOOKUP($B10,$R$3:$Z$9,8,FALSE) -> 0 | Z10: =VLOOKUP($B10,$R$3:$Z$9,9,FALSE) -> 60
B11: STAG | C11: =[3]Brewhouse!$A215 -> ST161 | D11: =[3]Brewhouse!$AB215 -> 53 | E11: =[3]Brewhouse!$AG215 -> 50.1 | F11: =[3]Brewhouse!$V215 -> 62 | G11: =[3]Brewhouse!$AE215 -> 11.7 | I11: =[3]Brewhouse!$AS215 -> 97.74062 | J11: =[3]Brewhouse!$AT215 -> 99.064531 | K11: =[3]Brewhouse!$Q215 -> 2.5943396 | L11: =[3]Brewhouse!$P215 -> 61 | M11: =[3]Brewhouse!$U215-[3]Brewhouse!$T215 -> 0.11597222 | N11: =[3]Brewhouse!$AW215 -> 0.39722222 | O11: =[3]Brewhouse!$AV215 -> R.Sookram | P11: copper up in pre-run | R11: =B11 -> STAG | S11: =VLOOKUP($B11,$R$3:$X$9,2,FALSE) -> 11.6 | T11: =VLOOKUP($B11,$R$3:$X$9,3,FALSE) -> 12 | U11: =VLOOKUP($B11,$R$3:$X$9,4,FALSE) -> 0 | V11: =VLOOKUP($B11,$R$3:$X$9,5,FALSE) -> 0.11805556 | W11: =VLOOKUP($B11,$R$3:$X$9,6,FALSE) -> 0.22569444 | X11: =VLOOKUP($B11,$R$3:$X$9,7,FALSE) -> 0.26388889 | Y11: =VLOOKUP($B11,$R$3:$Z$9,8,FALSE) -> 0 | Z11: =VLOOKUP($B11,$R$3:$Z$9,9,FALSE) -> 60
B12: 46148 | R12: =B12 -> 46148 | S12: =VLOOKUP($B12,$R$3:$X$9,2,FALSE) -> #N/A | T12: =VLOOKUP($B12,$R$3:$X$9,3,FALSE) -> #N/A | U12: =VLOOKUP($B12,$R$3:$X$9,4,FALSE) -> #N/A | V12: =VLOOKUP($B12,$R$3:$X$9,5,FALSE) -> #N/A | W12: =VLOOKUP($B12,$R$3:$X$9,6,FALSE) -> #N/A | X12: =VLOOKUP($B12,$R$3:$X$9,7,FALSE) -> #N/A | Y12: =VLOOKUP($B12,$R$3:$Z$9,8,FALSE) -> #N/A | Z12: =VLOOKUP($B12,$R$3:$Z$9,9,FALSE) -> #N/A
B13: STAG | C13: =[3]Brewhouse!$A216 -> ST162 | D13: =[3]Brewhouse!$AB216 -> 53.1 | E13: =[3]Brewhouse!$AG216 -> 50 | F13: =[3]Brewhouse!$V216 -> 63 | G13: =[3]Brewhouse!$AE216 -> 11.6 | I13: =[3]Brewhouse!$AS216 -> 97.156843 | J13: =[3]Brewhouse!$AT216 -> 98.471104 | K13: =[3]Brewhouse!$Q216 -> 4.2843691 | L13: =[3]Brewhouse!$P216 -> 61 | M13: =[3]Brewhouse!$U216-[3]Brewhouse!$T216 -> 0.125 | N13: =[3]Brewhouse!$AW216 -> 0.275 | O13: =[3]Brewhouse!$AV216 -> D. Gomaz | P13: spent grain issue | R13: =B13 -> STAG | S13: =VLOOKUP($B13,$R$3:$X$9,2,FALSE) -> 11.6 | T13: =VLOOKUP($B13,$R$3:$X$9,3,FALSE) -> 12 | U13: =VLOOKUP($B13,$R$3:$X$9,4,FALSE) -> 0 | V13: =VLOOKUP($B13,$R$3:$X$9,5,FALSE) -> 0.11805556 | W13: =VLOOKUP($B13,$R$3:$X$9,6,FALSE) -> 0.22569444 | X13: =VLOOKUP($B13,$R$3:$X$9,7,FALSE) -> 0.26388889 | Y13: =VLOOKUP($B13,$R$3:$Z$9,8,FALSE) -> 0 | Z13: =VLOOKUP($B13,$R$3:$Z$9,9,FALSE) -> 60
R14: =B14 -> 0 | S14: =VLOOKUP($B14,$R$3:$X$9,2,FALSE) -> #N/A | T14: =VLOOKUP($B14,$R$3:$X$9,3,FALSE) -> #N/A | U14: =VLOOKUP($B14,$R$3:$X$9,4,FALSE) -> #N/A | V14: =VLOOKUP($B14,$R$3:$X$9,5,FALSE) -> #N/A | W14: =VLOOKUP($B14,$R$3:$X$9,6,FALSE) -> #N/A | X14: =VLOOKUP($B14,$R$3:$X$9,7,FALSE) -> #N/A | Y14: =VLOOKUP($B14,$R$3:$Z$9,8,FALSE) -> #N/A | Z14: =VLOOKUP($B14,$R$3:$Z$9,9,FALSE) -> #N/A
R15: =B15 -> 0 | S15: =VLOOKUP($B15,$R$3:$X$9,2,FALSE) -> #N/A | T15: =VLOOKUP($B15,$R$3:$X$9,3,FALSE) -> #N/A | U15: =VLOOKUP($B15,$R$3:$X$9,4,FALSE) -> #N/A | V15: =VLOOKUP($B15,$R$3:$X$9,5,FALSE) -> #N/A | W15: =VLOOKUP($B15,$R$3:$X$9,6,FALSE) -> #N/A | X15: =VLOOKUP($B15,$R$3:$X$9,7,FALSE) -> #N/A | Y15: =VLOOKUP($B15,$R$3:$Z$9,8,FALSE) -> #N/A | Z15: =VLOOKUP($B15,$R$3:$Z$9,9,FALSE) -> #N/A
R16: =B16 -> 0 | S16: =VLOOKUP($B16,$R$3:$X$9,2,FALSE) -> #N/A | T16: =VLOOKUP($B16,$R$3:$X$9,3,FALSE) -> #N/A | U16: =VLOOKUP($B16,$R$3:$X$9,4,FALSE) -> #N/A | V16: =VLOOKUP($B16,$R$3:$X$9,5,FALSE) -> #N/A | W16: =VLOOKUP($B16,$R$3:$X$9,6,FALSE) -> #N/A | X16: =VLOOKUP($B16,$R$3:$X$9,7,FALSE) -> #N/A | Y16: =VLOOKUP($B16,$R$3:$Z$9,8,FALSE) -> #N/A | Z16: =VLOOKUP($B16,$R$3:$Z$9,9,FALSE) -> #N/A
R17: =B17 -> 0 | S17: =VLOOKUP($B17,$R$3:$X$9,2,FALSE) -> #N/A | T17: =VLOOKUP($B17,$R$3:$X$9,3,FALSE) -> #N/A | U17: =VLOOKUP($B17,$R$3:$X$9,4,FALSE) -> #N/A | V17: =VLOOKUP($B17,$R$3:$X$9,5,FALSE) -> #N/A | W17: =VLOOKUP($B17,$R$3:$X$9,6,FALSE) -> #N/A | X17: =VLOOKUP($B17,$R$3:$X$9,7,FALSE) -> #N/A | Y17: =VLOOKUP($B17,$R$3:$Z$9,8,FALSE) -> #N/A | Z17: =VLOOKUP($B17,$R$3:$Z$9,9,FALSE) -> #N/A
R18: =B18 -> 0 | S18: =VLOOKUP($B18,$R$3:$X$9,2,FALSE) -> #N/A | T18: =VLOOKUP($B18,$R$3:$X$9,3,FALSE) -> #N/A | U18: =VLOOKUP($B18,$R$3:$X$9,4,FALSE) -> #N/A | V18: =VLOOKUP($B18,$R$3:$X$9,5,FALSE) -> #N/A | W18: =VLOOKUP($B18,$R$3:$X$9,6,FALSE) -> #N/A | X18: =VLOOKUP($B18,$R$3:$X$9,7,FALSE) -> #N/A | Y18: =VLOOKUP($B18,$R$3:$Z$9,8,FALSE) -> #N/A | Z18: =VLOOKUP($B18,$R$3:$Z$9,9,FALSE) -> #N/A
R19: =B19 -> 0 | S19: =VLOOKUP($B19,$R$3:$X$9,2,FALSE) -> #N/A | T19: =VLOOKUP($B19,$R$3:$X$9,3,FALSE) -> #N/A | U19: =VLOOKUP($B19,$R$3:$X$9,4,FALSE) -> #N/A | V19: =VLOOKUP($B19,$R$3:$X$9,5,FALSE) -> #N/A | W19: =VLOOKUP($B19,$R$3:$X$9,6,FALSE) -> #N/A | X19: =VLOOKUP($B19,$R$3:$X$9,7,FALSE) -> #N/A | Y19: =VLOOKUP($B19,$R$3:$Z$9,8,FALSE) -> #N/A | Z19: =VLOOKUP($B19,$R$3:$Z$9,9,FALSE) -> #N/A
R20: =B20 -> 0 | S20: =VLOOKUP($B20,$R$3:$X$9,2,FALSE) -> #N/A | T20: =VLOOKUP($B20,$R$3:$X$9,3,FALSE) -> #N/A | U20: =VLOOKUP($B20,$R$3:$X$9,4,FALSE) -> #N/A | V20: =VLOOKUP($B20,$R$3:$X$9,5,FALSE) -> #N/A | W20: =VLOOKUP($B20,$R$3:$X$9,6,FALSE) -> #N/A | X20: =VLOOKUP($B20,$R$3:$X$9,7,FALSE) -> #N/A | Y20: =VLOOKUP($B20,$R$3:$Z$9,8,FALSE) -> #N/A | Z20: =VLOOKUP($B20,$R$3:$Z$9,9,FALSE) -> #N/A
R21: =B21 -> 0 | S21: =VLOOKUP($B21,$R$3:$X$9,2,FALSE) -> #N/A | T21: =VLOOKUP($B21,$R$3:$X$9,3,FALSE) -> #N/A | U21: =VLOOKUP($B21,$R$3:$X$9,4,FALSE) -> #N/A | V21: =VLOOKUP($B21,$R$3:$X$9,5,FALSE) -> #N/A | W21: =VLOOKUP($B21,$R$3:$X$9,6,FALSE) -> #N/A | X21: =VLOOKUP($B21,$R$3:$X$9,7,FALSE) -> #N/A | Y21: =VLOOKUP($B21,$R$3:$Z$9,8,FALSE) -> #N/A | Z21: =VLOOKUP($B21,$R$3:$Z$9,9,FALSE) -> #N/A
B22: BRAND | D22: BBT P.G./ O.G | I22: Brand | K22: MTD No. of Brews | L22: MTD | M22: YTD | N22: Target | R22: =B22 -> BRAND | S22: =VLOOKUP($B22,$R$3:$X$9,2,FALSE) -> #N/A | T22: =VLOOKUP($B22,$R$3:$X$9,3,FALSE) -> #N/A | U22: =VLOOKUP($B22,$R$3:$X$9,4,FALSE) -> #N/A | V22: =VLOOKUP($B22,$R$3:$X$9,5,FALSE) -> #N/A | W22: =VLOOKUP($B22,$R$3:$X$9,6,FALSE) -> #N/A | X22: =VLOOKUP($B22,$R$3:$X$9,7,FALSE) -> #N/A | Y22: =VLOOKUP($B22,$R$3:$Z$9,8,FALSE) -> #N/A | Z22: =VLOOKUP($B22,$R$3:$Z$9,9,FALSE) -> #N/A
I23: CARIB | K23: =COUNTA([4]Brewhouse!$A$372:$A$387) -> 16 | L23: =AVERAGE([4]Brewhouse!$AU$372:$AU$387) -> 98.902892 | M23: =AVERAGE([4]Brewhouse!$AU$42:$AU$123,[4]Brewhouse!$AU$125:$AU$188,[4]Brewhouse!$AU$198:$AU$290,[4]Brewhouse!$AU$292:$AU$370,[4]Brewhouse!$AU$372:$AU$387) -> 98.047809 | N23: 98 | R23: =B23 -> 0 | S23: =VLOOKUP($B23,$R$3:$X$9,2,FALSE) -> #N/A | T23: =VLOOKUP($B23,$R$3:$X$9,3,FALSE) -> #N/A | U23: =VLOOKUP($B23,$R$3:$X$9,4,FALSE) -> #N/A | V23: =VLOOKUP($B23,$R$3:$X$9,5,FALSE) -> #N/A | W23: =VLOOKUP($B23,$R$3:$X$9,6,FALSE) -> #N/A | X23: =VLOOKUP($B23,$R$3:$X$9,7,FALSE) -> #N/A | Y23: =VLOOKUP($B23,$R$3:$Z$9,8,FALSE) -> #N/A | Z23: =VLOOKUP($B23,$R$3:$Z$9,9,FALSE) -> #N/A
I24: STAG | J24: =AVERAGE(I10:I11) -> 96.191785 | K24: =COUNTA([3]Brewhouse!$A$214:$A$215) -> 2 | L24: =AVERAGE([3]Brewhouse!$AS$214:$AS$215) -> 96.191785 | M24: =AVERAGE([3]Brewhouse!$AS$52:$AS$81,[3]Brewhouse!$AS$83:$AS$124,[3]Brewhouse!$AS$134:$AS$177,[3]Brewhouse!$AS$22:$AS$179,[3]Brewhouse!$AS$214:$AS$215) -> 97.934041 | N24: 98 | R24: =B24 -> 0 | S24: =VLOOKUP($B24,$R$3:$X$9,2,FALSE) -> #N/A | T24: =VLOOKUP($B24,$R$3:$X$9,3,FALSE) -> #N/A | U24: =VLOOKUP($B24,$R$3:$X$9,4,FALSE) -> #N/A | V24: =VLOOKUP($B24,$R$3:$X$9,5,FALSE) -> #N/A | W24: =VLOOKUP($B24,$R$3:$X$9,6,FALSE) -> #N/A | X24: =VLOOKUP($B24,$R$3:$X$9,7,FALSE) -> #N/A | Y24: =VLOOKUP($B24,$R$3:$Z$9,8,FALSE) -> #N/A | Z24: =VLOOKUP($B24,$R$3:$Z$9,9,FALSE) -> #N/A
I25: GUINNESS | M25: =AVERAGE([5]Brewhouse!$AU$16:$AU$23,[5]Brewhouse!$AU$25:$AU$32,[5]Brewhouse!$AU$34:$AU$41,[5]Brewhouse!$AU$43:$AU$55) -> 96.793457 | N25: 98 | R25: =B25 -> 0 | S25: =VLOOKUP($B25,$R$3:$X$9,2,FALSE) -> #N/A | T25: =VLOOKUP($B25,$R$3:$X$9,3,FALSE) -> #N/A | U25: =VLOOKUP($B25,$R$3:$X$9,4,FALSE) -> #N/A | V25: =VLOOKUP($B25,$R$3:$X$9,5,FALSE) -> #N/A | W25: =VLOOKUP($B25,$R$3:$X$9,6,FALSE) -> #N/A | X25: =VLOOKUP($B25,$R$3:$X$9,7,FALSE) -> #N/A | Y25: =VLOOKUP($B25,$R$3:$Z$9,8,FALSE) -> #N/A | Z25: =VLOOKUP($B25,$R$3:$Z$9,9,FALSE) -> #N/A
I26: VITAMALT | M26: =AVERAGE([6]Brewhouse!$AV$23:$AV$34,[6]Brewhouse!$AV$36,[6]Brewhouse!$AV$38:$AV$52,[6]Brewhouse!$AV$54:$AV$60) -> 97.437513 | N26: 98 | R26: =B26 -> 0 | S26: =VLOOKUP($B26,$R$3:$X$9,2,FALSE) -> #N/A | T26: =VLOOKUP($B26,$R$3:$X$9,3,FALSE) -> #N/A | U26: =VLOOKUP($B26,$R$3:$X$9,4,FALSE) -> #N/A | V26: =VLOOKUP($B26,$R$3:$X$9,5,FALSE) -> #N/A | W26: =VLOOKUP($B26,$R$3:$X$9,6,FALSE) -> #N/A | X26: =VLOOKUP($B26,$R$3:$X$9,7,FALSE) -> #N/A | Y26: =VLOOKUP($B26,$R$3:$Z$9,8,FALSE) -> #N/A | Z26: =VLOOKUP($B26,$R$3:$Z$9,9,FALSE) -> #N/A
I27: MAXIMALT | N27: 98 | R27: =B27 -> 0 | S27: =VLOOKUP($B27,$R$3:$X$9,2,FALSE) -> #N/A | T27: =VLOOKUP($B27,$R$3:$X$9,3,FALSE) -> #N/A | U27: =VLOOKUP($B27,$R$3:$X$9,4,FALSE) -> #N/A | V27: =VLOOKUP($B27,$R$3:$X$9,5,FALSE) -> #N/A | W27: =VLOOKUP($B27,$R$3:$X$9,6,FALSE) -> #N/A | X27: =VLOOKUP($B27,$R$3:$X$9,7,FALSE) -> #N/A | Y27: =VLOOKUP($B27,$R$3:$Z$9,8,FALSE) -> #N/A | Z27: =VLOOKUP($B27,$R$3:$Z$9,9,FALSE) -> #N/A
