Workbook
Name ProductList: [1]November15!$R$3:$R$9
Name ProductList: [2]November15!$R$3:$R$9

Sheet Dec 18th
T1: P.G. | V1: Hot Time | X1: Process Time | Z1: Cooling Time
B2: Brewing Department Daily Process Loss Report | T2: Lower | U2: Upper | V2: Lower | W2: Upper | X2: Lower | Y2: Upper | Z2: Lower | AA2: Upper
S3: CARIB | T3: 11.6 | U3: 12 | V3: 0 | W3: 0.11805556 | X3: 0.17361111 | Y3: 0.21180556 | Z3: 0 | AA3: 60 | AC3: HR- PISNER
B4: Date: | C4: 45278 | J4: LOT WORT COLOUR: 3.4 | M4: Filter Sheets (Target 20 days) | S4: STAG | T4: 11.6 | U4: 12 | V4: 0 | W4: 0.11805556 | X4: 0.17361111 | Y4: 0.21180556 | Z4: 0 | AA4: 60
M5: Double | N5: Single | S5: GUINNESS | T5: 17 | U5: 17.5 | V5: 0 | W5: 0.10763889 | X5: 0.19444444 | Y5: 0.23263889 | Z5: 0 | AA5: 60
J6: MALT LOT: Lot 8 | L6: Sheet Day | S6: MACKESON | T6: 13.3 | U6: 13.5 | V6: 0 | W6: 0.12905093 | X6: 0.22222222 | Y6: 0.25347222 | Z6: 0
S7: STARMALT | T7: 17.1 | U7: 17.5 | V7: 0 | W7: 0.13605324 | X7: 0.20833333 | Y7: 0.24305556 | Z7: 0 | AA7: 60
B8: Brand | C8: Brew no. | D8: Kett. Hls | E8: Wort | F8: Cool Time(Mins) | G8: Cast. P.G. (Lab Result) | H8: Cast P.G. (Cellar Operator)-gravity | I8: Extr. Rec (79.1%) | J8: Theor. Extr. (77.5%) | K8: Boil Off /Vol. (4-6%) | L8: Boil Time | M8: Total Hot | N8: Brewing | P8: Comments | Q8: Actual Pilsen Malt | S8: Hurricane Reef | T8: 16.6 | U8: 17 | V8: 0 | W8: 0.12905093 | X8: 0.22222222 | Y8: 0.25347222 | Z8: 0
E9: Meter (Hls) | F9: Target(< 60Mins) | M9: Time | S9: VITAMALT | T9: 14.4 | U9: 14.6 | V9: 0 | W9: 0.13905093 | X9: 0.19097222 | Y9: 0.22569444 | Z9: 0 | AA9: 75
S10: =B10 -> 0 | T10: =VLOOKUP($B10,$S$3:$Y$9,2,FALSE) -> #N/A | U10: =VLOOKUP($B10,$S$3:$Y$9,3,FALSE) -> #N/A | V10: =VLOOKUP($B10,$S$3:$Y$9,4,FALSE) -> #N/A | W10: =VLOOKUP($B10,$S$3:$Y$9,5,FALSE) -> #N/A | X10: =VLOOKUP($B10,$S$3:$Y$9,6,FALSE) -> #N/A | Y10: =VLOOKUP($B10,$S$3:$Y$9,7,FALSE) -> #N/A | Z10: =VLOOKUP($B10,$S$3:$AA$9,8,FALSE) -> #N/A | AA10: =VLOOKUP($B10,$S$3:$AA$9,9,FALSE) -> #N/A
S11: =B11 -> 0 | T11: =VLOOKUP($B11,$S$3:$Y$9,2,FALSE) -> #N/A | U11: =VLOOKUP($B11,$S$3:$Y$9,3,FALSE) -> #N/A | V11: =VLOOKUP($B11,$S$3:$Y$9,4,FALSE) -> #N/A | W11: =VLOOKUP($B11,$S$3:$Y$9,5,FALSE) -> #N/A | X11: =VLOOKUP($B11,$S$3:$Y$9,6,FALSE) -> #N/A | Y11: =VLOOKUP($B11,$S$3:$Y$9,7,FALSE) -> #N/A | Z11: =VLOOKUP($B11,$S$3:$AA$9,8,FALSE) -> #N/A | AA11: =VLOOKUP($B11,$S$3:$AA$9,9,FALSE) -> #N/A
S12: =B12 -> 0 | T12: =VLOOKUP($B12,$S$3:$Y$9,2,FALSE) -> #N/A | U12: =VLOOKUP($B12,$S$3:$Y$9,3,FALSE) -> #N/A | V12: =VLOOKUP($B12,$S$3:$Y$9,4,FALSE) -> #N/A | W12: =VLOOKUP($B12,$S$3:$Y$9,5,FALSE) -> #N/A | X12: =VLOOKUP($B12,$S$3:$Y$9,6,FALSE) -> #N/A | Y12: =VLOOKUP($B12,$S$3:$Y$9,7,FALSE) -> #N/A | Z12: =VLOOKUP($B12,$S$3:$AA$9,8,FALSE) -> #N/A | AA12: =VLOOKUP($B12,$S$3:$AA$9,9,FALSE) -> #N/A
S13: =B13 -> 0 | T13: =VLOOKUP($B13,$S$3:$Y$9,2,FALSE) -> #N/A | U13: =VLOOKUP($B13,$S$3:$Y$9,3,FALSE) -> #N/A | V13: =VLOOKUP($B13,$S$3:$Y$9,4,FALSE) -> #N/A | W13: =VLOOKUP($B13,$S$3:$Y$9,5,FALSE) -> #N/A | X13: =VLOOKUP($B13,$S$3:$Y$9,6,FALSE) -> #N/A | Y13: =VLOOKUP($B13,$S$3:$Y$9,7,FALSE) -> #N/A | Z13: =VLOOKUP($B13,$S$3:$AA$9,8,FALSE) -> #N/A | AA13: =VLOOKUP($B13,$S$3:$AA$9,9,FALSE) -> #N/A
S14: =B14 -> 0 | T14: =VLOOKUP($B14,$S$3:$Y$9,2,FALSE) -> #N/A | U14: =VLOOKUP($B14,$S$3:$Y$9,3,FALSE) -> #N/A | V14: =VLOOKUP($B14,$S$3:$Y$9,4,FALSE) -> #N/A | W14: =VLOOKUP($B14,$S$3:$Y$9,5,FALSE) -> #N/A | X14: =VLOOKUP($B14,$S$3:$Y$9,6,FALSE) -> #N/A | Y14: =VLOOKUP($B14,$S$3:$Y$9,7,FALSE) -> #N/A | Z14: =VLOOKUP($B14,$S$3:$AA$9,8,FALSE) -> #N/A | AA14: =VLOOKUP($B14,$S$3:$AA$9,9,FALSE) -> #N/A
S15: =B15 -> 0 | T15: =VLOOKUP($B15,$S$3:$Y$9,2,FALSE) -> #N/A | U15: =VLOOKUP($B15,$S$3:$Y$9,3,FALSE) -> #N/A | V15: =VLOOKUP($B15,$S$3:$Y$9,4,FALSE) -> #N/A | W15: =VLOOKUP($B15,$S$3:$Y$9,5,FALSE) -> #N/A | X15: =VLOOKUP($B15,$S$3:$Y$9,6,FALSE) -> #N/A | Y15: =VLOOKUP($B15,$S$3:$Y$9,7,FALSE) -> #N/A | Z15: =VLOOKUP($B15,$S$3:$AA$9,8,FALSE) -> #N/A | AA15: =VLOOKUP($B15,$S$3:$AA$9,9,FALSE) -> #N/A
S16: =B16 -> 0 | T16: =VLOOKUP($B16,$S$3:$Y$9,2,FALSE) -> #N/A | U16: =VLOOKUP($B16,$S$3:$Y$9,3,FALSE) -> #N/A | V16: =VLOOKUP($B16,$S$3:$Y$9,4,FALSE) -> #N/A | W16: =VLOOKUP($B16,$S$3:$Y$9,5,FALSE) -> #N/A | X16: =VLOOKUP($B16,$S$3:$Y$9,6,FALSE) -> #N/A | Y16: =VLOOKUP($B16,$S$3:$Y$9,7,FALSE) -> #N/A | Z16: =VLOOKUP($B16,$S$3:$AA$9,8,FALSE) -> #N/A | AA16: =VLOOKUP($B16,$S$3:$AA$9,9,FALSE) -> #N/A
S17: =B17 -> 0 | T17: =VLOOKUP($B17,$S$3:$Y$9,2,FALSE) -> #N/A | U17: =VLOOKUP($B17,$S$3:$Y$9,3,FALSE) -> #N/A | V17: =VLOOKUP($B17,$S$3:$Y$9,4,FALSE) -> #N/A | W17: =VLOOKUP($B17,$S$3:$Y$9,5,FALSE) -> #N/A | X17: =VLOOKUP($B17,$S$3:$Y$9,6,FALSE) -> #N/A | Y17: =VLOOKUP($B17,$S$3:$Y$9,7,FALSE) -> #N/A | Z17: =VLOOKUP($B17,$S$3:$AA$9,8,FALSE) -> #N/A | AA17: =VLOOKUP($B17,$S$3:$AA$9,9,FALSE) -> #N/A
S18: =B18 -> 0 | T18: =VLOOKUP($B18,$S$3:$Y$9,2,FALSE) -> #N/A | U18: =VLOOKUP($B18,$S$3:$Y$9,3,FALSE) -> #N/A | V18: =VLOOKUP($B18,$S$3:$Y$9,4,FALSE) -> #N/A | W18: =VLOOKUP($B18,$S$3:$Y$9,5,FALSE) -> #N/A | X18: =VLOOKUP($B18,$S$3:$Y$9,6,FALSE) -> #N/A | Y18: =VLOOKUP($B18,$S$3:$Y$9,7,FALSE) -> #N/A | Z18: =VLOOKUP($B18,$S$3:$AA$9,8,FALSE) -> #N/A | AA18: =VLOOKUP($B18,$S$3:$AA$9,9,FALSE) -> #N/A
S19: =B19 -> 0 | T19: =VLOOKUP($B19,$S$3:$Y$9,2,FALSE) -> #N/A | U19: =VLOOKUP($B19,$S$3:$Y$9,3,FALSE) -> #N/A | V19: =VLOOKUP($B19,$S$3:$Y$9,4,FALSE) -> #N/A | W19: =VLOOKUP($B19,$S$3:$Y$9,5,FALSE) -> #N/A | X19: =VLOOKUP($B19,$S$3:$Y$9,6,FALSE) -> #N/A | Y19: =VLOOKUP($B19,$S$3:$Y$9,7,FALSE) -> #N/A | Z19: =VLOOKUP($B19,$S$3:$AA$9,8,FALSE) -> #N/A | AA19: =VLOOKUP($B19,$S$3:$AA$9,9,FALSE) -> #N/A
S20: =B20 -> 0 | T20: =VLOOKUP($B20,$S$3:$Y$9,2,FALSE) -> #N/A | U20: =VLOOKUP($B20,$S$3:$Y$9,3,FALSE) -> #N/A | V20: =VLOOKUP($B20,$S$3:$Y$9,4,FALSE) -> #N/A | W20: =VLOOKUP($B20,$S$3:$Y$9,5,FALSE) -> #N/A | X20: =VLOOKUP($B20,$S$3:$Y$9,6,FALSE) -> #N/A | Y20: =VLOOKUP($B20,$S$3:$Y$9,7,FALSE) -> #N/A | Z20: =VLOOKUP($B20,$S$3:$AA$9,8,FALSE) -> #N/A | AA20: =VLOOKUP($B20,$S$3:$AA$9,9,FALSE) -> #N/A
S21: =B21 -> 0 | T21: =VLOOKUP($B21,$S$3:$Y$9,2,FALSE) -> #N/A | U21: =VLOOKUP($B21,$S$3:$Y$9,3,FALSE) -> #N/A | V21: =VLOOKUP($B21,$S$3:$Y$9,4,FALSE) -> #N/A | W21: =VLOOKUP($B21,$S$3:$Y$9,5,FALSE) -> #N/A | X21: =VLOOKUP($B21,$S$3:$Y$9,6,FALSE) -> #N/A | Y21: =VLOOKUP($B21,$S$3:$Y$9,7,FALSE) -> #N/A | Z21: =VLOOKUP($B21,$S$3:$AA$9,8,FALSE) -> #N/A | AA21: =VLOOKUP($B21,$S$3:$AA$9,9,FALSE) -> #N/A
... S47: =B47 -> 0 | T47: =VLOOKUP($B47,$S$3:$Y$9,2,FALSE) -> #N/A | U47: =VLOOKUP($B47,$S$3:$Y$9,3,FALSE) -> #N/A | V47: =VLOOKUP($B47,$S$3:$Y$9,4,FALSE) -> #N/A | W47: =VLOOKUP($B47,$S$3:$Y$9,5,FALSE) -> #N/A | X47: =VLOOKUP($B47,$S$3:$Y$9,6,FALSE) -> #N/A | Y47: =VLOOKUP($B47,$S$3:$Y$9,7,FALSE) -> #N/A | Z47: =VLOOKUP($B47,$S$3:$AA$9,8,FALSE) -> #N/A | AA47: =VLOOKUP($B47,$S$3:$AA$9,9,FALSE) -> #N/A
I48: EXTRACT RECOVERY
B49: BRAND | D49: BBT P.G./ O.G | I49: Brand | J49: Actual | K49: MTD No. of Brews | L49: MTD | M49: YTD | N49: Target
B50: STAG | C50: 11.8 | D50: 11.73 | I50: CARIB | K50: =COUNTA([3]Brewhouse!$A$1596:$A$1619) -> 24 | L50: =AVERAGE([3]Brewhouse!$AU$1529,[3]Brewhouse!$AU$1531:$AU$1594,[3]Brewhouse!$AU$1596:$AU$1619) -> 98.205761 | M50: =AVERAGE([3]Brewhouse!$AU$849:$AU$924,[3]Brewhouse!$AU$926:$AU$971,[3]Brewhouse!$AU$973:$AU$1066,[3]Brewhouse!$AU$1068:$AU$1111,[3]Brewhouse!$AU$1113:$AU$1132,[3]Brewhouse!$AU$1134:$AU$1167,[3]Brewhouse!$AU$1169:$AU$1230,[3]Brewhouse!$AU$1232:$AU$1299,[3]Brewhouse!$AU$1301:$AU$1363,[3]Brewhouse!$AU$1365:$AU$1444,[3]Brewhouse!$AU$1446:$AU$1527,[3]Brewhouse!$AU$1529,[3]Brewhouse!$AU$1531:$AU$1594,[3]Brewhouse!$AU$1596:$AU$1619) -> 98.381806 | N50: 98
C51: 11.9 | I51: STAG | K51: =COUNTA([4]Brewhouse!$A$976:$A$1007) -> 32 | L51: =AVERAGE([4]Brewhouse!$AS$976:$AS$979,[4]Brewhouse!$AS$981:$AS$1007) -> 98.538567 | M51: =AVERAGE([4]Brewhouse!$AS$577:$AS$618,[4]Brewhouse!$AS$620:$AS$651,[4]Brewhouse!$AS$653:$AS$696,[4]Brewhouse!$AS$698:$AS$708,[4]Brewhouse!$AS$710:$AS$733,[4]Brewhouse!$AS$735:$AS$777,[4]Brewhouse!$AS$779:$AS$822,[4]Brewhouse!$AS$824:$AS$863,[4]Brewhouse!$AS$865:$AS$974,[4]Brewhouse!$AS$976:$AS$979,[4]Brewhouse!$AS$981:$AS$1007) -> 98.489671 | N51: 98
I52: GUINNESS | K52: =COUNTA([5]Brewhouse!$A$282:$A$289) -> 8 | L52: =AVERAGE([5]Brewhouse!$AU$269:$AU$279,[5]Brewhouse!$AU$282:$AU$289) -> 96.186177 | M52: =AVERAGE([5]Brewhouse!$AU$161:$AU$176,[5]Brewhouse!$AU$178:$AU$195,[5]Brewhouse!$AU$197:$AU$208,[5]Brewhouse!$AU$210:$AU$221,[5]Brewhouse!$AU$223:$AU$232,[5]Brewhouse!$AU$234:$AU$279,[5]Brewhouse!$AU$282:$AU$289) -> 96.64916 | N52: 98
I53: VITAMALT | K53: =COUNTA([6]Brewhouse!$A$158:$A$163) -> 6 | L53: =AVERAGE([6]Brewhouse!$AU$158:$AU$163) -> 94.60305 | M53: =AVERAGE([6]Brewhouse!$AU$91:$AU$101,[6]Brewhouse!$AU$103:$AU$112,[6]Brewhouse!$AU$114:$AU$123,[6]Brewhouse!$AU$125:$AU$134,[6]Brewhouse!$AU$136:$AU$145,[6]Brewhouse!$AU$147:$AU$156,[6]Brewhouse!$AU$158:$AU$163) -> 96.240014 | N53: 98
I54: MAXIMALT | N54: 98
I55: MACKESON | M55: =AVERAGE([7]Brewhouse!$AT$74:$AT$79) -> 93.959836 | N55: 98
I56: STARMALT | K56: =COUNTA([8]Brewhouse!$A$249:$A$254) -> 6 | L56: =AVERAGE([8]Brewhouse!$AY$249:$AY$254) -> 99.681996 | M56: =AVERAGE([8]Brewhouse!$AY$138:$AY$143,[8]Brewhouse!$AY$145:$AY$153,[8]Brewhouse!$AY$155,[8]Brewhouse!$AY$156:$AY$174,[8]Brewhouse!$AY$176:$AY$185,[8]Brewhouse!$AY$187:$AY$198,[8]Brewhouse!$AY$200:$AY$247,[8]Brewhouse!$AY$249:$AY$254) -> 98.774703 | N56: 98
I57: HR- P | M57: =AVERAGE([9]Brewhouse!$AW$13:$AW$14,[9]Brewhouse!$AW$16:$AW$17) -> 92.042628 | N57: 98
I58: Hurricane Reef | M58: =AVERAGE([9]Brewhouse!$AW$13:$AW$14) -> 88.376943 | N58: 98
K59: =SUM(K50:K58) -> 76 | L59: =((L50*K50)+(L51*K51)+(L52*K52)+(L53*K53)+(L54*K54)+(K57*L57)+(L55*K55)+(L56*K56)+(L58*K58))/(K59) -> 97.965422 | M59: =AVERAGE('[10]Closing- January 2023'!$L$42,'[11]Feb. 28th'!$L$42,'[12]March 31st'!$L$75,'[13]Apri 28th'!$L$51,L59) -> 98.06926 | N59: 98
J62: Daily Brewing Plan
J63: Brand | K63: Brews Achieved | L63: Average Brews per day
J64: CARIB | L64: MTD | M64: YTD | N64: TARGET
J65: STAG | K65: 5 | L65: =AVERAGE(#REF!,#REF!,K74,#REF!,#REF!,#REF!,#REF!,#REF!,#REF!,#REF!,#REF!) -> #REF! | M65: =AVERAGE(6,6,'[12]March 31st'!$L$80,'[14]June 30th '!$L$71,6,L65,'[15]July 31st'!$L$108,'[16]Aug 30th'!$L$124,7,[17]Oct.31st!$L$51) -> #REF! | N65: 9
J66: GUINN
J67: VITAMALT
...

Sheet Nov.3rd
S1: P.G. | U1: Hot Time | W1: Process Time | Y1: Cooling Time
B2: Brewing Department Daily Process Loss Report | S2: Lower | T2: Upper | U2: Lower | V2: Upper | W2: Lower | X2: Upper | Y2: Lower | Z2: Upper
R3: CARIB | S3: 11.6 | T3: 12 | U3: 0 | V3: 0.11805556 | W3: 0.22569444 | X3: 0.26388889 | Y3: 0 | Z3: 60 | AB3: HR- PISNER
B4: Date: | C4: 45965 | J4: LOT WORT COLOUR: 3.3 | M4: Filter Sheets (Target 20 days) | R4: STAG | S4: 11.6 | T4: 12 | U4: 0 | V4: 0.11805556 | W4: 0.22569444 | X4: 0.26388889 | Y4: 0 | Z4: 60
M5: Double | N5: Single | R5: GUINNESS | S5: 17 | T5: 17.5 | U5: 0 | V5: 0.10763889 | W5: 0.24652778 | X5: 0.28472222 | Y5: 0 | Z5: 60
J6: MALT LOT: Lot #4 | L6: Sheet Day | R6: MACKESON | S6: 13.3 | T6: 13.5 | U6: 0 | V6: 0.12905093 | W6: 0.27430556 | X6: 0.30208333 | Y6: 0
R7: STARMALT | S7: 17 | T7: 17.4 | U7: 0 | V7: 0.13605324 | W7: 0.27430556 | X7: 0.30902778 | Y7: 0 | Z7: 85
B8: Brand | C8: Brew no. | D8: Kett. Hls | E8: Wort | F8: Cool Time(Mins) | G8: Cast. P.G. (Lab Result) | H8: Cast P.G. (Cellar Operator)-gravity | I8: Extr. Rec (77.9%) | J8: Theor. Extr. (77.5%) | K8: Boil Off /Vol. (4-6%) | L8: Boil Time | M8: Total Hot | N8: Brewing | O8: Operator | R8: Hurricane Reef | S8: 16.6 | T8: 17 | U8: 0 | V8: 0.12905093 | W8: 0.27430556 | X8: 0.30208333 | Y8: 0
E9: Meter (Hls) | F9: Target(< 60Mins) | M9: Time | R9: VITAMALT | S9: 14.2 | T9: 14.6 | U9: 0 | V9: 0.13905093 | W9: 0.26041667 | X9: 0.29513889 | Y9: 0 | Z9: 75
B10: STARMALT | C10: =[22]Brewhouse!$A94 -> SM081 | D10: =[22]Brewhouse!$AH94 -> 53.1 | E10: =[22]Brewhouse!$AM94 -> 49.1 | F10: =[22]Brewhouse!$Z94 -> 77 | G10: =[22]Brewhouse!$AK94 -> 17.2 | H10: 17.2 | I10: =[22]Brewhouse!$AY94 -> 92.893275 | J10: =[22]Brewhouse!$AZ94 -> 93.108341 | K10: =[22]Brewhouse!$U94 -> 12.015066 | L10: =[22]Brewhouse!$T94 -> 60 | M10: =[22]Brewhouse!$Y94-[22]Brewhouse!$X94 -> 0.1375 | N10: =[22]Brewhouse!$AD94 -> 0.29305556 | O10: =[22]Brewhouse!$BC94 -> R. Regis | R10: =B10 -> STARMALT | S10: =VLOOKUP($B10,$R$3:$X$9,2,FALSE) -> 17 | T10: =VLOOKUP($B10,$R$3:$X$9,3,FALSE) -> 17.4 | U10: =VLOOKUP($B10,$R$3:$X$9,4,FALSE) -> 0 | V10: =VLOOKUP($B10,$R$3:$X$9,5,FALSE) -> 0.13605324 | W10: =VLOOKUP($B10,$R$3:$X$9,6,FALSE) -> 0.27430556 | X10: =VLOOKUP($B10,$R$3:$X$9,7,FALSE) -> 0.30902778 | Y10: =VLOOKUP($B10,$R$3:$Z$9,8,FALSE) -> 0 | Z10: =VLOOKUP($B10,$R$3:$Z$9,9,FALSE) -> 85
B11: STARMALT | C11: =[22]Brewhouse!$A95 -> SM082 | D11: =[22]Brewhouse!$AH95 -> 50 | E11: =[22]Brewhouse!$AM95 -> 51.4 | F11: =[22]Brewhouse!$Z95 -> 79 | G11: =[22]Brewhouse!$AK95 -> 17.2 | H11: 17.4 | I11: =[22]Brewhouse!$AY95 -> 97.244691 | J11: =[22]Brewhouse!$AZ95 -> 97.469832 | K11: =[22]Brewhouse!$U95 -> 4.96 | L11: =[22]Brewhouse!$T95 -> 60 | M11: =[22]Brewhouse!$Y95-[22]Brewhouse!$X95 -> 0.14097222 | N11: =[22]Brewhouse!$AD95 -> 0.30555556 | O11: =[22]Brewhouse!$BC95 -> R. Regis | R11: =B11 -> STARMALT | S11: =VLOOKUP($B11,$R$3:$X$9,2,FALSE) -> 17 | T11: =VLOOKUP($B11,$R$3:$X$9,3,FALSE) -> 17.4 | U11: =VLOOKUP($B11,$R$3:$X$9,4,FALSE) -> 0 | V11: =VLOOKUP($B11,$R$3:$X$9,5,FALSE) -> 0.13605324 | W11: =VLOOKUP($B11,$R$3:$X$9,6,FALSE) -> 0.27430556 | X11: =VLOOKUP($B11,$R$3:$X$9,7,FALSE) -> 0.30902778 | Y11: =VLOOKUP($B11,$R$3:$Z$9,8,FALSE) -> 0 | Z11: =VLOOKUP($B11,$R$3:$Z$9,9,FALSE) -> 85
B12: STARMALT | C12: =[22]Brewhouse!$A96 -> SM083 | D12: =[22]Brewhouse!$AH96 -> 53.1 | E12: =[22]Brewhouse!$AM96 -> 49.2 | F12: =[22]Brewhouse!$Z96 -> 69 | G12: =[22]Brewhouse!$AK96 -> 17.2 | H12: 17.2 | I12: =[22]Brewhouse!$AY96 -> 93.231959 | J12: =[22]Brewhouse!$AZ96 -> 93.447409 | K12: =[22]Brewhouse!$U96 -> 10.320151 | L12: =[22]Brewhouse!$T96 -> 62 | M12: =[22]Brewhouse!$Y96-[22]Brewhouse!$X96 -> 0.13402778 | N12: =[22]Brewhouse!$AD96 -> 0.28125 | O12: =[22]Brewhouse!$BC96 -> R. Regis | R12: =B12 -> STARMALT | S12: =VLOOKUP($B12,$R$3:$X$9,2,FALSE) -> 17 | T12: =VLOOKUP($B12,$R$3:$X$9,3,FALSE) -> 17.4 | U12: =VLOOKUP($B12,$R$3:$X$9,4,FALSE) -> 0 | V12: =VLOOKUP($B12,$R$3:$X$9,5,FALSE) -> 0.13605324 | W12: =VLOOKUP($B12,$R$3:$X$9,6,FALSE) -> 0.27430556 | X12: =VLOOKUP($B12,$R$3:$X$9,7,FALSE) -> 0.30902778 | Y12: =VLOOKUP($B12,$R$3:$Z$9,8,FALSE) -> 0 | Z12: =VLOOKUP($B12,$R$3:$Z$9,9,FALSE) -> 85
B13: STARMALT | C13: =[22]Brewhouse!$A97 -> SM084 | D13: =[22]Brewhouse!$AH97 -> 53.1 | E13: =[22]Brewhouse!$AM97 -> 51.6 | F13: =[22]Brewhouse!$Z97 -> 80 | G13: =[22]Brewhouse!$AK97 -> 17.2 | I13: =[22]Brewhouse!$AY97 -> 97.937147 | J13: =[22]Brewhouse!$AZ97 -> 98.16305 | K13: =[22]Brewhouse!$U97 -> 9.7551789 | L13: =[22]Brewhouse!$T97 -> 58 | M13: =[22]Brewhouse!$Y97-[22]Brewhouse!$X97 -> 0.1375 | N13: =[22]Brewhouse!$AD97 -> 0.29375 | O13: =[22]Brewhouse!$BC97 -> R.Sookram | R13: =B13 -> STARMALT | S13: =VLOOKUP($B13,$R$3:$X$9,2,FALSE) -> 17 | T13: =VLOOKUP($B13,$R$3:$X$9,3,FALSE) -> 17.4 | U13: =VLOOKUP($B13,$R$3:$X$9,4,FALSE) -> 0 | V13: =VLOOKUP($B13,$R$3:$X$9,5,FALSE) -> 0.13605324 | W13: =VLOOKUP($B13,$R$3:$X$9,6,FALSE) -> 0.27430556 | X13: =VLOOKUP($B13,$R$3:$X$9,7,FALSE) -> 0.30902778 | Y13: =VLOOKUP($B13,$R$3:$Z$9,8,FALSE) -> 0 | Z13: =VLOOKUP($B13,$R$3:$Z$9,9,FALSE) -> 85
R14: =B14 -> 0 | S14: =VLOOKUP($B14,$R$3:$X$9,2,FALSE) -> #N/A | T14: =VLOOKUP($B14,$R$3:$X$9,3,FALSE) -> #N/A | U14: =VLOOKUP($B14,$R$3:$X$9,4,FALSE) -> #N/A | V14: =VLOOKUP($B14,$R$3:$X$9,5,FALSE) -> #N/A | W14: =VLOOKUP($B14,$R$3:$X$9,6,FALSE) -> #N/A | X14: =VLOOKUP($B14,$R$3:$X$9,7,FALSE) -> #N/A | Y14: =VLOOKUP($B14,$R$3:$Z$9,8,FALSE) -> #N/A | Z14: =VLOOKUP($B14,$R$3:$Z$9,9,FALSE) -> #N/A
B15: VITAMALT | C15: =[23]Brewhouse!A97 -> VM083 | D15: =[23]Brewhouse!AE97 -> 50 | E15: =[23]Brewhouse!AJ97 -> 48 | F15: =[23]Brewhouse!X97 -> 78 | G15: =[23]Brewhouse!AH97 -> 14.1 | H15: 14.1 | I15: =[23]Brewhouse!AV97 -> 96.384143 | J15: =[23]Brewhouse!AW97 -> 96.478843 | K15: =[23]Brewhouse!S97 -> 9.12 | L15: =[23]Brewhouse!R97 -> 60 | M15: =[23]Brewhouse!$W97-[23]Brewhouse!$V97 -> 0.14652778 | N15: =[23]Brewhouse!AB97 -> 0.29097222 | O15: =[23]Brewhouse!$AZ97 -> K. Benjamin | R15: =B15 -> VITAMALT | S15: =VLOOKUP($B15,$R$3:$X$9,2,FALSE) -> 14.2 | T15: =VLOOKUP($B15,$R$3:$X$9,3,FALSE) -> 14.6 | U15: =VLOOKUP($B15,$R$3:$X$9,4,FALSE) -> 0 | V15: =VLOOKUP($B15,$R$3:$X$9,5,FALSE) -> 0.13905093 | W15: =VLOOKUP($B15,$R$3:$X$9,6,FALSE) -> 0.26041667 | X15: =VLOOKUP($B15,$R$3:$X$9,7,FALSE) -> 0.29513889 | Y15: =VLOOKUP($B15,$R$3:$Z$9,8,FALSE) -> 0 | Z15: =VLOOKUP($B15,$R$3:$Z$9,9,FALSE) -> 75
B16: VITAMALT | C16: =[23]Brewhouse!A98 -> VM084 | D16: =[23]Brewhouse!AE98 -> 50 | E16: =[23]Brewhouse!AJ98 -> 48.5 | F16: =[23]Brewhouse!X98 -> 70 | G16: =[23]Brewhouse!AH98 -> 14.3 | H16: 14.3 | I16: =[23]Brewhouse!AV98 -> 98.724258 | J16: =[23]Brewhouse!AW98 -> 98.821671 | K16: =[23]Brewhouse!S98 -> 4.92 | L16: =[23]Brewhouse!R98 -> 57 | M16: =[23]Brewhouse!$W98-[23]Brewhouse!$V98 -> 0.12777778 | N16: =[23]Brewhouse!AB98 -> 0.26944444 | O16: =[23]Brewhouse!$AZ98 -> K. Benjamin | R16: =B16 -> VITAMALT | S16: =VLOOKUP($B16,$R$3:$X$9,2,FALSE) -> 14.2 | T16: =VLOOKUP($B16,$R$3:$X$9,3,FALSE) -> 14.6 | U16: =VLOOKUP($B16,$R$3:$X$9,4,FALSE) -> 0 | V16: =VLOOKUP($B16,$R$3:$X$9,5,FALSE) -> 0.13905093 | W16: =VLOOKUP($B16,$R$3:$X$9,6,FALSE) -> 0.26041667 | X16: =VLOOKUP($B16,$R$3:$X$9,7,FALSE) -> 0.29513889 | Y16: =VLOOKUP($B16,$R$3:$Z$9,8,FALSE) -> 0 | Z16: =VLOOKUP($B16,$R$3:$Z$9,9,FALSE) -> 75
R17: =B17 -> 0 | S17: =VLOOKUP($B17,$R$3:$X$9,2,FALSE) -> #N/A | T17: =VLOOKUP($B17,$R$3:$X$9,3,FALSE) -> #N/A | U17: =VLOOKUP($B17,$R$3:$X$9,4,FALSE) -> #N/A | V17: =VLOOKUP($B17,$R$3:$X$9,5,FALSE) -> #N/A | W17: =VLOOKUP($B17,$R$3:$X$9,6,FALSE) -> #N/A | X17: =VLOOKUP($B17,$R$3:$X$9,7,FALSE) -> #N/A | Y17: =VLOOKUP($B17,$R$3:$Z$9,8,FALSE) -> #N/A | Z17: =VLOOKUP($B17,$R$3:$Z$9,9,FALSE) -> #N/A
R18: =B18 -> 0 | S18: =VLOOKUP($B18,$R$3:$X$9,2,FALSE) -> #N/A | T18: =VLOOKUP($B18,$R$3:$X$9,3,FALSE) -> #N/A | U18: =VLOOKUP($B18,$R$3:$X$9,4,FALSE) -> #N/A | V18: =VLOOKUP($B18,$R$3:$X$9,5,FALSE) -> #N/A | W18: =VLOOKUP($B18,$R$3:$X$9,6,FALSE) -> #N/A | X18: =VLOOKUP($B18,$R$3:$X$9,7,FALSE) -> #N/A | Y18: =VLOOKUP($B18,$R$3:$Z$9,8,FALSE) -> #N/A | Z18: =VLOOKUP($B18,$R$3:$Z$9,9,FALSE) -> #N/A
R19: =B19 -> 0 | S19: =VLOOKUP($B19,$R$3:$X$9,2,FALSE) -> #N/A | T19: =VLOOKUP($B19,$R$3:$X$9,3,FALSE) -> #N/A | U19: =VLOOKUP($B19,$R$3:$X$9,4,FALSE) -> #N/A | V19: =VLOOKUP($B19,$R$3:$X$9,5,FALSE) -> #N/A | W19: =VLOOKUP($B19,$R$3:$X$9,6,FALSE) -> #N/A | X19: =VLOOKUP($B19,$R$3:$X$9,7,FALSE) -> #N/A | Y19: =VLOOKUP($B19,$R$3:$Z$9,8,FALSE) -> #N/A | Z19: =VLOOKUP($B19,$R$3:$Z$9,9,FALSE) -> #N/A
R20: =B20 -> 0 | S20: =VLOOKUP($B20,$R$3:$X$9,2,FALSE) -> #N/A | T20: =VLOOKUP($B20,$R$3:$X$9,3,FALSE) -> #N/A | U20: =VLOOKUP($B20,$R$3:$X$9,4,FALSE) -> #N/A | V20: =VLOOKUP($B20,$R$3:$X$9,5,FALSE) -> #N/A | W20: =VLOOKUP($B20,$R$3:$X$9,6,FALSE) -> #N/A | X20: =VLOOKUP($B20,$R$3:$X$9,7,FALSE) -> #N/A | Y20: =VLOOKUP($B20,$R$3:$Z$9,8,FALSE) -> #N/A | Z20: =VLOOKUP($B20,$R$3:$Z$9,9,FALSE) -> #N/A
R21: =B21 -> 0 | S21: =VLOOKUP($B21,$R$3:$X$9,2,FALSE) -> #N/A | T21: =VLOOKUP($B21,$R$3:$X$9,3,FALSE) -> #N/A | U21: =VLOOKUP($B21,$R$3:$X$9,4,FALSE) -> #N/A | V21: =VLOOKUP($B21,$R$3:$X$9,5,FALSE) -> #N/A | W21: =VLOOKUP($B21,$R$3:$X$9,6,FALSE) -> #N/A | X21: =VLOOKUP($B21,$R$3:$X$9,7,FALSE) -> #N/A | Y21: =VLOOKUP($B21,$R$3:$Z$9,8,FALSE) -> #N/A | Z21: =VLOOKUP($B21,$R$3:$Z$9,9,FALSE) -> #N/A
R22: =B22 -> 0 | S22: =VLOOKUP($B22,$R$3:$X$9,2,FALSE) -> #N/A | T22: =VLOOKUP($B22,$R$3:$X$9,3,FALSE) -> #N/A | U22: =VLOOKUP($B22,$R$3:$X$9,4,FALSE) -> #N/A | V22: =VLOOKUP($B22,$R$3:$X$9,5,FALSE) -> #N/A | W22: =VLOOKUP($B22,$R$3:$X$9,6,FALSE) -> #N/A | X22: =VLOOKUP($B22,$R$3:$X$9,7,FALSE) -> #N/A | Y22: =VLOOKUP($B22,$R$3:$Z$9,8,FALSE) -> #N/A | Z22: =VLOOKUP($B22,$R$3:$Z$9,9,FALSE) -> #N/A
R23: =B23 -> 0 | S23: =VLOOKUP($B23,$R$3:$X$9,2,FALSE) -> #N/A | T23: =VLOOKUP($B23,$R$3:$X$9,3,FALSE) -> #N/A | U23: =VLOOKUP($B23,$R$3:$X$9,4,FALSE) -> #N/A | V23: =VLOOKUP($B23,$R$3:$X$9,5,FALSE) -> #N/A | W23: =VLOOKUP($B23,$R$3:$X$9,6,FALSE) -> #N/A | X23: =VLOOKUP($B23,$R$3:$X$9,7,FALSE) -> #N/A | Y23: =VLOOKUP($B23,$R$3:$Z$9,8,FALSE) -> #N/A | Z23: =VLOOKUP($B23,$R$3:$Z$9,9,FALSE) -> #N/A
R24: =B24 -> 0 | S24: =VLOOKUP($B24,$R$3:$X$9,2,FALSE) -> #N/A | T24: =VLOOKUP($B24,$R$3:$X$9,3,FALSE) -> #N/A | U24: =VLOOKUP($B24,$R$3:$X$9,4,FALSE) -> #N/A | V24: =VLOOKUP($B24,$R$3:$X$9,5,FALSE) -> #N/A | W24: =VLOOKUP($B24,$R$3:$X$9,6,FALSE) -> #N/A | X24: =VLOOKUP($B24,$R$3:$X$9,7,FALSE) -> #N/A | Y24: =VLOOKUP($B24,$R$3:$Z$9,8,FALSE) -> #N/A | Z24: =VLOOKUP($B24,$R$3:$Z$9,9,FALSE) -> #N/A
R25: =B25 -> 0 | S25: =VLOOKUP($B25,$R$3:$X$9,2,FALSE) -> #N/A | T25: =VLOOKUP($B25,$R$3:$X$9,3,FALSE) -> #N/A | U25: =VLOOKUP($B25,$R$3:$X$9,4,FALSE) -> #N/A | V25: =VLOOKUP($B25,$R$3:$X$9,5,FALSE) -> #N/A | W25: =VLOOKUP($B25,$R$3:$X$9,6,FALSE) -> #N/A | X25: =VLOOKUP($B25,$R$3:$X$9,7,FALSE) -> #N/A | Y25: =VLOOKUP($B25,$R$3:$Z$9,8,FALSE) -> #N/A | Z25: =VLOOKUP($B25,$R$3:$Z$9,9,FALSE) -> #N/A
R26: =B26 -> 0 | S26: =VLOOKUP($B26,$R$3:$X$9,2,FALSE) -> #N/A | T26: =VLOOKUP($B26,$R$3:$X$9,3,FALSE) -> #N/A | U26: =VLOOKUP($B26,$R$3:$X$9,4,FALSE) -> #N/A | V26: =VLOOKUP($B26,$R$3:$X$9,5,FALSE) -> #N/A | W26: =VLOOKUP($B26,$R$3:$X$9,6,FALSE) -> #N/A | X26: =VLOOKUP($B26,$R$3:$X$9,7,FALSE) -> #N/A | Y26: =VLOOKUP($B26,$R$3:$Z$9,8,FALSE) -> #N/A | Z26: =VLOOKUP($B26,$R$3:$Z$9,9,FALSE) -> #N/A
B27: BRAND | D27: BBT P.G./ O.G | I27: Brand | K27: MTD No. of Brews | L27: MTD | M27: YTD | N27: Target | R27: =B27 -> BRAND | S27: =VLOOKUP($B27,$R$3:$X$9,2,FALSE) -> #N/A | T27: =VLOOKUP($B27,$R$3:$X$9,3,FALSE) -> #N/A | U27: =VLOOKUP($B27,$R$3:$X$9,4,FALSE) -> #N/A | V27: =VLOOKUP($B27,$R$3:$X$9,5,FALSE) -> #N/A | W27: =VLOOKUP($B27,$R$3:$X$9,6,FALSE) -> #N/A | X27: =VLOOKUP($B27,$R$3:$X$9,7,FALSE) -> #N/A | Y27: =VLOOKUP($B27,$R$3:$Z$9,8,FALSE) -> #N/A | Z27: =VLOOKUP($B27,$R$3:$Z$9,9,FALSE) -> #N/A
B28: =I28 -> CARIB | C28: {=[24]Process!$D$839:$D$846} -> 11.9 | D28: 11.87 | I28: CARIB | M28: =AVERAGE([24]Brewhouse!$AU$102:$AU$171,[24]Brewhouse!$AU$173:$AU$253,[24]Brewhouse!$AU$255:$AU$339,[24]Brewhouse!$AU$341:$AU$346,[24]Brewhouse!$AU$348,[24]Brewhouse!$AU$349:$AU$406,[24]Brewhouse!$AU$408:$AU$491,[24]Brewhouse!$AU$493:$AU$578,[24]Brewhouse!$AU$580:$AU$652,[24]Brewhouse!$AU$655:$AU$738,[24]Brewhouse!$A$740:$A$821,[24]Brewhouse!$AU$823:$AU$862,[25]Brewhouse!$AS$420:$AS$423,[24]Brewhouse!$AU$867:$AU$908) -> 97.713914 | N28: 98 | R28: =B28 -> CARIB | S28: =VLOOKUP($B28,$R$3:$X$9,2,FALSE) -> 11.6 | T28: =VLOOKUP($B28,$R$3:$X$9,3,FALSE) -> 12 | U28: =VLOOKUP($B28,$R$3:$X$9,4,FALSE) -> 0 | V28: =VLOOKUP($B28,$R$3:$X$9,5,FALSE) -> 0.11805556 | W28: =VLOOKUP($B28,$R$3:$X$9,6,FALSE) -> 0.22569444 | X28: =VLOOKUP($B28,$R$3:$X$9,7,FALSE) -> 0.26388889 | Y28: =VLOOKUP($B28,$R$3:$Z$9,8,FALSE) -> 0 | Z28: =VLOOKUP($B28,$R$3:$Z$9,9,FALSE) -> 60
C29: 11.6 | I29: STAG | M29: =AVERAGE([25]Brewhouse!$AS$15:$AS$64,[25]Brewhouse!$AS$66:$AS$103,[25]Brewhouse!$AS$105:$AS$140,[25]Brewhouse!$AS$142:$AS$193,[25]Brewhouse!$AS$195:$AS$240,[25]Brewhouse!$AS$242:$AS$273,[25]Brewhouse!$AS$275:$AS$322,[25]Brewhouse!$AS$324:$AS$359,[25]Brewhouse!$AS$361:$AS$397,[25]Brewhouse!$AS$399:$AS$443) -> 97.924881 | N29: 98 | R29: =B29 -> 0 | S29: =VLOOKUP($B29,$R$3:$X$9,2,FALSE) -> #N/A | T29: =VLOOKUP($B29,$R$3:$X$9,3,FALSE) -> #N/A | U29: =VLOOKUP($B29,$R$3:$X$9,4,FALSE) -> #N/A | V29: =VLOOKUP($B29,$R$3:$X$9,5,FALSE) -> #N/A | W29: =VLOOKUP($B29,$R$3:$X$9,6,FALSE) -> #N/A | X29: =VLOOKUP($B29,$R$3:$X$9,7,FALSE) -> #N/A | Y29: =VLOOKUP($B29,$R$3:$Z$9,8,FALSE) -> #N/A | Z29: =VLOOKUP($B29,$R$3:$Z$9,9,FALSE) -> #N/A
C30: 11.6 | D30: 11.75 | I30: GUINNESS | M30: =AVERAGE([26]Brewhouse!$AU$4:$AU$7,[26]Brewhouse!$AU$9:$AU$22,[26]Brewhouse!$AU$24:$AU$35,[26]Brewhouse!$AU$37:$AU$45,[26]Brewhouse!$AU$47:$AU$62,[26]Brewhouse!$AU$64:$AU$79,[26]Brewhouse!$AU$81:$AU$92,[26]Brewhouse!$AU$94:$AU$97,[26]Brewhouse!$AU$99:$AU$106) -> 96.648781 | N30: 98 | R30: =B30 -> 0 | S30: =VLOOKUP($B30,$R$3:$X$9,2,FALSE) -> #N/A | T30: =VLOOKUP($B30,$R$3:$X$9,3,FALSE) -> #N/A | U30: =VLOOKUP($B30,$R$3:$X$9,4,FALSE) -> #N/A | V30: =VLOOKUP($B30,$R$3:$X$9,5,FALSE) -> #N/A | W30: =VLOOKUP($B30,$R$3:$X$9,6,FALSE) -> #N/A | X30: =VLOOKUP($B30,$R$3:$X$9,7,FALSE) -> #N/A | Y30: =VLOOKUP($B30,$R$3:$Z$9,8,FALSE) -> #N/A | Z30: =VLOOKUP($B30,$R$3:$Z$9,9,FALSE) -> #N/A
C31: 11.9 | I31: VITAMALT | J31: =AVERAGE(I15:I16) -> 97.5542 | K31: =COUNTA([23]Brewhouse!$A$97:$A$98) -> 2 | L31: =AVERAGE([23]Brewhouse!$AV$97:$AV$98) -> 97.5542 | M31: =AVERAGE([23]Brewhouse!$AV$5:$AV$14,[23]Brewhouse!$AV$16:$AV$19,[23]Brewhouse!$AV$21:$AV$24,[23]Brewhouse!$AV$26:$AV$33,[23]Brewhouse!$AV$35:$AV$46,[23]Brewhouse!$AV$48:$AV$53,[23]Brewhouse!$AV$55:$AV$62,[23]Brewhouse!$AV$64:$AV$77,[23]Brewhouse!$AV$79:$AV$86,[23]Brewhouse!$AV$88:$AV$95,[23]Brewhouse!$AV$97:$AV$98) -> 98.239162 | N31: 98 | R31: =B31 -> 0 | S31: =VLOOKUP($B31,$R$3:$X$9,2,FALSE) -> #N/A | T31: =VLOOKUP($B31,$R$3:$X$9,3,FALSE) -> #N/A | U31: =VLOOKUP($B31,$R$3:$X$9,4,FALSE) -> #N/A | V31: =VLOOKUP($B31,$R$3:$X$9,5,FALSE) -> #N/A | W31: =VLOOKUP($B31,$R$3:$X$9,6,FALSE) -> #N/A | X31: =VLOOKUP($B31,$R$3:$X$9,7,FALSE) -> #N/A | Y31: =VLOOKUP($B31,$R$3:$Z$9,8,FALSE) -> #N/A | Z31: =VLOOKUP($B31,$R$3:$Z$9,9,FALSE) -> #N/A
C32: 11.8 | D32: 11.88 | I32: MAXIMALT | N32: 98 | R32: =B32 -> 0 | S32: =VLOOKUP($B32,$R$3:$X$9,2,FALSE) -> #N/A | T32: =VLOOKUP($B32,$R$3:$X$9,3,FALSE) -> #N/A | U32: =VLOOKUP($B32,$R$3:$X$9,4,FALSE) -> #N/A | V32: =VLOOKUP($B32,$R$3:$X$9,5,FALSE) -> #N/A | W32: =VLOOKUP($B32,$R$3:$X$9,6,FALSE) -> #N/A | X32: =VLOOKUP($B32,$R$3:$X$9,7,FALSE) -> #N/A | Y32: =VLOOKUP($B32,$R$3:$Z$9,8,FALSE) -> #N/A | Z32: =VLOOKUP($B32,$R$3:$Z$9,9,FALSE) -> #N/A
C33: 11.7 | I33: MACKESON | M33: =AVERAGE([27]Brewhouse!$AT$4:$AT$11,[27]Brewhouse!$AT$13:$AT$16,[27]Brewhouse!$AT$18:$AT$21,[27]Brewhouse!$AT$26,[27]Brewhouse!$AT$28:$AT$35) -> 94.794664 | N33: 98 | R33: =B33 -> 0 | S33: =VLOOKUP($B33,$R$3:$X$9,2,FALSE) -> #N/A | T33: =VLOOKUP($B33,$R$3:$X$9,3,FALSE) -> #N/A | U33: =VLOOKUP($B33,$R$3:$X$9,4,FALSE) -> #N/A | V33: =VLOOKUP($B33,$R$3:$X$9,5,FALSE) -> #N/A | W33: =VLOOKUP($B33,$R$3:$X$9,6,FALSE) -> #N/A | X33: =VLOOKUP($B33,$R$3:$X$9,7,FALSE) -> #N/A | Y33: =VLOOKUP($B33,$R$3:$Z$9,8,FALSE) -> #N/A | Z33: =VLOOKUP($B33,$R$3:$Z$9,9,FALSE) -> #N/A
C34: 11.6 | D34: 12 | I34: STARMALT | J34: =AVERAGE(I10:I13) -> 95.326768 | K34: =COUNTA([22]Brewhouse!$A$94:$A$97) -> 4 | L34: =AVERAGE([22]Brewhouse!$AY$94:$AY$97) -> 95.326768 | M34: =AVERAGE([22]Brewhouse!$AY$6:$AY$13,[22]Brewhouse!$AY$15:$AY$20,[22]Brewhouse!$AY$22:$AY$29,[22]Brewhouse!$AY$31:$AY$34,[22]Brewhouse!$AY$36:$AY$43,[22]Brewhouse!$AY$45:$AY$50, [22]Brewhouse!$AY$56:$AY$73,[22]Brewhouse!$AY$75:$AY$92,[22]Brewhouse!$AY$94:$AY$97) -> 97.370193 | N34: 98 | R34: =B34 -> 0 | S34: =VLOOKUP($B34,$R$3:$X$9,2,FALSE) -> #N/A | T34: =VLOOKUP($B34,$R$3:$X$9,3,FALSE) -> #N/A | U34: =VLOOKUP($B34,$R$3:$X$9,4,FALSE) -> #N/A | V34: =VLOOKUP($B34,$R$3:$X$9,5,FALSE) -> #N/A | W34: =VLOOKUP($B34,$R$3:$X$9,6,FALSE) -> #N/A | X34: =VLOOKUP($B34,$R$3:$X$9,7,FALSE) -> #N/A | Y34: =VLOOKUP($B34,$R$3:$Z$9,8,FALSE) -> #N/A | Z34: =VLOOKUP($B34,$R$3:$Z$9,9,FALSE) -> #N/A
C35: 11.9 | I35: HR- Pils | M35: =AVERAGE([28]Brewhouse!$AU$5:$AU$8,[28]Brewhouse!$AU$10:$AU$13,[22]Brewhouse!$AY$75:$AY$77) -> 94.749192 | N35: 98 | R35: =B35 -> 0 | S35: =VLOOKUP($B35,$R$3:$X$9,2,FALSE) -> #N/A | T35: =VLOOKUP($B35,$R$3:$X$9,3,FALSE) -> #N/A | U35: =VLOOKUP($B35,$R$3:$X$9,4,FALSE) -> #N/A | V35: =VLOOKUP($B35,$R$3:$X$9,5,FALSE) -> #N/A | W35: =VLOOKUP($B35,$R$3:$X$9,6,FALSE) -> #N/A | X35: =VLOOKUP($B35,$R$3:$X$9,7,FALSE) -> #N/A | Y35: =VLOOKUP($B35,$R$3:$Z$9,8,FALSE) -> #N/A | Z35: =VLOOKUP($B35,$R$3:$Z$9,9,FALSE) -> #N/A
C36: {=[24]Process!$D$863:$D$864} -> 11.7 | D36: 11.97 | I36: HR- IPA | M36: =AVERAGE([29]Brewhouse!$AW$26:$AW$27) -> 95.310681 | N36: 98 | R36: =B36 -> 0 | S36: =VLOOKUP($B36,$R$3:$X$9,2,FALSE) -> #N/A | T36: =VLOOKUP($B36,$R$3:$X$9,3,FALSE) -> #N/A | U36: =VLOOKUP($B36,$R$3:$X$9,4,FALSE) -> #N/A | V36: =VLOOKUP($B36,$R$3:$X$9,5,FALSE) -> #N/A | W36: =VLOOKUP($B36,$R$3:$X$9,6,FALSE) -> #N/A | X36: =VLOOKUP($B36,$R$3:$X$9,7,FALSE) -> #N/A | Y36: =VLOOKUP($B36,$R$3:$Z$9,8,FALSE) -> #N/A | Z36: =VLOOKUP($B36,$R$3:$Z$9,9,FALSE) -> #N/A
C37: 11.9 | I37: HR- APA | M37: =AVERAGE([30]Brewhouse!$AU$13:$AU$14) -> 97.110575 | N37: 98 | R37: =B37 -> 0 | S37: =VLOOKUP($B37,$R$3:$X$9,2,FALSE) -> #N/A | T37: =VLOOKUP($B37,$R$3:$X$9,3,FALSE) -> #N/A | U37: =VLOOKUP($B37,$R$3:$X$9,4,FALSE) -> #N/A | V37: =VLOOKUP($B37,$R$3:$X$9,5,FALSE) -> #N/A | W37: =VLOOKUP($B37,$R$3:$X$9,6,FALSE) -> #N/A | X37: =VLOOKUP($B37,$R$3:$X$9,7,FALSE) -> #N/A | Y37: =VLOOKUP($B37,$R$3:$Z$9,8,FALSE) -> #N/A | Z37: =VLOOKUP($B37,$R$3:$Z$9,9,FALSE) -> #N/A
K38: =SUM(K28:K37) -> 6 | L38: =((L28*K28)+(L29*K29)+(L30*K30)+(L31*K31)+(L32*K32)+(K35*L35)+(L33*K33)+(L34*K34)+(L37*K37))/(K38) -> 96.069245 | M38: =AVERAGE('[31]Jan 31st'!$L$65,'[32]Feb 28th'!$L$35,'[33]Mar. 31st'!$L$35,'[34]Apr. 30th'!$L$45,'[35]May 30th'!$L$37,'[36]June 30th'!$L$57,'[37]July 29th '!$L$44,'[38]Aug 29th'!$L$29,'[39]Sept 30th'!$L$35,L38) -> 97.424875 | N38: 98 | R38: =B38 -> 0 | S38: =VLOOKUP($B38,$R$3:$X$9,2,FALSE) -> #N/A | T38: =VLOOKUP($B38,$R$3:$X$9,3,FALSE) -> #N/A | U38: =VLOOKUP($B38,$R$3:$X$9,4,FALSE) -> #N/A | V38: =VLOOKUP($B38,$R$3:$X$9,5,FALSE) -> #N/A | W38: =VLOOKUP($B38,$R$3:$X$9,6,FALSE) -> #N/A | X38: =VLOOKUP($B38,$R$3:$X$9,7,FALSE) -> #N/A | Y38: =VLOOKUP($B38,$R$3:$Z$9,8,FALSE) -> #N/A | Z38: =VLOOKUP($B38,$R$3:$Z$9,9,FALSE) -> #N/A
R39: =B39 -> 0 | S39: =VLOOKUP($B39,$R$3:$X$9,2,FALSE) -> #N/A | T39: =VLOOKUP($B39,$R$3:$X$9,3,FALSE) -> #N/A | U39: =VLOOKUP($B39,$R$3:$X$9,4,FALSE) -> #N/A | V39: =VLOOKUP($B39,$R$3:$X$9,5,FALSE) -> #N/A | W39: =VLOOKUP($B39,$R$3:$X$9,6,FALSE) -> #N/A | X39: =VLOOKUP($B39,$R$3:$X$9,7,FALSE) -> #N/A | Y39: =VLOOKUP($B39,$R$3:$Z$9,8,FALSE) -> #N/A | Z39: =VLOOKUP($B39,$R$3:$Z$9,9,FALSE) -> #N/A
J40: Daily Brewing Plan
...

Sheet Nov 4th
S1: P.G. | U1: Hot Time | W1: Process Time | Y1: Cooling Time
B2: Brewing Department Daily Process Loss Report | S2: Lower | T2: Upper | U2: Lower | V2: Upper | W2: Lower | X2: Upper | Y2: Lower | Z2: Upper
R3: CARIB | S3: 11.6 | T3: 12 | U3: 0 | V3: 0.11805556 | W3: 0.22569444 | X3: 0.26388889 | Y3: 0 | Z3: 60 | AB3: HR- PISNER
B4: Date: | C4: 45966 | J4: LOT WORT COLOUR: 3.3 | M4: Filter Sheets (Target 20 days) | R4: STAG | S4: 11.6 | T4: 12 | U4: 0 | V4: 0.11805556 | W4: 0.22569444 | X4: 0.26388889 | Y4: 0 | Z4: 60
M5: Double | N5: Single | R5: GUINNESS | S5: 17 | T5: 17.5 | U5: 0 | V5: 0.10763889 | W5: 0.24652778 | X5: 0.28472222 | Y5: 0 | Z5: 60
J6: MALT LOT: Lot #4 | L6: Sheet Day | R6: MACKESON | S6: 13.3 | T6: 13.5 | U6: 0 | V6: 0.12905093 | W6: 0.27430556 | X6: 0.30208333 | Y6: 0
R7: STARMALT | S7: 17 | T7: 17.4 | U7: 0 | V7: 0.13605324 | W7: 0.27430556 | X7: 0.30902778 | Y7: 0 | Z7: 85
B8: Brand | C8: Brew no. | D8: Kett. Hls | E8: Wort | F8: Cool Time(Mins) | G8: Cast. P.G. (Lab Result) | H8: Cast P.G. (Cellar Operator)-gravity | I8: Extr. Rec (77.9%) | J8: Theor. Extr. (77.5%) | K8: Boil Off /Vol. (4-6%) | L8: Boil Time | M8: Total Hot | N8: Brewing | O8: Operator | R8: Hurricane Reef | S8: 16.6 | T8: 17 | U8: 0 | V8: 0.12905093 | W8: 0.27430556 | X8: 0.30208333 | Y8: 0
E9: Meter (Hls) | F9: Target(< 60Mins) | M9: Time | R9: VITAMALT | S9: 14.2 | T9: 14.6 | U9: 0 | V9: 0.13905093 | W9: 0.26041667 | X9: 0.29513889 | Y9: 0 | Z9: 75
B10: VITAMALT | C10: =[23]Brewhouse!A99 -> VM085 | D10: =[23]Brewhouse!AE99 -> 50 | E10: =[23]Brewhouse!AJ99 -> 47.7 | F10: =[23]Brewhouse!X99 -> 77 | G10: =[23]Brewhouse!AH99 -> 14.3 | H10: 14.3 | I10: =[23]Brewhouse!AV99 -> 97.19787 | J10: =[23]Brewhouse!AW99 -> 97.293369 | K10: =[23]Brewhouse!S99 -> 2.52 | L10: =[23]Brewhouse!R99 -> 57 | M10: =[23]Brewhouse!$W99-[23]Brewhouse!$V99 -> 0.14236111 | N10: =[23]Brewhouse!AB99 -> 0.28333333 | O10: =[23]Brewhouse!$AZ99 -> K. Benjamin | R10: =B10 -> VITAMALT | S10: =VLOOKUP($B10,$R$3:$X$9,2,FALSE) -> 14.2 | T10: =VLOOKUP($B10,$R$3:$X$9,3,FALSE) -> 14.6 | U10: =VLOOKUP($B10,$R$3:$X$9,4,FALSE) -> 0 | V10: =VLOOKUP($B10,$R$3:$X$9,5,FALSE) -> 0.13905093 | W10: =VLOOKUP($B10,$R$3:$X$9,6,FALSE) -> 0.26041667 | X10: =VLOOKUP($B10,$R$3:$X$9,7,FALSE) -> 0.29513889 | Y10: =VLOOKUP($B10,$R$3:$Z$9,8,FALSE) -> 0 | Z10: =VLOOKUP($B10,$R$3:$Z$9,9,FALSE) -> 75
B11: VITAMALT | C11: =[23]Brewhouse!A100 -> VM086 | D11: =[23]Brewhouse!AE100 -> 50.1 | E11: =[23]Brewhouse!AJ100 -> 47.4 | F11: =[23]Brewhouse!X100 -> 74 | G11: =[23]Brewhouse!AH100 -> 14.6 | H11: 14.5 | I11: =[23]Brewhouse!AV100 -> 98.865272 | J11: =[23]Brewhouse!AW100 -> 98.961994 | K11: =[23]Brewhouse!S100 -> 15.688623 | L11: =[23]Brewhouse!R100 -> 61 | M11: =[23]Brewhouse!$W100-[23]Brewhouse!$V100 -> 0.14791667 | N11: =[23]Brewhouse!AB100 -> 0.33680556 | O11: =[23]Brewhouse!$AZ100 -> R. Regis | R11: =B11 -> VITAMALT | S11: =VLOOKUP($B11,$R$3:$X$9,2,FALSE) -> 14.2 | T11: =VLOOKUP($B11,$R$3:$X$9,3,FALSE) -> 14.6 | U11: =VLOOKUP($B11,$R$3:$X$9,4,FALSE) -> 0 | V11: =VLOOKUP($B11,$R$3:$X$9,5,FALSE) -> 0.13905093 | W11: =VLOOKUP($B11,$R$3:$X$9,6,FALSE) -> 0.26041667 | X11: =VLOOKUP($B11,$R$3:$X$9,7,FALSE) -> 0.29513889 | Y11: =VLOOKUP($B11,$R$3:$Z$9,8,FALSE) -> 0 | Z11: =VLOOKUP($B11,$R$3:$Z$9,9,FALSE) -> 75
B12: VITAMALT | C12: =[23]Brewhouse!A101 -> VM087 | D12: =[23]Brewhouse!AE101 -> 50.1 | E12: =[23]Brewhouse!AJ101 -> 47.4 | F12: =[23]Brewhouse!X101 -> 84 | G12: =[23]Brewhouse!AH101 -> 14.5 | H12: 14 | I12: =[23]Brewhouse!AV101 -> 97.852052 | J12: =[23]Brewhouse!AW101 -> 97.949014 | K12: =[23]Brewhouse!S101 -> 6.3073852 | L12: =[23]Brewhouse!R101 -> 61 | M12: =[23]Brewhouse!$W101-[23]Brewhouse!$V101 -> 0.13680556 | N12: =[23]Brewhouse!AB101 -> 0.35 | O12: =[23]Brewhouse!$AZ101 -> R. Regis | R12: =B12 -> VITAMALT | S12: =VLOOKUP($B12,$R$3:$X$9,2,FALSE) -> 14.2 | T12: =VLOOKUP($B12,$R$3:$X$9,3,FALSE) -> 14.6 | U12: =VLOOKUP($B12,$R$3:$X$9,4,FALSE) -> 0 | V12: =VLOOKUP($B12,$R$3:$X$9,5,FALSE) -> 0.13905093 | W12: =VLOOKUP($B12,$R$3:$X$9,6,FALSE) -> 0.26041667 | X12: =VLOOKUP($B12,$R$3:$X$9,7,FALSE) -> 0.29513889 | Y12: =VLOOKUP($B12,$R$3:$Z$9,8,FALSE) -> 0 | Z12: =VLOOKUP($B12,$R$3:$Z$9,9,FALSE) -> 75
B13: VITAMALT | C13: =[23]Brewhouse!A102 -> VM088 | D13: =[23]Brewhouse!AE102 -> 50.1 | E13: =[23]Brewhouse!AJ102 -> 50.8 | F13: =[23]Brewhouse!X102 -> 92 | G13: =[23]Brewhouse!AH102 -> 14.2 | H13: 14.3 | I13: =[23]Brewhouse!AV102 -> 101.48069 | J13: =[23]Brewhouse!AW102 -> 101.58544 | K13: =[23]Brewhouse!S102 -> 5.9081836 | L13: =[23]Brewhouse!R102 -> 60 | M13: =[23]Brewhouse!$W102-[23]Brewhouse!$V102 -> 0.14236111 | N13: =[23]Brewhouse!AB102 -> 0.29375 | O13: =[23]Brewhouse!$AZ102 -> R. Regis | R13: =B13 -> VITAMALT | S13: =VLOOKUP($B13,$R$3:$X$9,2,FALSE) -> 14.2 | T13: =VLOOKUP($B13,$R$3:$X$9,3,FALSE) -> 14.6 | U13: =VLOOKUP($B13,$R$3:$X$9,4,FALSE) -> 0 | V13: =VLOOKUP($B13,$R$3:$X$9,5,FALSE) -> 0.13905093 | W13: =VLOOKUP($B13,$R$3:$X$9,6,FALSE) -> 0.26041667 | X13: =VLOOKUP($B13,$R$3:$X$9,7,FALSE) -> 0.29513889 | Y13: =VLOOKUP($B13,$R$3:$Z$9,8,FALSE) -> 0 | Z13: =VLOOKUP($B13,$R$3:$Z$9,9,FALSE) -> 75
B14: VITAMALT | C14: =[23]Brewhouse!A103 -> VM089 | D14: =[23]Brewhouse!AE103 -> 50.1 | E14: =[23]Brewhouse!AJ103 -> 50.8 | F14: =[23]Brewhouse!X103 -> 89 | G14: =[23]Brewhouse!AH103 -> 14.1 | H14: 14.2 | I14: =[23]Brewhouse!AV103 -> 101.36729 | J14: =[23]Brewhouse!AW103 -> 101.46943 | K14: =[23]Brewhouse!S103 -> 5.3093812 | L14: =[23]Brewhouse!R103 -> 58 | M14: =[23]Brewhouse!$W103-[23]Brewhouse!$V103 -> 0.13819444 | N14: =[23]Brewhouse!AB103 -> 0.27083333 | O14: =[23]Brewhouse!$AZ103 -> R.Sookram | R14: =B14 -> VITAMALT | S14: =VLOOKUP($B14,$R$3:$X$9,2,FALSE) -> 14.2 | T14: =VLOOKUP($B14,$R$3:$X$9,3,FALSE) -> 14.6 | U14: =VLOOKUP($B14,$R$3:$X$9,4,FALSE) -> 0 | V14: =VLOOKUP($B14,$R$3:$X$9,5,FALSE) -> 0.13905093 | W14: =VLOOKUP($B14,$R$3:$X$9,6,FALSE) -> 0.26041667 | X14: =VLOOKUP($B14,$R$3:$X$9,7,FALSE) -> 0.29513889 | Y14: =VLOOKUP($B14,$R$3:$Z$9,8,FALSE) -> 0 | Z14: =VLOOKUP($B14,$R$3:$Z$9,9,FALSE) -> 75
B15: VITAMALT | C15: =[23]Brewhouse!A104 -> VM090 | D15: =[23]Brewhouse!AE104 -> 53.1 | E15: =[23]Brewhouse!AJ104 -> 47.4 | F15: =[23]Brewhouse!X104 -> 84 | G15: =[23]Brewhouse!AH104 -> 14.2 | H15: 14.3 | I15: =[23]Brewhouse!AV104 -> 95.481526 | J15: =[23]Brewhouse!AW104 -> 95.576936 | K15: =[23]Brewhouse!S104 -> 13.107345 | L15: =[23]Brewhouse!R104 -> 58 | M15: =[23]Brewhouse!$W104-[23]Brewhouse!$V104 -> 0.13402778 | N15: =[23]Brewhouse!AB104 -> 0.26527778 | O15: =[23]Brewhouse!$AZ104 -> R.Sookram | R15: =B15 -> VITAMALT | S15: =VLOOKUP($B15,$R$3:$X$9,2,FALSE) -> 14.2 | T15: =VLOOKUP($B15,$R$3:$X$9,3,FALSE) -> 14.6 | U15: =VLOOKUP($B15,$R$3:$X$9,4,FALSE) -> 0 | V15: =VLOOKUP($B15,$R$3:$X$9,5,FALSE) -> 0.13905093 | W15: =VLOOKUP($B15,$R$3:$X$9,6,FALSE) -> 0.26041667 | X15: =VLOOKUP($B15,$R$3:$X$9,7,FALSE) -> 0.29513889 | Y15: =VLOOKUP($B15,$R$3:$Z$9,8,FALSE) -> 0 | Z15: =VLOOKUP($B15,$R$3:$Z$9,9,FALSE) -> 75
R16: =B16 -> 0 | S16: =VLOOKUP($B16,$R$3:$X$9,2,FALSE) -> #N/A | T16: =VLOOKUP($B16,$R$3:$X$9,3,FALSE) -> #N/A | U16: =VLOOKUP($B16,$R$3:$X$9,4,FALSE) -> #N/A | V16: =VLOOKUP($B16,$R$3:$X$9,5,FALSE) -> #N/A | W16: =VLOOKUP($B16,$R$3:$X$9,6,FALSE) -> #N/A | X16: =VLOOKUP($B16,$R$3:$X$9,7,FALSE) -> #N/A | Y16: =VLOOKUP($B16,$R$3:$Z$9,8,FALSE) -> #N/A | Z16: =VLOOKUP($B16,$R$3:$Z$9,9,FALSE) -> #N/A
R17: =B17 -> 0 | S17: =VLOOKUP($B17,$R$3:$X$9,2,FALSE) -> #N/A | T17: =VLOOKUP($B17,$R$3:$X$9,3,FALSE) -> #N/A | U17: =VLOOKUP($B17,$R$3:$X$9,4,FALSE) -> #N/A | V17: =VLOOKUP($B17,$R$3:$X$9,5,FALSE) -> #N/A | W17: =VLOOKUP($B17,$R$3:$X$9,6,FALSE) -> #N/A | X17: =VLOOKUP($B17,$R$3:$X$9,7,FALSE) -> #N/A | Y17: =VLOOKUP($B17,$R$3:$Z$9,8,FALSE) -> #N/A | Z17: =VLOOKUP($B17,$R$3:$Z$9,9,FALSE) -> #N/A
B18: CARIB | C18: =[24]Brewhouse!$A914 -> CA799 | D18: =[24]Brewhouse!$AF914 -> 52.6 | E18: =[24]Brewhouse!$AI914 -> 51.5 | F18: =[24]Brewhouse!$V914 -> 58 | G18: =[24]Brewhouse!AG914 -> 11.5 | H18: 11.5 | I18: =[24]Brewhouse!$AU914 -> 96.793515 | J18: =[24]Brewhouse!$AV914 -> 97.247486 | K18: =[24]Brewhouse!$Q914 -> 5.4990584 | L18: =[24]Brewhouse!$P914 -> 58 | M18: =[24]Brewhouse!$U914-[24]Brewhouse!$T914 -> 0.12569444 | N18: =[24]Brewhouse!$Z914 -> 0.25138889 | O18: =[24]Brewhouse!$AX914 -> R.Sookram | R18: =B18 -> CARIB | S18: =VLOOKUP($B18,$R$3:$X$9,2,FALSE) -> 11.6 | T18: =VLOOKUP($B18,$R$3:$X$9,3,FALSE) -> 12 | U18: =VLOOKUP($B18,$R$3:$X$9,4,FALSE) -> 0 | V18: =VLOOKUP($B18,$R$3:$X$9,5,FALSE) -> 0.11805556 | W18: =VLOOKUP($B18,$R$3:$X$9,6,FALSE) -> 0.22569444 | X18: =VLOOKUP($B18,$R$3:$X$9,7,FALSE) -> 0.26388889 | Y18: =VLOOKUP($B18,$R$3:$Z$9,8,FALSE) -> 0 | Z18: =VLOOKUP($B18,$R$3:$Z$9,9,FALSE) -> 60
B19: CARIB | C19: =[24]Brewhouse!$A915 -> CA800 | D19: =[24]Brewhouse!$AF915 -> 51.2 | E19: =[24]Brewhouse!$AI915 -> 50.1 | F19: =[24]Brewhouse!$V915 -> 52 | G19: =[24]Brewhouse!AG915 -> 11.9 | H19: 11.9 | I19: =[24]Brewhouse!$AU915 -> 98.573166 | J19: =[24]Brewhouse!$AV915 -> 99.03519 | K19: =[24]Brewhouse!$Q915 -> 4.754717 | L19: =[24]Brewhouse!$P915 -> 59 | M19: =[24]Brewhouse!$U915-[24]Brewhouse!$T915 -> 0.10416667 | N19: =[24]Brewhouse!$Z915 -> 0.25138889 | O19: =[24]Brewhouse!$AX915 -> K. Benjamin | R19: =B19 -> CARIB | S19: =VLOOKUP($B19,$R$3:$X$9,2,FALSE) -> 11.6 | T19: =VLOOKUP($B19,$R$3:$X$9,3,FALSE) -> 12 | U19: =VLOOKUP($B19,$R$3:$X$9,4,FALSE) -> 0 | V19: =VLOOKUP($B19,$R$3:$X$9,5,FALSE) -> 0.11805556 | W19: =VLOOKUP($B19,$R$3:$X$9,6,FALSE) -> 0.22569444 | X19: =VLOOKUP($B19,$R$3:$X$9,7,FALSE) -> 0.26388889 | Y19: =VLOOKUP($B19,$R$3:$Z$9,8,FALSE) -> 0 | Z19: =VLOOKUP($B19,$R$3:$Z$9,9,FALSE) -> 60
B20: CARIB | C20: =[24]Brewhouse!$A916 -> CA801 | D20: =[24]Brewhouse!$AF916 -> 53.5 | E20: =[24]Brewhouse!$AI916 -> 52.4 | F20: =[24]Brewhouse!$V916 -> 61 | G20: =[24]Brewhouse!AG916 -> 11.6 | H20: 11.7 | I20: =[24]Brewhouse!$AU916 -> 99.387081 | J20: =[24]Brewhouse!$AV916 -> 99.853215 | K20: =[24]Brewhouse!$Q916 -> 1.1698113 | L20: =[24]Brewhouse!$P916 -> 60 | M20: =[24]Brewhouse!$U916-[24]Brewhouse!$T916 -> 0.12083333 | N20: =[24]Brewhouse!$Z916 -> 0.26388889 | O20: =[24]Brewhouse!$AX916 -> K. Benjamin | R20: =B20 -> CARIB | S20: =VLOOKUP($B20,$R$3:$X$9,2,FALSE) -> 11.6 | T20: =VLOOKUP($B20,$R$3:$X$9,3,FALSE) -> 12 | U20: =VLOOKUP($B20,$R$3:$X$9,4,FALSE) -> 0 | V20: =VLOOKUP($B20,$R$3:$X$9,5,FALSE) -> 0.11805556 | W20: =VLOOKUP($B20,$R$3:$X$9,6,FALSE) -> 0.22569444 | X20: =VLOOKUP($B20,$R$3:$X$9,7,FALSE) -> 0.26388889 | Y20: =VLOOKUP($B20,$R$3:$Z$9,8,FALSE) -> 0 | Z20: =VLOOKUP($B20,$R$3:$Z$9,9,FALSE) -> 60
R21: =B21 -> 0 | S21: =VLOOKUP($B21,$R$3:$X$9,2,FALSE) -> #N/A | T21: =VLOOKUP($B21,$R$3:$X$9,3,FALSE) -> #N/A | U21: =VLOOKUP($B21,$R$3:$X$9,4,FALSE) -> #N/A | V21: =VLOOKUP($B21,$R$3:$X$9,5,FALSE) -> #N/A | W21: =VLOOKUP($B21,$R$3:$X$9,6,FALSE) -> #N/A | X21: =VLOOKUP($B21,$R$3:$X$9,7,FALSE) -> #N/A | Y21: =VLOOKUP($B21,$R$3:$Z$9,8,FALSE) -> #N/A | Z21: =VLOOKUP($B21,$R$3:$Z$9,9,FALSE) -> #N/A
R22: =B22 -> 0 | S22: =VLOOKUP($B22,$R$3:$X$9,2,FALSE) -> #N/A | T22: =VLOOKUP($B22,$R$3:$X$9,3,FALSE) -> #N/A | U22: =VLOOKUP($B22,$R$3:$X$9,4,FALSE) -> #N/A | V22: =VLOOKUP($B22,$R$3:$X$9,5,FALSE) -> #N/A | W22: =VLOOKUP($B22,$R$3:$X$9,6,FALSE) -> #N/A | X22: =VLOOKUP($B22,$R$3:$X$9,7,FALSE) -> #N/A | Y22: =VLOOKUP($B22,$R$3:$Z$9,8,FALSE) -> #N/A | Z22: =VLOOKUP($B22,$R$3:$Z$9,9,FALSE) -> #N/A
R23: =B23 -> 0 | S23: =VLOOKUP($B23,$R$3:$X$9,2,FALSE) -> #N/A | T23: =VLOOKUP($B23,$R$3:$X$9,3,FALSE) -> #N/A | U23: =VLOOKUP($B23,$R$3:$X$9,4,FALSE) -> #N/A | V23: =VLOOKUP($B23,$R$3:$X$9,5,FALSE) -> #N/A | W23: =VLOOKUP($B23,$R$3:$X$9,6,FALSE) -> #N/A | X23: =VLOOKUP($B23,$R$3:$X$9,7,FALSE) -> #N/A | Y23: =VLOOKUP($B23,$R$3:$Z$9,8,FALSE) -> #N/A | Z23: =VLOOKUP($B23,$R$3:$Z$9,9,FALSE) -> #N/A
R24: =B24 -> 0 | S24: =VLOOKUP($B24,$R$3:$X$9,2,FALSE) -> #N/A | T24: =VLOOKUP($B24,$R$3:$X$9,3,FALSE) -> #N/A | U24: =VLOOKUP($B24,$R$3:$X$9,4,FALSE) -> #N/A | V24: =VLOOKUP($B24,$R$3:$X$9,5,FALSE) -> #N/A | W24: =VLOOKUP($B24,$R$3:$X$9,6,FALSE) -> #N/A | X24: =VLOOKUP($B24,$R$3:$X$9,7,FALSE) -> #N/A | Y24: =VLOOKUP($B24,$R$3:$Z$9,8,FALSE) -> #N/A | Z24: =VLOOKUP($B24,$R$3:$Z$9,9,FALSE) -> #N/A
R25: =B25 -> 0 | S25: =VLOOKUP($B25,$R$3:$X$9,2,FALSE) -> #N/A | T25: =VLOOKUP($B25,$R$3:$X$9,3,FALSE) -> #N/A | U25: =VLOOKUP($B25,$R$3:$X$9,4,FALSE) -> #N/A | V25: =VLOOKUP($B25,$R$3:$X$9,5,FALSE) -> #N/A | W25: =VLOOKUP($B25,$R$3:$X$9,6,FALSE) -> #N/A | X25: =VLOOKUP($B25,$R$3:$X$9,7,FALSE) -> #N/A | Y25: =VLOOKUP($B25,$R$3:$Z$9,8,FALSE) -> #N/A | Z25: =VLOOKUP($B25,$R$3:$Z$9,9,FALSE) -> #N/A
R26: =B26 -> 0 | S26: =VLOOKUP($B26,$R$3:$X$9,2,FALSE) -> #N/A | T26: =VLOOKUP($B26,$R$3:$X$9,3,FALSE) -> #N/A | U26: =VLOOKUP($B26,$R$3:$X$9,4,FALSE) -> #N/A | V26: =VLOOKUP($B26,$R$3:$X$9,5,FALSE) -> #N/A | W26: =VLOOKUP($B26,$R$3:$X$9,6,FALSE) -> #N/A | X26: =VLOOKUP($B26,$R$3:$X$9,7,FALSE) -> #N/A | Y26: =VLOOKUP($B26,$R$3:$Z$9,8,FALSE) -> #N/A | Z26: =VLOOKUP($B26,$R$3:$Z$9,9,FALSE) -> #N/A
B27: BRAND | D27: BBT P.G./ O.G | I27: Brand | K27: MTD No. of Brews | L27: MTD | M27: YTD | N27: Target | R27: =B27 -> BRAND | S27: =VLOOKUP($B27,$R$3:$X$9,2,FALSE) -> #N/A | T27: =VLOOKUP($B27,$R$3:$X$9,3,FALSE) -> #N/A | U27: =VLOOKUP($B27,$R$3:$X$9,4,FALSE) -> #N/A | V27: =VLOOKUP($B27,$R$3:$X$9,5,FALSE) -> #N/A | W27: =VLOOKUP($B27,$R$3:$X$9,6,FALSE) -> #N/A | X27: =VLOOKUP($B27,$R$3:$X$9,7,FALSE) -> #N/A | Y27: =VLOOKUP($B27,$R$3:$Z$9,8,FALSE) -> #N/A | Z27: =VLOOKUP($B27,$R$3:$Z$9,9,FALSE) -> #N/A
B28: =I28 -> CARIB | C28: =[24]Process!$D$865 -> 12 | D28: 11.77 | I28: CARIB | J28: =AVERAGE(I18:I20) -> 98.251254 | K28: =COUNTA([24]Brewhouse!$A$914:$A$916) -> 3 | L28: =AVERAGE([24]Brewhouse!$AU$914:$AU$916) -> 98.251254 | M28: =AVERAGE([24]Brewhouse!$AU$102:$AU$171,[24]Brewhouse!$AU$173:$AU$253,[24]Brewhouse!$AU$255:$AU$339,[24]Brewhouse!$AU$341:$AU$346,[24]Brewhouse!$AU$348,[24]Brewhouse!$AU$349:$AU$406,[24]Brewhouse!$AU$408:$AU$491,[24]Brewhouse!$AU$493:$AU$578,[24]Brewhouse!$AU$580:$AU$652,[24]Brewhouse!$AU$655:$AU$738,[24]Brewhouse!$A$740:$A$821,[24]Brewhouse!$AU$823:$AU$862,[25]Brewhouse!$AS$420:$AS$423,[24]Brewhouse!$AU$867:$AU$912,[24]Brewhouse!$AU$914:$AU$916) -> 97.716575 | N28: 98 | R28: =B28 -> CARIB | S28: =VLOOKUP($B28,$R$3:$X$9,2,FALSE) -> 11.6 | T28: =VLOOKUP($B28,$R$3:$X$9,3,FALSE) -> 12 | U28: =VLOOKUP($B28,$R$3:$X$9,4,FALSE) -> 0 | V28: =VLOOKUP($B28,$R$3:$X$9,5,FALSE) -> 0.11805556 | W28: =VLOOKUP($B28,$R$3:$X$9,6,FALSE) -> 0.22569444 | X28: =VLOOKUP($B28,$R$3:$X$9,7,FALSE) -> 0.26388889 | Y28: =VLOOKUP($B28,$R$3:$Z$9,8,FALSE) -> 0 | Z28: =VLOOKUP($B28,$R$3:$Z$9,9,FALSE) -> 60
C29: =[24]Process!D867 -> 11.5 | I29: STAG | M29: =AVERAGE([25]Brewhouse!$AS$15:$AS$64,[25]Brewhouse!$AS$66:$AS$103,[25]Brewhouse!$AS$105:$AS$140,[25]Brewhouse!$AS$142:$AS$193,[25]Brewhouse!$AS$195:$AS$240,[25]Brewhouse!$AS$242:$AS$273,[25]Brewhouse!$AS$275:$AS$322,[25]Brewhouse!$AS$324:$AS$359,[25]Brewhouse!$AS$361:$AS$397,[25]Brewhouse!$AS$399:$AS$443) -> 97.924881 | N29: 98 | R29: =B29 -> 0 | S29: =VLOOKUP($B29,$R$3:$X$9,2,FALSE) -> #N/A | T29: =VLOOKUP($B29,$R$3:$X$9,3,FALSE) -> #N/A | U29: =VLOOKUP($B29,$R$3:$X$9,4,FALSE) -> #N/A | V29: =VLOOKUP($B29,$R$3:$X$9,5,FALSE) -> #N/A | W29: =VLOOKUP($B29,$R$3:$X$9,6,FALSE) -> #N/A | X29: =VLOOKUP($B29,$R$3:$X$9,7,FALSE) -> #N/A | Y29: =VLOOKUP($B29,$R$3:$Z$9,8,FALSE) -> #N/A | Z29: =VLOOKUP($B29,$R$3:$Z$9,9,FALSE) -> #N/A
C30: =[24]Process!D868 -> 11.6 | D30: 11.82 | I30: GUINNESS | M30: =AVERAGE([26]Brewhouse!$AU$4:$AU$7,[26]Brewhouse!$AU$9:$AU$22,[26]Brewhouse!$AU$24:$AU$35,[26]Brewhouse!$AU$37:$AU$45,[26]Brewhouse!$AU$47:$AU$62,[26]Brewhouse!$AU$64:$AU$79,[26]Brewhouse!$AU$81:$AU$92,[26]Brewhouse!$AU$94:$AU$97,[26]Brewhouse!$AU$99:$AU$106) -> 96.648781 | N30: 98 | R30: =B30 -> 0 | S30: =VLOOKUP($B30,$R$3:$X$9,2,FALSE) -> #N/A | T30: =VLOOKUP($B30,$R$3:$X$9,3,FALSE) -> #N/A | U30: =VLOOKUP($B30,$R$3:$X$9,4,FALSE) -> #N/A | V30: =VLOOKUP($B30,$R$3:$X$9,5,FALSE) -> #N/A | W30: =VLOOKUP($B30,$R$3:$X$9,6,FALSE) -> #N/A | X30: =VLOOKUP($B30,$R$3:$X$9,7,FALSE) -> #N/A | Y30: =VLOOKUP($B30,$R$3:$Z$9,8,FALSE) -> #N/A | Z30: =VLOOKUP($B30,$R$3:$Z$9,9,FALSE) -> #N/A
C31: =[24]Process!D869 -> 11.7 | I31: VITAMALT | J31: =AVERAGE(I10:I15) -> 98.707451 | K31: =COUNTA([23]Brewhouse!$A$97:$A$104) -> 8 | L31: =AVERAGE([23]Brewhouse!$AV$97:$AV$104) -> 98.419138 | M31: =AVERAGE([23]Brewhouse!$AV$5:$AV$14,[23]Brewhouse!$AV$16:$AV$19,[23]Brewhouse!$AV$21:$AV$24,[23]Brewhouse!$AV$26:$AV$33,[23]Brewhouse!$AV$35:$AV$46,[23]Brewhouse!$AV$48:$AV$53,[23]Brewhouse!$AV$55:$AV$62,[23]Brewhouse!$AV$64:$AV$77,[23]Brewhouse!$AV$79:$AV$86,[23]Brewhouse!$AV$88:$AV$95,[23]Brewhouse!$AV$97:$AV$104) -> 98.270381 | N31: 98 | R31: =B31 -> 0 | S31: =VLOOKUP($B31,$R$3:$X$9,2,FALSE) -> #N/A | T31: =VLOOKUP($B31,$R$3:$X$9,3,FALSE) -> #N/A | U31: =VLOOKUP($B31,$R$3:$X$9,4,FALSE) -> #N/A | V31: =VLOOKUP($B31,$R$3:$X$9,5,FALSE) -> #N/A | W31: =VLOOKUP($B31,$R$3:$X$9,6,FALSE) -> #N/A | X31: =VLOOKUP($B31,$R$3:$X$9,7,FALSE) -> #N/A | Y31: =VLOOKUP($B31,$R$3:$Z$9,8,FALSE) -> #N/A | Z31: =VLOOKUP($B31,$R$3:$Z$9,9,FALSE) -> #N/A
C32: =[24]Process!D870 -> 11.7 | D32: 11.81 | I32: MAXIMALT | N32: 98 | R32: =B32 -> 0 | S32: =VLOOKUP($B32,$R$3:$X$9,2,FALSE) -> #N/A | T32: =VLOOKUP($B32,$R$3:$X$9,3,FALSE) -> #N/A | U32: =VLOOKUP($B32,$R$3:$X$9,4,FALSE) -> #N/A | V32: =VLOOKUP($B32,$R$3:$X$9,5,FALSE) -> #N/A | W32: =VLOOKUP($B32,$R$3:$X$9,6,FALSE) -> #N/A | X32: =VLOOKUP($B32,$R$3:$X$9,7,FALSE) -> #N/A | Y32: =VLOOKUP($B32,$R$3:$Z$9,8,FALSE) -> #N/A | Z32: =VLOOKUP($B32,$R$3:$Z$9,9,FALSE) -> #N/A
I33: MACKESON | M33: =AVERAGE([27]Brewhouse!$AT$4:$AT$11,[27]Brewhouse!$AT$13:$AT$16,[27]Brewhouse!$AT$18:$AT$21,[27]Brewhouse!$AT$26,[27]Brewhouse!$AT$28:$AT$35) -> 94.794664 | N33: 98 | R33: =B33 -> 0 | S33: =VLOOKUP($B33,$R$3:$X$9,2,FALSE) -> #N/A | T33: =VLOOKUP($B33,$R$3:$X$9,3,FALSE) -> #N/A | U33: =VLOOKUP($B33,$R$3:$X$9,4,FALSE) -> #N/A | V33: =VLOOKUP($B33,$R$3:$X$9,5,FALSE) -> #N/A | W33: =VLOOKUP($B33,$R$3:$X$9,6,FALSE) -> #N/A | X33: =VLOOKUP($B33,$R$3:$X$9,7,FALSE) -> #N/A | Y33: =VLOOKUP($B33,$R$3:$Z$9,8,FALSE) -> #N/A | Z33: =VLOOKUP($B33,$R$3:$Z$9,9,FALSE) -> #N/A
I34: STARMALT | K34: =COUNTA([22]Brewhouse!$A$94:$A$97) -> 4 | L34: =AVERAGE([22]Brewhouse!$AY$94:$AY$97) -> 95.326768 | M34: =AVERAGE([22]Brewhouse!$AY$6:$AY$13,[22]Brewhouse!$AY$15:$AY$20,[22]Brewhouse!$AY$22:$AY$29,[22]Brewhouse!$AY$31:$AY$34,[22]Brewhouse!$AY$36:$AY$43,[22]Brewhouse!$AY$45:$AY$50, [22]Brewhouse!$AY$56:$AY$73,[22]Brewhouse!$AY$75:$AY$92,[22]Brewhouse!$AY$94:$AY$97) -> 97.370193 | N34: 98 | R34: =B34 -> 0 | S34: =VLOOKUP($B34,$R$3:$X$9,2,FALSE) -> #N/A | T34: =VLOOKUP($B34,$R$3:$X$9,3,FALSE) -> #N/A | U34: =VLOOKUP($B34,$R$3:$X$9,4,FALSE) -> #N/A | V34: =VLOOKUP($B34,$R$3:$X$9,5,FALSE) -> #N/A | W34: =VLOOKUP($B34,$R$3:$X$9,6,FALSE) -> #N/A | X34: =VLOOKUP($B34,$R$3:$X$9,7,FALSE) -> #N/A | Y34: =VLOOKUP($B34,$R$3:$Z$9,8,FALSE) -> #N/A | Z34: =VLOOKUP($B34,$R$3:$Z$9,9,FALSE) -> #N/A
I35: HR- Pils | M35: =AVERAGE([28]Brewhouse!$AU$5:$AU$8,[28]Brewhouse!$AU$10:$AU$13,[22]Brewhouse!$AY$75:$AY$77) -> 94.749192 | N35: 98 | R35: =B35 -> 0 | S35: =VLOOKUP($B35,$R$3:$X$9,2,FALSE) -> #N/A | T35: =VLOOKUP($B35,$R$3:$X$9,3,FALSE) -> #N/A | U35: =VLOOKUP($B35,$R$3:$X$9,4,FALSE) -> #N/A | V35: =VLOOKUP($B35,$R$3:$X$9,5,FALSE) -> #N/A | W35: =VLOOKUP($B35,$R$3:$X$9,6,FALSE) -> #N/A | X35: =VLOOKUP($B35,$R$3:$X$9,7,FALSE) -> #N/A | Y35: =VLOOKUP($B35,$R$3:$Z$9,8,FALSE) -> #N/A | Z35: =VLOOKUP($B35,$R$3:$Z$9,9,FALSE) -> #N/A
I36: HR- IPA | M36: =AVERAGE([29]Brewhouse!$AW$26:$AW$27) -> 95.310681 | N36: 98 | R36: =B36 -> 0 | S36: =VLOOKUP($B36,$R$3:$X$9,2,FALSE) -> #N/A | T36: =VLOOKUP($B36,$R$3:$X$9,3,FALSE) -> #N/A | U36: =VLOOKUP($B36,$R$3:$X$9,4,FALSE) -> #N/A | V36: =VLOOKUP($B36,$R$3:$X$9,5,FALSE) -> #N/A | W36: =VLOOKUP($B36,$R$3:$X$9,6,FALSE) -> #N/A | X36: =VLOOKUP($B36,$R$3:$X$9,7,FALSE) -> #N/A | Y36: =VLOOKUP($B36,$R$3:$Z$9,8,FALSE) -> #N/A | Z36: =VLOOKUP($B36,$R$3:$Z$9,9,FALSE) -> #N/A
I37: HR- APA | M37: =AVERAGE([30]Brewhouse!$AU$13:$AU$14) -> 97.110575 | N37: 98 | R37: =B37 -> 0 | S37: =VLOOKUP($B37,$R$3:$X$9,2,FALSE) -> #N/A | T37: =VLOOKUP($B37,$R$3:$X$9,3,FALSE) -> #N/A | U37: =VLOOKUP($B37,$R$3:$X$9,4,FALSE) -> #N/A | V37: =VLOOKUP($B37,$R$3:$X$9,5,FALSE) -> #N/A | W37: =VLOOKUP($B37,$R$3:$X$9,6,FALSE) -> #N/A | X37: =VLOOKUP($B37,$R$3:$X$9,7,FALSE) -> #N/A | Y37: =VLOOKUP($B37,$R$3:$Z$9,8,FALSE) -> #N/A | Z37: =VLOOKUP($B37,$R$3:$Z$9,9,FALSE) -> #N/A
K38: =SUM(K28:K37) -> 15 | L38: =((L28*K28)+(L29*K29)+(L30*K30)+(L31*K31)+(L32*K32)+(K35*L35)+(L33*K33)+(L34*K34)+(L37*K37))/(K38) -> 97.560929 | M38: =AVERAGE('[31]Jan 31st'!$L$65,'[32]Feb 28th'!$L$35,'[33]Mar. 31st'!$L$35,'[34]Apr. 30th'!$L$45,'[35]May 30th'!$L$37,'[36]June 30th'!$L$57,'[37]July 29th '!$L$44,'[38]Aug 29th'!$L$29,'[39]Sept 30th'!$L$35,L38) -> 97.574043 | N38: 98 | R38: =B38 -> 0 | S38: =VLOOKUP($B38,$R$3:$X$9,2,FALSE) -> #N/A | T38: =VLOOKUP($B38,$R$3:$X$9,3,FALSE) -> #N/A | U38: =VLOOKUP($B38,$R$3:$X$9,4,FALSE) -> #N/A | V38: =VLOOKUP($B38,$R$3:$X$9,5,FALSE) -> #N/A | W38: =VLOOKUP($B38,$R$3:$X$9,6,FALSE) -> #N/A | X38: =VLOOKUP($B38,$R$3:$X$9,7,FALSE) -> #N/A | Y38: =VLOOKUP($B38,$R$3:$Z$9,8,FALSE) -> #N/A | Z38: =VLOOKUP($B38,$R$3:$Z$9,9,FALSE) -> #N/A
R39: =B39 -> 0 | S39: =VLOOKUP($B39,$R$3:$X$9,2,FALSE) -> #N/A | T39: =VLOOKUP($B39,$R$3:$X$9,3,FALSE) -> #N/A | U39: =VLOOKUP($B39,$R$3:$X$9,4,FALSE) -> #N/A | V39: =VLOOKUP($B39,$R$3:$X$9,5,FALSE) -> #N/A | W39: =VLOOKUP($B39,$R$3:$X$9,6,FALSE) -> #N/A | X39: =VLOOKUP($B39,$R$3:$X$9,7,FALSE) -> #N/A | Y39: =VLOOKUP($B39,$R$3:$Z$9,8,FALSE) -> #N/A | Z39: =VLOOKUP($B39,$R$3:$Z$9,9,FALSE) -> #N/A
B40: =I34 -> STARMALT | C40: =[22]Process!D93 -> 17.2 | D40: 17.18 | J40: Daily Brewing Plan
...

Sheet Nov 5th
S1: P.G. | U1: Hot Time | W1: Process Time | Y1: Cooling Time
B2: Brewing Department Daily Process Loss Report | S2: Lower | T2: Upper | U2: Lower | V2: Upper | W2: Lower | X2: Upper | Y2: Lower | Z2: Upper
R3: CARIB | S3: 11.6 | T3: 12 | U3: 0 | V3: 0.11805556 | W3: 0.22569444 | X3: 0.26388889 | Y3: 0 | Z3: 60 | AB3: HR- PISNER
B4: Date: | C4: 45967 | J4: LOT WORT COLOUR: 3.3 | M4: Filter Sheets (Target 20 days) | R4: STAG | S4: 11.6 | T4: 12 | U4: 0 | V4: 0.11805556 | W4: 0.22569444 | X4: 0.26388889 | Y4: 0 | Z4: 60
M5: Double | N5: Single | R5: GUINNESS | S5: 17 | T5: 17.5 | U5: 0 | V5: 0.10763889 | W5: 0.24652778 | X5: 0.28472222 | Y5: 0 | Z5: 60
J6: MALT LOT: Lot #4 | L6: Sheet Day | R6: MACKESON | S6: 13.3 | T6: 13.5 | U6: 0 | V6: 0.12905093 | W6: 0.27430556 | X6: 0.30208333 | Y6: 0
R7: STARMALT | S7: 17 | T7: 17.4 | U7: 0 | V7: 0.13605324 | W7: 0.27430556 | X7: 0.30902778 | Y7: 0 | Z7: 85
B8: Brand | C8: Brew no. | D8: Kett. Hls | E8: Wort | F8: Cool Time(Mins) | G8: Cast. P.G. (Lab Result) | H8: Cast P.G. (Cellar Operator)-gravity | I8: Extr. Rec (77.9%) | J8: Theor. Extr. (77.5%) | K8: Boil Off /Vol. (4-6%) | L8: Boil Time | M8: Total Hot | N8: Brewing | O8: Operator | R8: Hurricane Reef | S8: 16.6 | T8: 17 | U8: 0 | V8: 0.12905093 | W8: 0.27430556 | X8: 0.30208333 | Y8: 0
E9: Meter (Hls) | F9: Target(< 60Mins) | M9: Time | R9: VITAMALT | S9: 14.2 | T9: 14.6 | U9: 0 | V9: 0.13905093 | W9: 0.26041667 | X9: 0.29513889 | Y9: 0 | Z9: 75
B10: CARIB | C10: =[24]Brewhouse!$A917 -> CA802 | D10: =[24]Brewhouse!$AF917 -> 51.6 | E10: =[24]Brewhouse!$AI917 -> 51.06 | F10: =[24]Brewhouse!$V917 -> 63 | G10: =[24]Brewhouse!AG917 -> 11.5 | H10: 11.4 | I10: =[24]Brewhouse!$AU917 -> 97.270715 | J10: =[24]Brewhouse!$AV917 -> 97.726524 | K10: =[24]Brewhouse!$Q917 -> 4 | L10: =[24]Brewhouse!$P917 -> 60 | M10: =[24]Brewhouse!$U917-[24]Brewhouse!$T917 -> 0.13263889 | N10: =[24]Brewhouse!$Z917 -> 0.25694444 | O10: =[24]Brewhouse!$AX917 -> K. Benjamin | R10: =B10 -> CARIB | S10: =VLOOKUP($B10,$R$3:$X$9,2,FALSE) -> 11.6 | T10: =VLOOKUP($B10,$R$3:$X$9,3,FALSE) -> 12 | U10: =VLOOKUP($B10,$R$3:$X$9,4,FALSE) -> 0 | V10: =VLOOKUP($B10,$R$3:$X$9,5,FALSE) -> 0.11805556 | W10: =VLOOKUP($B10,$R$3:$X$9,6,FALSE) -> 0.22569444 | X10: =VLOOKUP($B10,$R$3:$X$9,7,FALSE) -> 0.26388889 | Y10: =VLOOKUP($B10,$R$3:$Z$9,8,FALSE) -> 0 | Z10: =VLOOKUP($B10,$R$3:$Z$9,9,FALSE) -> 60
B11: CARIB | C11: =[24]Brewhouse!$A918 -> CA803 | D11: =[24]Brewhouse!$AF918 -> 52.7 | E11: =[24]Brewhouse!$AI918 -> 52 | F11: =[24]Brewhouse!$V918 -> 65 | G11: =[24]Brewhouse!AG918 -> 11.9 | H11: 11.8 | I11: =[24]Brewhouse!$AU918 -> 98.939207 | J11: =[24]Brewhouse!$AV918 -> 99.402872 | K11: =[24]Brewhouse!$Q918 -> 1.9245283 | L11: =[24]Brewhouse!$P918 -> 60 | M11: =[24]Brewhouse!$U918-[24]Brewhouse!$T918 -> 0.12986111 | N11: =[24]Brewhouse!$Z918 -> 0.25972222 | O11: =[24]Brewhouse!$AX918 -> K. Benjamin | R11: =B11 -> CARIB | S11: =VLOOKUP($B11,$R$3:$X$9,2,FALSE) -> 11.6 | T11: =VLOOKUP($B11,$R$3:$X$9,3,FALSE) -> 12 | U11: =VLOOKUP($B11,$R$3:$X$9,4,FALSE) -> 0 | V11: =VLOOKUP($B11,$R$3:$X$9,5,FALSE) -> 0.11805556 | W11: =VLOOKUP($B11,$R$3:$X$9,6,FALSE) -> 0.22569444 | X11: =VLOOKUP($B11,$R$3:$X$9,7,FALSE) -> 0.26388889 | Y11: =VLOOKUP($B11,$R$3:$Z$9,8,FALSE) -> 0 | Z11: =VLOOKUP($B11,$R$3:$Z$9,9,FALSE) -> 60
B12: CARIB | C12: =[24]Brewhouse!$A919 -> CA804 | D12: =[24]Brewhouse!$AF919 -> 53 | E12: =[24]Brewhouse!$AI919 -> 51.5 | F12: =[24]Brewhouse!$V919 -> 65 | G12: =[24]Brewhouse!AG919 -> 11.6 | H12: 11.6 | I12: =[24]Brewhouse!$AU919 -> 98.641911 | J12: =[24]Brewhouse!$AV919 -> 99.104257 | K12: =[24]Brewhouse!$Q919 -> 1.3584906 | L12: =[24]Brewhouse!$P919 -> 60 | M12: =[24]Brewhouse!$U919-[24]Brewhouse!$T919 -> 0.11180556 | N12: =[24]Brewhouse!$Z919 -> 0.26944444 | O12: =[24]Brewhouse!$AX919 -> R. Regis | R12: =B12 -> CARIB | S12: =VLOOKUP($B12,$R$3:$X$9,2,FALSE) -> 11.6 | T12: =VLOOKUP($B12,$R$3:$X$9,3,FALSE) -> 12 | U12: =VLOOKUP($B12,$R$3:$X$9,4,FALSE) -> 0 | V12: =VLOOKUP($B12,$R$3:$X$9,5,FALSE) -> 0.11805556 | W12: =VLOOKUP($B12,$R$3:$X$9,6,FALSE) -> 0.22569444 | X12: =VLOOKUP($B12,$R$3:$X$9,7,FALSE) -> 0.26388889 | Y12: =VLOOKUP($B12,$R$3:$Z$9,8,FALSE) -> 0 | Z12: =VLOOKUP($B12,$R$3:$Z$9,9,FALSE) -> 60
B13: CARIB | C13: =[24]Brewhouse!$A920 -> CA805 | D13: =[24]Brewhouse!$AF920 -> 50.9 | E13: =[24]Brewhouse!$AI920 -> 51.1 | F13: =[24]Brewhouse!$V920 -> 70 | G13: =[24]Brewhouse!AG920 -> 11.6 | H13: 11.6 | I13: =[24]Brewhouse!$AU920 -> 98.117301 | J13: =[24]Brewhouse!$AV920 -> 98.577115 | K13: =[24]Brewhouse!$Q920 -> 5.4990584 | L13: =[24]Brewhouse!$P920 -> 60 | M13: =[24]Brewhouse!$U920-[24]Brewhouse!$T920 -> 0.11805556 | N13: =[24]Brewhouse!$Z920 -> 0.25694444 | O13: =[24]Brewhouse!$AX920 -> R. Regis | R13: =B13 -> CARIB | S13: =VLOOKUP($B13,$R$3:$X$9,2,FALSE) -> 11.6 | T13: =VLOOKUP($B13,$R$3:$X$9,3,FALSE) -> 12 | U13: =VLOOKUP($B13,$R$3:$X$9,4,FALSE) -> 0 | V13: =VLOOKUP($B13,$R$3:$X$9,5,FALSE) -> 0.11805556 | W13: =VLOOKUP($B13,$R$3:$X$9,6,FALSE) -> 0.22569444 | X13: =VLOOKUP($B13,$R$3:$X$9,7,FALSE) -> 0.26388889 | Y13: =VLOOKUP($B13,$R$3:$Z$9,8,FALSE) -> 0 | Z13: =VLOOKUP($B13,$R$3:$Z$9,9,FALSE) -> 60
B14: CARIB | C14: =[24]Brewhouse!$A921 -> CA806 | D14: =[24]Brewhouse!$AF921 -> 51.7 | E14: =[24]Brewhouse!$AI921 -> 52.1 | F14: =[24]Brewhouse!$V921 -> 73 | G14: =[24]Brewhouse!AG921 -> 11.6 | H14: 11.7 | I14: =[24]Brewhouse!$AU921 -> 99.668457 | J14: =[24]Brewhouse!$AV921 -> 100.13565 | K14: =[24]Brewhouse!$Q921 -> 3.992467 | L14: =[24]Brewhouse!$P921 -> 60 | M14: =[24]Brewhouse!$U921-[24]Brewhouse!$T921 -> 0.12013889 | N14: =[24]Brewhouse!$Z921 -> 0.26527778 | O14: =[24]Brewhouse!$AX921 -> R. Regis | R14: =B14 -> CARIB | S14: =VLOOKUP($B14,$R$3:$X$9,2,FALSE) -> 11.6 | T14: =VLOOKUP($B14,$R$3:$X$9,3,FALSE) -> 12 | U14: =VLOOKUP($B14,$R$3:$X$9,4,FALSE) -> 0 | V14: =VLOOKUP($B14,$R$3:$X$9,5,FALSE) -> 0.11805556 | W14: =VLOOKUP($B14,$R$3:$X$9,6,FALSE) -> 0.22569444 | X14: =VLOOKUP($B14,$R$3:$X$9,7,FALSE) -> 0.26388889 | Y14: =VLOOKUP($B14,$R$3:$Z$9,8,FALSE) -> 0 | Z14: =VLOOKUP($B14,$R$3:$Z$9,9,FALSE) -> 60
B15: CARIB | C15: =[24]Brewhouse!$A922 -> CA807 | D15: =[24]Brewhouse!$AF922 -> 49.3 | E15: =[24]Brewhouse!$AI922 -> 47.2 | F15: =[24]Brewhouse!$V922 -> 68 | G15: =[24]Brewhouse!AG922 -> 11.9 | H15: 12 | I15: =[24]Brewhouse!$AU922 -> 92.753166 | J15: =[24]Brewhouse!$AV922 -> 93.187945 | K15: =[24]Brewhouse!$Q922 -> 8.5122411 | L15: =[24]Brewhouse!$P922 -> 61 | M15: =[24]Brewhouse!$U922-[24]Brewhouse!$T922 -> 0.11319444 | N15: =[24]Brewhouse!$Z922 -> 0.2375 | O15: =[24]Brewhouse!$AX922 -> R.Sookram | R15: =B15 -> CARIB | S15: =VLOOKUP($B15,$R$3:$X$9,2,FALSE) -> 11.6 | T15: =VLOOKUP($B15,$R$3:$X$9,3,FALSE) -> 12 | U15: =VLOOKUP($B15,$R$3:$X$9,4,FALSE) -> 0 | V15: =VLOOKUP($B15,$R$3:$X$9,5,FALSE) -> 0.11805556 | W15: =VLOOKUP($B15,$R$3:$X$9,6,FALSE) -> 0.22569444 | X15: =VLOOKUP($B15,$R$3:$X$9,7,FALSE) -> 0.26388889 | Y15: =VLOOKUP($B15,$R$3:$Z$9,8,FALSE) -> 0 | Z15: =VLOOKUP($B15,$R$3:$Z$9,9,FALSE) -> 60
B16: CARIB | C16: =[24]Brewhouse!$A923 -> CA808 | D16: =[24]Brewhouse!$AF923 -> 51 | E16: =[24]Brewhouse!$AI923 -> 49.2 | F16: =[24]Brewhouse!$V923 -> 62 | G16: =[24]Brewhouse!AG923 -> 11.8 | H16: 17 | I16: =[24]Brewhouse!$AU923 -> 95.829154 | J16: =[24]Brewhouse!$AV923 -> 96.278352 | K16: =[24]Brewhouse!$Q923 -> 5.3107345 | L16: =[24]Brewhouse!$P923 -> 58 | M16: =[24]Brewhouse!$U923-[24]Brewhouse!$T923 -> 0.10763889 | N16: =[24]Brewhouse!$Z923 -> 0.24513889 | O16: =[24]Brewhouse!$AX923 -> R.Sookram | R16: =B16 -> CARIB | S16: =VLOOKUP($B16,$R$3:$X$9,2,FALSE) -> 11.6 | T16: =VLOOKUP($B16,$R$3:$X$9,3,FALSE) -> 12 | U16: =VLOOKUP($B16,$R$3:$X$9,4,FALSE) -> 0 | V16: =VLOOKUP($B16,$R$3:$X$9,5,FALSE) -> 0.11805556 | W16: =VLOOKUP($B16,$R$3:$X$9,6,FALSE) -> 0.22569444 | X16: =VLOOKUP($B16,$R$3:$X$9,7,FALSE) -> 0.26388889 | Y16: =VLOOKUP($B16,$R$3:$Z$9,8,FALSE) -> 0 | Z16: =VLOOKUP($B16,$R$3:$Z$9,9,FALSE) -> 60
