Workbook
Name ProductList: [1]November15!$R$3:$R$9
Name ProductList: [2]November15!$R$3:$R$9

Sheet Dec 18th
T1: P.G. | V1: Hot Time | X1: Process Time | Z1: Cooling Time
B2: Brewing Department Daily Process Loss Report | T2: Lower | U2: Upper | V2: Lower | W2: Upper | X2: Lower | Y2: Upper | Z2: Lower | AA2: Upper
S3: CARIB | T3: 11.6 | U3: 12 | V3: 0 | W3: 0.11805556 | X3: 0.17361111 | Y3: 0.21180556 | Z3: 0 | AA3: 60 | AC3: HR- PISNER
B4: Date: | C4: 45278 | J4: LOT WORT COLOUR: 3.4 | M4: Filter Sheets (Target 20 days) | S4: STAG | T4: 11.6 | U4: 12 | V4: 0 | W4: 0.11805556 | X4: 0.17361111 | Y4: 0.21180556 | Z4: 0 | AA4: 60
M5: Double | N5: Single | S5: GUINNESS | T5: 17 | U5: 17.5 | V5: 0 | W5: 0.10763889 | X5: 0.19444444 | Y5: 0.23263889 | Z5: 0 | AA5: 60
J6: MALT LOT: Lot 8 | L6: Sheet Day | S6: MACKESON | T6: 13.3 | U6: 13.5 | V6: 0 | W6: 0.12905093 | X6: 0.22222222 | Y6: 0.25347222 | Z6: 0
S7: STARMALT | T7: 17.1 | U7: 17.5 | V7: 0 | W7: 0.13605324 | X7: 0.20833333 | Y7: 0.24305556 | Z7: 0 | AA7: 60
B8: Brand | C8: Brew no. | D8: Kett. Hls | E8: Wort | F8: Cool Time(Mins) | G8: Cast. P.G. (Lab Result) | H8: Cast P.G. (Cellar Operator)-gravity | I8: Extr. Rec (79.1%) | J8: Theor. Extr. (77.5%) | K8: Boil Off /Vol. (4-6%) | L8: Boil Time | M8: Total Hot | N8: Brewing | P8: Comments | Q8: Actual Pilsen Malt | S8: Hurricane Reef | T8: 16.6 | U8: 17 | V8: 0 | W8: 0.12905093 | X8: 0.22222222 | Y8: 0.25347222 | Z8: 0
E9: Meter (Hls) | F9: Target(< 60Mins) | M9: Time | S9: VITAMALT | T9: 14.4 | U9: 14.6 | V9: 0 | W9: 0.13905093 | X9: 0.19097222 | Y9: 0.22569444 | Z9: 0 | AA9: 75
S10: =B10 -> 0 | T10: =VLOOKUP($B10,$S$3:$Y$9,2,FALSE) -> #N/A | U10: =VLOOKUP($B10,$S$3:$Y$9,3,FALSE) -> #N/A | V10: =VLOOKUP($B10,$S$3:$Y$9,4,FALSE) -> #N/A | W10: =VLOOKUP($B10,$S$3:$Y$9,5,FALSE) -> #N/A | X10: =VLOOKUP($B10,$S$3:$Y$9,6,FALSE) -> #N/A | Y10: =VLOOKUP($B10,$S$3:$Y$9,7,FALSE) -> #N/A | Z10: =VLOOKUP($B10,$S$3:$AA$9,8,FALSE) -> #N/A | AA10: =VLOOKUP($B10,$S$3:$AA$9,9,FALSE) -> #N/A
S11: =B11 -> 0 | T11: =VLOOKUP($B11,$S$3:$Y$9,2,FALSE) -> #N/A | U11: =VLOOKUP($B11,$S$3:$Y$9,3,FALSE) -> #N/A | V11: =VLOOKUP($B11,$S$3:$Y$9,4,FALSE) -> #N/A | W11: =VLOOKUP($B11,$S$3:$Y$9,5,FALSE) -> #N/A | X11: =VLOOKUP($B11,$S$3:$Y$9,6,FALSE) -> #N/A | Y11: =VLOOKUP($B11,$S$3:$Y$9,7,FALSE) -> #N/A | Z11: =VLOOKUP($B11,$S$3:$AA$9,8,FALSE) -> #N/A | AA11: =VLOOKUP($B11,$S$3:$AA$9,9,FALSE) -> #N/A
S12: =B12 -> 0 | T12: =VLOOKUP($B12,$S$3:$Y$9,2,FALSE) -> #N/A | U12: =VLOOKUP($B12,$S$3:$Y$9,3,FALSE) -> #N/A | V12: =VLOOKUP($B12,$S$3:$Y$9,4,FALSE) -> #N/A | W12: =VLOOKUP($B12,$S$3:$Y$9,5,FALSE) -> #N/A | X12: =VLOOKUP($B12,$S$3:$Y$9,6,FALSE) -> #N/A | Y12: =VLOOKUP($B12,$S$3:$Y$9,7,FALSE) -> #N/A | Z12: =VLOOKUP($B12,$S$3:$AA$9,8,FALSE) -> #N/A | AA12: =VLOOKUP($B12,$S$3:$AA$9,9,FALSE) -> #N/A
S13: =B13 -> 0 | T13: =VLOOKUP($B13,$S$3:$Y$9,2,FALSE) -> #N/A | U13: =VLOOKUP($B13,$S$3:$Y$9,3,FALSE) -> #N/A | V13: =VLOOKUP($B13,$S$3:$Y$9,4,FALSE) -> #N/A | W13: =VLOOKUP($B13,$S$3:$Y$9,5,FALSE) -> #N/A | X13: =VLOOKUP($B13,$S$3:$Y$9,6,FALSE) -> #N/A | Y13: =VLOOKUP($B13,$S$3:$Y$9,7,FALSE) -> #N/A | Z13: =VLOOKUP($B13,$S$3:$AA$9,8,FALSE) -> #N/A | AA13: =VLOOKUP($B13,$S$3:$AA$9,9,FALSE) -> #N/A
S14: =B14 -> 0 | T14: =VLOOKUP($B14,$S$3:$Y$9,2,FALSE) -> #N/A | U14: =VLOOKUP($B14,$S$3:$Y$9,3,FALSE) -> #N/A | V14: =VLOOKUP($B14,$S$3:$Y$9,4,FALSE) -> #N/A | W14: =VLOOKUP($B14,$S$3:$Y$9,5,FALSE) -> #N/A | X14: =VLOOKUP($B14,$S$3:$Y$9,6,FALSE) -> #N/A | Y14: =VLOOKUP($B14,$S$3:$Y$9,7,FALSE) -> #N/A | Z14: =VLOOKUP($B14,$S$3:$AA$9,8,FALSE) -> #N/A | AA14: =VLOOKUP($B14,$S$3:$AA$9,9,FALSE) -> #N/A
S15: =B15 -> 0 | T15: =VLOOKUP($B15,$S$3:$Y$9,2,FALSE) -> #N/A | U15: =VLOOKUP($B15,$S$3:$Y$9,3,FALSE) -> #N/A | V15: =VLOOKUP($B15,$S$3:$Y$9,4,FALSE) -> #N/A | W15: =VLOOKUP($B15,$S$3:$Y$9,5,FALSE) -> #N/A | X15: =VLOOKUP($B15,$S$3:$Y$9,6,FALSE) -> #N/A | Y15: =VLOOKUP($B15,$S$3:$Y$9,7,FALSE) -> #N/A | Z15: =VLOOKUP($B15,$S$3:$AA$9,8,FALSE) -> #N/A | AA15: =VLOOKUP($B15,$S$3:$AA$9,9,FALSE) -> #N/A
S16: =B16 -> 0 | T16: =VLOOKUP($B16,$S$3:$Y$9,2,FALSE) -> #N/A | U16: =VLOOKUP($B16,$S$3:$Y$9,3,FALSE) -> #N/A | V16: =VLOOKUP($B16,$S$3:$Y$9,4,FALSE) -> #N/A | W16: =VLOOKUP($B16,$S$3:$Y$9,5,FALSE) -> #N/A | X16: =VLOOKUP($B16,$S$3:$Y$9,6,FALSE) -> #N/A | Y16: =VLOOKUP($B16,$S$3:$Y$9,7,FALSE) -> #N/A | Z16: =VLOOKUP($B16,$S$3:$AA$9,8,FALSE) -> #N/A | AA16: =VLOOKUP($B16,$S$3:$AA$9,9,FALSE) -> #N/A
S17: =B17 -> 0 | T17: =VLOOKUP($B17,$S$3:$Y$9,2,FALSE) -> #N/A | U17: =VLOOKUP($B17,$S$3:$Y$9,3,FALSE) -> #N/A | V17: =VLOOKUP($B17,$S$3:$Y$9,4,FALSE) -> #N/A | W17: =VLOOKUP($B17,$S$3:$Y$9,5,FALSE) -> #N/A | X17: =VLOOKUP($B17,$S$3:$Y$9,6,FALSE) -> #N/A | Y17: =VLOOKUP($B17,$S$3:$Y$9,7,FALSE) -> #N/A | Z17: =VLOOKUP($B17,$S$3:$AA$9,8,FALSE) -> #N/A | AA17: =VLOOKUP($B17,$S$3:$AA$9,9,FALSE) -> #N/A
S18: =B18 -> 0 | T18: =VLOOKUP($B18,$S$3:$Y$9,2,FALSE) -> #N/A | U18: =VLOOKUP($B18,$S$3:$Y$9,3,FALSE) -> #N/A | V18: =VLOOKUP($B18,$S$3:$Y$9,4,FALSE) -> #N/A | W18: =VLOOKUP($B18,$S$3:$Y$9,5,FALSE) -> #N/A | X18: =VLOOKUP($B18,$S$3:$Y$9,6,FALSE) -> #N/A | Y18: =VLOOKUP($B18,$S$3:$Y$9,7,FALSE) -> #N/A | Z18: =VLOOKUP($B18,$S$3:$AA$9,8,FALSE) -> #N/A | AA18: =VLOOKUP($B18,$S$3:$AA$9,9,FALSE) -> #N/A
S19: =B19 -> 0 | T19: =VLOOKUP($B19,$S$3:$Y$9,2,FALSE) -> #N/A | U19: =VLOOKUP($B19,$S$3:$Y$9,3,FALSE) -> #N/A | V19: =VLOOKUP($B19,$S$3:$Y$9,4,FALSE) -> #N/A | W19: =VLOOKUP($B19,$S$3:$Y$9,5,FALSE) -> #N/A | X19: =VLOOKUP($B19,$S$3:$Y$9,6,FALSE) -> #N/A | Y19: =VLOOKUP($B19,$S$3:$Y$9,7,FALSE) -> #N/A | Z19: =VLOOKUP($B19,$S$3:$AA$9,8,FALSE) -> #N/A | AA19: =VLOOKUP($B19,$S$3:$AA$9,9,FALSE) -> #N/A
S20: =B20 -> 0 | T20: =VLOOKUP($B20,$S$3:$Y$9,2,FALSE) -> #N/A | U20: =VLOOKUP($B20,$S$3:$Y$9,3,FALSE) -> #N/A | V20: =VLOOKUP($B20,$S$3:$Y$9,4,FALSE) -> #N/A | W20: =VLOOKUP($B20,$S$3:$Y$9,5,FALSE) -> #N/A | X20: =VLOOKUP($B20,$S$3:$Y$9,6,FALSE) -> #N/A | Y20: =VLOOKUP($B20,$S$3:$Y$9,7,FALSE) -> #N/A | Z20: =VLOOKUP($B20,$S$3:$AA$9,8,FALSE) -> #N/A | AA20: =VLOOKUP($B20,$S$3:$AA$9,9,FALSE) -> #N/A
S21: =B21 -> 0 | T21: =VLOOKUP($B21,$S$3:$Y$9,2,FALSE) -> #N/A | U21: =VLOOKUP($B21,$S$3:$Y$9,3,FALSE) -> #N/A | V21: =VLOOKUP($B21,$S$3:$Y$9,4,FALSE) -> #N/A | W21: =VLOOKUP($B21,$S$3:$Y$9,5,FALSE) -> #N/A | X21: =VLOOKUP($B21,$S$3:$Y$9,6,FALSE) -> #N/A | Y21: =VLOOKUP($B21,$S$3:$Y$9,7,FALSE) -> #N/A | Z21: =VLOOKUP($B21,$S$3:$AA$9,8,FALSE) -> #N/A | AA21: =VLOOKUP($B21,$S$3:$AA$9,9,FALSE) -> #N/A
... S47: =B47 -> 0 | T47: =VLOOKUP($B47,$S$3:$Y$9,2,FALSE) -> #N/A | U47: =VLOOKUP($B47,$S$3:$Y$9,3,FALSE) -> #N/A | V47: =VLOOKUP($B47,$S$3:$Y$9,4,FALSE) -> #N/A | W47: =VLOOKUP($B47,$S$3:$Y$9,5,FALSE) -> #N/A | X47: =VLOOKUP($B47,$S$3:$Y$9,6,FALSE) -> #N/A | Y47: =VLOOKUP($B47,$S$3:$Y$9,7,FALSE) -> #N/A | Z47: =VLOOKUP($B47,$S$3:$AA$9,8,FALSE) -> #N/A | AA47: =VLOOKUP($B47,$S$3:$AA$9,9,FALSE) -> #N/A
I48: EXTRACT RECOVERY
B49: BRAND | D49: BBT P.G./ O.G | I49: Brand | J49: Actual | K49: MTD No. of Brews | L49: MTD | M49: YTD | N49: Target
B50: STAG | C50: 11.8 | D50: 11.73 | I50: CARIB | K50: =COUNTA([3]Brewhouse!$A$1596:$A$1619) -> 24 | L50: =AVERAGE([3]Brewhouse!$AU$1529,[3]Brewhouse!$AU$1531:$AU$1594,[3]Brewhouse!$AU$1596:$AU$1619) -> 98.205761 | M50: =AVERAGE([3]Brewhouse!$AU$849:$AU$924,[3]Brewhouse!$AU$926:$AU$971,[3]Brewhouse!$AU$973:$AU$1066,[3]Brewhouse!$AU$1068:$AU$1111,[3]Brewhouse!$AU$1113:$AU$1132,[3]Brewhouse!$AU$1134:$AU$1167,[3]Brewhouse!$AU$1169:$AU$1230,[3]Brewhouse!$AU$1232:$AU$1299,[3]Brewhouse!$AU$1301:$AU$1363,[3]Brewhouse!$AU$1365:$AU$1444,[3]Brewhouse!$AU$1446:$AU$1527,[3]Brewhouse!$AU$1529,[3]Brewhouse!$AU$1531:$AU$1594,[3]Brewhouse!$AU$1596:$AU$1619) -> 98.381806 | N50: 98
C51: 11.9 | I51: STAG | K51: =COUNTA([4]Brewhouse!$A$976:$A$1007) -> 32 | L51: =AVERAGE([4]Brewhouse!$AS$976:$AS$979,[4]Brewhouse!$AS$981:$AS$1007) -> 98.538567 | M51: =AVERAGE([4]Brewhouse!$AS$577:$AS$618,[4]Brewhouse!$AS$620:$AS$651,[4]Brewhouse!$AS$653:$AS$696,[4]Brewhouse!$AS$698:$AS$708,[4]Brewhouse!$AS$710:$AS$733,[4]Brewhouse!$AS$735:$AS$777,[4]Brewhouse!$AS$779:$AS$822,[4]Brewhouse!$AS$824:$AS$863,[4]Brewhouse!$AS$865:$AS$974,[4]Brewhouse!$AS$976:$AS$979,[4]Brewhouse!$AS$981:$AS$1007) -> 98.489671 | N51: 98
I52: GUINNESS | K52: =COUNTA([5]Brewhouse!$A$282:$A$289) -> 8 | L52: =AVERAGE([5]Brewhouse!$AU$269:$AU$279,[5]Brewhouse!$AU$282:$AU$289) -> 96.186177 | M52: =AVERAGE([5]Brewhouse!$AU$161:$AU$176,[5]Brewhouse!$AU$178:$AU$195,[5]Brewhouse!$AU$197:$AU$208,[5]Brewhouse!$AU$210:$AU$221,[5]Brewhouse!$AU$223:$AU$232,[5]Brewhouse!$AU$234:$AU$279,[5]Brewhouse!$AU$282:$AU$289) -> 96.64916 | N52: 98
I53: VITAMALT | K53: =COUNTA([6]Brewhouse!$A$158:$A$163) -> 6 | L53: =AVERAGE([6]Brewhouse!$AU$158:$AU$163) -> 94.60305 | M53: =AVERAGE([6]Brewhouse!$AU$91:$AU$101,[6]Brewhouse!$AU$103:$AU$112,[6]Brewhouse!$AU$114:$AU$123,[6]Brewhouse!$AU$125:$AU$134,[6]Brewhouse!$AU$136:$AU$145,[6]Brewhouse!$AU$147:$AU$156,[6]Brewhouse!$AU$158:$AU$163) -> 96.240014 | N53: 98
I54: MAXIMALT | N54: 98
I55: MACKESON | M55: =AVERAGE([7]Brewhouse!$AT$74:$AT$79) -> 93.959836 | N55: 98
I56: STARMALT | K56: =COUNTA([8]Brewhouse!$A$249:$A$254) -> 6 | L56: =AVERAGE([8]Brewhouse!$AY$249:$AY$254) -> 99.681996 | M56: =AVERAGE([8]Brewhouse!$AY$138:$AY$143,[8]Brewhouse!$AY$145:$AY$153,[8]Brewhouse!$AY$155,[8]Brewhouse!$AY$156:$AY$174,[8]Brewhouse!$AY$176:$AY$185,[8]Brewhouse!$AY$187:$AY$198,[8]Brewhouse!$AY$200:$AY$247,[8]Brewhouse!$AY$249:$AY$254) -> 98.774703 | N56: 98
I57: HR- P | M57: =AVERAGE([9]Brewhouse!$AW$13:$AW$14,[9]Brewhouse!$AW$16:$AW$17) -> 92.042628 | N57: 98
I58: Hurricane Reef | M58: =AVERAGE([9]Brewhouse!$AW$13:$AW$14) -> 88.376943 | N58: 98
K59: =SUM(K50:K58) -> 76 | L59: =((L50*K50)+(L51*K51)+(L52*K52)+(L53*K53)+(L54*K54)+(K57*L57)+(L55*K55)+(L56*K56)+(L58*K58))/(K59) -> 97.965422 | M59: =AVERAGE('[10]Closing- January 2023'!$L$42,'[11]Feb. 28th'!$L$42,'[12]March 31st'!$L$75,'[13]Apri 28th'!$L$51,L59) -> 98.06926 | N59: 98
J62: Daily Brewing Plan
J63: Brand | K63: Brews Achieved | L63: Average Brews per day
J64: CARIB | L64: MTD | M64: YTD | N64: TARGET
J65: STAG | K65: 5 | L65: =AVERAGE(#REF!,#REF!,K74,#REF!,#REF!,#REF!,#REF!,#REF!,#REF!,#REF!,#REF!) -> #REF! | M65: =AVERAGE(6,6,'[12]March 31st'!$L$80,'[14]June 30th '!$L$71,6,L65,'[15]July 31st'!$L$108,'[16]Aug 30th'!$L$124,7,[17]Oct.31st!$L$51) -> #REF! | N65: 9
J66: GUINN
J67: VITAMALT
...

Sheet Oct. 1st
S1: P.G. | U1: Hot Time | W1: Process Time | Y1: Cooling Time
B2: Brewing Department Daily Process Loss Report | S2: Lower | T2: Upper | U2: Lower | V2: Upper | W2: Lower | X2: Upper | Y2: Lower | Z2: Upper
R3: CARIB | S3: 11.6 | T3: 12 | U3: 0 | V3: 0.11805556 | W3: 0.22569444 | X3: 0.26388889 | Y3: 0 | Z3: 60 | AB3: HR- PISNER
B4: Date: | C4: 45932 | J4: LOT WORT COLOUR: 3.3 | M4: Filter Sheets (Target 20 days) | R4: STAG | S4: 11.6 | T4: 12 | U4: 0 | V4: 0.11805556 | W4: 0.22569444 | X4: 0.26388889 | Y4: 0 | Z4: 60
M5: Double | N5: Single | R5: GUINNESS | S5: 17 | T5: 17.5 | U5: 0 | V5: 0.10763889 | W5: 0.24652778 | X5: 0.28472222 | Y5: 0 | Z5: 60
J6: MALT LOT: Lot #3 | L6: Sheet Day | R6: MACKESON | S6: 13.3 | T6: 13.5 | U6: 0 | V6: 0.12905093 | W6: 0.27430556 | X6: 0.30208333 | Y6: 0
R7: STARMALT | S7: 17 | T7: 17.4 | U7: 0 | V7: 0.13605324 | W7: 0.27430556 | X7: 0.30902778 | Y7: 0 | Z7: 85
B8: Brand | C8: Brew no. | D8: Kett. Hls | E8: Wort | F8: Cool Time(Mins) | G8: Cast. P.G. (Lab Result) | H8: Cast P.G. (Cellar Operator)-gravity | I8: Extr. Rec (77.9%) | J8: Theor. Extr. (77.5%) | K8: Boil Off /Vol. (4-6%) | L8: Boil Time | M8: Total Hot | N8: Brewing | O8: Operator | R8: Hurricane Reef | S8: 16.6 | T8: 17 | U8: 0 | V8: 0.12905093 | W8: 0.27430556 | X8: 0.30208333 | Y8: 0
E9: Meter (Hls) | F9: Target(< 60Mins) | M9: Time | R9: VITAMALT | S9: 14.2 | T9: 14.6 | U9: 0 | V9: 0.13905093 | W9: 0.26041667 | X9: 0.29513889 | Y9: 0 | Z9: 75
B10: CARIB | C10: =[22]Brewhouse!$A823 -> CA713 | D10: =[22]Brewhouse!$AF823 -> 55.5 | E10: =[22]Brewhouse!$AI823 -> 49.8 | F10: =[22]Brewhouse!$V823 -> 69 | G10: =[22]Brewhouse!AG823 -> 11.9 | H10: 11.7 | I10: =[22]Brewhouse!$AU823 -> 96.671625 | J10: =[22]Brewhouse!$AV823 -> 98.32118 | K10: =[22]Brewhouse!$Q823 -> 5.2222222 | L10: =[22]Brewhouse!$P823 -> 57 | M10: =[22]Brewhouse!$U823-[22]Brewhouse!$T823 -> 0.12986111 | N10: =[22]Brewhouse!$Z823 -> 0.29444444 | O10: =[22]Brewhouse!$AX823 -> K.Benjamin | R10: =B10 -> CARIB | S10: =VLOOKUP($B10,$R$3:$X$9,2,FALSE) -> 11.6 | T10: =VLOOKUP($B10,$R$3:$X$9,3,FALSE) -> 12 | U10: =VLOOKUP($B10,$R$3:$X$9,4,FALSE) -> 0 | V10: =VLOOKUP($B10,$R$3:$X$9,5,FALSE) -> 0.11805556 | W10: =VLOOKUP($B10,$R$3:$X$9,6,FALSE) -> 0.22569444 | X10: =VLOOKUP($B10,$R$3:$X$9,7,FALSE) -> 0.26388889 | Y10: =VLOOKUP($B10,$R$3:$Z$9,8,FALSE) -> 0 | Z10: =VLOOKUP($B10,$R$3:$Z$9,9,FALSE) -> 60
B11: CARIB | C11: =[22]Brewhouse!$A824 -> CA714 | D11: =[22]Brewhouse!$AF824 -> 55.4 | E11: =[22]Brewhouse!$AI824 -> 50.2 | F11: =[22]Brewhouse!$V824 -> 61 | G11: =[22]Brewhouse!AG824 -> 11.7 | H11: 11.8 | I11: =[22]Brewhouse!$AU824 -> 96.677697 | J11: =[22]Brewhouse!$AV824 -> 98.326291 | K11: =[22]Brewhouse!$Q824 -> 4 | L11: =[22]Brewhouse!$P824 -> 62 | M11: =[22]Brewhouse!$U824-[22]Brewhouse!$T824 -> 0.11597222 | N11: =[22]Brewhouse!$Z824 -> 0.24652778 | O11: =[22]Brewhouse!$AX824 -> K.Benjamin | R11: =B11 -> CARIB | S11: =VLOOKUP($B11,$R$3:$X$9,2,FALSE) -> 11.6 | T11: =VLOOKUP($B11,$R$3:$X$9,3,FALSE) -> 12 | U11: =VLOOKUP($B11,$R$3:$X$9,4,FALSE) -> 0 | V11: =VLOOKUP($B11,$R$3:$X$9,5,FALSE) -> 0.11805556 | W11: =VLOOKUP($B11,$R$3:$X$9,6,FALSE) -> 0.22569444 | X11: =VLOOKUP($B11,$R$3:$X$9,7,FALSE) -> 0.26388889 | Y11: =VLOOKUP($B11,$R$3:$Z$9,8,FALSE) -> 0 | Z11: =VLOOKUP($B11,$R$3:$Z$9,9,FALSE) -> 60
B12: CARIB | C12: =[22]Brewhouse!$A825 -> CA715 | D12: =[22]Brewhouse!$AF825 -> 55.7 | E12: =[22]Brewhouse!$AI825 -> 50.5 | F12: =[22]Brewhouse!$V825 -> 60 | G12: =[22]Brewhouse!AG825 -> 11.7 | H12: 11.7 | I12: =[22]Brewhouse!$AU825 -> 96.53574 | J12: =[22]Brewhouse!$AV825 -> 98.182713 | K12: =[22]Brewhouse!$Q825 -> 2.1132075 | L12: =[22]Brewhouse!$P825 -> 59 | M12: =[22]Brewhouse!$U825-[22]Brewhouse!$T825 -> 0.10694444 | N12: =[22]Brewhouse!$Z825 -> 0.24791667 | O12: =[22]Brewhouse!$AX825 -> K.Benjamin | R12: =B12 -> CARIB | S12: =VLOOKUP($B12,$R$3:$X$9,2,FALSE) -> 11.6 | T12: =VLOOKUP($B12,$R$3:$X$9,3,FALSE) -> 12 | U12: =VLOOKUP($B12,$R$3:$X$9,4,FALSE) -> 0 | V12: =VLOOKUP($B12,$R$3:$X$9,5,FALSE) -> 0.11805556 | W12: =VLOOKUP($B12,$R$3:$X$9,6,FALSE) -> 0.22569444 | X12: =VLOOKUP($B12,$R$3:$X$9,7,FALSE) -> 0.26388889 | Y12: =VLOOKUP($B12,$R$3:$Z$9,8,FALSE) -> 0 | Z12: =VLOOKUP($B12,$R$3:$Z$9,9,FALSE) -> 60
B13: CARIB | C13: =[22]Brewhouse!$A826 -> CA716 | D13: =[22]Brewhouse!$AF826 -> 55.7 | E13: =[22]Brewhouse!$AI826 -> 51.1 | F13: =[22]Brewhouse!$V826 -> 71 | G13: =[22]Brewhouse!AG826 -> 11.9 | H13: 11.7 | I13: =[22]Brewhouse!$AU826 -> 99.073288 | J13: =[22]Brewhouse!$AV826 -> 100.76396 | K13: =[22]Brewhouse!$Q826 -> 0.79245283 | L13: =[22]Brewhouse!$P826 -> 60 | M13: =[22]Brewhouse!$U826-[22]Brewhouse!$T826 -> 0.11388889 | N13: =[22]Brewhouse!$Z826 -> 0.24791667 | O13: =[22]Brewhouse!$AX826 -> K.Benjamin | R13: =B13 -> CARIB | S13: =VLOOKUP($B13,$R$3:$X$9,2,FALSE) -> 11.6 | T13: =VLOOKUP($B13,$R$3:$X$9,3,FALSE) -> 12 | U13: =VLOOKUP($B13,$R$3:$X$9,4,FALSE) -> 0 | V13: =VLOOKUP($B13,$R$3:$X$9,5,FALSE) -> 0.11805556 | W13: =VLOOKUP($B13,$R$3:$X$9,6,FALSE) -> 0.22569444 | X13: =VLOOKUP($B13,$R$3:$X$9,7,FALSE) -> 0.26388889 | Y13: =VLOOKUP($B13,$R$3:$Z$9,8,FALSE) -> 0 | Z13: =VLOOKUP($B13,$R$3:$Z$9,9,FALSE) -> 60
B14: CARIB | C14: =[22]Brewhouse!$A827 -> CA717 | D14: =[22]Brewhouse!$AF827 -> 55.8 | E14: =[22]Brewhouse!$AI827 -> 51.9 | F14: =[22]Brewhouse!$V827 -> 69 | G14: =[22]Brewhouse!AG827 -> 11.4 | H14: 11.4 | I14: =[22]Brewhouse!$AU827 -> 96.893475 | J14: =[22]Brewhouse!$AV827 -> 98.546151 | K14: =[22]Brewhouse!$Q827 -> -0.33962264 | L14: =[22]Brewhouse!$P827 -> 60 | M14: =[22]Brewhouse!$U827-[22]Brewhouse!$T827 -> 0.11041667 | N14: =[22]Brewhouse!$Z827 -> 0.23819444 | O14: =[22]Brewhouse!$AX827 -> K.Benjamin | R14: =B14 -> CARIB | S14: =VLOOKUP($B14,$R$3:$X$9,2,FALSE) -> 11.6 | T14: =VLOOKUP($B14,$R$3:$X$9,3,FALSE) -> 12 | U14: =VLOOKUP($B14,$R$3:$X$9,4,FALSE) -> 0 | V14: =VLOOKUP($B14,$R$3:$X$9,5,FALSE) -> 0.11805556 | W14: =VLOOKUP($B14,$R$3:$X$9,6,FALSE) -> 0.22569444 | X14: =VLOOKUP($B14,$R$3:$X$9,7,FALSE) -> 0.26388889 | Y14: =VLOOKUP($B14,$R$3:$Z$9,8,FALSE) -> 0 | Z14: =VLOOKUP($B14,$R$3:$Z$9,9,FALSE) -> 60
B15: CARIB | C15: =[22]Brewhouse!$A828 -> CA718 | D15: =[22]Brewhouse!$AF828 -> 55.7 | E15: =[22]Brewhouse!$AI828 -> 51.1 | F15: =[22]Brewhouse!$V828 -> 62 | G15: =[22]Brewhouse!AG828 -> 11.7 | H15: 11.6 | I15: =[22]Brewhouse!$AU828 -> 97.6827 | J15: =[22]Brewhouse!$AV828 -> 99.34924 | K15: =[22]Brewhouse!$Q828 -> 2.8679245 | L15: =[22]Brewhouse!$P828 -> 60 | M15: =[22]Brewhouse!$U828-[22]Brewhouse!$T828 -> 0.11944444 | N15: =[22]Brewhouse!$Z828 -> 0.24861111 | O15: =[22]Brewhouse!$AX828 -> K.Benjamin | R15: =B15 -> CARIB | S15: =VLOOKUP($B15,$R$3:$X$9,2,FALSE) -> 11.6 | T15: =VLOOKUP($B15,$R$3:$X$9,3,FALSE) -> 12 | U15: =VLOOKUP($B15,$R$3:$X$9,4,FALSE) -> 0 | V15: =VLOOKUP($B15,$R$3:$X$9,5,FALSE) -> 0.11805556 | W15: =VLOOKUP($B15,$R$3:$X$9,6,FALSE) -> 0.22569444 | X15: =VLOOKUP($B15,$R$3:$X$9,7,FALSE) -> 0.26388889 | Y15: =VLOOKUP($B15,$R$3:$Z$9,8,FALSE) -> 0 | Z15: =VLOOKUP($B15,$R$3:$Z$9,9,FALSE) -> 60
B16: CARIB | C16: =[22]Brewhouse!$A829 -> CA719 | D16: =[22]Brewhouse!$AF829 -> 55.7 | E16: =[22]Brewhouse!$AI829 -> 51.8 | F16: =[22]Brewhouse!$V829 -> 74 | G16: =[22]Brewhouse!AG829 -> 11.7 | H16: 11.6 | I16: =[22]Brewhouse!$AU829 -> 99.511758 | J16: =[22]Brewhouse!$AV829 -> 101.20896 | K16: =[22]Brewhouse!$Q829 -> 1.9245283 | L16: =[22]Brewhouse!$P829 -> 60 | M16: =[22]Brewhouse!$U829-[22]Brewhouse!$T829 -> 0.12361111 | N16: =[22]Brewhouse!$Z829 -> 0.25555556 | O16: =[22]Brewhouse!$AX829 -> K.Benjamin | R16: =B16 -> CARIB | S16: =VLOOKUP($B16,$R$3:$X$9,2,FALSE) -> 11.6 | T16: =VLOOKUP($B16,$R$3:$X$9,3,FALSE) -> 12 | U16: =VLOOKUP($B16,$R$3:$X$9,4,FALSE) -> 0 | V16: =VLOOKUP($B16,$R$3:$X$9,5,FALSE) -> 0.11805556 | W16: =VLOOKUP($B16,$R$3:$X$9,6,FALSE) -> 0.22569444 | X16: =VLOOKUP($B16,$R$3:$X$9,7,FALSE) -> 0.26388889 | Y16: =VLOOKUP($B16,$R$3:$Z$9,8,FALSE) -> 0 | Z16: =VLOOKUP($B16,$R$3:$Z$9,9,FALSE) -> 60
B17: CARIB | C17: =[22]Brewhouse!$A830 -> CA720 | D17: =[22]Brewhouse!$AF830 -> 55.3 | E17: =[22]Brewhouse!$AI830 -> 52.5 | F17: =[22]Brewhouse!$V830 -> 83 | G17: =[22]Brewhouse!AG830 -> 11.6 | H17: 11.6 | I17: =[22]Brewhouse!$AU830 -> 99.94938 | J17: =[22]Brewhouse!$AV830 -> 101.65404 | K17: =[22]Brewhouse!$Q830 -> 1.7358491 | L17: =[22]Brewhouse!$P830 -> 60 | M17: =[22]Brewhouse!$U830-[22]Brewhouse!$T830 -> 0.12986111 | N17: =[22]Brewhouse!$Z830 -> 0.27083333 | O17: =[22]Brewhouse!$AX830 -> K.Benjamin | R17: =B17 -> CARIB | S17: =VLOOKUP($B17,$R$3:$X$9,2,FALSE) -> 11.6 | T17: =VLOOKUP($B17,$R$3:$X$9,3,FALSE) -> 12 | U17: =VLOOKUP($B17,$R$3:$X$9,4,FALSE) -> 0 | V17: =VLOOKUP($B17,$R$3:$X$9,5,FALSE) -> 0.11805556 | W17: =VLOOKUP($B17,$R$3:$X$9,6,FALSE) -> 0.22569444 | X17: =VLOOKUP($B17,$R$3:$X$9,7,FALSE) -> 0.26388889 | Y17: =VLOOKUP($B17,$R$3:$Z$9,8,FALSE) -> 0 | Z17: =VLOOKUP($B17,$R$3:$Z$9,9,FALSE) -> 60
B18: CARIB | C18: =[22]Brewhouse!$A831 -> CA721 | D18: =[22]Brewhouse!$AF831 -> 55.1 | E18: =[22]Brewhouse!$AI831 -> 46.7 | F18: =[22]Brewhouse!$V831 -> 72 | G18: =[22]Brewhouse!AG831 -> 12 | H18: 11.9 | I18: =[22]Brewhouse!$AU831 -> 92.135013 | J18: =[22]Brewhouse!$AV831 -> 93.706398 | K18: =[22]Brewhouse!$Q831 -> 4.7457627 | L18: =[22]Brewhouse!$P831 -> 58 | M18: =[22]Brewhouse!$U831-[22]Brewhouse!$T831 -> 0.12083333 | N18: =[22]Brewhouse!$Z831 -> 0.25138889 | O18: =[22]Brewhouse!$AX831 -> R.Sookram | R18: =B18 -> CARIB | S18: =VLOOKUP($B18,$R$3:$X$9,2,FALSE) -> 11.6 | T18: =VLOOKUP($B18,$R$3:$X$9,3,FALSE) -> 12 | U18: =VLOOKUP($B18,$R$3:$X$9,4,FALSE) -> 0 | V18: =VLOOKUP($B18,$R$3:$X$9,5,FALSE) -> 0.11805556 | W18: =VLOOKUP($B18,$R$3:$X$9,6,FALSE) -> 0.22569444 | X18: =VLOOKUP($B18,$R$3:$X$9,7,FALSE) -> 0.26388889 | Y18: =VLOOKUP($B18,$R$3:$Z$9,8,FALSE) -> 0 | Z18: =VLOOKUP($B18,$R$3:$Z$9,9,FALSE) -> 60
B19: CARIB | C19: =[22]Brewhouse!$A832 -> CA722 | D19: =[22]Brewhouse!$AF832 -> 55.6 | E19: =[22]Brewhouse!$AI832 -> 50 | F19: =[22]Brewhouse!$V832 -> 67 | G19: =[22]Brewhouse!AG832 -> 11.8 | H19: 11.7 | I19: =[22]Brewhouse!$AU832 -> 97.158609 | J19: =[22]Brewhouse!$AV832 -> 98.815403 | K19: =[22]Brewhouse!$Q832 -> 3.2391714 | L19: =[22]Brewhouse!$P832 -> 60 | M19: =[22]Brewhouse!$U832-[22]Brewhouse!$T832 -> 0.11319444 | N19: =[22]Brewhouse!$Z832 -> 0.2625 | O19: =[22]Brewhouse!$AX832 -> R.Sookram | R19: =B19 -> CARIB | S19: =VLOOKUP($B19,$R$3:$X$9,2,FALSE) -> 11.6 | T19: =VLOOKUP($B19,$R$3:$X$9,3,FALSE) -> 12 | U19: =VLOOKUP($B19,$R$3:$X$9,4,FALSE) -> 0 | V19: =VLOOKUP($B19,$R$3:$X$9,5,FALSE) -> 0.11805556 | W19: =VLOOKUP($B19,$R$3:$X$9,6,FALSE) -> 0.22569444 | X19: =VLOOKUP($B19,$R$3:$X$9,7,FALSE) -> 0.26388889 | Y19: =VLOOKUP($B19,$R$3:$Z$9,8,FALSE) -> 0 | Z19: =VLOOKUP($B19,$R$3:$Z$9,9,FALSE) -> 60
R20: =B20 -> 0 | S20: =VLOOKUP($B20,$R$3:$X$9,2,FALSE) -> #N/A | T20: =VLOOKUP($B20,$R$3:$X$9,3,FALSE) -> #N/A | U20: =VLOOKUP($B20,$R$3:$X$9,4,FALSE) -> #N/A | V20: =VLOOKUP($B20,$R$3:$X$9,5,FALSE) -> #N/A | W20: =VLOOKUP($B20,$R$3:$X$9,6,FALSE) -> #N/A | X20: =VLOOKUP($B20,$R$3:$X$9,7,FALSE) -> #N/A | Y20: =VLOOKUP($B20,$R$3:$Z$9,8,FALSE) -> #N/A | Z20: =VLOOKUP($B20,$R$3:$Z$9,9,FALSE) -> #N/A
R21: =B21 -> 0 | S21: =VLOOKUP($B21,$R$3:$X$9,2,FALSE) -> #N/A | T21: =VLOOKUP($B21,$R$3:$X$9,3,FALSE) -> #N/A | U21: =VLOOKUP($B21,$R$3:$X$9,4,FALSE) -> #N/A | V21: =VLOOKUP($B21,$R$3:$X$9,5,FALSE) -> #N/A | W21: =VLOOKUP($B21,$R$3:$X$9,6,FALSE) -> #N/A | X21: =VLOOKUP($B21,$R$3:$X$9,7,FALSE) -> #N/A | Y21: =VLOOKUP($B21,$R$3:$Z$9,8,FALSE) -> #N/A | Z21: =VLOOKUP($B21,$R$3:$Z$9,9,FALSE) -> #N/A
R22: =B22 -> 0 | S22: =VLOOKUP($B22,$R$3:$X$9,2,FALSE) -> #N/A | T22: =VLOOKUP($B22,$R$3:$X$9,3,FALSE) -> #N/A | U22: =VLOOKUP($B22,$R$3:$X$9,4,FALSE) -> #N/A | V22: =VLOOKUP($B22,$R$3:$X$9,5,FALSE) -> #N/A | W22: =VLOOKUP($B22,$R$3:$X$9,6,FALSE) -> #N/A | X22: =VLOOKUP($B22,$R$3:$X$9,7,FALSE) -> #N/A | Y22: =VLOOKUP($B22,$R$3:$Z$9,8,FALSE) -> #N/A | Z22: =VLOOKUP($B22,$R$3:$Z$9,9,FALSE) -> #N/A
R23: =B23 -> 0 | S23: =VLOOKUP($B23,$R$3:$X$9,2,FALSE) -> #N/A | T23: =VLOOKUP($B23,$R$3:$X$9,3,FALSE) -> #N/A | U23: =VLOOKUP($B23,$R$3:$X$9,4,FALSE) -> #N/A | V23: =VLOOKUP($B23,$R$3:$X$9,5,FALSE) -> #N/A | W23: =VLOOKUP($B23,$R$3:$X$9,6,FALSE) -> #N/A | X23: =VLOOKUP($B23,$R$3:$X$9,7,FALSE) -> #N/A | Y23: =VLOOKUP($B23,$R$3:$Z$9,8,FALSE) -> #N/A | Z23: =VLOOKUP($B23,$R$3:$Z$9,9,FALSE) -> #N/A
B24: BRAND | D24: BBT P.G./ O.G | I24: Brand | J24: Actual | K24: MTD No. of Brews | L24: MTD | M24: YTD | N24: Target | R24: =B24 -> BRAND | S24: =VLOOKUP($B24,$R$3:$X$9,2,FALSE) -> #N/A | T24: =VLOOKUP($B24,$R$3:$X$9,3,FALSE) -> #N/A | U24: =VLOOKUP($B24,$R$3:$X$9,4,FALSE) -> #N/A | V24: =VLOOKUP($B24,$R$3:$X$9,5,FALSE) -> #N/A | W24: =VLOOKUP($B24,$R$3:$X$9,6,FALSE) -> #N/A | X24: =VLOOKUP($B24,$R$3:$X$9,7,FALSE) -> #N/A | Y24: =VLOOKUP($B24,$R$3:$Z$9,8,FALSE) -> #N/A | Z24: =VLOOKUP($B24,$R$3:$Z$9,9,FALSE) -> #N/A
B25: =I26 -> STAG | C25: =[23]Process!D371 -> 11.5 | D25: 11.86 | I25: CARIB | J25: =AVERAGE(I10:I19) -> 97.228929 | K25: =COUNTA([22]Brewhouse!$A$823:$A$832) -> 10 | L25: =AVERAGE([22]Brewhouse!$AU$823:$AU$832) -> 97.228929 | M25: =AVERAGE([22]Brewhouse!$AU$102:$AU$171,[22]Brewhouse!$AU$173:$AU$253,[22]Brewhouse!$AU$255:$AU$339,[22]Brewhouse!$AU$341:$AU$346,[22]Brewhouse!$AU$348,[22]Brewhouse!$AU$349:$AU$406,[22]Brewhouse!$AU$408:$AU$491,[22]Brewhouse!$AU$493:$AU$578,[22]Brewhouse!$AU$580:$AU$652,[22]Brewhouse!$AU$655:$AU$738,[22]Brewhouse!$A$740:$A$821,[22]Brewhouse!$AU$823:$AU$832) -> 97.699765 | N25: 98 | R25: =B25 -> STAG | S25: =VLOOKUP($B25,$R$3:$X$9,2,FALSE) -> 11.6 | T25: =VLOOKUP($B25,$R$3:$X$9,3,FALSE) -> 12 | U25: =VLOOKUP($B25,$R$3:$X$9,4,FALSE) -> 0 | V25: =VLOOKUP($B25,$R$3:$X$9,5,FALSE) -> 0.11805556 | W25: =VLOOKUP($B25,$R$3:$X$9,6,FALSE) -> 0.22569444 | X25: =VLOOKUP($B25,$R$3:$X$9,7,FALSE) -> 0.26388889 | Y25: =VLOOKUP($B25,$R$3:$Z$9,8,FALSE) -> 0 | Z25: =VLOOKUP($B25,$R$3:$Z$9,9,FALSE) -> 60
C26: =[23]Process!D372 -> 11.9 | I26: STAG | M26: =AVERAGE([23]Brewhouse!$AS$15:$AS$64,[23]Brewhouse!$AS$66:$AS$103,[23]Brewhouse!$AS$105:$AS$140,[23]Brewhouse!$AS$142:$AS$193,[23]Brewhouse!$AS$195:$AS$240,[23]Brewhouse!$AS$242:$AS$273,[23]Brewhouse!$AS$275:$AS$322,[23]Brewhouse!$AS$324:$AS$359,[23]Brewhouse!$AS$361:$AS$397) -> 97.99635 | N26: 98 | R26: =B26 -> 0 | S26: =VLOOKUP($B26,$R$3:$X$9,2,FALSE) -> #N/A | T26: =VLOOKUP($B26,$R$3:$X$9,3,FALSE) -> #N/A | U26: =VLOOKUP($B26,$R$3:$X$9,4,FALSE) -> #N/A | V26: =VLOOKUP($B26,$R$3:$X$9,5,FALSE) -> #N/A | W26: =VLOOKUP($B26,$R$3:$X$9,6,FALSE) -> #N/A | X26: =VLOOKUP($B26,$R$3:$X$9,7,FALSE) -> #N/A | Y26: =VLOOKUP($B26,$R$3:$Z$9,8,FALSE) -> #N/A | Z26: =VLOOKUP($B26,$R$3:$Z$9,9,FALSE) -> #N/A
C27: =[23]Process!D373 -> 11.9 | D27: 11.86 | I27: GUINNESS | M27: =AVERAGE([24]Brewhouse!$AU$4:$AU$7,[24]Brewhouse!$AU$9:$AU$22,[24]Brewhouse!$AU$24:$AU$35,[24]Brewhouse!$AU$37:$AU$45,[24]Brewhouse!$AU$47:$AU$62,[24]Brewhouse!$AU$64:$AU$79,[24]Brewhouse!$AU$81:$AU$92,[24]Brewhouse!$AU$94:$AU$97) -> 96.8166 | N27: 98 | R27: =B27 -> 0 | S27: =VLOOKUP($B27,$R$3:$X$9,2,FALSE) -> #N/A | T27: =VLOOKUP($B27,$R$3:$X$9,3,FALSE) -> #N/A | U27: =VLOOKUP($B27,$R$3:$X$9,4,FALSE) -> #N/A | V27: =VLOOKUP($B27,$R$3:$X$9,5,FALSE) -> #N/A | W27: =VLOOKUP($B27,$R$3:$X$9,6,FALSE) -> #N/A | X27: =VLOOKUP($B27,$R$3:$X$9,7,FALSE) -> #N/A | Y27: =VLOOKUP($B27,$R$3:$Z$9,8,FALSE) -> #N/A | Z27: =VLOOKUP($B27,$R$3:$Z$9,9,FALSE) -> #N/A
C28: =[23]Process!D374 -> 11.9 | I28: VITAMALT | M28: =AVERAGE([25]Brewhouse!$AV$5:$AV$14,[25]Brewhouse!$AV$16:$AV$19,[25]Brewhouse!$AV$21:$AV$24,[25]Brewhouse!$AV$26:$AV$33,[25]Brewhouse!$AV$35:$AV$46,[25]Brewhouse!$AV$48:$AV$53,[25]Brewhouse!$AV$55:$AV$62,[25]Brewhouse!$AV$64:$AV$77,[25]Brewhouse!$AV$79:$AV$86) -> 98.293408 | N28: 98 | R28: =B28 -> 0 | S28: =VLOOKUP($B28,$R$3:$X$9,2,FALSE) -> #N/A | T28: =VLOOKUP($B28,$R$3:$X$9,3,FALSE) -> #N/A | U28: =VLOOKUP($B28,$R$3:$X$9,4,FALSE) -> #N/A | V28: =VLOOKUP($B28,$R$3:$X$9,5,FALSE) -> #N/A | W28: =VLOOKUP($B28,$R$3:$X$9,6,FALSE) -> #N/A | X28: =VLOOKUP($B28,$R$3:$X$9,7,FALSE) -> #N/A | Y28: =VLOOKUP($B28,$R$3:$Z$9,8,FALSE) -> #N/A | Z28: =VLOOKUP($B28,$R$3:$Z$9,9,FALSE) -> #N/A
C29: =[23]Process!D375 -> 11.6 | D29: 11.82 | I29: MAXIMALT | N29: 98 | R29: =B29 -> 0 | S29: =VLOOKUP($B29,$R$3:$X$9,2,FALSE) -> #N/A | T29: =VLOOKUP($B29,$R$3:$X$9,3,FALSE) -> #N/A | U29: =VLOOKUP($B29,$R$3:$X$9,4,FALSE) -> #N/A | V29: =VLOOKUP($B29,$R$3:$X$9,5,FALSE) -> #N/A | W29: =VLOOKUP($B29,$R$3:$X$9,6,FALSE) -> #N/A | X29: =VLOOKUP($B29,$R$3:$X$9,7,FALSE) -> #N/A | Y29: =VLOOKUP($B29,$R$3:$Z$9,8,FALSE) -> #N/A | Z29: =VLOOKUP($B29,$R$3:$Z$9,9,FALSE) -> #N/A
C30: =[23]Process!D376 -> 11.8 | I30: MACKESON | M30: =AVERAGE([26]Brewhouse!$AT$4:$AT$11,[26]Brewhouse!$AT$13:$AT$16,[26]Brewhouse!$AT$18:$AT$21,[26]Brewhouse!$AT$26,[26]Brewhouse!$AT$28:$AT$35) -> 94.794664 | N30: 98 | R30: =B30 -> 0 | S30: =VLOOKUP($B30,$R$3:$X$9,2,FALSE) -> #N/A | T30: =VLOOKUP($B30,$R$3:$X$9,3,FALSE) -> #N/A | U30: =VLOOKUP($B30,$R$3:$X$9,4,FALSE) -> #N/A | V30: =VLOOKUP($B30,$R$3:$X$9,5,FALSE) -> #N/A | W30: =VLOOKUP($B30,$R$3:$X$9,6,FALSE) -> #N/A | X30: =VLOOKUP($B30,$R$3:$X$9,7,FALSE) -> #N/A | Y30: =VLOOKUP($B30,$R$3:$Z$9,8,FALSE) -> #N/A | Z30: =VLOOKUP($B30,$R$3:$Z$9,9,FALSE) -> #N/A
C31: =[23]Process!D377 -> 12.1 | D31: 12.03 | I31: STARMALT | M31: =AVERAGE([27]Brewhouse!$AY$6:$AY$13,[27]Brewhouse!$AY$15:$AY$20,[27]Brewhouse!$AY$22:$AY$29,[27]Brewhouse!$AY$31:$AY$34,[27]Brewhouse!$AY$36:$AY$43,[27]Brewhouse!$AY$45:$AY$50, [27]Brewhouse!$AY$56:$AY$73,[27]Brewhouse!$AY$75:$AY$92) -> 97.477741 | N31: 98 | R31: =B31 -> 0 | S31: =VLOOKUP($B31,$R$3:$X$9,2,FALSE) -> #N/A | T31: =VLOOKUP($B31,$R$3:$X$9,3,FALSE) -> #N/A | U31: =VLOOKUP($B31,$R$3:$X$9,4,FALSE) -> #N/A | V31: =VLOOKUP($B31,$R$3:$X$9,5,FALSE) -> #N/A | W31: =VLOOKUP($B31,$R$3:$X$9,6,FALSE) -> #N/A | X31: =VLOOKUP($B31,$R$3:$X$9,7,FALSE) -> #N/A | Y31: =VLOOKUP($B31,$R$3:$Z$9,8,FALSE) -> #N/A | Z31: =VLOOKUP($B31,$R$3:$Z$9,9,FALSE) -> #N/A
C32: =[23]Process!D378 -> 11.9 | I32: HR- Pils | M32: =AVERAGE([28]Brewhouse!$AU$5:$AU$8,[28]Brewhouse!$AU$10:$AU$13,[27]Brewhouse!$AY$75:$AY$77) -> 94.749192 | N32: 98 | R32: =B32 -> 0 | S32: =VLOOKUP($B32,$R$3:$X$9,2,FALSE) -> #N/A | T32: =VLOOKUP($B32,$R$3:$X$9,3,FALSE) -> #N/A | U32: =VLOOKUP($B32,$R$3:$X$9,4,FALSE) -> #N/A | V32: =VLOOKUP($B32,$R$3:$X$9,5,FALSE) -> #N/A | W32: =VLOOKUP($B32,$R$3:$X$9,6,FALSE) -> #N/A | X32: =VLOOKUP($B32,$R$3:$X$9,7,FALSE) -> #N/A | Y32: =VLOOKUP($B32,$R$3:$Z$9,8,FALSE) -> #N/A | Z32: =VLOOKUP($B32,$R$3:$Z$9,9,FALSE) -> #N/A
C33: =[23]Process!D379 -> 11.6 | D33: 11.95 | I33: HR- IPA | M33: =AVERAGE([29]Brewhouse!$AW$26:$AW$27) -> 95.310681 | N33: 98 | R33: =B33 -> 0 | S33: =VLOOKUP($B33,$R$3:$X$9,2,FALSE) -> #N/A | T33: =VLOOKUP($B33,$R$3:$X$9,3,FALSE) -> #N/A | U33: =VLOOKUP($B33,$R$3:$X$9,4,FALSE) -> #N/A | V33: =VLOOKUP($B33,$R$3:$X$9,5,FALSE) -> #N/A | W33: =VLOOKUP($B33,$R$3:$X$9,6,FALSE) -> #N/A | X33: =VLOOKUP($B33,$R$3:$X$9,7,FALSE) -> #N/A | Y33: =VLOOKUP($B33,$R$3:$Z$9,8,FALSE) -> #N/A | Z33: =VLOOKUP($B33,$R$3:$Z$9,9,FALSE) -> #N/A
C34: =[23]Process!D380 -> 12 | I34: HR- APA | M34: =AVERAGE([30]Brewhouse!$AU$13:$AU$14) -> 97.110575 | N34: 98 | R34: =B34 -> 0 | S34: =VLOOKUP($B34,$R$3:$X$9,2,FALSE) -> #N/A | T34: =VLOOKUP($B34,$R$3:$X$9,3,FALSE) -> #N/A | U34: =VLOOKUP($B34,$R$3:$X$9,4,FALSE) -> #N/A | V34: =VLOOKUP($B34,$R$3:$X$9,5,FALSE) -> #N/A | W34: =VLOOKUP($B34,$R$3:$X$9,6,FALSE) -> #N/A | X34: =VLOOKUP($B34,$R$3:$X$9,7,FALSE) -> #N/A | Y34: =VLOOKUP($B34,$R$3:$Z$9,8,FALSE) -> #N/A | Z34: =VLOOKUP($B34,$R$3:$Z$9,9,FALSE) -> #N/A
K35: =SUM(K25:K34) -> 10 | L35: =((L25*K25)+(L26*K26)+(L27*K27)+(L28*K28)+(L29*K29)+(K32*L32)+(L30*K30)+(L31*K31)+(L34*K34))/(K35) -> 97.228929 | M35: =AVERAGE('[31]Jan 31st'!$L$65,'[32]Feb 28th'!$L$35,'[33]Mar. 31st'!$L$35,'[34]Apr. 30th'!$L$45,'[35]May 30th'!$L$37,'[36]June 30th'!$L$57,'[37]July 29th '!$L$44,'[38]Aug 29th'!$L$29,'[39]Sept 30th'!$L$35,L35) -> 97.540843 | N35: 98 | R35: =B35 -> 0 | S35: =VLOOKUP($B35,$R$3:$X$9,2,FALSE) -> #N/A | T35: =VLOOKUP($B35,$R$3:$X$9,3,FALSE) -> #N/A | U35: =VLOOKUP($B35,$R$3:$X$9,4,FALSE) -> #N/A | V35: =VLOOKUP($B35,$R$3:$X$9,5,FALSE) -> #N/A | W35: =VLOOKUP($B35,$R$3:$X$9,6,FALSE) -> #N/A | X35: =VLOOKUP($B35,$R$3:$X$9,7,FALSE) -> #N/A | Y35: =VLOOKUP($B35,$R$3:$Z$9,8,FALSE) -> #N/A | Z35: =VLOOKUP($B35,$R$3:$Z$9,9,FALSE) -> #N/A
R36: =B36 -> 0 | S36: =VLOOKUP($B36,$R$3:$X$9,2,FALSE) -> #N/A | T36: =VLOOKUP($B36,$R$3:$X$9,3,FALSE) -> #N/A | U36: =VLOOKUP($B36,$R$3:$X$9,4,FALSE) -> #N/A | V36: =VLOOKUP($B36,$R$3:$X$9,5,FALSE) -> #N/A | W36: =VLOOKUP($B36,$R$3:$X$9,6,FALSE) -> #N/A | X36: =VLOOKUP($B36,$R$3:$X$9,7,FALSE) -> #N/A | Y36: =VLOOKUP($B36,$R$3:$Z$9,8,FALSE) -> #N/A | Z36: =VLOOKUP($B36,$R$3:$Z$9,9,FALSE) -> #N/A
B37: =I25 -> CARIB | C37: =[22]Process!D784 -> 11.4 | D37: 11.77 | J37: Daily Brewing Plan
C38: =[22]Process!D785 -> 12.2 | J38: Brand | K38: Brews Achieved | L38: Average Brews per day
J39: CARIB | K39: 10 | L39: MTD | M39: YTD | N39: TARGET
J40: STAG | L40: =K49 -> 10 | M40: =AVERAGE('[31]Jan 29th '!$M$70,'[32]Feb 28th'!$L$40,'[33]Mar. 31st'!$L$40,'[34]Apr. 30th'!$L$50,'[35]May 30th'!$L$42,'[36]June 30th'!$L$62,'[37]July 29th '!$L$49,'[38]Aug 29th'!$L$34,'[39]Sept 30th'!$L$40,L40) -> 7.3061278 | N40: 9.2
...

Sheet Oct. 2nd
S1: P.G. | U1: Hot Time | W1: Process Time | Y1: Cooling Time
B2: Brewing Department Daily Process Loss Report | S2: Lower | T2: Upper | U2: Lower | V2: Upper | W2: Lower | X2: Upper | Y2: Lower | Z2: Upper
R3: CARIB | S3: 11.6 | T3: 12 | U3: 0 | V3: 0.11805556 | W3: 0.22569444 | X3: 0.26388889 | Y3: 0 | Z3: 60 | AB3: HR- PISNER
B4: Date: | C4: 45933 | J4: LOT WORT COLOUR: 3.3 | M4: Filter Sheets (Target 20 days) | R4: STAG | S4: 11.6 | T4: 12 | U4: 0 | V4: 0.11805556 | W4: 0.22569444 | X4: 0.26388889 | Y4: 0 | Z4: 60
M5: Double | N5: Single | R5: GUINNESS | S5: 17 | T5: 17.5 | U5: 0 | V5: 0.10763889 | W5: 0.24652778 | X5: 0.28472222 | Y5: 0 | Z5: 60
J6: MALT LOT: Lot #3 | L6: Sheet Day | R6: MACKESON | S6: 13.3 | T6: 13.5 | U6: 0 | V6: 0.12905093 | W6: 0.27430556 | X6: 0.30208333 | Y6: 0
R7: STARMALT | S7: 17 | T7: 17.4 | U7: 0 | V7: 0.13605324 | W7: 0.27430556 | X7: 0.30902778 | Y7: 0 | Z7: 85
B8: Brand | C8: Brew no. | D8: Kett. Hls | E8: Wort | F8: Cool Time(Mins) | G8: Cast. P.G. (Lab Result) | H8: Cast P.G. (Cellar Operator)-gravity | I8: Extr. Rec (77.9%) | J8: Theor. Extr. (77.5%) | K8: Boil Off /Vol. (4-6%) | L8: Boil Time | M8: Total Hot | N8: Brewing | O8: Operator | R8: Hurricane Reef | S8: 16.6 | T8: 17 | U8: 0 | V8: 0.12905093 | W8: 0.27430556 | X8: 0.30208333 | Y8: 0
E9: Meter (Hls) | F9: Target(< 60Mins) | M9: Time | R9: VITAMALT | S9: 14.2 | T9: 14.6 | U9: 0 | V9: 0.13905093 | W9: 0.26041667 | X9: 0.29513889 | Y9: 0 | Z9: 75
B10: CARIB | C10: =[22]Brewhouse!$A833 -> CA723 | D10: =[22]Brewhouse!$AF833 -> 50.3 | E10: =[22]Brewhouse!$AI833 -> 49.9 | F10: =[22]Brewhouse!$V833 -> 60 | G10: =[22]Brewhouse!AG833 -> 11.8 | H10: 11.8 | I10: =[22]Brewhouse!$AU833 -> 97.448637 | J10: =[22]Brewhouse!$AV833 -> 99.109832 | K10: =[22]Brewhouse!$Q833 -> 6.4528302 | L10: =[22]Brewhouse!$P833 -> 0 | M10: =[22]Brewhouse!$U833-[22]Brewhouse!$T833 -> 0.11666667 | N10: =[22]Brewhouse!$Z833 -> 0.25833333 | O10: =[22]Brewhouse!$AX833 -> R.Sookram | R10: =B10 -> CARIB | S10: =VLOOKUP($B10,$R$3:$X$9,2,FALSE) -> 11.6 | T10: =VLOOKUP($B10,$R$3:$X$9,3,FALSE) -> 12 | U10: =VLOOKUP($B10,$R$3:$X$9,4,FALSE) -> 0 | V10: =VLOOKUP($B10,$R$3:$X$9,5,FALSE) -> 0.11805556 | W10: =VLOOKUP($B10,$R$3:$X$9,6,FALSE) -> 0.22569444 | X10: =VLOOKUP($B10,$R$3:$X$9,7,FALSE) -> 0.26388889 | Y10: =VLOOKUP($B10,$R$3:$Z$9,8,FALSE) -> 0 | Z10: =VLOOKUP($B10,$R$3:$Z$9,9,FALSE) -> 60
B11: CARIB | C11: =[22]Brewhouse!$A834 -> CA724 | D11: =[22]Brewhouse!$AF834 -> 52.6 | E11: =[22]Brewhouse!$AI834 -> 50.8 | F11: =[22]Brewhouse!$V834 -> 55 | G11: =[22]Brewhouse!AG834 -> 11.6 | H11: 11.8 | I11: =[22]Brewhouse!$AU834 -> 96.712924 | J11: =[22]Brewhouse!$AV834 -> 98.362387 | K11: =[22]Brewhouse!$Q834 -> 2.1132075 | L11: =[22]Brewhouse!$P834 -> 60 | M11: =[22]Brewhouse!$U834-[22]Brewhouse!$T834 -> 0.11388889 | N11: =[22]Brewhouse!$Z834 -> 0.25208333 | O11: =[22]Brewhouse!$AX834 -> K.Benjamin | R11: =B11 -> CARIB | S11: =VLOOKUP($B11,$R$3:$X$9,2,FALSE) -> 11.6 | T11: =VLOOKUP($B11,$R$3:$X$9,3,FALSE) -> 12 | U11: =VLOOKUP($B11,$R$3:$X$9,4,FALSE) -> 0 | V11: =VLOOKUP($B11,$R$3:$X$9,5,FALSE) -> 0.11805556 | W11: =VLOOKUP($B11,$R$3:$X$9,6,FALSE) -> 0.22569444 | X11: =VLOOKUP($B11,$R$3:$X$9,7,FALSE) -> 0.26388889 | Y11: =VLOOKUP($B11,$R$3:$Z$9,8,FALSE) -> 0 | Z11: =VLOOKUP($B11,$R$3:$Z$9,9,FALSE) -> 60
B12: CARIB | C12: =[22]Brewhouse!$A835 -> CA725 | D12: =[22]Brewhouse!$AF835 -> 51.3 | E12: =[22]Brewhouse!$AI835 -> 50.4 | F12: =[22]Brewhouse!$V835 -> 61 | G12: =[22]Brewhouse!AG835 -> 11.6 | H12: 11.8 | I12: =[22]Brewhouse!$AU835 -> 96.309528 | J12: =[22]Brewhouse!$AV835 -> 97.951709 | K12: =[22]Brewhouse!$Q835 -> 4.5660377 | L12: =[22]Brewhouse!$P835 -> 61 | M12: =[22]Brewhouse!$U835-[22]Brewhouse!$T835 -> 0.12152778 | N12: =[22]Brewhouse!$Z835 -> 0.26180556 | O12: =[22]Brewhouse!$AX835 -> K.Benjamin | R12: =B12 -> CARIB | S12: =VLOOKUP($B12,$R$3:$X$9,2,FALSE) -> 11.6 | T12: =VLOOKUP($B12,$R$3:$X$9,3,FALSE) -> 12 | U12: =VLOOKUP($B12,$R$3:$X$9,4,FALSE) -> 0 | V12: =VLOOKUP($B12,$R$3:$X$9,5,FALSE) -> 0.11805556 | W12: =VLOOKUP($B12,$R$3:$X$9,6,FALSE) -> 0.22569444 | X12: =VLOOKUP($B12,$R$3:$X$9,7,FALSE) -> 0.26388889 | Y12: =VLOOKUP($B12,$R$3:$Z$9,8,FALSE) -> 0 | Z12: =VLOOKUP($B12,$R$3:$Z$9,9,FALSE) -> 60
B13: CARIB | C13: =[22]Brewhouse!$A836 -> CA726 | D13: =[22]Brewhouse!$AF836 -> 52.4 | E13: =[22]Brewhouse!$AI836 -> 51.5 | F13: =[22]Brewhouse!$V836 -> 71 | G13: =[22]Brewhouse!AG836 -> 11.7 | H13: 11.8 | I13: =[22]Brewhouse!$AU836 -> 99.949173 | J13: =[22]Brewhouse!$AV836 -> 101.65369 | K13: =[22]Brewhouse!$Q836 -> 2.490566 | L13: =[22]Brewhouse!$P836 -> 70 | M13: =[22]Brewhouse!$U836-[22]Brewhouse!$T836 -> 0.11388889 | N13: =[22]Brewhouse!$Z836 -> 0.26458333 | O13: =[22]Brewhouse!$AX836 -> K.Benjamin | P13: 10 mins extra boil | R13: =B13 -> CARIB | S13: =VLOOKUP($B13,$R$3:$X$9,2,FALSE) -> 11.6 | T13: =VLOOKUP($B13,$R$3:$X$9,3,FALSE) -> 12 | U13: =VLOOKUP($B13,$R$3:$X$9,4,FALSE) -> 0 | V13: =VLOOKUP($B13,$R$3:$X$9,5,FALSE) -> 0.11805556 | W13: =VLOOKUP($B13,$R$3:$X$9,6,FALSE) -> 0.22569444 | X13: =VLOOKUP($B13,$R$3:$X$9,7,FALSE) -> 0.26388889 | Y13: =VLOOKUP($B13,$R$3:$Z$9,8,FALSE) -> 0 | Z13: =VLOOKUP($B13,$R$3:$Z$9,9,FALSE) -> 60
B14: CARIB | C14: =[22]Brewhouse!$A837 -> CA727 | D14: =[22]Brewhouse!$AF837 -> 52 | E14: =[22]Brewhouse!$AI837 -> 50.5 | F14: =[22]Brewhouse!$V837 -> 69 | G14: =[22]Brewhouse!AG837 -> 11.6 | H14: 11.5 | I14: =[22]Brewhouse!$AU837 -> 96.620825 | J14: =[22]Brewhouse!$AV837 -> 98.26818 | K14: =[22]Brewhouse!$Q837 -> 3.4274953 | L14: =[22]Brewhouse!$P837 -> 60 | M14: =[22]Brewhouse!$U837-[22]Brewhouse!$T837 -> 0.11875 | N14: =[22]Brewhouse!$Z837 -> 0.30833333 | O14: =[22]Brewhouse!$AX837 -> R. Regis | P14: Skip came 1.5hrs late, hence delay in bre transfer to Lauter tun | R14: =B14 -> CARIB | S14: =VLOOKUP($B14,$R$3:$X$9,2,FALSE) -> 11.6 | T14: =VLOOKUP($B14,$R$3:$X$9,3,FALSE) -> 12 | U14: =VLOOKUP($B14,$R$3:$X$9,4,FALSE) -> 0 | V14: =VLOOKUP($B14,$R$3:$X$9,5,FALSE) -> 0.11805556 | W14: =VLOOKUP($B14,$R$3:$X$9,6,FALSE) -> 0.22569444 | X14: =VLOOKUP($B14,$R$3:$X$9,7,FALSE) -> 0.26388889 | Y14: =VLOOKUP($B14,$R$3:$Z$9,8,FALSE) -> 0 | Z14: =VLOOKUP($B14,$R$3:$Z$9,9,FALSE) -> 60
B15: CARIB | C15: =[22]Brewhouse!$A838 -> CA728 | D15: =[22]Brewhouse!$AF838 -> 53.3 | E15: =[22]Brewhouse!$AI838 -> 51.2 | F15: =[22]Brewhouse!$V838 -> 70 | G15: =[22]Brewhouse!AG838 -> 11.8 | H15: 11.9 | I15: =[22]Brewhouse!$AU838 -> 99.366945 | J15: =[22]Brewhouse!$AV838 -> 101.06154 | K15: =[22]Brewhouse!$Q838 -> 0.97928437 | L15: =[22]Brewhouse!$P838 -> 60 | M15: =[22]Brewhouse!$U838-[22]Brewhouse!$T838 -> 0.11666667 | N15: =[22]Brewhouse!$Z838 -> 0.26458333 | O15: =[22]Brewhouse!$AX838 -> R. Regis | R15: =B15 -> CARIB | S15: =VLOOKUP($B15,$R$3:$X$9,2,FALSE) -> 11.6 | T15: =VLOOKUP($B15,$R$3:$X$9,3,FALSE) -> 12 | U15: =VLOOKUP($B15,$R$3:$X$9,4,FALSE) -> 0 | V15: =VLOOKUP($B15,$R$3:$X$9,5,FALSE) -> 0.11805556 | W15: =VLOOKUP($B15,$R$3:$X$9,6,FALSE) -> 0.22569444 | X15: =VLOOKUP($B15,$R$3:$X$9,7,FALSE) -> 0.26388889 | Y15: =VLOOKUP($B15,$R$3:$Z$9,8,FALSE) -> 0 | Z15: =VLOOKUP($B15,$R$3:$Z$9,9,FALSE) -> 60
R16: =B16 -> 0 | S16: =VLOOKUP($B16,$R$3:$X$9,2,FALSE) -> #N/A | T16: =VLOOKUP($B16,$R$3:$X$9,3,FALSE) -> #N/A | U16: =VLOOKUP($B16,$R$3:$X$9,4,FALSE) -> #N/A | V16: =VLOOKUP($B16,$R$3:$X$9,5,FALSE) -> #N/A | W16: =VLOOKUP($B16,$R$3:$X$9,6,FALSE) -> #N/A | X16: =VLOOKUP($B16,$R$3:$X$9,7,FALSE) -> #N/A | Y16: =VLOOKUP($B16,$R$3:$Z$9,8,FALSE) -> #N/A | Z16: =VLOOKUP($B16,$R$3:$Z$9,9,FALSE) -> #N/A
B17: STAG | C17: =[23]Brewhouse!$A399 -> ST376 | D17: =[23]Brewhouse!$AD399 -> 47.5 | E17: =[23]Brewhouse!$AG399 -> 47.2 | F17: =[23]Brewhouse!$V399 -> 62 | G17: =[23]Brewhouse!$AE399 -> 11.8 | H17: 12.1 | I17: =[23]Brewhouse!$AS399 -> 92.950609 | J17: =[23]Brewhouse!$AT399 -> 94.287839 | K17: =[23]Brewhouse!$Q399 -> 13.605769 | L17: =[23]Brewhouse!$P399 -> 61 | M17: =[23]Brewhouse!$U399-[23]Brewhouse!$T399 -> 0.11458333 | N17: =[23]Brewhouse!$AW399 -> 0.25208333 | O17: =[23]Brewhouse!$AV399 -> R. Regis | R17: =B17 -> STAG | S17: =VLOOKUP($B17,$R$3:$X$9,2,FALSE) -> 11.6 | T17: =VLOOKUP($B17,$R$3:$X$9,3,FALSE) -> 12 | U17: =VLOOKUP($B17,$R$3:$X$9,4,FALSE) -> 0 | V17: =VLOOKUP($B17,$R$3:$X$9,5,FALSE) -> 0.11805556 | W17: =VLOOKUP($B17,$R$3:$X$9,6,FALSE) -> 0.22569444 | X17: =VLOOKUP($B17,$R$3:$X$9,7,FALSE) -> 0.26388889 | Y17: =VLOOKUP($B17,$R$3:$Z$9,8,FALSE) -> 0 | Z17: =VLOOKUP($B17,$R$3:$Z$9,9,FALSE) -> 60
B18: STAG | C18: =[23]Brewhouse!$A400 -> ST377 | D18: =[23]Brewhouse!$AD400 -> 47.3 | E18: =[23]Brewhouse!$AG400 -> 49 | F18: =[23]Brewhouse!$V400 -> 67 | G18: =[23]Brewhouse!$AE400 -> 12 | H18: 11.9 | I18: =[23]Brewhouse!$AS400 -> 98.215673 | J18: =[23]Brewhouse!$AT400 -> 99.628649 | K18: =[23]Brewhouse!$Q400 -> 13.387716 | L18: =[23]Brewhouse!$P400 -> 60 | M18: =[23]Brewhouse!$U400-[23]Brewhouse!$T400 -> 0.11805556 | N18: =[23]Brewhouse!$AW400 -> 0.25625 | O18: =[23]Brewhouse!$AV400 -> R.Sookram | R18: =B18 -> STAG | S18: =VLOOKUP($B18,$R$3:$X$9,2,FALSE) -> 11.6 | T18: =VLOOKUP($B18,$R$3:$X$9,3,FALSE) -> 12 | U18: =VLOOKUP($B18,$R$3:$X$9,4,FALSE) -> 0 | V18: =VLOOKUP($B18,$R$3:$X$9,5,FALSE) -> 0.11805556 | W18: =VLOOKUP($B18,$R$3:$X$9,6,FALSE) -> 0.22569444 | X18: =VLOOKUP($B18,$R$3:$X$9,7,FALSE) -> 0.26388889 | Y18: =VLOOKUP($B18,$R$3:$Z$9,8,FALSE) -> 0 | Z18: =VLOOKUP($B18,$R$3:$Z$9,9,FALSE) -> 60
B19: STAG | C19: =[23]Brewhouse!$A401 -> ST378 | D19: =[23]Brewhouse!$AD401 -> 48.7 | E19: =[23]Brewhouse!$AG401 -> 48.8 | F19: =[23]Brewhouse!$V401 -> 60 | G19: =[23]Brewhouse!$AE401 -> 11.9 | I19: =[23]Brewhouse!$AS401 -> 96.958135 | J19: =[23]Brewhouse!$AT401 -> 98.353019 | K19: =[23]Brewhouse!$Q401 -> 16.492395 | L19: =[23]Brewhouse!$P401 -> 57 | M19: =[23]Brewhouse!$U401-[23]Brewhouse!$T401 -> 0.13958333 | N19: =[23]Brewhouse!$AW401 -> 0.27986111 | O19: =[23]Brewhouse!$AV401 -> R.Sookram | R19: =B19 -> STAG | S19: =VLOOKUP($B19,$R$3:$X$9,2,FALSE) -> 11.6 | T19: =VLOOKUP($B19,$R$3:$X$9,3,FALSE) -> 12 | U19: =VLOOKUP($B19,$R$3:$X$9,4,FALSE) -> 0 | V19: =VLOOKUP($B19,$R$3:$X$9,5,FALSE) -> 0.11805556 | W19: =VLOOKUP($B19,$R$3:$X$9,6,FALSE) -> 0.22569444 | X19: =VLOOKUP($B19,$R$3:$X$9,7,FALSE) -> 0.26388889 | Y19: =VLOOKUP($B19,$R$3:$Z$9,8,FALSE) -> 0 | Z19: =VLOOKUP($B19,$R$3:$Z$9,9,FALSE) -> 60
R20: =B20 -> 0 | S20: =VLOOKUP($B20,$R$3:$X$9,2,FALSE) -> #N/A | T20: =VLOOKUP($B20,$R$3:$X$9,3,FALSE) -> #N/A | U20: =VLOOKUP($B20,$R$3:$X$9,4,FALSE) -> #N/A | V20: =VLOOKUP($B20,$R$3:$X$9,5,FALSE) -> #N/A | W20: =VLOOKUP($B20,$R$3:$X$9,6,FALSE) -> #N/A | X20: =VLOOKUP($B20,$R$3:$X$9,7,FALSE) -> #N/A | Y20: =VLOOKUP($B20,$R$3:$Z$9,8,FALSE) -> #N/A | Z20: =VLOOKUP($B20,$R$3:$Z$9,9,FALSE) -> #N/A
R21: =B21 -> 0 | S21: =VLOOKUP($B21,$R$3:$X$9,2,FALSE) -> #N/A | T21: =VLOOKUP($B21,$R$3:$X$9,3,FALSE) -> #N/A | U21: =VLOOKUP($B21,$R$3:$X$9,4,FALSE) -> #N/A | V21: =VLOOKUP($B21,$R$3:$X$9,5,FALSE) -> #N/A | W21: =VLOOKUP($B21,$R$3:$X$9,6,FALSE) -> #N/A | X21: =VLOOKUP($B21,$R$3:$X$9,7,FALSE) -> #N/A | Y21: =VLOOKUP($B21,$R$3:$Z$9,8,FALSE) -> #N/A | Z21: =VLOOKUP($B21,$R$3:$Z$9,9,FALSE) -> #N/A
R22: =B22 -> 0 | S22: =VLOOKUP($B22,$R$3:$X$9,2,FALSE) -> #N/A | T22: =VLOOKUP($B22,$R$3:$X$9,3,FALSE) -> #N/A | U22: =VLOOKUP($B22,$R$3:$X$9,4,FALSE) -> #N/A | V22: =VLOOKUP($B22,$R$3:$X$9,5,FALSE) -> #N/A | W22: =VLOOKUP($B22,$R$3:$X$9,6,FALSE) -> #N/A | X22: =VLOOKUP($B22,$R$3:$X$9,7,FALSE) -> #N/A | Y22: =VLOOKUP($B22,$R$3:$Z$9,8,FALSE) -> #N/A | Z22: =VLOOKUP($B22,$R$3:$Z$9,9,FALSE) -> #N/A
R23: =B23 -> 0 | S23: =VLOOKUP($B23,$R$3:$X$9,2,FALSE) -> #N/A | T23: =VLOOKUP($B23,$R$3:$X$9,3,FALSE) -> #N/A | U23: =VLOOKUP($B23,$R$3:$X$9,4,FALSE) -> #N/A | V23: =VLOOKUP($B23,$R$3:$X$9,5,FALSE) -> #N/A | W23: =VLOOKUP($B23,$R$3:$X$9,6,FALSE) -> #N/A | X23: =VLOOKUP($B23,$R$3:$X$9,7,FALSE) -> #N/A | Y23: =VLOOKUP($B23,$R$3:$Z$9,8,FALSE) -> #N/A | Z23: =VLOOKUP($B23,$R$3:$Z$9,9,FALSE) -> #N/A
R24: =B24 -> 0 | S24: =VLOOKUP($B24,$R$3:$X$9,2,FALSE) -> #N/A | T24: =VLOOKUP($B24,$R$3:$X$9,3,FALSE) -> #N/A | U24: =VLOOKUP($B24,$R$3:$X$9,4,FALSE) -> #N/A | V24: =VLOOKUP($B24,$R$3:$X$9,5,FALSE) -> #N/A | W24: =VLOOKUP($B24,$R$3:$X$9,6,FALSE) -> #N/A | X24: =VLOOKUP($B24,$R$3:$X$9,7,FALSE) -> #N/A | Y24: =VLOOKUP($B24,$R$3:$Z$9,8,FALSE) -> #N/A | Z24: =VLOOKUP($B24,$R$3:$Z$9,9,FALSE) -> #N/A
R25: =B25 -> 0 | S25: =VLOOKUP($B25,$R$3:$X$9,2,FALSE) -> #N/A | T25: =VLOOKUP($B25,$R$3:$X$9,3,FALSE) -> #N/A | U25: =VLOOKUP($B25,$R$3:$X$9,4,FALSE) -> #N/A | V25: =VLOOKUP($B25,$R$3:$X$9,5,FALSE) -> #N/A | W25: =VLOOKUP($B25,$R$3:$X$9,6,FALSE) -> #N/A | X25: =VLOOKUP($B25,$R$3:$X$9,7,FALSE) -> #N/A | Y25: =VLOOKUP($B25,$R$3:$Z$9,8,FALSE) -> #N/A | Z25: =VLOOKUP($B25,$R$3:$Z$9,9,FALSE) -> #N/A
B26: BRAND | D26: BBT P.G./ O.G | I26: Brand | J26: Actual | K26: MTD No. of Brews | L26: MTD | M26: YTD | N26: Target | R26: =B26 -> BRAND | S26: =VLOOKUP($B26,$R$3:$X$9,2,FALSE) -> #N/A | T26: =VLOOKUP($B26,$R$3:$X$9,3,FALSE) -> #N/A | U26: =VLOOKUP($B26,$R$3:$X$9,4,FALSE) -> #N/A | V26: =VLOOKUP($B26,$R$3:$X$9,5,FALSE) -> #N/A | W26: =VLOOKUP($B26,$R$3:$X$9,6,FALSE) -> #N/A | X26: =VLOOKUP($B26,$R$3:$X$9,7,FALSE) -> #N/A | Y26: =VLOOKUP($B26,$R$3:$Z$9,8,FALSE) -> #N/A | Z26: =VLOOKUP($B26,$R$3:$Z$9,9,FALSE) -> #N/A
B27: =I33 -> STARMALT | D27: 17.04 | I27: CARIB | J27: =AVERAGE(I10:I15) -> 97.734672 | K27: =COUNTA([22]Brewhouse!$A$823:$A$838) -> 16 | L27: =AVERAGE([22]Brewhouse!$AU$823:$AU$838) -> 97.418582 | M27: =AVERAGE([22]Brewhouse!$AU$102:$AU$171,[22]Brewhouse!$AU$173:$AU$253,[22]Brewhouse!$AU$255:$AU$339,[22]Brewhouse!$AU$341:$AU$346,[22]Brewhouse!$AU$348,[22]Brewhouse!$AU$349:$AU$406,[22]Brewhouse!$AU$408:$AU$491,[22]Brewhouse!$AU$493:$AU$578,[22]Brewhouse!$AU$580:$AU$652,[22]Brewhouse!$AU$655:$AU$738,[22]Brewhouse!$A$740:$A$821,[22]Brewhouse!$AU$823:$AU$838) -> 97.70009 | N27: 98 | R27: =B27 -> STARMALT | S27: =VLOOKUP($B27,$R$3:$X$9,2,FALSE) -> 17 | T27: =VLOOKUP($B27,$R$3:$X$9,3,FALSE) -> 17.4 | U27: =VLOOKUP($B27,$R$3:$X$9,4,FALSE) -> 0 | V27: =VLOOKUP($B27,$R$3:$X$9,5,FALSE) -> 0.13605324 | W27: =VLOOKUP($B27,$R$3:$X$9,6,FALSE) -> 0.27430556 | X27: =VLOOKUP($B27,$R$3:$X$9,7,FALSE) -> 0.30902778 | Y27: =VLOOKUP($B27,$R$3:$Z$9,8,FALSE) -> 0 | Z27: =VLOOKUP($B27,$R$3:$Z$9,9,FALSE) -> 85
I28: STAG | J28: =AVERAGE(I17:I19) -> 96.041472 | K28: =COUNTA([23]Brewhouse!$A$399:$A$401) -> 3 | L28: =AVERAGE([23]Brewhouse!$AS$399:$AS$401) -> 96.041472 | M28: =AVERAGE([23]Brewhouse!$AS$15:$AS$64,[23]Brewhouse!$AS$66:$AS$103,[23]Brewhouse!$AS$105:$AS$140,[23]Brewhouse!$AS$142:$AS$193,[23]Brewhouse!$AS$195:$AS$240,[23]Brewhouse!$AS$242:$AS$273,[23]Brewhouse!$AS$275:$AS$322,[23]Brewhouse!$AS$324:$AS$359,[23]Brewhouse!$AS$361:$AS$397,[23]Brewhouse!$AS$399:$AS$401) -> 97.980835 | N28: 98 | R28: =B28 -> 0 | S28: =VLOOKUP($B28,$R$3:$X$9,2,FALSE) -> #N/A | T28: =VLOOKUP($B28,$R$3:$X$9,3,FALSE) -> #N/A | U28: =VLOOKUP($B28,$R$3:$X$9,4,FALSE) -> #N/A | V28: =VLOOKUP($B28,$R$3:$X$9,5,FALSE) -> #N/A | W28: =VLOOKUP($B28,$R$3:$X$9,6,FALSE) -> #N/A | X28: =VLOOKUP($B28,$R$3:$X$9,7,FALSE) -> #N/A | Y28: =VLOOKUP($B28,$R$3:$Z$9,8,FALSE) -> #N/A | Z28: =VLOOKUP($B28,$R$3:$Z$9,9,FALSE) -> #N/A
D29: 17.04 | I29: GUINNESS | M29: =AVERAGE([24]Brewhouse!$AU$4:$AU$7,[24]Brewhouse!$AU$9:$AU$22,[24]Brewhouse!$AU$24:$AU$35,[24]Brewhouse!$AU$37:$AU$45,[24]Brewhouse!$AU$47:$AU$62,[24]Brewhouse!$AU$64:$AU$79,[24]Brewhouse!$AU$81:$AU$92,[24]Brewhouse!$AU$94:$AU$97) -> 96.8166 | N29: 98 | R29: =B29 -> 0 | S29: =VLOOKUP($B29,$R$3:$X$9,2,FALSE) -> #N/A | T29: =VLOOKUP($B29,$R$3:$X$9,3,FALSE) -> #N/A | U29: =VLOOKUP($B29,$R$3:$X$9,4,FALSE) -> #N/A | V29: =VLOOKUP($B29,$R$3:$X$9,5,FALSE) -> #N/A | W29: =VLOOKUP($B29,$R$3:$X$9,6,FALSE) -> #N/A | X29: =VLOOKUP($B29,$R$3:$X$9,7,FALSE) -> #N/A | Y29: =VLOOKUP($B29,$R$3:$Z$9,8,FALSE) -> #N/A | Z29: =VLOOKUP($B29,$R$3:$Z$9,9,FALSE) -> #N/A
I30: VITAMALT | M30: =AVERAGE([25]Brewhouse!$AV$5:$AV$14,[25]Brewhouse!$AV$16:$AV$19,[25]Brewhouse!$AV$21:$AV$24,[25]Brewhouse!$AV$26:$AV$33,[25]Brewhouse!$AV$35:$AV$46,[25]Brewhouse!$AV$48:$AV$53,[25]Brewhouse!$AV$55:$AV$62,[25]Brewhouse!$AV$64:$AV$77,[25]Brewhouse!$AV$79:$AV$86) -> 98.293408 | N30: 98 | R30: =B30 -> 0 | S30: =VLOOKUP($B30,$R$3:$X$9,2,FALSE) -> #N/A | T30: =VLOOKUP($B30,$R$3:$X$9,3,FALSE) -> #N/A | U30: =VLOOKUP($B30,$R$3:$X$9,4,FALSE) -> #N/A | V30: =VLOOKUP($B30,$R$3:$X$9,5,FALSE) -> #N/A | W30: =VLOOKUP($B30,$R$3:$X$9,6,FALSE) -> #N/A | X30: =VLOOKUP($B30,$R$3:$X$9,7,FALSE) -> #N/A | Y30: =VLOOKUP($B30,$R$3:$Z$9,8,FALSE) -> #N/A | Z30: =VLOOKUP($B30,$R$3:$Z$9,9,FALSE) -> #N/A
D31: 17.02 | I31: MAXIMALT | N31: 98 | R31: =B31 -> 0 | S31: =VLOOKUP($B31,$R$3:$X$9,2,FALSE) -> #N/A | T31: =VLOOKUP($B31,$R$3:$X$9,3,FALSE) -> #N/A | U31: =VLOOKUP($B31,$R$3:$X$9,4,FALSE) -> #N/A | V31: =VLOOKUP($B31,$R$3:$X$9,5,FALSE) -> #N/A | W31: =VLOOKUP($B31,$R$3:$X$9,6,FALSE) -> #N/A | X31: =VLOOKUP($B31,$R$3:$X$9,7,FALSE) -> #N/A | Y31: =VLOOKUP($B31,$R$3:$Z$9,8,FALSE) -> #N/A | Z31: =VLOOKUP($B31,$R$3:$Z$9,9,FALSE) -> #N/A
I32: MACKESON | M32: =AVERAGE([26]Brewhouse!$AT$4:$AT$11,[26]Brewhouse!$AT$13:$AT$16,[26]Brewhouse!$AT$18:$AT$21,[26]Brewhouse!$AT$26,[26]Brewhouse!$AT$28:$AT$35) -> 94.794664 | N32: 98 | R32: =B32 -> 0 | S32: =VLOOKUP($B32,$R$3:$X$9,2,FALSE) -> #N/A | T32: =VLOOKUP($B32,$R$3:$X$9,3,FALSE) -> #N/A | U32: =VLOOKUP($B32,$R$3:$X$9,4,FALSE) -> #N/A | V32: =VLOOKUP($B32,$R$3:$X$9,5,FALSE) -> #N/A | W32: =VLOOKUP($B32,$R$3:$X$9,6,FALSE) -> #N/A | X32: =VLOOKUP($B32,$R$3:$X$9,7,FALSE) -> #N/A | Y32: =VLOOKUP($B32,$R$3:$Z$9,8,FALSE) -> #N/A | Z32: =VLOOKUP($B32,$R$3:$Z$9,9,FALSE) -> #N/A
D33: 17.17 | I33: STARMALT | M33: =AVERAGE([27]Brewhouse!$AY$6:$AY$13,[27]Brewhouse!$AY$15:$AY$20,[27]Brewhouse!$AY$22:$AY$29,[27]Brewhouse!$AY$31:$AY$34,[27]Brewhouse!$AY$36:$AY$43,[27]Brewhouse!$AY$45:$AY$50, [27]Brewhouse!$AY$56:$AY$73,[27]Brewhouse!$AY$75:$AY$92) -> 97.477741 | N33: 98 | R33: =B33 -> 0 | S33: =VLOOKUP($B33,$R$3:$X$9,2,FALSE) -> #N/A | T33: =VLOOKUP($B33,$R$3:$X$9,3,FALSE) -> #N/A | U33: =VLOOKUP($B33,$R$3:$X$9,4,FALSE) -> #N/A | V33: =VLOOKUP($B33,$R$3:$X$9,5,FALSE) -> #N/A | W33: =VLOOKUP($B33,$R$3:$X$9,6,FALSE) -> #N/A | X33: =VLOOKUP($B33,$R$3:$X$9,7,FALSE) -> #N/A | Y33: =VLOOKUP($B33,$R$3:$Z$9,8,FALSE) -> #N/A | Z33: =VLOOKUP($B33,$R$3:$Z$9,9,FALSE) -> #N/A
I34: HR- Pils | M34: =AVERAGE([28]Brewhouse!$AU$5:$AU$8,[28]Brewhouse!$AU$10:$AU$13,[27]Brewhouse!$AY$75:$AY$77) -> 94.749192 | N34: 98 | R34: =B34 -> 0 | S34: =VLOOKUP($B34,$R$3:$X$9,2,FALSE) -> #N/A | T34: =VLOOKUP($B34,$R$3:$X$9,3,FALSE) -> #N/A | U34: =VLOOKUP($B34,$R$3:$X$9,4,FALSE) -> #N/A | V34: =VLOOKUP($B34,$R$3:$X$9,5,FALSE) -> #N/A | W34: =VLOOKUP($B34,$R$3:$X$9,6,FALSE) -> #N/A | X34: =VLOOKUP($B34,$R$3:$X$9,7,FALSE) -> #N/A | Y34: =VLOOKUP($B34,$R$3:$Z$9,8,FALSE) -> #N/A | Z34: =VLOOKUP($B34,$R$3:$Z$9,9,FALSE) -> #N/A
D35: 17.05 | I35: HR- IPA | M35: =AVERAGE([29]Brewhouse!$AW$26:$AW$27) -> 95.310681 | N35: 98 | R35: =B35 -> 0 | S35: =VLOOKUP($B35,$R$3:$X$9,2,FALSE) -> #N/A | T35: =VLOOKUP($B35,$R$3:$X$9,3,FALSE) -> #N/A | U35: =VLOOKUP($B35,$R$3:$X$9,4,FALSE) -> #N/A | V35: =VLOOKUP($B35,$R$3:$X$9,5,FALSE) -> #N/A | W35: =VLOOKUP($B35,$R$3:$X$9,6,FALSE) -> #N/A | X35: =VLOOKUP($B35,$R$3:$X$9,7,FALSE) -> #N/A | Y35: =VLOOKUP($B35,$R$3:$Z$9,8,FALSE) -> #N/A | Z35: =VLOOKUP($B35,$R$3:$Z$9,9,FALSE) -> #N/A
I36: HR- APA | M36: =AVERAGE([30]Brewhouse!$AU$13:$AU$14) -> 97.110575 | N36: 98 | R36: =B36 -> 0 | S36: =VLOOKUP($B36,$R$3:$X$9,2,FALSE) -> #N/A | T36: =VLOOKUP($B36,$R$3:$X$9,3,FALSE) -> #N/A | U36: =VLOOKUP($B36,$R$3:$X$9,4,FALSE) -> #N/A | V36: =VLOOKUP($B36,$R$3:$X$9,5,FALSE) -> #N/A | W36: =VLOOKUP($B36,$R$3:$X$9,6,FALSE) -> #N/A | X36: =VLOOKUP($B36,$R$3:$X$9,7,FALSE) -> #N/A | Y36: =VLOOKUP($B36,$R$3:$Z$9,8,FALSE) -> #N/A | Z36: =VLOOKUP($B36,$R$3:$Z$9,9,FALSE) -> #N/A
K37: =SUM(K27:K36) -> 19 | L37: =((L27*K27)+(L28*K28)+(L29*K29)+(L30*K30)+(L31*K31)+(K34*L34)+(L32*K32)+(L33*K33)+(L36*K36))/(K37) -> 97.201144 | M37: =AVERAGE('[31]Jan 31st'!$L$65,'[32]Feb 28th'!$L$35,'[33]Mar. 31st'!$L$35,'[34]Apr. 30th'!$L$45,'[35]May 30th'!$L$37,'[36]June 30th'!$L$57,'[37]July 29th '!$L$44,'[38]Aug 29th'!$L$29,'[39]Sept 30th'!$L$35,L37) -> 97.538065 | N37: 98 | R37: =B37 -> 0 | S37: =VLOOKUP($B37,$R$3:$X$9,2,FALSE) -> #N/A | T37: =VLOOKUP($B37,$R$3:$X$9,3,FALSE) -> #N/A | U37: =VLOOKUP($B37,$R$3:$X$9,4,FALSE) -> #N/A | V37: =VLOOKUP($B37,$R$3:$X$9,5,FALSE) -> #N/A | W37: =VLOOKUP($B37,$R$3:$X$9,6,FALSE) -> #N/A | X37: =VLOOKUP($B37,$R$3:$X$9,7,FALSE) -> #N/A | Y37: =VLOOKUP($B37,$R$3:$Z$9,8,FALSE) -> #N/A | Z37: =VLOOKUP($B37,$R$3:$Z$9,9,FALSE) -> #N/A
R38: =B38 -> 0 | S38: =VLOOKUP($B38,$R$3:$X$9,2,FALSE) -> #N/A | T38: =VLOOKUP($B38,$R$3:$X$9,3,FALSE) -> #N/A | U38: =VLOOKUP($B38,$R$3:$X$9,4,FALSE) -> #N/A | V38: =VLOOKUP($B38,$R$3:$X$9,5,FALSE) -> #N/A | W38: =VLOOKUP($B38,$R$3:$X$9,6,FALSE) -> #N/A | X38: =VLOOKUP($B38,$R$3:$X$9,7,FALSE) -> #N/A | Y38: =VLOOKUP($B38,$R$3:$Z$9,8,FALSE) -> #N/A | Z38: =VLOOKUP($B38,$R$3:$Z$9,9,FALSE) -> #N/A
B39: =I27 -> CARIB | C39: {=[22]Process!$D$766:$D$767} -> 12 | D39: 11.75 | J39: Daily Brewing Plan
C40: 11.9 | J40: Brand | K40: Brews Achieved | L40: Average Brews per day
...

Sheet Oct. 3rd
S1: P.G. | U1: Hot Time | W1: Process Time | Y1: Cooling Time
B2: Brewing Department Daily Process Loss Report | S2: Lower | T2: Upper | U2: Lower | V2: Upper | W2: Lower | X2: Upper | Y2: Lower | Z2: Upper
R3: CARIB | S3: 11.6 | T3: 12 | U3: 0 | V3: 0.11805556 | W3: 0.22569444 | X3: 0.26388889 | Y3: 0 | Z3: 60 | AB3: HR- PISNER
B4: Date: | C4: 45936 | J4: LOT WORT COLOUR: 3.3 | M4: Filter Sheets (Target 20 days) | R4: STAG | S4: 11.6 | T4: 12 | U4: 0 | V4: 0.11805556 | W4: 0.22569444 | X4: 0.26388889 | Y4: 0 | Z4: 60
M5: Double | N5: Single | R5: GUINNESS | S5: 17 | T5: 17.5 | U5: 0 | V5: 0.10763889 | W5: 0.24652778 | X5: 0.28472222 | Y5: 0 | Z5: 60
J6: MALT LOT: Lot #3 | L6: Sheet Day | R6: MACKESON | S6: 13.3 | T6: 13.5 | U6: 0 | V6: 0.12905093 | W6: 0.27430556 | X6: 0.30208333 | Y6: 0
R7: STARMALT | S7: 17 | T7: 17.4 | U7: 0 | V7: 0.13605324 | W7: 0.27430556 | X7: 0.30902778 | Y7: 0 | Z7: 85
B8: Brand | C8: Brew no. | D8: Kett. Hls | E8: Wort | F8: Cool Time(Mins) | G8: Cast. P.G. (Lab Result) | H8: Cast P.G. (Cellar Operator)-gravity | I8: Extr. Rec (77.9%) | J8: Theor. Extr. (77.5%) | K8: Boil Off /Vol. (4-6%) | L8: Boil Time | M8: Total Hot | N8: Brewing | O8: Operator | R8: Hurricane Reef | S8: 16.6 | T8: 17 | U8: 0 | V8: 0.12905093 | W8: 0.27430556 | X8: 0.30208333 | Y8: 0
E9: Meter (Hls) | F9: Target(< 60Mins) | M9: Time | R9: VITAMALT | S9: 14.2 | T9: 14.6 | U9: 0 | V9: 0.13905093 | W9: 0.26041667 | X9: 0.29513889 | Y9: 0 | Z9: 75
B10: STAG | C10: =[23]Brewhouse!$A402 -> ST379 | D10: =[23]Brewhouse!$AD402 -> 48.6 | E10: =[23]Brewhouse!$AG402 -> 48.3 | F10: =[23]Brewhouse!$V402 -> 54 | G10: =[23]Brewhouse!$AE402 -> 12 | H10: 11.9 | I10: =[23]Brewhouse!$AS402 -> 96.206841 | J10: =[23]Brewhouse!$AT402 -> 97.593188 | K10: =[23]Brewhouse!$Q402 -> 13.221154 | L10: =[23]Brewhouse!$P402 -> 58 | M10: =[23]Brewhouse!$U402-[23]Brewhouse!$T402 -> 0.10902778 | N10: =[23]Brewhouse!$AW402 -> 0.29513889 | O10: =[23]Brewhouse!$AV402 -> R.Sookram | R10: =B10 -> STAG | S10: =VLOOKUP($B10,$R$3:$X$9,2,FALSE) -> 11.6 | T10: =VLOOKUP($B10,$R$3:$X$9,3,FALSE) -> 12 | U10: =VLOOKUP($B10,$R$3:$X$9,4,FALSE) -> 0 | V10: =VLOOKUP($B10,$R$3:$X$9,5,FALSE) -> 0.11805556 | W10: =VLOOKUP($B10,$R$3:$X$9,6,FALSE) -> 0.22569444 | X10: =VLOOKUP($B10,$R$3:$X$9,7,FALSE) -> 0.26388889 | Y10: =VLOOKUP($B10,$R$3:$Z$9,8,FALSE) -> 0 | Z10: =VLOOKUP($B10,$R$3:$Z$9,9,FALSE) -> 60
B11: STAG | C11: =[23]Brewhouse!$A403 -> ST380 | D11: =[23]Brewhouse!$AD403 -> 50.4 | E11: =[23]Brewhouse!$AG403 -> 49.5 | F11: =[23]Brewhouse!$V403 -> 56 | G11: =[23]Brewhouse!$AE403 -> 11.9 | H11: 11.9 | I11: =[23]Brewhouse!$AS403 -> 98.472932 | J11: =[23]Brewhouse!$AT403 -> 99.88914 | K11: =[23]Brewhouse!$Q403 -> 9.1826923 | L11: =[23]Brewhouse!$P403 -> 62 | M11: =[23]Brewhouse!$U403-[23]Brewhouse!$T403 -> 0.11458333 | N11: =[23]Brewhouse!$AW403 -> 0.25069444 | O11: =[23]Brewhouse!$AV403 -> K. Benjamin | R11: =B11 -> STAG | S11: =VLOOKUP($B11,$R$3:$X$9,2,FALSE) -> 11.6 | T11: =VLOOKUP($B11,$R$3:$X$9,3,FALSE) -> 12 | U11: =VLOOKUP($B11,$R$3:$X$9,4,FALSE) -> 0 | V11: =VLOOKUP($B11,$R$3:$X$9,5,FALSE) -> 0.11805556 | W11: =VLOOKUP($B11,$R$3:$X$9,6,FALSE) -> 0.22569444 | X11: =VLOOKUP($B11,$R$3:$X$9,7,FALSE) -> 0.26388889 | Y11: =VLOOKUP($B11,$R$3:$Z$9,8,FALSE) -> 0 | Z11: =VLOOKUP($B11,$R$3:$Z$9,9,FALSE) -> 60
B12: STAG | C12: =[23]Brewhouse!$A404 -> ST381 | D12: =[23]Brewhouse!$AD404 -> 50.3 | E12: =[23]Brewhouse!$AG404 -> 50.1 | F12: =[23]Brewhouse!$V404 -> 63 | G12: =[23]Brewhouse!$AE404 -> 11.7 | H12: 11.8 | I12: =[23]Brewhouse!$AS404 -> 97.414067 | J12: =[23]Brewhouse!$AT404 -> 98.816893 | K12: =[23]Brewhouse!$Q404 -> 11.490385 | L12: =[23]Brewhouse!$P404 -> 59 | M12: =[23]Brewhouse!$U404-[23]Brewhouse!$T404 -> 0.11875 | N12: =[23]Brewhouse!$AW404 -> 0.25694444 | O12: =[23]Brewhouse!$AV404 -> K. Benjamin | R12: =B12 -> STAG | S12: =VLOOKUP($B12,$R$3:$X$9,2,FALSE) -> 11.6 | T12: =VLOOKUP($B12,$R$3:$X$9,3,FALSE) -> 12 | U12: =VLOOKUP($B12,$R$3:$X$9,4,FALSE) -> 0 | V12: =VLOOKUP($B12,$R$3:$X$9,5,FALSE) -> 0.11805556 | W12: =VLOOKUP($B12,$R$3:$X$9,6,FALSE) -> 0.22569444 | X12: =VLOOKUP($B12,$R$3:$X$9,7,FALSE) -> 0.26388889 | Y12: =VLOOKUP($B12,$R$3:$Z$9,8,FALSE) -> 0 | Z12: =VLOOKUP($B12,$R$3:$Z$9,9,FALSE) -> 60
B13: STAG | C13: =[23]Brewhouse!$A405 -> ST382 | D13: =[23]Brewhouse!$AD405 -> 48.5 | E13: =[23]Brewhouse!$AG405 -> 48.2 | F13: =[23]Brewhouse!$V405 -> 63 | G13: =[23]Brewhouse!$AE405 -> 12.2 | H13: 12.1 | I13: =[23]Brewhouse!$AS405 -> 98.057442 | J13: =[23]Brewhouse!$AT405 -> 99.469071 | K13: =[23]Brewhouse!$Q405 -> 11.875 | L13: =[23]Brewhouse!$P405 -> 60 | M13: =[23]Brewhouse!$U405-[23]Brewhouse!$T405 -> 0.11736111 | N13: =[23]Brewhouse!$AW405 -> 0.25763889 | O13: =[23]Brewhouse!$AV405 -> K. Benjamin | R13: =B13 -> STAG | S13: =VLOOKUP($B13,$R$3:$X$9,2,FALSE) -> 11.6 | T13: =VLOOKUP($B13,$R$3:$X$9,3,FALSE) -> 12 | U13: =VLOOKUP($B13,$R$3:$X$9,4,FALSE) -> 0 | V13: =VLOOKUP($B13,$R$3:$X$9,5,FALSE) -> 0.11805556 | W13: =VLOOKUP($B13,$R$3:$X$9,6,FALSE) -> 0.22569444 | X13: =VLOOKUP($B13,$R$3:$X$9,7,FALSE) -> 0.26388889 | Y13: =VLOOKUP($B13,$R$3:$Z$9,8,FALSE) -> 0 | Z13: =VLOOKUP($B13,$R$3:$Z$9,9,FALSE) -> 60
B14: STAG | C14: =[23]Brewhouse!$A406 -> ST383 | D14: =[23]Brewhouse!$AD406 -> 50.2 | E14: =[23]Brewhouse!$AG406 -> 49.9 | F14: =[23]Brewhouse!$V406 -> 64 | G14: =[23]Brewhouse!$AE406 -> 11.8 | H14: 11.8 | I14: =[23]Brewhouse!$AS406 -> 98.138683 | J14: =[23]Brewhouse!$AT406 -> 99.681423 | K14: =[23]Brewhouse!$Q406 -> 9.5673077 | L14: =[23]Brewhouse!$P406 -> 68 | M14: =[23]Brewhouse!$U406-[23]Brewhouse!$T406 -> 0.12083333 | N14: =[23]Brewhouse!$AW406 -> 0.25277778 | O14: =[23]Brewhouse!$AV406 -> R. Regis | R14: =B14 -> STAG | S14: =VLOOKUP($B14,$R$3:$X$9,2,FALSE) -> 11.6 | T14: =VLOOKUP($B14,$R$3:$X$9,3,FALSE) -> 12 | U14: =VLOOKUP($B14,$R$3:$X$9,4,FALSE) -> 0 | V14: =VLOOKUP($B14,$R$3:$X$9,5,FALSE) -> 0.11805556 | W14: =VLOOKUP($B14,$R$3:$X$9,6,FALSE) -> 0.22569444 | X14: =VLOOKUP($B14,$R$3:$X$9,7,FALSE) -> 0.26388889 | Y14: =VLOOKUP($B14,$R$3:$Z$9,8,FALSE) -> 0 | Z14: =VLOOKUP($B14,$R$3:$Z$9,9,FALSE) -> 60
B15: STAG | C15: =[23]Brewhouse!$A407 -> ST384 | D15: =[23]Brewhouse!$AD407 -> 46.9 | E15: =[23]Brewhouse!$AG407 -> 47.1 | F15: =[23]Brewhouse!$V407 -> 85 | G15: =[23]Brewhouse!$AE407 -> 11.9 | H15: 12 | I15: =[23]Brewhouse!$AS407 -> 99.745351 | J15: =[23]Brewhouse!$AT407 -> 101.41576 | K15: =[23]Brewhouse!$Q407 -> 10.129741 | L15: =[23]Brewhouse!$P407 -> 60 | M15: =[23]Brewhouse!$U407-[23]Brewhouse!$T407 -> 0.14166667 | N15: =[23]Brewhouse!$AW407 -> 0.29166667 | O15: =[23]Brewhouse!$AV407 -> R. Regis | R15: =B15 -> STAG | S15: =VLOOKUP($B15,$R$3:$X$9,2,FALSE) -> 11.6 | T15: =VLOOKUP($B15,$R$3:$X$9,3,FALSE) -> 12 | U15: =VLOOKUP($B15,$R$3:$X$9,4,FALSE) -> 0 | V15: =VLOOKUP($B15,$R$3:$X$9,5,FALSE) -> 0.11805556 | W15: =VLOOKUP($B15,$R$3:$X$9,6,FALSE) -> 0.22569444 | X15: =VLOOKUP($B15,$R$3:$X$9,7,FALSE) -> 0.26388889 | Y15: =VLOOKUP($B15,$R$3:$Z$9,8,FALSE) -> 0 | Z15: =VLOOKUP($B15,$R$3:$Z$9,9,FALSE) -> 60
R16: =B16 -> 0 | S16: =VLOOKUP($B16,$R$3:$X$9,2,FALSE) -> #N/A | T16: =VLOOKUP($B16,$R$3:$X$9,3,FALSE) -> #N/A | U16: =VLOOKUP($B16,$R$3:$X$9,4,FALSE) -> #N/A | V16: =VLOOKUP($B16,$R$3:$X$9,5,FALSE) -> #N/A | W16: =VLOOKUP($B16,$R$3:$X$9,6,FALSE) -> #N/A | X16: =VLOOKUP($B16,$R$3:$X$9,7,FALSE) -> #N/A | Y16: =VLOOKUP($B16,$R$3:$Z$9,8,FALSE) -> #N/A | Z16: =VLOOKUP($B16,$R$3:$Z$9,9,FALSE) -> #N/A
