Workbook
Name ProductList: [1]November15!$R$3:$R$9
Name ProductList: [2]November15!$R$3:$R$9

Sheet Dec 18th
T1: P.G. | V1: Hot Time | X1: Process Time | Z1: Cooling Time
B2: Brewing Department Daily Process Loss Report | T2: Lower | U2: Upper | V2: Lower | W2: Upper | X2: Lower | Y2: Upper | Z2: Lower | AA2: Upper
S3: CARIB | T3: 11.6 | U3: 12 | V3: 0 | W3: 0.11805556 | X3: 0.17361111 | Y3: 0.21180556 | Z3: 0 | AA3: 60 | AC3: HR- PISNER
B4: Date: | C4: 45278 | J4: LOT WORT COLOUR: 3.4 | M4: Filter Sheets (Target 20 days) | S4: STAG | T4: 11.6 | U4: 12 | V4: 0 | W4: 0.11805556 | X4: 0.17361111 | Y4: 0.21180556 | Z4: 0 | AA4: 60
M5: Double | N5: Single | S5: GUINNESS | T5: 17 | U5: 17.5 | V5: 0 | W5: 0.10763889 | X5: 0.19444444 | Y5: 0.23263889 | Z5: 0 | AA5: 60
J6: MALT LOT: Lot 8 | L6: Sheet Day | S6: MACKESON | T6: 13.3 | U6: 13.5 | V6: 0 | W6: 0.12905093 | X6: 0.22222222 | Y6: 0.25347222 | Z6: 0
S7: STARMALT | T7: 17.1 | U7: 17.5 | V7: 0 | W7: 0.13605324 | X7: 0.20833333 | Y7: 0.24305556 | Z7: 0 | AA7: 60
B8: Brand | C8: Brew no. | D8: Kett. Hls | E8: Wort | F8: Cool Time(Mins) | G8: Cast. P.G. (Lab Result) | H8: Cast P.G. (Cellar Operator)-gravity | I8: Extr. Rec (79.1%) | J8: Theor. Extr. (77.5%) | K8: Boil Off /Vol. (4-6%) | L8: Boil Time | M8: Total Hot | N8: Brewing | P8: Comments | Q8: Actual Pilsen Malt | S8: Hurricane Reef | T8: 16.6 | U8: 17 | V8: 0 | W8: 0.12905093 | X8: 0.22222222 | Y8: 0.25347222 | Z8: 0
E9: Meter (Hls) | F9: Target(< 60Mins) | M9: Time | S9: VITAMALT | T9: 14.4 | U9: 14.6 | V9: 0 | W9: 0.13905093 | X9: 0.19097222 | Y9: 0.22569444 | Z9: 0 | AA9: 75
S10: =B10 -> 0 | T10: =VLOOKUP($B10,$S$3:$Y$9,2,FALSE) -> #N/A | U10: =VLOOKUP($B10,$S$3:$Y$9,3,FALSE) -> #N/A | V10: =VLOOKUP($B10,$S$3:$Y$9,4,FALSE) -> #N/A | W10: =VLOOKUP($B10,$S$3:$Y$9,5,FALSE) -> #N/A | X10: =VLOOKUP($B10,$S$3:$Y$9,6,FALSE) -> #N/A | Y10: =VLOOKUP($B10,$S$3:$Y$9,7,FALSE) -> #N/A | Z10: =VLOOKUP($B10,$S$3:$AA$9,8,FALSE) -> #N/A | AA10: =VLOOKUP($B10,$S$3:$AA$9,9,FALSE) -> #N/A
S11: =B11 -> 0 | T11: =VLOOKUP($B11,$S$3:$Y$9,2,FALSE) -> #N/A | U11: =VLOOKUP($B11,$S$3:$Y$9,3,FALSE) -> #N/A | V11: =VLOOKUP($B11,$S$3:$Y$9,4,FALSE) -> #N/A | W11: =VLOOKUP($B11,$S$3:$Y$9,5,FALSE) -> #N/A | X11: =VLOOKUP($B11,$S$3:$Y$9,6,FALSE) -> #N/A | Y11: =VLOOKUP($B11,$S$3:$Y$9,7,FALSE) -> #N/A | Z11: =VLOOKUP($B11,$S$3:$AA$9,8,FALSE) -> #N/A | AA11: =VLOOKUP($B11,$S$3:$AA$9,9,FALSE) -> #N/A
S12: =B12 -> 0 | T12: =VLOOKUP($B12,$S$3:$Y$9,2,FALSE) -> #N/A | U12: =VLOOKUP($B12,$S$3:$Y$9,3,FALSE) -> #N/A | V12: =VLOOKUP($B12,$S$3:$Y$9,4,FALSE) -> #N/A | W12: =VLOOKUP($B12,$S$3:$Y$9,5,FALSE) -> #N/A | X12: =VLOOKUP($B12,$S$3:$Y$9,6,FALSE) -> #N/A | Y12: =VLOOKUP($B12,$S$3:$Y$9,7,FALSE) -> #N/A | Z12: =VLOOKUP($B12,$S$3:$AA$9,8,FALSE) -> #N/A | AA12: =VLOOKUP($B12,$S$3:$AA$9,9,FALSE) -> #N/A
S13: =B13 -> 0 | T13: =VLOOKUP($B13,$S$3:$Y$9,2,FALSE) -> #N/A | U13: =VLOOKUP($B13,$S$3:$Y$9,3,FALSE) -> #N/A | V13: =VLOOKUP($B13,$S$3:$Y$9,4,FALSE) -> #N/A | W13: =VLOOKUP($B13,$S$3:$Y$9,5,FALSE) -> #N/A | X13: =VLOOKUP($B13,$S$3:$Y$9,6,FALSE) -> #N/A | Y13: =VLOOKUP($B13,$S$3:$Y$9,7,FALSE) -> #N/A | Z13: =VLOOKUP($B13,$S$3:$AA$9,8,FALSE) -> #N/A | AA13: =VLOOKUP($B13,$S$3:$AA$9,9,FALSE) -> #N/A
S14: =B14 -> 0 | T14: =VLOOKUP($B14,$S$3:$Y$9,2,FALSE) -> #N/A | U14: =VLOOKUP($B14,$S$3:$Y$9,3,FALSE) -> #N/A | V14: =VLOOKUP($B14,$S$3:$Y$9,4,FALSE) -> #N/A | W14: =VLOOKUP($B14,$S$3:$Y$9,5,FALSE) -> #N/A | X14: =VLOOKUP($B14,$S$3:$Y$9,6,FALSE) -> #N/A | Y14: =VLOOKUP($B14,$S$3:$Y$9,7,FALSE) -> #N/A | Z14: =VLOOKUP($B14,$S$3:$AA$9,8,FALSE) -> #N/A | AA14: =VLOOKUP($B14,$S$3:$AA$9,9,FALSE) -> #N/A
S15: =B15 -> 0 | T15: =VLOOKUP($B15,$S$3:$Y$9,2,FALSE) -> #N/A | U15: =VLOOKUP($B15,$S$3:$Y$9,3,FALSE) -> #N/A | V15: =VLOOKUP($B15,$S$3:$Y$9,4,FALSE) -> #N/A | W15: =VLOOKUP($B15,$S$3:$Y$9,5,FALSE) -> #N/A | X15: =VLOOKUP($B15,$S$3:$Y$9,6,FALSE) -> #N/A | Y15: =VLOOKUP($B15,$S$3:$Y$9,7,FALSE) -> #N/A | Z15: =VLOOKUP($B15,$S$3:$AA$9,8,FALSE) -> #N/A | AA15: =VLOOKUP($B15,$S$3:$AA$9,9,FALSE) -> #N/A
S16: =B16 -> 0 | T16: =VLOOKUP($B16,$S$3:$Y$9,2,FALSE) -> #N/A | U16: =VLOOKUP($B16,$S$3:$Y$9,3,FALSE) -> #N/A | V16: =VLOOKUP($B16,$S$3:$Y$9,4,FALSE) -> #N/A | W16: =VLOOKUP($B16,$S$3:$Y$9,5,FALSE) -> #N/A | X16: =VLOOKUP($B16,$S$3:$Y$9,6,FALSE) -> #N/A | Y16: =VLOOKUP($B16,$S$3:$Y$9,7,FALSE) -> #N/A | Z16: =VLOOKUP($B16,$S$3:$AA$9,8,FALSE) -> #N/A | AA16: =VLOOKUP($B16,$S$3:$AA$9,9,FALSE) -> #N/A
S17: =B17 -> 0 | T17: =VLOOKUP($B17,$S$3:$Y$9,2,FALSE) -> #N/A | U17: =VLOOKUP($B17,$S$3:$Y$9,3,FALSE) -> #N/A | V17: =VLOOKUP($B17,$S$3:$Y$9,4,FALSE) -> #N/A | W17: =VLOOKUP($B17,$S$3:$Y$9,5,FALSE) -> #N/A | X17: =VLOOKUP($B17,$S$3:$Y$9,6,FALSE) -> #N/A | Y17: =VLOOKUP($B17,$S$3:$Y$9,7,FALSE) -> #N/A | Z17: =VLOOKUP($B17,$S$3:$AA$9,8,FALSE) -> #N/A | AA17: =VLOOKUP($B17,$S$3:$AA$9,9,FALSE) -> #N/A
S18: =B18 -> 0 | T18: =VLOOKUP($B18,$S$3:$Y$9,2,FALSE) -> #N/A | U18: =VLOOKUP($B18,$S$3:$Y$9,3,FALSE) -> #N/A | V18: =VLOOKUP($B18,$S$3:$Y$9,4,FALSE) -> #N/A | W18: =VLOOKUP($B18,$S$3:$Y$9,5,FALSE) -> #N/A | X18: =VLOOKUP($B18,$S$3:$Y$9,6,FALSE) -> #N/A | Y18: =VLOOKUP($B18,$S$3:$Y$9,7,FALSE) -> #N/A | Z18: =VLOOKUP($B18,$S$3:$AA$9,8,FALSE) -> #N/A | AA18: =VLOOKUP($B18,$S$3:$AA$9,9,FALSE) -> #N/A
S19: =B19 -> 0 | T19: =VLOOKUP($B19,$S$3:$Y$9,2,FALSE) -> #N/A | U19: =VLOOKUP($B19,$S$3:$Y$9,3,FALSE) -> #N/A | V19: =VLOOKUP($B19,$S$3:$Y$9,4,FALSE) -> #N/A | W19: =VLOOKUP($B19,$S$3:$Y$9,5,FALSE) -> #N/A | X19: =VLOOKUP($B19,$S$3:$Y$9,6,FALSE) -> #N/A | Y19: =VLOOKUP($B19,$S$3:$Y$9,7,FALSE) -> #N/A | Z19: =VLOOKUP($B19,$S$3:$AA$9,8,FALSE) -> #N/A | AA19: =VLOOKUP($B19,$S$3:$AA$9,9,FALSE) -> #N/A
S20: =B20 -> 0 | T20: =VLOOKUP($B20,$S$3:$Y$9,2,FALSE) -> #N/A | U20: =VLOOKUP($B20,$S$3:$Y$9,3,FALSE) -> #N/A | V20: =VLOOKUP($B20,$S$3:$Y$9,4,FALSE) -> #N/A | W20: =VLOOKUP($B20,$S$3:$Y$9,5,FALSE) -> #N/A | X20: =VLOOKUP($B20,$S$3:$Y$9,6,FALSE) -> #N/A | Y20: =VLOOKUP($B20,$S$3:$Y$9,7,FALSE) -> #N/A | Z20: =VLOOKUP($B20,$S$3:$AA$9,8,FALSE) -> #N/A | AA20: =VLOOKUP($B20,$S$3:$AA$9,9,FALSE) -> #N/A
S21: =B21 -> 0 | T21: =VLOOKUP($B21,$S$3:$Y$9,2,FALSE) -> #N/A | U21: =VLOOKUP($B21,$S$3:$Y$9,3,FALSE) -> #N/A | V21: =VLOOKUP($B21,$S$3:$Y$9,4,FALSE) -> #N/A | W21: =VLOOKUP($B21,$S$3:$Y$9,5,FALSE) -> #N/A | X21: =VLOOKUP($B21,$S$3:$Y$9,6,FALSE) -> #N/A | Y21: =VLOOKUP($B21,$S$3:$Y$9,7,FALSE) -> #N/A | Z21: =VLOOKUP($B21,$S$3:$AA$9,8,FALSE) -> #N/A | AA21: =VLOOKUP($B21,$S$3:$AA$9,9,FALSE) -> #N/A
... S47: =B47 -> 0 | T47: =VLOOKUP($B47,$S$3:$Y$9,2,FALSE) -> #N/A | U47: =VLOOKUP($B47,$S$3:$Y$9,3,FALSE) -> #N/A | V47: =VLOOKUP($B47,$S$3:$Y$9,4,FALSE) -> #N/A | W47: =VLOOKUP($B47,$S$3:$Y$9,5,FALSE) -> #N/A | X47: =VLOOKUP($B47,$S$3:$Y$9,6,FALSE) -> #N/A | Y47: =VLOOKUP($B47,$S$3:$Y$9,7,FALSE) -> #N/A | Z47: =VLOOKUP($B47,$S$3:$AA$9,8,FALSE) -> #N/A | AA47: =VLOOKUP($B47,$S$3:$AA$9,9,FALSE) -> #N/A
I48: EXTRACT RECOVERY
B49: BRAND | D49: BBT P.G./ O.G | I49: Brand | J49: Actual | K49: MTD No. of Brews | L49: MTD | M49: YTD | N49: Target
B50: STAG | C50: 11.8 | D50: 11.73 | I50: CARIB | K50: =COUNTA([3]Brewhouse!$A$1596:$A$1619) -> 24 | L50: =AVERAGE([3]Brewhouse!$AU$1529,[3]Brewhouse!$AU$1531:$AU$1594,[3]Brewhouse!$AU$1596:$AU$1619) -> 98.205761 | M50: =AVERAGE([3]Brewhouse!$AU$849:$AU$924,[3]Brewhouse!$AU$926:$AU$971,[3]Brewhouse!$AU$973:$AU$1066,[3]Brewhouse!$AU$1068:$AU$1111,[3]Brewhouse!$AU$1113:$AU$1132,[3]Brewhouse!$AU$1134:$AU$1167,[3]Brewhouse!$AU$1169:$AU$1230,[3]Brewhouse!$AU$1232:$AU$1299,[3]Brewhouse!$AU$1301:$AU$1363,[3]Brewhouse!$AU$1365:$AU$1444,[3]Brewhouse!$AU$1446:$AU$1527,[3]Brewhouse!$AU$1529,[3]Brewhouse!$AU$1531:$AU$1594,[3]Brewhouse!$AU$1596:$AU$1619) -> 98.381806 | N50: 98
C51: 11.9 | I51: STAG | K51: =COUNTA([4]Brewhouse!$A$976:$A$1007) -> 32 | L51: =AVERAGE([4]Brewhouse!$AS$976:$AS$979,[4]Brewhouse!$AS$981:$AS$1007) -> 98.538567 | M51: =AVERAGE([4]Brewhouse!$AS$577:$AS$618,[4]Brewhouse!$AS$620:$AS$651,[4]Brewhouse!$AS$653:$AS$696,[4]Brewhouse!$AS$698:$AS$708,[4]Brewhouse!$AS$710:$AS$733,[4]Brewhouse!$AS$735:$AS$777,[4]Brewhouse!$AS$779:$AS$822,[4]Brewhouse!$AS$824:$AS$863,[4]Brewhouse!$AS$865:$AS$974,[4]Brewhouse!$AS$976:$AS$979,[4]Brewhouse!$AS$981:$AS$1007) -> 98.489671 | N51: 98
I52: GUINNESS | K52: =COUNTA([5]Brewhouse!$A$282:$A$289) -> 8 | L52: =AVERAGE([5]Brewhouse!$AU$269:$AU$279,[5]Brewhouse!$AU$282:$AU$289) -> 96.186177 | M52: =AVERAGE([5]Brewhouse!$AU$161:$AU$176,[5]Brewhouse!$AU$178:$AU$195,[5]Brewhouse!$AU$197:$AU$208,[5]Brewhouse!$AU$210:$AU$221,[5]Brewhouse!$AU$223:$AU$232,[5]Brewhouse!$AU$234:$AU$279,[5]Brewhouse!$AU$282:$AU$289) -> 96.64916 | N52: 98
I53: VITAMALT | K53: =COUNTA([6]Brewhouse!$A$158:$A$163) -> 6 | L53: =AVERAGE([6]Brewhouse!$AU$158:$AU$163) -> 94.60305 | M53: =AVERAGE([6]Brewhouse!$AU$91:$AU$101,[6]Brewhouse!$AU$103:$AU$112,[6]Brewhouse!$AU$114:$AU$123,[6]Brewhouse!$AU$125:$AU$134,[6]Brewhouse!$AU$136:$AU$145,[6]Brewhouse!$AU$147:$AU$156,[6]Brewhouse!$AU$158:$AU$163) -> 96.240014 | N53: 98
I54: MAXIMALT | N54: 98
I55: MACKESON | M55: =AVERAGE([7]Brewhouse!$AT$74:$AT$79) -> 93.959836 | N55: 98
I56: STARMALT | K56: =COUNTA([8]Brewhouse!$A$249:$A$254) -> 6 | L56: =AVERAGE([8]Brewhouse!$AY$249:$AY$254) -> 99.681996 | M56: =AVERAGE([8]Brewhouse!$AY$138:$AY$143,[8]Brewhouse!$AY$145:$AY$153,[8]Brewhouse!$AY$155,[8]Brewhouse!$AY$156:$AY$174,[8]Brewhouse!$AY$176:$AY$185,[8]Brewhouse!$AY$187:$AY$198,[8]Brewhouse!$AY$200:$AY$247,[8]Brewhouse!$AY$249:$AY$254) -> 98.774703 | N56: 98
I57: HR- P | M57: =AVERAGE([9]Brewhouse!$AW$13:$AW$14,[9]Brewhouse!$AW$16:$AW$17) -> 92.042628 | N57: 98
I58: Hurricane Reef | M58: =AVERAGE([9]Brewhouse!$AW$13:$AW$14) -> 88.376943 | N58: 98
K59: =SUM(K50:K58) -> 76 | L59: =((L50*K50)+(L51*K51)+(L52*K52)+(L53*K53)+(L54*K54)+(K57*L57)+(L55*K55)+(L56*K56)+(L58*K58))/(K59) -> 97.965422 | M59: =AVERAGE('[10]Closing- January 2023'!$L$42,'[11]Feb. 28th'!$L$42,'[12]March 31st'!$L$75,'[13]Apri 28th'!$L$51,L59) -> 98.06926 | N59: 98
J62: Daily Brewing Plan
J63: Brand | K63: Brews Achieved | L63: Average Brews per day
J64: CARIB | L64: MTD | M64: YTD | N64: TARGET
J65: STAG | K65: 5 | L65: =AVERAGE(#REF!,#REF!,K74,#REF!,#REF!,#REF!,#REF!,#REF!,#REF!,#REF!,#REF!) -> #REF! | M65: =AVERAGE(6,6,'[12]March 31st'!$L$80,'[14]June 30th '!$L$71,6,L65,'[15]July 31st'!$L$108,'[16]Aug 30th'!$L$124,7,[17]Oct.31st!$L$51) -> #REF! | N65: 9
J66: GUINN
J67: VITAMALT
...

Sheet Sept 1st
S1: P.G. | U1: Hot Time | W1: Process Time | Y1: Cooling Time
B2: Brewing Department Daily Process Loss Report | S2: Lower | T2: Upper | U2: Lower | V2: Upper | W2: Lower | X2: Upper | Y2: Lower | Z2: Upper
R3: CARIB | S3: 11.6 | T3: 12 | U3: 0 | V3: 0.11805556 | W3: 0.22569444 | X3: 0.26388889 | Y3: 0 | Z3: 60 | AB3: HR- PISNER
B4: Date: | C4: 45902 | J4: LOT WORT COLOUR: 3.5 | M4: Filter Sheets (Target 20 days) | R4: STAG | S4: 11.6 | T4: 12 | U4: 0 | V4: 0.11805556 | W4: 0.22569444 | X4: 0.26388889 | Y4: 0 | Z4: 60
M5: Double | N5: Single | R5: GUINNESS | S5: 17 | T5: 17.5 | U5: 0 | V5: 0.10763889 | W5: 0.24652778 | X5: 0.28472222 | Y5: 0 | Z5: 60
J6: MALT LOT: Lot #44 | L6: Sheet Day | R6: MACKESON | S6: 13.3 | T6: 13.5 | U6: 0 | V6: 0.12905093 | W6: 0.27430556 | X6: 0.30208333 | Y6: 0
R7: STARMALT | S7: 17 | T7: 17.4 | U7: 0 | V7: 0.13605324 | W7: 0.27430556 | X7: 0.30902778 | Y7: 0 | Z7: 85
B8: Brand | C8: Brew no. | D8: Kett. Hls | E8: Wort | F8: Cool Time(Mins) | G8: Cast. P.G. (Lab Result) | H8: Cast P.G. (Cellar Operator)-gravity | I8: Extr. Rec (77.9%) | J8: Theor. Extr. (77.5%) | K8: Boil Off /Vol. (4-6%) | L8: Boil Time | M8: Total Hot | N8: Brewing | O8: Operator | R8: Hurricane Reef | S8: 16.6 | T8: 17 | U8: 0 | V8: 0.12905093 | W8: 0.27430556 | X8: 0.30208333 | Y8: 0
E9: Meter (Hls) | F9: Target(< 60Mins) | M9: Time | R9: VITAMALT | S9: 14.2 | T9: 14.6 | U9: 0 | V9: 0.13905093 | W9: 0.26041667 | X9: 0.29513889 | Y9: 0 | Z9: 75
B10: CARIB | C10: =[22]Brewhouse!$A740 -> CA631 | D10: =[22]Brewhouse!$AF740 -> 48.2 | E10: =[22]Brewhouse!$AI740 -> 48.8 | F10: =[22]Brewhouse!$V740 -> 60 | G10: =[22]Brewhouse!AG740 -> 11.6 | I10: =[22]Brewhouse!$AU740 -> 95.362732 | J10: =[22]Brewhouse!$AV740 -> 97.566418 | K10: =[22]Brewhouse!$Q740 -> 10.415094 | L10: =[22]Brewhouse!$P740 -> 59 | M10: =[22]Brewhouse!$U740-[22]Brewhouse!$T740 -> 0.12013889 | N10: =[22]Brewhouse!$Z740 -> 0.24791667 | O10: =[22]Brewhouse!$AX740 -> K.Benjamin | R10: =B10 -> CARIB | S10: =VLOOKUP($B10,$R$3:$X$9,2,FALSE) -> 11.6 | T10: =VLOOKUP($B10,$R$3:$X$9,3,FALSE) -> 12 | U10: =VLOOKUP($B10,$R$3:$X$9,4,FALSE) -> 0 | V10: =VLOOKUP($B10,$R$3:$X$9,5,FALSE) -> 0.11805556 | W10: =VLOOKUP($B10,$R$3:$X$9,6,FALSE) -> 0.22569444 | X10: =VLOOKUP($B10,$R$3:$X$9,7,FALSE) -> 0.26388889 | Y10: =VLOOKUP($B10,$R$3:$Z$9,8,FALSE) -> 0 | Z10: =VLOOKUP($B10,$R$3:$Z$9,9,FALSE) -> 60
B11: CARIB | C11: =[22]Brewhouse!$A741 -> CA632 | D11: =[22]Brewhouse!$AF741 -> 51.8 | E11: =[22]Brewhouse!$AI741 -> 51.4 | F11: =[22]Brewhouse!$V741 -> 62 | G11: =[22]Brewhouse!AG741 -> 11.9 | I11: =[22]Brewhouse!$AU741 -> 99.363543 | J11: =[22]Brewhouse!$AV741 -> 101.66356 | K11: =[22]Brewhouse!$Q741 -> 3.6226415 | L11: =[22]Brewhouse!$P741 -> 61 | M11: =[22]Brewhouse!$U741-[22]Brewhouse!$T741 -> 0.10694444 | N11: =[22]Brewhouse!$Z741 -> 0.25 | O11: =[22]Brewhouse!$AX741 -> R. Regis | R11: =B11 -> CARIB | S11: =VLOOKUP($B11,$R$3:$X$9,2,FALSE) -> 11.6 | T11: =VLOOKUP($B11,$R$3:$X$9,3,FALSE) -> 12 | U11: =VLOOKUP($B11,$R$3:$X$9,4,FALSE) -> 0 | V11: =VLOOKUP($B11,$R$3:$X$9,5,FALSE) -> 0.11805556 | W11: =VLOOKUP($B11,$R$3:$X$9,6,FALSE) -> 0.22569444 | X11: =VLOOKUP($B11,$R$3:$X$9,7,FALSE) -> 0.26388889 | Y11: =VLOOKUP($B11,$R$3:$Z$9,8,FALSE) -> 0 | Z11: =VLOOKUP($B11,$R$3:$Z$9,9,FALSE) -> 60
B12: CARIB | C12: =[22]Brewhouse!$A742 -> CA633 | D12: =[22]Brewhouse!$AF742 -> 53.6 | E12: =[22]Brewhouse!$AI742 -> 52.8 | F12: =[22]Brewhouse!$V742 -> 57 | G12: =[22]Brewhouse!AG742 -> 11.8 | I12: =[22]Brewhouse!$AU742 -> 101.9218 | J12: =[22]Brewhouse!$AV742 -> 104.28026 | K12: =[22]Brewhouse!$Q742 -> 2.6792453 | L12: =[22]Brewhouse!$P742 -> 59 | M12: =[22]Brewhouse!$U742-[22]Brewhouse!$T742 -> 0.10694444 | N12: =[22]Brewhouse!$Z742 -> 0.24861111 | O12: =[22]Brewhouse!$AX742 -> R. Regis | R12: =B12 -> CARIB | S12: =VLOOKUP($B12,$R$3:$X$9,2,FALSE) -> 11.6 | T12: =VLOOKUP($B12,$R$3:$X$9,3,FALSE) -> 12 | U12: =VLOOKUP($B12,$R$3:$X$9,4,FALSE) -> 0 | V12: =VLOOKUP($B12,$R$3:$X$9,5,FALSE) -> 0.11805556 | W12: =VLOOKUP($B12,$R$3:$X$9,6,FALSE) -> 0.22569444 | X12: =VLOOKUP($B12,$R$3:$X$9,7,FALSE) -> 0.26388889 | Y12: =VLOOKUP($B12,$R$3:$Z$9,8,FALSE) -> 0 | Z12: =VLOOKUP($B12,$R$3:$Z$9,9,FALSE) -> 60
B13: CARIB | C13: =[22]Brewhouse!$A743 -> CA634 | D13: =[22]Brewhouse!$AF743 -> 52.8 | E13: =[22]Brewhouse!$AI743 -> 51.4 | F13: =[22]Brewhouse!$V743 -> 62 | G13: =[22]Brewhouse!AG743 -> 11.8 | I13: =[22]Brewhouse!$AU743 -> 102.52919 | J13: =[22]Brewhouse!$AV743 -> 104.8982 | K13: =[22]Brewhouse!$Q743 -> 2.490566 | L13: =[22]Brewhouse!$P743 -> 60 | M13: =[22]Brewhouse!$U743-[22]Brewhouse!$T743 -> 0.10833333 | N13: =[22]Brewhouse!$Z743 -> 0.24097222 | O13: =[22]Brewhouse!$AX743 -> R. Regis | R13: =B13 -> CARIB | S13: =VLOOKUP($B13,$R$3:$X$9,2,FALSE) -> 11.6 | T13: =VLOOKUP($B13,$R$3:$X$9,3,FALSE) -> 12 | U13: =VLOOKUP($B13,$R$3:$X$9,4,FALSE) -> 0 | V13: =VLOOKUP($B13,$R$3:$X$9,5,FALSE) -> 0.11805556 | W13: =VLOOKUP($B13,$R$3:$X$9,6,FALSE) -> 0.22569444 | X13: =VLOOKUP($B13,$R$3:$X$9,7,FALSE) -> 0.26388889 | Y13: =VLOOKUP($B13,$R$3:$Z$9,8,FALSE) -> 0 | Z13: =VLOOKUP($B13,$R$3:$Z$9,9,FALSE) -> 60
B14: CARIB | C14: =[22]Brewhouse!$A744 -> CA635 | D14: =[22]Brewhouse!$AF744 -> 52.3 | E14: =[22]Brewhouse!$AI744 -> 50.4 | F14: =[22]Brewhouse!$V744 -> 63 | G14: =[22]Brewhouse!AG744 -> 11.8 | I14: =[22]Brewhouse!$AU744 -> 97.168341 | J14: =[22]Brewhouse!$AV744 -> 99.416931 | K14: =[22]Brewhouse!$Q744 -> 2.6792453 | L14: =[22]Brewhouse!$P744 -> 61 | M14: =[22]Brewhouse!$U744-[22]Brewhouse!$T744 -> 0.024305556 | N14: =[22]Brewhouse!$Z744 -> 0.24722222 | O14: =[22]Brewhouse!$AX744 -> R. Regis | R14: =B14 -> CARIB | S14: =VLOOKUP($B14,$R$3:$X$9,2,FALSE) -> 11.6 | T14: =VLOOKUP($B14,$R$3:$X$9,3,FALSE) -> 12 | U14: =VLOOKUP($B14,$R$3:$X$9,4,FALSE) -> 0 | V14: =VLOOKUP($B14,$R$3:$X$9,5,FALSE) -> 0.11805556 | W14: =VLOOKUP($B14,$R$3:$X$9,6,FALSE) -> 0.22569444 | X14: =VLOOKUP($B14,$R$3:$X$9,7,FALSE) -> 0.26388889 | Y14: =VLOOKUP($B14,$R$3:$Z$9,8,FALSE) -> 0 | Z14: =VLOOKUP($B14,$R$3:$Z$9,9,FALSE) -> 60
B15: CARIB | C15: =[22]Brewhouse!$A745 -> CA636 | D15: =[22]Brewhouse!$AF745 -> 52.8 | E15: =[22]Brewhouse!$AI745 -> 51.4 | F15: =[22]Brewhouse!$V745 -> 58 | G15: =[22]Brewhouse!AG745 -> 11.6 | I15: =[22]Brewhouse!$AU745 -> 96.849171 | J15: =[22]Brewhouse!$AV745 -> 99.090865 | K15: =[22]Brewhouse!$Q745 -> 3.5555556 | L15: =[22]Brewhouse!$P745 -> 57 | M15: =[22]Brewhouse!$U745-[22]Brewhouse!$T745 -> 0.10277778 | N15: =[22]Brewhouse!$Z745 -> 0.24236111 | O15: =[22]Brewhouse!$AX745 -> R.Sookram | R15: =B15 -> CARIB | S15: =VLOOKUP($B15,$R$3:$X$9,2,FALSE) -> 11.6 | T15: =VLOOKUP($B15,$R$3:$X$9,3,FALSE) -> 12 | U15: =VLOOKUP($B15,$R$3:$X$9,4,FALSE) -> 0 | V15: =VLOOKUP($B15,$R$3:$X$9,5,FALSE) -> 0.11805556 | W15: =VLOOKUP($B15,$R$3:$X$9,6,FALSE) -> 0.22569444 | X15: =VLOOKUP($B15,$R$3:$X$9,7,FALSE) -> 0.26388889 | Y15: =VLOOKUP($B15,$R$3:$Z$9,8,FALSE) -> 0 | Z15: =VLOOKUP($B15,$R$3:$Z$9,9,FALSE) -> 60
R16: =B16 -> 0 | S16: =VLOOKUP($B16,$R$3:$X$9,2,FALSE) -> #N/A | T16: =VLOOKUP($B16,$R$3:$X$9,3,FALSE) -> #N/A | U16: =VLOOKUP($B16,$R$3:$X$9,4,FALSE) -> #N/A | V16: =VLOOKUP($B16,$R$3:$X$9,5,FALSE) -> #N/A | W16: =VLOOKUP($B16,$R$3:$X$9,6,FALSE) -> #N/A | X16: =VLOOKUP($B16,$R$3:$X$9,7,FALSE) -> #N/A | Y16: =VLOOKUP($B16,$R$3:$Z$9,8,FALSE) -> #N/A | Z16: =VLOOKUP($B16,$R$3:$Z$9,9,FALSE) -> #N/A
B17: STARMALT | C17: =[23]Brewhouse!$A75 -> SM063 | D17: =[23]Brewhouse!$AH75 -> 53 | E17: =[23]Brewhouse!$AM75 -> 49.5 | F17: =[23]Brewhouse!$Z75 -> 65 | G17: =[23]Brewhouse!$AK75 -> 17.1 | I17: =[23]Brewhouse!$AY75 -> 92.872717 | J17: =[23]Brewhouse!$AZ75 -> 93.905774 | K17: =[23]Brewhouse!$U75 -> 8.0754717 | L17: =[23]Brewhouse!$T75 -> 60 | M17: =[23]Brewhouse!$Y75-[23]Brewhouse!$X75 -> 0.12916667 | N17: =[23]Brewhouse!$AD75 -> 0.27708333 | O17: =[23]Brewhouse!$BC75 -> R.Sookram | R17: =B17 -> STARMALT | S17: =VLOOKUP($B17,$R$3:$X$9,2,FALSE) -> 17 | T17: =VLOOKUP($B17,$R$3:$X$9,3,FALSE) -> 17.4 | U17: =VLOOKUP($B17,$R$3:$X$9,4,FALSE) -> 0 | V17: =VLOOKUP($B17,$R$3:$X$9,5,FALSE) -> 0.13605324 | W17: =VLOOKUP($B17,$R$3:$X$9,6,FALSE) -> 0.27430556 | X17: =VLOOKUP($B17,$R$3:$X$9,7,FALSE) -> 0.30902778 | Y17: =VLOOKUP($B17,$R$3:$Z$9,8,FALSE) -> 0 | Z17: =VLOOKUP($B17,$R$3:$Z$9,9,FALSE) -> 85
B18: STARMALT | C18: =[23]Brewhouse!$A76 -> SM064 | D18: =[23]Brewhouse!$AH76 -> 53 | E18: =[23]Brewhouse!$AM76 -> 51.7 | F18: =[23]Brewhouse!$Z76 -> 64 | G18: =[23]Brewhouse!$AK76 -> 17.2 | I18: =[23]Brewhouse!$AY76 -> 97.504936 | J18: =[23]Brewhouse!$AZ76 -> 98.590541 | K18: =[23]Brewhouse!$U76 -> 7.3207547 | L18: =[23]Brewhouse!$T76 -> 62 | M18: =[23]Brewhouse!$Y76-[23]Brewhouse!$X76 -> 0.12777778 | N18: =[23]Brewhouse!$AD76 -> 0.28125 | O18: =[23]Brewhouse!$BC76 -> K. Benjamin | R18: =B18 -> STARMALT | S18: =VLOOKUP($B18,$R$3:$X$9,2,FALSE) -> 17 | T18: =VLOOKUP($B18,$R$3:$X$9,3,FALSE) -> 17.4 | U18: =VLOOKUP($B18,$R$3:$X$9,4,FALSE) -> 0 | V18: =VLOOKUP($B18,$R$3:$X$9,5,FALSE) -> 0.13605324 | W18: =VLOOKUP($B18,$R$3:$X$9,6,FALSE) -> 0.27430556 | X18: =VLOOKUP($B18,$R$3:$X$9,7,FALSE) -> 0.30902778 | Y18: =VLOOKUP($B18,$R$3:$Z$9,8,FALSE) -> 0 | Z18: =VLOOKUP($B18,$R$3:$Z$9,9,FALSE) -> 85
B19: STARMALT | C19: =[23]Brewhouse!$A77 -> SM065 | D19: =[23]Brewhouse!$AH77 -> 53 | E19: =[23]Brewhouse!$AM77 -> 51.9 | F19: =[23]Brewhouse!$Z77 -> 70 | G19: =[23]Brewhouse!$AK77 -> 17.2 | I19: =[23]Brewhouse!$AY77 -> 97.882131 | J19: =[23]Brewhouse!$AZ77 -> 98.971936 | K19: =[23]Brewhouse!$U77 -> 6 | L19: =[23]Brewhouse!$T77 -> 61 | M19: =[23]Brewhouse!$Y77-[23]Brewhouse!$X77 -> 0.12708333 | N19: =[23]Brewhouse!$AD77 -> 0.275 | O19: =[23]Brewhouse!$BC77 -> K. Benjamin | R19: =B19 -> STARMALT | S19: =VLOOKUP($B19,$R$3:$X$9,2,FALSE) -> 17 | T19: =VLOOKUP($B19,$R$3:$X$9,3,FALSE) -> 17.4 | U19: =VLOOKUP($B19,$R$3:$X$9,4,FALSE) -> 0 | V19: =VLOOKUP($B19,$R$3:$X$9,5,FALSE) -> 0.13605324 | W19: =VLOOKUP($B19,$R$3:$X$9,6,FALSE) -> 0.27430556 | X19: =VLOOKUP($B19,$R$3:$X$9,7,FALSE) -> 0.30902778 | Y19: =VLOOKUP($B19,$R$3:$Z$9,8,FALSE) -> 0 | Z19: =VLOOKUP($B19,$R$3:$Z$9,9,FALSE) -> 85
R20: =B20 -> 0 | S20: =VLOOKUP($B20,$R$3:$X$9,2,FALSE) -> #N/A | T20: =VLOOKUP($B20,$R$3:$X$9,3,FALSE) -> #N/A | U20: =VLOOKUP($B20,$R$3:$X$9,4,FALSE) -> #N/A | V20: =VLOOKUP($B20,$R$3:$X$9,5,FALSE) -> #N/A | W20: =VLOOKUP($B20,$R$3:$X$9,6,FALSE) -> #N/A | X20: =VLOOKUP($B20,$R$3:$X$9,7,FALSE) -> #N/A | Y20: =VLOOKUP($B20,$R$3:$Z$9,8,FALSE) -> #N/A | Z20: =VLOOKUP($B20,$R$3:$Z$9,9,FALSE) -> #N/A
R21: =B21 -> 0 | S21: =VLOOKUP($B21,$R$3:$X$9,2,FALSE) -> #N/A | T21: =VLOOKUP($B21,$R$3:$X$9,3,FALSE) -> #N/A | U21: =VLOOKUP($B21,$R$3:$X$9,4,FALSE) -> #N/A | V21: =VLOOKUP($B21,$R$3:$X$9,5,FALSE) -> #N/A | W21: =VLOOKUP($B21,$R$3:$X$9,6,FALSE) -> #N/A | X21: =VLOOKUP($B21,$R$3:$X$9,7,FALSE) -> #N/A | Y21: =VLOOKUP($B21,$R$3:$Z$9,8,FALSE) -> #N/A | Z21: =VLOOKUP($B21,$R$3:$Z$9,9,FALSE) -> #N/A
R22: =B22 -> 0 | S22: =VLOOKUP($B22,$R$3:$X$9,2,FALSE) -> #N/A | T22: =VLOOKUP($B22,$R$3:$X$9,3,FALSE) -> #N/A | U22: =VLOOKUP($B22,$R$3:$X$9,4,FALSE) -> #N/A | V22: =VLOOKUP($B22,$R$3:$X$9,5,FALSE) -> #N/A | W22: =VLOOKUP($B22,$R$3:$X$9,6,FALSE) -> #N/A | X22: =VLOOKUP($B22,$R$3:$X$9,7,FALSE) -> #N/A | Y22: =VLOOKUP($B22,$R$3:$Z$9,8,FALSE) -> #N/A | Z22: =VLOOKUP($B22,$R$3:$Z$9,9,FALSE) -> #N/A
R23: =B23 -> 0 | S23: =VLOOKUP($B23,$R$3:$X$9,2,FALSE) -> #N/A | T23: =VLOOKUP($B23,$R$3:$X$9,3,FALSE) -> #N/A | U23: =VLOOKUP($B23,$R$3:$X$9,4,FALSE) -> #N/A | V23: =VLOOKUP($B23,$R$3:$X$9,5,FALSE) -> #N/A | W23: =VLOOKUP($B23,$R$3:$X$9,6,FALSE) -> #N/A | X23: =VLOOKUP($B23,$R$3:$X$9,7,FALSE) -> #N/A | Y23: =VLOOKUP($B23,$R$3:$Z$9,8,FALSE) -> #N/A | Z23: =VLOOKUP($B23,$R$3:$Z$9,9,FALSE) -> #N/A
R24: =B24 -> 0 | S24: =VLOOKUP($B24,$R$3:$X$9,2,FALSE) -> #N/A | T24: =VLOOKUP($B24,$R$3:$X$9,3,FALSE) -> #N/A | U24: =VLOOKUP($B24,$R$3:$X$9,4,FALSE) -> #N/A | V24: =VLOOKUP($B24,$R$3:$X$9,5,FALSE) -> #N/A | W24: =VLOOKUP($B24,$R$3:$X$9,6,FALSE) -> #N/A | X24: =VLOOKUP($B24,$R$3:$X$9,7,FALSE) -> #N/A | Y24: =VLOOKUP($B24,$R$3:$Z$9,8,FALSE) -> #N/A | Z24: =VLOOKUP($B24,$R$3:$Z$9,9,FALSE) -> #N/A
R25: =B25 -> 0 | S25: =VLOOKUP($B25,$R$3:$X$9,2,FALSE) -> #N/A | T25: =VLOOKUP($B25,$R$3:$X$9,3,FALSE) -> #N/A | U25: =VLOOKUP($B25,$R$3:$X$9,4,FALSE) -> #N/A | V25: =VLOOKUP($B25,$R$3:$X$9,5,FALSE) -> #N/A | W25: =VLOOKUP($B25,$R$3:$X$9,6,FALSE) -> #N/A | X25: =VLOOKUP($B25,$R$3:$X$9,7,FALSE) -> #N/A | Y25: =VLOOKUP($B25,$R$3:$Z$9,8,FALSE) -> #N/A | Z25: =VLOOKUP($B25,$R$3:$Z$9,9,FALSE) -> #N/A
R26: =B26 -> 0 | S26: =VLOOKUP($B26,$R$3:$X$9,2,FALSE) -> #N/A | T26: =VLOOKUP($B26,$R$3:$X$9,3,FALSE) -> #N/A | U26: =VLOOKUP($B26,$R$3:$X$9,4,FALSE) -> #N/A | V26: =VLOOKUP($B26,$R$3:$X$9,5,FALSE) -> #N/A | W26: =VLOOKUP($B26,$R$3:$X$9,6,FALSE) -> #N/A | X26: =VLOOKUP($B26,$R$3:$X$9,7,FALSE) -> #N/A | Y26: =VLOOKUP($B26,$R$3:$Z$9,8,FALSE) -> #N/A | Z26: =VLOOKUP($B26,$R$3:$Z$9,9,FALSE) -> #N/A
R27: =B27 -> 0 | S27: =VLOOKUP($B27,$R$3:$X$9,2,FALSE) -> #N/A | T27: =VLOOKUP($B27,$R$3:$X$9,3,FALSE) -> #N/A | U27: =VLOOKUP($B27,$R$3:$X$9,4,FALSE) -> #N/A | V27: =VLOOKUP($B27,$R$3:$X$9,5,FALSE) -> #N/A | W27: =VLOOKUP($B27,$R$3:$X$9,6,FALSE) -> #N/A | X27: =VLOOKUP($B27,$R$3:$X$9,7,FALSE) -> #N/A | Y27: =VLOOKUP($B27,$R$3:$Z$9,8,FALSE) -> #N/A | Z27: =VLOOKUP($B27,$R$3:$Z$9,9,FALSE) -> #N/A
B28: BRAND | D28: BBT P.G./ O.G | I28: Brand | J28: Actual | K28: MTD No. of Brews | L28: MTD | M28: YTD | N28: Target | R28: =B28 -> BRAND | S28: =VLOOKUP($B28,$R$3:$X$9,2,FALSE) -> #N/A | T28: =VLOOKUP($B28,$R$3:$X$9,3,FALSE) -> #N/A | U28: =VLOOKUP($B28,$R$3:$X$9,4,FALSE) -> #N/A | V28: =VLOOKUP($B28,$R$3:$X$9,5,FALSE) -> #N/A | W28: =VLOOKUP($B28,$R$3:$X$9,6,FALSE) -> #N/A | X28: =VLOOKUP($B28,$R$3:$X$9,7,FALSE) -> #N/A | Y28: =VLOOKUP($B28,$R$3:$Z$9,8,FALSE) -> #N/A | Z28: =VLOOKUP($B28,$R$3:$Z$9,9,FALSE) -> #N/A
I29: CARIB | J29: =AVERAGE(I10:I15) -> 98.865796 | K29: =COUNTA([22]Brewhouse!$A$740:$A$745) -> 6 | L29: =AVERAGE([22]Brewhouse!$AU$740:$AU$745) -> 98.865796 | M29: =AVERAGE([22]Brewhouse!$AU$102:$AU$171,[22]Brewhouse!$AU$173:$AU$253,[22]Brewhouse!$AU$255:$AU$339,[22]Brewhouse!$AU$341:$AU$346,[22]Brewhouse!$AU$348,[22]Brewhouse!$AU$349:$AU$406,[22]Brewhouse!$AU$408:$AU$491,[22]Brewhouse!$AU$493:$AU$578,[22]Brewhouse!$AU$580:$AU$652,[22]Brewhouse!$AU$655:$AU$745) -> 97.716623 | N29: 98 | R29: =B29 -> 0 | S29: =VLOOKUP($B29,$R$3:$X$9,2,FALSE) -> #N/A | T29: =VLOOKUP($B29,$R$3:$X$9,3,FALSE) -> #N/A | U29: =VLOOKUP($B29,$R$3:$X$9,4,FALSE) -> #N/A | V29: =VLOOKUP($B29,$R$3:$X$9,5,FALSE) -> #N/A | W29: =VLOOKUP($B29,$R$3:$X$9,6,FALSE) -> #N/A | X29: =VLOOKUP($B29,$R$3:$X$9,7,FALSE) -> #N/A | Y29: =VLOOKUP($B29,$R$3:$Z$9,8,FALSE) -> #N/A | Z29: =VLOOKUP($B29,$R$3:$Z$9,9,FALSE) -> #N/A
I30: STAG | M30: =AVERAGE([24]Brewhouse!$AS$15:$AS$64,[24]Brewhouse!$AS$66:$AS$103,[24]Brewhouse!$AS$105:$AS$140,[24]Brewhouse!$AS$142:$AS$193,[24]Brewhouse!$AS$195:$AS$240,[24]Brewhouse!$AS$242:$AS$273,[24]Brewhouse!$AS$275:$AS$322,[24]Brewhouse!$AS$324:$AS$359) -> 98.06549 | N30: 98 | R30: =B30 -> 0 | S30: =VLOOKUP($B30,$R$3:$X$9,2,FALSE) -> #N/A | T30: =VLOOKUP($B30,$R$3:$X$9,3,FALSE) -> #N/A | U30: =VLOOKUP($B30,$R$3:$X$9,4,FALSE) -> #N/A | V30: =VLOOKUP($B30,$R$3:$X$9,5,FALSE) -> #N/A | W30: =VLOOKUP($B30,$R$3:$X$9,6,FALSE) -> #N/A | X30: =VLOOKUP($B30,$R$3:$X$9,7,FALSE) -> #N/A | Y30: =VLOOKUP($B30,$R$3:$Z$9,8,FALSE) -> #N/A | Z30: =VLOOKUP($B30,$R$3:$Z$9,9,FALSE) -> #N/A
I31: GUINNESS | M31: =AVERAGE([25]Brewhouse!$AU$4:$AU$7,[25]Brewhouse!$AU$9:$AU$22,[25]Brewhouse!$AU$24:$AU$35,[25]Brewhouse!$AU$37:$AU$45,[25]Brewhouse!$AU$47:$AU$62,[25]Brewhouse!$AU$64:$AU$79,[25]Brewhouse!$AU$81:$AU$92) -> 96.938185 | N31: 98 | R31: =B31 -> 0 | S31: =VLOOKUP($B31,$R$3:$X$9,2,FALSE) -> #N/A | T31: =VLOOKUP($B31,$R$3:$X$9,3,FALSE) -> #N/A | U31: =VLOOKUP($B31,$R$3:$X$9,4,FALSE) -> #N/A | V31: =VLOOKUP($B31,$R$3:$X$9,5,FALSE) -> #N/A | W31: =VLOOKUP($B31,$R$3:$X$9,6,FALSE) -> #N/A | X31: =VLOOKUP($B31,$R$3:$X$9,7,FALSE) -> #N/A | Y31: =VLOOKUP($B31,$R$3:$Z$9,8,FALSE) -> #N/A | Z31: =VLOOKUP($B31,$R$3:$Z$9,9,FALSE) -> #N/A
I32: VITAMALT | M32: =AVERAGE([26]Brewhouse!$AV$5:$AV$14,[26]Brewhouse!$AV$16:$AV$19,[26]Brewhouse!$AV$21:$AV$24,[26]Brewhouse!$AV$26:$AV$33,[26]Brewhouse!$AV$35:$AV$46,[26]Brewhouse!$AV$48:$AV$53,[26]Brewhouse!$AV$55:$AV$62,[26]Brewhouse!$AV$64:$AV$77) -> 98.521411 | N32: 98 | R32: =B32 -> 0 | S32: =VLOOKUP($B32,$R$3:$X$9,2,FALSE) -> #N/A | T32: =VLOOKUP($B32,$R$3:$X$9,3,FALSE) -> #N/A | U32: =VLOOKUP($B32,$R$3:$X$9,4,FALSE) -> #N/A | V32: =VLOOKUP($B32,$R$3:$X$9,5,FALSE) -> #N/A | W32: =VLOOKUP($B32,$R$3:$X$9,6,FALSE) -> #N/A | X32: =VLOOKUP($B32,$R$3:$X$9,7,FALSE) -> #N/A | Y32: =VLOOKUP($B32,$R$3:$Z$9,8,FALSE) -> #N/A | Z32: =VLOOKUP($B32,$R$3:$Z$9,9,FALSE) -> #N/A
I33: MAXIMALT | N33: 98 | R33: =B33 -> 0 | S33: =VLOOKUP($B33,$R$3:$X$9,2,FALSE) -> #N/A | T33: =VLOOKUP($B33,$R$3:$X$9,3,FALSE) -> #N/A | U33: =VLOOKUP($B33,$R$3:$X$9,4,FALSE) -> #N/A | V33: =VLOOKUP($B33,$R$3:$X$9,5,FALSE) -> #N/A | W33: =VLOOKUP($B33,$R$3:$X$9,6,FALSE) -> #N/A | X33: =VLOOKUP($B33,$R$3:$X$9,7,FALSE) -> #N/A | Y33: =VLOOKUP($B33,$R$3:$Z$9,8,FALSE) -> #N/A | Z33: =VLOOKUP($B33,$R$3:$Z$9,9,FALSE) -> #N/A
I34: MACKESON | M34: =AVERAGE([27]Brewhouse!$AT$4:$AT$11,[27]Brewhouse!$AT$13:$AT$16,[27]Brewhouse!$AT$18:$AT$21,[27]Brewhouse!$AT$26) -> 94.588058 | N34: 98
I35: STARMALT | J35: =AVERAGE(I17:I19) -> 96.086595 | K35: =COUNTA([23]Brewhouse!$A$75:$A$77) -> 3 | L35: =AVERAGE([23]Brewhouse!$AY$75:$AY$77) -> 96.086595 | M35: =AVERAGE([23]Brewhouse!$AY$6:$AY$13,[23]Brewhouse!$AY$15:$AY$20,[23]Brewhouse!$AY$22:$AY$29,[23]Brewhouse!$AY$31:$AY$34,[23]Brewhouse!$AY$36:$AY$43,[23]Brewhouse!$AY$45:$AY$50, [23]Brewhouse!$AY$56:$AY$73,[23]Brewhouse!$AY$75:$AY$77) -> 97.30094 | N35: 98
I36: HR- Pils | M36: =AVERAGE([28]Brewhouse!$AU$5:$AU$8,[28]Brewhouse!$AU$10:$AU$13,[23]Brewhouse!$AY$75:$AY$77) -> 94.749192 | N36: 98
I37: HR- IPA | M37: =AVERAGE([29]Brewhouse!$AW$26:$AW$27) -> 95.310681 | N37: 98
I38: HR- APA | M38: =AVERAGE([30]Brewhouse!$AU$13:$AU$14) -> 97.110575 | N38: 98
K39: =SUM(K29:K38) -> 9 | L39: =((L29*K29)+(L30*K30)+(L31*K31)+(L32*K32)+(L33*K33)+(K36*L36)+(L34*K34)+(L35*K35)+(L38*K38))/(K39) -> 97.939395 | M39: =AVERAGE('[31]Jan 31st'!$L$65,'[32]Feb 28th'!$L$35,'[33]Mar. 31st'!$L$35,'[34]Apr. 30th'!$L$45,'[35]May 30th'!$L$37,'[36]June 30th'!$L$57,L39) -> 97.698758 | N39: 98
J41: Daily Brewing Plan
...

Sheet Sept 2nd
S1: P.G. | U1: Hot Time | W1: Process Time | Y1: Cooling Time
B2: Brewing Department Daily Process Loss Report | S2: Lower | T2: Upper | U2: Lower | V2: Upper | W2: Lower | X2: Upper | Y2: Lower | Z2: Upper
R3: CARIB | S3: 11.6 | T3: 12 | U3: 0 | V3: 0.11805556 | W3: 0.22569444 | X3: 0.26388889 | Y3: 0 | Z3: 60 | AB3: HR- PISNER
B4: Date: | C4: 45903 | J4: LOT WORT COLOUR: 3.5 | M4: Filter Sheets (Target 20 days) | R4: STAG | S4: 11.6 | T4: 12 | U4: 0 | V4: 0.11805556 | W4: 0.22569444 | X4: 0.26388889 | Y4: 0 | Z4: 60
M5: Double | N5: Single | R5: GUINNESS | S5: 17 | T5: 17.5 | U5: 0 | V5: 0.10763889 | W5: 0.24652778 | X5: 0.28472222 | Y5: 0 | Z5: 60
J6: MALT LOT: Lot #44 | L6: Sheet Day | R6: MACKESON | S6: 13.3 | T6: 13.5 | U6: 0 | V6: 0.12905093 | W6: 0.27430556 | X6: 0.30208333 | Y6: 0
R7: STARMALT | S7: 17 | T7: 17.4 | U7: 0 | V7: 0.13605324 | W7: 0.27430556 | X7: 0.30902778 | Y7: 0 | Z7: 85
B8: Brand | C8: Brew no. | D8: Kett. Hls | E8: Wort | F8: Cool Time(Mins) | G8: Cast. P.G. (Lab Result) | H8: Cast P.G. (Cellar Operator)-gravity | I8: Extr. Rec (77.9%) | J8: Theor. Extr. (77.5%) | K8: Boil Off /Vol. (4-6%) | L8: Boil Time | M8: Total Hot | N8: Brewing | O8: Operator | R8: Hurricane Reef | S8: 16.6 | T8: 17 | U8: 0 | V8: 0.12905093 | W8: 0.27430556 | X8: 0.30208333 | Y8: 0
E9: Meter (Hls) | F9: Target(< 60Mins) | M9: Time | R9: VITAMALT | S9: 14.2 | T9: 14.6 | U9: 0 | V9: 0.13905093 | W9: 0.26041667 | X9: 0.29513889 | Y9: 0 | Z9: 75
B10: STARMALT | C10: =[23]Brewhouse!$A78 -> SM066 | D10: =[23]Brewhouse!$AH78 -> 53 | E10: =[23]Brewhouse!$AM78 -> 51.9 | F10: =[23]Brewhouse!$Z78 -> 73 | G10: =[23]Brewhouse!$AK78 -> 17.2 | I10: =[23]Brewhouse!$AY78 -> 97.485149 | J10: =[23]Brewhouse!$AZ78 -> 98.575621 | K10: =[23]Brewhouse!$U78 -> 5.6226415 | L10: =[23]Brewhouse!$T78 -> 60 | M10: =[23]Brewhouse!$Y78-[23]Brewhouse!$X78 -> 0.13055556 | N10: =[23]Brewhouse!$AD78 -> 0.27916667 | O10: =[23]Brewhouse!$BC78 -> K. Benjamin | R10: =B10 -> STARMALT | S10: =VLOOKUP($B10,$R$3:$X$9,2,FALSE) -> 17 | T10: =VLOOKUP($B10,$R$3:$X$9,3,FALSE) -> 17.4 | U10: =VLOOKUP($B10,$R$3:$X$9,4,FALSE) -> 0 | V10: =VLOOKUP($B10,$R$3:$X$9,5,FALSE) -> 0.13605324 | W10: =VLOOKUP($B10,$R$3:$X$9,6,FALSE) -> 0.27430556 | X10: =VLOOKUP($B10,$R$3:$X$9,7,FALSE) -> 0.30902778 | Y10: =VLOOKUP($B10,$R$3:$Z$9,8,FALSE) -> 0 | Z10: =VLOOKUP($B10,$R$3:$Z$9,9,FALSE) -> 85
B11: STARMALT | C11: =[23]Brewhouse!$A79 -> SM067 | D11: =[23]Brewhouse!$AH79 -> 53 | E11: =[23]Brewhouse!$AM79 -> 52 | F11: =[23]Brewhouse!$Z79 -> 67 | G11: =[23]Brewhouse!$AK79 -> 17.6 | I11: =[23]Brewhouse!$AY79 -> 99.793676 | J11: =[23]Brewhouse!$AZ79 -> 100.91411 | K11: =[23]Brewhouse!$U79 -> 15.433962 | L11: =[23]Brewhouse!$T79 -> 62 | M11: =[23]Brewhouse!$Y79-[23]Brewhouse!$X79 -> 0.20625 | N11: =[23]Brewhouse!$AD79 -> 0.36319444 | O11: =[23]Brewhouse!$BC79 -> K. Benjamin | R11: =B11 -> STARMALT | S11: =VLOOKUP($B11,$R$3:$X$9,2,FALSE) -> 17 | T11: =VLOOKUP($B11,$R$3:$X$9,3,FALSE) -> 17.4 | U11: =VLOOKUP($B11,$R$3:$X$9,4,FALSE) -> 0 | V11: =VLOOKUP($B11,$R$3:$X$9,5,FALSE) -> 0.13605324 | W11: =VLOOKUP($B11,$R$3:$X$9,6,FALSE) -> 0.27430556 | X11: =VLOOKUP($B11,$R$3:$X$9,7,FALSE) -> 0.30902778 | Y11: =VLOOKUP($B11,$R$3:$Z$9,8,FALSE) -> 0 | Z11: =VLOOKUP($B11,$R$3:$Z$9,9,FALSE) -> 85
B12: STARMALT | C12: =[23]Brewhouse!$A80 -> SM068 | D12: =[23]Brewhouse!$AH80 -> 53.1 | E12: =[23]Brewhouse!$AM80 -> 53.4 | F12: =[23]Brewhouse!$Z80 -> 71 | G12: =[23]Brewhouse!$AK80 -> 16.9 | I12: =[23]Brewhouse!$AY80 -> 98.208221 | J12: =[23]Brewhouse!$AZ80 -> 99.309836 | K12: =[23]Brewhouse!$U80 -> 5.4237288 | L12: =[23]Brewhouse!$T80 -> 59 | M12: =[23]Brewhouse!$Y80-[23]Brewhouse!$X80 -> 0.13194444 | N12: =[23]Brewhouse!$AD80 -> 0.4125 | O12: =[23]Brewhouse!$BC80 -> R. Regis | R12: =B12 -> STARMALT | S12: =VLOOKUP($B12,$R$3:$X$9,2,FALSE) -> 17 | T12: =VLOOKUP($B12,$R$3:$X$9,3,FALSE) -> 17.4 | U12: =VLOOKUP($B12,$R$3:$X$9,4,FALSE) -> 0 | V12: =VLOOKUP($B12,$R$3:$X$9,5,FALSE) -> 0.13605324 | W12: =VLOOKUP($B12,$R$3:$X$9,6,FALSE) -> 0.27430556 | X12: =VLOOKUP($B12,$R$3:$X$9,7,FALSE) -> 0.30902778 | Y12: =VLOOKUP($B12,$R$3:$Z$9,8,FALSE) -> 0 | Z12: =VLOOKUP($B12,$R$3:$Z$9,9,FALSE) -> 85
B13: STARMALT | C13: =[23]Brewhouse!$A81 -> SM069 | D13: =[23]Brewhouse!$AH81 -> 53.1 | E13: =[23]Brewhouse!$AM81 -> 53.4 | F13: =[23]Brewhouse!$Z81 -> 65 | G13: =[23]Brewhouse!$AK81 -> 17.2 | I13: =[23]Brewhouse!$AY81 -> 100.22135 | J13: =[23]Brewhouse!$AZ81 -> 101.34346 | K13: =[23]Brewhouse!$U81 -> 4.1054614 | L13: =[23]Brewhouse!$T81 -> 70 | M13: =[23]Brewhouse!$Y81-[23]Brewhouse!$X81 -> 0.15208333 | N13: =[23]Brewhouse!$AD81 -> 0.31597222 | O13: =[23]Brewhouse!$BC81 -> R. Regis | R13: =B13 -> STARMALT | S13: =VLOOKUP($B13,$R$3:$X$9,2,FALSE) -> 17 | T13: =VLOOKUP($B13,$R$3:$X$9,3,FALSE) -> 17.4 | U13: =VLOOKUP($B13,$R$3:$X$9,4,FALSE) -> 0 | V13: =VLOOKUP($B13,$R$3:$X$9,5,FALSE) -> 0.13605324 | W13: =VLOOKUP($B13,$R$3:$X$9,6,FALSE) -> 0.27430556 | X13: =VLOOKUP($B13,$R$3:$X$9,7,FALSE) -> 0.30902778 | Y13: =VLOOKUP($B13,$R$3:$Z$9,8,FALSE) -> 0 | Z13: =VLOOKUP($B13,$R$3:$Z$9,9,FALSE) -> 85
B14: STARMALT | C14: =[23]Brewhouse!$A82 -> SM070 | D14: =[23]Brewhouse!$AH82 -> 53.1 | E14: =[23]Brewhouse!$AM82 -> 52.5 | F14: =[23]Brewhouse!$Z82 -> 80 | G14: =[23]Brewhouse!$AK82 -> 17.1 | I14: =[23]Brewhouse!$AY82 -> 97.942529 | J14: =[23]Brewhouse!$AZ82 -> 99.039134 | K14: =[23]Brewhouse!$U82 -> 4.2937853 | L14: =[23]Brewhouse!$T82 -> 69 | M14: =[23]Brewhouse!$Y82-[23]Brewhouse!$X82 -> 0.14375 | N14: =[23]Brewhouse!$AD82 -> 0.31944444 | O14: =[23]Brewhouse!$BC82 -> R.Sookram | R14: =B14 -> STARMALT | S14: =VLOOKUP($B14,$R$3:$X$9,2,FALSE) -> 17 | T14: =VLOOKUP($B14,$R$3:$X$9,3,FALSE) -> 17.4 | U14: =VLOOKUP($B14,$R$3:$X$9,4,FALSE) -> 0 | V14: =VLOOKUP($B14,$R$3:$X$9,5,FALSE) -> 0.13605324 | W14: =VLOOKUP($B14,$R$3:$X$9,6,FALSE) -> 0.27430556 | X14: =VLOOKUP($B14,$R$3:$X$9,7,FALSE) -> 0.30902778 | Y14: =VLOOKUP($B14,$R$3:$Z$9,8,FALSE) -> 0 | Z14: =VLOOKUP($B14,$R$3:$Z$9,9,FALSE) -> 85
R15: =B15 -> 0 | S15: =VLOOKUP($B15,$R$3:$X$9,2,FALSE) -> #N/A | T15: =VLOOKUP($B15,$R$3:$X$9,3,FALSE) -> #N/A | U15: =VLOOKUP($B15,$R$3:$X$9,4,FALSE) -> #N/A | V15: =VLOOKUP($B15,$R$3:$X$9,5,FALSE) -> #N/A | W15: =VLOOKUP($B15,$R$3:$X$9,6,FALSE) -> #N/A | X15: =VLOOKUP($B15,$R$3:$X$9,7,FALSE) -> #N/A | Y15: =VLOOKUP($B15,$R$3:$Z$9,8,FALSE) -> #N/A | Z15: =VLOOKUP($B15,$R$3:$Z$9,9,FALSE) -> #N/A
B16: CARIB | C16: =[22]Brewhouse!$A746 -> CA637 | D16: =[22]Brewhouse!$AF746 -> 50.9 | E16: =[22]Brewhouse!$AI746 -> 48.7 | F16: =[22]Brewhouse!$V746 -> 49 | G16: =[22]Brewhouse!AG746 -> 11.8 | I16: =[22]Brewhouse!$AU746 -> 93.373778 | J16: =[22]Brewhouse!$AV746 -> 95.445671 | K16: =[22]Brewhouse!$Q746 -> 9.2962963 | L16: =[22]Brewhouse!$P746 -> 60 | M16: =[22]Brewhouse!$U746-[22]Brewhouse!$T746 -> 0.10347222 | N16: =[22]Brewhouse!$Z746 -> 0.23263889 | O16: =[22]Brewhouse!$AX746 -> R.Sookram | R16: =B16 -> CARIB | S16: =VLOOKUP($B16,$R$3:$X$9,2,FALSE) -> 11.6 | T16: =VLOOKUP($B16,$R$3:$X$9,3,FALSE) -> 12 | U16: =VLOOKUP($B16,$R$3:$X$9,4,FALSE) -> 0 | V16: =VLOOKUP($B16,$R$3:$X$9,5,FALSE) -> 0.11805556 | W16: =VLOOKUP($B16,$R$3:$X$9,6,FALSE) -> 0.22569444 | X16: =VLOOKUP($B16,$R$3:$X$9,7,FALSE) -> 0.26388889 | Y16: =VLOOKUP($B16,$R$3:$Z$9,8,FALSE) -> 0 | Z16: =VLOOKUP($B16,$R$3:$Z$9,9,FALSE) -> 60
B17: CARIB | C17: =[22]Brewhouse!$A747 -> CA638 | D17: =[22]Brewhouse!$AF747 -> 52.4 | E17: =[22]Brewhouse!$AI747 -> 49.7 | F17: =[22]Brewhouse!$V747 -> 52 | G17: =[22]Brewhouse!AG747 -> 11.9 | I17: =[22]Brewhouse!$AU747 -> 95.786153 | J17: =[22]Brewhouse!$AV747 -> 97.912271 | K17: =[22]Brewhouse!$Q747 -> 5.6981132 | L17: =[22]Brewhouse!$P747 -> 60 | M17: =[22]Brewhouse!$U747-[22]Brewhouse!$T747 -> 0.10763889 | N17: =[22]Brewhouse!$Z747 -> 0.23888889 | O17: =[22]Brewhouse!$AX747 -> K.Benjamin | R17: =B17 -> CARIB | S17: =VLOOKUP($B17,$R$3:$X$9,2,FALSE) -> 11.6 | T17: =VLOOKUP($B17,$R$3:$X$9,3,FALSE) -> 12 | U17: =VLOOKUP($B17,$R$3:$X$9,4,FALSE) -> 0 | V17: =VLOOKUP($B17,$R$3:$X$9,5,FALSE) -> 0.11805556 | W17: =VLOOKUP($B17,$R$3:$X$9,6,FALSE) -> 0.22569444 | X17: =VLOOKUP($B17,$R$3:$X$9,7,FALSE) -> 0.26388889 | Y17: =VLOOKUP($B17,$R$3:$Z$9,8,FALSE) -> 0 | Z17: =VLOOKUP($B17,$R$3:$Z$9,9,FALSE) -> 60
B18: CARIB | C18: =[22]Brewhouse!$A748 -> CA639 | D18: =[22]Brewhouse!$AF748 -> 52.3 | E18: =[22]Brewhouse!$AI748 -> 50.7 | F18: =[22]Brewhouse!$V748 -> 53 | G18: =[22]Brewhouse!AG748 -> 11.9 | I18: =[22]Brewhouse!$AU748 -> 98.495905 | J18: =[22]Brewhouse!$AV748 -> 100.77534 | K18: =[22]Brewhouse!$Q748 -> 3.6226415 | L18: =[22]Brewhouse!$P748 -> 60 | M18: =[22]Brewhouse!$U748-[22]Brewhouse!$T748 -> 0.10486111 | N18: =[22]Brewhouse!$Z748 -> 0.24305556 | O18: =[22]Brewhouse!$AX748 -> K.Benjamin | R18: =B18 -> CARIB | S18: =VLOOKUP($B18,$R$3:$X$9,2,FALSE) -> 11.6 | T18: =VLOOKUP($B18,$R$3:$X$9,3,FALSE) -> 12 | U18: =VLOOKUP($B18,$R$3:$X$9,4,FALSE) -> 0 | V18: =VLOOKUP($B18,$R$3:$X$9,5,FALSE) -> 0.11805556 | W18: =VLOOKUP($B18,$R$3:$X$9,6,FALSE) -> 0.22569444 | X18: =VLOOKUP($B18,$R$3:$X$9,7,FALSE) -> 0.26388889 | Y18: =VLOOKUP($B18,$R$3:$Z$9,8,FALSE) -> 0 | Z18: =VLOOKUP($B18,$R$3:$Z$9,9,FALSE) -> 60
R19: =B19 -> 0 | S19: =VLOOKUP($B19,$R$3:$X$9,2,FALSE) -> #N/A | T19: =VLOOKUP($B19,$R$3:$X$9,3,FALSE) -> #N/A | U19: =VLOOKUP($B19,$R$3:$X$9,4,FALSE) -> #N/A | V19: =VLOOKUP($B19,$R$3:$X$9,5,FALSE) -> #N/A | W19: =VLOOKUP($B19,$R$3:$X$9,6,FALSE) -> #N/A | X19: =VLOOKUP($B19,$R$3:$X$9,7,FALSE) -> #N/A | Y19: =VLOOKUP($B19,$R$3:$Z$9,8,FALSE) -> #N/A | Z19: =VLOOKUP($B19,$R$3:$Z$9,9,FALSE) -> #N/A
R20: =B20 -> 0 | S20: =VLOOKUP($B20,$R$3:$X$9,2,FALSE) -> #N/A | T20: =VLOOKUP($B20,$R$3:$X$9,3,FALSE) -> #N/A | U20: =VLOOKUP($B20,$R$3:$X$9,4,FALSE) -> #N/A | V20: =VLOOKUP($B20,$R$3:$X$9,5,FALSE) -> #N/A | W20: =VLOOKUP($B20,$R$3:$X$9,6,FALSE) -> #N/A | X20: =VLOOKUP($B20,$R$3:$X$9,7,FALSE) -> #N/A | Y20: =VLOOKUP($B20,$R$3:$Z$9,8,FALSE) -> #N/A | Z20: =VLOOKUP($B20,$R$3:$Z$9,9,FALSE) -> #N/A
R21: =B21 -> 0 | S21: =VLOOKUP($B21,$R$3:$X$9,2,FALSE) -> #N/A | T21: =VLOOKUP($B21,$R$3:$X$9,3,FALSE) -> #N/A | U21: =VLOOKUP($B21,$R$3:$X$9,4,FALSE) -> #N/A | V21: =VLOOKUP($B21,$R$3:$X$9,5,FALSE) -> #N/A | W21: =VLOOKUP($B21,$R$3:$X$9,6,FALSE) -> #N/A | X21: =VLOOKUP($B21,$R$3:$X$9,7,FALSE) -> #N/A | Y21: =VLOOKUP($B21,$R$3:$Z$9,8,FALSE) -> #N/A | Z21: =VLOOKUP($B21,$R$3:$Z$9,9,FALSE) -> #N/A
R22: =B22 -> 0 | S22: =VLOOKUP($B22,$R$3:$X$9,2,FALSE) -> #N/A | T22: =VLOOKUP($B22,$R$3:$X$9,3,FALSE) -> #N/A | U22: =VLOOKUP($B22,$R$3:$X$9,4,FALSE) -> #N/A | V22: =VLOOKUP($B22,$R$3:$X$9,5,FALSE) -> #N/A | W22: =VLOOKUP($B22,$R$3:$X$9,6,FALSE) -> #N/A | X22: =VLOOKUP($B22,$R$3:$X$9,7,FALSE) -> #N/A | Y22: =VLOOKUP($B22,$R$3:$Z$9,8,FALSE) -> #N/A | Z22: =VLOOKUP($B22,$R$3:$Z$9,9,FALSE) -> #N/A
R23: =B23 -> 0 | S23: =VLOOKUP($B23,$R$3:$X$9,2,FALSE) -> #N/A | T23: =VLOOKUP($B23,$R$3:$X$9,3,FALSE) -> #N/A | U23: =VLOOKUP($B23,$R$3:$X$9,4,FALSE) -> #N/A | V23: =VLOOKUP($B23,$R$3:$X$9,5,FALSE) -> #N/A | W23: =VLOOKUP($B23,$R$3:$X$9,6,FALSE) -> #N/A | X23: =VLOOKUP($B23,$R$3:$X$9,7,FALSE) -> #N/A | Y23: =VLOOKUP($B23,$R$3:$Z$9,8,FALSE) -> #N/A | Z23: =VLOOKUP($B23,$R$3:$Z$9,9,FALSE) -> #N/A
R24: =B24 -> 0 | S24: =VLOOKUP($B24,$R$3:$X$9,2,FALSE) -> #N/A | T24: =VLOOKUP($B24,$R$3:$X$9,3,FALSE) -> #N/A | U24: =VLOOKUP($B24,$R$3:$X$9,4,FALSE) -> #N/A | V24: =VLOOKUP($B24,$R$3:$X$9,5,FALSE) -> #N/A | W24: =VLOOKUP($B24,$R$3:$X$9,6,FALSE) -> #N/A | X24: =VLOOKUP($B24,$R$3:$X$9,7,FALSE) -> #N/A | Y24: =VLOOKUP($B24,$R$3:$Z$9,8,FALSE) -> #N/A | Z24: =VLOOKUP($B24,$R$3:$Z$9,9,FALSE) -> #N/A
R25: =B25 -> 0 | S25: =VLOOKUP($B25,$R$3:$X$9,2,FALSE) -> #N/A | T25: =VLOOKUP($B25,$R$3:$X$9,3,FALSE) -> #N/A | U25: =VLOOKUP($B25,$R$3:$X$9,4,FALSE) -> #N/A | V25: =VLOOKUP($B25,$R$3:$X$9,5,FALSE) -> #N/A | W25: =VLOOKUP($B25,$R$3:$X$9,6,FALSE) -> #N/A | X25: =VLOOKUP($B25,$R$3:$X$9,7,FALSE) -> #N/A | Y25: =VLOOKUP($B25,$R$3:$Z$9,8,FALSE) -> #N/A | Z25: =VLOOKUP($B25,$R$3:$Z$9,9,FALSE) -> #N/A
B26: BRAND | D26: BBT P.G./ O.G | I26: Brand | J26: Actual | K26: MTD No. of Brews | L26: MTD | M26: YTD | N26: Target | R26: =B26 -> BRAND | S26: =VLOOKUP($B26,$R$3:$X$9,2,FALSE) -> #N/A | T26: =VLOOKUP($B26,$R$3:$X$9,3,FALSE) -> #N/A | U26: =VLOOKUP($B26,$R$3:$X$9,4,FALSE) -> #N/A | V26: =VLOOKUP($B26,$R$3:$X$9,5,FALSE) -> #N/A | W26: =VLOOKUP($B26,$R$3:$X$9,6,FALSE) -> #N/A | X26: =VLOOKUP($B26,$R$3:$X$9,7,FALSE) -> #N/A | Y26: =VLOOKUP($B26,$R$3:$Z$9,8,FALSE) -> #N/A | Z26: =VLOOKUP($B26,$R$3:$Z$9,9,FALSE) -> #N/A
B27: =J41 -> CARIB | I27: CARIB | J27: =AVERAGE(I16:I18) -> 95.885279 | K27: =COUNTA([22]Brewhouse!$A$740:$A$748) -> 9 | L27: =AVERAGE([22]Brewhouse!$AU$740:$AU$748) -> 97.87229 | M27: =AVERAGE([22]Brewhouse!$AU$102:$AU$171,[22]Brewhouse!$AU$173:$AU$253,[22]Brewhouse!$AU$255:$AU$339,[22]Brewhouse!$AU$341:$AU$346,[22]Brewhouse!$AU$348,[22]Brewhouse!$AU$349:$AU$406,[22]Brewhouse!$AU$408:$AU$491,[22]Brewhouse!$AU$493:$AU$578,[22]Brewhouse!$AU$580:$AU$652,[22]Brewhouse!$AU$655:$AU$748) -> 97.708011 | N27: 98 | R27: =B27 -> CARIB | S27: =VLOOKUP($B27,$R$3:$X$9,2,FALSE) -> 11.6 | T27: =VLOOKUP($B27,$R$3:$X$9,3,FALSE) -> 12 | U27: =VLOOKUP($B27,$R$3:$X$9,4,FALSE) -> 0 | V27: =VLOOKUP($B27,$R$3:$X$9,5,FALSE) -> 0.11805556 | W27: =VLOOKUP($B27,$R$3:$X$9,6,FALSE) -> 0.22569444 | X27: =VLOOKUP($B27,$R$3:$X$9,7,FALSE) -> 0.26388889 | Y27: =VLOOKUP($B27,$R$3:$Z$9,8,FALSE) -> 0 | Z27: =VLOOKUP($B27,$R$3:$Z$9,9,FALSE) -> 60
I28: STAG | M28: =AVERAGE([24]Brewhouse!$AS$15:$AS$64,[24]Brewhouse!$AS$66:$AS$103,[24]Brewhouse!$AS$105:$AS$140,[24]Brewhouse!$AS$142:$AS$193,[24]Brewhouse!$AS$195:$AS$240,[24]Brewhouse!$AS$242:$AS$273,[24]Brewhouse!$AS$275:$AS$322,[24]Brewhouse!$AS$324:$AS$359) -> 98.06549 | N28: 98 | R28: =B28 -> 0 | S28: =VLOOKUP($B28,$R$3:$X$9,2,FALSE) -> #N/A | T28: =VLOOKUP($B28,$R$3:$X$9,3,FALSE) -> #N/A | U28: =VLOOKUP($B28,$R$3:$X$9,4,FALSE) -> #N/A | V28: =VLOOKUP($B28,$R$3:$X$9,5,FALSE) -> #N/A | W28: =VLOOKUP($B28,$R$3:$X$9,6,FALSE) -> #N/A | X28: =VLOOKUP($B28,$R$3:$X$9,7,FALSE) -> #N/A | Y28: =VLOOKUP($B28,$R$3:$Z$9,8,FALSE) -> #N/A | Z28: =VLOOKUP($B28,$R$3:$Z$9,9,FALSE) -> #N/A
I29: GUINNESS | M29: =AVERAGE([25]Brewhouse!$AU$4:$AU$7,[25]Brewhouse!$AU$9:$AU$22,[25]Brewhouse!$AU$24:$AU$35,[25]Brewhouse!$AU$37:$AU$45,[25]Brewhouse!$AU$47:$AU$62,[25]Brewhouse!$AU$64:$AU$79,[25]Brewhouse!$AU$81:$AU$92) -> 96.938185 | N29: 98 | R29: =B29 -> 0 | S29: =VLOOKUP($B29,$R$3:$X$9,2,FALSE) -> #N/A | T29: =VLOOKUP($B29,$R$3:$X$9,3,FALSE) -> #N/A | U29: =VLOOKUP($B29,$R$3:$X$9,4,FALSE) -> #N/A | V29: =VLOOKUP($B29,$R$3:$X$9,5,FALSE) -> #N/A | W29: =VLOOKUP($B29,$R$3:$X$9,6,FALSE) -> #N/A | X29: =VLOOKUP($B29,$R$3:$X$9,7,FALSE) -> #N/A | Y29: =VLOOKUP($B29,$R$3:$Z$9,8,FALSE) -> #N/A | Z29: =VLOOKUP($B29,$R$3:$Z$9,9,FALSE) -> #N/A
I30: VITAMALT | M30: =AVERAGE([26]Brewhouse!$AV$5:$AV$14,[26]Brewhouse!$AV$16:$AV$19,[26]Brewhouse!$AV$21:$AV$24,[26]Brewhouse!$AV$26:$AV$33,[26]Brewhouse!$AV$35:$AV$46,[26]Brewhouse!$AV$48:$AV$53,[26]Brewhouse!$AV$55:$AV$62,[26]Brewhouse!$AV$64:$AV$77) -> 98.521411 | N30: 98 | R30: =B30 -> 0 | S30: =VLOOKUP($B30,$R$3:$X$9,2,FALSE) -> #N/A | T30: =VLOOKUP($B30,$R$3:$X$9,3,FALSE) -> #N/A | U30: =VLOOKUP($B30,$R$3:$X$9,4,FALSE) -> #N/A | V30: =VLOOKUP($B30,$R$3:$X$9,5,FALSE) -> #N/A | W30: =VLOOKUP($B30,$R$3:$X$9,6,FALSE) -> #N/A | X30: =VLOOKUP($B30,$R$3:$X$9,7,FALSE) -> #N/A | Y30: =VLOOKUP($B30,$R$3:$Z$9,8,FALSE) -> #N/A | Z30: =VLOOKUP($B30,$R$3:$Z$9,9,FALSE) -> #N/A
I31: MAXIMALT | N31: 98 | R31: =B31 -> 0 | S31: =VLOOKUP($B31,$R$3:$X$9,2,FALSE) -> #N/A | T31: =VLOOKUP($B31,$R$3:$X$9,3,FALSE) -> #N/A | U31: =VLOOKUP($B31,$R$3:$X$9,4,FALSE) -> #N/A | V31: =VLOOKUP($B31,$R$3:$X$9,5,FALSE) -> #N/A | W31: =VLOOKUP($B31,$R$3:$X$9,6,FALSE) -> #N/A | X31: =VLOOKUP($B31,$R$3:$X$9,7,FALSE) -> #N/A | Y31: =VLOOKUP($B31,$R$3:$Z$9,8,FALSE) -> #N/A | Z31: =VLOOKUP($B31,$R$3:$Z$9,9,FALSE) -> #N/A
I32: MACKESON | M32: =AVERAGE([27]Brewhouse!$AT$4:$AT$11,[27]Brewhouse!$AT$13:$AT$16,[27]Brewhouse!$AT$18:$AT$21,[27]Brewhouse!$AT$26) -> 94.588058 | N32: 98
I33: STARMALT | J33: =AVERAGE(I10:I14) -> 98.730184 | K33: =COUNTA([23]Brewhouse!$A$75:$A$82) -> 8 | L33: =AVERAGE([23]Brewhouse!$AY$75:$AY$82) -> 97.738838 | M33: =AVERAGE([23]Brewhouse!$AY$6:$AY$13,[23]Brewhouse!$AY$15:$AY$20,[23]Brewhouse!$AY$22:$AY$29,[23]Brewhouse!$AY$31:$AY$34,[23]Brewhouse!$AY$36:$AY$43,[23]Brewhouse!$AY$45:$AY$50, [23]Brewhouse!$AY$56:$AY$73,[23]Brewhouse!$AY$75:$AY$82) -> 97.409216 | N33: 98
I34: HR- Pils | M34: =AVERAGE([28]Brewhouse!$AU$5:$AU$8,[28]Brewhouse!$AU$10:$AU$13,[23]Brewhouse!$AY$75:$AY$77) -> 94.749192 | N34: 98
I35: HR- IPA | M35: =AVERAGE([29]Brewhouse!$AW$26:$AW$27) -> 95.310681 | N35: 98
I36: HR- APA | M36: =AVERAGE([30]Brewhouse!$AU$13:$AU$14) -> 97.110575 | N36: 98
K37: =SUM(K27:K36) -> 17 | L37: =((L27*K27)+(L28*K28)+(L29*K29)+(L30*K30)+(L31*K31)+(K34*L34)+(L32*K32)+(L33*K33)+(L36*K36))/(K37) -> 97.809489 | M37: =AVERAGE('[31]Jan 31st'!$L$65,'[32]Feb 28th'!$L$35,'[33]Mar. 31st'!$L$35,'[34]Apr. 30th'!$L$45,'[35]May 30th'!$L$37,'[36]June 30th'!$L$57,L37) -> 97.6802 | N37: 98
J39: Daily Brewing Plan
J40: Brand | K40: Brews Achieved | L40: Average Brews per day
J41: CARIB | K41: 5 | L41: MTD | M41: YTD | N41: TARGET
...

Sheet Sept 3rd
S1: P.G. | U1: Hot Time | W1: Process Time | Y1: Cooling Time
B2: Brewing Department Daily Process Loss Report | S2: Lower | T2: Upper | U2: Lower | V2: Upper | W2: Lower | X2: Upper | Y2: Lower | Z2: Upper
R3: CARIB | S3: 11.6 | T3: 12 | U3: 0 | V3: 0.11805556 | W3: 0.22569444 | X3: 0.26388889 | Y3: 0 | Z3: 60 | AB3: HR- PISNER
B4: Date: | C4: 45904 | J4: LOT WORT COLOUR: 3.5 | M4: Filter Sheets (Target 20 days) | R4: STAG | S4: 11.6 | T4: 12 | U4: 0 | V4: 0.11805556 | W4: 0.22569444 | X4: 0.26388889 | Y4: 0 | Z4: 60
M5: Double | N5: Single | R5: GUINNESS | S5: 17 | T5: 17.5 | U5: 0 | V5: 0.10763889 | W5: 0.24652778 | X5: 0.28472222 | Y5: 0 | Z5: 60
J6: MALT LOT: Lot #44 | L6: Sheet Day | R6: MACKESON | S6: 13.3 | T6: 13.5 | U6: 0 | V6: 0.12905093 | W6: 0.27430556 | X6: 0.30208333 | Y6: 0
R7: STARMALT | S7: 17 | T7: 17.4 | U7: 0 | V7: 0.13605324 | W7: 0.27430556 | X7: 0.30902778 | Y7: 0 | Z7: 85
B8: Brand | C8: Brew no. | D8: Kett. Hls | E8: Wort | F8: Cool Time(Mins) | G8: Cast. P.G. (Lab Result) | H8: Cast P.G. (Cellar Operator)-gravity | I8: Extr. Rec (77.9%) | J8: Theor. Extr. (77.5%) | K8: Boil Off /Vol. (4-6%) | L8: Boil Time | M8: Total Hot | N8: Brewing | O8: Operator | R8: Hurricane Reef | S8: 16.6 | T8: 17 | U8: 0 | V8: 0.12905093 | W8: 0.27430556 | X8: 0.30208333 | Y8: 0
E9: Meter (Hls) | F9: Target(< 60Mins) | M9: Time | R9: VITAMALT | S9: 14.2 | T9: 14.6 | U9: 0 | V9: 0.13905093 | W9: 0.26041667 | X9: 0.29513889 | Y9: 0 | Z9: 75
B10: CARIB | C10: =[22]Brewhouse!$A749 -> CA640 | D10: =[22]Brewhouse!$AF749 -> 49.7 | E10: =[22]Brewhouse!$AI749 -> 49.7 | F10: =[22]Brewhouse!$V749 -> 57 | G10: =[22]Brewhouse!AG749 -> 11.9 | I10: =[22]Brewhouse!$AU749 -> 96.91328 | J10: =[22]Brewhouse!$AV749 -> 99.155721 | K10: =[22]Brewhouse!$Q749 -> 7.5849057 | L10: =[22]Brewhouse!$P749 -> 60 | M10: =[22]Brewhouse!$U749-[22]Brewhouse!$T749 -> 0.11805556 | N10: =[22]Brewhouse!$Z749 -> 0.24652778 | O10: =[22]Brewhouse!$AX749 -> K.Benjamin | R10: =B10 -> CARIB | S10: =VLOOKUP($B10,$R$3:$X$9,2,FALSE) -> 11.6 | T10: =VLOOKUP($B10,$R$3:$X$9,3,FALSE) -> 12 | U10: =VLOOKUP($B10,$R$3:$X$9,4,FALSE) -> 0 | V10: =VLOOKUP($B10,$R$3:$X$9,5,FALSE) -> 0.11805556 | W10: =VLOOKUP($B10,$R$3:$X$9,6,FALSE) -> 0.22569444 | X10: =VLOOKUP($B10,$R$3:$X$9,7,FALSE) -> 0.26388889 | Y10: =VLOOKUP($B10,$R$3:$Z$9,8,FALSE) -> 0 | Z10: =VLOOKUP($B10,$R$3:$Z$9,9,FALSE) -> 60
B11: CARIB | C11: =[22]Brewhouse!$A750 -> CA641 | D11: =[22]Brewhouse!$AF750 -> 50.6 | E11: =[22]Brewhouse!$AI750 -> 48.9 | F11: =[22]Brewhouse!$V750 -> 58 | G11: =[22]Brewhouse!AG750 -> 11.7 | I11: =[22]Brewhouse!$AU750 -> 92.692854 | J11: =[22]Brewhouse!$AV750 -> 94.750088 | K11: =[22]Brewhouse!$Q750 -> 6.0640301 | L11: =[22]Brewhouse!$P750 -> 60 | M11: =[22]Brewhouse!$U750-[22]Brewhouse!$T750 -> 0.11388889 | N11: =[22]Brewhouse!$Z750 -> 0.25 | O11: =[22]Brewhouse!$AX750 -> R. Regis | R11: =B11 -> CARIB | S11: =VLOOKUP($B11,$R$3:$X$9,2,FALSE) -> 11.6 | T11: =VLOOKUP($B11,$R$3:$X$9,3,FALSE) -> 12 | U11: =VLOOKUP($B11,$R$3:$X$9,4,FALSE) -> 0 | V11: =VLOOKUP($B11,$R$3:$X$9,5,FALSE) -> 0.11805556 | W11: =VLOOKUP($B11,$R$3:$X$9,6,FALSE) -> 0.22569444 | X11: =VLOOKUP($B11,$R$3:$X$9,7,FALSE) -> 0.26388889 | Y11: =VLOOKUP($B11,$R$3:$Z$9,8,FALSE) -> 0 | Z11: =VLOOKUP($B11,$R$3:$Z$9,9,FALSE) -> 60
B12: CARIB | C12: =[22]Brewhouse!$A751 -> CA642 | D12: =[22]Brewhouse!$AF751 -> 53.5 | E12: =[22]Brewhouse!$AI751 -> 52.7 | F12: =[22]Brewhouse!$V751 -> 65 | G12: =[22]Brewhouse!AG751 -> 11.6 | I12: =[22]Brewhouse!$AU751 -> 98.754509 | J12: =[22]Brewhouse!$AV751 -> 100.94675 | K12: =[22]Brewhouse!$Q751 -> 2.2975518 | L12: =[22]Brewhouse!$P751 -> 60 | M12: =[22]Brewhouse!$U751-[22]Brewhouse!$T751 -> 0.1125 | N12: =[22]Brewhouse!$Z751 -> 0.24375 | O12: =[22]Brewhouse!$AX751 -> R. Regis | R12: =B12 -> CARIB | S12: =VLOOKUP($B12,$R$3:$X$9,2,FALSE) -> 11.6 | T12: =VLOOKUP($B12,$R$3:$X$9,3,FALSE) -> 12 | U12: =VLOOKUP($B12,$R$3:$X$9,4,FALSE) -> 0 | V12: =VLOOKUP($B12,$R$3:$X$9,5,FALSE) -> 0.11805556 | W12: =VLOOKUP($B12,$R$3:$X$9,6,FALSE) -> 0.22569444 | X12: =VLOOKUP($B12,$R$3:$X$9,7,FALSE) -> 0.26388889 | Y12: =VLOOKUP($B12,$R$3:$Z$9,8,FALSE) -> 0 | Z12: =VLOOKUP($B12,$R$3:$Z$9,9,FALSE) -> 60
B13: CARIB | C13: =[22]Brewhouse!$A752 -> CA643 | D13: =[22]Brewhouse!$AF752 -> 52.4 | E13: =[22]Brewhouse!$AI752 -> 50.4 | F13: =[22]Brewhouse!$V752 -> 64 | G13: =[22]Brewhouse!AG752 -> 11.9 | I13: =[22]Brewhouse!$AU752 -> 96.897137 | J13: =[22]Brewhouse!$AV752 -> 99.048382 | K13: =[22]Brewhouse!$Q752 -> 2.490566 | L13: =[22]Brewhouse!$P752 -> 60 | M13: =[22]Brewhouse!$U752-[22]Brewhouse!$T752 -> 0.11180556 | N13: =[22]Brewhouse!$Z752 -> 0.25625 | O13: =[22]Brewhouse!$AX752 -> R. Regis | R13: =B13 -> CARIB | S13: =VLOOKUP($B13,$R$3:$X$9,2,FALSE) -> 11.6 | T13: =VLOOKUP($B13,$R$3:$X$9,3,FALSE) -> 12 | U13: =VLOOKUP($B13,$R$3:$X$9,4,FALSE) -> 0 | V13: =VLOOKUP($B13,$R$3:$X$9,5,FALSE) -> 0.11805556 | W13: =VLOOKUP($B13,$R$3:$X$9,6,FALSE) -> 0.22569444 | X13: =VLOOKUP($B13,$R$3:$X$9,7,FALSE) -> 0.26388889 | Y13: =VLOOKUP($B13,$R$3:$Z$9,8,FALSE) -> 0 | Z13: =VLOOKUP($B13,$R$3:$Z$9,9,FALSE) -> 60
B14: CARIB | C14: =[22]Brewhouse!$A753 -> CA644 | D14: =[22]Brewhouse!$AF753 -> 53.3 | E14: =[22]Brewhouse!$AI753 -> 51.9 | F14: =[22]Brewhouse!$V753 -> 62 | G14: =[22]Brewhouse!AG753 -> 11.7 | I14: =[22]Brewhouse!$AU753 -> 98.379533 | J14: =[22]Brewhouse!$AV753 -> 100.56298 | K14: =[22]Brewhouse!$Q753 -> 1.5471698 | L14: =[22]Brewhouse!$P753 -> 57 | M14: =[22]Brewhouse!$U753-[22]Brewhouse!$T753 -> 0.10902778 | N14: =[22]Brewhouse!$Z753 -> 0.26041667 | O14: =[22]Brewhouse!$AX753 -> R. Regis | R14: =B14 -> CARIB | S14: =VLOOKUP($B14,$R$3:$X$9,2,FALSE) -> 11.6 | T14: =VLOOKUP($B14,$R$3:$X$9,3,FALSE) -> 12 | U14: =VLOOKUP($B14,$R$3:$X$9,4,FALSE) -> 0 | V14: =VLOOKUP($B14,$R$3:$X$9,5,FALSE) -> 0.11805556 | W14: =VLOOKUP($B14,$R$3:$X$9,6,FALSE) -> 0.22569444 | X14: =VLOOKUP($B14,$R$3:$X$9,7,FALSE) -> 0.26388889 | Y14: =VLOOKUP($B14,$R$3:$Z$9,8,FALSE) -> 0 | Z14: =VLOOKUP($B14,$R$3:$Z$9,9,FALSE) -> 60
B15: CARIB | C15: =[22]Brewhouse!$A754 -> CA645 | D15: =[22]Brewhouse!$AF754 -> 53 | E15: =[22]Brewhouse!$AI754 -> 51.1 | F15: =[22]Brewhouse!$V754 -> 63 | G15: =[22]Brewhouse!AG754 -> 11.6 | I15: =[22]Brewhouse!$AU754 -> 96.881645 | J15: =[22]Brewhouse!$AV754 -> 99.123478 | K15: =[22]Brewhouse!$Q754 -> 3.1851852 | L15: =[22]Brewhouse!$P754 -> 57 | M15: =[22]Brewhouse!$U754-[22]Brewhouse!$T754 -> 0.10069444 | N15: =[22]Brewhouse!$Z754 -> 0.24791667 | O15: =[22]Brewhouse!$AX754 -> R.Sookram | R15: =B15 -> CARIB | S15: =VLOOKUP($B15,$R$3:$X$9,2,FALSE) -> 11.6 | T15: =VLOOKUP($B15,$R$3:$X$9,3,FALSE) -> 12 | U15: =VLOOKUP($B15,$R$3:$X$9,4,FALSE) -> 0 | V15: =VLOOKUP($B15,$R$3:$X$9,5,FALSE) -> 0.11805556 | W15: =VLOOKUP($B15,$R$3:$X$9,6,FALSE) -> 0.22569444 | X15: =VLOOKUP($B15,$R$3:$X$9,7,FALSE) -> 0.26388889 | Y15: =VLOOKUP($B15,$R$3:$Z$9,8,FALSE) -> 0 | Z15: =VLOOKUP($B15,$R$3:$Z$9,9,FALSE) -> 60
B16: CARIB | C16: =[22]Brewhouse!$A755 -> CA646 | D16: =[22]Brewhouse!$AF755 -> 53.3 | E16: =[22]Brewhouse!$AI755 -> 51.6 | F16: =[22]Brewhouse!$V755 -> 71 | G16: =[22]Brewhouse!AG755 -> 11.6 | I16: =[22]Brewhouse!$AU755 -> 97.829607 | J16: =[22]Brewhouse!$AV755 -> 100.09338 | K16: =[22]Brewhouse!$Q755 -> 2.6296296 | L16: =[22]Brewhouse!$P755 -> 58 | M16: =[22]Brewhouse!$U755-[22]Brewhouse!$T755 -> 0.10833333 | N16: =[22]Brewhouse!$Z755 -> 0.25833333 | O16: =[22]Brewhouse!$AX755 -> R.Sookram | R16: =B16 -> CARIB | S16: =VLOOKUP($B16,$R$3:$X$9,2,FALSE) -> 11.6 | T16: =VLOOKUP($B16,$R$3:$X$9,3,FALSE) -> 12 | U16: =VLOOKUP($B16,$R$3:$X$9,4,FALSE) -> 0 | V16: =VLOOKUP($B16,$R$3:$X$9,5,FALSE) -> 0.11805556 | W16: =VLOOKUP($B16,$R$3:$X$9,6,FALSE) -> 0.22569444 | X16: =VLOOKUP($B16,$R$3:$X$9,7,FALSE) -> 0.26388889 | Y16: =VLOOKUP($B16,$R$3:$Z$9,8,FALSE) -> 0 | Z16: =VLOOKUP($B16,$R$3:$Z$9,9,FALSE) -> 60
B17: CARIB | C17: =[22]Brewhouse!$A756 -> CA647 | D17: =[22]Brewhouse!$AF756 -> 53.8 | E17: =[22]Brewhouse!$AI756 -> 52 | F17: =[22]Brewhouse!$V756 -> 57 | G17: =[22]Brewhouse!AG756 -> 11.9 | I17: =[22]Brewhouse!$AU756 -> 101.3982 | J17: =[22]Brewhouse!$AV756 -> 103.74442 | K17: =[22]Brewhouse!$Q756 -> 2.4444444 | L17: =[22]Brewhouse!$P756 -> 58 | M17: =[22]Brewhouse!$U756-[22]Brewhouse!$T756 -> 0.10416667 | N17: =[22]Brewhouse!$Z756 -> 0.25069444 | O17: =[22]Brewhouse!$AX756 -> R.Sookram | R17: =B17 -> CARIB | S17: =VLOOKUP($B17,$R$3:$X$9,2,FALSE) -> 11.6 | T17: =VLOOKUP($B17,$R$3:$X$9,3,FALSE) -> 12 | U17: =VLOOKUP($B17,$R$3:$X$9,4,FALSE) -> 0 | V17: =VLOOKUP($B17,$R$3:$X$9,5,FALSE) -> 0.11805556 | W17: =VLOOKUP($B17,$R$3:$X$9,6,FALSE) -> 0.22569444 | X17: =VLOOKUP($B17,$R$3:$X$9,7,FALSE) -> 0.26388889 | Y17: =VLOOKUP($B17,$R$3:$Z$9,8,FALSE) -> 0 | Z17: =VLOOKUP($B17,$R$3:$Z$9,9,FALSE) -> 60
B18: CARIB | C18: =[22]Brewhouse!$A757 -> CA648 | D18: =[22]Brewhouse!$AF757 -> 52 | E18: =[22]Brewhouse!$AI757 -> 51 | F18: =[22]Brewhouse!$V757 -> 58 | G18: =[22]Brewhouse!AG757 -> 11.8 | I18: =[22]Brewhouse!$AU757 -> 98.447189 | J18: =[22]Brewhouse!$AV757 -> 100.72525 | K18: =[22]Brewhouse!$Q757 -> 3.245283 | L18: =[22]Brewhouse!$P757 -> 63 | M18: =[22]Brewhouse!$U757-[22]Brewhouse!$T757 -> 0.11944444 | N18: =[22]Brewhouse!$Z757 -> 0.2625 | O18: =[22]Brewhouse!$AX757 -> K.Benjamin | R18: =B18 -> CARIB | S18: =VLOOKUP($B18,$R$3:$X$9,2,FALSE) -> 11.6 | T18: =VLOOKUP($B18,$R$3:$X$9,3,FALSE) -> 12 | U18: =VLOOKUP($B18,$R$3:$X$9,4,FALSE) -> 0 | V18: =VLOOKUP($B18,$R$3:$X$9,5,FALSE) -> 0.11805556 | W18: =VLOOKUP($B18,$R$3:$X$9,6,FALSE) -> 0.22569444 | X18: =VLOOKUP($B18,$R$3:$X$9,7,FALSE) -> 0.26388889 | Y18: =VLOOKUP($B18,$R$3:$Z$9,8,FALSE) -> 0 | Z18: =VLOOKUP($B18,$R$3:$Z$9,9,FALSE) -> 60
B19: CARIB | C19: =[22]Brewhouse!$A758 -> CA649 | D19: =[22]Brewhouse!$AF758 -> 52.7 | E19: =[22]Brewhouse!$AI758 -> 49.8 | F19: =[22]Brewhouse!$V758 -> 55 | G19: =[22]Brewhouse!AG758 -> 11.7 | I19: =[22]Brewhouse!$AU758 -> 94.631693 | J19: =[22]Brewhouse!$AV758 -> 96.731498 | K19: =[22]Brewhouse!$Q758 -> 1.9245283 | L19: =[22]Brewhouse!$P758 -> 59 | M19: =[22]Brewhouse!$U758-[22]Brewhouse!$T758 -> 0.10833333 | N19: =[22]Brewhouse!$Z758 -> 0.25 | O19: =[22]Brewhouse!$AX758 -> K.Benjamin | R19: =B19 -> CARIB | S19: =VLOOKUP($B19,$R$3:$X$9,2,FALSE) -> 11.6 | T19: =VLOOKUP($B19,$R$3:$X$9,3,FALSE) -> 12 | U19: =VLOOKUP($B19,$R$3:$X$9,4,FALSE) -> 0 | V19: =VLOOKUP($B19,$R$3:$X$9,5,FALSE) -> 0.11805556 | W19: =VLOOKUP($B19,$R$3:$X$9,6,FALSE) -> 0.22569444 | X19: =VLOOKUP($B19,$R$3:$X$9,7,FALSE) -> 0.26388889 | Y19: =VLOOKUP($B19,$R$3:$Z$9,8,FALSE) -> 0 | Z19: =VLOOKUP($B19,$R$3:$Z$9,9,FALSE) -> 60
R20: =B20 -> 0 | S20: =VLOOKUP($B20,$R$3:$X$9,2,FALSE) -> #N/A | T20: =VLOOKUP($B20,$R$3:$X$9,3,FALSE) -> #N/A | U20: =VLOOKUP($B20,$R$3:$X$9,4,FALSE) -> #N/A | V20: =VLOOKUP($B20,$R$3:$X$9,5,FALSE) -> #N/A | W20: =VLOOKUP($B20,$R$3:$X$9,6,FALSE) -> #N/A | X20: =VLOOKUP($B20,$R$3:$X$9,7,FALSE) -> #N/A | Y20: =VLOOKUP($B20,$R$3:$Z$9,8,FALSE) -> #N/A | Z20: =VLOOKUP($B20,$R$3:$Z$9,9,FALSE) -> #N/A
R21: =B21 -> 0 | S21: =VLOOKUP($B21,$R$3:$X$9,2,FALSE) -> #N/A | T21: =VLOOKUP($B21,$R$3:$X$9,3,FALSE) -> #N/A | U21: =VLOOKUP($B21,$R$3:$X$9,4,FALSE) -> #N/A | V21: =VLOOKUP($B21,$R$3:$X$9,5,FALSE) -> #N/A | W21: =VLOOKUP($B21,$R$3:$X$9,6,FALSE) -> #N/A | X21: =VLOOKUP($B21,$R$3:$X$9,7,FALSE) -> #N/A | Y21: =VLOOKUP($B21,$R$3:$Z$9,8,FALSE) -> #N/A | Z21: =VLOOKUP($B21,$R$3:$Z$9,9,FALSE) -> #N/A
R22: =B22 -> 0 | S22: =VLOOKUP($B22,$R$3:$X$9,2,FALSE) -> #N/A | T22: =VLOOKUP($B22,$R$3:$X$9,3,FALSE) -> #N/A | U22: =VLOOKUP($B22,$R$3:$X$9,4,FALSE) -> #N/A | V22: =VLOOKUP($B22,$R$3:$X$9,5,FALSE) -> #N/A | W22: =VLOOKUP($B22,$R$3:$X$9,6,FALSE) -> #N/A | X22: =VLOOKUP($B22,$R$3:$X$9,7,FALSE) -> #N/A | Y22: =VLOOKUP($B22,$R$3:$Z$9,8,FALSE) -> #N/A | Z22: =VLOOKUP($B22,$R$3:$Z$9,9,FALSE) -> #N/A
R23: =B23 -> 0 | S23: =VLOOKUP($B23,$R$3:$X$9,2,FALSE) -> #N/A | T23: =VLOOKUP($B23,$R$3:$X$9,3,FALSE) -> #N/A | U23: =VLOOKUP($B23,$R$3:$X$9,4,FALSE) -> #N/A | V23: =VLOOKUP($B23,$R$3:$X$9,5,FALSE) -> #N/A | W23: =VLOOKUP($B23,$R$3:$X$9,6,FALSE) -> #N/A | X23: =VLOOKUP($B23,$R$3:$X$9,7,FALSE) -> #N/A | Y23: =VLOOKUP($B23,$R$3:$Z$9,8,FALSE) -> #N/A | Z23: =VLOOKUP($B23,$R$3:$Z$9,9,FALSE) -> #N/A
R24: =B24 -> 0 | S24: =VLOOKUP($B24,$R$3:$X$9,2,FALSE) -> #N/A | T24: =VLOOKUP($B24,$R$3:$X$9,3,FALSE) -> #N/A | U24: =VLOOKUP($B24,$R$3:$X$9,4,FALSE) -> #N/A | V24: =VLOOKUP($B24,$R$3:$X$9,5,FALSE) -> #N/A | W24: =VLOOKUP($B24,$R$3:$X$9,6,FALSE) -> #N/A | X24: =VLOOKUP($B24,$R$3:$X$9,7,FALSE) -> #N/A | Y24: =VLOOKUP($B24,$R$3:$Z$9,8,FALSE) -> #N/A | Z24: =VLOOKUP($B24,$R$3:$Z$9,9,FALSE) -> #N/A
R25: =B25 -> 0 | S25: =VLOOKUP($B25,$R$3:$X$9,2,FALSE) -> #N/A | T25: =VLOOKUP($B25,$R$3:$X$9,3,FALSE) -> #N/A | U25: =VLOOKUP($B25,$R$3:$X$9,4,FALSE) -> #N/A | V25: =VLOOKUP($B25,$R$3:$X$9,5,FALSE) -> #N/A | W25: =VLOOKUP($B25,$R$3:$X$9,6,FALSE) -> #N/A | X25: =VLOOKUP($B25,$R$3:$X$9,7,FALSE) -> #N/A | Y25: =VLOOKUP($B25,$R$3:$Z$9,8,FALSE) -> #N/A | Z25: =VLOOKUP($B25,$R$3:$Z$9,9,FALSE) -> #N/A
R26: =B26 -> 0 | S26: =VLOOKUP($B26,$R$3:$X$9,2,FALSE) -> #N/A | T26: =VLOOKUP($B26,$R$3:$X$9,3,FALSE) -> #N/A | U26: =VLOOKUP($B26,$R$3:$X$9,4,FALSE) -> #N/A | V26: =VLOOKUP($B26,$R$3:$X$9,5,FALSE) -> #N/A | W26: =VLOOKUP($B26,$R$3:$X$9,6,FALSE) -> #N/A | X26: =VLOOKUP($B26,$R$3:$X$9,7,FALSE) -> #N/A | Y26: =VLOOKUP($B26,$R$3:$Z$9,8,FALSE) -> #N/A | Z26: =VLOOKUP($B26,$R$3:$Z$9,9,FALSE) -> #N/A
B27: BRAND | D27: BBT P.G./ O.G | I27: Brand | J27: Actual | K27: MTD No. of Brews | L27: MTD | M27: YTD | N27: Target | R27: =B27 -> BRAND | S27: =VLOOKUP($B27,$R$3:$X$9,2,FALSE) -> #N/A | T27: =VLOOKUP($B27,$R$3:$X$9,3,FALSE) -> #N/A | U27: =VLOOKUP($B27,$R$3:$X$9,4,FALSE) -> #N/A | V27: =VLOOKUP($B27,$R$3:$X$9,5,FALSE) -> #N/A | W27: =VLOOKUP($B27,$R$3:$X$9,6,FALSE) -> #N/A | X27: =VLOOKUP($B27,$R$3:$X$9,7,FALSE) -> #N/A | Y27: =VLOOKUP($B27,$R$3:$Z$9,8,FALSE) -> #N/A | Z27: =VLOOKUP($B27,$R$3:$Z$9,9,FALSE) -> #N/A
