Workbook
Name ProductList: [1]November15!$R$3:$R$9
Name ProductList: [2]November15!$R$3:$R$9

Sheet Dec 18th
T1: P.G. | V1: Hot Time | X1: Process Time | Z1: Cooling Time
B2: Brewing Department Daily Process Loss Report | T2: Lower | U2: Upper | V2: Lower | W2: Upper | X2: Lower | Y2: Upper | Z2: Lower | AA2: Upper
S3: CARIB | T3: 11.6 | U3: 12 | V3: 0 | W3: 0.11805556 | X3: 0.17361111 | Y3: 0.21180556 | Z3: 0 | AA3: 60 | AC3: HR- PISNER
B4: Date: | C4: 45278 | J4: LOT WORT COLOUR: 3.4 | M4: Filter Sheets (Target 20 days) | S4: STAG | T4: 11.6 | U4: 12 | V4: 0 | W4: 0.11805556 | X4: 0.17361111 | Y4: 0.21180556 | Z4: 0 | AA4: 60
M5: Double | N5: Single | S5: GUINNESS | T5: 17 | U5: 17.5 | V5: 0 | W5: 0.10763889 | X5: 0.19444444 | Y5: 0.23263889 | Z5: 0 | AA5: 60
J6: MALT LOT: Lot 8 | L6: Sheet Day | S6: MACKESON | T6: 13.3 | U6: 13.5 | V6: 0 | W6: 0.12905093 | X6: 0.22222222 | Y6: 0.25347222 | Z6: 0
S7: STARMALT | T7: 17.1 | U7: 17.5 | V7: 0 | W7: 0.13605324 | X7: 0.20833333 | Y7: 0.24305556 | Z7: 0 | AA7: 60
B8: Brand | C8: Brew no. | D8: Kett. Hls | E8: Wort | F8: Cool Time(Mins) | G8: Cast. P.G. (Lab Result) | H8: Cast P.G. (Cellar Operator)-gravity | I8: Extr. Rec (79.1%) | J8: Theor. Extr. (77.5%) | K8: Boil Off /Vol. (4-6%) | L8: Boil Time | M8: Total Hot | N8: Brewing | P8: Comments | Q8: Actual Pilsen Malt | S8: Hurricane Reef | T8: 16.6 | U8: 17 | V8: 0 | W8: 0.12905093 | X8: 0.22222222 | Y8: 0.25347222 | Z8: 0
E9: Meter (Hls) | F9: Target(< 60Mins) | M9: Time | S9: VITAMALT | T9: 14.4 | U9: 14.6 | V9: 0 | W9: 0.13905093 | X9: 0.19097222 | Y9: 0.22569444 | Z9: 0 | AA9: 75
S10: =B10 -> 0 | T10: =VLOOKUP($B10,$S$3:$Y$9,2,FALSE) -> #N/A | U10: =VLOOKUP($B10,$S$3:$Y$9,3,FALSE) -> #N/A | V10: =VLOOKUP($B10,$S$3:$Y$9,4,FALSE) -> #N/A | W10: =VLOOKUP($B10,$S$3:$Y$9,5,FALSE) -> #N/A | X10: =VLOOKUP($B10,$S$3:$Y$9,6,FALSE) -> #N/A | Y10: =VLOOKUP($B10,$S$3:$Y$9,7,FALSE) -> #N/A | Z10: =VLOOKUP($B10,$S$3:$AA$9,8,FALSE) -> #N/A | AA10: =VLOOKUP($B10,$S$3:$AA$9,9,FALSE) -> #N/A
S11: =B11 -> 0 | T11: =VLOOKUP($B11,$S$3:$Y$9,2,FALSE) -> #N/A | U11: =VLOOKUP($B11,$S$3:$Y$9,3,FALSE) -> #N/A | V11: =VLOOKUP($B11,$S$3:$Y$9,4,FALSE) -> #N/A | W11: =VLOOKUP($B11,$S$3:$Y$9,5,FALSE) -> #N/A | X11: =VLOOKUP($B11,$S$3:$Y$9,6,FALSE) -> #N/A | Y11: =VLOOKUP($B11,$S$3:$Y$9,7,FALSE) -> #N/A | Z11: =VLOOKUP($B11,$S$3:$AA$9,8,FALSE) -> #N/A | AA11: =VLOOKUP($B11,$S$3:$AA$9,9,FALSE) -> #N/A
S12: =B12 -> 0 | T12: =VLOOKUP($B12,$S$3:$Y$9,2,FALSE) -> #N/A | U12: =VLOOKUP($B12,$S$3:$Y$9,3,FALSE) -> #N/A | V12: =VLOOKUP($B12,$S$3:$Y$9,4,FALSE) -> #N/A | W12: =VLOOKUP($B12,$S$3:$Y$9,5,FALSE) -> #N/A | X12: =VLOOKUP($B12,$S$3:$Y$9,6,FALSE) -> #N/A | Y12: =VLOOKUP($B12,$S$3:$Y$9,7,FALSE) -> #N/A | Z12: =VLOOKUP($B12,$S$3:$AA$9,8,FALSE) -> #N/A | AA12: =VLOOKUP($B12,$S$3:$AA$9,9,FALSE) -> #N/A
S13: =B13 -> 0 | T13: =VLOOKUP($B13,$S$3:$Y$9,2,FALSE) -> #N/A | U13: =VLOOKUP($B13,$S$3:$Y$9,3,FALSE) -> #N/A | V13: =VLOOKUP($B13,$S$3:$Y$9,4,FALSE) -> #N/A | W13: =VLOOKUP($B13,$S$3:$Y$9,5,FALSE) -> #N/A | X13: =VLOOKUP($B13,$S$3:$Y$9,6,FALSE) -> #N/A | Y13: =VLOOKUP($B13,$S$3:$Y$9,7,FALSE) -> #N/A | Z13: =VLOOKUP($B13,$S$3:$AA$9,8,FALSE) -> #N/A | AA13: =VLOOKUP($B13,$S$3:$AA$9,9,FALSE) -> #N/A
S14: =B14 -> 0 | T14: =VLOOKUP($B14,$S$3:$Y$9,2,FALSE) -> #N/A | U14: =VLOOKUP($B14,$S$3:$Y$9,3,FALSE) -> #N/A | V14: =VLOOKUP($B14,$S$3:$Y$9,4,FALSE) -> #N/A | W14: =VLOOKUP($B14,$S$3:$Y$9,5,FALSE) -> #N/A | X14: =VLOOKUP($B14,$S$3:$Y$9,6,FALSE) -> #N/A | Y14: =VLOOKUP($B14,$S$3:$Y$9,7,FALSE) -> #N/A | Z14: =VLOOKUP($B14,$S$3:$AA$9,8,FALSE) -> #N/A | AA14: =VLOOKUP($B14,$S$3:$AA$9,9,FALSE) -> #N/A
S15: =B15 -> 0 | T15: =VLOOKUP($B15,$S$3:$Y$9,2,FALSE) -> #N/A | U15: =VLOOKUP($B15,$S$3:$Y$9,3,FALSE) -> #N/A | V15: =VLOOKUP($B15,$S$3:$Y$9,4,FALSE) -> #N/A | W15: =VLOOKUP($B15,$S$3:$Y$9,5,FALSE) -> #N/A | X15: =VLOOKUP($B15,$S$3:$Y$9,6,FALSE) -> #N/A | Y15: =VLOOKUP($B15,$S$3:$Y$9,7,FALSE) -> #N/A | Z15: =VLOOKUP($B15,$S$3:$AA$9,8,FALSE) -> #N/A | AA15: =VLOOKUP($B15,$S$3:$AA$9,9,FALSE) -> #N/A
S16: =B16 -> 0 | T16: =VLOOKUP($B16,$S$3:$Y$9,2,FALSE) -> #N/A | U16: =VLOOKUP($B16,$S$3:$Y$9,3,FALSE) -> #N/A | V16: =VLOOKUP($B16,$S$3:$Y$9,4,FALSE) -> #N/A | W16: =VLOOKUP($B16,$S$3:$Y$9,5,FALSE) -> #N/A | X16: =VLOOKUP($B16,$S$3:$Y$9,6,FALSE) -> #N/A | Y16: =VLOOKUP($B16,$S$3:$Y$9,7,FALSE) -> #N/A | Z16: =VLOOKUP($B16,$S$3:$AA$9,8,FALSE) -> #N/A | AA16: =VLOOKUP($B16,$S$3:$AA$9,9,FALSE) -> #N/A
S17: =B17 -> 0 | T17: =VLOOKUP($B17,$S$3:$Y$9,2,FALSE) -> #N/A | U17: =VLOOKUP($B17,$S$3:$Y$9,3,FALSE) -> #N/A | V17: =VLOOKUP($B17,$S$3:$Y$9,4,FALSE) -> #N/A | W17: =VLOOKUP($B17,$S$3:$Y$9,5,FALSE) -> #N/A | X17: =VLOOKUP($B17,$S$3:$Y$9,6,FALSE) -> #N/A | Y17: =VLOOKUP($B17,$S$3:$Y$9,7,FALSE) -> #N/A | Z17: =VLOOKUP($B17,$S$3:$AA$9,8,FALSE) -> #N/A | AA17: =VLOOKUP($B17,$S$3:$AA$9,9,FALSE) -> #N/A
S18: =B18 -> 0 | T18: =VLOOKUP($B18,$S$3:$Y$9,2,FALSE) -> #N/A | U18: =VLOOKUP($B18,$S$3:$Y$9,3,FALSE) -> #N/A | V18: =VLOOKUP($B18,$S$3:$Y$9,4,FALSE) -> #N/A | W18: =VLOOKUP($B18,$S$3:$Y$9,5,FALSE) -> #N/A | X18: =VLOOKUP($B18,$S$3:$Y$9,6,FALSE) -> #N/A | Y18: =VLOOKUP($B18,$S$3:$Y$9,7,FALSE) -> #N/A | Z18: =VLOOKUP($B18,$S$3:$AA$9,8,FALSE) -> #N/A | AA18: =VLOOKUP($B18,$S$3:$AA$9,9,FALSE) -> #N/A
S19: =B19 -> 0 | T19: =VLOOKUP($B19,$S$3:$Y$9,2,FALSE) -> #N/A | U19: =VLOOKUP($B19,$S$3:$Y$9,3,FALSE) -> #N/A | V19: =VLOOKUP($B19,$S$3:$Y$9,4,FALSE) -> #N/A | W19: =VLOOKUP($B19,$S$3:$Y$9,5,FALSE) -> #N/A | X19: =VLOOKUP($B19,$S$3:$Y$9,6,FALSE) -> #N/A | Y19: =VLOOKUP($B19,$S$3:$Y$9,7,FALSE) -> #N/A | Z19: =VLOOKUP($B19,$S$3:$AA$9,8,FALSE) -> #N/A | AA19: =VLOOKUP($B19,$S$3:$AA$9,9,FALSE) -> #N/A
S20: =B20 -> 0 | T20: =VLOOKUP($B20,$S$3:$Y$9,2,FALSE) -> #N/A | U20: =VLOOKUP($B20,$S$3:$Y$9,3,FALSE) -> #N/A | V20: =VLOOKUP($B20,$S$3:$Y$9,4,FALSE) -> #N/A | W20: =VLOOKUP($B20,$S$3:$Y$9,5,FALSE) -> #N/A | X20: =VLOOKUP($B20,$S$3:$Y$9,6,FALSE) -> #N/A | Y20: =VLOOKUP($B20,$S$3:$Y$9,7,FALSE) -> #N/A | Z20: =VLOOKUP($B20,$S$3:$AA$9,8,FALSE) -> #N/A | AA20: =VLOOKUP($B20,$S$3:$AA$9,9,FALSE) -> #N/A
S21: =B21 -> 0 | T21: =VLOOKUP($B21,$S$3:$Y$9,2,FALSE) -> #N/A | U21: =VLOOKUP($B21,$S$3:$Y$9,3,FALSE) -> #N/A | V21: =VLOOKUP($B21,$S$3:$Y$9,4,FALSE) -> #N/A | W21: =VLOOKUP($B21,$S$3:$Y$9,5,FALSE) -> #N/A | X21: =VLOOKUP($B21,$S$3:$Y$9,6,FALSE) -> #N/A | Y21: =VLOOKUP($B21,$S$3:$Y$9,7,FALSE) -> #N/A | Z21: =VLOOKUP($B21,$S$3:$AA$9,8,FALSE) -> #N/A | AA21: =VLOOKUP($B21,$S$3:$AA$9,9,FALSE) -> #N/A
... S47: =B47 -> 0 | T47: =VLOOKUP($B47,$S$3:$Y$9,2,FALSE) -> #N/A | U47: =VLOOKUP($B47,$S$3:$Y$9,3,FALSE) -> #N/A | V47: =VLOOKUP($B47,$S$3:$Y$9,4,FALSE) -> #N/A | W47: =VLOOKUP($B47,$S$3:$Y$9,5,FALSE) -> #N/A | X47: =VLOOKUP($B47,$S$3:$Y$9,6,FALSE) -> #N/A | Y47: =VLOOKUP($B47,$S$3:$Y$9,7,FALSE) -> #N/A | Z47: =VLOOKUP($B47,$S$3:$AA$9,8,FALSE) -> #N/A | AA47: =VLOOKUP($B47,$S$3:$AA$9,9,FALSE) -> #N/A
I48: EXTRACT RECOVERY
B49: BRAND | D49: BBT P.G./ O.G | I49: Brand | J49: Actual | K49: MTD No. of Brews | L49: MTD | M49: YTD | N49: Target
B50: STAG | C50: 11.8 | D50: 11.73 | I50: CARIB | K50: =COUNTA([20]Brewhouse!$A$1596:$A$1619) -> 24 | L50: =AVERAGE([20]Brewhouse!$AU$1529,[20]Brewhouse!$AU$1531:$AU$1594,[20]Brewhouse!$AU$1596:$AU$1619) -> 98.205761 | M50: =AVERAGE([20]Brewhouse!$AU$849:$AU$924,[20]Brewhouse!$AU$926:$AU$971,[20]Brewhouse!$AU$973:$AU$1066,[20]Brewhouse!$AU$1068:$AU$1111,[20]Brewhouse!$AU$1113:$AU$1132,[20]Brewhouse!$AU$1134:$AU$1167,[20]Brewhouse!$AU$1169:$AU$1230,[20]Brewhouse!$AU$1232:$AU$1299,[20]Brewhouse!$AU$1301:$AU$1363,[20]Brewhouse!$AU$1365:$AU$1444,[20]Brewhouse!$AU$1446:$AU$1527,[20]Brewhouse!$AU$1529,[20]Brewhouse!$AU$1531:$AU$1594,[20]Brewhouse!$AU$1596:$AU$1619) -> 98.381806 | N50: 98
C51: 11.9 | I51: STAG | K51: =COUNTA([21]Brewhouse!$A$976:$A$1007) -> 32 | L51: =AVERAGE([21]Brewhouse!$AS$976:$AS$979,[21]Brewhouse!$AS$981:$AS$1007) -> 98.538567 | M51: =AVERAGE([21]Brewhouse!$AS$577:$AS$618,[21]Brewhouse!$AS$620:$AS$651,[21]Brewhouse!$AS$653:$AS$696,[21]Brewhouse!$AS$698:$AS$708,[21]Brewhouse!$AS$710:$AS$733,[21]Brewhouse!$AS$735:$AS$777,[21]Brewhouse!$AS$779:$AS$822,[21]Brewhouse!$AS$824:$AS$863,[21]Brewhouse!$AS$865:$AS$974,[21]Brewhouse!$AS$976:$AS$979,[21]Brewhouse!$AS$981:$AS$1007) -> 98.489671 | N51: 98
I52: GUINNESS | K52: =COUNTA([22]Brewhouse!$A$282:$A$289) -> 8 | L52: =AVERAGE([22]Brewhouse!$AU$269:$AU$279,[22]Brewhouse!$AU$282:$AU$289) -> 96.186177 | M52: =AVERAGE([22]Brewhouse!$AU$161:$AU$176,[22]Brewhouse!$AU$178:$AU$195,[22]Brewhouse!$AU$197:$AU$208,[22]Brewhouse!$AU$210:$AU$221,[22]Brewhouse!$AU$223:$AU$232,[22]Brewhouse!$AU$234:$AU$279,[22]Brewhouse!$AU$282:$AU$289) -> 96.64916 | N52: 98
I53: VITAMALT | K53: =COUNTA([23]Brewhouse!$A$158:$A$163) -> 6 | L53: =AVERAGE([23]Brewhouse!$AU$158:$AU$163) -> 94.60305 | M53: =AVERAGE([23]Brewhouse!$AU$91:$AU$101,[23]Brewhouse!$AU$103:$AU$112,[23]Brewhouse!$AU$114:$AU$123,[23]Brewhouse!$AU$125:$AU$134,[23]Brewhouse!$AU$136:$AU$145,[23]Brewhouse!$AU$147:$AU$156,[23]Brewhouse!$AU$158:$AU$163) -> 96.240014 | N53: 98
I54: MAXIMALT | N54: 98
I55: MACKESON | M55: =AVERAGE([24]Brewhouse!$AT$74:$AT$79) -> 93.959836 | N55: 98
I56: STARMALT | K56: =COUNTA([25]Brewhouse!$A$249:$A$254) -> 6 | L56: =AVERAGE([25]Brewhouse!$AY$249:$AY$254) -> 99.681996 | M56: =AVERAGE([25]Brewhouse!$AY$138:$AY$143,[25]Brewhouse!$AY$145:$AY$153,[25]Brewhouse!$AY$155,[25]Brewhouse!$AY$156:$AY$174,[25]Brewhouse!$AY$176:$AY$185,[25]Brewhouse!$AY$187:$AY$198,[25]Brewhouse!$AY$200:$AY$247,[25]Brewhouse!$AY$249:$AY$254) -> 98.774703 | N56: 98
I57: HR- P | M57: =AVERAGE([26]Brewhouse!$AW$13:$AW$14,[26]Brewhouse!$AW$16:$AW$17) -> 92.042628 | N57: 98
I58: Hurricane Reef | M58: =AVERAGE([26]Brewhouse!$AW$13:$AW$14) -> 88.376943 | N58: 98
K59: =SUM(K50:K58) -> 76 | L59: =((L50*K50)+(L51*K51)+(L52*K52)+(L53*K53)+(L54*K54)+(K57*L57)+(L55*K55)+(L56*K56)+(L58*K58))/(K59) -> 97.965422 | M59: =AVERAGE('[27]Closing- January 2023'!$L$42,'[28]Feb. 28th'!$L$42,'[29]March 31st'!$L$75,'[30]Apri 28th'!$L$51,L59) -> 98.06926 | N59: 98
J62: Daily Brewing Plan
J63: Brand | K63: Brews Achieved | L63: Average Brews per day
J64: CARIB | L64: MTD | M64: YTD | N64: TARGET
J65: STAG | K65: 5 | L65: =AVERAGE(#REF!,#REF!,K74,#REF!,#REF!,#REF!,#REF!,#REF!,#REF!,#REF!,#REF!) -> #REF! | M65: =AVERAGE(6,6,'[29]March 31st'!$L$80,'[31]June 30th '!$L$71,6,L65,'[32]July 31st'!$L$108,'[33]Aug 30th'!$L$124,7,[34]Oct.31st!$L$51) -> #REF! | N65: 9
J66: GUINN
J67: VITAMALT
...

Sheet Sept 1st
S1: P.G. | U1: Hot Time | W1: Process Time | Y1: Cooling Time
B2: Brewing Department Daily Process Loss Report | S2: Lower | T2: Upper | U2: Lower | V2: Upper | W2: Lower | X2: Upper | Y2: Lower | Z2: Upper
R3: CARIB | S3: 11.6 | T3: 12 | U3: 0 | V3: 0.11805556 | W3: 0.22569444 | X3: 0.26388889 | Y3: 0 | Z3: 60 | AB3: HR- PISNER
B4: Date: | C4: 46267 | J4: LOT WORT COLOUR: 3.4 | M4: Filter Sheets (Target 20 days) | R4: STAG | S4: 11.6 | T4: 12 | U4: 0 | V4: 0.11805556 | W4: 0.22569444 | X4: 0.26388889 | Y4: 0 | Z4: 60
M5: Double | N5: Single | R5: GUINNESS | S5: 17 | T5: 17.5 | U5: 0 | V5: 0.10763889 | W5: 0.24652778 | X5: 0.28472222 | Y5: 0 | Z5: 60
J6: MALT LOT: Lot #15 | L6: Sheet Day | R6: MACKESON | S6: 13.3 | T6: 13.5 | U6: 0 | V6: 0.12905093 | W6: 0.27430556 | X6: 0.30208333 | Y6: 0
R7: STARMALT | S7: 17 | T7: 17.4 | U7: 0 | V7: 0.13605324 | W7: 0.27430556 | X7: 0.30902778 | Y7: 0 | Z7: 85
B8: Brand | C8: Brew no. | D8: Kett. Hls | E8: Wort | F8: Cool Time(Mins) | G8: Cast. P.G. (Lab Result) | H8: Cast P.G. (Cellar Operator)-gravity | I8: Extr. Rec (78%) | J8: Theor. Extr. (77.5%) | K8: Boil Off /Vol. (4-6%) | L8: Boil Time | M8: Total Hot | N8: Brewing Time | O8: Operator | R8: Hurricane Reef | S8: 16.6 | T8: 17 | U8: 0 | V8: 0.12905093 | W8: 0.27430556 | X8: 0.30208333 | Y8: 0
E9: Meter (Hls) | F9: Target(< 60Mins) | M9: Time | R9: VITAMALT | S9: 14.2 | T9: 14.6 | U9: 0 | V9: 0.13905093 | W9: 0.26041667 | X9: 0.29513889 | Y9: 0 | Z9: 75
B10: CARIB | C10: =[4]Brewhouse!$A696 -> CA647 | D10: =[4]Brewhouse!$AF696 -> 48.6 | E10: =[4]Brewhouse!$AI696 -> 49.2 | F10: =[4]Brewhouse!$V696 -> 61 | G10: =[4]Brewhouse!AG696 -> 11.8 | I10: =[4]Brewhouse!$AU696 -> 97.633608 | J10: =[4]Brewhouse!$AV696 -> 97.722345 | K10: =[4]Brewhouse!$Q696 -> 11.497227 | L10: =[4]Brewhouse!$P696 -> 60 | M10: =[4]Brewhouse!$U696-[4]Brewhouse!$T696 -> 0.13194444 | N10: =[4]Brewhouse!$Z696 -> 0.27222222 | O10: =[4]Brewhouse!$AX696 -> R. Sookram
B11: CARIB | C11: =[4]Brewhouse!$A697 -> CA648 | D11: =[4]Brewhouse!$AF697 -> 48.2 | E11: =[4]Brewhouse!$AI697 -> 49.1 | F11: =[4]Brewhouse!$V697 -> 64 | G11: =[4]Brewhouse!AG697 -> 12 | I11: =[4]Brewhouse!$AU697 -> 99.296131 | J11: =[4]Brewhouse!$AV697 -> 99.386372 | K11: =[4]Brewhouse!$Q697 -> 12.074074 | L11: =[4]Brewhouse!$P697 -> 58 | M11: =[4]Brewhouse!$U697-[4]Brewhouse!$T697 -> 0.13333333 | N11: =[4]Brewhouse!$Z697 -> 0.29375 | O11: =[4]Brewhouse!$AX697 -> R. Sookram
B12: CARIB | C12: =[4]Brewhouse!$A698 -> CA649 | D12: =[4]Brewhouse!$AF698 -> 41.7 | E12: =[4]Brewhouse!$AI698 -> 43 | F12: =[4]Brewhouse!$V698 -> 46 | G12: =[4]Brewhouse!AG698 -> 11.9 | I12: =[4]Brewhouse!$AU698 -> 98.221286 | J12: =[4]Brewhouse!$AV698 -> 98.309885 | K12: =[4]Brewhouse!$Q698 -> 16.537678 | L12: =[4]Brewhouse!$P698 -> 60 | M12: =[4]Brewhouse!$U698-[4]Brewhouse!$T698 -> 0.12083333 | N12: =[4]Brewhouse!$Z698 -> 0.26875 | O12: =[4]Brewhouse!$AX698 -> R. Regis
B13: CARIB | C13: =[4]Brewhouse!$A699 -> CA650 | D13: =[4]Brewhouse!$AF699 -> 48.1 | E13: =[4]Brewhouse!$AI699 -> 48.9 | F13: =[4]Brewhouse!$V699 -> 58 | G13: =[4]Brewhouse!AG699 -> 11.7 | I13: =[4]Brewhouse!$AU699 -> 96.173273 | J13: =[4]Brewhouse!$AV699 -> 96.260682 | K13: =[4]Brewhouse!$Q699 -> 12.421442 | L13: =[4]Brewhouse!$P699 -> 60 | M13: =[4]Brewhouse!$U699-[4]Brewhouse!$T699 -> 0.11041667 | N13: =[4]Brewhouse!$Z699 -> 0.43263889 | O13: =[4]Brewhouse!$AX699 -> R. Regis
B14: CARIB | C14: =[4]Brewhouse!$A700 -> CA651 | D14: =[4]Brewhouse!$AF700 -> 48.1 | E14: =[4]Brewhouse!$AI700 -> 49 | F14: =[4]Brewhouse!$V700 -> 60 | G14: =[4]Brewhouse!AG700 -> 11.7 | I14: =[4]Brewhouse!$AU700 -> 96.130104 | J14: =[4]Brewhouse!$AV700 -> 96.217485 | K14: =[4]Brewhouse!$Q700 -> 12.421442 | L14: =[4]Brewhouse!$P700 -> 60 | M14: =[4]Brewhouse!$U700-[4]Brewhouse!$T700 -> 0.10763889 | N14: =[4]Brewhouse!$Z700 -> 0.24166667 | O14: =[4]Brewhouse!$AX700 -> R. Regis
B15: CARIB | C15: =[4]Brewhouse!$A701 -> CA652 | D15: =[4]Brewhouse!$AF701 -> 50.3 | E15: =[4]Brewhouse!$AI701 -> 51.1 | F15: =[4]Brewhouse!$V701 -> 64 | G15: =[4]Brewhouse!AG701 -> 11.9 | I15: =[4]Brewhouse!$AU701 -> 102.43572 | J15: =[4]Brewhouse!$AV701 -> 102.52882 | K15: =[4]Brewhouse!$Q701 -> 8.3548983 | L15: =[4]Brewhouse!$P701 -> 57 | M15: =[4]Brewhouse!$U701-[4]Brewhouse!$T701 -> 0.12569444 | N15: =[4]Brewhouse!$Z701 -> 0.26180556 | O15: =[4]Brewhouse!$AX701 -> R. Regis
B16: CARIB | C16: =[4]Brewhouse!$A702 -> CA653 | D16: =[4]Brewhouse!$AF702 -> 48 | E16: =[4]Brewhouse!$AI702 -> 48.6 | F16: =[4]Brewhouse!$V702 -> 56 | G16: =[4]Brewhouse!AG702 -> 11.8 | I16: =[4]Brewhouse!$AU702 -> 96.684179 | J16: =[4]Brewhouse!$AV702 -> 96.772041 | K16: =[4]Brewhouse!$Q702 -> 12.606285 | L16: =[4]Brewhouse!$P702 -> 57 | M16: =[4]Brewhouse!$U702-[4]Brewhouse!$T702 -> 0.10347222 | N16: =[4]Brewhouse!$Z702 -> 0.25486111 | O16: =[4]Brewhouse!$AX702 -> R. Regis
R17: =B17 -> 0 | S17: =VLOOKUP($B17,$R$3:$X$9,2,FALSE) -> #N/A | T17: =VLOOKUP($B17,$R$3:$X$9,3,FALSE) -> #N/A | U17: =VLOOKUP($B17,$R$3:$X$9,4,FALSE) -> #N/A | V17: =VLOOKUP($B17,$R$3:$X$9,5,FALSE) -> #N/A | W17: =VLOOKUP($B17,$R$3:$X$9,6,FALSE) -> #N/A | X17: =VLOOKUP($B17,$R$3:$X$9,7,FALSE) -> #N/A | Y17: =VLOOKUP($B17,$R$3:$Z$9,8,FALSE) -> #N/A | Z17: =VLOOKUP($B17,$R$3:$Z$9,9,FALSE) -> #N/A
R18: =B18 -> 0 | S18: =VLOOKUP($B18,$R$3:$X$9,2,FALSE) -> #N/A | T18: =VLOOKUP($B18,$R$3:$X$9,3,FALSE) -> #N/A | U18: =VLOOKUP($B18,$R$3:$X$9,4,FALSE) -> #N/A | V18: =VLOOKUP($B18,$R$3:$X$9,5,FALSE) -> #N/A | W18: =VLOOKUP($B18,$R$3:$X$9,6,FALSE) -> #N/A | X18: =VLOOKUP($B18,$R$3:$X$9,7,FALSE) -> #N/A | Y18: =VLOOKUP($B18,$R$3:$Z$9,8,FALSE) -> #N/A | Z18: =VLOOKUP($B18,$R$3:$Z$9,9,FALSE) -> #N/A
R19: =B19 -> 0 | S19: =VLOOKUP($B19,$R$3:$X$9,2,FALSE) -> #N/A | T19: =VLOOKUP($B19,$R$3:$X$9,3,FALSE) -> #N/A | U19: =VLOOKUP($B19,$R$3:$X$9,4,FALSE) -> #N/A | V19: =VLOOKUP($B19,$R$3:$X$9,5,FALSE) -> #N/A | W19: =VLOOKUP($B19,$R$3:$X$9,6,FALSE) -> #N/A | X19: =VLOOKUP($B19,$R$3:$X$9,7,FALSE) -> #N/A | Y19: =VLOOKUP($B19,$R$3:$Z$9,8,FALSE) -> #N/A | Z19: =VLOOKUP($B19,$R$3:$Z$9,9,FALSE) -> #N/A
B20: BRAND | D20: BBT P.G./ O.G | I20: Brand | K20: MTD No. of Brews | L20: MTD | M20: YTD | N20: Target | R20: =B20 -> BRAND | S20: =VLOOKUP($B20,$R$3:$X$9,2,FALSE) -> #N/A | T20: =VLOOKUP($B20,$R$3:$X$9,3,FALSE) -> #N/A | U20: =VLOOKUP($B20,$R$3:$X$9,4,FALSE) -> #N/A | V20: =VLOOKUP($B20,$R$3:$X$9,5,FALSE) -> #N/A | W20: =VLOOKUP($B20,$R$3:$X$9,6,FALSE) -> #N/A | X20: =VLOOKUP($B20,$R$3:$X$9,7,FALSE) -> #N/A | Y20: =VLOOKUP($B20,$R$3:$Z$9,8,FALSE) -> #N/A | Z20: =VLOOKUP($B20,$R$3:$Z$9,9,FALSE) -> #N/A
I21: CARIB | J21: =AVERAGE(I10:I16) -> 98.082044 | K21: =COUNTA([4]Brewhouse!$A$696:$A$702) -> 7 | L21: =AVERAGE([4]Brewhouse!$AU$696:$AU$702) -> 98.082044 | M21: =AVERAGE([4]Brewhouse!$AU$42:$AU$123,[4]Brewhouse!$AU$125:$AU$188,[4]Brewhouse!$AU$198:$AU$290,[4]Brewhouse!$AU$292:$AU$370,[4]Brewhouse!$AU$372:$AU$439,[4]Brewhouse!$AU$441:$AU$497,[4]Brewhouse!$AU$499:$AU$519,[4]Brewhouse!$AU$521:$AU$593,[4]Brewhouse!$AU$595:$AU$703) -> 98.283439 | N21: 98 | R21: =B21 -> 0 | S21: =VLOOKUP($B21,$R$3:$X$9,2,FALSE) -> #N/A | T21: =VLOOKUP($B21,$R$3:$X$9,3,FALSE) -> #N/A | U21: =VLOOKUP($B21,$R$3:$X$9,4,FALSE) -> #N/A | V21: =VLOOKUP($B21,$R$3:$X$9,5,FALSE) -> #N/A | W21: =VLOOKUP($B21,$R$3:$X$9,6,FALSE) -> #N/A | X21: =VLOOKUP($B21,$R$3:$X$9,7,FALSE) -> #N/A | Y21: =VLOOKUP($B21,$R$3:$Z$9,8,FALSE) -> #N/A | Z21: =VLOOKUP($B21,$R$3:$Z$9,9,FALSE) -> #N/A
I22: STAG | M22: =AVERAGE([5]Brewhouse!$AS$52:$AS$81,[5]Brewhouse!$AS$83:$AS$124,[5]Brewhouse!$AS$134:$AS$177,[5]Brewhouse!$AS$22:$AS$179,[5]Brewhouse!$AS$214:$AS$249,[5]Brewhouse!$AS$252:$AS$293,[5]Brewhouse!$AS$295:$AS$325,[5]Brewhouse!$AS$327:$AS$361) -> 98.239656 | N22: 98 | R22: =B22 -> 0 | S22: =VLOOKUP($B22,$R$3:$X$9,2,FALSE) -> #N/A | T22: =VLOOKUP($B22,$R$3:$X$9,3,FALSE) -> #N/A | U22: =VLOOKUP($B22,$R$3:$X$9,4,FALSE) -> #N/A | V22: =VLOOKUP($B22,$R$3:$X$9,5,FALSE) -> #N/A | W22: =VLOOKUP($B22,$R$3:$X$9,6,FALSE) -> #N/A | X22: =VLOOKUP($B22,$R$3:$X$9,7,FALSE) -> #N/A | Y22: =VLOOKUP($B22,$R$3:$Z$9,8,FALSE) -> #N/A | Z22: =VLOOKUP($B22,$R$3:$Z$9,9,FALSE) -> #N/A
I23: GUINNESS | M23: =AVERAGE([6]Brewhouse!$AU$16:$AU$23,[6]Brewhouse!$AU$25:$AU$32,[6]Brewhouse!$AU$34:$AU$41,[6]Brewhouse!$AU$43:$AU$60,[6]Brewhouse!$AU$62:$AU$69,[6]Brewhouse!$AU$71:$AU$88,[6]Brewhouse!$AU$90:$AU$97) -> 96.502171 | N23: 98 | R23: =B23 -> 0 | S23: =VLOOKUP($B23,$R$3:$X$9,2,FALSE) -> #N/A | T23: =VLOOKUP($B23,$R$3:$X$9,3,FALSE) -> #N/A | U23: =VLOOKUP($B23,$R$3:$X$9,4,FALSE) -> #N/A | V23: =VLOOKUP($B23,$R$3:$X$9,5,FALSE) -> #N/A | W23: =VLOOKUP($B23,$R$3:$X$9,6,FALSE) -> #N/A | X23: =VLOOKUP($B23,$R$3:$X$9,7,FALSE) -> #N/A | Y23: =VLOOKUP($B23,$R$3:$Z$9,8,FALSE) -> #N/A | Z23: =VLOOKUP($B23,$R$3:$Z$9,9,FALSE) -> #N/A
I24: VITAMALT | M24: =AVERAGE([7]Brewhouse!$AV$23:$AV$34,[7]Brewhouse!$AV$36,[7]Brewhouse!$AV$38:$AV$52,[7]Brewhouse!$AV$54:$AV$60,[7]Brewhouse!$AV$62:$AV$69,[7]Brewhouse!$AV$71:$AV$78,[7]Brewhouse!$AV$80:$AV$87,[7]Brewhouse!$AV$89:$AV$96) -> 97.559547 | N24: 98 | R24: =B24 -> 0 | S24: =VLOOKUP($B24,$R$3:$X$9,2,FALSE) -> #N/A | T24: =VLOOKUP($B24,$R$3:$X$9,3,FALSE) -> #N/A | U24: =VLOOKUP($B24,$R$3:$X$9,4,FALSE) -> #N/A | V24: =VLOOKUP($B24,$R$3:$X$9,5,FALSE) -> #N/A | W24: =VLOOKUP($B24,$R$3:$X$9,6,FALSE) -> #N/A | X24: =VLOOKUP($B24,$R$3:$X$9,7,FALSE) -> #N/A | Y24: =VLOOKUP($B24,$R$3:$Z$9,8,FALSE) -> #N/A | Z24: =VLOOKUP($B24,$R$3:$Z$9,9,FALSE) -> #N/A
I25: MAXIMALT | N25: 98 | R25: =B25 -> 0 | S25: =VLOOKUP($B25,$R$3:$X$9,2,FALSE) -> #N/A | T25: =VLOOKUP($B25,$R$3:$X$9,3,FALSE) -> #N/A | U25: =VLOOKUP($B25,$R$3:$X$9,4,FALSE) -> #N/A | V25: =VLOOKUP($B25,$R$3:$X$9,5,FALSE) -> #N/A | W25: =VLOOKUP($B25,$R$3:$X$9,6,FALSE) -> #N/A | X25: =VLOOKUP($B25,$R$3:$X$9,7,FALSE) -> #N/A | Y25: =VLOOKUP($B25,$R$3:$Z$9,8,FALSE) -> #N/A | Z25: =VLOOKUP($B25,$R$3:$Z$9,9,FALSE) -> #N/A
I26: MACKESON | M26: =AVERAGE([8]Brewhouse!$AT$4:$AT$11,[8]Brewhouse!$AT$13:$AT$16,[8]Brewhouse!$AT$18:$AT$21) -> 91.832675 | N26: 98 | R26: =B26 -> 0 | S26: =VLOOKUP($B26,$R$3:$X$9,2,FALSE) -> #N/A | T26: =VLOOKUP($B26,$R$3:$X$9,3,FALSE) -> #N/A | U26: =VLOOKUP($B26,$R$3:$X$9,4,FALSE) -> #N/A | V26: =VLOOKUP($B26,$R$3:$X$9,5,FALSE) -> #N/A | W26: =VLOOKUP($B26,$R$3:$X$9,6,FALSE) -> #N/A | X26: =VLOOKUP($B26,$R$3:$X$9,7,FALSE) -> #N/A | Y26: =VLOOKUP($B26,$R$3:$Z$9,8,FALSE) -> #N/A | Z26: =VLOOKUP($B26,$R$3:$Z$9,9,FALSE) -> #N/A
I27: STARMALT | M27: =AVERAGE([3]Brewhouse!$AY$5:$AY$14,[3]Brewhouse!$AY$16:$AY$23,[3]Brewhouse!$AY$42,[3]Brewhouse!$AY$44:$AY$51,[3]Brewhouse!$AY$53:$AY$64,[3]Brewhouse!$AY$66:$AY$73,[3]Brewhouse!$AY$75:$AY$82,[3]Brewhouse!$AY$84:$AY$101) -> 97.78466 | N27: 98 | R27: =B27 -> 0 | S27: =VLOOKUP($B27,$R$3:$X$9,2,FALSE) -> #N/A | T27: =VLOOKUP($B27,$R$3:$X$9,3,FALSE) -> #N/A | U27: =VLOOKUP($B27,$R$3:$X$9,4,FALSE) -> #N/A | V27: =VLOOKUP($B27,$R$3:$X$9,5,FALSE) -> #N/A | W27: =VLOOKUP($B27,$R$3:$X$9,6,FALSE) -> #N/A | X27: =VLOOKUP($B27,$R$3:$X$9,7,FALSE) -> #N/A | Y27: =VLOOKUP($B27,$R$3:$Z$9,8,FALSE) -> #N/A | Z27: =VLOOKUP($B27,$R$3:$Z$9,9,FALSE) -> #N/A
I28: HR- Pils | N28: 98 | R28: =B28 -> 0 | S28: =VLOOKUP($B28,$R$3:$X$9,2,FALSE) -> #N/A | T28: =VLOOKUP($B28,$R$3:$X$9,3,FALSE) -> #N/A | U28: =VLOOKUP($B28,$R$3:$X$9,4,FALSE) -> #N/A | V28: =VLOOKUP($B28,$R$3:$X$9,5,FALSE) -> #N/A | W28: =VLOOKUP($B28,$R$3:$X$9,6,FALSE) -> #N/A | X28: =VLOOKUP($B28,$R$3:$X$9,7,FALSE) -> #N/A | Y28: =VLOOKUP($B28,$R$3:$Z$9,8,FALSE) -> #N/A | Z28: =VLOOKUP($B28,$R$3:$Z$9,9,FALSE) -> #N/A
I29: HR- IPA | N29: 98 | R29: =B29 -> 0 | S29: =VLOOKUP($B29,$R$3:$X$9,2,FALSE) -> #N/A | T29: =VLOOKUP($B29,$R$3:$X$9,3,FALSE) -> #N/A | U29: =VLOOKUP($B29,$R$3:$X$9,4,FALSE) -> #N/A | V29: =VLOOKUP($B29,$R$3:$X$9,5,FALSE) -> #N/A | W29: =VLOOKUP($B29,$R$3:$X$9,6,FALSE) -> #N/A | X29: =VLOOKUP($B29,$R$3:$X$9,7,FALSE) -> #N/A | Y29: =VLOOKUP($B29,$R$3:$Z$9,8,FALSE) -> #N/A | Z29: =VLOOKUP($B29,$R$3:$Z$9,9,FALSE) -> #N/A
I30: HR- APA | N30: 98 | R30: =B30 -> 0 | S30: =VLOOKUP($B30,$R$3:$X$9,2,FALSE) -> #N/A | T30: =VLOOKUP($B30,$R$3:$X$9,3,FALSE) -> #N/A | U30: =VLOOKUP($B30,$R$3:$X$9,4,FALSE) -> #N/A | V30: =VLOOKUP($B30,$R$3:$X$9,5,FALSE) -> #N/A | W30: =VLOOKUP($B30,$R$3:$X$9,6,FALSE) -> #N/A | X30: =VLOOKUP($B30,$R$3:$X$9,7,FALSE) -> #N/A | Y30: =VLOOKUP($B30,$R$3:$Z$9,8,FALSE) -> #N/A | Z30: =VLOOKUP($B30,$R$3:$Z$9,9,FALSE) -> #N/A
K31: =SUM(K21:K30) -> 7 | L31: =((L21*K21)+(L22*K22)+(L23*K23)+(L24*K24)+(L25*K25)+(K28*L28)+(L26*K26)+(L27*K27)+(L30*K30))/(K31) -> 98.082044 | M31: =AVERAGE('[9]Jan30th-31st'!$L$42,'[10]Feb 27th-28th'!$L$45,'[11]Mar 31st'!$L$42,'[12]Apr 30th'!$L$41,'[13]May 29th '!$L$35,'[14]June 30th'!$L$32,[15]July31st!$L$36,'[16]Aug 31st'!$L$32,L31) -> 97.995733 | N31: 98 | R31: =B31 -> 0 | S31: =VLOOKUP($B31,$R$3:$X$9,2,FALSE) -> #N/A | T31: =VLOOKUP($B31,$R$3:$X$9,3,FALSE) -> #N/A | U31: =VLOOKUP($B31,$R$3:$X$9,4,FALSE) -> #N/A | V31: =VLOOKUP($B31,$R$3:$X$9,5,FALSE) -> #N/A | W31: =VLOOKUP($B31,$R$3:$X$9,6,FALSE) -> #N/A | X31: =VLOOKUP($B31,$R$3:$X$9,7,FALSE) -> #N/A | Y31: =VLOOKUP($B31,$R$3:$Z$9,8,FALSE) -> #N/A | Z31: =VLOOKUP($B31,$R$3:$Z$9,9,FALSE) -> #N/A
R32: =B32 -> 0 | S32: =VLOOKUP($B32,$R$3:$X$9,2,FALSE) -> #N/A | T32: =VLOOKUP($B32,$R$3:$X$9,3,FALSE) -> #N/A | U32: =VLOOKUP($B32,$R$3:$X$9,4,FALSE) -> #N/A | V32: =VLOOKUP($B32,$R$3:$X$9,5,FALSE) -> #N/A | W32: =VLOOKUP($B32,$R$3:$X$9,6,FALSE) -> #N/A | X32: =VLOOKUP($B32,$R$3:$X$9,7,FALSE) -> #N/A | Y32: =VLOOKUP($B32,$R$3:$Z$9,8,FALSE) -> #N/A | Z32: =VLOOKUP($B32,$R$3:$Z$9,9,FALSE) -> #N/A
J33: Daily Brewing Plan
J34: Brand | L34: Average Brews per day
J35: CARIB | K35: 7 | L35: MTD | M35: YTD | N35: TARGET
J36: STAG | L36: =AVERAGE(K45) -> 7 | M36: =AVERAGE('[9]Jan30th-31st'!$L$47,L36,'[10]Feb 26th '!$L$39,'[11]Mar 31st'!$L$47,'[12]Apr 30th'!$L$46,'[13]May 29th '!$L$40,'[14]June 30th'!$L$39,[15]July31st!$L$41,'[16]Aug 31st'!$L$37) -> 6.515567 | N36: 9.2
J37: GUINN
J38: VITAMALT
J39: STARMALT
J40: MACKESON
...

Sheet Sept 2nd
S1: P.G. | U1: Hot Time | W1: Process Time | Y1: Cooling Time
B2: Brewing Department Daily Process Loss Report | S2: Lower | T2: Upper | U2: Lower | V2: Upper | W2: Lower | X2: Upper | Y2: Lower | Z2: Upper
R3: CARIB | S3: 11.6 | T3: 12 | U3: 0 | V3: 0.11805556 | W3: 0.22569444 | X3: 0.26388889 | Y3: 0 | Z3: 60 | AB3: HR- PISNER
B4: Date: | C4: 46268 | J4: LOT WORT COLOUR: 3.4 | M4: Filter Sheets (Target 20 days) | R4: STAG | S4: 11.6 | T4: 12 | U4: 0 | V4: 0.11805556 | W4: 0.22569444 | X4: 0.26388889 | Y4: 0 | Z4: 60
M5: Double | N5: Single | R5: GUINNESS | S5: 17 | T5: 17.5 | U5: 0 | V5: 0.10763889 | W5: 0.24652778 | X5: 0.28472222 | Y5: 0 | Z5: 60
J6: MALT LOT: Lot #15 | L6: Sheet Day | R6: MACKESON | S6: 13.3 | T6: 13.5 | U6: 0 | V6: 0.12905093 | W6: 0.27430556 | X6: 0.30208333 | Y6: 0
R7: STARMALT | S7: 17 | T7: 17.4 | U7: 0 | V7: 0.13605324 | W7: 0.27430556 | X7: 0.30902778 | Y7: 0 | Z7: 85
B8: Brand | C8: Brew no. | D8: Kett. Hls | E8: Wort | F8: Cool Time(Mins) | G8: Cast. P.G. (Lab Result) | H8: Cast P.G. (Cellar Operator)-gravity | I8: Extr. Rec (78%) | J8: Theor. Extr. (77.5%) | K8: Boil Off /Vol. (4-6%) | L8: Boil Time | M8: Total Hot | N8: Brewing Time | O8: Operator | R8: Hurricane Reef | S8: 16.6 | T8: 17 | U8: 0 | V8: 0.12905093 | W8: 0.27430556 | X8: 0.30208333 | Y8: 0
E9: Meter (Hls) | F9: Target(< 60Mins) | M9: Time | R9: VITAMALT | S9: 14.2 | T9: 14.6 | U9: 0 | V9: 0.13905093 | W9: 0.26041667 | X9: 0.29513889 | Y9: 0 | Z9: 75
B10: CARIB | C10: =[4]Brewhouse!$A703 -> CA654 | D10: =[4]Brewhouse!$AF703 -> 49 | E10: =[4]Brewhouse!$AI703 -> 49.6 | F10: =[4]Brewhouse!$V703 -> 60 | G10: =[4]Brewhouse!AG703 -> 11.8 | I10: =[4]Brewhouse!$AU703 -> 98.126699 | J10: =[4]Brewhouse!$AV703 -> 98.886898 | K10: =[4]Brewhouse!$Q703 -> 11.497227 | L10: =[4]Brewhouse!$P703 -> 57 | M10: =[4]Brewhouse!$U703-[4]Brewhouse!$T703 -> 0.11041667 | N10: =[4]Brewhouse!$Z703 -> 0.25972222 | O10: =[4]Brewhouse!$AX703 -> R. Sookram | R10: =B10 -> CARIB | S10: =VLOOKUP($B10,$R$3:$X$9,2,FALSE) -> 11.6 | T10: =VLOOKUP($B10,$R$3:$X$9,3,FALSE) -> 12 | U10: =VLOOKUP($B10,$R$3:$X$9,4,FALSE) -> 0 | V10: =VLOOKUP($B10,$R$3:$X$9,5,FALSE) -> 0.11805556 | W10: =VLOOKUP($B10,$R$3:$X$9,6,FALSE) -> 0.22569444 | X10: =VLOOKUP($B10,$R$3:$X$9,7,FALSE) -> 0.26388889 | Y10: =VLOOKUP($B10,$R$3:$Z$9,8,FALSE) -> 0 | Z10: =VLOOKUP($B10,$R$3:$Z$9,9,FALSE) -> 60
B11: CARIB | C11: =[4]Brewhouse!$A704 -> CA655 | D11: =[4]Brewhouse!$AF704 -> 49.9 | E11: =[4]Brewhouse!$AI704 -> 50.7 | F11: =[4]Brewhouse!$V704 -> 63 | G11: =[4]Brewhouse!AG704 -> 11.7 | I11: =[4]Brewhouse!$AU704 -> 99.408786 | J11: =[4]Brewhouse!$AV704 -> 100.17892 | K11: =[4]Brewhouse!$Q704 -> 9.0942699 | L11: =[4]Brewhouse!$P704 -> 57 | M11: =[4]Brewhouse!$U704-[4]Brewhouse!$T704 -> 0.10972222 | N11: =[4]Brewhouse!$Z704 -> 0.25833333 | O11: =[4]Brewhouse!$AX704 -> D. Gomaz | R11: =B11 -> CARIB | S11: =VLOOKUP($B11,$R$3:$X$9,2,FALSE) -> 11.6 | T11: =VLOOKUP($B11,$R$3:$X$9,3,FALSE) -> 12 | U11: =VLOOKUP($B11,$R$3:$X$9,4,FALSE) -> 0 | V11: =VLOOKUP($B11,$R$3:$X$9,5,FALSE) -> 0.11805556 | W11: =VLOOKUP($B11,$R$3:$X$9,6,FALSE) -> 0.22569444 | X11: =VLOOKUP($B11,$R$3:$X$9,7,FALSE) -> 0.26388889 | Y11: =VLOOKUP($B11,$R$3:$Z$9,8,FALSE) -> 0 | Z11: =VLOOKUP($B11,$R$3:$Z$9,9,FALSE) -> 60
B12: CARIB | C12: =[4]Brewhouse!$A705 -> CA656 | D12: =[4]Brewhouse!$AF705 -> 48.7 | E12: =[4]Brewhouse!$AI705 -> 48.8 | F12: =[4]Brewhouse!$V705 -> 60 | G12: =[4]Brewhouse!AG705 -> 11.8 | I12: =[4]Brewhouse!$AU705 -> 96.54401 | J12: =[4]Brewhouse!$AV705 -> 97.291948 | K12: =[4]Brewhouse!$Q705 -> 12.791128 | L12: =[4]Brewhouse!$P705 -> 60 | M12: =[4]Brewhouse!$U705-[4]Brewhouse!$T705 -> 0.11041667 | N12: =[4]Brewhouse!$Z705 -> 0.25416667 | O12: =[4]Brewhouse!$AX705 -> D. Gomaz | R12: =B12 -> CARIB | S12: =VLOOKUP($B12,$R$3:$X$9,2,FALSE) -> 11.6 | T12: =VLOOKUP($B12,$R$3:$X$9,3,FALSE) -> 12 | U12: =VLOOKUP($B12,$R$3:$X$9,4,FALSE) -> 0 | V12: =VLOOKUP($B12,$R$3:$X$9,5,FALSE) -> 0.11805556 | W12: =VLOOKUP($B12,$R$3:$X$9,6,FALSE) -> 0.22569444 | X12: =VLOOKUP($B12,$R$3:$X$9,7,FALSE) -> 0.26388889 | Y12: =VLOOKUP($B12,$R$3:$Z$9,8,FALSE) -> 0 | Z12: =VLOOKUP($B12,$R$3:$Z$9,9,FALSE) -> 60
B13: CARIB | C13: =[4]Brewhouse!$A706 -> CA657 | D13: =[4]Brewhouse!$AF706 -> 50.6 | E13: =[4]Brewhouse!$AI706 -> 51.7 | F13: =[4]Brewhouse!$V706 -> 60 | G13: =[4]Brewhouse!AG706 -> 11.6 | I13: =[4]Brewhouse!$AU706 -> 98.726419 | J13: =[4]Brewhouse!$AV706 -> 99.491971 | K13: =[4]Brewhouse!$Q706 -> 7.8003697 | L13: =[4]Brewhouse!$P706 -> 59 | M13: =[4]Brewhouse!$U706-[4]Brewhouse!$T706 -> 0.10694444 | N13: =[4]Brewhouse!$Z706 -> 0.25277778 | O13: =[4]Brewhouse!$AX706 -> D. Gomaz | R13: =B13 -> CARIB | S13: =VLOOKUP($B13,$R$3:$X$9,2,FALSE) -> 11.6 | T13: =VLOOKUP($B13,$R$3:$X$9,3,FALSE) -> 12 | U13: =VLOOKUP($B13,$R$3:$X$9,4,FALSE) -> 0 | V13: =VLOOKUP($B13,$R$3:$X$9,5,FALSE) -> 0.11805556 | W13: =VLOOKUP($B13,$R$3:$X$9,6,FALSE) -> 0.22569444 | X13: =VLOOKUP($B13,$R$3:$X$9,7,FALSE) -> 0.26388889 | Y13: =VLOOKUP($B13,$R$3:$Z$9,8,FALSE) -> 0 | Z13: =VLOOKUP($B13,$R$3:$Z$9,9,FALSE) -> 60
B14: CARIB | C14: =[4]Brewhouse!$A707 -> CA658 | D14: =[4]Brewhouse!$AF707 -> 48.7 | E14: =[4]Brewhouse!$AI707 -> 48.3 | F14: =[4]Brewhouse!$V707 -> 55 | G14: =[4]Brewhouse!AG707 -> 11.9 | I14: =[4]Brewhouse!$AU707 -> 95.56863 | J14: =[4]Brewhouse!$AV707 -> 96.309357 | K14: =[4]Brewhouse!$Q707 -> 11.312384 | L14: =[4]Brewhouse!$P707 -> 61 | M14: =[4]Brewhouse!$U707-[4]Brewhouse!$T707 -> 0.10902778 | N14: =[4]Brewhouse!$Z707 -> 0.24236111 | O14: =[4]Brewhouse!$AX707 -> D. Gomaz | R14: =B14 -> CARIB | S14: =VLOOKUP($B14,$R$3:$X$9,2,FALSE) -> 11.6 | T14: =VLOOKUP($B14,$R$3:$X$9,3,FALSE) -> 12 | U14: =VLOOKUP($B14,$R$3:$X$9,4,FALSE) -> 0 | V14: =VLOOKUP($B14,$R$3:$X$9,5,FALSE) -> 0.11805556 | W14: =VLOOKUP($B14,$R$3:$X$9,6,FALSE) -> 0.22569444 | X14: =VLOOKUP($B14,$R$3:$X$9,7,FALSE) -> 0.26388889 | Y14: =VLOOKUP($B14,$R$3:$Z$9,8,FALSE) -> 0 | Z14: =VLOOKUP($B14,$R$3:$Z$9,9,FALSE) -> 60
B15: CARIB | C15: =[4]Brewhouse!$A708 -> CA659 | D15: =[4]Brewhouse!$AF708 -> 48.6 | E15: =[4]Brewhouse!$AI708 -> 49.7 | F15: =[4]Brewhouse!$V708 -> 60 | G15: =[4]Brewhouse!AG708 -> 11.6 | I15: =[4]Brewhouse!$AU708 -> 96.692705 | J15: =[4]Brewhouse!$AV708 -> 97.441745 | K15: =[4]Brewhouse!$Q708 -> 12.97597 | L15: =[4]Brewhouse!$P708 -> 62 | M15: =[4]Brewhouse!$U708-[4]Brewhouse!$T708 -> 0.11111111 | N15: =[4]Brewhouse!$Z708 -> 0.24583333 | O15: =[4]Brewhouse!$AX708 -> D. Gomaz | R15: =B15 -> CARIB | S15: =VLOOKUP($B15,$R$3:$X$9,2,FALSE) -> 11.6 | T15: =VLOOKUP($B15,$R$3:$X$9,3,FALSE) -> 12 | U15: =VLOOKUP($B15,$R$3:$X$9,4,FALSE) -> 0 | V15: =VLOOKUP($B15,$R$3:$X$9,5,FALSE) -> 0.11805556 | W15: =VLOOKUP($B15,$R$3:$X$9,6,FALSE) -> 0.22569444 | X15: =VLOOKUP($B15,$R$3:$X$9,7,FALSE) -> 0.26388889 | Y15: =VLOOKUP($B15,$R$3:$Z$9,8,FALSE) -> 0 | Z15: =VLOOKUP($B15,$R$3:$Z$9,9,FALSE) -> 60
B16: CARIB | C16: =[4]Brewhouse!$A709 -> CA660 | D16: =[4]Brewhouse!$AF709 -> 50.5 | E16: =[4]Brewhouse!$AI709 -> 50.1 | F16: =[4]Brewhouse!$V709 -> 58 | G16: =[4]Brewhouse!AG709 -> 12 | I16: =[4]Brewhouse!$AU709 -> 101.00946 | J16: =[4]Brewhouse!$AV709 -> 101.79194 | K16: =[4]Brewhouse!$Q709 -> 9.4639556 | L16: =[4]Brewhouse!$P709 -> 100 | M16: =[4]Brewhouse!$U709-[4]Brewhouse!$T709 -> 0.21597222 | N16: =[4]Brewhouse!$Z709 -> 0.36180556 | O16: =[4]Brewhouse!$AX709 -> R. Regis | P16: Wort kettle pump problems | R16: =B16 -> CARIB | S16: =VLOOKUP($B16,$R$3:$X$9,2,FALSE) -> 11.6 | T16: =VLOOKUP($B16,$R$3:$X$9,3,FALSE) -> 12 | U16: =VLOOKUP($B16,$R$3:$X$9,4,FALSE) -> 0 | V16: =VLOOKUP($B16,$R$3:$X$9,5,FALSE) -> 0.11805556 | W16: =VLOOKUP($B16,$R$3:$X$9,6,FALSE) -> 0.22569444 | X16: =VLOOKUP($B16,$R$3:$X$9,7,FALSE) -> 0.26388889 | Y16: =VLOOKUP($B16,$R$3:$Z$9,8,FALSE) -> 0 | Z16: =VLOOKUP($B16,$R$3:$Z$9,9,FALSE) -> 60
B17: CARIB | C17: =[4]Brewhouse!$A710 -> CA661 | D17: =[4]Brewhouse!$AF710 -> 48.8 | E17: =[4]Brewhouse!$AI710 -> 49.4 | F17: =[4]Brewhouse!$V710 -> 59 | G17: =[4]Brewhouse!AG710 -> 11.5 | I17: =[4]Brewhouse!$AU710 -> 95.23677 | J17: =[4]Brewhouse!$AV710 -> 95.974532 | K17: =[4]Brewhouse!$Q710 -> 10.962963 | L17: =[4]Brewhouse!$P710 -> 57 | M17: =[4]Brewhouse!$U710-[4]Brewhouse!$T710 -> 0.12986111 | N17: =[4]Brewhouse!$Z710 -> 0.49166667 | O17: =[4]Brewhouse!$AX710 -> R. Regis | P17: Wort kettle pump problems | R17: =B17 -> CARIB | S17: =VLOOKUP($B17,$R$3:$X$9,2,FALSE) -> 11.6 | T17: =VLOOKUP($B17,$R$3:$X$9,3,FALSE) -> 12 | U17: =VLOOKUP($B17,$R$3:$X$9,4,FALSE) -> 0 | V17: =VLOOKUP($B17,$R$3:$X$9,5,FALSE) -> 0.11805556 | W17: =VLOOKUP($B17,$R$3:$X$9,6,FALSE) -> 0.22569444 | X17: =VLOOKUP($B17,$R$3:$X$9,7,FALSE) -> 0.26388889 | Y17: =VLOOKUP($B17,$R$3:$Z$9,8,FALSE) -> 0 | Z17: =VLOOKUP($B17,$R$3:$Z$9,9,FALSE) -> 60
B18: CARIB | C18: =[4]Brewhouse!$A711 -> CA662 | D18: =[4]Brewhouse!$AF711 -> 48 | E18: =[4]Brewhouse!$AI711 -> 48.7 | F18: =[4]Brewhouse!$V711 -> 60 | G18: =[4]Brewhouse!AG711 -> 12 | I18: =[4]Brewhouse!$AU711 -> 97.941169 | J18: =[4]Brewhouse!$AV711 -> 98.699982 | K18: =[4]Brewhouse!$Q711 -> 12.444444 | L18: =[4]Brewhouse!$P711 -> 59 | M18: =[4]Brewhouse!$U711-[4]Brewhouse!$T711 -> 0.10486111 | N18: =[4]Brewhouse!$Z711 -> 0.51111111 | O18: =[4]Brewhouse!$AX711 -> R. Regis | R18: =B18 -> CARIB | S18: =VLOOKUP($B18,$R$3:$X$9,2,FALSE) -> 11.6 | T18: =VLOOKUP($B18,$R$3:$X$9,3,FALSE) -> 12 | U18: =VLOOKUP($B18,$R$3:$X$9,4,FALSE) -> 0 | V18: =VLOOKUP($B18,$R$3:$X$9,5,FALSE) -> 0.11805556 | W18: =VLOOKUP($B18,$R$3:$X$9,6,FALSE) -> 0.22569444 | X18: =VLOOKUP($B18,$R$3:$X$9,7,FALSE) -> 0.26388889 | Y18: =VLOOKUP($B18,$R$3:$Z$9,8,FALSE) -> 0 | Z18: =VLOOKUP($B18,$R$3:$Z$9,9,FALSE) -> 60
R19: =B19 -> 0 | S19: =VLOOKUP($B19,$R$3:$X$9,2,FALSE) -> #N/A | T19: =VLOOKUP($B19,$R$3:$X$9,3,FALSE) -> #N/A | U19: =VLOOKUP($B19,$R$3:$X$9,4,FALSE) -> #N/A | V19: =VLOOKUP($B19,$R$3:$X$9,5,FALSE) -> #N/A | W19: =VLOOKUP($B19,$R$3:$X$9,6,FALSE) -> #N/A | X19: =VLOOKUP($B19,$R$3:$X$9,7,FALSE) -> #N/A | Y19: =VLOOKUP($B19,$R$3:$Z$9,8,FALSE) -> #N/A | Z19: =VLOOKUP($B19,$R$3:$Z$9,9,FALSE) -> #N/A
R20: =B20 -> 0 | S20: =VLOOKUP($B20,$R$3:$X$9,2,FALSE) -> #N/A | T20: =VLOOKUP($B20,$R$3:$X$9,3,FALSE) -> #N/A | U20: =VLOOKUP($B20,$R$3:$X$9,4,FALSE) -> #N/A | V20: =VLOOKUP($B20,$R$3:$X$9,5,FALSE) -> #N/A | W20: =VLOOKUP($B20,$R$3:$X$9,6,FALSE) -> #N/A | X20: =VLOOKUP($B20,$R$3:$X$9,7,FALSE) -> #N/A | Y20: =VLOOKUP($B20,$R$3:$Z$9,8,FALSE) -> #N/A | Z20: =VLOOKUP($B20,$R$3:$Z$9,9,FALSE) -> #N/A
R21: =B21 -> 0 | S21: =VLOOKUP($B21,$R$3:$X$9,2,FALSE) -> #N/A | T21: =VLOOKUP($B21,$R$3:$X$9,3,FALSE) -> #N/A | U21: =VLOOKUP($B21,$R$3:$X$9,4,FALSE) -> #N/A | V21: =VLOOKUP($B21,$R$3:$X$9,5,FALSE) -> #N/A | W21: =VLOOKUP($B21,$R$3:$X$9,6,FALSE) -> #N/A | X21: =VLOOKUP($B21,$R$3:$X$9,7,FALSE) -> #N/A | Y21: =VLOOKUP($B21,$R$3:$Z$9,8,FALSE) -> #N/A | Z21: =VLOOKUP($B21,$R$3:$Z$9,9,FALSE) -> #N/A
B22: BRAND | D22: BBT P.G./ O.G | I22: Brand | K22: MTD No. of Brews | L22: MTD | M22: YTD | N22: Target | R22: =B22 -> BRAND | S22: =VLOOKUP($B22,$R$3:$X$9,2,FALSE) -> #N/A | T22: =VLOOKUP($B22,$R$3:$X$9,3,FALSE) -> #N/A | U22: =VLOOKUP($B22,$R$3:$X$9,4,FALSE) -> #N/A | V22: =VLOOKUP($B22,$R$3:$X$9,5,FALSE) -> #N/A | W22: =VLOOKUP($B22,$R$3:$X$9,6,FALSE) -> #N/A | X22: =VLOOKUP($B22,$R$3:$X$9,7,FALSE) -> #N/A | Y22: =VLOOKUP($B22,$R$3:$Z$9,8,FALSE) -> #N/A | Z22: =VLOOKUP($B22,$R$3:$Z$9,9,FALSE) -> #N/A
I23: CARIB | J23: =AVERAGE(I10:I17) -> 97.664186 | K23: =COUNTA([4]Brewhouse!$A$696:$A$711) -> 16 | L23: =AVERAGE([4]Brewhouse!$AU$696:$AU$711) -> 97.86431 | M23: =AVERAGE([4]Brewhouse!$AU$42:$AU$123,[4]Brewhouse!$AU$125:$AU$188,[4]Brewhouse!$AU$198:$AU$290,[4]Brewhouse!$AU$292:$AU$370,[4]Brewhouse!$AU$372:$AU$439,[4]Brewhouse!$AU$441:$AU$497,[4]Brewhouse!$AU$499:$AU$519,[4]Brewhouse!$AU$521:$AU$593,[4]Brewhouse!$AU$595:$AU$711) -> 98.275568 | N23: 98 | R23: =B23 -> 0 | S23: =VLOOKUP($B23,$R$3:$X$9,2,FALSE) -> #N/A | T23: =VLOOKUP($B23,$R$3:$X$9,3,FALSE) -> #N/A | U23: =VLOOKUP($B23,$R$3:$X$9,4,FALSE) -> #N/A | V23: =VLOOKUP($B23,$R$3:$X$9,5,FALSE) -> #N/A | W23: =VLOOKUP($B23,$R$3:$X$9,6,FALSE) -> #N/A | X23: =VLOOKUP($B23,$R$3:$X$9,7,FALSE) -> #N/A | Y23: =VLOOKUP($B23,$R$3:$Z$9,8,FALSE) -> #N/A | Z23: =VLOOKUP($B23,$R$3:$Z$9,9,FALSE) -> #N/A
I24: STAG | M24: =AVERAGE([5]Brewhouse!$AS$52:$AS$81,[5]Brewhouse!$AS$83:$AS$124,[5]Brewhouse!$AS$134:$AS$177,[5]Brewhouse!$AS$22:$AS$179,[5]Brewhouse!$AS$214:$AS$249,[5]Brewhouse!$AS$252:$AS$293,[5]Brewhouse!$AS$295:$AS$325,[5]Brewhouse!$AS$327:$AS$361) -> 98.239656 | N24: 98 | R24: =B24 -> 0 | S24: =VLOOKUP($B24,$R$3:$X$9,2,FALSE) -> #N/A | T24: =VLOOKUP($B24,$R$3:$X$9,3,FALSE) -> #N/A | U24: =VLOOKUP($B24,$R$3:$X$9,4,FALSE) -> #N/A | V24: =VLOOKUP($B24,$R$3:$X$9,5,FALSE) -> #N/A | W24: =VLOOKUP($B24,$R$3:$X$9,6,FALSE) -> #N/A | X24: =VLOOKUP($B24,$R$3:$X$9,7,FALSE) -> #N/A | Y24: =VLOOKUP($B24,$R$3:$Z$9,8,FALSE) -> #N/A | Z24: =VLOOKUP($B24,$R$3:$Z$9,9,FALSE) -> #N/A
I25: GUINNESS | M25: =AVERAGE([6]Brewhouse!$AU$16:$AU$23,[6]Brewhouse!$AU$25:$AU$32,[6]Brewhouse!$AU$34:$AU$41,[6]Brewhouse!$AU$43:$AU$60,[6]Brewhouse!$AU$62:$AU$69,[6]Brewhouse!$AU$71:$AU$88,[6]Brewhouse!$AU$90:$AU$97) -> 96.502171 | N25: 98 | R25: =B25 -> 0 | S25: =VLOOKUP($B25,$R$3:$X$9,2,FALSE) -> #N/A | T25: =VLOOKUP($B25,$R$3:$X$9,3,FALSE) -> #N/A | U25: =VLOOKUP($B25,$R$3:$X$9,4,FALSE) -> #N/A | V25: =VLOOKUP($B25,$R$3:$X$9,5,FALSE) -> #N/A | W25: =VLOOKUP($B25,$R$3:$X$9,6,FALSE) -> #N/A | X25: =VLOOKUP($B25,$R$3:$X$9,7,FALSE) -> #N/A | Y25: =VLOOKUP($B25,$R$3:$Z$9,8,FALSE) -> #N/A | Z25: =VLOOKUP($B25,$R$3:$Z$9,9,FALSE) -> #N/A
I26: VITAMALT | M26: =AVERAGE([7]Brewhouse!$AV$23:$AV$34,[7]Brewhouse!$AV$36,[7]Brewhouse!$AV$38:$AV$52,[7]Brewhouse!$AV$54:$AV$60,[7]Brewhouse!$AV$62:$AV$69,[7]Brewhouse!$AV$71:$AV$78,[7]Brewhouse!$AV$80:$AV$87,[7]Brewhouse!$AV$89:$AV$96) -> 97.559547 | N26: 98 | R26: =B26 -> 0 | S26: =VLOOKUP($B26,$R$3:$X$9,2,FALSE) -> #N/A | T26: =VLOOKUP($B26,$R$3:$X$9,3,FALSE) -> #N/A | U26: =VLOOKUP($B26,$R$3:$X$9,4,FALSE) -> #N/A | V26: =VLOOKUP($B26,$R$3:$X$9,5,FALSE) -> #N/A | W26: =VLOOKUP($B26,$R$3:$X$9,6,FALSE) -> #N/A | X26: =VLOOKUP($B26,$R$3:$X$9,7,FALSE) -> #N/A | Y26: =VLOOKUP($B26,$R$3:$Z$9,8,FALSE) -> #N/A | Z26: =VLOOKUP($B26,$R$3:$Z$9,9,FALSE) -> #N/A
I27: MAXIMALT | N27: 98 | R27: =B27 -> 0 | S27: =VLOOKUP($B27,$R$3:$X$9,2,FALSE) -> #N/A | T27: =VLOOKUP($B27,$R$3:$X$9,3,FALSE) -> #N/A | U27: =VLOOKUP($B27,$R$3:$X$9,4,FALSE) -> #N/A | V27: =VLOOKUP($B27,$R$3:$X$9,5,FALSE) -> #N/A | W27: =VLOOKUP($B27,$R$3:$X$9,6,FALSE) -> #N/A | X27: =VLOOKUP($B27,$R$3:$X$9,7,FALSE) -> #N/A | Y27: =VLOOKUP($B27,$R$3:$Z$9,8,FALSE) -> #N/A | Z27: =VLOOKUP($B27,$R$3:$Z$9,9,FALSE) -> #N/A
I28: MACKESON | M28: =AVERAGE([8]Brewhouse!$AT$4:$AT$11,[8]Brewhouse!$AT$13:$AT$16,[8]Brewhouse!$AT$18:$AT$21) -> 91.832675 | N28: 98 | R28: =B28 -> 0 | S28: =VLOOKUP($B28,$R$3:$X$9,2,FALSE) -> #N/A | T28: =VLOOKUP($B28,$R$3:$X$9,3,FALSE) -> #N/A | U28: =VLOOKUP($B28,$R$3:$X$9,4,FALSE) -> #N/A | V28: =VLOOKUP($B28,$R$3:$X$9,5,FALSE) -> #N/A | W28: =VLOOKUP($B28,$R$3:$X$9,6,FALSE) -> #N/A | X28: =VLOOKUP($B28,$R$3:$X$9,7,FALSE) -> #N/A | Y28: =VLOOKUP($B28,$R$3:$Z$9,8,FALSE) -> #N/A | Z28: =VLOOKUP($B28,$R$3:$Z$9,9,FALSE) -> #N/A
I29: STARMALT | M29: =AVERAGE([3]Brewhouse!$AY$5:$AY$14,[3]Brewhouse!$AY$16:$AY$23,[3]Brewhouse!$AY$42,[3]Brewhouse!$AY$44:$AY$51,[3]Brewhouse!$AY$53:$AY$64,[3]Brewhouse!$AY$66:$AY$73,[3]Brewhouse!$AY$75:$AY$82,[3]Brewhouse!$AY$84:$AY$101) -> 97.78466 | N29: 98 | R29: =B29 -> 0 | S29: =VLOOKUP($B29,$R$3:$X$9,2,FALSE) -> #N/A | T29: =VLOOKUP($B29,$R$3:$X$9,3,FALSE) -> #N/A | U29: =VLOOKUP($B29,$R$3:$X$9,4,FALSE) -> #N/A | V29: =VLOOKUP($B29,$R$3:$X$9,5,FALSE) -> #N/A | W29: =VLOOKUP($B29,$R$3:$X$9,6,FALSE) -> #N/A | X29: =VLOOKUP($B29,$R$3:$X$9,7,FALSE) -> #N/A | Y29: =VLOOKUP($B29,$R$3:$Z$9,8,FALSE) -> #N/A | Z29: =VLOOKUP($B29,$R$3:$Z$9,9,FALSE) -> #N/A
I30: HR- Pils | N30: 98 | R30: =B30 -> 0 | S30: =VLOOKUP($B30,$R$3:$X$9,2,FALSE) -> #N/A | T30: =VLOOKUP($B30,$R$3:$X$9,3,FALSE) -> #N/A | U30: =VLOOKUP($B30,$R$3:$X$9,4,FALSE) -> #N/A | V30: =VLOOKUP($B30,$R$3:$X$9,5,FALSE) -> #N/A | W30: =VLOOKUP($B30,$R$3:$X$9,6,FALSE) -> #N/A | X30: =VLOOKUP($B30,$R$3:$X$9,7,FALSE) -> #N/A | Y30: =VLOOKUP($B30,$R$3:$Z$9,8,FALSE) -> #N/A | Z30: =VLOOKUP($B30,$R$3:$Z$9,9,FALSE) -> #N/A
I31: HR- IPA | N31: 98 | R31: =B31 -> 0 | S31: =VLOOKUP($B31,$R$3:$X$9,2,FALSE) -> #N/A | T31: =VLOOKUP($B31,$R$3:$X$9,3,FALSE) -> #N/A | U31: =VLOOKUP($B31,$R$3:$X$9,4,FALSE) -> #N/A | V31: =VLOOKUP($B31,$R$3:$X$9,5,FALSE) -> #N/A | W31: =VLOOKUP($B31,$R$3:$X$9,6,FALSE) -> #N/A | X31: =VLOOKUP($B31,$R$3:$X$9,7,FALSE) -> #N/A | Y31: =VLOOKUP($B31,$R$3:$Z$9,8,FALSE) -> #N/A | Z31: =VLOOKUP($B31,$R$3:$Z$9,9,FALSE) -> #N/A
I32: HR- APA | N32: 98 | R32: =B32 -> 0 | S32: =VLOOKUP($B32,$R$3:$X$9,2,FALSE) -> #N/A | T32: =VLOOKUP($B32,$R$3:$X$9,3,FALSE) -> #N/A | U32: =VLOOKUP($B32,$R$3:$X$9,4,FALSE) -> #N/A | V32: =VLOOKUP($B32,$R$3:$X$9,5,FALSE) -> #N/A | W32: =VLOOKUP($B32,$R$3:$X$9,6,FALSE) -> #N/A | X32: =VLOOKUP($B32,$R$3:$X$9,7,FALSE) -> #N/A | Y32: =VLOOKUP($B32,$R$3:$Z$9,8,FALSE) -> #N/A | Z32: =VLOOKUP($B32,$R$3:$Z$9,9,FALSE) -> #N/A
K33: =SUM(K23:K32) -> 16 | L33: =((L23*K23)+(L24*K24)+(L25*K25)+(L26*K26)+(L27*K27)+(K30*L30)+(L28*K28)+(L29*K29)+(L32*K32))/(K33) -> 97.86431 | M33: =AVERAGE('[9]Jan30th-31st'!$L$42,'[10]Feb 27th-28th'!$L$45,'[11]Mar 31st'!$L$42,'[12]Apr 30th'!$L$41,'[13]May 29th '!$L$35,'[14]June 30th'!$L$32,[15]July31st!$L$36,'[16]Aug 31st'!$L$32,L33) -> 97.968516 | N33: 98 | R33: =B33 -> 0 | S33: =VLOOKUP($B33,$R$3:$X$9,2,FALSE) -> #N/A | T33: =VLOOKUP($B33,$R$3:$X$9,3,FALSE) -> #N/A | U33: =VLOOKUP($B33,$R$3:$X$9,4,FALSE) -> #N/A | V33: =VLOOKUP($B33,$R$3:$X$9,5,FALSE) -> #N/A | W33: =VLOOKUP($B33,$R$3:$X$9,6,FALSE) -> #N/A | X33: =VLOOKUP($B33,$R$3:$X$9,7,FALSE) -> #N/A | Y33: =VLOOKUP($B33,$R$3:$Z$9,8,FALSE) -> #N/A | Z33: =VLOOKUP($B33,$R$3:$Z$9,9,FALSE) -> #N/A
R34: =B34 -> 0 | S34: =VLOOKUP($B34,$R$3:$X$9,2,FALSE) -> #N/A | T34: =VLOOKUP($B34,$R$3:$X$9,3,FALSE) -> #N/A | U34: =VLOOKUP($B34,$R$3:$X$9,4,FALSE) -> #N/A | V34: =VLOOKUP($B34,$R$3:$X$9,5,FALSE) -> #N/A | W34: =VLOOKUP($B34,$R$3:$X$9,6,FALSE) -> #N/A | X34: =VLOOKUP($B34,$R$3:$X$9,7,FALSE) -> #N/A | Y34: =VLOOKUP($B34,$R$3:$Z$9,8,FALSE) -> #N/A | Z34: =VLOOKUP($B34,$R$3:$Z$9,9,FALSE) -> #N/A
J35: Daily Brewing Plan
J36: Brand | L36: Average Brews per day
J37: CARIB | K37: 9 | L37: MTD | M37: YTD | N37: TARGET
J38: STAG | L38: =AVERAGE('Sept 1st'!K45,K47) -> 8 | M38: =AVERAGE('[9]Jan30th-31st'!$L$47,L38,'[10]Feb 26th '!$L$39,'[11]Mar 31st'!$L$47,'[12]Apr 30th'!$L$46,'[13]May 29th '!$L$40,'[14]June 30th'!$L$39,[15]July31st!$L$41,'[16]Aug 31st'!$L$37) -> 6.6266782 | N38: 9.2
J39: GUINN
J40: VITAMALT
...

Sheet Sept 3rd
S1: P.G. | U1: Hot Time | W1: Process Time | Y1: Cooling Time
B2: Brewing Department Daily Process Loss Report | S2: Lower | T2: Upper | U2: Lower | V2: Upper | W2: Lower | X2: Upper | Y2: Lower | Z2: Upper
R3: CARIB | S3: 11.6 | T3: 12 | U3: 0 | V3: 0.11805556 | W3: 0.22569444 | X3: 0.26388889 | Y3: 0 | Z3: 60 | AB3: HR- PISNER
B4: Date: | C4: 46268 | J4: LOT WORT COLOUR: 3.4 | M4: Filter Sheets (Target 20 days) | R4: STAG | S4: 11.6 | T4: 12 | U4: 0 | V4: 0.11805556 | W4: 0.22569444 | X4: 0.26388889 | Y4: 0 | Z4: 60
M5: Double | N5: Single | R5: GUINNESS | S5: 17 | T5: 17.5 | U5: 0 | V5: 0.10763889 | W5: 0.24652778 | X5: 0.28472222 | Y5: 0 | Z5: 60
J6: MALT LOT: Lot #15 | L6: Sheet Day | R6: MACKESON | S6: 13.3 | T6: 13.5 | U6: 0 | V6: 0.12905093 | W6: 0.27430556 | X6: 0.30208333 | Y6: 0
R7: STARMALT | S7: 17 | T7: 17.4 | U7: 0 | V7: 0.13605324 | W7: 0.27430556 | X7: 0.30902778 | Y7: 0 | Z7: 85
B8: Brand | C8: Brew no. | D8: Kett. Hls | E8: Wort | F8: Cool Time(Mins) | G8: Cast. P.G. (Lab Result) | H8: Cast P.G. (Cellar Operator)-gravity | I8: Extr. Rec (78%) | J8: Theor. Extr. (77.5%) | K8: Boil Off /Vol. (4-6%) | L8: Boil Time | M8: Total Hot | N8: Brewing Time | O8: Operator | R8: Hurricane Reef | S8: 16.6 | T8: 17 | U8: 0 | V8: 0.12905093 | W8: 0.27430556 | X8: 0.30208333 | Y8: 0
E9: Meter (Hls) | F9: Target(< 60Mins) | M9: Time | R9: VITAMALT | S9: 14.2 | T9: 14.6 | U9: 0 | V9: 0.13905093 | W9: 0.26041667 | X9: 0.29513889 | Y9: 0 | Z9: 75
B10: CARIB | C10: =[4]Brewhouse!$A712 -> CA663 | D10: =[4]Brewhouse!$AF712 -> 49.6 | E10: =[4]Brewhouse!$AI712 -> 50.3 | F10: =[4]Brewhouse!$V712 -> 63 | G10: =[4]Brewhouse!AG712 -> 11.7 | I10: =[4]Brewhouse!$AU712 -> 98.624495 | J10: =[4]Brewhouse!$AV712 -> 99.388551 | K10: =[4]Brewhouse!$Q712 -> 9.6487985 | L10: =[4]Brewhouse!$P712 -> 60 | M10: =[4]Brewhouse!$U712-[4]Brewhouse!$T712 -> 0.11597222 | N10: =[4]Brewhouse!$Z712 -> 0.26319444 | O10: =[4]Brewhouse!$AX712 -> R. Sookram | R10: =B10 -> CARIB | S10: =VLOOKUP($B10,$R$3:$X$9,2,FALSE) -> 11.6 | T10: =VLOOKUP($B10,$R$3:$X$9,3,FALSE) -> 12 | U10: =VLOOKUP($B10,$R$3:$X$9,4,FALSE) -> 0 | V10: =VLOOKUP($B10,$R$3:$X$9,5,FALSE) -> 0.11805556 | W10: =VLOOKUP($B10,$R$3:$X$9,6,FALSE) -> 0.22569444 | X10: =VLOOKUP($B10,$R$3:$X$9,7,FALSE) -> 0.26388889 | Y10: =VLOOKUP($B10,$R$3:$Z$9,8,FALSE) -> 0 | Z10: =VLOOKUP($B10,$R$3:$Z$9,9,FALSE) -> 60
B11: CARIB | C11: =[4]Brewhouse!$A713 -> CA664 | D11: =[4]Brewhouse!$AF713 -> 50.4 | E11: =[4]Brewhouse!$AI713 -> 51.1 | F11: =[4]Brewhouse!$V713 -> 63 | G11: =[4]Brewhouse!AG713 -> 11.6 | I11: =[4]Brewhouse!$AU713 -> 99.291912 | J11: =[4]Brewhouse!$AV713 -> 100.06114 | K11: =[4]Brewhouse!$Q713 -> 8.1700555 | L11: =[4]Brewhouse!$P713 -> 61 | M11: =[4]Brewhouse!$U713-[4]Brewhouse!$T713 -> 0.10833333 | N11: =[4]Brewhouse!$Z713 -> 0.26111111 | O11: =[4]Brewhouse!$AX713 -> D. Gomaz | R11: =B11 -> CARIB | S11: =VLOOKUP($B11,$R$3:$X$9,2,FALSE) -> 11.6 | T11: =VLOOKUP($B11,$R$3:$X$9,3,FALSE) -> 12 | U11: =VLOOKUP($B11,$R$3:$X$9,4,FALSE) -> 0 | V11: =VLOOKUP($B11,$R$3:$X$9,5,FALSE) -> 0.11805556 | W11: =VLOOKUP($B11,$R$3:$X$9,6,FALSE) -> 0.22569444 | X11: =VLOOKUP($B11,$R$3:$X$9,7,FALSE) -> 0.26388889 | Y11: =VLOOKUP($B11,$R$3:$Z$9,8,FALSE) -> 0 | Z11: =VLOOKUP($B11,$R$3:$Z$9,9,FALSE) -> 60
B12: CARIB | C12: =[4]Brewhouse!$A714 -> CA665 | D12: =[4]Brewhouse!$AF714 -> 51.4 | E12: =[4]Brewhouse!$AI714 -> 51.9 | F12: =[4]Brewhouse!$V714 -> 60 | G12: =[4]Brewhouse!AG714 -> 11.8 | I12: =[4]Brewhouse!$AU714 -> 102.67693 | J12: =[4]Brewhouse!$AV714 -> 103.47238 | K12: =[4]Brewhouse!$Q714 -> 6.3216266 | L12: =[4]Brewhouse!$P714 -> 62 | M12: =[4]Brewhouse!$U714-[4]Brewhouse!$T714 -> 0.125 | N12: =[4]Brewhouse!$Z714 -> 0.27986111 | O12: =[4]Brewhouse!$AX714 -> D. Gomaz | R12: =B12 -> CARIB | S12: =VLOOKUP($B12,$R$3:$X$9,2,FALSE) -> 11.6 | T12: =VLOOKUP($B12,$R$3:$X$9,3,FALSE) -> 12 | U12: =VLOOKUP($B12,$R$3:$X$9,4,FALSE) -> 0 | V12: =VLOOKUP($B12,$R$3:$X$9,5,FALSE) -> 0.11805556 | W12: =VLOOKUP($B12,$R$3:$X$9,6,FALSE) -> 0.22569444 | X12: =VLOOKUP($B12,$R$3:$X$9,7,FALSE) -> 0.26388889 | Y12: =VLOOKUP($B12,$R$3:$Z$9,8,FALSE) -> 0 | Z12: =VLOOKUP($B12,$R$3:$Z$9,9,FALSE) -> 60
B13: CARIB | C13: =[4]Brewhouse!$A715 -> CA666 | D13: =[4]Brewhouse!$AF715 -> 45.3 | E13: =[4]Brewhouse!$AI715 -> 46.2 | F13: =[4]Brewhouse!$V715 -> 57 | G13: =[4]Brewhouse!AG715 -> 11.7 | I13: =[4]Brewhouse!$AU715 -> 102.38451 | J13: =[4]Brewhouse!$AV715 -> 103.17215 | K13: =[4]Brewhouse!$Q715 -> 9.9393939 | L13: =[4]Brewhouse!$P715 -> 61 | M13: =[4]Brewhouse!$U715-[4]Brewhouse!$T715 -> 0.1125 | N13: =[4]Brewhouse!$Z715 -> 0.25694444 | O13: =[4]Brewhouse!$AX715 -> D. Gomaz | R13: =B13 -> CARIB | S13: =VLOOKUP($B13,$R$3:$X$9,2,FALSE) -> 11.6 | T13: =VLOOKUP($B13,$R$3:$X$9,3,FALSE) -> 12 | U13: =VLOOKUP($B13,$R$3:$X$9,4,FALSE) -> 0 | V13: =VLOOKUP($B13,$R$3:$X$9,5,FALSE) -> 0.11805556 | W13: =VLOOKUP($B13,$R$3:$X$9,6,FALSE) -> 0.22569444 | X13: =VLOOKUP($B13,$R$3:$X$9,7,FALSE) -> 0.26388889 | Y13: =VLOOKUP($B13,$R$3:$Z$9,8,FALSE) -> 0 | Z13: =VLOOKUP($B13,$R$3:$Z$9,9,FALSE) -> 60
R14: =B14 -> 0 | S14: =VLOOKUP($B14,$R$3:$X$9,2,FALSE) -> #N/A | T14: =VLOOKUP($B14,$R$3:$X$9,3,FALSE) -> #N/A | U14: =VLOOKUP($B14,$R$3:$X$9,4,FALSE) -> #N/A | V14: =VLOOKUP($B14,$R$3:$X$9,5,FALSE) -> #N/A | W14: =VLOOKUP($B14,$R$3:$X$9,6,FALSE) -> #N/A | X14: =VLOOKUP($B14,$R$3:$X$9,7,FALSE) -> #N/A | Y14: =VLOOKUP($B14,$R$3:$Z$9,8,FALSE) -> #N/A | Z14: =VLOOKUP($B14,$R$3:$Z$9,9,FALSE) -> #N/A
B15: MACKESON | C15: =[8]Brewhouse!$A23 -> MK017 | D15: =[8]Brewhouse!$AF23 -> 49.3 | E15: =[8]Brewhouse!$AI23 -> 48.1 | F15: =[8]Brewhouse!$X23 -> 53 | G15: =[8]Brewhouse!$AG23 -> 13 | I15: =[8]Brewhouse!$AT23 -> 91.951724 | J15: =[8]Brewhouse!$AU23 -> 92.579945 | K15: =[8]Brewhouse!$S23 -> 12.685918 | L15: =[8]Brewhouse!$R23 -> 111 | M15: =[8]Brewhouse!$W23-[8]Brewhouse!$V23 -> 0.14930556 | N15: =[8]Brewhouse!$AA23 -> 0.31666667 | O15: =[8]Brewhouse!$AX23 -> R.Regis | R15: =B15 -> MACKESON | S15: =VLOOKUP($B15,$R$3:$X$9,2,FALSE) -> 13.3 | T15: =VLOOKUP($B15,$R$3:$X$9,3,FALSE) -> 13.5 | U15: =VLOOKUP($B15,$R$3:$X$9,4,FALSE) -> 0 | V15: =VLOOKUP($B15,$R$3:$X$9,5,FALSE) -> 0.12905093 | W15: =VLOOKUP($B15,$R$3:$X$9,6,FALSE) -> 0.27430556 | X15: =VLOOKUP($B15,$R$3:$X$9,7,FALSE) -> 0.30208333 | Y15: =VLOOKUP($B15,$R$3:$Z$9,8,FALSE) -> 0 | Z15: =VLOOKUP($B15,$R$3:$Z$9,9,FALSE) -> 0
B16: MACKESON | C16: =[8]Brewhouse!$A24 -> MK018 | D16: =[8]Brewhouse!$AF24 -> 51.6 | E16: =[8]Brewhouse!$AI24 -> 51.1 | F16: =[8]Brewhouse!$X24 -> 62 | G16: =[8]Brewhouse!$AG24 -> 13.1 | I16: =[8]Brewhouse!$AT24 -> 96.150584 | J16: =[8]Brewhouse!$AU24 -> 96.807492 | K16: =[8]Brewhouse!$S24 -> 8.4228571 | L16: =[8]Brewhouse!$R24 -> 95 | M16: =[8]Brewhouse!$W24-[8]Brewhouse!$V24 -> 0.13888889 | N16: =[8]Brewhouse!$AA24 -> 0.35902778 | O16: =[8]Brewhouse!$AX24 -> R.Regis | R16: =B16 -> MACKESON | S16: =VLOOKUP($B16,$R$3:$X$9,2,FALSE) -> 13.3 | T16: =VLOOKUP($B16,$R$3:$X$9,3,FALSE) -> 13.5 | U16: =VLOOKUP($B16,$R$3:$X$9,4,FALSE) -> 0 | V16: =VLOOKUP($B16,$R$3:$X$9,5,FALSE) -> 0.12905093 | W16: =VLOOKUP($B16,$R$3:$X$9,6,FALSE) -> 0.27430556 | X16: =VLOOKUP($B16,$R$3:$X$9,7,FALSE) -> 0.30208333 | Y16: =VLOOKUP($B16,$R$3:$Z$9,8,FALSE) -> 0 | Z16: =VLOOKUP($B16,$R$3:$Z$9,9,FALSE) -> 0
B17: MACKESON | C17: =[8]Brewhouse!$A25 -> MK019 | D17: =[8]Brewhouse!$AF25 -> 51.1 | E17: =[8]Brewhouse!$AI25 -> 50.6 | F17: =[8]Brewhouse!$X25 -> 55 | G17: =[8]Brewhouse!$AG25 -> 13.3 | I17: =[8]Brewhouse!$AT25 -> 96.73092 | J17: =[8]Brewhouse!$AU25 -> 97.391793 | K17: =[8]Brewhouse!$S25 -> 9.3157143 | L17: =[8]Brewhouse!$R25 -> 80 | M17: =[8]Brewhouse!$W25-[8]Brewhouse!$V25 -> 0.14236111 | N17: =[8]Brewhouse!$AA25 -> 0.34375 | O17: =[8]Brewhouse!$AX25 -> R.Regis | R17: =B17 -> MACKESON | S17: =VLOOKUP($B17,$R$3:$X$9,2,FALSE) -> 13.3 | T17: =VLOOKUP($B17,$R$3:$X$9,3,FALSE) -> 13.5 | U17: =VLOOKUP($B17,$R$3:$X$9,4,FALSE) -> 0 | V17: =VLOOKUP($B17,$R$3:$X$9,5,FALSE) -> 0.12905093 | W17: =VLOOKUP($B17,$R$3:$X$9,6,FALSE) -> 0.27430556 | X17: =VLOOKUP($B17,$R$3:$X$9,7,FALSE) -> 0.30208333 | Y17: =VLOOKUP($B17,$R$3:$Z$9,8,FALSE) -> 0 | Z17: =VLOOKUP($B17,$R$3:$Z$9,9,FALSE) -> 0
R18: =B18 -> 0 | S18: =VLOOKUP($B18,$R$3:$X$9,2,FALSE) -> #N/A | T18: =VLOOKUP($B18,$R$3:$X$9,3,FALSE) -> #N/A | U18: =VLOOKUP($B18,$R$3:$X$9,4,FALSE) -> #N/A | V18: =VLOOKUP($B18,$R$3:$X$9,5,FALSE) -> #N/A | W18: =VLOOKUP($B18,$R$3:$X$9,6,FALSE) -> #N/A | X18: =VLOOKUP($B18,$R$3:$X$9,7,FALSE) -> #N/A | Y18: =VLOOKUP($B18,$R$3:$Z$9,8,FALSE) -> #N/A | Z18: =VLOOKUP($B18,$R$3:$Z$9,9,FALSE) -> #N/A
B19: BRAND | D19: BBT P.G./ O.G | I19: Brand | K19: MTD No. of Brews | L19: MTD | M19: YTD | N19: Target | R19: =B19 -> BRAND | S19: =VLOOKUP($B19,$R$3:$X$9,2,FALSE) -> #N/A | T19: =VLOOKUP($B19,$R$3:$X$9,3,FALSE) -> #N/A | U19: =VLOOKUP($B19,$R$3:$X$9,4,FALSE) -> #N/A | V19: =VLOOKUP($B19,$R$3:$X$9,5,FALSE) -> #N/A | W19: =VLOOKUP($B19,$R$3:$X$9,6,FALSE) -> #N/A | X19: =VLOOKUP($B19,$R$3:$X$9,7,FALSE) -> #N/A | Y19: =VLOOKUP($B19,$R$3:$Z$9,8,FALSE) -> #N/A | Z19: =VLOOKUP($B19,$R$3:$Z$9,9,FALSE) -> #N/A
I20: CARIB | J20: =AVERAGE(I10:I13) -> 100.74446 | K20: =COUNTA([4]Brewhouse!$A$696:$A$715) -> 20 | L20: =AVERAGE([4]Brewhouse!$AU$696:$AU$715) -> 98.44034 | M20: =AVERAGE([4]Brewhouse!$AU$42:$AU$123,[4]Brewhouse!$AU$125:$AU$188,[4]Brewhouse!$AU$198:$AU$290,[4]Brewhouse!$AU$292:$AU$370,[4]Brewhouse!$AU$372:$AU$439,[4]Brewhouse!$AU$441:$AU$497,[4]Brewhouse!$AU$499:$AU$519,[4]Brewhouse!$AU$521:$AU$593,[4]Brewhouse!$AU$595:$AU$715) -> 98.290599 | N20: 98 | R20: =B20 -> 0 | S20: =VLOOKUP($B20,$R$3:$X$9,2,FALSE) -> #N/A | T20: =VLOOKUP($B20,$R$3:$X$9,3,FALSE) -> #N/A | U20: =VLOOKUP($B20,$R$3:$X$9,4,FALSE) -> #N/A | V20: =VLOOKUP($B20,$R$3:$X$9,5,FALSE) -> #N/A | W20: =VLOOKUP($B20,$R$3:$X$9,6,FALSE) -> #N/A | X20: =VLOOKUP($B20,$R$3:$X$9,7,FALSE) -> #N/A | Y20: =VLOOKUP($B20,$R$3:$Z$9,8,FALSE) -> #N/A | Z20: =VLOOKUP($B20,$R$3:$Z$9,9,FALSE) -> #N/A
I21: STAG | M21: =AVERAGE([5]Brewhouse!$AS$52:$AS$81,[5]Brewhouse!$AS$83:$AS$124,[5]Brewhouse!$AS$134:$AS$177,[5]Brewhouse!$AS$22:$AS$179,[5]Brewhouse!$AS$214:$AS$249,[5]Brewhouse!$AS$252:$AS$293,[5]Brewhouse!$AS$295:$AS$325,[5]Brewhouse!$AS$327:$AS$361) -> 98.239656 | N21: 98 | R21: =B21 -> 0 | S21: =VLOOKUP($B21,$R$3:$X$9,2,FALSE) -> #N/A | T21: =VLOOKUP($B21,$R$3:$X$9,3,FALSE) -> #N/A | U21: =VLOOKUP($B21,$R$3:$X$9,4,FALSE) -> #N/A | V21: =VLOOKUP($B21,$R$3:$X$9,5,FALSE) -> #N/A | W21: =VLOOKUP($B21,$R$3:$X$9,6,FALSE) -> #N/A | X21: =VLOOKUP($B21,$R$3:$X$9,7,FALSE) -> #N/A | Y21: =VLOOKUP($B21,$R$3:$Z$9,8,FALSE) -> #N/A | Z21: =VLOOKUP($B21,$R$3:$Z$9,9,FALSE) -> #N/A
I22: GUINNESS | M22: =AVERAGE([6]Brewhouse!$AU$16:$AU$23,[6]Brewhouse!$AU$25:$AU$32,[6]Brewhouse!$AU$34:$AU$41,[6]Brewhouse!$AU$43:$AU$60,[6]Brewhouse!$AU$62:$AU$69,[6]Brewhouse!$AU$71:$AU$88,[6]Brewhouse!$AU$90:$AU$97) -> 96.502171 | N22: 98 | R22: =B22 -> 0 | S22: =VLOOKUP($B22,$R$3:$X$9,2,FALSE) -> #N/A | T22: =VLOOKUP($B22,$R$3:$X$9,3,FALSE) -> #N/A | U22: =VLOOKUP($B22,$R$3:$X$9,4,FALSE) -> #N/A | V22: =VLOOKUP($B22,$R$3:$X$9,5,FALSE) -> #N/A | W22: =VLOOKUP($B22,$R$3:$X$9,6,FALSE) -> #N/A | X22: =VLOOKUP($B22,$R$3:$X$9,7,FALSE) -> #N/A | Y22: =VLOOKUP($B22,$R$3:$Z$9,8,FALSE) -> #N/A | Z22: =VLOOKUP($B22,$R$3:$Z$9,9,FALSE) -> #N/A
I23: VITAMALT | M23: =AVERAGE([7]Brewhouse!$AV$23:$AV$34,[7]Brewhouse!$AV$36,[7]Brewhouse!$AV$38:$AV$52,[7]Brewhouse!$AV$54:$AV$60,[7]Brewhouse!$AV$62:$AV$69,[7]Brewhouse!$AV$71:$AV$78,[7]Brewhouse!$AV$80:$AV$87,[7]Brewhouse!$AV$89:$AV$96) -> 97.559547 | N23: 98 | R23: =B23 -> 0 | S23: =VLOOKUP($B23,$R$3:$X$9,2,FALSE) -> #N/A | T23: =VLOOKUP($B23,$R$3:$X$9,3,FALSE) -> #N/A | U23: =VLOOKUP($B23,$R$3:$X$9,4,FALSE) -> #N/A | V23: =VLOOKUP($B23,$R$3:$X$9,5,FALSE) -> #N/A | W23: =VLOOKUP($B23,$R$3:$X$9,6,FALSE) -> #N/A | X23: =VLOOKUP($B23,$R$3:$X$9,7,FALSE) -> #N/A | Y23: =VLOOKUP($B23,$R$3:$Z$9,8,FALSE) -> #N/A | Z23: =VLOOKUP($B23,$R$3:$Z$9,9,FALSE) -> #N/A
I24: MAXIMALT | N24: 98 | R24: =B24 -> 0 | S24: =VLOOKUP($B24,$R$3:$X$9,2,FALSE) -> #N/A | T24: =VLOOKUP($B24,$R$3:$X$9,3,FALSE) -> #N/A | U24: =VLOOKUP($B24,$R$3:$X$9,4,FALSE) -> #N/A | V24: =VLOOKUP($B24,$R$3:$X$9,5,FALSE) -> #N/A | W24: =VLOOKUP($B24,$R$3:$X$9,6,FALSE) -> #N/A | X24: =VLOOKUP($B24,$R$3:$X$9,7,FALSE) -> #N/A | Y24: =VLOOKUP($B24,$R$3:$Z$9,8,FALSE) -> #N/A | Z24: =VLOOKUP($B24,$R$3:$Z$9,9,FALSE) -> #N/A
I25: MACKESON | J25: =AVERAGE(I15:I17) -> 94.944409 | K25: =COUNTA([8]Brewhouse!$A$23:$A$25) -> 3 | L25: =AVERAGE([8]Brewhouse!$AT$23:$AT$25) -> 94.944409 | M25: =AVERAGE([8]Brewhouse!$AT$4:$AT$11,[8]Brewhouse!$AT$13:$AT$16,[8]Brewhouse!$AT$18:$AT$25) -> 92.34358 | N25: 98 | R25: =B25 -> 0 | S25: =VLOOKUP($B25,$R$3:$X$9,2,FALSE) -> #N/A | T25: =VLOOKUP($B25,$R$3:$X$9,3,FALSE) -> #N/A | U25: =VLOOKUP($B25,$R$3:$X$9,4,FALSE) -> #N/A | V25: =VLOOKUP($B25,$R$3:$X$9,5,FALSE) -> #N/A | W25: =VLOOKUP($B25,$R$3:$X$9,6,FALSE) -> #N/A | X25: =VLOOKUP($B25,$R$3:$X$9,7,FALSE) -> #N/A | Y25: =VLOOKUP($B25,$R$3:$Z$9,8,FALSE) -> #N/A | Z25: =VLOOKUP($B25,$R$3:$Z$9,9,FALSE) -> #N/A
I26: STARMALT | M26: =AVERAGE([3]Brewhouse!$AY$5:$AY$14,[3]Brewhouse!$AY$16:$AY$23,[3]Brewhouse!$AY$42,[3]Brewhouse!$AY$44:$AY$51,[3]Brewhouse!$AY$53:$AY$64,[3]Brewhouse!$AY$66:$AY$73,[3]Brewhouse!$AY$75:$AY$82,[3]Brewhouse!$AY$84:$AY$101) -> 97.78466 | N26: 98 | R26: =B26 -> 0 | S26: =VLOOKUP($B26,$R$3:$X$9,2,FALSE) -> #N/A | T26: =VLOOKUP($B26,$R$3:$X$9,3,FALSE) -> #N/A | U26: =VLOOKUP($B26,$R$3:$X$9,4,FALSE) -> #N/A | V26: =VLOOKUP($B26,$R$3:$X$9,5,FALSE) -> #N/A | W26: =VLOOKUP($B26,$R$3:$X$9,6,FALSE) -> #N/A | X26: =VLOOKUP($B26,$R$3:$X$9,7,FALSE) -> #N/A | Y26: =VLOOKUP($B26,$R$3:$Z$9,8,FALSE) -> #N/A | Z26: =VLOOKUP($B26,$R$3:$Z$9,9,FALSE) -> #N/A
I27: HR- Pils | N27: 98 | R27: =B27 -> 0 | S27: =VLOOKUP($B27,$R$3:$X$9,2,FALSE) -> #N/A | T27: =VLOOKUP($B27,$R$3:$X$9,3,FALSE) -> #N/A | U27: =VLOOKUP($B27,$R$3:$X$9,4,FALSE) -> #N/A | V27: =VLOOKUP($B27,$R$3:$X$9,5,FALSE) -> #N/A | W27: =VLOOKUP($B27,$R$3:$X$9,6,FALSE) -> #N/A | X27: =VLOOKUP($B27,$R$3:$X$9,7,FALSE) -> #N/A | Y27: =VLOOKUP($B27,$R$3:$Z$9,8,FALSE) -> #N/A | Z27: =VLOOKUP($B27,$R$3:$Z$9,9,FALSE) -> #N/A
I28: HR- IPA | N28: 98 | R28: =B28 -> 0 | S28: =VLOOKUP($B28,$R$3:$X$9,2,FALSE) -> #N/A | T28: =VLOOKUP($B28,$R$3:$X$9,3,FALSE) -> #N/A | U28: =VLOOKUP($B28,$R$3:$X$9,4,FALSE) -> #N/A | V28: =VLOOKUP($B28,$R$3:$X$9,5,FALSE) -> #N/A | W28: =VLOOKUP($B28,$R$3:$X$9,6,FALSE) -> #N/A | X28: =VLOOKUP($B28,$R$3:$X$9,7,FALSE) -> #N/A | Y28: =VLOOKUP($B28,$R$3:$Z$9,8,FALSE) -> #N/A | Z28: =VLOOKUP($B28,$R$3:$Z$9,9,FALSE) -> #N/A
I29: HR- APA | N29: 98 | R29: =B29 -> 0 | S29: =VLOOKUP($B29,$R$3:$X$9,2,FALSE) -> #N/A | T29: =VLOOKUP($B29,$R$3:$X$9,3,FALSE) -> #N/A | U29: =VLOOKUP($B29,$R$3:$X$9,4,FALSE) -> #N/A | V29: =VLOOKUP($B29,$R$3:$X$9,5,FALSE) -> #N/A | W29: =VLOOKUP($B29,$R$3:$X$9,6,FALSE) -> #N/A | X29: =VLOOKUP($B29,$R$3:$X$9,7,FALSE) -> #N/A | Y29: =VLOOKUP($B29,$R$3:$Z$9,8,FALSE) -> #N/A | Z29: =VLOOKUP($B29,$R$3:$Z$9,9,FALSE) -> #N/A
K30: =SUM(K20:K29) -> 23 | L30: =((L20*K20)+(L21*K21)+(L22*K22)+(L23*K23)+(L24*K24)+(K27*L27)+(L25*K25)+(L26*K26)+(L29*K29))/(K30) -> 97.984349 | M30: =AVERAGE('[9]Jan30th-31st'!$L$42,'[10]Feb 27th-28th'!$L$45,'[11]Mar 31st'!$L$42,'[12]Apr 30th'!$L$41,'[13]May 29th '!$L$35,'[14]June 30th'!$L$32,[15]July31st!$L$36,'[16]Aug 31st'!$L$32,L30) -> 97.983521 | N30: 98 | R30: =B30 -> 0 | S30: =VLOOKUP($B30,$R$3:$X$9,2,FALSE) -> #N/A | T30: =VLOOKUP($B30,$R$3:$X$9,3,FALSE) -> #N/A | U30: =VLOOKUP($B30,$R$3:$X$9,4,FALSE) -> #N/A | V30: =VLOOKUP($B30,$R$3:$X$9,5,FALSE) -> #N/A | W30: =VLOOKUP($B30,$R$3:$X$9,6,FALSE) -> #N/A | X30: =VLOOKUP($B30,$R$3:$X$9,7,FALSE) -> #N/A | Y30: =VLOOKUP($B30,$R$3:$Z$9,8,FALSE) -> #N/A | Z30: =VLOOKUP($B30,$R$3:$Z$9,9,FALSE) -> #N/A
R31: =B31 -> 0 | S31: =VLOOKUP($B31,$R$3:$X$9,2,FALSE) -> #N/A | T31: =VLOOKUP($B31,$R$3:$X$9,3,FALSE) -> #N/A | U31: =VLOOKUP($B31,$R$3:$X$9,4,FALSE) -> #N/A | V31: =VLOOKUP($B31,$R$3:$X$9,5,FALSE) -> #N/A | W31: =VLOOKUP($B31,$R$3:$X$9,6,FALSE) -> #N/A | X31: =VLOOKUP($B31,$R$3:$X$9,7,FALSE) -> #N/A | Y31: =VLOOKUP($B31,$R$3:$Z$9,8,FALSE) -> #N/A | Z31: =VLOOKUP($B31,$R$3:$Z$9,9,FALSE) -> #N/A
J32: Daily Brewing Plan
J33: Brand | L33: Average Brews per day
J34: CARIB | K34: 4 | L34: MTD | M34: YTD | N34: TARGET
J35: STAG | L35: =AVERAGE('Sept 1st'!K45,'Sept 2nd'!K47,K44) -> 7.6666667 | M35: =AVERAGE('[9]Jan30th-31st'!$L$47,L35,'[10]Feb 26th '!$L$39,'[11]Mar 31st'!$L$47,'[12]Apr 30th'!$L$46,'[13]May 29th '!$L$40,'[14]June 30th'!$L$39,[15]July31st!$L$41,'[16]Aug 31st'!$L$37) -> 6.5896411 | N35: 9.2
J36: GUINN
J37: VITAMALT
J38: STARMALT | K38: 3
J39: MACKESON
J40: HURRICANE REEF- IPA
...

Sheet Sept 4th
S1: P.G. | U1: Hot Time | W1: Process Time | Y1: Cooling Time
B2: Brewing Department Daily Process Loss Report | S2: Lower | T2: Upper | U2: Lower | V2: Upper | W2: Lower | X2: Upper | Y2: Lower | Z2: Upper
R3: CARIB | S3: 11.6 | T3: 12 | U3: 0 | V3: 0.11805556 | W3: 0.22569444 | X3: 0.26388889 | Y3: 0 | Z3: 60 | AB3: HR- PISNER
