Workbook

Sheet Entries September 2026
B1: ENTRIES FOR DAILY CONS. MONITOR | O1: =B1 -> ENTRIES FOR DAILY CONS. MONITOR
O2: Service 227.3 cubic meters (2273 Hls)Filtered 189.3 cubic meters(1893 Hls)
D3: FUEL | J3: ELECT. | L3: CO2 | O3: WATER | AG3: CO2 Scrubber (m3) | AH3: Supply to Washdown Area (m3) | AI3: Supply to RUs (m3) | AJ3: Steam Mass Flow Meter | AL3: CO2 TANKS' READING
B4: Boilers tot. | C4: Boiler 1. AUTO FLAME CONTROL | D4: Gen. meter | E4: Tank level | F4: Boiler 1 | G4: Boiler 2 | H4: Gen | I4: Meter1 | J4: Meter 2 | K4: Gen Meter | L4: Consumption (BBT SECTION) (kg) | M4: Consumption (Totalizer Flowmeter) | N4: Consumption (Filler) (kg) | O4: Nawasa Meter (m3) | P4: Annandale Supply (m3) | Q4: Service Supply to Plant (m3) | R4: Cellars/Filtration (m3) | S4: Brewhouse Meter (m3) | T4: Cellars/Process Areas (m3) | U4: Pasteuriser (m3) | V4: Water Plant-Nawasa Annadale (m3) | W4: Water Plant-Well # 1 (m3) | X4: CIP Process | Y4: Bottle Washer | Z4: Boiler | AA4: Permeate #1 | AB4: Permeate #2 | AC4: Bottle Filler (m3) | AD4: RO # 1 Totaliser (m3) | AE4: RO # 2 Totaliser (m3) | AF4: Recovered Water (m3) | AL4: Tank "C" | AM4: Tank "A" | AN4: Tank "B" | AO4: Mobile Tanker
A5: DATE | B5: (liters) | C5: (liters) | D5: (Imp. gals) | E5: (inches) | F5: Hrs | G5: Hrs | H5: Hrs. | I5: (Kwhr) | J5: (Kwhr) | K5: (Kwhr) | M5: (kg) | X5: (m3) | Y5: (m3) | Z5: (m3) | AL5: inH2O | AM5: (Kg.) | AN5: (Kg.) | AO5: (pounds)
A6: 1 | B6: 8451450 | C6: 1598841.8 | E6: 64 | F6: 10809.2 | G6: 68225 | I6: 1690601 | K6: 468000 | L6: 75099.65 | M6: 591678.5 | N6: 80405.01 | O6: 248483 | P6: 81270 | Q6: 984412 | S6: 94074 | U6: 472 | V6: 1361581 | X6: 48114 | Y6: 68647 | Z6: 15262 | AA6: 97122 | AC6: 6383 | AD6: 263787 | AJ6: 7372523.6
A7: 2 | B7: 8454730 | C7: 1601851.8 | E7: 64 | F7: 10829.8 | G7: 68225 | I7: 1699336 | K7: 468000 | L7: 76062.98 | M7: 594407.13 | N7: 80699.27 | O7: 248725 | P7: 81511 | Q7: 984729 | S7: 94206 | U7: 475 | V7: 1361862 | X7: 48193 | Y7: 68788 | Z7: 15285 | AA7: 97122 | AC7: 6405 | AD7: 263787 | AJ7: 7372523.6
A8: 3 | B8: 8458270 | C8: 1605358.1 | E8: 64 | F8: 10851.1 | G8: 68225 | I8: 1707774 | K8: 468000 | L8: 76830.15 | M8: 597280.56 | N8: 81006.42 | O8: 248957 | P8: 81781 | Q8: 984967 | S8: 94386 | U8: 476 | V8: 1362117 | X8: 48232 | Y8: 68912 | Z8: 15304 | AA8: 97122 | AC8: 6430 | AD8: 263787 | AJ8: 7372523.6
A9: 4 | B9: 8461730 | C9: 1608732.6 | E9: 64 | F9: 10872.2 | G9: 68225 | I9: 1716468 | K9: 468000 | L9: 77107.94 | M9: 599486.5 | N9: 81273.88 | O9: 249127 | P9: 81969 | Q9: 985226 | S9: 94521 | U9: 479 | V9: 1362314 | X9: 48287 | Y9: 69029 | Z9: 15325 | AA9: 97122 | AC9: 6452 | AD9: 263787 | AJ9: 7372523.6
A10: 5 | B10: 8463770 | C10: 1610468.1 | E10: 64 | F10: 10887.5 | G10: 68225 | I10: 1722147 | K10: 468000 | L10: 77240.23 | M10: 599800.17 | N10: 81317.18 | O10: 249488 | P10: 82064 | Q10: 985418 | S10: 94668 | U10: 480 | V10: 1362414 | X10: 48374 | Y10: 69050 | Z10: 15337 | AA10: 97122 | AC10: 6460 | AD10: 263787 | AJ10: 7372523.6
A11: 6 | B11: 8463770 | C11: 1610468.1 | E11: 64 | F11: 10887.5 | G11: 68225 | I11: 1725532 | K11: 468000 | L11: 77240.23 | M11: 599800.17 | N11: 81317.18 | O11: 249488 | P11: 82064 | Q11: 985418 | S11: 94668 | U11: 480 | V11: 1362414 | X11: 48374 | Y11: 69050 | Z11: 15337 | AA11: 97122 | AC11: 6460 | AD11: 263787 | AJ11: 7372523.6
A12: 7 | B12: 8463770 | C12: 1610468.1 | E12: 64 | F12: 10887.5 | G12: 68225 | I12: 1728329 | K12: 468000 | L12: 77240.23 | M12: 599800.17 | N12: 81317.18 | O12: 249488 | P12: 82064 | Q12: 985454 | S12: 94668 | U12: 480 | V12: 1362414 | X12: 48374 | Y12: 69050 | Z12: 15337 | AA12: 97122 | AC12: 6460 | AD12: 263787 | AJ12: 7372523.6
A13: 8 | B13: 8466080 | C13: 1612773 | E13: 64 | F13: 10906 | G13: 68225 | I13: 1733368 | K13: 468000 | L13: 77353.86 | M13: 600252.75 | N13: 81317.18 | O13: 249557 | P13: 82219 | Q13: 985580 | S13: 94853 | U13: 480 | V13: 1362577 | X13: 48424 | Y13: 69080 | Z13: 15353 | AA13: 97122 | AC13: 6461 | AD13: 263787 | AJ13: 7372560.3
A14: 9 | B14: 8469430 | C14: 1615652.8 | E14: 64 | F14: 10926.8 | G14: 68225 | I14: 1740022 | K14: 468000 | L14: 77579.32 | M14: 601691.56 | N14: 81459.57 | O14: 249784 | P14: 82357 | Q14: 985799 | S14: 94968 | U14: 498 | V14: 1362721 | X14: 48451 | Y14: 69164 | Z14: 15386 | AA14: 97122 | AC14: 6476 | AD14: 263787 | AJ14: 7372742.3
A15: 10 | B15: 8473280 | C15: 1619466.3 | E15: 64 | F15: 10947.3 | G15: 68225 | I15: 1748396 | K15: 468000 | L15: 78014.52 | M15: 603510.36 | N15: 81682.48 | O15: 250033 | P15: 82595 | Q15: 986009 | S15: 95164 | U15: 500 | V15: 1362952 | X15: 48487 | Y15: 69265 | Z15: 15413 | AA15: 97122 | AC15: 6492 | AD15: 263787 | AJ15: 7372742.3
A16: 11 | B16: 8476240 | C16: 1622183.7 | E16: 64 | F16: 10969.9 | G16: 68225 | I16: 1754904 | K16: 468000 | L16: 78552.14 | M16: 605507.13 | N16: 81901.91 | O16: 250114 | P16: 82855 | Q16: 986195 | S16: 95268 | U16: 506 | V16: 1363258 | X16: 48504 | Y16: 69356 | Z16: 15431 | AA16: 97122 | AC16: 6508 | AD16: 263787 | AJ16: 7372742.3
A17: 12 | B17: 8479070 | C17: 1624864.1 | E17: 64 | F17: 10988 | G17: 68225 | I17: 1761592 | K17: 468000 | L17: 79300.41 | M17: 607085.1 | N17: 82065.23 | O17: 250167 | P17: 83104 | Q17: 986368 | S17: 95409 | U17: 508 | V17: 1363506 | X17: 48533 | Y17: 69425 | Z17: 15448 | AA17: 97122 | AC17: 6521 | AD17: 263787 | AJ17: 7372742.3
... A33: 28 | B33: 8511380 | C33: 1654716.8 | E33: 64 | F33: 11198.7 | G33: 68225 | I33: 1857893 | K33: 468000 | L33: 85114.1 | M33: 626088.9 | N33: 84125.63 | O33: 252574 | P33: 85125 | Q33: 988880 | S33: 96713 | U33: 533 | V33: 1365415 | X33: 48987 | Y33: 70503 | Z33: 15645 | AA33: 97122 | AC33: 6703 | AD33: 263787 | AJ33: 7383496
A34: 29
A35: 30
A36: 31
A37: 1

Sheet Utility Analysis September 2026
J2: GRENADA BREWERIES LIMITED
J3: UTILITY ANALYSIS
A5: MONTH: | I5: 39295
A7: DATE | D7: ELECTRICITY GRENLEC | E7: Solar System CARIB | F7: % (Solar/Total Usage) | G7: CARIB GENSET | H7: ELECTRICITY TOTAL | I7: WATER | J7: FUEL | K7: CO2 | L7: PRODUCTION - HL | Q7: UTILITY RATIOS
B8: METER 1 | C8: METER 2 | Q8: Elect | R8: Water | S8: Fuel | T8: CO2
G9: USAGE (kwh) | H9: USAGE (kwh) | I9: USAGE (Hl) | J9: USAGE (l) | K9: USAGE (Kg.) | L9: BREWED | M9: BOTTLED | N9: KEGS | O9: OTHER | P9: TOTAL | Q9: KWH/Hl | R9: Hl/hl | S9: Litres/hl | T9: kg./Hl
A10: 1 | B10: =IF('Entries September 2026'!I7<'Entries September 2026'!I6,"0",(IF('Entries September 2026'!I7>='Entries September 2026'!I6,'Entries September 2026'!I7-'Entries September 2026'!I6,(999999-'Entries September 2026'!I6)+'Entries September 2026'!I7+1))) -> 8735 | C10: =IF('Entries September 2026'!J7<='Entries September 2026'!J6,"0",IF('Entries September 2026'!J7>='Entries September 2026'!J6,'Entries September 2026'!J7-'Entries September 2026'!J6,(999999-'Entries September 2026'!J6)+'Entries September 2026'!J7+1)) -> 0 | D10: =B10+C10 -> 8735 | E10: 1374.6 | F10: =IF((E10+D10)=0,"0",E10/(D10+E10)) -> 0.13596977 | G10: =IF('Entries September 2026'!K7<'Entries September 2026'!K6,"0",IF('Entries September 2026'!K7>='Entries September 2026'!K6,'Entries September 2026'!K7-'Entries September 2026'!K6,(999999-'Entries September 2026'!K6)+'Entries September 2026'!K7+1)) -> 0 | H10: =D10+G10+E10 -> 10109.6 | I10: ='Water '!Z7*10 -> 4830 | J10: =IF('Entries September 2026'!B7-'Entries September 2026'!B6<1,"0",'Entries September 2026'!B7-'Entries September 2026'!B6) -> 3280 | K10: ='CO2'!E7 -> 2700 | L10: =+'PROD.FIG. '!F5 -> 0 | M10: =+'PROD.FIG. '!C5 -> 0 | N10: =+'PROD.FIG. '!D5 -> 0 | O10: =+'PROD.FIG. '!E5 -> 0 | P10: {=TRANSPOSE('Daily KPIs'!B9:AF9)} -> 493.416 | Q10: =IF(P10=0,0,H10/P10) -> 20.488999 | R10: =IF(Q10=0,0,I10/P10) -> 9.7889002 | S10: =IF(R10=0,0,J10/P10) -> 6.6475347 | T10: =IF(S10=0,0,K10/P10) -> 5.472056
A11: 2 | B11: =IF('Entries September 2026'!I8<'Entries September 2026'!I7,"0",(IF('Entries September 2026'!I8>='Entries September 2026'!I7,'Entries September 2026'!I8-'Entries September 2026'!I7,(999999-'Entries September 2026'!I7)+'Entries September 2026'!I8+1))) -> 8438 | C11: =IF('Entries September 2026'!J8<='Entries September 2026'!J7,"0",IF('Entries September 2026'!J8>='Entries September 2026'!J7,'Entries September 2026'!J8-'Entries September 2026'!J7,(999999-'Entries September 2026'!J7)+'Entries September 2026'!J8+1)) -> 0 | D11: =B11+C11 -> 8438 | E11: 1635.3 | F11: =IF((E11+D11)=0,"0",E11/(D11+E11)) -> 0.16234005 | G11: =IF('Entries September 2026'!K8<'Entries September 2026'!K7,"0",IF('Entries September 2026'!K8>='Entries September 2026'!K7,'Entries September 2026'!K8-'Entries September 2026'!K7,(999999-'Entries September 2026'!K7)+'Entries September 2026'!K8+1)) -> 0 | H11: =D11+G11+E11 -> 10073.3 | I11: ='Water '!Z8*10 -> 5020 | J11: =IF('Entries September 2026'!B8-'Entries September 2026'!B7<1,"0",'Entries September 2026'!B8-'Entries September 2026'!B7) -> 3540 | K11: ='CO2'!E8 -> 2900 | L11: =+'PROD.FIG. '!F6 -> 0 | M11: =+'PROD.FIG. '!C6 -> 0 | N11: =+'PROD.FIG. '!D6 -> 0 | O11: =+'PROD.FIG. '!E6 -> 0 | P11: 519.42 | Q11: =IF(P11=0,0,H11/P11) -> 19.393362 | R11: =IF(Q11=0,0,I11/P11) -> 9.6646259 | S11: =IF(R11=0,0,J11/P11) -> 6.815294 | T11: =IF(S11=0,0,K11/P11) -> 5.5831504
A12: 3 | B12: =IF('Entries September 2026'!I9<'Entries September 2026'!I8,"0",(IF('Entries September 2026'!I9>='Entries September 2026'!I8,'Entries September 2026'!I9-'Entries September 2026'!I8,(999999-'Entries September 2026'!I8)+'Entries September 2026'!I9+1))) -> 8694 | C12: =IF('Entries September 2026'!J9<='Entries September 2026'!J8,"0",IF('Entries September 2026'!J9>='Entries September 2026'!J8,'Entries September 2026'!J9-'Entries September 2026'!J8,(999999-'Entries September 2026'!J8)+'Entries September 2026'!J9+1)) -> 0 | D12: =B12+C12 -> 8694 | E12: 1611.6 | F12: =IF((E12+D12)=0,"0",E12/(D12+E12)) -> 0.156381 | G12: =IF('Entries September 2026'!K9<'Entries September 2026'!K8,"0",IF('Entries September 2026'!K9>='Entries September 2026'!K8,'Entries September 2026'!K9-'Entries September 2026'!K8,(999999-'Entries September 2026'!K8)+'Entries September 2026'!K9+1)) -> 0 | H12: =D12+G12+E12 -> 10305.6 | I12: ='Water '!Z9*10 -> 3580 | J12: =IF('Entries September 2026'!B9-'Entries September 2026'!B8<1,"0",'Entries September 2026'!B9-'Entries September 2026'!B8) -> 3460 | K12: ='CO2'!E9 -> 2100 | L12: =+'PROD.FIG. '!F7 -> 0 | M12: =+'PROD.FIG. '!C7 -> 0 | N12: =+'PROD.FIG. '!D7 -> 0 | O12: =+'PROD.FIG. '!E7 -> 0 | P12: 447.678 | Q12: =IF(P12=0,0,H12/P12) -> 23.020117 | R12: =IF(Q12=0,0,I12/P12) -> 7.9968191 | S12: =IF(R12=0,0,J12/P12) -> 7.7287693 | T12: =IF(S12=0,0,K12/P12) -> 4.6908716
A13: 4 | B13: =IF('Entries September 2026'!I10<'Entries September 2026'!I9,"0",(IF('Entries September 2026'!I10>='Entries September 2026'!I9,'Entries September 2026'!I10-'Entries September 2026'!I9,(999999-'Entries September 2026'!I9)+'Entries September 2026'!I10+1))) -> 5679 | C13: =IF('Entries September 2026'!J10<='Entries September 2026'!J9,"0",IF('Entries September 2026'!J10>='Entries September 2026'!J9,'Entries September 2026'!J10-'Entries September 2026'!J9,(999999-'Entries September 2026'!J9)+'Entries September 2026'!J10+1)) -> 0 | D13: =B13+C13 -> 5679 | E13: 1542 | F13: =IF((E13+D13)=0,"0",E13/(D13+E13)) -> 0.21354383 | G13: =IF('Entries September 2026'!K10<'Entries September 2026'!K9,"0",IF('Entries September 2026'!K10>='Entries September 2026'!K9,'Entries September 2026'!K10-'Entries September 2026'!K9,(999999-'Entries September 2026'!K9)+'Entries September 2026'!K10+1)) -> 0 | H13: =D13+G13+E13 -> 7221 | I13: ='Water '!Z10*10 -> 4560 | J13: =IF('Entries September 2026'!B10-'Entries September 2026'!B9<1,"0",'Entries September 2026'!B10-'Entries September 2026'!B9) -> 2040 | K13: ='CO2'!E10 -> 1100 | L13: =+'PROD.FIG. '!F8 -> 0 | M13: =+'PROD.FIG. '!C8 -> 0 | N13: =+'PROD.FIG. '!D8 -> 0 | O13: =+'PROD.FIG. '!E8 -> 0 | P13: 96.294 | Q13: =IF(P13=0,0,H13/P13) -> 74.989096 | R13: =IF(Q13=0,0,I13/P13) -> 47.354975 | S13: =IF(R13=0,0,J13/P13) -> 21.185121 | T13: =IF(S13=0,0,K13/P13) -> 11.423349
A14: 5 | B14: =IF('Entries September 2026'!I11<'Entries September 2026'!I10,"0",(IF('Entries September 2026'!I11>='Entries September 2026'!I10,'Entries September 2026'!I11-'Entries September 2026'!I10,(999999-'Entries September 2026'!I10)+'Entries September 2026'!I11+1))) -> 3385 | C14: =IF('Entries September 2026'!J11<='Entries September 2026'!J10,"0",IF('Entries September 2026'!J11>='Entries September 2026'!J10,'Entries September 2026'!J11-'Entries September 2026'!J10,(999999-'Entries September 2026'!J10)+'Entries September 2026'!J11+1)) -> 0 | D14: =B14+C14 -> 3385 | E14: 1552.4 | F14: =IF((E14+D14)=0,"0",E14/(D14+E14)) -> 0.31441649 | G14: =IF('Entries September 2026'!K11<'Entries September 2026'!K10,"0",IF('Entries September 2026'!K11>='Entries September 2026'!K10,'Entries September 2026'!K11-'Entries September 2026'!K10,(999999-'Entries September 2026'!K10)+'Entries September 2026'!K11+1)) -> 0 | H14: =D14+G14+E14 -> 4937.4 | I14: ='Water '!Z11*10 -> 0 | J14: =IF('Entries September 2026'!B11-'Entries September 2026'!B10<1,"0",'Entries September 2026'!B11-'Entries September 2026'!B10) -> 0 | K14: ='CO2'!E11 -> -2400 | L14: =+'PROD.FIG. '!F9 -> 0 | M14: =+'PROD.FIG. '!C9 -> 0 | N14: =+'PROD.FIG. '!D9 -> 0 | O14: =+'PROD.FIG. '!E9 -> 0 | P14: 0 | Q14: =IF(P14=0,0,H14/P14) -> 0 | R14: =IF(Q14=0,0,I14/P14) -> 0 | S14: =IF(R14=0,0,J14/P14) -> 0 | T14: =IF(S14=0,0,K14/P14) -> 0
A15: 6 | B15: =IF('Entries September 2026'!I12<'Entries September 2026'!I11,"0",(IF('Entries September 2026'!I12>='Entries September 2026'!I11,'Entries September 2026'!I12-'Entries September 2026'!I11,(999999-'Entries September 2026'!I11)+'Entries September 2026'!I12+1))) -> 2797 | C15: =IF('Entries September 2026'!J12<='Entries September 2026'!J11,"0",IF('Entries September 2026'!J12>='Entries September 2026'!J11,'Entries September 2026'!J12-'Entries September 2026'!J11,(999999-'Entries September 2026'!J11)+'Entries September 2026'!J12+1)) -> 0 | D15: =B15+C15 -> 2797 | E15: 1574.3 | F15: =IF((E15+D15)=0,"0",E15/(D15+E15)) -> 0.36014458 | G15: =IF('Entries September 2026'!K12<'Entries September 2026'!K11,"0",IF('Entries September 2026'!K12>='Entries September 2026'!K11,'Entries September 2026'!K12-'Entries September 2026'!K11,(999999-'Entries September 2026'!K11)+'Entries September 2026'!K12+1)) -> 0 | H15: =D15+G15+E15 -> 4371.3 | I15: ='Water '!Z12*10 -> 0 | J15: =IF('Entries September 2026'!B12-'Entries September 2026'!B11<1,"0",'Entries September 2026'!B12-'Entries September 2026'!B11) -> 0 | K15: ='CO2'!E12 -> 0 | L15: =+'PROD.FIG. '!F10 -> 0 | M15: =+'PROD.FIG. '!C10 -> 0 | N15: =+'PROD.FIG. '!D10 -> 0 | O15: =+'PROD.FIG. '!E10 -> 0 | P15: 0 | Q15: =IF(P15=0,0,H15/P15) -> 0 | R15: =IF(Q15=0,0,I15/P15) -> 0 | S15: =IF(R15=0,0,J15/P15) -> 0 | T15: =IF(S15=0,0,K15/P15) -> 0
A16: 7 | B16: =IF('Entries September 2026'!I13<'Entries September 2026'!I12,"0",(IF('Entries September 2026'!I13>='Entries September 2026'!I12,'Entries September 2026'!I13-'Entries September 2026'!I12,(999999-'Entries September 2026'!I12)+'Entries September 2026'!I13+1))) -> 5039 | C16: =IF('Entries September 2026'!J13<='Entries September 2026'!J12,"0",IF('Entries September 2026'!J13>='Entries September 2026'!J12,'Entries September 2026'!J13-'Entries September 2026'!J12,(999999-'Entries September 2026'!J12)+'Entries September 2026'!J13+1)) -> 0 | D16: =B16+C16 -> 5039 | E16: 1506.9 | F16: =IF((E16+D16)=0,"0",E16/(D16+E16)) -> 0.23020517 | G16: =IF('Entries September 2026'!K13<'Entries September 2026'!K12,"0",IF('Entries September 2026'!K13>='Entries September 2026'!K12,'Entries September 2026'!K13-'Entries September 2026'!K12,(999999-'Entries September 2026'!K12)+'Entries September 2026'!K13+1)) -> 0 | H16: =D16+G16+E16 -> 6545.9 | I16: ='Water '!Z13*10 -> 2240 | J16: =IF('Entries September 2026'!B13-'Entries September 2026'!B12<1,"0",'Entries September 2026'!B13-'Entries September 2026'!B12) -> 2310 | K16: ='CO2'!E13 -> 700 | L16: =+'PROD.FIG. '!F11 -> 0 | M16: =+'PROD.FIG. '!C11 -> 0 | N16: =+'PROD.FIG. '!D11 -> 0 | O16: =+'PROD.FIG. '!E11 -> 0 | P16: 0 | Q16: =IF(P16=0,0,H16/P16) -> 0 | R16: =IF(Q16=0,0,I16/P16) -> 0 | S16: =IF(R16=0,0,J16/P16) -> 0 | T16: =IF(S16=0,0,K16/P16) -> 0
A17: 8 | B17: =IF('Entries September 2026'!I14<'Entries September 2026'!I13,"0",(IF('Entries September 2026'!I14>='Entries September 2026'!I13,'Entries September 2026'!I14-'Entries September 2026'!I13,(999999-'Entries September 2026'!I13)+'Entries September 2026'!I14+1))) -> 6654 | C17: =IF('Entries September 2026'!J14<='Entries September 2026'!J13,"0",IF('Entries September 2026'!J14>='Entries September 2026'!J13,'Entries September 2026'!J14-'Entries September 2026'!J13,(999999-'Entries September 2026'!J13)+'Entries September 2026'!J14+1)) -> 0 | D17: =B17+C17 -> 6654 | E17: 1558.3 | F17: =IF((E17+D17)=0,"0",E17/(D17+E17)) -> 0.18975196 | G17: =IF('Entries September 2026'!K14<'Entries September 2026'!K13,"0",IF('Entries September 2026'!K14>='Entries September 2026'!K13,'Entries September 2026'!K14-'Entries September 2026'!K13,(999999-'Entries September 2026'!K13)+'Entries September 2026'!K14+1)) -> 0 | H17: =D17+G17+E17 -> 8212.3 | I17: ='Water '!Z14*10 -> 3650 | J17: =IF('Entries September 2026'!B14-'Entries September 2026'!B13<1,"0",'Entries September 2026'!B14-'Entries September 2026'!B13) -> 3350 | K17: ='CO2'!E14 -> 1900 | L17: =+'PROD.FIG. '!F12 -> 0 | M17: =+'PROD.FIG. '!C12 -> 0 | N17: =+'PROD.FIG. '!D12 -> 0 | O17: =+'PROD.FIG. '!E12 -> 0 | P17: 261.492 | Q17: =IF(P17=0,0,H17/P17) -> 31.40555 | R17: =IF(Q17=0,0,I17/P17) -> 13.958362 | S17: =IF(R17=0,0,J17/P17) -> 12.811099 | T17: =IF(S17=0,0,K17/P17) -> 7.2659967
A18: 9 | B18: =IF('Entries September 2026'!I15<'Entries September 2026'!I14,"0",(IF('Entries September 2026'!I15>='Entries September 2026'!I14,'Entries September 2026'!I15-'Entries September 2026'!I14,(999999-'Entries September 2026'!I14)+'Entries September 2026'!I15+1))) -> 8374 | C18: =IF('Entries September 2026'!J15<='Entries September 2026'!J14,"0",IF('Entries September 2026'!J15>='Entries September 2026'!J14,'Entries September 2026'!J15-'Entries September 2026'!J14,(999999-'Entries September 2026'!J14)+'Entries September 2026'!J15+1)) -> 0 | D18: =B18+C18 -> 8374 | E18: 1042.7 | F18: =IF((E18+D18)=0,"0",E18/(D18+E18)) -> 0.11072881 | G18: =IF('Entries September 2026'!K15<'Entries September 2026'!K14,"0",IF('Entries September 2026'!K15>='Entries September 2026'!K14,'Entries September 2026'!K15-'Entries September 2026'!K14,(999999-'Entries September 2026'!K14)+'Entries September 2026'!K15+1)) -> 0 | H18: =D18+G18+E18 -> 9416.7 | I18: ='Water '!Z15*10 -> 4870 | J18: =IF('Entries September 2026'!B15-'Entries September 2026'!B14<1,"0",'Entries September 2026'!B15-'Entries September 2026'!B14) -> 3850 | K18: ='CO2'!E15 -> 1900 | L18: =+'PROD.FIG. '!F13 -> 0 | M18: =+'PROD.FIG. '!C13 -> 0 | N18: =+'PROD.FIG. '!D13 -> 0 | O18: =+'PROD.FIG. '!E13 -> 0 | P18: 401.61 | Q18: =IF(P18=0,0,H18/P18) -> 23.447374 | R18: =IF(Q18=0,0,I18/P18) -> 12.126192 | S18: =IF(R18=0,0,J18/P18) -> 9.5864147 | T18: =IF(S18=0,0,K18/P18) -> 4.7309579
A19: 10 | B19: =IF('Entries September 2026'!I16<'Entries September 2026'!I15,"0",(IF('Entries September 2026'!I16>='Entries September 2026'!I15,'Entries September 2026'!I16-'Entries September 2026'!I15,(999999-'Entries September 2026'!I15)+'Entries September 2026'!I16+1))) -> 6508 | C19: =IF('Entries September 2026'!J16<='Entries September 2026'!J15,"0",IF('Entries September 2026'!J16>='Entries September 2026'!J15,'Entries September 2026'!J16-'Entries September 2026'!J15,(999999-'Entries September 2026'!J15)+'Entries September 2026'!J16+1)) -> 0 | D19: =B19+C19 -> 6508 | E19: 539.6 | F19: =IF((E19+D19)=0,"0",E19/(D19+E19)) -> 0.076565072 | G19: =IF('Entries September 2026'!K16<'Entries September 2026'!K15,"0",IF('Entries September 2026'!K16>='Entries September 2026'!K15,'Entries September 2026'!K16-'Entries September 2026'!K15,(999999-'Entries September 2026'!K15)+'Entries September 2026'!K16+1)) -> 0 | H19: =D19+G19+E19 -> 7047.6 | I19: ='Water '!Z16*10 -> 3410 | J19: =IF('Entries September 2026'!B16-'Entries September 2026'!B15<1,"0",'Entries September 2026'!B16-'Entries September 2026'!B15) -> 2960 | K19: ='CO2'!E16 -> 2500 | L19: =+'PROD.FIG. '!F14 -> 0 | M19: =+'PROD.FIG. '!C14 -> 0 | N19: =+'PROD.FIG. '!D14 -> 0 | O19: =+'PROD.FIG. '!E14 -> 0 | P19: 402.864 | Q19: =IF(P19=0,0,H19/P19) -> 17.493745 | R19: =IF(Q19=0,0,I19/P19) -> 8.4643949 | S19: =IF(R19=0,0,J19/P19) -> 7.3473927 | T19: =IF(S19=0,0,K19/P19) -> 6.2055681
A20: 11 | B20: =IF('Entries September 2026'!I17<'Entries September 2026'!I16,"0",(IF('Entries September 2026'!I17>='Entries September 2026'!I16,'Entries September 2026'!I17-'Entries September 2026'!I16,(999999-'Entries September 2026'!I16)+'Entries September 2026'!I17+1))) -> 6688 | C20: =IF('Entries September 2026'!J17<='Entries September 2026'!J16,"0",IF('Entries September 2026'!J17>='Entries September 2026'!J16,'Entries September 2026'!J17-'Entries September 2026'!J16,(999999-'Entries September 2026'!J16)+'Entries September 2026'!J17+1)) -> 0 | D20: =B20+C20 -> 6688 | E20: 1365.4 | F20: =IF((E20+D20)=0,"0",E20/(D20+E20)) -> 0.1695433 | G20: =IF('Entries September 2026'!K17<'Entries September 2026'!K16,"0",IF('Entries September 2026'!K17>='Entries September 2026'!K16,'Entries September 2026'!K17-'Entries September 2026'!K16,(999999-'Entries September 2026'!K16)+'Entries September 2026'!K17+1)) -> 0 | H20: =D20+G20+E20 -> 8053.4 | I20: ='Water '!Z17*10 -> 3020 | J20: =IF('Entries September 2026'!B17-'Entries September 2026'!B16<1,"0",'Entries September 2026'!B17-'Entries September 2026'!B16) -> 2830 | K20: ='CO2'!E17 -> 1600 | L20: =+'PROD.FIG. '!F15 -> 0 | M20: =+'PROD.FIG. '!C15 -> 0 | N20: =+'PROD.FIG. '!D15 -> 0 | O20: =+'PROD.FIG. '!E15 -> 0 | P20: 266.244 | Q20: =IF(P20=0,0,H20/P20) -> 30.248193 | R20: =IF(Q20=0,0,I20/P20) -> 11.342979 | S20: =IF(R20=0,0,J20/P20) -> 10.629348 | T20: =IF(S20=0,0,K20/P20) -> 6.0095251
A21: 12 | B21: =IF('Entries September 2026'!I18<'Entries September 2026'!I17,"0",(IF('Entries September 2026'!I18>='Entries September 2026'!I17,'Entries September 2026'!I18-'Entries September 2026'!I17,(999999-'Entries September 2026'!I17)+'Entries September 2026'!I18+1))) -> 3127 | C21: =IF('Entries September 2026'!J18<='Entries September 2026'!J17,"0",IF('Entries September 2026'!J18>='Entries September 2026'!J17,'Entries September 2026'!J18-'Entries September 2026'!J17,(999999-'Entries September 2026'!J17)+'Entries September 2026'!J18+1)) -> 0 | D21: =B21+C21 -> 3127 | E21: 1012.4 | F21: =IF((E21+D21)=0,"0",E21/(D21+E21)) -> 0.24457651 | G21: =IF('Entries September 2026'!K18<'Entries September 2026'!K17,"0",IF('Entries September 2026'!K18>='Entries September 2026'!K17,'Entries September 2026'!K18-'Entries September 2026'!K17,(999999-'Entries September 2026'!K17)+'Entries September 2026'!K18+1)) -> 0 | H21: =D21+G21+E21 -> 4139.4 | I21: ='Water '!Z18*10 -> 1660 | J21: =IF('Entries September 2026'!B18-'Entries September 2026'!B17<1,"0",'Entries September 2026'!B18-'Entries September 2026'!B17) -> 230 | K21: ='CO2'!E18 -> 0 | L21: =+'PROD.FIG. '!F16 -> 0 | M21: =+'PROD.FIG. '!C16 -> 0 | N21: =+'PROD.FIG. '!D16 -> 0 | O21: =+'PROD.FIG. '!E16 -> 0 | P21: 0 | Q21: =IF(P21=0,0,H21/P21) -> 0 | R21: =IF(Q21=0,0,I21/P21) -> 0 | S21: =IF(R21=0,0,J21/P21) -> 0 | T21: =IF(S21=0,0,K21/P21) -> 0
A22: 13 | B22: =IF('Entries September 2026'!I19<'Entries September 2026'!I18,"0",(IF('Entries September 2026'!I19>='Entries September 2026'!I18,'Entries September 2026'!I19-'Entries September 2026'!I18,(999999-'Entries September 2026'!I18)+'Entries September 2026'!I19+1))) -> 4203 | C22: =IF('Entries September 2026'!J19<='Entries September 2026'!J18,"0",IF('Entries September 2026'!J19>='Entries September 2026'!J18,'Entries September 2026'!J19-'Entries September 2026'!J18,(999999-'Entries September 2026'!J18)+'Entries September 2026'!J19+1)) -> 0 | D22: =B22+C22 -> 4203 | E22: 439 | F22: =IF((E22+D22)=0,"0",E22/(D22+E22)) -> 0.094571305 | G22: =IF('Entries September 2026'!K19<'Entries September 2026'!K18,"0",IF('Entries September 2026'!K19>='Entries September 2026'!K18,'Entries September 2026'!K19-'Entries September 2026'!K18,(999999-'Entries September 2026'!K18)+'Entries September 2026'!K19+1)) -> 0 | H22: =D22+G22+E22 -> 4642 | I22: ='Water '!Z19*10 -> 0 | J22: =IF('Entries September 2026'!B19-'Entries September 2026'!B18<1,"0",'Entries September 2026'!B19-'Entries September 2026'!B18) -> 850 | K22: ='CO2'!E19 -> 0 | L22: =+'PROD.FIG. '!F17 -> 0 | M22: =+'PROD.FIG. '!C17 -> 0 | N22: =+'PROD.FIG. '!D17 -> 0 | O22: =+'PROD.FIG. '!E17 -> 0 | P22: 0 | Q22: =IF(P22=0,0,H22/P22) -> 0 | R22: =IF(Q22=0,0,I22/P22) -> 0 | S22: =IF(R22=0,0,J22/P22) -> 0 | T22: =IF(S22=0,0,K22/P22) -> 0
... A37: 28 | B37: =IF('Entries September 2026'!I34<'Entries September 2026'!I33,"0",(IF('Entries September 2026'!I34>='Entries September 2026'!I33,'Entries September 2026'!I34-'Entries September 2026'!I33,(999999-'Entries September 2026'!I33)+'Entries September 2026'!I34+1))) -> 0 | C37: =IF('Entries September 2026'!J34<='Entries September 2026'!J33,"0",IF('Entries September 2026'!J34>='Entries September 2026'!J33,'Entries September 2026'!J34-'Entries September 2026'!J33,(999999-'Entries September 2026'!J33)+'Entries September 2026'!J34+1)) -> 0 | D37: =B37+C37 -> 0 | E37: 1396.2 | F37: =IF((E37+D37)=0,"0",E37/(D37+E37)) -> 1 | G37: =IF('Entries September 2026'!K34<'Entries September 2026'!K33,"0",IF('Entries September 2026'!K34>='Entries September 2026'!K33,'Entries September 2026'!K34-'Entries September 2026'!K33,(999999-'Entries September 2026'!K33)+'Entries September 2026'!K34+1)) -> 0 | H37: =D37+G37+E37 -> 1396.2 | I37: ='Water '!Z34*10 -> 0 | J37: =IF('Entries September 2026'!B34-'Entries September 2026'!B33<1,"0",'Entries September 2026'!B34-'Entries September 2026'!B33) -> 0 | K37: ='CO2'!E34 -> 1300 | L37: =+'PROD.FIG. '!F32 -> 0 | M37: =+'PROD.FIG. '!C32 -> 0 | N37: =+'PROD.FIG. '!D32 -> 0 | O37: =+'PROD.FIG. '!E32 -> 0 | P37: 258.72 | Q37: =IF(P37=0,0,H37/P37) -> 5.3965677 | R37: =IF(Q37=0,0,I37/P37) -> 0 | S37: =IF(R37=0,0,J37/P37) -> 0 | T37: =IF(S37=0,0,K37/P37) -> 0
A38: 29 | B38: =IF('Entries September 2026'!I35<'Entries September 2026'!I34,"0",(IF('Entries September 2026'!I35>='Entries September 2026'!I34,'Entries September 2026'!I35-'Entries September 2026'!I34,(999999-'Entries September 2026'!I34)+'Entries September 2026'!I35+1))) -> 0 | C38: =IF('Entries September 2026'!J35<='Entries September 2026'!J34,"0",IF('Entries September 2026'!J35>='Entries September 2026'!J34,'Entries September 2026'!J35-'Entries September 2026'!J34,(999999-'Entries September 2026'!J34)+'Entries September 2026'!J35+1)) -> 0 | D38: =B38+C38 -> 0 | F38: =IF((E38+D38)=0,"0",E38/(D38+E38)) -> 0 | G38: =IF('Entries September 2026'!K35<'Entries September 2026'!K34,"0",IF('Entries September 2026'!K35>='Entries September 2026'!K34,'Entries September 2026'!K35-'Entries September 2026'!K34,(999999-'Entries September 2026'!K34)+'Entries September 2026'!K35+1)) -> 0 | H38: =IF('Entries September 2026'!L35<'Entries September 2026'!L34,"0",IF('Entries September 2026'!L35>='Entries September 2026'!L34,'Entries September 2026'!L35-'Entries September 2026'!L34,(999999-'Entries September 2026'!L34)+'Entries September 2026'!L35+1)) -> 0 | I38: =IF('Entries September 2026'!M35<'Entries September 2026'!M34,"0",IF('Entries September 2026'!M35>='Entries September 2026'!M34,'Entries September 2026'!M35-'Entries September 2026'!M34,(999999-'Entries September 2026'!M34)+'Entries September 2026'!M35+1)) -> 0 | J38: =IF('Entries September 2026'!N35<'Entries September 2026'!N34,"0",IF('Entries September 2026'!N35>='Entries September 2026'!N34,'Entries September 2026'!N35-'Entries September 2026'!N34,(999999-'Entries September 2026'!N34)+'Entries September 2026'!N35+1)) -> 0 | K38: =IF('Entries September 2026'!O35<'Entries September 2026'!O34,"0",IF('Entries September 2026'!O35>='Entries September 2026'!O34,'Entries September 2026'!O35-'Entries September 2026'!O34,(999999-'Entries September 2026'!O34)+'Entries September 2026'!O35+1)) -> 0 | L38: =IF('Entries September 2026'!P35<'Entries September 2026'!P34,"0",IF('Entries September 2026'!P35>='Entries September 2026'!P34,'Entries September 2026'!P35-'Entries September 2026'!P34,(999999-'Entries September 2026'!P34)+'Entries September 2026'!P35+1)) -> 0 | M38: =IF('Entries September 2026'!Q35<'Entries September 2026'!Q34,"0",IF('Entries September 2026'!Q35>='Entries September 2026'!Q34,'Entries September 2026'!Q35-'Entries September 2026'!Q34,(999999-'Entries September 2026'!Q34)+'Entries September 2026'!Q35+1)) -> 0 | N38: =+'PROD.FIG. '!D33 -> 0 | O38: =+'PROD.FIG. '!E33 -> 0 | P38: 0 | Q38: =IF(P38=0,0,H38/P38) -> 0 | R38: =IF(Q38=0,0,I38/P38) -> 0 | S38: =IF(R38=0,0,J38/P38) -> 0 | T38: =IF(S38=0,0,K38/P38) -> 0
A39: 30 | B39: =IF('Entries September 2026'!I36<'Entries September 2026'!I35,"0",(IF('Entries September 2026'!I36>='Entries September 2026'!I35,'Entries September 2026'!I36-'Entries September 2026'!I35,(999999-'Entries September 2026'!I35)+'Entries September 2026'!I36+1))) -> 0 | C39: =IF('Entries September 2026'!J36<='Entries September 2026'!J35,"0",IF('Entries September 2026'!J36>='Entries September 2026'!J35,'Entries September 2026'!J36-'Entries September 2026'!J35,(999999-'Entries September 2026'!J35)+'Entries September 2026'!J36+1)) -> 0 | D39: =B39+C39 -> 0 | F39: =IF((E39+D39)=0,"0",E39/(D39+E39)) -> 0 | G39: =IF('Entries September 2026'!K36<'Entries September 2026'!K35,"0",IF('Entries September 2026'!K36>='Entries September 2026'!K35,'Entries September 2026'!K36-'Entries September 2026'!K35,(999999-'Entries September 2026'!K35)+'Entries September 2026'!K36+1)) -> 0 | H39: =D39+G39+E39 -> 0 | I39: ='Water '!Z36*10 -> 0 | J39: =IF('Entries September 2026'!B36-'Entries September 2026'!B35<1,"0",'Entries September 2026'!B36-'Entries September 2026'!B35) -> 0 | K39: ='CO2'!E36 -> 0 | L39: =+'PROD.FIG. '!F34 -> 0 | M39: =+'PROD.FIG. '!C34 -> 0 | N39: =+'PROD.FIG. '!D34 -> 0 | O39: =+'PROD.FIG. '!E34 -> 0 | P39: 0 | Q39: =IF(P39=0,0,H39/P39) -> 0 | R39: =IF(Q39=0,0,I39/P39) -> 0 | S39: =IF(R39=0,0,J39/P39) -> 0 | T39: =IF(S39=0,0,K39/P39) -> 0
A40: 31 | B40: =IF('Entries September 2026'!I37<'Entries September 2026'!I36,"0",(IF('Entries September 2026'!I37>='Entries September 2026'!I36,'Entries September 2026'!I37-'Entries September 2026'!I36,(999999-'Entries September 2026'!I36)+'Entries September 2026'!I37+1))) -> 0 | C40: =IF('Entries September 2026'!J37<='Entries September 2026'!J36,"0",IF('Entries September 2026'!J37>='Entries September 2026'!J36,'Entries September 2026'!J37-'Entries September 2026'!J36,(999999-'Entries September 2026'!J36)+'Entries September 2026'!J37+1)) -> 0 | D40: =B40+C40 -> 0 | F40: =IF((E40+D40)=0,"0",E40/(D40+E40)) -> 0 | G40: =IF('Entries September 2026'!K37<'Entries September 2026'!K36,"0",IF('Entries September 2026'!K37>='Entries September 2026'!K36,'Entries September 2026'!K37-'Entries September 2026'!K36,(999999-'Entries September 2026'!K36)+'Entries September 2026'!K37+1)) -> 0 | H40: =D40+G40+E40 -> 0 | I40: ='Water '!Z37*10 -> 0 | J40: =IF('Entries September 2026'!B37-'Entries September 2026'!B36<1,"0",'Entries September 2026'!B37-'Entries September 2026'!B36) -> 0 | K40: ='CO2'!E37 -> 0 | P40: 0 | Q40: =IF(P40=0,0,H40/P40) -> 0 | R40: =IF(Q40=0,0,I40/P40) -> 0 | S40: =IF(R40=0,0,J40/P40) -> 0 | T40: =IF(S40=0,0,K40/P40) -> 0
Q41: MTD
D42: Kwhr | G42: Kwhr | H42: Kwhr | I42: Hl | J42: L | K42: kg. | L42: hl | M42: hl | N42: hl | O42: hl | P42: hl | Q42: Elect | R42: Water | S42: Fuel | T42: CO2
A43: Total | D43: =SUM(D10:D40) -> 167292 | E43: =SUM(E10:E40) -> 37573.6 | F43: =IF((E43+D43)=0,"0",E43/(D43+E43)) -> 0.1834061 | G43: =SUM(G10:G40) -> 0 | H43: =SUM(H10:H40) -> 204865.6 | I43: =SUM(I10:I40) -> 79460 | J43: =SUM(J10:J40) -> 59930 | K43: =SUM(K10:K40) -> 35700 | L43: =SUM(L10:L40) -> 0 | M43: =SUM(M10:M40) -> 0 | N43: =SUM(N10:N40) -> 0 | ... P43: =SUM(P10:P40) -> 6666.462 | Q43: KWH/Hl | R43: Hl/hl | S43: Litres/hl | T43: kg./Hl
D44: TOTAL | E44: =D43+E43 -> 204865.6 | Q44: =IF(P43=0,0,H43/P43) -> 30.730783 | R44: =IF(Q44=0,0,I43/P43) -> 11.919366 | S44: =IF(R44=0,0,J43/P43) -> 8.989776 | T44: =IF(S44=0,0,K43/P43) -> 5.3551644

Sheet Sheet2

Sheet Steam Mass Flow 
A3: DATE | B3: Steam Mass Flow Reading
A5: 1 | B5: =IF('Entries September 2026'!AJ7-'Entries September 2026'!AJ6<1,"0",'Entries September 2026'!AJ7-'Entries September 2026'!AJ6) -> 0
A6: 2 | B6: =IF('Entries September 2026'!AJ8-'Entries September 2026'!AJ7<1,"0",'Entries September 2026'!AJ8-'Entries September 2026'!AJ7) -> 0
A7: 3 | B7: =IF('Entries September 2026'!AJ9-'Entries September 2026'!AJ8<1,"0",'Entries September 2026'!AJ9-'Entries September 2026'!AJ8) -> 0
A8: 4 | B8: =IF('Entries September 2026'!AJ10-'Entries September 2026'!AJ9<1,"0",'Entries September 2026'!AJ10-'Entries September 2026'!AJ9) -> 0
A9: 5 | B9: =IF('Entries September 2026'!AJ11-'Entries September 2026'!AJ10<1,"0",'Entries September 2026'!AJ11-'Entries September 2026'!AJ10) -> 0
A10: 6 | B10: =IF('Entries September 2026'!AJ12-'Entries September 2026'!AJ11<1,"0",'Entries September 2026'!AJ12-'Entries September 2026'!AJ11) -> 0
A11: 7 | B11: =IF('Entries September 2026'!AJ13-'Entries September 2026'!AJ12<1,"0",'Entries September 2026'!AJ13-'Entries September 2026'!AJ12) -> 36.736
A12: 8 | B12: =IF('Entries September 2026'!AJ14-'Entries September 2026'!AJ13<1,"0",'Entries September 2026'!AJ14-'Entries September 2026'!AJ13) -> 181.974
A13: 9 | B13: =IF('Entries September 2026'!AJ15-'Entries September 2026'!AJ14<1,"0",'Entries September 2026'!AJ15-'Entries September 2026'!AJ14) -> 0
A14: 10 | B14: =IF('Entries September 2026'!AJ16-'Entries September 2026'!AJ15<1,"0",'Entries September 2026'!AJ16-'Entries September 2026'!AJ15) -> 0
A15: 11 | B15: =IF('Entries September 2026'!AJ17-'Entries September 2026'!AJ16<1,"0",'Entries September 2026'!AJ17-'Entries September 2026'!AJ16) -> 0
A16: 12 | B16: =IF('Entries September 2026'!AJ18-'Entries September 2026'!AJ17<1,"0",'Entries September 2026'!AJ18-'Entries September 2026'!AJ17) -> 0
... A35: 31 | B35: =IF('Entries September 2026'!AJ37-'Entries September 2026'!AJ36<1,"0",'Entries September 2026'!AJ37-'Entries September 2026'!AJ36) -> 0
B36: =SUM(B5:B35) -> 10972.435

Sheet Fuel 
A1: DAILY FUEL CONSUMPTION FOR SEPTEMBER 2026
M2: KPI WITH ORIGINAL METER | N2: KPI WITH AUTO FLAME METER
A4: DATE | B4: Boiler 1 | C4: Boiler 1 | D4: Boiler 1. (AF Control) | E4: Boiler 2 | F4: Boiler 2 | G4: Gen. | H4: Gen | I4: Boiler 1 | J4: Gen. | K4: Daily cons. | L4: Total Prod.(HL) | M4: Fuel(Litres/HL) | N4: Fuel(Litres/HL) | O4: DIFERENCE (LTS)
B5: Cons ( l ) | C5: Hrs | D5: Cons ( l ) | E5: Cons ( l ) | F5: Hrs | G5: Cons ( l ) | H5: Hrs | I5: cons (l/hr) | J5: Cons.(l/hr) | K5: (litres)
A7: 1 | B7: =IF('Entries September 2026'!B7-'Entries September 2026'!B6<1,"0",'Entries September 2026'!B7-'Entries September 2026'!B6) -> 3280 | C7: =IF('Entries September 2026'!F7-'Entries September 2026'!F6<1,"0",'Entries September 2026'!F7-'Entries September 2026'!F6) -> 20.6 | D7: =IF('Entries September 2026'!C7-'Entries September 2026'!C6<1,"0",'Entries September 2026'!C7-'Entries September 2026'!C6) -> 3010 | E7: =IF(F7=0,"0", D7/F7) -> 0 | F7: =IF('Entries September 2026'!G7-'Entries September 2026'!G6<1,"0",'Entries September 2026'!G7-'Entries September 2026'!G6) -> 0 | I7: =IF(C7=0,"0", B7/(C7)) -> 159.2233 | J7: =IF(H7=0,"0", G7/H7) -> 0 | K7: =B7+E7+G7 -> 3280 | L7: {=IF(TRANSPOSE('Daily KPIs'!B9:AF9)=0,"0",TRANSPOSE('Daily KPIs'!B9:AF9))} -> 493.416 | M7: =IF(L7=0,"0",(K7/L7)) -> 6.6475347 | N7: =IF(L7=0,"0",(D7/L7)) -> 6.1003291 | O7: =B7-D7 -> 270
A8: 2 | B8: =IF('Entries September 2026'!B8-'Entries September 2026'!B7<1,"0",'Entries September 2026'!B8-'Entries September 2026'!B7) -> 3540 | C8: =IF('Entries September 2026'!F8-'Entries September 2026'!F7<1,"0",'Entries September 2026'!F8-'Entries September 2026'!F7) -> 21.3 | D8: =IF('Entries September 2026'!C8-'Entries September 2026'!C7<1,"0",'Entries September 2026'!C8-'Entries September 2026'!C7) -> 3506.3 | E8: =IF(F8=0,"0", D8/F8) -> 0 | F8: =IF('Entries September 2026'!G8-'Entries September 2026'!G7<1,"0",'Entries September 2026'!G8-'Entries September 2026'!G7) -> 0 | I8: =IF(C8=0,"0", B8/(C8)) -> 166.19718 | J8: =IF(H8=0,"0", G8/H8) -> 0 | K8: =B8+E8+G8 -> 3540 | L8: 519.42 | M8: =IF(L8=0,"0",(K8/L8)) -> 6.815294 | N8: =IF(L8=0,"0",(D8/L8)) -> 6.7504139 | O8: =B8-D8 -> 33.7
A9: 3 | B9: =IF('Entries September 2026'!B9-'Entries September 2026'!B8<1,"0",'Entries September 2026'!B9-'Entries September 2026'!B8) -> 3460 | C9: =IF('Entries September 2026'!F9-'Entries September 2026'!F8<1,"0",'Entries September 2026'!F9-'Entries September 2026'!F8) -> 21.1 | D9: =IF('Entries September 2026'!C9-'Entries September 2026'!C8<1,"0",'Entries September 2026'!C9-'Entries September 2026'!C8) -> 3374.5 | E9: =IF(F9=0,"0", D9/F9) -> 0 | F9: =IF('Entries September 2026'!G9-'Entries September 2026'!G8<1,"0",'Entries September 2026'!G9-'Entries September 2026'!G8) -> 0 | I9: =IF(C9=0,"0", B9/(C9)) -> 163.98104 | J9: =IF(H9=0,"0", G9/H9) -> 0 | K9: =B9+E9+G9 -> 3460 | L9: 447.678 | M9: =IF(L9=0,"0",(K9/L9)) -> 7.7287693 | N9: =IF(L9=0,"0",(D9/L9)) -> 7.5377839 | O9: =B9-D9 -> 85.5
A10: 4 | B10: =IF('Entries September 2026'!B10-'Entries September 2026'!B9<1,"0",'Entries September 2026'!B10-'Entries September 2026'!B9) -> 2040 | C10: =IF('Entries September 2026'!F10-'Entries September 2026'!F9<1,"0",'Entries September 2026'!F10-'Entries September 2026'!F9) -> 15.3 | D10: =IF('Entries September 2026'!C10-'Entries September 2026'!C9<1,"0",'Entries September 2026'!C10-'Entries September 2026'!C9) -> 1735.5 | E10: =IF(F10=0,"0", D10/F10) -> 0 | F10: =IF('Entries September 2026'!G10-'Entries September 2026'!G9<1,"0",'Entries September 2026'!G10-'Entries September 2026'!G9) -> 0 | I10: =IF(C10=0,"0", B10/(C10)) -> 133.33333 | J10: =IF(H10=0,"0", G10/H10) -> 0 | K10: =B10+E10+G10 -> 2040 | L10: 96.294 | M10: =IF(L10=0,"0",(K10/L10)) -> 21.185121 | N10: =IF(L10=0,"0",(D10/L10)) -> 18.02293 | O10: =B10-D10 -> 304.5
A11: 5 | B11: =IF('Entries September 2026'!B11-'Entries September 2026'!B10<1,"0",'Entries September 2026'!B11-'Entries September 2026'!B10) -> 0 | C11: =IF('Entries September 2026'!F11-'Entries September 2026'!F10<1,"0",'Entries September 2026'!F11-'Entries September 2026'!F10) -> 0 | D11: =IF('Entries September 2026'!C11-'Entries September 2026'!C10<1,"0",'Entries September 2026'!C11-'Entries September 2026'!C10) -> 0 | E11: =IF(F11=0,"0", D11/F11) -> 0 | F11: =IF('Entries September 2026'!G11-'Entries September 2026'!G10<1,"0",'Entries September 2026'!G11-'Entries September 2026'!G10) -> 0 | I11: =IF(C11=0,"0", B11/(C11)) -> 0 | J11: =IF(H11=0,"0", G11/H11) -> 0 | K11: =B11+E11+G11 -> 0 | L11: 0 | M11: =IF(L11=0,"0",(K11/L11)) -> 0 | N11: =IF(L11=0,"0",(D11/L11)) -> 0 | O11: =B11-D11 -> 0
A12: 6 | B12: =IF('Entries September 2026'!B12-'Entries September 2026'!B11<1,"0",'Entries September 2026'!B12-'Entries September 2026'!B11) -> 0 | C12: =IF('Entries September 2026'!F12-'Entries September 2026'!F11<1,"0",'Entries September 2026'!F12-'Entries September 2026'!F11) -> 0 | D12: =IF('Entries September 2026'!C12-'Entries September 2026'!C11<1,"0",'Entries September 2026'!C12-'Entries September 2026'!C11) -> 0 | E12: =IF(F12=0,"0", D12/F12) -> 0 | F12: =IF('Entries September 2026'!G12-'Entries September 2026'!G11<1,"0",'Entries September 2026'!G12-'Entries September 2026'!G11) -> 0 | I12: =IF(C12=0,"0", B12/(C12)) -> 0 | J12: =IF(H12=0,"0", G12/H12) -> 0 | K12: =B12+E12+G12 -> 0 | L12: 0 | M12: =IF(L12=0,"0",(K12/L12)) -> 0 | N12: =IF(L12=0,"0",(D12/L12)) -> 0 | O12: =B12-D12 -> 0
A13: 7 | B13: =IF('Entries September 2026'!B13-'Entries September 2026'!B12<1,"0",'Entries September 2026'!B13-'Entries September 2026'!B12) -> 2310 | C13: =IF('Entries September 2026'!F13-'Entries September 2026'!F12<1,"0",'Entries September 2026'!F13-'Entries September 2026'!F12) -> 18.5 | D13: =IF('Entries September 2026'!C13-'Entries September 2026'!C12<1,"0",'Entries September 2026'!C13-'Entries September 2026'!C12) -> 2304.9 | E13: =IF(F13=0,"0", D13/F13) -> 0 | F13: =IF('Entries September 2026'!G13-'Entries September 2026'!G12<1,"0",'Entries September 2026'!G13-'Entries September 2026'!G12) -> 0 | I13: =IF(C13=0,"0", B13/(C13)) -> 124.86486 | J13: =IF(H13=0,"0", G13/H13) -> 0 | K13: =B13+E13+G13 -> 2310 | L13: 0 | M13: =IF(L13=0,"0",(K13/L13)) -> 0 | N13: =IF(L13=0,"0",(D13/L13)) -> 0 | O13: =B13-D13 -> 5.1
A14: 8 | B14: =IF('Entries September 2026'!B14-'Entries September 2026'!B13<1,"0",'Entries September 2026'!B14-'Entries September 2026'!B13) -> 3350 | C14: =IF('Entries September 2026'!F14-'Entries September 2026'!F13<1,"0",'Entries September 2026'!F14-'Entries September 2026'!F13) -> 20.8 | D14: =IF('Entries September 2026'!C14-'Entries September 2026'!C13<1,"0",'Entries September 2026'!C14-'Entries September 2026'!C13) -> 2879.8 | E14: =IF(F14=0,"0", D14/F14) -> 0 | F14: =IF('Entries September 2026'!G14-'Entries September 2026'!G13<1,"0",'Entries September 2026'!G14-'Entries September 2026'!G13) -> 0 | I14: =IF(C14=0,"0", B14/(C14)) -> 161.05769 | J14: =IF(H14=0,"0", G14/H14) -> 0 | K14: =B14+E14+G14 -> 3350 | L14: 261.492 | M14: =IF(L14=0,"0",(K14/L14)) -> 12.811099 | N14: =IF(L14=0,"0",(D14/L14)) -> 11.012956 | O14: =B14-D14 -> 470.2
A15: 9 | B15: =IF('Entries September 2026'!B15-'Entries September 2026'!B14<1,"0",'Entries September 2026'!B15-'Entries September 2026'!B14) -> 3850 | C15: =IF('Entries September 2026'!F15-'Entries September 2026'!F14<1,"0",'Entries September 2026'!F15-'Entries September 2026'!F14) -> 20.5 | D15: =IF('Entries September 2026'!C15-'Entries September 2026'!C14<1,"0",'Entries September 2026'!C15-'Entries September 2026'!C14) -> 3813.5 | E15: =IF(F15=0,"0", D15/F15) -> 0 | F15: =IF('Entries September 2026'!G15-'Entries September 2026'!G14<1,"0",'Entries September 2026'!G15-'Entries September 2026'!G14) -> 0 | I15: =IF(C15=0,"0", B15/(C15)) -> 187.80488 | J15: =IF(H15=0,"0", G15/H15) -> 0 | K15: =B15+E15+G15 -> 3850 | L15: 401.61 | M15: =IF(L15=0,"0",(K15/L15)) -> 9.5864147 | N15: =IF(L15=0,"0",(D15/L15)) -> 9.4955305 | O15: =B15-D15 -> 36.5
A16: 10 | B16: =IF('Entries September 2026'!B16-'Entries September 2026'!B15<1,"0",'Entries September 2026'!B16-'Entries September 2026'!B15) -> 2960 | C16: =IF('Entries September 2026'!F16-'Entries September 2026'!F15<1,"0",'Entries September 2026'!F16-'Entries September 2026'!F15) -> 22.6 | D16: =IF('Entries September 2026'!C16-'Entries September 2026'!C15<1,"0",'Entries September 2026'!C16-'Entries September 2026'!C15) -> 2717.4 | E16: =IF(F16=0,"0", D16/F16) -> 0 | F16: =IF('Entries September 2026'!G16-'Entries September 2026'!G15<1,"0",'Entries September 2026'!G16-'Entries September 2026'!G15) -> 0 | I16: =IF(C16=0,"0", B16/(C16)) -> 130.97345 | J16: =IF(H16=0,"0", G16/H16) -> 0 | K16: =B16+E16+G16 -> 2960 | L16: 402.864 | M16: =IF(L16=0,"0",(K16/L16)) -> 7.3473927 | N16: =IF(L16=0,"0",(D16/L16)) -> 6.7452043 | O16: =B16-D16 -> 242.6
A17: 11 | B17: =IF('Entries September 2026'!B17-'Entries September 2026'!B16<1,"0",'Entries September 2026'!B17-'Entries September 2026'!B16) -> 2830 | C17: =IF('Entries September 2026'!F17-'Entries September 2026'!F16<1,"0",'Entries September 2026'!F17-'Entries September 2026'!F16) -> 18.1 | D17: =IF('Entries September 2026'!C17-'Entries September 2026'!C16<1,"0",'Entries September 2026'!C17-'Entries September 2026'!C16) -> 2680.4 | E17: =IF(F17=0,"0", D17/F17) -> 0 | F17: =IF('Entries September 2026'!G17-'Entries September 2026'!G16<1,"0",'Entries September 2026'!G17-'Entries September 2026'!G16) -> 0 | I17: =IF(C17=0,"0", B17/(C17)) -> 156.35359 | J17: =IF(H17=0,"0", G17/H17) -> 0 | K17: =B17+E17+G17 -> 2830 | L17: 266.244 | M17: =IF(L17=0,"0",(K17/L17)) -> 10.629348 | N17: =IF(L17=0,"0",(D17/L17)) -> 10.067457 | O17: =B17-D17 -> 149.6
A18: 12 | B18: =IF('Entries September 2026'!B18-'Entries September 2026'!B17<1,"0",'Entries September 2026'!B18-'Entries September 2026'!B17) -> 230 | C18: =IF('Entries September 2026'!F18-'Entries September 2026'!F17<1,"0",'Entries September 2026'!F18-'Entries September 2026'!F17) -> 1.5 | D18: =IF('Entries September 2026'!C18-'Entries September 2026'!C17<1,"0",'Entries September 2026'!C18-'Entries September 2026'!C17) -> 223.7 | E18: =IF(F18=0,"0", D18/F18) -> 0 | F18: =IF('Entries September 2026'!G18-'Entries September 2026'!G17<1,"0",'Entries September 2026'!G18-'Entries September 2026'!G17) -> 0 | I18: =IF(C18=0,"0", B18/(C18)) -> 153.33333 | J18: =IF(H18=0,"0", G18/H18) -> 0 | K18: =B18+E18+G18 -> 230 | L18: 0 | M18: =IF(L18=0,"0",(K18/L18)) -> 0 | N18: =IF(L18=0,"0",(D18/L18)) -> 0 | O18: =B18-D18 -> 6.3
A19: 13 | B19: =IF('Entries September 2026'!B19-'Entries September 2026'!B18<1,"0",'Entries September 2026'!B19-'Entries September 2026'!B18) -> 850 | C19: =IF('Entries September 2026'!F19-'Entries September 2026'!F18<1,"0",'Entries September 2026'!F19-'Entries September 2026'!F18) -> 5.3 | D19: =IF('Entries September 2026'!C19-'Entries September 2026'!C18<1,"0",'Entries September 2026'!C19-'Entries September 2026'!C18) -> 809.4 | E19: =IF(F19=0,"0", D19/F19) -> 0 | F19: =IF('Entries September 2026'!G19-'Entries September 2026'!G18<1,"0",'Entries September 2026'!G19-'Entries September 2026'!G18) -> 0 | I19: =IF(C19=0,"0", B19/(C19)) -> 160.37736 | J19: =IF(H19=0,"0", G19/H19) -> 0 | K19: =B19+E19+G19 -> 850 | L19: 0 | M19: =IF(L19=0,"0",(K19/L19)) -> 0 | N19: =IF(L19=0,"0",(D19/L19)) -> 0 | O19: =B19-D19 -> 40.6
A20: 14 | B20: =IF('Entries September 2026'!B20-'Entries September 2026'!B19<1,"0",'Entries September 2026'!B20-'Entries September 2026'!B19) -> 3430 | C20: =IF('Entries September 2026'!F20-'Entries September 2026'!F19<1,"0",'Entries September 2026'!F20-'Entries September 2026'!F19) -> 21.6 | D20: =IF('Entries September 2026'!C20-'Entries September 2026'!C19<1,"0",'Entries September 2026'!C20-'Entries September 2026'!C19) -> 3379.4 | E20: =IF(F20=0,"0", D20/F20) -> 0 | F20: =IF('Entries September 2026'!G20-'Entries September 2026'!G19<1,"0",'Entries September 2026'!G20-'Entries September 2026'!G19) -> 0 | I20: =IF(C20=0,"0", B20/(C20)) -> 158.7963 | J20: =IF(H20=0,"0", G20/H20) -> 0 | K20: =B20+E20+G20 -> 3430 | L20: 497.904 | M20: =IF(L20=0,"0",(K20/L20)) -> 6.8888782 | N20: =IF(L20=0,"0",(D20/L20)) -> 6.7872522 | O20: =B20-D20 -> 50.6
A21: 15 | B21: =IF('Entries September 2026'!B21-'Entries September 2026'!B20<1,"0",'Entries September 2026'!B21-'Entries September 2026'!B20) -> 3640 | C21: =IF('Entries September 2026'!F21-'Entries September 2026'!F20<1,"0",'Entries September 2026'!F21-'Entries September 2026'!F20) -> 22.2 | D21: =IF('Entries September 2026'!C21-'Entries September 2026'!C20<1,"0",'Entries September 2026'!C21-'Entries September 2026'!C20) -> 3368.8 | E21: =IF(F21=0,"0", D21/F21) -> 0 | F21: =IF('Entries September 2026'!G21-'Entries September 2026'!G20<1,"0",'Entries September 2026'!G21-'Entries September 2026'!G20) -> 0 | I21: =IF(C21=0,"0", B21/(C21)) -> 163.96396 | J21: =IF(H21=0,"0", G21/H21) -> 0 | K21: =B21+E21+G21 -> 3640 | L21: 602.91 | M21: =IF(L21=0,"0",(K21/L21)) -> 6.0373853 | N21: =IF(L21=0,"0",(D21/L21)) -> 5.587567 | O21: =B21-D21 -> 271.2
A22: 16 | B22: =IF('Entries September 2026'!B22-'Entries September 2026'!B21<1,"0",'Entries September 2026'!B22-'Entries September 2026'!B21) -> 3050 | C22: =IF('Entries September 2026'!F22-'Entries September 2026'!F21<1,"0",'Entries September 2026'!F22-'Entries September 2026'!F21) -> 20.5 | D22: =IF('Entries September 2026'!C22-'Entries September 2026'!C21<1,"0",'Entries September 2026'!C22-'Entries September 2026'!C21) -> 2717.4 | E22: =IF(F22=0,"0", D22/F22) -> 0 | F22: =IF('Entries September 2026'!G22-'Entries September 2026'!G21<1,"0",'Entries September 2026'!G22-'Entries September 2026'!G21) -> 0 | I22: =IF(C22=0,"0", B22/(C22)) -> 148.78049 | J22: =IF(H22=0,"0", G22/H22) -> 0 | K22: =B22+E22+G22 -> 3050 | L22: 243.342 | M22: =IF(L22=0,"0",(K22/L22)) -> 12.5338 | N22: =IF(L22=0,"0",(D22/L22)) -> 11.167 | O22: =B22-D22 -> 332.6
A23: 17 | B23: =IF('Entries September 2026'!B23-'Entries September 2026'!B22<1,"0",'Entries September 2026'!B23-'Entries September 2026'!B22) -> 3500 | C23: =IF('Entries September 2026'!F23-'Entries September 2026'!F22<1,"0",'Entries September 2026'!F23-'Entries September 2026'!F22) -> 21.7 | D23: =IF('Entries September 2026'!C23-'Entries September 2026'!C22<1,"0",'Entries September 2026'!C23-'Entries September 2026'!C22) -> 3314.7 | E23: =IF(F23=0,"0", D23/F23) -> 0 | F23: =IF('Entries September 2026'!G23-'Entries September 2026'!G22<1,"0",'Entries September 2026'!G23-'Entries September 2026'!G22) -> 0 | I23: =IF(C23=0,"0", B23/(C23)) -> 161.29032 | J23: =IF(H23=0,"0", G23/H23) -> 0 | K23: =B23+E23+G23 -> 3500 | L23: 290.202 | M23: =IF(L23=0,"0",(K23/L23)) -> 12.060565 | N23: =IF(L23=0,"0",(D23/L23)) -> 11.422044 | O23: =B23-D23 -> 185.3
A24: 18 | B24: =IF('Entries September 2026'!B24-'Entries September 2026'!B23<1,"0",'Entries September 2026'!B24-'Entries September 2026'!B23) -> 2650 | C24: =IF('Entries September 2026'!F24-'Entries September 2026'!F23<1,"0",'Entries September 2026'!F24-'Entries September 2026'!F23) -> 17.9 | D24: =IF('Entries September 2026'!C24-'Entries September 2026'!C23<1,"0",'Entries September 2026'!C24-'Entries September 2026'!C23) -> 2318.1 | E24: =IF(F24=0,"0", D24/F24) -> 0 | F24: =IF('Entries September 2026'!G24-'Entries September 2026'!G23<1,"0",'Entries September 2026'!G24-'Entries September 2026'!G23) -> 0 | I24: =IF(C24=0,"0", B24/(C24)) -> 148.04469 | J24: =IF(H24=0,"0", G24/H24) -> 0 | K24: =B24+E24+G24 -> 2650 | L24: 440.814 | M24: =IF(L24=0,"0",(K24/L24)) -> 6.0116058 | N24: =IF(L24=0,"0",(D24/L24)) -> 5.2586805 | O24: =B24-D24 -> 331.9
A25: 19 | B25: =IF('Entries September 2026'!B25-'Entries September 2026'!B24<1,"0",'Entries September 2026'!B25-'Entries September 2026'!B24) -> 300 | C25: =IF('Entries September 2026'!F25-'Entries September 2026'!F24<1,"0",'Entries September 2026'!F25-'Entries September 2026'!F24) -> 1.9 | D25: =IF('Entries September 2026'!C25-'Entries September 2026'!C24<1,"0",'Entries September 2026'!C25-'Entries September 2026'!C24) -> 318.2 | E25: =IF(F25=0,"0", D25/F25) -> 0 | F25: =IF('Entries September 2026'!G25-'Entries September 2026'!G24<1,"0",'Entries September 2026'!G25-'Entries September 2026'!G24) -> 0 | I25: =IF(C25=0,"0", B25/(C25)) -> 157.89474 | J25: =IF(H25=0,"0", G25/H25) -> 0 | K25: =B25+E25+G25 -> 300 | L25: 0 | M25: =IF(L25=0,"0",(K25/L25)) -> 0 | N25: =IF(L25=0,"0",(D25/L25)) -> 0 | O25: =B25-D25 -> -18.2
A26: 20 | B26: =IF('Entries September 2026'!B26-'Entries September 2026'!B25<1,"0",'Entries September 2026'!B26-'Entries September 2026'!B25) -> 140 | C26: =IF('Entries September 2026'!F26-'Entries September 2026'!F25<1,"0",'Entries September 2026'!F26-'Entries September 2026'!F25) -> 0 | D26: =IF('Entries September 2026'!C26-'Entries September 2026'!C25<1,"0",'Entries September 2026'!C26-'Entries September 2026'!C25) -> 146.3 | E26: =IF(F26=0,"0", D26/F26) -> 0 | F26: =IF('Entries September 2026'!G26-'Entries September 2026'!G25<1,"0",'Entries September 2026'!G26-'Entries September 2026'!G25) -> 0 | I26: =IF(C26=0,"0", B26/(C26)) -> 0 | J26: =IF(H26=0,"0", G26/H26) -> 0 | K26: =B26+E26+G26 -> 140 | L26: 0 | M26: =IF(L26=0,"0",(K26/L26)) -> 0 | N26: =IF(L26=0,"0",(D26/L26)) -> 0 | O26: =B26-D26 -> -6.3
A27: 21 | B27: =IF('Entries September 2026'!B27-'Entries September 2026'!B26<1,"0",'Entries September 2026'!B27-'Entries September 2026'!B26) -> 3110 | C27: =IF('Entries September 2026'!F27-'Entries September 2026'!F26<1,"0",'Entries September 2026'!F27-'Entries September 2026'!F26) -> 19.1 | D27: =IF('Entries September 2026'!C27-'Entries September 2026'!C26<1,"0",'Entries September 2026'!C27-'Entries September 2026'!C26) -> 3161 | E27: =IF(F27=0,"0", D27/F27) -> 0 | F27: =IF('Entries September 2026'!G27-'Entries September 2026'!G26<1,"0",'Entries September 2026'!G27-'Entries September 2026'!G26) -> 0 | I27: =IF(C27=0,"0", B27/(C27)) -> 162.82723 | J27: =IF(H27=0,"0", G27/H27) -> 0 | K27: =B27+E27+G27 -> 3110 | L27: 179.916 | M27: =IF(L27=0,"0",(K27/L27)) -> 17.285845 | N27: =IF(L27=0,"0",(D27/L27)) -> 17.56931 | O27: =B27-D27 -> -51
A28: 22 | B28: =IF('Entries September 2026'!B28-'Entries September 2026'!B27<1,"0",'Entries September 2026'!B28-'Entries September 2026'!B27) -> 2820 | C28: =IF('Entries September 2026'!F28-'Entries September 2026'!F27<1,"0",'Entries September 2026'!F28-'Entries September 2026'!F27) -> 18.7 | D28: =IF('Entries September 2026'!C28-'Entries September 2026'!C27<1,"0",'Entries September 2026'!C28-'Entries September 2026'!C27) -> 2558.2 | E28: =IF(F28=0,"0", D28/F28) -> 0 | F28: =IF('Entries September 2026'!G28-'Entries September 2026'!G27<1,"0",'Entries September 2026'!G28-'Entries September 2026'!G27) -> 0 | I28: =IF(C28=0,"0", B28/(C28)) -> 150.80214 | J28: =IF(H28=0,"0", G28/H28) -> 0 | K28: =B28+E28+G28 -> 2820 | L28: 365.508 | M28: =IF(L28=0,"0",(K28/L28)) -> 7.7152894 | N28: =IF(L28=0,"0",(D28/L28)) -> 6.999026 | O28: =B28-D28 -> 261.8
A29: 23 | B29: =IF('Entries September 2026'!B29-'Entries September 2026'!B28<1,"0",'Entries September 2026'!B29-'Entries September 2026'!B28) -> 3070 | C29: =IF('Entries September 2026'!F29-'Entries September 2026'!F28<1,"0",'Entries September 2026'!F29-'Entries September 2026'!F28) -> 20.3 | D29: =IF('Entries September 2026'!C29-'Entries September 2026'!C28<1,"0",'Entries September 2026'!C29-'Entries September 2026'!C28) -> 2850.4 | E29: =IF(F29=0,"0", D29/F29) -> 0 | F29: =IF('Entries September 2026'!G29-'Entries September 2026'!G28<1,"0",'Entries September 2026'!G29-'Entries September 2026'!G28) -> 0 | I29: =IF(C29=0,"0", B29/(C29)) -> 151.23153 | J29: =IF(H29=0,"0", G29/H29) -> 0 | K29: =B29+E29+G29 -> 3070 | L29: 280.17 | M29: =IF(L29=0,"0",(K29/L29)) -> 10.957633 | N29: =IF(L29=0,"0",(D29/L29)) -> 10.173823 | O29: =B29-D29 -> 219.6
A30: 24 | B30: =IF('Entries September 2026'!B30-'Entries September 2026'!B29<1,"0",'Entries September 2026'!B30-'Entries September 2026'!B29) -> 2920 | C30: =IF('Entries September 2026'!F30-'Entries September 2026'!F29<1,"0",'Entries September 2026'!F30-'Entries September 2026'!F29) -> 20.4 | D30: =IF('Entries September 2026'!C30-'Entries September 2026'!C29<1,"0",'Entries September 2026'!C30-'Entries September 2026'!C29) -> 2483.7 | E30: =IF(F30=0,"0", D30/F30) -> 0 | F30: =IF('Entries September 2026'!G30-'Entries September 2026'!G29<1,"0",'Entries September 2026'!G30-'Entries September 2026'!G29) -> 0 | I30: =IF(C30=0,"0", B30/(C30)) -> 143.13725 | J30: =IF(H30=0,"0", G30/H30) -> 0 | K30: =B30+E30+G30 -> 2920 | L30: 354.948 | M30: =IF(L30=0,"0",(K30/L30)) -> 8.2265571 | N30: =IF(L30=0,"0",(D30/L30)) -> 6.997363 | O30: =B30-D30 -> 436.3
A31: 25 | B31: =IF('Entries September 2026'!B31-'Entries September 2026'!B30<1,"0",'Entries September 2026'!B31-'Entries September 2026'!B30) -> 2370 | C31: =IF('Entries September 2026'!F31-'Entries September 2026'!F30<1,"0",'Entries September 2026'!F31-'Entries September 2026'!F30) -> 17.6 | D31: =IF('Entries September 2026'!C31-'Entries September 2026'!C30<1,"0",'Entries September 2026'!C31-'Entries September 2026'!C30) -> 1926.1 | E31: =IF(F31=0,"0", D31/F31) -> 0 | F31: =IF('Entries September 2026'!G31-'Entries September 2026'!G30<1,"0",'Entries September 2026'!G31-'Entries September 2026'!G30) -> 0 | I31: =IF(C31=0,"0", B31/(C31)) -> 134.65909 | J31: =IF(H31=0,"0", G31/H31) -> 0 | K31: =B31+E31+G31 -> 2370 | L31: 263.01 | M31: =IF(L31=0,"0",(K31/L31)) -> 9.0110642 | N31: =IF(L31=0,"0",(D31/L31)) -> 7.3232957 | O31: =B31-D31 -> 443.9
A32: 26 | B32: =IF('Entries September 2026'!B32-'Entries September 2026'!B31<1,"0",'Entries September 2026'!B32-'Entries September 2026'!B31) -> 100 | C32: =IF('Entries September 2026'!F32-'Entries September 2026'!F31<1,"0",'Entries September 2026'!F32-'Entries September 2026'!F31) -> 0 | D32: =IF('Entries September 2026'!C32-'Entries September 2026'!C31<1,"0",'Entries September 2026'!C32-'Entries September 2026'!C31) -> 128.1 | E32: =IF(F32=0,"0", D32/F32) -> 0 | F32: =IF('Entries September 2026'!G32-'Entries September 2026'!G31<1,"0",'Entries September 2026'!G32-'Entries September 2026'!G31) -> 0 | I32: =IF(C32=0,"0", B32/(C32)) -> 0 | J32: =IF(H32=0,"0", G32/H32) -> 0 | K32: =B32+E32+G32 -> 100 | L32: 0 | M32: =IF(L32=0,"0",(K32/L32)) -> 0 | N32: =IF(L32=0,"0",(D32/L32)) -> 0 | O32: =B32-D32 -> -28.1
A33: 27 | B33: =IF('Entries September 2026'!B33-'Entries September 2026'!B32<1,"0",'Entries September 2026'!B33-'Entries September 2026'!B32) -> 130 | C33: =IF('Entries September 2026'!F33-'Entries September 2026'!F32<1,"0",'Entries September 2026'!F33-'Entries September 2026'!F32) -> 0 | D33: =IF('Entries September 2026'!C33-'Entries September 2026'!C32<1,"0",'Entries September 2026'!C33-'Entries September 2026'!C32) -> 149.2 | E33: =IF(F33=0,"0", D33/F33) -> 0 | F33: =IF('Entries September 2026'!G33-'Entries September 2026'!G32<1,"0",'Entries September 2026'!G33-'Entries September 2026'!G32) -> 0 | I33: =IF(C33=0,"0", B33/(C33)) -> 0 | J33: =IF(H33=0,"0", G33/H33) -> 0 | K33: =B33+E33+G33 -> 130 | L33: 0 | M33: =IF(L33=0,"0",(K33/L33)) -> 0 | N33: =IF(L33=0,"0",(D33/L33)) -> 0 | O33: =B33-D33 -> -19.2
A34: 28 | B34: =IF('Entries September 2026'!B34-'Entries September 2026'!B33<1,"0",'Entries September 2026'!B34-'Entries September 2026'!B33) -> 0 | C34: =IF('Entries September 2026'!F34-'Entries September 2026'!F33<1,"0",'Entries September 2026'!F34-'Entries September 2026'!F33) -> 0 | D34: =IF('Entries September 2026'!C34-'Entries September 2026'!C33<1,"0",'Entries September 2026'!C34-'Entries September 2026'!C33) -> 0 | E34: =IF(F34=0,"0", D34/F34) -> 0 | F34: =IF('Entries September 2026'!G34-'Entries September 2026'!G33<1,"0",'Entries September 2026'!G34-'Entries September 2026'!G33) -> 0 | I34: =IF(C34=0,"0", B34/(C34)) -> 0 | J34: =IF(H34=0,"0", G34/H34) -> 0 | K34: =B34+E34+G34 -> 0 | L34: 258.72 | M34: =IF(L34=0,"0",(K34/L34)) -> 0 | N34: =IF(L34=0,"0",(D34/L34)) -> 0 | O34: =B34-D34 -> 0
A35: 29 | B35: =IF('Entries September 2026'!B35-'Entries September 2026'!B34<1,"0",'Entries September 2026'!B35-'Entries September 2026'!B34) -> 0 | C35: =IF('Entries September 2026'!F35-'Entries September 2026'!F34<1,"0",'Entries September 2026'!F35-'Entries September 2026'!F34) -> 0 | D35: =IF('Entries September 2026'!C35-'Entries September 2026'!C34<1,"0",'Entries September 2026'!C35-'Entries September 2026'!C34) -> 0 | E35: =IF(F35=0,"0", D35/F35) -> 0 | F35: =IF('Entries September 2026'!G35-'Entries September 2026'!G34<1,"0",'Entries September 2026'!G35-'Entries September 2026'!G34) -> 0 | I35: =IF(C35=0,"0", B35/(C35)) -> 0 | J35: =IF(H35=0,"0", G35/H35) -> 0 | K35: =B35+E35+G35 -> 0 | L35: 0 | M35: =IF(L35=0,"0",(K35/L35)) -> 0 | N35: =IF(L35=0,"0",(D35/L35)) -> 0 | O35: =B35-D35 -> 0
A36: 30 | B36: =IF('Entries September 2026'!B36-'Entries September 2026'!B35<1,"0",'Entries September 2026'!B36-'Entries September 2026'!B35) -> 0 | C36: =IF('Entries September 2026'!F36-'Entries September 2026'!F35<1,"0",'Entries September 2026'!F36-'Entries September 2026'!F35) -> 0 | D36: =IF('Entries September 2026'!C36-'Entries September 2026'!C35<1,"0",'Entries September 2026'!C36-'Entries September 2026'!C35) -> 0 | E36: =IF(F36=0,"0", D36/F36) -> 0 | F36: =IF('Entries September 2026'!G36-'Entries September 2026'!G35<1,"0",'Entries September 2026'!G36-'Entries September 2026'!G35) -> 0 | I36: =IF(C36=0,"0", B36/(C36)) -> 0 | J36: =IF(H36=0,"0", G36/H36) -> 0 | K36: =B36+E36+G36 -> 0 | L36: 0 | M36: =IF(L36=0,"0",(K36/L36)) -> 0 | N36: =IF(L36=0,"0",(D36/L36)) -> 0 | O36: =B36-D36 -> 0
