Workbook

Sheet Entries September'25
B1: ENTRIES FOR DAILY CONS. MONITOR | O1: =B1 -> ENTRIES FOR DAILY CONS. MONITOR
C2: old | F2: old | O2: Service 227.3 cubic meters (2273 Hls)Filtered 189.3 cubic meters(1893 Hls)
D3: FUEL | J3: ELECT. | L3: CO2 | O3: WATER | AG3: CO2 Scrubber (m3) | AH3: Supply to Washdown Area (m3) | AI3: Supply to RUs (m3) | AJ3: Steam Mass Flow Meter | AL3: CO2 TANKS' READING
B4: Boilers tot. | C4: Boiler 1 | D4: Gen. meter | E4: Tank level | F4: Boiler 1 | G4: Boiler 2 | H4: Gen | I4: Meter1 | J4: Meter 2 | K4: Gen Meter | L4: Consumption (BMF) (kg) | M4: Consumption (Totalizer Flowmeter) | N4: Consumption (Filler) (kg) | O4: Nawasa Meter (m3) | P4: Annandale Supply (m3) | Q4: Service Supply to Plant (m3) | R4: Cellars/Filtration (m3) | S4: Brewhouse Meter (m3) | T4: Cellars/Process Areas (m3) | U4: Pasteuriser (m3) | V4: Water Plant-Nawasa Annadale (m3) | W4: Water Plant-Well # 1 (m3) | X4: CIP Process | Y4: Bottle Washer | Z4: Boiler | AA4: Permeate #1 | AB4: Permeate #2 | AC4: Bottle Filler (m3) | AD4: RO # 1 Totaliser (m3) | AE4: RO # 2 Totaliser (m3) | AF4: Recovered Water (m3) | AL4: Tank "C" | AM4: Tank "A" | AN4: Tank "B" | AO4: Mobile Tanker
A5: DATE | B5: (liters) | C5: (liters) | D5: (Imp. gals) | E5: (inches) | F5: Hrs | G5: Hrs | H5: Hrs. | I5: (Kwhr) | J5: (Kwhr) | K5: (Kwhr) | M5: (kg) | X5: (m3) | Y5: (m3) | Z5: (m3) | AL5: inH2O | AM5: (Kg.) | AN5: (Kg.) | AO5: (pounds)
A6: 1 | B6: 7621570 | E6: 64 | F6: 5453.8 | G6: 68225 | I6: 7478 | J6: 535202 | K6: 468000 | L6: 227.79 | M6: 60838.97 | N6: 9964.36 | O6: 193319 | P6: 33963 | Q6: 919465 | S6: 55371 | U6: 21155 | V6: 1312021 | X6: 37047 | Y6: 41306 | Z6: 9181 | AA6: 97122 | AC6: 743 | AD6: 260127 | AJ6: 7297992.7
A7: 2 | B7: 7624590 | E7: 64 | F7: 5472.8 | G7: 68225 | I7: 11905 | J7: 539254 | K7: 468000 | L7: 227.79 | M7: 63352.87 | N7: 10246.66 | O7: 193765 | P7: 34207 | Q7: 919717 | S7: 55537 | U7: 21161 | V7: 1312247 | X7: 37133 | Y7: 41384 | Z7: 9192 | AA7: 97122 | AC7: 769 | AD7: 260127 | AJ7: 7298375.3 | AL7: 220 | AM7: 0 | AN7: 0
A8: 3 | B8: 7627550 | E8: 64 | F8: 5493.2 | G8: 68225 | I8: 16674 | J8: 543617 | K8: 468000 | L8: 227.79 | M8: 65344.93 | N8: 10493.58 | O8: 193861 | P8: 34344 | Q8: 919959 | S8: 55745 | U8: 21170 | V8: 1312390 | X8: 37205 | Y8: 41454 | Z8: 9215 | AA8: 97122 | AC8: 787 | AD8: 260127 | AJ8: 7298375.3 | AL8: 220 | AM8: 0 | AN8: 0
A9: 4 | B9: 7630460 | E9: 64 | F9: 5512.9 | G9: 68225 | I9: 20831 | J9: 547421 | K9: 468000 | L9: 227.79 | M9: 67011.84 | N9: 10740.68 | O9: 194068 | P9: 34519 | Q9: 920129 | S9: 55910 | U9: 21178 | V9: 1312395 | X9: 37227 | Y9: 41522 | Z9: 9230 | AA9: 97122 | AC9: 807 | AD9: 260127 | AJ9: 7298375.3 | AL9: 190 | AM9: 0 | AN9: 0
A10: 5 | B10: 7633640 | E10: 64 | F10: 5532.3 | G10: 68225 | I10: 25153 | J10: 551375 | K10: 468000 | L10: 227.79 | M10: 68434.22 | N10: 11009.6 | O10: 194139 | P10: 34809 | Q10: 920352 | S10: 56090 | U10: 21186 | V10: 1312874 | X10: 37295 | Y10: 41597 | Z10: 9249 | AA10: 97122 | AC10: 826 | AD10: 260127 | AJ10: 7298375.3 | AM10: 0 | AN10: 0
A11: 6 | B11: 7636470 | E11: 64 | F11: 5550.4 | G11: 68225 | I11: 29416 | J11: 555275 | K11: 468000 | L11: 227.79 | M11: 69950.75 | N11: 11226 | O11: 194221 | P11: 35063 | Q11: 920530 | S11: 56297 | U11: 21191 | V11: 1313146 | X11: 37347 | Y11: 41656 | Z11: 9264 | AA11: 97122 | AC11: 841 | AD11: 260160 | AJ11: 7298375.3 | AM11: 0 | AN11: 0
A12: 7 | B12: 7636760 | E12: 64 | F12: 5552.7 | G12: 68225 | I12: 32164 | J12: 557786 | K12: 468000 | L12: 227.79 | M12: 69950.75 | N12: 11226 | O12: 194221 | P12: 35152 | Q12: 920613 | S12: 56297 | U12: 21191 | V12: 1313239 | X12: 37347 | Y12: 41696 | Z12: 9265 | AA12: 97122 | AC12: 841 | AD12: 260160 | AJ12: 7298375.3 | AL12: 160 | AM12: 0 | AN12: 0
A13: 8 | B13: 7636930 | E13: 64 | F13: 5553.3 | G13: 68225 | I13: 34795 | J13: 560192 | K13: 468000 | L13: 227.79 | M13: 69950.75 | N13: 11226 | O13: 194221 | P13: 35152 | Q13: 920613 | S13: 56297 | U13: 21191 | V13: 1313239 | X13: 37347 | Y13: 41696 | Z13: 9267 | AA13: 97122 | AC13: 841 | AD13: 260160 | AJ13: 7298375.3 | AL13: 140 | AM13: 0 | AN13: 0 | AO13: =2.204623*19100 -> 42108.299
A14: 9 | B14: 7640320 | E14: 64 | F14: 5573.6 | G14: 68225 | I14: 38973 | J14: 564017 | K14: 468000 | L14: 227.79 | M14: 71384.99 | N14: 11454.92 | O14: 194403 | P14: 35297 | Q14: 920779 | S14: 56488 | U14: 21206 | V14: 1313391 | X14: 37359 | Y14: 41760 | Z14: 9285 | AA14: 97122 | AC14: 856 | AD14: 260160 | AJ14: 7299271.8 | AL14: 140 | AM14: 0 | AN14: 0 | AO14: 21974
A15: 10 | B15: 7643380 | E15: 64 | F15: 5593.6 | G15: 68225 | I15: 43584 | J15: 568243 | K15: 468000 | L15: 227.79 | M15: 73336.36 | N15: 11755.98 | O15: 194736 | P15: 35349 | Q15: 920985 | S15: 56699 | U15: 21216 | V15: 1313445 | X15: 37389 | Y15: 41835 | Z15: 9299 | AA15: 97122 | AC15: 875 | AD15: 260160 | AJ15: 7299271.8 | AL15: 130 | AM15: 11400 | AN15: 4560
A16: 11 | B16: 7646190 | E16: 64 | F16: 5611.3 | G16: 68225 | I16: 48177 | J16: 572447 | K16: 468000 | L16: 227.79 | M16: 74844.41 | N16: 12008.01 | O16: 194919 | P16: 35458 | Q16: 921189 | S16: 56888 | U16: 21225 | V16: 1313560 | X16: 37438 | Y16: 41905 | Z16: 9312 | AA16: 97122 | AC16: 893 | AD16: 260160 | AJ16: 7299271.8
A17: 12 | B17: 7648560 | E17: 64 | F17: 5629.3 | G17: 68225 | I17: 51936 | J17: 575885 | K17: 468000 | L17: 227.79 | M17: 75116.63 | N17: 12093.9 | O17: 194973 | P17: 35689 | Q17: 921287 | S17: 57052 | U17: 21231 | V17: 1313802 | X17: 37468 | Y17: 41926 | Z17: 9322 | AA17: 97122 | AC17: 898 | AD17: 260160 | AJ17: 7299271.8
A18: 13 | B18: 7649900 | E18: 64 | F18: 5629.3 | G18: 68225 | I18: 55698 | J18: 579318 | K18: 468000 | L18: 227.79 | M18: 75518.24 | N18: 12120.96 | O18: 194973 | P18: 35769 | Q18: 921368 | S18: 57102 | U18: 21235 | V18: 1313886 | X18: 37480 | Y18: 41949 | Z18: 9329 | AA18: 97122 | AC18: 902 | AD18: 260160 | AJ18: 7299413.2
A19: 14 | B19: 7649900 | E19: 64 | F19: 5629.3 | G19: 68225 | I19: 58519 | J19: 581890 | K19: 468000 | L19: 227.79 | M19: 75518.24 | N19: 12120.96 | O19: 194973 | P19: 35845 | Q19: 921390 | S19: 57102 | U19: 21235 | V19: 1313966 | X19: 37480 | Y19: 41953 | Z19: 9329 | AA19: 97122 | AC19: 902 | AD19: 260160 | AJ19: 7299413.2
A20: 15 | B20: 7650850 | E20: 64 | F20: 5644.1 | G20: 68225 | I20: 61384 | J20: 584507 | K20: 468000 | L20: 227.79 | M20: 75518.24 | N20: 12124.1 | O20: 194973 | P20: 35913 | Q20: 921464 | S20: 57108 | U20: 21235 | V20: 1314040 | X20: 37484 | Y20: 41982 | Z20: 9331 | AA20: 97122 | AC20: 919 | AD20: 260160 | AJ20: 7299413.2
A21: 16 | B21: 7653990 | E21: 64 | F21: 5664.1 | G21: 68225 | I21: 66125 | J21: 588852 | K21: 468000 | L21: 227.79 | M21: 77738.36 | N21: 12526.18 | O21: 195222 | P21: 36016 | Q21: 921713 | S21: 57208 | U21: 21250 | V21: 1314209 | X21: 37530 | Y21: 42082 | Z21: 9352 | AA21: 97122 | AC21: 945 | AD21: 260160 | AJ21: 7299446.6
A22: 17 | B22: 7656270 | E22: 64 | F22: 5680.3 | G22: 68225 | I22: 70120 | J22: 592512 | K22: 468000 | L22: 227.79 | M22: 80081.15 | N22: 12881.28 | O22: 195424 | P22: 36201 | Q22: 921914 | S22: 57327 | U22: 21261 | V22: 1314340 | X22: 37567 | Y22: 42166 | Z22: 9364 | AA22: 97122 | AC22: 965 | AD22: 260160 | AJ22: 7299446.6
A23: 18 | B23: 7659460 | E23: 64 | F23: 5700.9 | G23: 68225 | I23: 74799 | J23: 596805 | K23: 468000 | L23: 227.79 | M23: 82454.88 | N23: 13310.16 | O23: 195535 | P23: 36388 | Q23: 922154 | S23: 57476 | U23: 21275 | V23: 1314536 | X23: 37599 | Y23: 42265 | Z23: 9381 | AA23: 97122 | AC23: 994 | AD23: 260160 | AJ23: 7299446.6
A24: 19 | B24: 7663070 | E24: 64 | F24: 5721.3 | G24: 68225 | I24: 79826 | J24: 601416 | K24: 468000 | L24: 321.6 | M24: 85808.84 | N24: 13907.03 | O24: 195744 | P24: 36622 | Q24: 922445 | S24: 57638 | U24: 21288 | V24: 1314772 | X24: 37656 | Y24: 42393 | Z24: 9403 | AA24: 97122 | AC24: 1026 | AD24: 260160 | AJ24: 7299446.6
A25: 20 | B25: 7665980 | E25: 64 | F25: 5739.5 | G25: 68225 | I25: 84348 | J25: 605558 | K25: 468000 | L25: 426.44 | M25: 88685.08 | N25: 14322.87 | O25: 195942 | P25: 36847 | Q25: 922655 | S25: 57806 | U25: 21297 | V25: 1315015 | X25: 37695 | Y25: 42482 | Z25: 9418 | AA25: 97122 | AC25: 1050 | AD25: 260160 | AJ25: 7299446.6
A26: 21 | B26: 7665980 | E26: 64 | F26: 5739.5 | G26: 68225 | I26: 87376 | J26: 608310 | K26: 468000 | L26: 426.44 | M26: 88685.08 | N26: 14322.87 | O26: 195942 | P26: 36847 | Q26: 922692 | S26: 57806 | U26: 21299 | V26: 1315015 | X26: 37695 | Y26: 42488 | Z26: 9421 | AA26: 97122 | AC26: 1050 | AD26: 260160 | AJ26: 7305318.8
A27: 22 | B27: 7667310 | E27: 64 | F27: 5746.2 | G27: 68225 | I27: 89902 | J27: 610606 | K27: 468000 | L27: 426.44 | M27: 88686.95 | N27: 14322.93 | O27: 196016 | P27: 36892 | Q27: 922715 | S27: 57807 | U27: 21300 | V27: 1315067 | X27: 37695 | Y27: 42513 | Z27: 9428 | AA27: 97122 | AC27: 1064 | AD27: 260160 | AJ27: 7305440
... A36: 1 | B36: 7688000 | E36: 64 | F36: 5885.9 | G36: 68225 | I36: 126545 | J36: 644115 | K36: 468000 | L36: 698.99 | M36: 100759.27 | N36: 16327.16 | O36: 197585 | P36: 37910 | Q36: 924266 | S36: 58897 | U36: 21369 | V36: 1316136 | X36: 38049 | Y36: 43045 | Z36: 9523 | AA36: 97122 | AC36: 1208 | AD36: 260317 | AJ36: 7305590.9
A37: 2

Sheet Utility Analysis September'25 
H2: GRENADA BREWERIES LIMITED
H3: UTILITY ANALYSIS
A5: MONTH: | G5: 39295
A7: DATE | D7: ELECTRICITY GRENLEC | E7: CARIB GENSET | F7: ELECTRICITY TOTAL | G7: WATER | H7: FUEL | I7: CO2 | J7: PRODUCTION - HL | O7: UTILITY RATIOS
B8: METER 1 | C8: METER 2 | O8: Elect | P8: Water | Q8: Fuel | R8: CO2
D9: USAGE (kwh) | E9: USAGE (kwh) | F9: USAGE (kwh) | G9: USAGE (Hl) | H9: USAGE (l) | I9: USAGE (Kg.) | J9: BREWED | K9: BOTTLED | L9: KEGS | M9: OTHER | N9: TOTAL | O9: KWH/Hl | P9: Hl/hl | Q9: Litres/hl | R9: kg./Hl
A10: 1 | B10: =IF('Entries September''25'!I7<'Entries September''25'!I6,"0",IF('Entries September''25'!I7>='Entries September''25'!I6,'Entries September''25'!I7-'Entries September''25'!I6,(999999-'Entries September''25'!I6)+'Entries September''25'!I7+1)) -> 4427 | C10: =IF('Entries September''25'!J7<'Entries September''25'!J6,"0",IF('Entries September''25'!J7>='Entries September''25'!J6,'Entries September''25'!J7-'Entries September''25'!J6,(999999-'Entries September''25'!J6)+'Entries September''25'!J7+1)) -> 4052 | D10: =B10+C10 -> 8479 | E10: =IF('Entries September''25'!K7<'Entries September''25'!K6,"0",IF('Entries September''25'!K7>='Entries September''25'!K6,'Entries September''25'!K7-'Entries September''25'!K6,(999999-'Entries September''25'!K6)+'Entries September''25'!K7+1)) -> 0 | F10: =D10+E10 -> 8479 | G10: ='Water '!Z7*10 -> 6900 | H10: =IF('Entries September''25'!B7-'Entries September''25'!B6<1,"0",'Entries September''25'!B7-'Entries September''25'!B6) -> 3020 | I10: ='CO2'!E7 -> 2400 | J10: =+'PROD.FIG. '!F5 -> 0 | K10: =+'PROD.FIG. '!C5 -> 0 | L10: =+'PROD.FIG. '!D5 -> 0 | M10: =+'PROD.FIG. '!E5 -> 0 | N10: {=TRANSPOSE('Daily KPIs'!B9:AF9)} -> 390.852 | O10: =IF(N10=0,0,F10/N10) -> 21.693633 | P10: =IF(O10=0,0,G10/N10) -> 17.653741 | Q10: =IF(P10=0,0,H10/N10) -> 7.7267099 | R10: =IF(Q10=0,0,I10/N10) -> 6.1404317
A11: 2 | B11: =IF('Entries September''25'!I8<'Entries September''25'!I7,"0",IF('Entries September''25'!I8>='Entries September''25'!I7,'Entries September''25'!I8-'Entries September''25'!I7,(999999-'Entries September''25'!I7)+'Entries September''25'!I8+1)) -> 4769 | C11: =IF('Entries September''25'!J8<'Entries September''25'!J7,"0",IF('Entries September''25'!J8>='Entries September''25'!J7,'Entries September''25'!J8-'Entries September''25'!J7,(999999-'Entries September''25'!J7)+'Entries September''25'!J8+1)) -> 4363 | D11: =B11+C11 -> 9132 | E11: =IF('Entries September''25'!K8<'Entries September''25'!K7,"0",IF('Entries September''25'!K8>='Entries September''25'!K7,'Entries September''25'!K8-'Entries September''25'!K7,(999999-'Entries September''25'!K7)+'Entries September''25'!K8+1)) -> 0 | F11: =D11+E11 -> 9132 | G11: ='Water '!Z8*10 -> 2330 | H11: =IF('Entries September''25'!B8-'Entries September''25'!B7<1,"0",'Entries September''25'!B8-'Entries September''25'!B7) -> 2960 | I11: ='CO2'!E8 -> 2000 | J11: =+'PROD.FIG. '!F6 -> 0 | K11: =+'PROD.FIG. '!C6 -> 0 | L11: =+'PROD.FIG. '!D6 -> 0 | M11: =+'PROD.FIG. '!E6 -> 0 | N11: 311.388 | O11: =IF(N11=0,0,F11/N11) -> 29.326756 | P11: =IF(O11=0,0,G11/N11) -> 7.4826262 | Q11: =IF(P11=0,0,H11/N11) -> 9.5058255 | R11: =IF(Q11=0,0,I11/N11) -> 6.4228551
A12: 3 | B12: =IF('Entries September''25'!I9<'Entries September''25'!I8,"0",IF('Entries September''25'!I9>='Entries September''25'!I8,'Entries September''25'!I9-'Entries September''25'!I8,(999999-'Entries September''25'!I8)+'Entries September''25'!I9+1)) -> 4157 | C12: =IF('Entries September''25'!J9<'Entries September''25'!J8,"0",IF('Entries September''25'!J9>='Entries September''25'!J8,'Entries September''25'!J9-'Entries September''25'!J8,(999999-'Entries September''25'!J8)+'Entries September''25'!J9+1)) -> 3804 | D12: =B12+C12 -> 7961 | E12: =IF('Entries September''25'!K9<'Entries September''25'!K8,"0",IF('Entries September''25'!K9>='Entries September''25'!K8,'Entries September''25'!K9-'Entries September''25'!K8,(999999-'Entries September''25'!K8)+'Entries September''25'!K9+1)) -> 0 | F12: =D12+E12 -> 7961 | G12: ='Water '!Z9*10 -> 3820 | H12: =IF('Entries September''25'!B9-'Entries September''25'!B8<1,"0",'Entries September''25'!B9-'Entries September''25'!B8) -> 2910 | I12: ='CO2'!E9 -> 1800 | J12: =+'PROD.FIG. '!F7 -> 0 | K12: =+'PROD.FIG. '!C7 -> 0 | L12: =+'PROD.FIG. '!D7 -> 0 | M12: =+'PROD.FIG. '!E7 -> 0 | N12: 297.858 | O12: =IF(N12=0,0,F12/N12) -> 26.727501 | P12: =IF(O12=0,0,G12/N12) -> 12.824903 | Q12: =IF(P12=0,0,H12/N12) -> 9.7697561 | R12: =IF(Q12=0,0,I12/N12) -> 6.0431481
A13: 4 | B13: =IF('Entries September''25'!I10<'Entries September''25'!I9,"0",IF('Entries September''25'!I10>='Entries September''25'!I9,'Entries September''25'!I10-'Entries September''25'!I9,(999999-'Entries September''25'!I9)+'Entries September''25'!I10+1)) -> 4322 | C13: =IF('Entries September''25'!J10<'Entries September''25'!J9,"0",IF('Entries September''25'!J10>='Entries September''25'!J9,'Entries September''25'!J10-'Entries September''25'!J9,(999999-'Entries September''25'!J9)+'Entries September''25'!J10+1)) -> 3954 | D13: =B13+C13 -> 8276 | E13: =IF('Entries September''25'!K10<'Entries September''25'!K9,"0",IF('Entries September''25'!K10>='Entries September''25'!K9,'Entries September''25'!K10-'Entries September''25'!K9,(999999-'Entries September''25'!K9)+'Entries September''25'!K10+1)) -> 0 | F13: =D13+E13 -> 8276 | G13: ='Water '!Z10*10 -> 3610 | H13: =IF('Entries September''25'!B10-'Entries September''25'!B9<1,"0",'Entries September''25'!B10-'Entries September''25'!B9) -> 3180 | I13: ='CO2'!E10 -> 1400 | J13: =+'PROD.FIG. '!F8 -> 0 | K13: =+'PROD.FIG. '!C8 -> 0 | L13: =+'PROD.FIG. '!D8 -> 0 | M13: =+'PROD.FIG. '!E8 -> 0 | N13: 392.106 | O13: =IF(N13=0,0,F13/N13) -> 21.106538 | P13: =IF(O13=0,0,G13/N13) -> 9.2066941 | Q13: =IF(P13=0,0,H13/N13) -> 8.1100519 | R13: =IF(Q13=0,0,I13/N13) -> 3.5704631
A14: 5 | B14: =IF('Entries September''25'!I11<'Entries September''25'!I10,"0",IF('Entries September''25'!I11>='Entries September''25'!I10,'Entries September''25'!I11-'Entries September''25'!I10,(999999-'Entries September''25'!I10)+'Entries September''25'!I11+1)) -> 4263 | C14: =IF('Entries September''25'!J11<'Entries September''25'!J10,"0",IF('Entries September''25'!J11>='Entries September''25'!J10,'Entries September''25'!J11-'Entries September''25'!J10,(999999-'Entries September''25'!J10)+'Entries September''25'!J11+1)) -> 3900 | D14: =B14+C14 -> 8163 | E14: =IF('Entries September''25'!K11<'Entries September''25'!K10,"0",IF('Entries September''25'!K11>='Entries September''25'!K10,'Entries September''25'!K11-'Entries September''25'!K10,(999999-'Entries September''25'!K10)+'Entries September''25'!K11+1)) -> 0 | F14: =D14+E14 -> 8163 | G14: ='Water '!Z11*10 -> 3360 | H14: =IF('Entries September''25'!B11-'Entries September''25'!B10<1,"0",'Entries September''25'!B11-'Entries September''25'!B10) -> 2830 | I14: ='CO2'!E11 -> 1500 | J14: =+'PROD.FIG. '!F9 -> 0 | K14: =+'PROD.FIG. '!C9 -> 0 | L14: =+'PROD.FIG. '!D9 -> 0 | M14: =+'PROD.FIG. '!E9 -> 0 | N14: 274.494 | O14: =IF(N14=0,0,F14/N14) -> 29.738355 | P14: =IF(O14=0,0,G14/N14) -> 12.240705 | Q14: =IF(P14=0,0,H14/N14) -> 10.309879 | R14: =IF(Q14=0,0,I14/N14) -> 5.4646003
A15: 6 | B15: =IF('Entries September''25'!I12<'Entries September''25'!I11,"0",IF('Entries September''25'!I12>='Entries September''25'!I11,'Entries September''25'!I12-'Entries September''25'!I11,(999999-'Entries September''25'!I11)+'Entries September''25'!I12+1)) -> 2748 | C15: =IF('Entries September''25'!J12<'Entries September''25'!J11,"0",IF('Entries September''25'!J12>='Entries September''25'!J11,'Entries September''25'!J12-'Entries September''25'!J11,(999999-'Entries September''25'!J11)+'Entries September''25'!J12+1)) -> 2511 | D15: =B15+C15 -> 5259 | E15: =IF('Entries September''25'!K12<'Entries September''25'!K11,"0",IF('Entries September''25'!K12>='Entries September''25'!K11,'Entries September''25'!K12-'Entries September''25'!K11,(999999-'Entries September''25'!K11)+'Entries September''25'!K12+1)) -> 0 | F15: =D15+E15 -> 5259 | G15: ='Water '!Z12*10 -> 890 | H15: =IF('Entries September''25'!B12-'Entries September''25'!B11<1,"0",'Entries September''25'!B12-'Entries September''25'!B11) -> 290 | I15: ='CO2'!E12 -> 0 | J15: =+'PROD.FIG. '!F10 -> 0 | K15: =+'PROD.FIG. '!C10 -> 0 | L15: =+'PROD.FIG. '!D10 -> 0 | M15: =+'PROD.FIG. '!E10 -> 0 | N15: 0 | O15: =IF(N15=0,0,F15/N15) -> 0 | P15: =IF(O15=0,0,G15/N15) -> 0 | Q15: =IF(P15=0,0,H15/N15) -> 0 | R15: =IF(Q15=0,0,I15/N15) -> 0
A16: 7 | B16: =IF('Entries September''25'!I13<'Entries September''25'!I12,"0",IF('Entries September''25'!I13>='Entries September''25'!I12,'Entries September''25'!I13-'Entries September''25'!I12,(999999-'Entries September''25'!I12)+'Entries September''25'!I13+1)) -> 2631 | C16: =IF('Entries September''25'!J13<'Entries September''25'!J12,"0",IF('Entries September''25'!J13>='Entries September''25'!J12,'Entries September''25'!J13-'Entries September''25'!J12,(999999-'Entries September''25'!J12)+'Entries September''25'!J13+1)) -> 2406 | D16: =B16+C16 -> 5037 | E16: =IF('Entries September''25'!K13<'Entries September''25'!K12,"0",IF('Entries September''25'!K13>='Entries September''25'!K12,'Entries September''25'!K13-'Entries September''25'!K12,(999999-'Entries September''25'!K12)+'Entries September''25'!K13+1)) -> 0 | F16: =D16+E16 -> 5037 | G16: ='Water '!Z13*10 -> 0 | H16: =IF('Entries September''25'!B13-'Entries September''25'!B12<1,"0",'Entries September''25'!B13-'Entries September''25'!B12) -> 170 | I16: ='CO2'!E13 -> 3000 | J16: =+'PROD.FIG. '!F11 -> 0 | K16: =+'PROD.FIG. '!C11 -> 0 | L16: =+'PROD.FIG. '!D11 -> 0 | M16: =+'PROD.FIG. '!E11 -> 0 | N16: 0 | O16: =IF(N16=0,0,F16/N16) -> 0 | P16: =IF(O16=0,0,G16/N16) -> 0 | Q16: =IF(P16=0,0,H16/N16) -> 0 | R16: =IF(Q16=0,0,I16/N16) -> 0
A17: 8 | B17: =IF('Entries September''25'!I14<'Entries September''25'!I13,"0",IF('Entries September''25'!I14>='Entries September''25'!I13,'Entries September''25'!I14-'Entries September''25'!I13,(999999-'Entries September''25'!I13)+'Entries September''25'!I14+1)) -> 4178 | C17: =IF('Entries September''25'!J14<'Entries September''25'!J13,"0",IF('Entries September''25'!J14>='Entries September''25'!J13,'Entries September''25'!J14-'Entries September''25'!J13,(999999-'Entries September''25'!J13)+'Entries September''25'!J14+1)) -> 3825 | D17: =B17+C17 -> 8003 | E17: =IF('Entries September''25'!K14<'Entries September''25'!K13,"0",IF('Entries September''25'!K14>='Entries September''25'!K13,'Entries September''25'!K14-'Entries September''25'!K13,(999999-'Entries September''25'!K13)+'Entries September''25'!K14+1)) -> 0 | F17: =D17+E17 -> 8003 | G17: ='Water '!Z14*10 -> 3270 | H17: =IF('Entries September''25'!B14-'Entries September''25'!B13<1,"0",'Entries September''25'!B14-'Entries September''25'!B13) -> 3390 | I17: ='CO2'!E14 -> 1600 | J17: =+'PROD.FIG. '!F12 -> 0 | K17: =+'PROD.FIG. '!C12 -> 0 | L17: =+'PROD.FIG. '!D12 -> 0 | M17: =+'PROD.FIG. '!E12 -> 0 | N17: 306.372 | O17: =IF(N17=0,0,F17/N17) -> 26.121839 | P17: =IF(O17=0,0,G17/N17) -> 10.673299 | Q17: =IF(P17=0,0,H17/N17) -> 11.06498 | R17: =IF(Q17=0,0,I17/N17) -> 5.2224094
A18: 9 | B18: =IF('Entries September''25'!I15<'Entries September''25'!I14,"0",IF('Entries September''25'!I15>='Entries September''25'!I14,'Entries September''25'!I15-'Entries September''25'!I14,(999999-'Entries September''25'!I14)+'Entries September''25'!I15+1)) -> 4611 | C18: =IF('Entries September''25'!J15<'Entries September''25'!J14,"0",IF('Entries September''25'!J15>='Entries September''25'!J14,'Entries September''25'!J15-'Entries September''25'!J14,(999999-'Entries September''25'!J14)+'Entries September''25'!J15+1)) -> 4226 | D18: =B18+C18 -> 8837 | E18: =IF('Entries September''25'!K15<'Entries September''25'!K14,"0",IF('Entries September''25'!K15>='Entries September''25'!K14,'Entries September''25'!K15-'Entries September''25'!K14,(999999-'Entries September''25'!K14)+'Entries September''25'!K15+1)) -> 0 | F18: =D18+E18 -> 8837 | G18: ='Water '!Z15*10 -> 3850 | H18: =IF('Entries September''25'!B15-'Entries September''25'!B14<1,"0",'Entries September''25'!B15-'Entries September''25'!B14) -> 3060 | I18: ='CO2'!E15 -> 1400 | J18: =+'PROD.FIG. '!F13 -> 0 | K18: =+'PROD.FIG. '!C13 -> 0 | L18: =+'PROD.FIG. '!D13 -> 0 | M18: =+'PROD.FIG. '!E13 -> 0 | N18: 360.096 | O18: =IF(N18=0,0,F18/N18) -> 24.540678 | P18: =IF(O18=0,0,G18/N18) -> 10.691593 | Q18: =IF(P18=0,0,H18/N18) -> 8.4977339 | R18: =IF(Q18=0,0,I18/N18) -> 3.8878521
A19: 10 | B19: =IF('Entries September''25'!I16<'Entries September''25'!I15,"0",IF('Entries September''25'!I16>='Entries September''25'!I15,'Entries September''25'!I16-'Entries September''25'!I15,(999999-'Entries September''25'!I15)+'Entries September''25'!I16+1)) -> 4593 | C19: =IF('Entries September''25'!J16<'Entries September''25'!J15,"0",IF('Entries September''25'!J16>='Entries September''25'!J15,'Entries September''25'!J16-'Entries September''25'!J15,(999999-'Entries September''25'!J15)+'Entries September''25'!J16+1)) -> 4204 | D19: =B19+C19 -> 8797 | E19: =IF('Entries September''25'!K16<'Entries September''25'!K15,"0",IF('Entries September''25'!K16>='Entries September''25'!K15,'Entries September''25'!K16-'Entries September''25'!K15,(999999-'Entries September''25'!K15)+'Entries September''25'!K16+1)) -> 0 | F19: =D19+E19 -> 8797 | G19: ='Water '!Z16*10 -> 2920 | H19: =IF('Entries September''25'!B16-'Entries September''25'!B15<1,"0",'Entries September''25'!B16-'Entries September''25'!B15) -> 2810 | I19: ='CO2'!E16 -> 1100 | J19: =+'PROD.FIG. '!F14 -> 0 | K19: =+'PROD.FIG. '!C14 -> 0 | L19: =+'PROD.FIG. '!D14 -> 0 | M19: =+'PROD.FIG. '!E14 -> 0 | N19: 320.826 | O19: =IF(N19=0,0,F19/N19) -> 27.419848 | P19: =IF(O19=0,0,G19/N19) -> 9.1015067 | Q19: =IF(P19=0,0,H19/N19) -> 8.7586418 | R19: =IF(Q19=0,0,I19/N19) -> 3.4286498
A20: 11 | B20: =IF('Entries September''25'!I17<'Entries September''25'!I16,"0",IF('Entries September''25'!I17>='Entries September''25'!I16,'Entries September''25'!I17-'Entries September''25'!I16,(999999-'Entries September''25'!I16)+'Entries September''25'!I17+1)) -> 3759 | C20: =IF('Entries September''25'!J17<'Entries September''25'!J16,"0",IF('Entries September''25'!J17>='Entries September''25'!J16,'Entries September''25'!J17-'Entries September''25'!J16,(999999-'Entries September''25'!J16)+'Entries September''25'!J17+1)) -> 3438 | D20: =B20+C20 -> 7197 | E20: =IF('Entries September''25'!K17<'Entries September''25'!K16,"0",IF('Entries September''25'!K17>='Entries September''25'!K16,'Entries September''25'!K17-'Entries September''25'!K16,(999999-'Entries September''25'!K16)+'Entries September''25'!K17+1)) -> 0 | F20: =D20+E20 -> 7197 | G20: ='Water '!Z17*10 -> 2850 | H20: =IF('Entries September''25'!B17-'Entries September''25'!B16<1,"0",'Entries September''25'!B17-'Entries September''25'!B16) -> 2370 | I20: ='CO2'!E17 -> 0 | J20: =+'PROD.FIG. '!F15 -> 0 | K20: =+'PROD.FIG. '!C15 -> 0 | L20: =+'PROD.FIG. '!D15 -> 0 | M20: =+'PROD.FIG. '!E15 -> 0 | N20: 5.676 | O20: =IF(N20=0,0,F20/N20) -> 1267.9704 | P20: =IF(O20=0,0,G20/N20) -> 502.11416 | Q20: =IF(P20=0,0,H20/N20) -> 417.54757 | R20: =IF(Q20=0,0,I20/N20) -> 0
A21: 12 | B21: =IF('Entries September''25'!I18<'Entries September''25'!I17,"0",IF('Entries September''25'!I18>='Entries September''25'!I17,'Entries September''25'!I18-'Entries September''25'!I17,(999999-'Entries September''25'!I17)+'Entries September''25'!I18+1)) -> 3762 | C21: =IF('Entries September''25'!J18<'Entries September''25'!J17,"0",IF('Entries September''25'!J18>='Entries September''25'!J17,'Entries September''25'!J18-'Entries September''25'!J17,(999999-'Entries September''25'!J17)+'Entries September''25'!J18+1)) -> 3433 | D21: =B21+C21 -> 7195 | E21: =IF('Entries September''25'!K18<'Entries September''25'!K17,"0",IF('Entries September''25'!K18>='Entries September''25'!K17,'Entries September''25'!K18-'Entries September''25'!K17,(999999-'Entries September''25'!K17)+'Entries September''25'!K18+1)) -> 0 | F21: =D21+E21 -> 7195 | G21: ='Water '!Z18*10 -> 800 | H21: =IF('Entries September''25'!B18-'Entries September''25'!B17<1,"0",'Entries September''25'!B18-'Entries September''25'!B17) -> 1340 | I21: ='CO2'!E18 -> 300 | J21: =+'PROD.FIG. '!F16 -> 0 | K21: =+'PROD.FIG. '!C16 -> 0 | L21: =+'PROD.FIG. '!D16 -> 0 | M21: =+'PROD.FIG. '!E16 -> 0 | N21: 64.878 | O21: =IF(N21=0,0,F21/N21) -> 110.90046 | P21: =IF(O21=0,0,G21/N21) -> 12.330836 | Q21: =IF(P21=0,0,H21/N21) -> 20.654151 | R21: =IF(Q21=0,0,I21/N21) -> 4.6240636
A22: 13 | B22: =IF('Entries September''25'!I19<'Entries September''25'!I18,"0",IF('Entries September''25'!I19>='Entries September''25'!I18,'Entries September''25'!I19-'Entries September''25'!I18,(999999-'Entries September''25'!I18)+'Entries September''25'!I19+1)) -> 2821 | C22: =IF('Entries September''25'!J19<'Entries September''25'!J18,"0",IF('Entries September''25'!J19>='Entries September''25'!J18,'Entries September''25'!J19-'Entries September''25'!J18,(999999-'Entries September''25'!J18)+'Entries September''25'!J19+1)) -> 2572 | D22: =B22+C22 -> 5393 | E22: =IF('Entries September''25'!K19<'Entries September''25'!K18,"0",IF('Entries September''25'!K19>='Entries September''25'!K18,'Entries September''25'!K19-'Entries September''25'!K18,(999999-'Entries September''25'!K18)+'Entries September''25'!K19+1)) -> 0 | F22: =D22+E22 -> 5393 | G22: ='Water '!Z19*10 -> 760 | H22: =IF('Entries September''25'!B19-'Entries September''25'!B18<1,"0",'Entries September''25'!B19-'Entries September''25'!B18) -> 0 | I22: ='CO2'!E19 -> 0 | J22: =+'PROD.FIG. '!F17 -> 0 | K22: =+'PROD.FIG. '!C17 -> 0 | L22: =+'PROD.FIG. '!D17 -> 0 | M22: =+'PROD.FIG. '!E17 -> 0 | N22: 0 | O22: =IF(N22=0,0,F22/N22) -> 0 | P22: =IF(O22=0,0,G22/N22) -> 0 | Q22: =IF(P22=0,0,H22/N22) -> 0 | R22: =IF(Q22=0,0,I22/N22) -> 0
... A39: 30 | B39: =IF('Entries September''25'!I36<'Entries September''25'!I35,"0",IF('Entries September''25'!I36>='Entries September''25'!I35,'Entries September''25'!I36-'Entries September''25'!I35,(999999-'Entries September''25'!I35)+'Entries September''25'!I36+1)) -> 4769 | C39: =IF('Entries September''25'!J36<'Entries September''25'!J35,"0",IF('Entries September''25'!J36>='Entries September''25'!J35,'Entries September''25'!J36-'Entries September''25'!J35,(999999-'Entries September''25'!J35)+'Entries September''25'!J36+1)) -> 4362 | D39: =B39+C39 -> 9131 | E39: =IF('Entries September''25'!K36<'Entries September''25'!K35,"0",IF('Entries September''25'!K36>='Entries September''25'!K35,'Entries September''25'!K36-'Entries September''25'!K35,(999999-'Entries September''25'!K35)+'Entries September''25'!K36+1)) -> 0 | F39: =D39+E39 -> 9131 | G39: ='Water '!Z36*10 -> 3690 | H39: =IF('Entries September''25'!B36-'Entries September''25'!B35<1,"0",'Entries September''25'!B36-'Entries September''25'!B35) -> 3180 | I39: ='CO2'!E36 -> 1300 | J39: =+'PROD.FIG. '!F34 -> 0 | K39: =+'PROD.FIG. '!C34 -> 0 | L39: =+'PROD.FIG. '!D34 -> 0 | M39: =+'PROD.FIG. '!E34 -> 0 | N39: 198.528 | O39: =IF(N39=0,0,F39/N39) -> 45.993512 | P39: =IF(O39=0,0,G39/N39) -> 18.586799 | Q39: =IF(P39=0,0,H39/N39) -> 16.017892 | R39: =IF(Q39=0,0,I39/N39) -> 6.5481947
A40: 1 | B40: =IF('Entries September''25'!I37<'Entries September''25'!I36,"0",IF('Entries September''25'!I37>='Entries September''25'!I36,'Entries September''25'!I37-'Entries September''25'!I36,(999999-'Entries September''25'!I36)+'Entries September''25'!I37+1)) -> 0 | C40: =IF('Entries September''25'!J37<'Entries September''25'!J36,"0",IF('Entries September''25'!J37>='Entries September''25'!J36,'Entries September''25'!J37-'Entries September''25'!J36,(999999-'Entries September''25'!J36)+'Entries September''25'!J37+1)) -> 0 | D40: =B40+C40 -> 0 | E40: =IF('Entries September''25'!K37<'Entries September''25'!K36,"0",IF('Entries September''25'!K37>='Entries September''25'!K36,'Entries September''25'!K37-'Entries September''25'!K36,(999999-'Entries September''25'!K36)+'Entries September''25'!K37+1)) -> 0 | F40: =D40+E40 -> 0 | G40: ='Water '!Z37*10 -> 0 | H40: =IF('Entries September''25'!B37-'Entries September''25'!B36<1,"0",'Entries September''25'!B37-'Entries September''25'!B36) -> 0 | I40: ='CO2'!E37 -> 0 | N40: 0 | O40: =IF(N40=0,0,F40/N40) -> 0 | P40: =IF(O40=0,0,G40/N40) -> 0 | Q40: =IF(P40=0,0,H40/N40) -> 0 | R40: =IF(Q40=0,0,I40/N40) -> 0
O41: MTD
D42: Kwhr | E42: Kwhr | F42: Kwhr | G42: Hl | H42: L | I42: kg. | J42: hl | K42: hl | L42: hl | M42: hl | N42: hl | O42: Elect | P42: Water | Q42: Fuel | R42: CO2
A43: Total | D43: =SUM(D10:D40) -> 227980 | E43: =SUM(E10:E40) -> 0 | F43: =SUM(F10:F40) -> 227980 | G43: =SUM(G10:G40) -> 82130 | H43: =SUM(H10:H40) -> 66430 | I43: =SUM(I10:I40) -> 44700 | J43: =SUM(J10:J40) -> 0 | K43: =SUM(K10:K40) -> 0 | ... N43: =SUM(N10:N40) -> 7491.0012 | O43: KWH/Hl | P43: Hl/hl | Q43: Litres/hl | R43: kg./Hl
O44: =IF(N43=0,0,F43/N43) -> 30.433849 | P44: =IF(O44=0,0,G43/N43) -> 10.963821 | Q44: =IF(P44=0,0,H43/N43) -> 8.8679735 | R44: =IF(Q44=0,0,I43/N43) -> 5.9671596

Sheet Steam Mass Flow 
A3: DATE | B3: Steam Mass Flow Reading
A5: 1 | B5: =IF('Entries September''25'!AJ7-'Entries September''25'!AJ6<1,"0",'Entries September''25'!AJ7-'Entries September''25'!AJ6) -> 382.655
A6: 2 | B6: =IF('Entries September''25'!AJ8-'Entries September''25'!AJ7<1,"0",'Entries September''25'!AJ8-'Entries September''25'!AJ7) -> 0
A7: 3 | B7: =IF('Entries September''25'!AJ9-'Entries September''25'!AJ8<1,"0",'Entries September''25'!AJ9-'Entries September''25'!AJ8) -> 0
A8: 4 | B8: =IF('Entries September''25'!AJ10-'Entries September''25'!AJ9<1,"0",'Entries September''25'!AJ10-'Entries September''25'!AJ9) -> 0
A9: 5 | B9: =IF('Entries September''25'!AJ11-'Entries September''25'!AJ10<1,"0",'Entries September''25'!AJ11-'Entries September''25'!AJ10) -> 0
A10: 6 | B10: =IF('Entries September''25'!AJ12-'Entries September''25'!AJ11<1,"0",'Entries September''25'!AJ12-'Entries September''25'!AJ11) -> 0
A11: 7 | B11: =IF('Entries September''25'!AJ13-'Entries September''25'!AJ12<1,"0",'Entries September''25'!AJ13-'Entries September''25'!AJ12) -> 0
A12: 8 | B12: =IF('Entries September''25'!AJ14-'Entries September''25'!AJ13<1,"0",'Entries September''25'!AJ14-'Entries September''25'!AJ13) -> 896.424
A13: 9 | B13: =IF('Entries September''25'!AJ15-'Entries September''25'!AJ14<1,"0",'Entries September''25'!AJ15-'Entries September''25'!AJ14) -> 0
A14: 10 | B14: =IF('Entries September''25'!AJ16-'Entries September''25'!AJ15<1,"0",'Entries September''25'!AJ16-'Entries September''25'!AJ15) -> 0
A15: 11 | B15: =IF('Entries September''25'!AJ17-'Entries September''25'!AJ16<1,"0",'Entries September''25'!AJ17-'Entries September''25'!AJ16) -> 0
A16: 12 | B16: =IF('Entries September''25'!AJ18-'Entries September''25'!AJ17<1,"0",'Entries September''25'!AJ18-'Entries September''25'!AJ17) -> 141.445
... A34: 30 | B34: =IF('Entries September''25'!AJ36-'Entries September''25'!AJ35<1,"0",'Entries September''25'!AJ36-'Entries September''25'!AJ35) -> 0
A35: 1
B36: =SUM(B5:B35) -> 7598.212

Sheet Fuel 
A1: DAILY FUEL CONSUMPTION FOR SEPTEMBER 2025
A4: DATE | B4: Boiler 1 | C4: Boiler 1 | D4: Boiler 2 | E4: Boiler 2 | F4: Gen. | G4: Gen | H4: Boiler 1 sp. | I4: Boiler 2 sp. | J4: Gen. sp | K4: Daily cons. | L4: Total Prod.(HL) | M4: Fuel(Litres/HL)
B5: Cons ( l ) | C5: Hrs | D5: Cons ( l ) | E5: Hrs | F5: Cons ( l ) | G5: Hrs | H5: cons (l/hr) | I5: cons (l/hr) | J5: Cons.(l/hr) | K5: (litres)
A7: 1 | B7: =IF('Entries September''25'!B7-'Entries September''25'!B6<1,"0",'Entries September''25'!B7-'Entries September''25'!B6) -> 3020 | C7: =IF('Entries September''25'!F7-'Entries September''25'!F6<1,"0",'Entries September''25'!F7-'Entries September''25'!F6) -> 19 | D7: =IF('Entries September''25'!C6=0,0,+'Entries September''25'!C6-'Entries September''25'!#REF!) -> 0 | E7: =IF('Entries September''25'!G7-'Entries September''25'!G6<1,"0",'Entries September''25'!G7-'Entries September''25'!G6) -> 0 | H7: =IF(C7+E7=0,"0", B7/(C7+E7)) -> 158.94737 | I7: =IF(E7=0,"0", D7/E7) -> 0 | J7: =IF(G7=0,"0", F7/G7) -> 0 | K7: =B7+D7+F7 -> 3020 | L7: {=IF(TRANSPOSE('Daily KPIs'!B9:AF9)=0,"0",TRANSPOSE('Daily KPIs'!B9:AF9))} -> 390.852 | M7: =IF(L7=0,"0",(K7/L7)) -> 7.7267099
A8: 2 | B8: =IF('Entries September''25'!B8-'Entries September''25'!B7<1,"0",'Entries September''25'!B8-'Entries September''25'!B7) -> 2960 | C8: =IF('Entries September''25'!F8-'Entries September''25'!F7<1,"0",'Entries September''25'!F8-'Entries September''25'!F7) -> 20.4 | D8: =IF('Entries September''25'!C7=0,0,+'Entries September''25'!C7-'Entries September''25'!C6) -> 0 | E8: =IF('Entries September''25'!G8-'Entries September''25'!G7<1,"0",'Entries September''25'!G8-'Entries September''25'!G7) -> 0 | H8: =IF(C8+E8=0,"0", B8/(C8+E8)) -> 145.09804 | I8: =IF(E8=0,"0", D8/E8) -> 0 | J8: =IF(G8=0,"0", F8/G8) -> 0 | K8: =B8+D8+F8 -> 2960 | L8: 311.388 | M8: =IF(L8=0,"0",(K8/L8)) -> 9.5058255
A9: 3 | B9: =IF('Entries September''25'!B9-'Entries September''25'!B8<1,"0",'Entries September''25'!B9-'Entries September''25'!B8) -> 2910 | C9: =IF('Entries September''25'!F9-'Entries September''25'!F8<1,"0",'Entries September''25'!F9-'Entries September''25'!F8) -> 19.7 | D9: =IF('Entries September''25'!C8=0,0,+'Entries September''25'!C8-'Entries September''25'!C7) -> 0 | E9: =IF('Entries September''25'!G9-'Entries September''25'!G8<1,"0",'Entries September''25'!G9-'Entries September''25'!G8) -> 0 | H9: =IF(C9+E9=0,"0", B9/(C9+E9)) -> 147.71574 | I9: =IF(E9=0,"0", D9/E9) -> 0 | J9: =IF(G9=0,"0", F9/G9) -> 0 | K9: =B9+D9+F9 -> 2910 | L9: 297.858 | M9: =IF(L9=0,"0",(K9/L9)) -> 9.7697561
A10: 4 | B10: =IF('Entries September''25'!B10-'Entries September''25'!B9<1,"0",'Entries September''25'!B10-'Entries September''25'!B9) -> 3180 | C10: =IF('Entries September''25'!F10-'Entries September''25'!F9<1,"0",'Entries September''25'!F10-'Entries September''25'!F9) -> 19.4 | D10: =IF('Entries September''25'!C11=0,0,+'Entries September''25'!C11-'Entries September''25'!C8) -> 0 | E10: =IF('Entries September''25'!G10-'Entries September''25'!G9<1,"0",'Entries September''25'!G10-'Entries September''25'!G9) -> 0 | H10: =IF(C10+E10=0,"0", B10/(C10+E10)) -> 163.91753 | I10: =IF(E10=0,"0", D10/E10) -> 0 | J10: =IF(G10=0,"0", F10/G10) -> 0 | K10: =B10+D10+F10 -> 3180 | L10: 392.106 | M10: =IF(L10=0,"0",(K10/L10)) -> 8.1100519
A11: 5 | B11: =IF('Entries September''25'!B11-'Entries September''25'!B10<1,"0",'Entries September''25'!B11-'Entries September''25'!B10) -> 2830 | C11: =IF('Entries September''25'!F11-'Entries September''25'!F10<1,"0",'Entries September''25'!F11-'Entries September''25'!F10) -> 18.1 | D11: =IF('Entries September''25'!C10=0,0,+'Entries September''25'!C10-'Entries September''25'!C11) -> 0 | E11: =IF('Entries September''25'!G11-'Entries September''25'!G10<1,"0",'Entries September''25'!G11-'Entries September''25'!G10) -> 0 | H11: =IF(C11+E11=0,"0", B11/(C11+E11)) -> 156.35359 | I11: =IF(E11=0,"0", D11/E11) -> 0 | J11: =IF(G11=0,"0", F11/G11) -> 0 | K11: =B11+D11+F11 -> 2830 | L11: 274.494 | M11: =IF(L11=0,"0",(K11/L11)) -> 10.309879
A12: 6 | B12: =IF('Entries September''25'!B12-'Entries September''25'!B11<1,"0",'Entries September''25'!B12-'Entries September''25'!B11) -> 290 | C12: =IF('Entries September''25'!F12-'Entries September''25'!F11<1,"0",'Entries September''25'!F12-'Entries September''25'!F11) -> 2.3 | D12: =IF('Entries September''25'!C12=0,0,+'Entries September''25'!C12-'Entries September''25'!C10) -> 0 | E12: =IF('Entries September''25'!G12-'Entries September''25'!G11<1,"0",'Entries September''25'!G12-'Entries September''25'!G11) -> 0 | H12: =IF(C12+E12=0,"0", B12/(C12+E12)) -> 126.08696 | I12: =IF(E12=0,"0", D12/E12) -> 0 | J12: =IF(G12=0,"0", F12/G12) -> 0 | K12: =B12+D12+F12 -> 290 | L12: 0 | M12: =IF(L12=0,"0",(K12/L12)) -> 0
A13: 7 | B13: =IF('Entries September''25'!B13-'Entries September''25'!B12<1,"0",'Entries September''25'!B13-'Entries September''25'!B12) -> 170 | C13: =IF('Entries September''25'!F13-'Entries September''25'!F12<1,"0",'Entries September''25'!F13-'Entries September''25'!F12) -> 0 | D13: =IF('Entries September''25'!C13=0,0,+'Entries September''25'!C13-'Entries September''25'!C11) -> 0 | E13: =IF('Entries September''25'!G13-'Entries September''25'!G12<1,"0",'Entries September''25'!G13-'Entries September''25'!G12) -> 0 | H13: =IF(C13+E13=0,"0", B13/(C13+E13)) -> 0 | I13: =IF(E13=0,"0", D13/E13) -> 0 | J13: =IF(G13=0,"0", F13/G13) -> 0 | K13: =B13+D13+F13 -> 170 | L13: 0 | M13: =IF(L13=0,"0",(K13/L13)) -> 0
A14: 8 | B14: =IF('Entries September''25'!B14-'Entries September''25'!B13<1,"0",'Entries September''25'!B14-'Entries September''25'!B13) -> 3390 | C14: =IF('Entries September''25'!F14-'Entries September''25'!F13<1,"0",'Entries September''25'!F14-'Entries September''25'!F13) -> 20.3 | D14: =IF('Entries September''25'!C13=0,0,+'Entries September''25'!C13-'Entries September''25'!#REF!) -> 0 | E14: =IF('Entries September''25'!G14-'Entries September''25'!G13<1,"0",'Entries September''25'!G14-'Entries September''25'!G13) -> 0 | H14: =IF(C14+E14=0,"0", B14/(C14+E14)) -> 166.99507 | I14: =IF(E14=0,"0", D14/E14) -> 0 | J14: =IF(G14=0,"0", F14/G14) -> 0 | K14: =B14+D14+F14 -> 3390 | L14: 306.372 | M14: =IF(L14=0,"0",(K14/L14)) -> 11.06498
A15: 9 | B15: =IF('Entries September''25'!B15-'Entries September''25'!B14<1,"0",'Entries September''25'!B15-'Entries September''25'!B14) -> 3060 | C15: =IF('Entries September''25'!F15-'Entries September''25'!F14<1,"0",'Entries September''25'!F15-'Entries September''25'!F14) -> 20 | D15: =IF('Entries September''25'!C14=0,0,+'Entries September''25'!C14-'Entries September''25'!C13) -> 0 | E15: =IF('Entries September''25'!G15-'Entries September''25'!G14<1,"0",'Entries September''25'!G15-'Entries September''25'!G14) -> 0 | H15: =IF(C15+E15=0,"0", B15/(C15+E15)) -> 153 | I15: =IF(E15=0,"0", D15/E15) -> 0 | J15: =IF(G15=0,"0", F15/G15) -> 0 | K15: =B15+D15+F15 -> 3060 | L15: 360.096 | M15: =IF(L15=0,"0",(K15/L15)) -> 8.4977339
A16: 10 | B16: =IF('Entries September''25'!B16-'Entries September''25'!B15<1,"0",'Entries September''25'!B16-'Entries September''25'!B15) -> 2810 | C16: =IF('Entries September''25'!F16-'Entries September''25'!F15<1,"0",'Entries September''25'!F16-'Entries September''25'!F15) -> 17.7 | D16: =IF('Entries September''25'!C15=0,0,+'Entries September''25'!C15-'Entries September''25'!C14) -> 0 | E16: =IF('Entries September''25'!G16-'Entries September''25'!G15<1,"0",'Entries September''25'!G16-'Entries September''25'!G15) -> 0 | H16: =IF(C16+E16=0,"0", B16/(C16+E16)) -> 158.75706 | I16: =IF(E16=0,"0", D16/E16) -> 0 | J16: =IF(G16=0,"0", F16/G16) -> 0 | K16: =B16+D16+F16 -> 2810 | L16: 320.826 | M16: =IF(L16=0,"0",(K16/L16)) -> 8.7586418
A17: 11 | B17: =IF('Entries September''25'!B17-'Entries September''25'!B16<1,"0",'Entries September''25'!B17-'Entries September''25'!B16) -> 2370 | C17: =IF('Entries September''25'!F17-'Entries September''25'!F16<1,"0",'Entries September''25'!F17-'Entries September''25'!F16) -> 18 | D17: =IF('Entries September''25'!C16=0,0,+'Entries September''25'!C16-'Entries September''25'!C15) -> 0 | E17: =IF('Entries September''25'!G17-'Entries September''25'!G16<1,"0",'Entries September''25'!G17-'Entries September''25'!G16) -> 0 | H17: =IF(C17+E17=0,"0", B17/(C17+E17)) -> 131.66667 | I17: =IF(E17=0,"0", D17/E17) -> 0 | J17: =IF(G17=0,"0", F17/G17) -> 0 | K17: =B17+D17+F17 -> 2370 | L17: 5.676 | M17: =IF(L17=0,"0",(K17/L17)) -> 417.54757
A18: 12 | B18: =IF('Entries September''25'!B18-'Entries September''25'!B17<1,"0",'Entries September''25'!B18-'Entries September''25'!B17) -> 1340 | C18: =IF('Entries September''25'!F18-'Entries September''25'!F17<1,"0",'Entries September''25'!F18-'Entries September''25'!F17) -> 0 | D18: =IF('Entries September''25'!C17=0,0,+'Entries September''25'!C17-'Entries September''25'!C16) -> 0 | E18: =IF('Entries September''25'!G18-'Entries September''25'!G17<1,"0",'Entries September''25'!G18-'Entries September''25'!G17) -> 0 | H18: =IF(C18+E18=0,"0", B18/(C18+E18)) -> 0 | I18: =IF(E18=0,"0", D18/E18) -> 0 | J18: =IF(G18=0,"0", F18/G18) -> 0 | K18: =B18+D18+F18 -> 1340 | L18: 64.878 | M18: =IF(L18=0,"0",(K18/L18)) -> 20.654151
A19: 13 | B19: =IF('Entries September''25'!B19-'Entries September''25'!B18<1,"0",'Entries September''25'!B19-'Entries September''25'!B18) -> 0 | C19: =IF('Entries September''25'!F19-'Entries September''25'!F18<1,"0",'Entries September''25'!F19-'Entries September''25'!F18) -> 0 | D19: =IF('Entries September''25'!C18=0,0,+'Entries September''25'!C18-'Entries September''25'!C17) -> 0 | E19: =IF('Entries September''25'!G19-'Entries September''25'!G18<1,"0",'Entries September''25'!G19-'Entries September''25'!G18) -> 0 | H19: =IF(C19+E19=0,"0", B19/(C19+E19)) -> 0 | I19: =IF(E19=0,"0", D19/E19) -> 0 | J19: =IF(G19=0,"0", F19/G19) -> 0 | K19: =B19+D19+F19 -> 0 | L19: 0 | M19: =IF(L19=0,"0",(K19/L19)) -> 0
A20: 14 | B20: =IF('Entries September''25'!B20-'Entries September''25'!B19<1,"0",'Entries September''25'!B20-'Entries September''25'!B19) -> 950 | C20: =IF('Entries September''25'!F20-'Entries September''25'!F19<1,"0",'Entries September''25'!F20-'Entries September''25'!F19) -> 14.8 | D20: =IF('Entries September''25'!C19=0,0,+'Entries September''25'!C19-'Entries September''25'!C18) -> 0 | E20: =IF('Entries September''25'!G20-'Entries September''25'!G19<1,"0",'Entries September''25'!G20-'Entries September''25'!G19) -> 0 | H20: =IF(C20+E20=0,"0", B20/(C20+E20)) -> 64.189189 | I20: =IF(E20=0,"0", D20/E20) -> 0 | J20: =IF(G20=0,"0", F20/G20) -> 0 | K20: =B20+D20+F20 -> 950 | L20: 0 | M20: =IF(L20=0,"0",(K20/L20)) -> 0
A21: 15 | B21: =IF('Entries September''25'!B21-'Entries September''25'!B20<1,"0",'Entries September''25'!B21-'Entries September''25'!B20) -> 3140 | C21: =IF('Entries September''25'!F21-'Entries September''25'!F20<1,"0",'Entries September''25'!F21-'Entries September''25'!F20) -> 20 | D21: =IF('Entries September''25'!C20=0,0,+'Entries September''25'!C20-'Entries September''25'!C19) -> 0 | E21: =IF('Entries September''25'!G21-'Entries September''25'!G20<1,"0",'Entries September''25'!G21-'Entries September''25'!G20) -> 0 | H21: =IF(C21+E21=0,"0", B21/(C21+E21)) -> 157 | I21: =IF(E21=0,"0", D21/E21) -> 0 | J21: =IF(G21=0,"0", F21/G21) -> 0 | K21: =B21+D21+F21 -> 3140 | L21: 518.4312 | M21: =IF(L21=0,"0",(K21/L21)) -> 6.0567342
A22: 16 | B22: =IF('Entries September''25'!B22-'Entries September''25'!B21<1,"0",'Entries September''25'!B22-'Entries September''25'!B21) -> 2280 | C22: =IF('Entries September''25'!F22-'Entries September''25'!F21<1,"0",'Entries September''25'!F22-'Entries September''25'!F21) -> 16.2 | D22: =IF('Entries September''25'!C21=0,0,+'Entries September''25'!C21-'Entries September''25'!C20) -> 0 | E22: =IF('Entries September''25'!G22-'Entries September''25'!G21<1,"0",'Entries September''25'!G22-'Entries September''25'!G21) -> 0 | H22: =IF(C22+E22=0,"0", B22/(C22+E22)) -> 140.74074 | I22: =IF(E22=0,"0", D22/E22) -> 0 | J22: =IF(G22=0,"0", F22/G22) -> 0 | K22: =B22+D22+F22 -> 2280 | L22: 442.332 | M22: =IF(L22=0,"0",(K22/L22)) -> 5.1544993
A23: 17 | B23: =IF('Entries September''25'!B23-'Entries September''25'!B22<1,"0",'Entries September''25'!B23-'Entries September''25'!B22) -> 3190 | C23: =IF('Entries September''25'!F23-'Entries September''25'!F22<1,"0",'Entries September''25'!F23-'Entries September''25'!F22) -> 20.6 | D23: =IF('Entries September''25'!C22=0,0,+'Entries September''25'!C22-'Entries September''25'!C21) -> 0 | E23: =IF('Entries September''25'!G23-'Entries September''25'!G22<1,"0",'Entries September''25'!G23-'Entries September''25'!G22) -> 0 | H23: =IF(C23+E23=0,"0", B23/(C23+E23)) -> 154.85437 | I23: =IF(E23=0,"0", D23/E23) -> 0 | J23: =IF(G23=0,"0", F23/G23) -> 0 | K23: =B23+D23+F23 -> 3190 | L23: 439.758 | M23: =IF(L23=0,"0",(K23/L23)) -> 7.2539897
A24: 18 | B24: =IF('Entries September''25'!B24-'Entries September''25'!B23<1,"0",'Entries September''25'!B24-'Entries September''25'!B23) -> 3610 | C24: =IF('Entries September''25'!F24-'Entries September''25'!F23<1,"0",'Entries September''25'!F24-'Entries September''25'!F23) -> 20.4 | D24: =IF('Entries September''25'!C23=0,0,+'Entries September''25'!C23-'Entries September''25'!C22) -> 0 | E24: =IF('Entries September''25'!G24-'Entries September''25'!G23<1,"0",'Entries September''25'!G24-'Entries September''25'!G23) -> 0 | H24: =IF(C24+E24=0,"0", B24/(C24+E24)) -> 176.96078 | I24: =IF(E24=0,"0", D24/E24) -> 0 | J24: =IF(G24=0,"0", F24/G24) -> 0 | K24: =B24+D24+F24 -> 3610 | L24: 814.044 | M24: =IF(L24=0,"0",(K24/L24)) -> 4.4346497
A25: 19 | B25: =IF('Entries September''25'!B25-'Entries September''25'!B24<1,"0",'Entries September''25'!B25-'Entries September''25'!B24) -> 2910 | C25: =IF('Entries September''25'!F25-'Entries September''25'!F24<1,"0",'Entries September''25'!F25-'Entries September''25'!F24) -> 18.2 | D25: =IF('Entries September''25'!C24=0,0,+'Entries September''25'!C24-'Entries September''25'!C23) -> 0 | E25: =IF('Entries September''25'!G25-'Entries September''25'!G24<1,"0",'Entries September''25'!G25-'Entries September''25'!G24) -> 0 | H25: =IF(C25+E25=0,"0", B25/(C25+E25)) -> 159.89011 | I25: =IF(E25=0,"0", D25/E25) -> 0 | J25: =IF(G25=0,"0", F25/G25) -> 0 | K25: =B25+D25+F25 -> 2910 | L25: 524.37 | M25: =IF(L25=0,"0",(K25/L25)) -> 5.5495166
A26: 20 | B26: =IF('Entries September''25'!B26-'Entries September''25'!B25<1,"0",'Entries September''25'!B26-'Entries September''25'!B25) -> 0 | C26: =IF('Entries September''25'!F26-'Entries September''25'!F25<1,"0",'Entries September''25'!F26-'Entries September''25'!F25) -> 0 | D26: =IF('Entries September''25'!C25=0,0,+'Entries September''25'!C25-'Entries September''25'!C24) -> 0 | E26: =IF('Entries September''25'!G26-'Entries September''25'!G25<1,"0",'Entries September''25'!G26-'Entries September''25'!G25) -> 0 | H26: =IF(C26+E26=0,"0", B26/(C26+E26)) -> 0 | I26: =IF(E26=0,"0", D26/E26) -> 0 | J26: =IF(G26=0,"0", F26/G26) -> 0 | K26: =B26+D26+F26 -> 0 | L26: 0 | M26: =IF(L26=0,"0",(K26/L26)) -> 0
A27: 21 | B27: =IF('Entries September''25'!B27-'Entries September''25'!B26<1,"0",'Entries September''25'!B27-'Entries September''25'!B26) -> 1330 | C27: =IF('Entries September''25'!F27-'Entries September''25'!F26<1,"0",'Entries September''25'!F27-'Entries September''25'!F26) -> 6.7 | D27: =IF('Entries September''25'!C26=0,0,+'Entries September''25'!C26-'Entries September''25'!C25) -> 0 | E27: =IF('Entries September''25'!G27-'Entries September''25'!G26<1,"0",'Entries September''25'!G27-'Entries September''25'!G26) -> 0 | H27: =IF(C27+E27=0,"0", B27/(C27+E27)) -> 198.50746 | I27: =IF(E27=0,"0", D27/E27) -> 0 | J27: =IF(G27=0,"0", F27/G27) -> 0 | K27: =B27+D27+F27 -> 1330 | L27: 0 | M27: =IF(L27=0,"0",(K27/L27)) -> 0
A28: 22 | B28: =IF('Entries September''25'!B28-'Entries September''25'!B27<1,"0",'Entries September''25'!B28-'Entries September''25'!B27) -> 2910 | C28: =IF('Entries September''25'!F28-'Entries September''25'!F27<1,"0",'Entries September''25'!F28-'Entries September''25'!F27) -> 18.8 | D28: =IF('Entries September''25'!C27=0,0,+'Entries September''25'!C27-'Entries September''25'!C26) -> 0 | E28: =IF('Entries September''25'!G28-'Entries September''25'!G27<1,"0",'Entries September''25'!G28-'Entries September''25'!G27) -> 0 | H28: =IF(C28+E28=0,"0", B28/(C28+E28)) -> 154.78723 | I28: =IF(E28=0,"0", D28/E28) -> 0 | J28: =IF(G28=0,"0", F28/G28) -> 0 | K28: =B28+D28+F28 -> 2910 | L28: 349.47 | M28: =IF(L28=0,"0",(K28/L28)) -> 8.326895
A29: 23 | B29: =IF('Entries September''25'!B29-'Entries September''25'!B28<1,"0",'Entries September''25'!B29-'Entries September''25'!B28) -> 3220 | C29: =IF('Entries September''25'!F29-'Entries September''25'!F28<1,"0",'Entries September''25'!F29-'Entries September''25'!F28) -> 20.8 | D29: =IF('Entries September''25'!C28=0,0,+'Entries September''25'!C28-'Entries September''25'!C27) -> 0 | E29: =IF('Entries September''25'!G29-'Entries September''25'!G28<1,"0",'Entries September''25'!G29-'Entries September''25'!G28) -> 0 | H29: =IF(C29+E29=0,"0", B29/(C29+E29)) -> 154.80769 | I29: =IF(E29=0,"0", D29/E29) -> 0 | J29: =IF(G29=0,"0", F29/G29) -> 0 | K29: =B29+D29+F29 -> 3220 | L29: 484.242 | M29: =IF(L29=0,"0",(K29/L29)) -> 6.6495678
A30: 24 | B30: =IF('Entries September''25'!B30-'Entries September''25'!B29<1,"0",'Entries September''25'!B30-'Entries September''25'!B29) -> 1540 | C30: =IF('Entries September''25'!F30-'Entries September''25'!F29<1,"0",'Entries September''25'!F30-'Entries September''25'!F29) -> 13.4 | D30: =IF('Entries September''25'!C29=0,0,+'Entries September''25'!C29-'Entries September''25'!C28) -> 0 | E30: =IF('Entries September''25'!G30-'Entries September''25'!G29<1,"0",'Entries September''25'!G30-'Entries September''25'!G29) -> 0 | H30: =IF(C30+E30=0,"0", B30/(C30+E30)) -> 114.92537 | I30: =IF(E30=0,"0", D30/E30) -> 0 | J30: =IF(G30=0,"0", F30/G30) -> 0 | K30: =B30+D30+F30 -> 1540 | L30: 0 | M30: =IF(L30=0,"0",(K30/L30)) -> 0
A31: 25 | B31: =IF('Entries September''25'!B31-'Entries September''25'!B30<1,"0",'Entries September''25'!B31-'Entries September''25'!B30) -> 3110 | C31: =IF('Entries September''25'!F31-'Entries September''25'!F30<1,"0",'Entries September''25'!F31-'Entries September''25'!F30) -> 20.2 | D31: =IF('Entries September''25'!C30=0,0,+'Entries September''25'!C30-'Entries September''25'!C29) -> 0 | E31: =IF('Entries September''25'!G31-'Entries September''25'!G30<1,"0",'Entries September''25'!G31-'Entries September''25'!G30) -> 0 | H31: =IF(C31+E31=0,"0", B31/(C31+E31)) -> 153.9604 | I31: =IF(E31=0,"0", D31/E31) -> 0 | J31: =IF(G31=0,"0", F31/G31) -> 0 | K31: =B31+D31+F31 -> 3110 | L31: 282.942 | M31: =IF(L31=0,"0",(K31/L31)) -> 10.991652
A32: 26 | B32: =IF('Entries September''25'!B32-'Entries September''25'!B31<1,"0",'Entries September''25'!B32-'Entries September''25'!B31) -> 2810 | C32: =IF('Entries September''25'!F32-'Entries September''25'!F31<1,"0",'Entries September''25'!F32-'Entries September''25'!F31) -> 18.5 | D32: =IF('Entries September''25'!C31=0,0,+'Entries September''25'!C31-'Entries September''25'!C30) -> 0 | E32: =IF('Entries September''25'!G32-'Entries September''25'!G31<1,"0",'Entries September''25'!G32-'Entries September''25'!G31) -> 0 | H32: =IF(C32+E32=0,"0", B32/(C32+E32)) -> 151.89189 | I32: =IF(E32=0,"0", D32/E32) -> 0 | J32: =IF(G32=0,"0", F32/G32) -> 0 | K32: =B32+D32+F32 -> 2810 | L32: 523.248 | M32: =IF(L32=0,"0",(K32/L32)) -> 5.3703024
A33: 27 | B33: =IF('Entries September''25'!B33-'Entries September''25'!B32<1,"0",'Entries September''25'!B33-'Entries September''25'!B32) -> 690 | C33: =IF('Entries September''25'!F33-'Entries September''25'!F32<1,"0",'Entries September''25'!F33-'Entries September''25'!F32) -> 4.6 | D33: =IF('Entries September''25'!C32=0,0,+'Entries September''25'!C32-'Entries September''25'!C31) -> 0 | E33: =IF('Entries September''25'!G33-'Entries September''25'!G32<1,"0",'Entries September''25'!G33-'Entries September''25'!G32) -> 0 | H33: =IF(C33+E33=0,"0", B33/(C33+E33)) -> 150 | I33: =IF(E33=0,"0", D33/E33) -> 0 | J33: =IF(G33=0,"0", F33/G33) -> 0 | K33: =B33+D33+F33 -> 690 | L33: 0 | M33: =IF(L33=0,"0",(K33/L33)) -> 0
A34: 28 | B34: =IF('Entries September''25'!B34-'Entries September''25'!B33<1,"0",'Entries September''25'!B34-'Entries September''25'!B33) -> 740 | C34: =IF('Entries September''25'!F34-'Entries September''25'!F33<1,"0",'Entries September''25'!F34-'Entries September''25'!F33) -> 5.1 | D34: =IF('Entries September''25'!C33=0,0,+'Entries September''25'!C33-'Entries September''25'!C32) -> 0 | E34: =IF('Entries September''25'!G34-'Entries September''25'!G33<1,"0",'Entries September''25'!G34-'Entries September''25'!G33) -> 0 | H34: =IF(C34+E34=0,"0", B34/(C34+E34)) -> 145.09804 | I34: =IF(E34=0,"0", D34/E34) -> 0 | J34: =IF(G34=0,"0", F34/G34) -> 0 | K34: =B34+D34+F34 -> 740 | L34: 0 | M34: =IF(L34=0,"0",(K34/L34)) -> 0
A35: 29 | B35: =IF('Entries September''25'!B35-'Entries September''25'!B34<1,"0",'Entries September''25'!B35-'Entries September''25'!B34) -> 2490 | C35: =IF('Entries September''25'!F35-'Entries September''25'!F34<1,"0",'Entries September''25'!F35-'Entries September''25'!F34) -> 17.5 | E35: =IF('Entries September''25'!G35-'Entries September''25'!G34<1,"0",'Entries September''25'!G35-'Entries September''25'!G34) -> 0 | H35: =IF(C35+E35=0,"0", B35/(C35+E35)) -> 142.28571 | I35: =IF(E35=0,"0", D35/E35) -> 0 | J35: =IF(G35=0,"0", F35/G35) -> 0 | K35: =B35+D35+F35 -> 2490 | L35: 189.09 | M35: =IF(L35=0,"0",(K35/L35)) -> 13.168333
A36: 30 | B36: =IF('Entries September''25'!B36-'Entries September''25'!B35<1,"0",'Entries September''25'!B36-'Entries September''25'!B35) -> 3180 | C36: =IF('Entries September''25'!F36-'Entries September''25'!F35<1,"0",'Entries September''25'!F36-'Entries September''25'!F35) -> 20.8 | E36: =IF('Entries September''25'!G36-'Entries September''25'!G35<1,"0",'Entries September''25'!G36-'Entries September''25'!G35) -> 0 | H36: =IF(C36+E36=0,"0", B36/(C36+E36)) -> 152.88462 | I36: =IF(E36=0,"0", D36/E36) -> 0 | J36: =IF(G36=0,"0", F36/G36) -> 0 | K36: =B36+D36+F36 -> 3180 | L36: 198.528 | M36: =IF(L36=0,"0",(K36/L36)) -> 16.017892
A37: 1 | B37: =IF('Entries September''25'!B37-'Entries September''25'!B36<1,"0",'Entries September''25'!B37-'Entries September''25'!B36) -> 0 | C37: =IF('Entries September''25'!F37-'Entries September''25'!F36<1,"0",'Entries September''25'!F37-'Entries September''25'!F36) -> 0 | E37: =IF('Entries September''25'!G37-'Entries September''25'!G36<1,"0",'Entries September''25'!G37-'Entries September''25'!G36) -> 0 | H37: =IF(C37+E37=0,"0", B37/(C37+E37)) -> 0 | I37: =IF(E37=0,"0", D37/E37) -> 0 | J37: =IF(G37=0,"0", F37/G37) -> 0 | K37: =B37+D37+F37 -> 0 | L37: 0
A38: MTD | B38: =SUM(B7:B37) -> 66430 | C38: =SUM(C7:C37) -> 431.5 | D38: =SUM(D7:D34) -> 0 | E38: =SUM(E7:E34) -> 0 | H38: =IF(C38+E38=0,"0", B38/(C38+E38)) -> 153.95133 | K38: =SUM(K7:K37) -> 66430 | L38: =SUM(L7:L37) -> 7491.0012 | M38: =IF(L38=0,"0",(K38/L38)) -> 8.8679735 | N38: 7.2 | O38: =M38/N38*100 -> 123.1663
A39: AVE. | B39: =AVERAGE(B7:B37) -> 2372.5 | C39: =AVERAGE(C7:C37) -> 16.596154 | H39: cons (l/hr)

Sheet Water 
B4: DATE | C4: Well Supply (m3) | D4: Nawasa Supply (m3) | E4: Annanale Supply (m3) | F4: RO Water Plant Nawasa (m3) | G4: Service Water Received (m3) | H4: Service Water Supply to Plant (m3) | I4: CO2 Scrubber (m3) | J4: Brewhouse / Old Pepsi Area (m3) | K4: Filtration/Cellars (m3) | L4: Cellars/Process Area (m3) | M4: Pasteuriser (m3) | R4: Permeate Produced (m3) | S4: Plant Cons. USAGE (Hl.) | U4: Bottle Filler (m3) | X4: Rus (m3) | Y4: Washdown Area (m3) | Z4: TOTAL SUPPLY (M3) | AA4: Total Prod.(HL) | AB4: Water KPI (Hl/Hl)
N5: CIP Process (m3) | O5: Bottles Washer (m3) | P5: Bottles Filler (m3) | Q5: Boiler Supply (m3) | T5: ∑ Service Water to Processes | V5: Water into RO #1 (m3) | W5: Water into RO #2 (m3)
B6: -
B7: 1 | C7: =IF('Entries September''25'!W7-'Entries September''25'!W6<1,"0",'Entries September''25'!W7-'Entries September''25'!W6) -> 0 | D7: =IF('Entries September''25'!O7-'Entries September''25'!O6<1,"0",'Entries September''25'!O7-'Entries September''25'!O6) -> 446 | E7: =IF('Entries September''25'!P7-'Entries September''25'!P6<1,"0",'Entries September''25'!P7-'Entries September''25'!P6) -> 244 | F7: =IF('Entries September''25'!V7-'Entries September''25'!V6<1,"0",'Entries September''25'!V7-'Entries September''25'!V6) -> 226 | G7: =(D7+E7)-F7 -> 464 | H7: =IF('Entries September''25'!Q7-'Entries September''25'!Q6<1,0,'Entries September''25'!Q7-'Entries September''25'!Q6) -> 252 | I7: =IF('Entries September''25'!AG7-'Entries September''25'!AG6<1,0,'Entries September''25'!AG7-'Entries September''25'!AG6) -> 0 | J7: =IF('Entries September''25'!S7-'Entries September''25'!S6<1,"0",'Entries September''25'!S7-'Entries September''25'!S6) -> 166 | K7: =IF('Entries September''25'!R7-'Entries September''25'!R6<1,"0",'Entries September''25'!R7-'Entries September''25'!R6) -> 0 | L7: =IF('Entries September''25'!T7-'Entries September''25'!T6<1,"0",'Entries September''25'!T7-'Entries September''25'!T6) -> 0 | M7: =IF('Entries September''25'!U7-'Entries September''25'!U6<1,"0",'Entries September''25'!U7-'Entries September''25'!U6) -> 6 | N7: =IF('Entries September''25'!X7-'Entries September''25'!X6<1,"0",'Entries September''25'!X7-'Entries September''25'!X6) -> 86 | O7: =IF('Entries September''25'!Y7-'Entries September''25'!Y6<1,"0",'Entries September''25'!Y7-'Entries September''25'!Y6) -> 78 | P7: =IF('Entries September''25'!AC7-'Entries September''25'!AC6<1,"0",'Entries September''25'!AC7-'Entries September''25'!AC6) -> 26 | Q7: =IF('Entries September''25'!Z7-'Entries September''25'!Z6<1,"0",'Entries September''25'!Z7-'Entries September''25'!Z6) -> 11 | R7: =IF(('Entries September''25'!AA7-'Entries September''25'!AA6)+('Entries September''25'!AB7-'Entries September''25'!AB6)<1,"0",('Entries September''25'!AA7-'Entries September''25'!AA6)+('Entries September''25'!AB7-'Entries September''25'!AB6)) -> 0 | S7: =(R7+G7)*10 -> 4640 | T7: =O7+N7+M7+L7 -> 170 | U7: =IF('Entries September''25'!AC7-'Entries September''25'!AC6<1,"0",'Entries September''25'!AC7-'Entries September''25'!AC6) -> 26 | V7: =IF('Entries September''25'!AD7-'Entries September''25'!AD6<1,"0",'Entries September''25'!AD7-'Entries September''25'!AD6) -> 0 | W7: =IF('Entries September''25'!AE7-'Entries September''25'!AE6<1,"0",'Entries September''25'!AE7-'Entries September''25'!AE6) -> 0 | X7: =IF('Entries September''25'!AI7-'Entries September''25'!AI6<1,"0",'Entries September''25'!AI7-'Entries September''25'!AI6) -> 0 | Y7: =IF('Entries September''25'!AH7-'Entries September''25'!AH6<1,"0",'Entries September''25'!AH7-'Entries September''25'!AH6) -> 0 | Z7: =C7+D7+E7 -> 690 | AA7: {=IF(TRANSPOSE('Daily KPIs'!B9:AF9)=0,"0",TRANSPOSE('Daily KPIs'!B9:AF9))} -> 390.852 | AB7: =IF(AA7=0,"0",(Z7*10/AA7)) -> 17.653741
